File: combined_ligament_solver/data/processed/Data Sheet 3_S160134_PCL.csv
Specimen properties : Length,30,mm,Unnamed: 3,Unnamed: 4,Unnamed: 5,Unnamed: 6,Unnamed: 7,Unnamed: 8,Unnamed: 9,Unnamed: 10,Unnamed: 11,Stress-Strain,Unnamed: 13,Unnamed: 14,Unnamed: 15,Unnamed: 16,Unnamed: 17,Unnamed: 18,Unnamed: 19,Unnamed: 20,Unnamed: 21,Unnamed: 22,Unnamed: 23,Unnamed: 24,Unnamed: 25,Unnamed: 26,Unnamed: 27,Linear,Unnamed: 29,Unnamed: 30,Unnamed: 31,Unnamed: 32,Unnamed: 33,Modulus,Unnamed: 35,Failure,Unnamed: 37,Unnamed: 38,Unnamed: 39,Unnamed: 40
Cross Section Average,48.8245,mm2,,,,,,,,,,Polynomial Coefficients,,,,,,,,,,,,,,,,Force,,Stress,Extension,Strain,,Secant,Tangent,Load,Stress,Extension,Strain,Stiffness
Time,Extension,Load,Total cycle count,,,Extension,Load,Strain,Stress,E-tan,,X6,666285.4014150756,,,,,,,,,Strain,Stress,E-tan,,,,(N),,(MPa),(mm),(%),,(MPa),(MPa),(N),(MPa),(mm),(%),(N/mm)
(s),(mm),(N),,,,(mm),(N),(mm/mm),(MPa),(MPa),,X5,-417034.77844610513,,,,,,,,,(mm/mm),(MPa),(MPa),,,,765.824900280971,,15.685258431340229,5.22,17.4,,90.14516339850707,192.83145513736045,1336.48828,27.34857766080554,7.1830099999999995,23.943366666666666,146.70975101168025
0.6,3.19277,1.3035,0,,,8.05749,596.78619,0.15609599999999996,12.198354105008757,183.68592623700488,,,,,,,,,,,,0.006,-0.001544963887626146,0.5138180052927775,,,,,,,,,,,,,,,,
1.3,3.30956,1.50813,0,,,13.89127,167.54951,,,,,,,,,,,,,,,0.013,0.010511797025070244,2.6490237065040727,,,,,,,,,,,,,,,,
2,3.42612,2.04119,0,,,19.72436,1.14152,,,,,,,,,,,,,,,0.02,0.03870296847262822,5.140661744084668,,,,,,,,,,,,,,,,
2.7,3.54274,2.54449,0,,,25.55774,0.84674,,,,,,,,,,,,,,,0.027,0.08704042456736948,8.353411639471625,,,,,,,,,,,,,,,,
3.4,3.65942,3.42551,0,,,,,,,,,,,,,,,,,,,0.034,0.16169340657674722,12.554257361269128,,,,,,,,,,,,,,,,
4.1,3.7761,4.65435,0,,,,,,,,,,,,,,,,,,,0.041,0.2703369050386924,17.92055007154262,,,,,,,,,,,,,,,,
4.8,3.89277,5.88206,0,,,,,,,,,,,,,,,,,,,0.048,0.42155648110101784,24.548070872112557,,,,,,,,,,,,,,,,
5.5,4.00934,7.2081,0,,,,,,,,,,,,,,,,,,,0.055,0.6243095270848796,32.45909355084883,,,,,,,,,,,,,,,,
6.2,4.12601,8.80767,0,,,,,,,,,,,,,,,,,,,0.062,0.8874429662722961,41.610447327963335,,,,,,,,,,,,,,,,
6.9,4.24269,10.62622,0,,,,,,,,,,,,,,,,,,,0.069,1.2192673919177255,51.90157960230652,,,,,,,,,,,,,,,,
7.6,4.35942,12.52521,0,,,,,,,,,,,,,,,,,,,0.076,1.6271876454836964,63.18261869765755,,,,,,,,,,,,,,,,
8.3,4.47604,16.15561,0,,,,,,,,,,,,,,,,,,,0.083,2.117389834100508,75.26243660902301,,,,,,,,,,,,,,,,
9,4.59272,19.81406,0,,,,,,,,,,,,,,,,,,,0.09,2.6945847872499655,87.91671174892448,,,,,,,,,,,,,,,,
9.7,4.70928,23.98325,0,,,,,,,,,,,,,,,,,,,0.097,3.361807952673206,100.89599169370125,,,,,,,,,,,,,,,,
10.4,4.82607,29.32041,0,,,,,,,,,,,,,,,,,,,0.104,4.120275731502544,113.93375592979628,,,,,,,,,,,,,,,,
11.1,4.94281,33.84298,0,,,,,,,,,,,,,,,,,,,0.111,4.969298252617408,126.75447860005103,,,,,,,,,,,,,,,,
11.692,5.04135,40.05958,0.5,,,,,,,,,,,,,,,,,,,0.118,5.906248586224306,139.08169125000487,,,,,,,,,,,,,,,,
12.392,4.92439,31.09618,0.5,,,,,,,,,,,,,,,,,,,0.125,6.926588396660881,150.64604557418167,,,,,,,,,,,,,,,,
13.092,4.80777,24.3602,0.5,,,,,,,,,,,,,,,,,,,0.132,8.023950034423995,161.1933761623961,,,,,,,,,,,,,,,,
13.792,4.69109,19.33718,0.5,,,,,,,,,,,,,,,,,,,0.139,9.190275067421876,170.49276324603275,,,,,,,,,,,,,,,,
14.492,4.57447,15.27528,0.5,,,,,,,,,,,,,,,,,,,0.146,10.416009251450326,178.3445954443417,,,,,,,,,,,,,,,,
15.192,4.45785,11.80506,0.5,,,,,,,,,,,,,,,,,,,0.153,11.690353939893035,184.58863251075266,,,,,,,,,,,,,,,,
15.892,4.34118,9.59773,0.5,,,,,,,,,,,,,,,,,,,0.16,13.001573932645819,189.11206807913297,,,,,,,,,,,,,,,,
16.592,4.2245,7.57285,0.5,,,,,,,,,,,,,,,,,,,0.167,14.337361764265092,191.8575924101125,,,,,,,,,,,,,,,,
17.292,4.10777,5.7999,0.5,,,,,,,,,,,,,,,,,,MAX,0.174,15.685258431340229,192.83145513736045,,,,,,,,,,,,,,,,
17.992,3.99115,4.57267,0.5,,,,,,,,,,,,,,,,,,,0.181,17.033130559090147,192.11152801393874,,,,,,,,,,,,,,,,
18.692,3.87453,3.37505,0.5,,,,,,,,,,,,,,,,,,,0.188,18.369704007183795,189.85536765848093,,,,,,,,,,,,,,,,
19.392,3.75785,2.44225,0.5,,,,,,,,,,,,,,,,,,,0.195,19.685153914784742,186.30827830148516,,,,,,,,,,,,,,,,
20.092,3.64112,1.88492,0.5,,,,,,,,,,,,,,,,,,,,,,,,,,,,,,,,,,,,,
20.792,3.52438,1.41602,0.5,,,,,,,,,,,,,,,,,,,,,,,,,,,,,,,,,,,,,
21.492,3.40765,1.12827,0.5,,,,,,,,,,,,,,,,,,,,,,,,,,,,,,,,,,,,,
21.932,3.43525,1.16666,1,,,,,,,,,,,,,,,,,,,,,,,,,,,,,,,,,,,,,
22.632,3.55204,1.6229,1,,,,,,,,,,,,,,,,,,,,,,,,,,,,,,,,,,,,,
23.332,3.66877,2.24907,1,,,,,,,,,,,,,,,,,,,,,,,,,,,,,,,,,,,,,
24.032,3.78533,3.18827,1,,,,,,,,,,,,,,,,,,,,,,,,,,,,,,,,,,,,,
24.732,3.90201,4.47911,1,,,,,,,,,,,,,,,,,,,,,,,,,,,,,,,,,,,,,
25.432,4.01863,5.95153,1,,,,,,,,,,,,,,,,,,,,,,,,,,,,,,,,,,,,,
26.132,4.13531,7.56357,1,,,,,,,,,,,,,,,,,,,,,,,,,,,,,,,,,,,,,
26.832,4.25204,9.4254,1,,,,,,,,,,,,,,,,,,,,,,,,,,,,,,,,,,,,,
27.532,4.36877,12.00962,1,,,,,,,,,,,,,,,,,,,,,,,,,,,,,,,,,,,,,
28.232,4.48539,15.05422,1,,,,,,,,,,,,,,,,,,,,,,,,,,,,,,,,,,,,,
28.932,4.60213,18.66046,1,,,,,,,,,,,,,,,,,,,,,,,,,,,,,,,,,,,,,
29.632,4.7188,22.93079,1,,,,,,,,,,,,,,,,,,,,,,,,,,,,,,,,,,,,,
30.332,4.83548,28.17412,1,,,,,,,,,,,,,,,,,,,,,,,,,,,,,,,,,,,,,
31.032,4.95221,34.55858,1,,,,,,,,,,,,,,,,,,,,,,,,,,,,,,,,,,,,,
31.69,5.06192,40.02178,1.5,,,,,,,,,,,,,,,,,,,,,,,,,,,,,,,,,,,,,
32.292,4.96179,32.26469,1.5,,,,,,,,,,,,,,,,,,,,,,,,,,,,,,,,,,,,,
32.992,4.84517,25.09361,1.5,,,,,,,,,,,,,,,,,,,,,,,,,,,,,,,,,,,,,
33.692,4.72849,19.99442,1.5,,,,,,,,,,,,,,,,,,,,,,,,,,,,,,,,,,,,,
34.392,4.61187,16.20664,1.5,,,,,,,,,,,,,,,,,,,,,,,,,,,,,,,,,,,,,
35.092,4.49514,12.73928,1.5,,,,,,,,,,,,,,,,,,,,,,,,,,,,,,,,,,,,,
35.792,4.37846,9.80938,1.5,,,,,,,,,,,,,,,,,,,,,,,,,,,,,,,,,,,,,
36.492,4.26179,8.28986,1.5,,,,,,,,,,,,,,,,,,,,,,,,,,,,,,,,,,,,,
37.192,4.14505,6.16565,1.5,,,,,,,,,,,,,,,,,,,,,,,,,,,,,,,,,,,,,
37.892,4.02838,4.6857,1.5,,,,,,,,,,,,,,,,,,,,,,,,,,,,,,,,,,,,,
38.592,3.91164,3.59703,1.5,,,,,,,,,,,,,,,,,,,,,,,,,,,,,,,,,,,,,
39.292,3.79497,2.60436,1.5,,,,,,,,,,,,,,,,,,,,,,,,,,,,,,,,,,,,,
39.992,3.67829,1.85099,1.5,,,,,,,,,,,,,,,,,,,,,,,,,,,,,,,,,,,,,
40.692,3.56173,1.50507,1.5,,,,,,,,,,,,,,,,,,,,,,,,,,,,,,,,,,,,,
41.392,3.44516,1.13621,1.5,,,,,,,,,,,,,,,,,,,,,,,,,,,,,,,,,,,,,
41.814,3.44205,1.14562,2,,,,,,,,,,,,,,,,,,,,,,,,,,,,,,,,,,,,,
42.514,3.55906,1.62022,2,,,,,,,,,,,,,,,,,,,,,,,,,,,,,,,,,,,,,
43.214,3.67568,2.22302,2,,,,,,,,,,,,,,,,,,,,,,,,,,,,,,,,,,,,,
43.914,3.7923,3.11503,2,,,,,,,,,,,,,,,,,,,,,,,,,,,,,,,,,,,,,
44.614,3.90898,4.40003,2,,,,,,,,,,,,,,,,,,,,,,,,,,,,,,,,,,,,,
45.314,4.02566,5.86752,2,,,,,,,,,,,,,,,,,,,,,,,,,,,,,,,,,,,,,
46.014,4.14239,7.37345,2,,,,,,,,,,,,,,,,,,,,,,,,,,,,,,,,,,,,,
46.714,4.25907,9.30019,2,,,,,,,,,,,,,,,,,,,,,,,,,,,,,,,,,,,,,
47.414,4.37574,12.03828,2,,,,,,,,,,,,,,,,,,,,,,,,,,,,,,,,,,,,,
48.114,4.49248,14.95184,2,,,,,,,,,,,,,,,,,,,,,,,,,,,,,,,,,,,,,
48.814,4.60921,18.60206,2,,,,,,,,,,,,,,,,,,,,,,,,,,,,,,,,,,,,,
49.514,4.72589,22.80621,2,,,,,,,,,,,,,,,,,,,,,,,,,,,,,,,,,,,,,
50.214,4.84251,27.93312,2,,,,,,,,,,,,,,,,,,,,,,,,,,,,,,,,,,,,,
50.914,4.95901,33.6154,2,,,,,,,,,,,,,,,,,,,,,,,,,,,,,,,,,,,,,
51.566,5.06781,40.01051,2.5,,,,,,,,,,,,,,,,,,,,,,,,,,,,,,,,,,,,,
52.168,4.96785,32.2637,2.5,,,,,,,,,,,,,,,,,,,,,,,,,,,,,,,,,,,,,
52.868,4.85118,25.0517,2.5,,,,,,,,,,,,,,,,,,,,,,,,,,,,,,,,,,,,,
53.568,4.73444,20.05285,2.5,,,,,,,,,,,,,,,,,,,,,,,,,,,,,,,,,,,,,
54.268,4.61782,16.15211,2.5,,,,,,,,,,,,,,,,,,,,,,,,,,,,,,,,,,,,,
54.968,4.50115,12.79065,2.5,,,,,,,,,,,,,,,,,,,,,,,,,,,,,,,,,,,,,
55.668,4.38453,9.854,2.5,,,,,,,,,,,,,,,,,,,,,,,,,,,,,,,,,,,,,
56.368,4.26785,8.10367,2.5,,,,,,,,,,,,,,,,,,,,,,,,,,,,,,,,,,,,,
57.068,4.15106,6.10508,2.5,,,,,,,,,,,,,,,,,,,,,,,,,,,,,,,,,,,,,
57.768,4.03438,4.71115,2.5,,,,,,,,,,,,,,,,,,,,,,,,,,,,,,,,,,,,,
58.468,3.91771,3.53382,2.5,,,,,,,,,,,,,,,,,,,,,,,,,,,,,,,,,,,,,
59.168,3.80103,2.60441,2.5,,,,,,,,,,,,,,,,,,,,,,,,,,,,,,,,,,,,,
59.868,3.6843,1.83582,2.5,,,,,,,,,,,,,,,,,,,,,,,,,,,,,,,,,,,,,
60.568,3.56762,1.41785,2.5,,,,,,,,,,,,,,,,,,,,,,,,,,,,,,,,,,,,,
61.268,3.451,1.08148,2.5,,,,,,,,,,,,,,,,,,,,,,,,,,,,,,,,,,,,,
61.728,3.47548,1.19073,3,,,,,,,,,,,,,,,,,,,,,,,,,,,,,,,,,,,,,
62.428,3.59216,1.69405,3,,,,,,,,,,,,,,,,,,,,,,,,,,,,,,,,,,,,,
63.128,3.70883,2.32389,3,,,,,,,,,,,,,,,,,,,,,,,,,,,,,,,,,,,,,
63.828,3.8254,3.23922,3,,,,,,,,,,,,,,,,,,,,,,,,,,,,,,,,,,,,,
64.528,3.94202,4.68136,3,,,,,,,,,,,,,,,,,,,,,,,,,,,,,,,,,,,,,
65.228,4.05875,6.12633,3,,,,,,,,,,,,,,,,,,,,,,,,,,,,,,,,,,,,,
65.928,4.17543,7.66275,3,,,,,,,,,,,,,,,,,,,,,,,,,,,,,,,,,,,,,
66.628,4.29205,9.86924,3,,,,,,,,,,,,,,,,,,,,,,,,,,,,,,,,,,,,,
67.328,4.40867,12.75967,3,,,,,,,,,,,,,,,,,,,,,,,,,,,,,,,,,,,,,
68.028,4.52529,15.69838,3,,,,,,,,,,,,,,,,,,,,,,,,,,,,,,,,,,,,,
68.728,4.64196,19.5968,3,,,,,,,,,,,,,,,,,,,,,,,,,,,,,,,,,,,,,
69.428,4.75875,23.88043,3,,,,,,,,,,,,,,,,,,,,,,,,,,,,,,,,,,,,,
70.128,4.87543,29.4714,3,,,,,,,,,,,,,,,,,,,,,,,,,,,,,,,,,,,,,
70.828,4.99205,34.32607,3,,,,,,,,,,,,,,,,,,,,,,,,,,,,,,,,,,,,,
71.404,5.05903,39.7271,3.5,,,,,,,,,,,,,,,,,,,,,,,,,,,,,,,,,,,,,
72.104,4.93776,29.96978,3.5,,,,,,,,,,,,,,,,,,,,,,,,,,,,,,,,,,,,,
72.804,4.82097,23.51419,3.5,,,,,,,,,,,,,,,,,,,,,,,,,,,,,,,,,,,,,
73.504,4.7043,18.77405,3.5,,,,,,,,,,,,,,,,,,,,,,,,,,,,,,,,,,,,,
74.204,4.58768,15.12914,3.5,,,,,,,,,,,,,,,,,,,,,,,,,,,,,,,,,,,,,
74.904,4.47106,11.87269,3.5,,,,,,,,,,,,,,,,,,,,,,,,,,,,,,,,,,,,,
75.604,4.35438,9.18737,3.5,,,,,,,,,,,,,,,,,,,,,,,,,,,,,,,,,,,,,
76.304,4.23776,7.57538,3.5,,,,,,,,,,,,,,,,,,,,,,,,,,,,,,,,,,,,,
77.004,4.12108,5.65783,3.5,,,,,,,,,,,,,,,,,,,,,,,,,,,,,,,,,,,,,
77.704,4.00452,4.31805,3.5,,,,,,,,,,,,,,,,,,,,,,,,,,,,,,,,,,,,,
78.404,3.88784,3.19338,3.5,,,,,,,,,,,,,,,,,,,,,,,,,,,,,,,,,,,,,
79.104,3.77111,2.32259,3.5,,,,,,,,,,,,,,,,,,,,,,,,,,,,,,,,,,,,,
79.804,3.65443,1.66036,3.5,,,,,,,,,,,,,,,,,,,,,,,,,,,,,,,,,,,,,
80.504,3.53781,1.25963,3.5,,,,,,,,,,,,,,,,,,,,,,,,,,,,,,,,,,,,,
81.01,3.45332,0.99384,4,,,,,,,,,,,,,,,,,,,,,,,,,,,,,,,,,,,,,
81.612,3.55396,1.37849,4,,,,,,,,,,,,,,,,,,,,,,,,,,,,,,,,,,,,,
82.312,3.67064,2.05998,4,,,,,,,,,,,,,,,,,,,,,,,,,,,,,,,,,,,,,
83.012,3.78737,2.81629,4,,,,,,,,,,,,,,,,,,,,,,,,,,,,,,,,,,,,,
83.712,3.90405,3.94175,4,,,,,,,,,,,,,,,,,,,,,,,,,,,,,,,,,,,,,
84.412,4.02061,5.53806,4,,,,,,,,,,,,,,,,,,,,,,,,,,,,,,,,,,,,,
85.112,4.13729,7.08578,4,,,,,,,,,,,,,,,,,,,,,,,,,,,,,,,,,,,,,
85.812,4.25397,8.95631,4,,,,,,,,,,,,,,,,,,,,,,,,,,,,,,,,,,,,,
86.512,4.37076,11.68628,4,,,,,,,,,,,,,,,,,,,,,,,,,,,,,,,,,,,,,
87.212,4.48749,14.52711,4,,,,,,,,,,,,,,,,,,,,,,,,,,,,,,,,,,,,,
87.912,4.60417,18.14946,4,,,,,,,,,,,,,,,,,,,,,,,,,,,,,,,,,,,,,
88.612,4.72079,22.28608,4,,,,,,,,,,,,,,,,,,,,,,,,,,,,,,,,,,,,,
89.312,4.83746,27.33819,4,,,,,,,,,,,,,,,,,,,,,,,,,,,,,,,,,,,,,
90.012,4.95414,32.09204,4,,,,,,,,,,,,,,,,,,,,,,,,,,,,,,,,,,,,,
90.712,5.07082,39.76658,4,,,,,,,,,,,,,,,,,,,,,,,,,,,,,,,,,,,,,
91.236,4.99103,33.51326,4.5,,,,,,,,,,,,,,,,,,,,,,,,,,,,,,,,,,,,,
91.936,4.87435,25.9788,4.5,,,,,,,,,,,,,,,,,,,,,,,,,,,,,,,,,,,,,
92.636,4.75762,20.67932,4.5,,,,,,,,,,,,,,,,,,,,,,,,,,,,,,,,,,,,,
93.336,4.64106,16.65161,4.5,,,,,,,,,,,,,,,,,,,,,,,,,,,,,,,,,,,,,
94.036,4.52444,13.21745,4.5,,,,,,,,,,,,,,,,,,,,,,,,,,,,,,,,,,,,,
94.736,4.40776,10.20361,4.5,,,,,,,,,,,,,,,,,,,,,,,,,,,,,,,,,,,,,
95.436,4.29108,8.20191,4.5,,,,,,,,,,,,,,,,,,,,,,,,,,,,,,,,,,,,,
96.136,4.17441,6.3913,4.5,,,,,,,,,,,,,,,,,,,,,,,,,,,,,,,,,,,,,
96.836,4.05779,4.89357,4.5,,,,,,,,,,,,,,,,,,,,,,,,,,,,,,,,,,,,,
97.536,3.94111,3.58727,4.5,,,,,,,,,,,,,,,,,,,,,,,,,,,,,,,,,,,,,
98.236,3.82449,2.65367,4.5,,,,,,,,,,,,,,,,,,,,,,,,,,,,,,,,,,,,,
98.936,3.70781,1.91295,4.5,,,,,,,,,,,,,,,,,,,,,,,,,,,,,,,,,,,,,
99.636,3.59108,1.3995,4.5,,,,,,,,,,,,,,,,,,,,,,,,,,,,,,,,,,,,,
100.336,3.4744,1.05865,4.5,,,,,,,,,,,,,,,,,,,,,,,,,,,,,,,,,,,,,
100.76,3.53815,1.27561,5,,,,,,,,,,,,,,,,,,,,,,,,,,,,,,,,,,,,,
101.46,3.65477,1.87546,5,,,,,,,,,,,,,,,,,,,,,,,,,,,,,,,,,,,,,
102.16,3.77134,2.57209,5,,,,,,,,,,,,,,,,,,,,,,,,,,,,,,,,,,,,,
102.86,3.88801,3.64928,5,,,,,,,,,,,,,,,,,,,,,,,,,,,,,,,,,,,,,
103.56,4.0048,5.19529,5,,,,,,,,,,,,,,,,,,,,,,,,,,,,,,,,,,,,,
104.26,4.12142,6.72184,5,,,,,,,,,,,,,,,,,,,,,,,,,,,,,,,,,,,,,
104.96,4.2381,8.55196,5,,,,,,,,,,,,,,,,,,,,,,,,,,,,,,,,,,,,,
105.66,4.35466,11.19434,5,,,,,,,,,,,,,,,,,,,,,,,,,,,,,,,,,,,,,
106.36,4.47128,13.89358,5,,,,,,,,,,,,,,,,,,,,,,,,,,,,,,,,,,,,,
107.06,4.58796,17.54686,5,,,,,,,,,,,,,,,,,,,,,,,,,,,,,,,,,,,,,
107.76,4.70469,21.55198,5,,,,,,,,,,,,,,,,,,,,,,,,,,,,,,,,,,,,,
108.46,4.82137,26.47762,5,,,,,,,,,,,,,,,,,,,,,,,,,,,,,,,,,,,,,
109.16,4.93805,32.55722,5,,,,,,,,,,,,,,,,,,,,,,,,,,,,,,,,,,,,,
109.86,5.05478,38.45514,5,,,,,,,,,,,,,,,,,,,,,,,,,,,,,,,,,,,,,
110.394,5.0103,34.86243,5.5,,,,,,,,,,,,,,,,,,,,,,,,,,,,,,,,,,,,,
111.094,4.89351,26.93356,5.5,,,,,,,,,,,,,,,,,,,,,,,,,,,,,,,,,,,,,
111.794,4.77677,21.32985,5.5,,,,,,,,,,,,,,,,,,,,,,,,,,,,,,,,,,,,,
112.494,4.6601,17.14418,5.5,,,,,,,,,,,,,,,,,,,,,,,,,,,,,,,,,,,,,
113.194,4.54336,13.6556,5.5,,,,,,,,,,,,,,,,,,,,,,,,,,,,,,,,,,,,,
113.894,4.42669,10.63088,5.5,,,,,,,,,,,,,,,,,,,,,,,,,,,,,,,,,,,,,
114.594,4.30995,8.47899,5.5,,,,,,,,,,,,,,,,,,,,,,,,,,,,,,,,,,,,,
115.294,4.19328,6.67,5.5,,,,,,,,,,,,,,,,,,,,,,,,,,,,,,,,,,,,,
115.994,4.0766,5.06279,5.5,,,,,,,,,,,,,,,,,,,,,,,,,,,,,,,,,,,,,
116.694,3.96004,3.72618,5.5,,,,,,,,,,,,,,,,,,,,,,,,,,,,,,,,,,,,,
117.394,3.84336,2.71281,5.5,,,,,,,,,,,,,,,,,,,,,,,,,,,,,,,,,,,,,
118.094,3.7268,1.96563,5.5,,,,,,,,,,,,,,,,,,,,,,,,,,,,,,,,,,,,,
118.794,3.61006,1.46288,5.5,,,,,,,,,,,,,,,,,,,,,,,,,,,,,,,,,,,,,
119.494,3.49356,1.13992,5.5,,,,,,,,,,,,,,,,,,,,,,,,,,,,,,,,,,,,,
119.952,3.51798,1.23932,6,,,,,,,,,,,,,,,,,,,,,,,,,,,,,,,,,,,,,
120.652,3.63477,1.7686,6,,,,,,,,,,,,,,,,,,,,,,,,,,,,,,,,,,,,,
121.352,3.75139,2.4523,6,,,,,,,,,,,,,,,,,,,,,,,,,,,,,,,,,,,,,
122.052,3.86812,3.41243,6,,,,,,,,,,,,,,,,,,,,,,,,,,,,,,,,,,,,,
122.752,3.9848,4.87051,6,,,,,,,,,,,,,,,,,,,,,,,,,,,,,,,,,,,,,
123.452,4.10159,6.44715,6,,,,,,,,,,,,,,,,,,,,,,,,,,,,,,,,,,,,,
124.152,4.21821,8.12242,6,,,,,,,,,,,,,,,,,,,,,,,,,,,,,,,,,,,,,
124.852,4.33483,10.5954,6,,,,,,,,,,,,,,,,,,,,,,,,,,,,,,,,,,,,,
125.552,4.45139,13.44583,6,,,,,,,,,,,,,,,,,,,,,,,,,,,,,,,,,,,,,
126.252,4.56801,16.8065,6,,,,,,,,,,,,,,,,,,,,,,,,,,,,,,,,,,,,,
126.952,4.68469,20.70923,6,,,,,,,,,,,,,,,,,,,,,,,,,,,,,,,,,,,,,
127.652,4.80148,25.45164,6,,,,,,,,,,,,,,,,,,,,,,,,,,,,,,,,,,,,,
128.352,4.9181,31.43718,6,,,,,,,,,,,,,,,,,,,,,,,,,,,,,,,,,,,,,
129.052,5.03466,37.00605,6,,,,,,,,,,,,,,,,,,,,,,,,,,,,,,,,,,,,,
129.606,5.0269,36.17487,6.5,,,,,,,,,,,,,,,,,,,,,,,,,,,,,,,,,,,,,
130.306,4.91017,27.92804,6.5,,,,,,,,,,,,,,,,,,,,,,,,,,,,,,,,,,,,,
131.006,4.79349,22.01126,6.5,,,,,,,,,,,,,,,,,,,,,,,,,,,,,,,,,,,,,
131.706,4.67681,17.8342,6.5,,,,,,,,,,,,,,,,,,,,,,,,,,,,,,,,,,,,,
132.406,4.56014,14.24005,6.5,,,,,,,,,,,,,,,,,,,,,,,,,,,,,,,,,,,,,
133.106,4.4434,10.97149,6.5,,,,,,,,,,,,,,,,,,,,,,,,,,,,,,,,,,,,,
133.806,4.32684,8.71521,6.5,,,,,,,,,,,,,,,,,,,,,,,,,,,,,,,,,,,,,
134.506,4.21016,7.00112,6.5,,,,,,,,,,,,,,,,,,,,,,,,,,,,,,,,,,,,,
135.206,4.09349,5.27942,6.5,,,,,,,,,,,,,,,,,,,,,,,,,,,,,,,,,,,,,
135.906,3.97675,3.90119,6.5,,,,,,,,,,,,,,,,,,,,,,,,,,,,,,,,,,,,,
136.606,3.85996,2.90007,6.5,,,,,,,,,,,,,,,,,,,,,,,,,,,,,,,,,,,,,
137.306,3.74329,2.12076,6.5,,,,,,,,,,,,,,,,,,,,,,,,,,,,,,,,,,,,,
138.006,3.62667,1.59008,6.5,,,,,,,,,,,,,,,,,,,,,,,,,,,,,,,,,,,,,
138.706,3.5101,1.1547,6.5,,,,,,,,,,,,,,,,,,,,,,,,,,,,,,,,,,,,,
139.13,3.46823,1.04182,7,,,,,,,,,,,,,,,,,,,,,,,,,,,,,,,,,,,,,
139.83,3.59046,1.57923,7,,,,,,,,,,,,,,,,,,,,,,,,,,,,,,,,,,,,,
140.53,3.70708,2.17692,7,,,,,,,,,,,,,,,,,,,,,,,,,,,,,,,,,,,,,
141.23,3.82375,3.11431,7,,,,,,,,,,,,,,,,,,,,,,,,,,,,,,,,,,,,,
141.93,3.94037,4.38211,7,,,,,,,,,,,,,,,,,,,,,,,,,,,,,,,,,,,,,
142.63,4.05711,5.91237,7,,,,,,,,,,,,,,,,,,,,,,,,,,,,,,,,,,,,,
143.33,4.17378,7.40888,7,,,,,,,,,,,,,,,,,,,,,,,,,,,,,,,,,,,,,
144.03,4.29035,9.58764,7,,,,,,,,,,,,,,,,,,,,,,,,,,,,,,,,,,,,,
144.73,4.40702,12.42574,7,,,,,,,,,,,,,,,,,,,,,,,,,,,,,,,,,,,,,
145.43,4.5237,15.35368,7,,,,,,,,,,,,,,,,,,,,,,,,,,,,,,,,,,,,,
146.13,4.64038,19.09886,7,,,,,,,,,,,,,,,,,,,,,,,,,,,,,,,,,,,,,
146.83,4.757,23.45123,7,,,,,,,,,,,,,,,,,,,,,,,,,,,,,,,,,,,,,
147.53,4.87367,28.97808,7,,,,,,,,,,,,,,,,,,,,,,,,,,,,,,,,,,,,,
148.23,4.99035,34.28486,7,,,,,,,,,,,,,,,,,,,,,,,,,,,,,,,,,,,,,
148.76,5.07869,40.0463,7.5,,,,,,,,,,,,,,,,,,,,,,,,,,,,,,,,,,,,,
149.46,4.96179,31.20417,7.5,,,,,,,,,,,,,,,,,,,,,,,,,,,,,,,,,,,,,
150.16,4.84511,24.31895,7.5,,,,,,,,,,,,,,,,,,,,,,,,,,,,,,,,,,,,,
150.86,4.72849,19.52485,7.5,,,,,,,,,,,,,,,,,,,,,,,,,,,,,,,,,,,,,
151.56,4.61187,15.78492,7.5,,,,,,,,,,,,,,,,,,,,,,,,,,,,,,,,,,,,,
152.26,4.49514,12.25235,7.5,,,,,,,,,,,,,,,,,,,,,,,,,,,,,,,,,,,,,
152.96,4.37841,9.49627,7.5,,,,,,,,,,,,,,,,,,,,,,,,,,,,,,,,,,,,,
153.66,4.26173,7.86445,7.5,,,,,,,,,,,,,,,,,,,,,,,,,,,,,,,,,,,,,
154.36,4.14505,5.87353,7.5,,,,,,,,,,,,,,,,,,,,,,,,,,,,,,,,,,,,,
155.06,4.02838,4.52449,7.5,,,,,,,,,,,,,,,,,,,,,,,,,,,,,,,,,,,,,
155.76,3.91176,3.36584,7.5,,,,,,,,,,,,,,,,,,,,,,,,,,,,,,,,,,,,,
156.46,3.79497,2.35919,7.5,,,,,,,,,,,,,,,,,,,,,,,,,,,,,,,,,,,,,
157.16,3.67829,1.76922,7.5,,,,,,,,,,,,,,,,,,,,,,,,,,,,,,,,,,,,,
157.86,3.56173,1.29334,7.5,,,,,,,,,,,,,,,,,,,,,,,,,,,,,,,,,,,,,
158.504,3.4544,0.99945,8,,,,,,,,,,,,,,,,,,,,,,,,,,,,,,,,,,,,,
159.008,3.53815,1.30204,8,,,,,,,,,,,,,,,,,,,,,,,,,,,,,,,,,,,,,
159.708,3.65477,1.92929,8,,,,,,,,,,,,,,,,,,,,,,,,,,,,,,,,,,,,,
160.408,3.77134,2.67628,8,,,,,,,,,,,,,,,,,,,,,,,,,,,,,,,,,,,,,
161.108,3.88801,3.73251,8,,,,,,,,,,,,,,,,,,,,,,,,,,,,,,,,,,,,,
161.808,4.00475,5.28437,8,,,,,,,,,,,,,,,,,,,,,,,,,,,,,,,,,,,,,
162.508,4.12148,6.72878,8,,,,,,,,,,,,,,,,,,,,,,,,,,,,,,,,,,,,,
163.208,4.23804,8.4275,8,,,,,,,,,,,,,,,,,,,,,,,,,,,,,,,,,,,,,
163.908,4.35466,11.02912,8,,,,,,,,,,,,,,,,,,,,,,,,,,,,,,,,,,,,,
164.608,4.47128,13.76494,8,,,,,,,,,,,,,,,,,,,,,,,,,,,,,,,,,,,,,
165.308,4.58796,17.30309,8,,,,,,,,,,,,,,,,,,,,,,,,,,,,,,,,,,,,,
166.008,4.70469,21.2743,8,,,,,,,,,,,,,,,,,,,,,,,,,,,,,,,,,,,,,
166.708,4.82143,26.3209,8,,,,,,,,,,,,,,,,,,,,,,,,,,,,,,,,,,,,,
167.408,4.93799,31.78549,8,,,,,,,,,,,,,,,,,,,,,,,,,,,,,,,,,,,,,
168.108,5.05478,38.34685,8,,,,,,,,,,,,,,,,,,,,,,,,,,,,,,,,,,,,,
168.648,5.01132,34.80831,8.5,,,,,,,,,,,,,,,,,,,,,,,,,,,,,,,,,,,,,
169.348,4.89447,27.00827,8.5,,,,,,,,,,,,,,,,,,,,,,,,,,,,,,,,,,,,,
170.048,4.77779,21.33978,8.5,,,,,,,,,,,,,,,,,,,,,,,,,,,,,,,,,,,,,
170.748,4.66117,17.2084,8.5,,,,,,,,,,,,,,,,,,,,,,,,,,,,,,,,,,,,,
171.448,4.54444,13.71292,8.5,,,,,,,,,,,,,,,,,,,,,,,,,,,,,,,,,,,,,
172.148,4.42771,10.57084,8.5,,,,,,,,,,,,,,,,,,,,,,,,,,,,,,,,,,,,,
172.848,4.31097,8.42185,8.5,,,,,,,,,,,,,,,,,,,,,,,,,,,,,,,,,,,,,
173.548,4.1943,6.74696,8.5,,,,,,,,,,,,,,,,,,,,,,,,,,,,,,,,,,,,,
174.248,4.07762,5.16628,8.5,,,,,,,,,,,,,,,,,,,,,,,,,,,,,,,,,,,,,
174.948,3.961,3.78417,8.5,,,,,,,,,,,,,,,,,,,,,,,,,,,,,,,,,,,,,
175.648,3.84432,2.74093,8.5,,,,,,,,,,,,,,,,,,,,,,,,,,,,,,,,,,,,,
176.348,3.72782,1.97363,8.5,,,,,,,,,,,,,,,,,,,,,,,,,,,,,,,,,,,,,
177.048,3.61108,1.51127,8.5,,,,,,,,,,,,,,,,,,,,,,,,,,,,,,,,,,,,,
177.748,3.49452,1.1554,8.5,,,,,,,,,,,,,,,,,,,,,,,,,,,,,,,,,,,,,
178.202,3.48608,1.06794,9,,,,,,,,,,,,,,,,,,,,,,,,,,,,,,,,,,,,,
178.902,3.60309,1.62401,9,,,,,,,,,,,,,,,,,,,,,,,,,,,,,,,,,,,,,
179.602,3.71966,2.29691,9,,,,,,,,,,,,,,,,,,,,,,,,,,,,,,,,,,,,,
180.302,3.83633,3.21538,9,,,,,,,,,,,,,,,,,,,,,,,,,,,,,,,,,,,,,
181.002,3.95301,4.6629,9,,,,,,,,,,,,,,,,,,,,,,,,,,,,,,,,,,,,,
181.702,4.06969,6.11467,9,,,,,,,,,,,,,,,,,,,,,,,,,,,,,,,,,,,,,
182.402,4.18642,7.59106,9,,,,,,,,,,,,,,,,,,,,,,,,,,,,,,,,,,,,,
183.102,4.30304,9.88523,9,,,,,,,,,,,,,,,,,,,,,,,,,,,,,,,,,,,,,
183.802,4.41966,12.68036,9,,,,,,,,,,,,,,,,,,,,,,,,,,,,,,,,,,,,,
184.502,4.53628,15.57287,9,,,,,,,,,,,,,,,,,,,,,,,,,,,,,,,,,,,,,
185.202,4.65301,19.49045,9,,,,,,,,,,,,,,,,,,,,,,,,,,,,,,,,,,,,,
185.902,4.76975,23.94616,9,,,,,,,,,,,,,,,,,,,,,,,,,,,,,,,,,,,,,
186.602,4.88648,29.52015,9,,,,,,,,,,,,,,,,,,,,,,,,,,,,,,,,,,,,,
187.302,5.0031,35.1661,9,,,,,,,,,,,,,,,,,,,,,,,,,,,,,,,,,,,,,
187.846,5.06475,39.7135,9.5,,,,,,,,,,,,,,,,,,,,,,,,,,,,,,,,,,,,,
188.546,4.94349,30.03397,9.5,,,,,,,,,,,,,,,,,,,,,,,,,,,,,,,,,,,,,
189.246,4.82681,23.51975,9.5,,,,,,,,,,,,,,,,,,,,,,,,,,,,,,,,,,,,,
189.946,4.71002,18.85417,9.5,,,,,,,,,,,,,,,,,,,,,,,,,,,,,,,,,,,,,
190.646,4.59334,15.23049,9.5,,,,,,,,,,,,,,,,,,,,,,,,,,,,,,,,,,,,,
191.346,4.47661,11.76068,9.5,,,,,,,,,,,,,,,,,,,,,,,,,,,,,,,,,,,,,
192.046,4.35999,9.17579,9.5,,,,,,,,,,,,,,,,,,,,,,,,,,,,,,,,,,,,,
192.746,4.24337,7.51372,9.5,,,,,,,,,,,,,,,,,,,,,,,,,,,,,,,,,,,,,
193.446,4.12675,5.67062,9.5,,,,,,,,,,,,,,,,,,,,,,,,,,,,,,,,,,,,,
194.146,4.01013,4.32569,9.5,,,,,,,,,,,,,,,,,,,,,,,,,,,,,,,,,,,,,
194.846,3.89357,3.20345,9.5,,,,,,,,,,,,,,,,,,,,,,,,,,,,,,,,,,,,,
195.546,3.77683,2.25759,9.5,,,,,,,,,,,,,,,,,,,,,,,,,,,,,,,,,,,,,
196.246,3.66016,1.67713,9.5,,,,,,,,,,,,,,,,,,,,,,,,,,,,,,,,,,,,,
196.946,3.54348,1.31513,9.5,,,,,,,,,,,,,,,,,,,,,,,,,,,,,,,,,,,,,
197.476,3.45514,0.99539,10,,,,,,,,,,,,,,,,,,,,,,,,,,,,,,,,,,,,,
198.176,3.37036,0.79661,10,,,,,,,,,,,,,,,,,,,,,,,,,,,,,,,,,,,,,
198.876,3.36045,0.75787,10,,,,,,,,,,,,,,,,,,,,,,,,,,,,,,,,,,,,,
199.576,3.36101,0.79679,10,,,,,,,,,,,,,,,,,,,,,,,,,,,,,,,,,,,,,
200.276,3.36322,0.81547,10,,,,,,,,,,,,,,,,,,,,,,,,,,,,,,,,,,,,,
200.976,3.39445,0.89562,10,,,,,,,,,,,,,,,,,,,,,,,,,,,,,,,,,,,,,
201.676,3.47316,1.12487,10,,,,,,,,,,,,,,,,,,,,,,,,,,,,,,,,,,,,,
202.376,3.5054,1.32119,10,,,,,,,,,,,,,,,,,,,,,,,,,,,,,,,,,,,,,
203.076,3.50512,1.27948,10,,,,,,,,,,,,,,,,,,,,,,,,,,,,,,,,,,,,,
203.776,3.5024,1.3105,10,,,,,,,,,,,,,,,,,,,,,,,,,,,,,,,,,,,,,
204.476,3.47367,1.17008,10,,,,,,,,,,,,,,,,,,,,,,,,,,,,,,,,,,,,,
205.176,3.41774,0.92386,10,,,,,,,,,,,,,,,,,,,,,,,,,,,,,,,,,,,,,
205.876,3.4034,0.98916,10,,,,,,,,,,,,,,,,,,,,,,,,,,,,,,,,,,,,,
206.576,3.40289,0.98297,10,,,,,,,,,,,,,,,,,,,,,,,,,,,,,,,,,,,,,
207.276,3.40312,0.89777,10,,,,,,,,,,,,,,,,,,,,,,,,,,,,,,,,,,,,,
207.976,3.4034,0.96085,10,,,,,,,,,,,,,,,,,,,,,,,,,,,,,,,,,,,,,
208.676,3.40391,0.92035,10,,,,,,,,,,,,,,,,,,,,,,,,,,,,,,,,,,,,,
209.376,3.4064,0.93135,10,,,,,,,,,,,,,,,,,,,,,,,,,,,,,,,,,,,,,
210.076,3.41598,0.97467,10,,,,,,,,,,,,,,,,,,,,,,,,,,,,,,,,,,,,,
210.776,3.44981,1.11405,10,,,,,,,,,,,,,,,,,,,,,,,,,,,,,,,,,,,,,
211.476,3.46069,1.18246,10,,,,,,,,,,,,,,,,,,,,,,,,,,,,,,,,,,,,,
212.176,3.46086,1.15151,10,,,,,,,,,,,,,,,,,,,,,,,,,,,,,,,,,,,,,
212.876,3.46069,1.12318,10,,,,,,,,,,,,,,,,,,,,,,,,,,,,,,,,,,,,,
213.576,3.46041,1.13703,10,,,,,,,,,,,,,,,,,,,,,,,,,,,,,,,,,,,,,
214.276,3.4591,1.13835,10,,,,,,,,,,,,,,,,,,,,,,,,,,,,,,,,,,,,,
214.976,3.45219,1.13277,10,,,,,,,,,,,,,,,,,,,,,,,,,,,,,,,,,,,,,
215.676,3.43315,1.05131,10,,,,,,,,,,,,,,,,,,,,,,,,,,,,,,,,,,,,,
216.376,3.42034,1.04259,10,,,,,,,,,,,,,,,,,,,,,,,,,,,,,,,,,,,,,
217.076,3.41711,1.02714,10,,,,,,,,,,,,,,,,,,,,,,,,,,,,,,,,,,,,,
217.776,3.41655,1.02583,10,,,,,,,,,,,,,,,,,,,,,,,,,,,,,,,,,,,,,
218.476,3.41638,1.01767,10,,,,,,,,,,,,,,,,,,,,,,,,,,,,,,,,,,,,,
219.176,3.41643,1.01784,10,,,,,,,,,,,,,,,,,,,,,,,,,,,,,,,,,,,,,
219.876,3.41649,1.02433,10,,,,,,,,,,,,,,,,,,,,,,,,,,,,,,,,,,,,,
220.576,3.41649,1.04832,10,,,,,,,,,,,,,,,,,,,,,,,,,,,,,,,,,,,,,
221.276,3.4166,0.9992,10,,,,,,,,,,,,,,,,,,,,,,,,,,,,,,,,,,,,,
221.976,3.4166,1.02578,10,,,,,,,,,,,,,,,,,,,,,,,,,,,,,,,,,,,,,
222.676,3.41666,1.01036,10,,,,,,,,,,,,,,,,,,,,,,,,,,,,,,,,,,,,,
223.376,3.41672,1.01462,10,,,,,,,,,,,,,,,,,,,,,,,,,,,,,,,,,,,,,
224.076,3.41683,1.03112,10,,,,,,,,,,,,,,,,,,,,,,,,,,,,,,,,,,,,,
224.776,3.417,0.97129,10,,,,,,,,,,,,,,,,,,,,,,,,,,,,,,,,,,,,,
225.476,3.41728,1.07077,10,,,,,,,,,,,,,,,,,,,,,,,,,,,,,,,,,,,,,
226.176,3.41768,0.98926,10,,,,,,,,,,,,,,,,,,,,,,,,,,,,,,,,,,,,,
226.876,3.41864,0.96763,10,,,,,,,,,,,,,,,,,,,,,,,,,,,,,,,,,,,,,
227.576,3.42051,1.02436,10,,,,,,,,,,,,,,,,,,,,,,,,,,,,,,,,,,,,,
228.276,3.4238,1.02477,10,,,,,,,,,,,,,,,,,,,,,,,,,,,,,,,,,,,,,
228.976,3.43258,1.11612,10,,,,,,,,,,,,,,,,,,,,,,,,,,,,,,,,,,,,,
229.676,3.44018,1.03936,10,,,,,,,,,,,,,,,,,,,,,,,,,,,,,,,,,,,,,
230.376,3.44148,1.11484,10,,,,,,,,,,,,,,,,,,,,,,,,,,,,,,,,,,,,,
231.076,3.44159,1.12889,10,,,,,,,,,,,,,,,,,,,,,,,,,,,,,,,,,,,,,
231.776,3.44137,1.13476,10,,,,,,,,,,,,,,,,,,,,,,,,,,,,,,,,,,,,,
232.476,3.44131,1.15189,10,,,,,,,,,,,,,,,,,,,,,,,,,,,,,,,,,,,,,
233.176,3.44114,1.11401,10,,,,,,,,,,,,,,,,,,,,,,,,,,,,,,,,,,,,,
233.876,3.44074,1.11483,10,,,,,,,,,,,,,,,,,,,,,,,,,,,,,,,,,,,,,
234.576,3.43876,1.14945,10,,,,,,,,,,,,,,,,,,,,,,,,,,,,,,,,,,,,,
235.276,3.43451,1.12947,10,,,,,,,,,,,,,,,,,,,,,,,,,,,,,,,,,,,,,
235.976,3.42301,1.06041,10,,,,,,,,,,,,,,,,,,,,,,,,,,,,,,,,,,,,,
236.676,3.41757,1.01455,10,,,,,,,,,,,,,,,,,,,,,,,,,,,,,,,,,,,,,
237.376,3.41558,1.06382,10,,,,,,,,,,,,,,,,,,,,,,,,,,,,,,,,,,,,,
238.076,3.41388,1.03695,10,,,,,,,,,,,,,,,,,,,,,,,,,,,,,,,,,,,,,
238.776,3.41298,1.06924,10,,,,,,,,,,,,,,,,,,,,,,,,,,,,,,,,,,,,,
239.476,3.41264,1.0726,10,,,,,,,,,,,,,,,,,,,,,,,,,,,,,,,,,,,,,
240.176,3.41213,1.03342,10,,,,,,,,,,,,,,,,,,,,,,,,,,,,,,,,,,,,,
240.876,3.41179,0.96734,10,,,,,,,,,,,,,,,,,,,,,,,,,,,,,,,,,,,,,
241.576,3.41133,1.0772,10,,,,,,,,,,,,,,,,,,,,,,,,,,,,,,,,,,,,,
242.276,3.41094,1.06132,10,,,,,,,,,,,,,,,,,,,,,,,,,,,,,,,,,,,,,
242.976,3.4106,1.08438,10,,,,,,,,,,,,,,,,,,,,,,,,,,,,,,,,,,,,,
243.676,3.41031,1.05298,10,,,,,,,,,,,,,,,,,,,,,,,,,,,,,,,,,,,,,
244.376,3.40997,1.03229,10,,,,,,,,,,,,,,,,,,,,,,,,,,,,,,,,,,,,,
245.076,3.40975,1.04792,10,,,,,,,,,,,,,,,,,,,,,,,,,,,,,,,,,,,,,
245.776,3.40946,1.0553,10,,,,,,,,,,,,,,,,,,,,,,,,,,,,,,,,,,,,,
246.476,3.40924,1.02235,10,,,,,,,,,,,,,,,,,,,,,,,,,,,,,,,,,,,,,
247.176,3.40895,1.0657,10,,,,,,,,,,,,,,,,,,,,,,,,,,,,,,,,,,,,,
247.876,3.4089,1.0014,10,,,,,,,,,,,,,,,,,,,,,,,,,,,,,,,,,,,,,
248.576,3.40873,1.00279,10,,,,,,,,,,,,,,,,,,,,,,,,,,,,,,,,,,,,,
249.276,3.40867,0.9962,10,,,,,,,,,,,,,,,,,,,,,,,,,,,,,,,,,,,,,
249.976,3.40873,1.00275,10,,,,,,,,,,,,,,,,,,,,,,,,,,,,,,,,,,,,,
250.676,3.40873,1.02094,10,,,,,,,,,,,,,,,,,,,,,,,,,,,,,,,,,,,,,
251.376,3.40873,1.04196,10,,,,,,,,,,,,,,,,,,,,,,,,,,,,,,,,,,,,,
252.076,3.40867,1.12178,10,,,,,,,,,,,,,,,,,,,,,,,,,,,,,,,,,,,,,
252.776,3.40878,1.03753,10,,,,,,,,,,,,,,,,,,,,,,,,,,,,,,,,,,,,,
253.476,3.40878,0.98903,10,,,,,,,,,,,,,,,,,,,,,,,,,,,,,,,,,,,,,
254.176,3.40878,1.02541,10,,,,,,,,,,,,,,,,,,,,,,,,,,,,,,,,,,,,,
254.876,3.40878,1.08359,10,,,,,,,,,,,,,,,,,,,,,,,,,,,,,,,,,,,,,
255.576,3.40878,1.0624,10,,,,,,,,,,,,,,,,,,,,,,,,,,,,,,,,,,,,,
256.276,3.40878,1.01495,10,,,,,,,,,,,,,,,,,,,,,,,,,,,,,,,,,,,,,
256.976,3.40878,1.04128,10,,,,,,,,,,,,,,,,,,,,,,,,,,,,,,,,,,,,,
257.676,3.40878,1.04612,10,,,,,,,,,,,,,,,,,,,,,,,,,,,,,,,,,,,,,
258.376,3.40884,0.99584,10,,,,,,,,,,,,,,,,,,,,,,,,,,,,,,,,,,,,,
259.076,3.4089,0.99458,10,,,,,,,,,,,,,,,,,,,,,,,,,,,,,,,,,,,,,
259.776,3.40895,1.02552,10,,,,,,,,,,,,,,,,,,,,,,,,,,,,,,,,,,,,,
260.476,3.40901,0.99115,10,,,,,,,,,,,,,,,,,,,,,,,,,,,,,,,,,,,,,
261.176,3.40907,1.03646,10,,,,,,,,,,,,,,,,,,,,,,,,,,,,,,,,,,,,,
261.876,3.40918,1.00187,10,,,,,,,,,,,,,,,,,,,,,,,,,,,,,,,,,,,,,
262.576,3.40929,1.07213,10,,,,,,,,,,,,,,,,,,,,,,,,,,,,,,,,,,,,,
263.276,3.40946,1.05521,10,,,,,,,,,,,,,,,,,,,,,,,,,,,,,,,,,,,,,
263.976,3.40969,1.04327,10,,,,,,,,,,,,,,,,,,,,,,,,,,,,,,,,,,,,,
264.676,3.41003,1.00283,10,,,,,,,,,,,,,,,,,,,,,,,,,,,,,,,,,,,,,
265.376,3.41037,0.9963,10,,,,,,,,,,,,,,,,,,,,,,,,,,,,,,,,,,,,,
266.076,3.41105,1.02631,10,,,,,,,,,,,,,,,,,,,,,,,,,,,,,,,,,,,,,
266.776,3.41298,1.0565,10,,,,,,,,,,,,,,,,,,,,,,,,,,,,,,,,,,,,,
267.476,3.41955,1.02678,10,,,,,,,,,,,,,,,,,,,,,,,,,,,,,,,,,,,,,
268.176,3.42884,1.09011,10,,,,,,,,,,,,,,,,,,,,,,,,,,,,,,,,,,,,,
268.876,3.434,1.04986,10,,,,,,,,,,,,,,,,,,,,,,,,,,,,,,,,,,,,,
269.576,3.43451,1.22343,10,,,,,,,,,,,,,,,,,,,,,,,,,,,,,,,,,,,,,
270.276,3.43451,1.13063,10,,,,,,,,,,,,,,,,,,,,,,,,,,,,,,,,,,,,,
270.976,3.43434,1.09578,10,,,,,,,,,,,,,,,,,,,,,,,,,,,,,,,,,,,,,
271.676,3.43417,1.09336,10,,,,,,,,,,,,,,,,,,,,,,,,,,,,,,,,,,,,,
272.376,3.43372,1.16596,10,,,,,,,,,,,,,,,,,,,,,,,,,,,,,,,,,,,,,
273.076,3.43173,1.129,10,,,,,,,,,,,,,,,,,,,,,,,,,,,,,,,,,,,,,
273.776,3.4255,1.1001,10,,,,,,,,,,,,,,,,,,,,,,,,,,,,,,,,,,,,,
274.476,3.41587,1.0826,10,,,,,,,,,,,,,,,,,,,,,,,,,,,,,,,,,,,,,
275.176,3.41122,1.08921,10,,,,,,,,,,,,,,,,,,,,,,,,,,,,,,,,,,,,,
275.876,3.40833,1.02617,10,,,,,,,,,,,,,,,,,,,,,,,,,,,,,,,,,,,,,
276.576,3.40748,1.08329,10,,,,,,,,,,,,,,,,,,,,,,,,,,,,,,,,,,,,,
277.276,3.4072,1.02057,10,,,,,,,,,,,,,,,,,,,,,,,,,,,,,,,,,,,,,
277.976,3.40703,1.05903,10,,,,,,,,,,,,,,,,,,,,,,,,,,,,,,,,,,,,,
278.676,3.40691,1.0149,10,,,,,,,,,,,,,,,,,,,,,,,,,,,,,,,,,,,,,
279.376,3.40697,1.07474,10,,,,,,,,,,,,,,,,,,,,,,,,,,,,,,,,,,,,,
280.076,3.40697,1.02802,10,,,,,,,,,,,,,,,,,,,,,,,,,,,,,,,,,,,,,
280.776,3.40697,1.04312,10,,,,,,,,,,,,,,,,,,,,,,,,,,,,,,,,,,,,,
281.476,3.40697,1.05288,10,,,,,,,,,,,,,,,,,,,,,,,,,,,,,,,,,,,,,
282.176,3.40697,1.04532,10,,,,,,,,,,,,,,,,,,,,,,,,,,,,,,,,,,,,,
282.876,3.40697,1.05972,10,,,,,,,,,,,,,,,,,,,,,,,,,,,,,,,,,,,,,
283.576,3.40697,1.11547,10,,,,,,,,,,,,,,,,,,,,,,,,,,,,,,,,,,,,,
284.276,3.40697,1.03996,10,,,,,,,,,,,,,,,,,,,,,,,,,,,,,,,,,,,,,
284.976,3.40703,1.01504,10,,,,,,,,,,,,,,,,,,,,,,,,,,,,,,,,,,,,,
285.676,3.40703,1.0156,10,,,,,,,,,,,,,,,,,,,,,,,,,,,,,,,,,,,,,
286.376,3.40708,1.03245,10,,,,,,,,,,,,,,,,,,,,,,,,,,,,,,,,,,,,,
287.076,3.40714,1.01891,10,,,,,,,,,,,,,,,,,,,,,,,,,,,,,,,,,,,,,
287.776,3.40714,1.08508,10,,,,,,,,,,,,,,,,,,,,,,,,,,,,,,,,,,,,,
288.476,3.4072,1.09766,10,,,,,,,,,,,,,,,,,,,,,,,,,,,,,,,,,,,,,
289.176,3.40714,1.01656,10,,,,,,,,,,,,,,,,,,,,,,,,,,,,,,,,,,,,,
289.876,3.40731,0.97918,10,,,,,,,,,,,,,,,,,,,,,,,,,,,,,,,,,,,,,
290.576,3.40742,1.0433,10,,,,,,,,,,,,,,,,,,,,,,,,,,,,,,,,,,,,,
291.276,3.40754,0.99268,10,,,,,,,,,,,,,,,,,,,,,,,,,,,,,,,,,,,,,
291.976,3.40776,1.03646,10,,,,,,,,,,,,,,,,,,,,,,,,,,,,,,,,,,,,,
292.676,3.40793,1.06229,10,,,,,,,,,,,,,,,,,,,,,,,,,,,,,,,,,,,,,
293.376,3.40816,1.01707,10,,,,,,,,,,,,,,,,,,,,,,,,,,,,,,,,,,,,,
294.076,3.4085,0.99677,10,,,,,,,,,,,,,,,,,,,,,,,,,,,,,,,,,,,,,
294.776,3.40918,1.03796,10,,,,,,,,,,,,,,,,,,,,,,,,,,,,,,,,,,,,,
295.476,3.41065,1.04278,10,,,,,,,,,,,,,,,,,,,,,,,,,,,,,,,,,,,,,
296.176,3.41247,1.02598,10,,,,,,,,,,,,,,,,,,,,,,,,,,,,,,,,,,,,,
296.876,3.41519,1.02501,10,,,,,,,,,,,,,,,,,,,,,,,,,,,,,,,,,,,,,
297.576,3.41972,1.0381,10,,,,,,,,,,,,,,,,,,,,,,,,,,,,,,,,,,,,,
298.276,3.42737,1.04368,10,,,,,,,,,,,,,,,,,,,,,,,,,,,,,,,,,,,,,
298.976,3.43241,1.16282,10,,,,,,,,,,,,,,,,,,,,,,,,,,,,,,,,,,,,,
299.676,3.43258,1.1326,10,,,,,,,,,,,,,,,,,,,,,,,,,,,,,,,,,,,,,
300.376,3.43241,1.13566,10,,,,,,,,,,,,,,,,,,,,,,,,,,,,,,,,,,,,,
301.076,3.43224,1.12427,10,,,,,,,,,,,,,,,,,,,,,,,,,,,,,,,,,,,,,
301.776,3.43179,1.16023,10,,,,,,,,,,,,,,,,,,,,,,,,,,,,,,,,,,,,,
302.476,3.42975,1.09552,10,,,,,,,,,,,,,,,,,,,,,,,,,,,,,,,,,,,,,
303.176,3.42403,1.11522,10,,,,,,,,,,,,,,,,,,,,,,,,,,,,,,,,,,,,,
303.876,3.41094,1.03274,10,,,,,,,,,,,,,,,,,,,,,,,,,,,,,,,,,,,,,
304.576,3.40691,1.08663,10,,,,,,,,,,,,,,,,,,,,,,,,,,,,,,,,,,,,,
305.276,3.40516,1.04845,10,,,,,,,,,,,,,,,,,,,,,,,,,,,,,,,,,,,,,
305.976,3.40414,1.06384,10,,,,,,,,,,,,,,,,,,,,,,,,,,,,,,,,,,,,,
306.676,3.40334,1.03139,10,,,,,,,,,,,,,,,,,,,,,,,,,,,,,,,,,,,,,
307.376,3.40295,1.02294,10,,,,,,,,,,,,,,,,,,,,,,,,,,,,,,,,,,,,,
308.076,3.40278,1.01802,10,,,,,,,,,,,,,,,,,,,,,,,,,,,,,,,,,,,,,
308.776,3.40283,1.03136,10,,,,,,,,,,,,,,,,,,,,,,,,,,,,,,,,,,,,,
309.476,3.40283,1.01524,10,,,,,,,,,,,,,,,,,,,,,,,,,,,,,,,,,,,,,
310.176,3.40289,1.00004,10,,,,,,,,,,,,,,,,,,,,,,,,,,,,,,,,,,,,,
310.876,3.40295,1.03755,10,,,,,,,,,,,,,,,,,,,,,,,,,,,,,,,,,,,,,
311.576,3.40295,1.03456,10,,,,,,,,,,,,,,,,,,,,,,,,,,,,,,,,,,,,,
312.276,3.40306,0.99019,10,,,,,,,,,,,,,,,,,,,,,,,,,,,,,,,,,,,,,
312.976,3.40312,1.03618,10,,,,,,,,,,,,,,,,,,,,,,,,,,,,,,,,,,,,,
313.676,3.40317,0.97059,10,,,,,,,,,,,,,,,,,,,,,,,,,,,,,,,,,,,,,
314.376,3.40346,1.03296,10,,,,,,,,,,,,,,,,,,,,,,,,,,,,,,,,,,,,,
315.076,3.40363,1.00747,10,,,,,,,,,,,,,,,,,,,,,,,,,,,,,,,,,,,,,
315.776,3.40385,1.01291,10,,,,,,,,,,,,,,,,,,,,,,,,,,,,,,,,,,,,,
316.476,3.40425,0.99361,10,,,,,,,,,,,,,,,,,,,,,,,,,,,,,,,,,,,,,
317.176,3.40487,1.00548,10,,,,,,,,,,,,,,,,,,,,,,,,,,,,,,,,,,,,,
317.876,3.4064,1.00929,10,,,,,,,,,,,,,,,,,,,,,,,,,,,,,,,,,,,,,
318.576,3.40873,1.04617,10,,,,,,,,,,,,,,,,,,,,,,,,,,,,,,,,,,,,,
319.276,3.41201,1.00134,10,,,,,,,,,,,,,,,,,,,,,,,,,,,,,,,,,,,,,
319.976,3.4157,1.08236,10,,,,,,,,,,,,,,,,,,,,,,,,,,,,,,,,,,,,,
320.676,3.41881,1.08611,10,,,,,,,,,,,,,,,,,,,,,,,,,,,,,,,,,,,,,
321.376,3.42029,1.09829,10,,,,,,,,,,,,,,,,,,,,,,,,,,,,,,,,,,,,,
322.076,3.42068,1.04457,10,,,,,,,,,,,,,,,,,,,,,,,,,,,,,,,,,,,,,
322.776,3.42091,1.08346,10,,,,,,,,,,,,,,,,,,,,,,,,,,,,,,,,,,,,,
323.476,3.42102,1.0979,10,,,,,,,,,,,,,,,,,,,,,,,,,,,,,,,,,,,,,
324.176,3.42091,1.09486,10,,,,,,,,,,,,,,,,,,,,,,,,,,,,,,,,,,,,,
324.876,3.4208,1.10905,10,,,,,,,,,,,,,,,,,,,,,,,,,,,,,,,,,,,,,
325.576,3.4208,1.06531,10,,,,,,,,,,,,,,,,,,,,,,,,,,,,,,,,,,,,,
326.276,3.42068,1.11364,10,,,,,,,,,,,,,,,,,,,,,,,,,,,,,,,,,,,,,
326.976,3.42063,1.0783,10,,,,,,,,,,,,,,,,,,,,,,,,,,,,,,,,,,,,,
327.676,3.4204,1.20373,10,,,,,,,,,,,,,,,,,,,,,,,,,,,,,,,,,,,,,
328.376,3.41995,1.12278,10,,,,,,,,,,,,,,,,,,,,,,,,,,,,,,,,,,,,,
329.076,3.41876,1.12019,10,,,,,,,,,,,,,,,,,,,,,,,,,,,,,,,,,,,,,
329.776,3.41519,1.11344,10,,,,,,,,,,,,,,,,,,,,,,,,,,,,,,,,,,,,,
330.476,3.41009,1.07967,10,,,,,,,,,,,,,,,,,,,,,,,,,,,,,,,,,,,,,
331.176,3.4072,1.05957,10,,,,,,,,,,,,,,,,,,,,,,,,,,,,,,,,,,,,,
331.876,3.40612,1.06971,10,,,,,,,,,,,,,,,,,,,,,,,,,,,,,,,,,,,,,
332.576,3.40504,1.00052,10,,,,,,,,,,,,,,,,,,,,,,,,,,,,,,,,,,,,,
333.276,3.40385,1.06414,10,,,,,,,,,,,,,,,,,,,,,,,,,,,,,,,,,,,,,
333.976,3.40204,1.10543,10,,,,,,,,,,,,,,,,,,,,,,,,,,,,,,,,,,,,,
334.676,3.4,1.07787,10,,,,,,,,,,,,,,,,,,,,,,,,,,,,,,,,,,,,,
335.376,3.39881,1.05126,10,,,,,,,,,,,,,,,,,,,,,,,,,,,,,,,,,,,,,
336.076,3.39813,1.01726,10,,,,,,,,,,,,,,,,,,,,,,,,,,,,,,,,,,,,,
336.776,3.39779,1.02325,10,,,,,,,,,,,,,,,,,,,,,,,,,,,,,,,,,,,,,
337.476,3.39762,1.02229,10,,,,,,,,,,,,,,,,,,,,,,,,,,,,,,,,,,,,,
338.176,3.39762,1.03941,10,,,,,,,,,,,,,,,,,,,,,,,,,,,,,,,,,,,,,
338.876,3.39773,0.99119,10,,,,,,,,,,,,,,,,,,,,,,,,,,,,,,,,,,,,,
339.576,3.39779,1.01624,10,,,,,,,,,,,,,,,,,,,,,,,,,,,,,,,,,,,,,
340.276,3.39779,1.02577,10,,,,,,,,,,,,,,,,,,,,,,,,,,,,,,,,,,,,,
340.976,3.3979,1.03208,10,,,,,,,,,,,,,,,,,,,,,,,,,,,,,,,,,,,,,
341.676,3.39796,1.0268,10,,,,,,,,,,,,,,,,,,,,,,,,,,,,,,,,,,,,,
342.376,3.39802,1.04024,10,,,,,,,,,,,,,,,,,,,,,,,,,,,,,,,,,,,,,
343.076,3.39813,1.01068,10,,,,,,,,,,,,,,,,,,,,,,,,,,,,,,,,,,,,,
343.776,3.3983,0.98352,10,,,,,,,,,,,,,,,,,,,,,,,,,,,,,,,,,,,,,
344.476,3.39858,0.99945,10,,,,,,,,,,,,,,,,,,,,,,,,,,,,,,,,,,,,,
345.176,3.39898,1.02979,10,,,,,,,,,,,,,,,,,,,,,,,,,,,,,,,,,,,,,
345.876,3.39972,1.0612,10,,,,,,,,,,,,,,,,,,,,,,,,,,,,,,,,,,,,,
346.576,3.40125,1.01939,10,,,,,,,,,,,,,,,,,,,,,,,,,,,,,,,,,,,,,
347.276,3.40499,1.02908,10,,,,,,,,,,,,,,,,,,,,,,,,,,,,,,,,,,,,,
347.976,3.41082,1.08654,10,,,,,,,,,,,,,,,,,,,,,,,,,,,,,,,,,,,,,
348.676,3.41428,1.01883,10,,,,,,,,,,,,,,,,,,,,,,,,,,,,,,,,,,,,,
349.376,3.41796,1.03274,10,,,,,,,,,,,,,,,,,,,,,,,,,,,,,,,,,,,,,
350.076,3.41978,1.03367,10,,,,,,,,,,,,,,,,,,,,,,,,,,,,,,,,,,,,,
350.776,3.41995,1.13155,10,,,,,,,,,,,,,,,,,,,,,,,,,,,,,,,,,,,,,
351.476,3.41983,1.07365,10,,,,,,,,,,,,,,,,,,,,,,,,,,,,,,,,,,,,,
352.176,3.41972,1.08856,10,,,,,,,,,,,,,,,,,,,,,,,,,,,,,,,,,,,,,
352.876,3.41966,1.07295,10,,,,,,,,,,,,,,,,,,,,,,,,,,,,,,,,,,,,,
353.576,3.41955,1.12791,10,,,,,,,,,,,,,,,,,,,,,,,,,,,,,,,,,,,,,
354.276,3.41938,1.09548,10,,,,,,,,,,,,,,,,,,,,,,,,,,,,,,,,,,,,,
354.976,3.41859,1.11948,10,,,,,,,,,,,,,,,,,,,,,,,,,,,,,,,,,,,,,
355.676,3.41706,1.12793,10,,,,,,,,,,,,,,,,,,,,,,,,,,,,,,,,,,,,,
356.376,3.41371,1.11066,10,,,,,,,,,,,,,,,,,,,,,,,,,,,,,,,,,,,,,
357.076,3.4085,1.09291,10,,,,,,,,,,,,,,,,,,,,,,,,,,,,,,,,,,,,,
357.776,3.40612,1.08563,10,,,,,,,,,,,,,,,,,,,,,,,,,,,,,,,,,,,,,
358.476,3.40516,1.08156,10,,,,,,,,,,,,,,,,,,,,,,,,,,,,,,,,,,,,,
359.176,3.40414,1.08767,10,,,,,,,,,,,,,,,,,,,,,,,,,,,,,,,,,,,,,
359.876,3.40238,1.05661,10,,,,,,,,,,,,,,,,,,,,,,,,,,,,,,,,,,,,,
360.576,3.40085,1.02928,10,,,,,,,,,,,,,,,,,,,,,,,,,,,,,,,,,,,,,
361.276,3.40006,1.06716,10,,,,,,,,,,,,,,,,,,,,,,,,,,,,,,,,,,,,,
361.976,3.39972,1.10011,10,,,,,,,,,,,,,,,,,,,,,,,,,,,,,,,,,,,,,
362.676,3.39926,1.01107,10,,,,,,,,,,,,,,,,,,,,,,,,,,,,,,,,,,,,,
363.376,3.39892,1.05565,10,,,,,,,,,,,,,,,,,,,,,,,,,,,,,,,,,,,,,
364.076,3.39898,1.00575,10,,,,,,,,,,,,,,,,,,,,,,,,,,,,,,,,,,,,,
364.776,3.39904,1.0193,10,,,,,,,,,,,,,,,,,,,,,,,,,,,,,,,,,,,,,
365.476,3.39898,1.01793,10,,,,,,,,,,,,,,,,,,,,,,,,,,,,,,,,,,,,,
366.176,3.39909,1.02808,10,,,,,,,,,,,,,,,,,,,,,,,,,,,,,,,,,,,,,
366.876,3.39915,1.01482,10,,,,,,,,,,,,,,,,,,,,,,,,,,,,,,,,,,,,,
367.576,3.39921,1.06385,10,,,,,,,,,,,,,,,,,,,,,,,,,,,,,,,,,,,,,
368.276,3.39932,1.00522,10,,,,,,,,,,,,,,,,,,,,,,,,,,,,,,,,,,,,,
368.976,3.39949,1.03003,10,,,,,,,,,,,,,,,,,,,,,,,,,,,,,,,,,,,,,
369.676,3.3996,0.9944,10,,,,,,,,,,,,,,,,,,,,,,,,,,,,,,,,,,,,,
370.376,3.39972,1.06756,10,,,,,,,,,,,,,,,,,,,,,,,,,,,,,,,,,,,,,
371.076,3.39972,1.04829,10,,,,,,,,,,,,,,,,,,,,,,,,,,,,,,,,,,,,,
371.776,3.39977,1.11176,10,,,,,,,,,,,,,,,,,,,,,,,,,,,,,,,,,,,,,
372.476,3.39977,1.09175,10,,,,,,,,,,,,,,,,,,,,,,,,,,,,,,,,,,,,,
373.176,3.39977,1.11655,10,,,,,,,,,,,,,,,,,,,,,,,,,,,,,,,,,,,,,
373.876,3.39966,1.02668,10,,,,,,,,,,,,,,,,,,,,,,,,,,,,,,,,,,,,,
374.576,3.39966,1.08802,10,,,,,,,,,,,,,,,,,,,,,,,,,,,,,,,,,,,,,
375.276,3.39977,1.02554,10,,,,,,,,,,,,,,,,,,,,,,,,,,,,,,,,,,,,,
375.976,3.39966,1.06817,10,,,,,,,,,,,,,,,,,,,,,,,,,,,,,,,,,,,,,
376.676,3.39966,1.05002,10,,,,,,,,,,,,,,,,,,,,,,,,,,,,,,,,,,,,,
377.376,3.39966,1.07569,10,,,,,,,,,,,,,,,,,,,,,,,,,,,,,,,,,,,,,
378.076,3.39966,1.0629,10,,,,,,,,,,,,,,,,,,,,,,,,,,,,,,,,,,,,,
378.776,3.39977,1.1023,10,,,,,,,,,,,,,,,,,,,,,,,,,,,,,,,,,,,,,
379.476,3.39966,1.03874,10,,,,,,,,,,,,,,,,,,,,,,,,,,,,,,,,,,,,,
380.176,3.39966,1.06969,10,,,,,,,,,,,,,,,,,,,,,,,,,,,,,,,,,,,,,
380.876,3.39977,1.03033,10,,,,,,,,,,,,,,,,,,,,,,,,,,,,,,,,,,,,,
381.576,3.39966,1.03383,10,,,,,,,,,,,,,,,,,,,,,,,,,,,,,,,,,,,,,
382.276,3.39977,1.00413,10,,,,,,,,,,,,,,,,,,,,,,,,,,,,,,,,,,,,,
382.976,3.39966,1.04406,10,,,,,,,,,,,,,,,,,,,,,,,,,,,,,,,,,,,,,
383.676,3.39966,1.04036,10,,,,,,,,,,,,,,,,,,,,,,,,,,,,,,,,,,,,,
384.376,3.39966,1.09721,10,,,,,,,,,,,,,,,,,,,,,,,,,,,,,,,,,,,,,
385.076,3.39966,1.07472,10,,,,,,,,,,,,,,,,,,,,,,,,,,,,,,,,,,,,,
385.776,3.39966,1.07031,10,,,,,,,,,,,,,,,,,,,,,,,,,,,,,,,,,,,,,
386.476,3.39966,1.06134,10,,,,,,,,,,,,,,,,,,,,,,,,,,,,,,,,,,,,,
387.176,3.39966,1.05631,10,,,,,,,,,,,,,,,,,,,,,,,,,,,,,,,,,,,,,
387.876,3.39966,1.01294,10,,,,,,,,,,,,,,,,,,,,,,,,,,,,,,,,,,,,,
388.576,3.39977,1.07411,10,,,,,,,,,,,,,,,,,,,,,,,,,,,,,,,,,,,,,
389.276,3.39966,1.05664,10,,,,,,,,,,,,,,,,,,,,,,,,,,,,,,,,,,,,,
389.976,3.39977,1.05919,10,,,,,,,,,,,,,,,,,,,,,,,,,,,,,,,,,,,,,
390.676,3.39966,1.07882,10,,,,,,,,,,,,,,,,,,,,,,,,,,,,,,,,,,,,,
391.376,3.39966,1.0756,10,,,,,,,,,,,,,,,,,,,,,,,,,,,,,,,,,,,,,
392.076,3.39977,1.06499,10,,,,,,,,,,,,,,,,,,,,,,,,,,,,,,,,,,,,,
392.776,3.39977,1.03113,10,,,,,,,,,,,,,,,,,,,,,,,,,,,,,,,,,,,,,
393.476,3.39966,1.03707,10,,,,,,,,,,,,,,,,,,,,,,,,,,,,,,,,,,,,,
394.176,3.39966,1.12505,10,,,,,,,,,,,,,,,,,,,,,,,,,,,,,,,,,,,,,
394.876,3.39966,1.0616,10,,,,,,,,,,,,,,,,,,,,,,,,,,,,,,,,,,,,,
395.576,3.39966,1.0354,10,,,,,,,,,,,,,,,,,,,,,,,,,,,,,,,,,,,,,
396.276,3.39977,1.01688,10,,,,,,,,,,,,,,,,,,,,,,,,,,,,,,,,,,,,,
396.976,3.39966,1.04523,10,,,,,,,,,,,,,,,,,,,,,,,,,,,,,,,,,,,,,
397.676,3.39977,1.03567,10,,,,,,,,,,,,,,,,,,,,,,,,,,,,,,,,,,,,,
398.376,3.39966,1.02098,10,,,,,,,,,,,,,,,,,,,,,,,,,,,,,,,,,,,,,
399.076,3.39977,1.07863,10,,,,,,,,,,,,,,,,,,,,,,,,,,,,,,,,,,,,,
399.776,3.39977,1.09174,10,,,,,,,,,,,,,,,,,,,,,,,,,,,,,,,,,,,,,
400.476,3.39966,1.10825,10,,,,,,,,,,,,,,,,,,,,,,,,,,,,,,,,,,,,,
401.176,3.39966,1.08814,10,,,,,,,,,,,,,,,,,,,,,,,,,,,,,,,,,,,,,
401.876,3.39966,1.04996,10,,,,,,,,,,,,,,,,,,,,,,,,,,,,,,,,,,,,,
402.576,3.39977,1.06994,10,,,,,,,,,,,,,,,,,,,,,,,,,,,,,,,,,,,,,
403.276,3.39966,1.03325,10,,,,,,,,,,,,,,,,,,,,,,,,,,,,,,,,,,,,,
403.976,3.39966,1.05939,10,,,,,,,,,,,,,,,,,,,,,,,,,,,,,,,,,,,,,
404.676,3.39966,1.05172,10,,,,,,,,,,,,,,,,,,,,,,,,,,,,,,,,,,,,,
405.376,3.39966,1.07052,10,,,,,,,,,,,,,,,,,,,,,,,,,,,,,,,,,,,,,
406.076,3.39966,1.06183,10,,,,,,,,,,,,,,,,,,,,,,,,,,,,,,,,,,,,,
406.776,3.39966,1.06964,10,,,,,,,,,,,,,,,,,,,,,,,,,,,,,,,,,,,,,
407.476,3.39966,1.04671,10,,,,,,,,,,,,,,,,,,,,,,,,,,,,,,,,,,,,,
408.176,3.39966,1.03852,10,,,,,,,,,,,,,,,,,,,,,,,,,,,,,,,,,,,,,
408.876,3.39966,1.03417,10,,,,,,,,,,,,,,,,,,,,,,,,,,,,,,,,,,,,,
409.576,3.39966,1.08437,10,,,,,,,,,,,,,,,,,,,,,,,,,,,,,,,,,,,,,
410.276,3.39972,1.07675,10,,,,,,,,,,,,,,,,,,,,,,,,,,,,,,,,,,,,,
410.976,3.39972,1.06071,10,,,,,,,,,,,,,,,,,,,,,,,,,,,,,,,,,,,,,
411.676,3.3996,1.07958,10,,,,,,,,,,,,,,,,,,,,,,,,,,,,,,,,,,,,,
412.376,3.39972,1.05863,10,,,,,,,,,,,,,,,,,,,,,,,,,,,,,,,,,,,,,
413.076,3.39972,1.0376,10,,,,,,,,,,,,,,,,,,,,,,,,,,,,,,,,,,,,,
413.776,3.3996,1.01409,10,,,,,,,,,,,,,,,,,,,,,,,,,,,,,,,,,,,,,
414.476,3.39972,1.03713,10,,,,,,,,,,,,,,,,,,,,,,,,,,,,,,,,,,,,,
415.176,3.39972,1.04638,10,,,,,,,,,,,,,,,,,,,,,,,,,,,,,,,,,,,,,
415.876,3.39972,1.09283,10,,,,,,,,,,,,,,,,,,,,,,,,,,,,,,,,,,,,,
416.576,3.39972,1.04876,10,,,,,,,,,,,,,,,,,,,,,,,,,,,,,,,,,,,,,
417.276,3.3996,1.00198,10,,,,,,,,,,,,,,,,,,,,,,,,,,,,,,,,,,,,,
417.976,3.39972,1.05985,10,,,,,,,,,,,,,,,,,,,,,,,,,,,,,,,,,,,,,
418.676,3.3996,1.03356,10,,,,,,,,,,,,,,,,,,,,,,,,,,,,,,,,,,,,,
419.376,3.3996,1.06701,10,,,,,,,,,,,,,,,,,,,,,,,,,,,,,,,,,,,,,
420.076,3.39966,1.01642,10,,,,,,,,,,,,,,,,,,,,,,,,,,,,,,,,,,,,,
420.776,3.39966,1.04173,10,,,,,,,,,,,,,,,,,,,,,,,,,,,,,,,,,,,,,
421.476,3.39972,1.0942,10,,,,,,,,,,,,,,,,,,,,,,,,,,,,,,,,,,,,,
422.176,3.3996,1.03039,10,,,,,,,,,,,,,,,,,,,,,,,,,,,,,,,,,,,,,
422.876,3.3996,1.06943,10,,,,,,,,,,,,,,,,,,,,,,,,,,,,,,,,,,,,,
423.576,3.3996,1.04146,10,,,,,,,,,,,,,,,,,,,,,,,,,,,,,,,,,,,,,
424.276,3.39972,1.06909,10,,,,,,,,,,,,,,,,,,,,,,,,,,,,,,,,,,,,,
424.976,3.3996,1.06549,10,,,,,,,,,,,,,,,,,,,,,,,,,,,,,,,,,,,,,
425.676,3.3996,1.02049,10,,,,,,,,,,,,,,,,,,,,,,,,,,,,,,,,,,,,,
426.376,3.3996,1.08824,10,,,,,,,,,,,,,,,,,,,,,,,,,,,,,,,,,,,,,
427.076,3.3996,1.10735,10,,,,,,,,,,,,,,,,,,,,,,,,,,,,,,,,,,,,,
427.776,3.3996,1.08077,10,,,,,,,,,,,,,,,,,,,,,,,,,,,,,,,,,,,,,
428.476,3.3996,1.04201,10,,,,,,,,,,,,,,,,,,,,,,,,,,,,,,,,,,,,,
429.176,3.3996,1.0281,10,,,,,,,,,,,,,,,,,,,,,,,,,,,,,,,,,,,,,
429.876,3.39955,1.16267,10,,,,,,,,,,,,,,,,,,,,,,,,,,,,,,,,,,,,,
430.576,3.39966,1.09278,10,,,,,,,,,,,,,,,,,,,,,,,,,,,,,,,,,,,,,
431.276,3.39966,1.02553,10,,,,,,,,,,,,,,,,,,,,,,,,,,,,,,,,,,,,,
431.976,3.39966,1.07332,10,,,,,,,,,,,,,,,,,,,,,,,,,,,,,,,,,,,,,
432.676,3.39966,1.02611,10,,,,,,,,,,,,,,,,,,,,,,,,,,,,,,,,,,,,,
433.376,3.39966,1.10934,10,,,,,,,,,,,,,,,,,,,,,,,,,,,,,,,,,,,,,
434.076,3.39966,1.02023,10,,,,,,,,,,,,,,,,,,,,,,,,,,,,,,,,,,,,,
434.776,3.39966,1.1047,10,,,,,,,,,,,,,,,,,,,,,,,,,,,,,,,,,,,,,
435.476,3.39955,1.07402,10,,,,,,,,,,,,,,,,,,,,,,,,,,,,,,,,,,,,,
436.176,3.39949,1.04708,10,,,,,,,,,,,,,,,,,,,,,,,,,,,,,,,,,,,,,
436.876,3.39949,1.02531,10,,,,,,,,,,,,,,,,,,,,,,,,,,,,,,,,,,,,,
437.576,3.39949,1.05764,10,,,,,,,,,,,,,,,,,,,,,,,,,,,,,,,,,,,,,
438.276,3.39949,1.04335,10,,,,,,,,,,,,,,,,,,,,,,,,,,,,,,,,,,,,,
438.976,3.3996,1.05262,10,,,,,,,,,,,,,,,,,,,,,,,,,,,,,,,,,,,,,
439.676,3.3996,1.04373,10,,,,,,,,,,,,,,,,,,,,,,,,,,,,,,,,,,,,,
440.376,3.3996,1.04551,10,,,,,,,,,,,,,,,,,,,,,,,,,,,,,,,,,,,,,
441.076,3.3996,1.08398,10,,,,,,,,,,,,,,,,,,,,,,,,,,,,,,,,,,,,,
441.776,3.3996,1.05063,10,,,,,,,,,,,,,,,,,,,,,,,,,,,,,,,,,,,,,
442.476,3.3996,1.06272,10,,,,,,,,,,,,,,,,,,,,,,,,,,,,,,,,,,,,,
443.176,3.3996,1.12055,10,,,,,,,,,,,,,,,,,,,,,,,,,,,,,,,,,,,,,
443.876,3.3996,1.04555,10,,,,,,,,,,,,,,,,,,,,,,,,,,,,,,,,,,,,,
444.576,3.3996,1.0466,10,,,,,,,,,,,,,,,,,,,,,,,,,,,,,,,,,,,,,
445.276,3.3996,1.05202,10,,,,,,,,,,,,,,,,,,,,,,,,,,,,,,,,,,,,,
445.976,3.3996,1.05482,10,,,,,,,,,,,,,,,,,,,,,,,,,,,,,,,,,,,,,
446.676,3.3996,1.00492,10,,,,,,,,,,,,,,,,,,,,,,,,,,,,,,,,,,,,,
447.376,3.3996,1.02647,10,,,,,,,,,,,,,,,,,,,,,,,,,,,,,,,,,,,,,
448.076,3.3996,1.06759,10,,,,,,,,,,,,,,,,,,,,,,,,,,,,,,,,,,,,,
448.776,3.3996,1.08676,10,,,,,,,,,,,,,,,,,,,,,,,,,,,,,,,,,,,,,
449.476,3.3996,1.02099,10,,,,,,,,,,,,,,,,,,,,,,,,,,,,,,,,,,,,,
450.176,3.3996,1.03338,10,,,,,,,,,,,,,,,,,,,,,,,,,,,,,,,,,,,,,
450.876,3.3996,0.99054,10,,,,,,,,,,,,,,,,,,,,,,,,,,,,,,,,,,,,,
451.576,3.3996,1.07937,10,,,,,,,,,,,,,,,,,,,,,,,,,,,,,,,,,,,,,
452.276,3.39949,1.0555,10,,,,,,,,,,,,,,,,,,,,,,,,,,,,,,,,,,,,,
452.976,3.39949,1.0816,10,,,,,,,,,,,,,,,,,,,,,,,,,,,,,,,,,,,,,
453.676,3.3996,0.9939,10,,,,,,,,,,,,,,,,,,,,,,,,,,,,,,,,,,,,,
454.376,3.3996,1.06213,10,,,,,,,,,,,,,,,,,,,,,,,,,,,,,,,,,,,,,
455.076,3.3996,1.0391,10,,,,,,,,,,,,,,,,,,,,,,,,,,,,,,,,,,,,,
455.776,3.3996,1.05125,10,,,,,,,,,,,,,,,,,,,,,,,,,,,,,,,,,,,,,
456.476,3.3996,1.05451,10,,,,,,,,,,,,,,,,,,,,,,,,,,,,,,,,,,,,,
457.176,3.3996,1.07314,10,,,,,,,,,,,,,,,,,,,,,,,,,,,,,,,,,,,,,
457.876,3.39949,1.03254,10,,,,,,,,,,,,,,,,,,,,,,,,,,,,,,,,,,,,,
458.576,3.39949,1.01666,10,,,,,,,,,,,,,,,,,,,,,,,,,,,,,,,,,,,,,
459.276,3.3996,1.00213,10,,,,,,,,,,,,,,,,,,,,,,,,,,,,,,,,,,,,,
459.976,3.3996,1.06495,10,,,,,,,,,,,,,,,,,,,,,,,,,,,,,,,,,,,,,
460.676,3.3996,1.00313,10,,,,,,,,,,,,,,,,,,,,,,,,,,,,,,,,,,,,,
461.376,3.39949,1.04367,10,,,,,,,,,,,,,,,,,,,,,,,,,,,,,,,,,,,,,
462.076,3.39949,1.0707,10,,,,,,,,,,,,,,,,,,,,,,,,,,,,,,,,,,,,,
462.776,3.39949,1.04689,10,,,,,,,,,,,,,,,,,,,,,,,,,,,,,,,,,,,,,
463.476,3.3996,1.0221,10,,,,,,,,,,,,,,,,,,,,,,,,,,,,,,,,,,,,,
464.176,3.3996,1.04886,10,,,,,,,,,,,,,,,,,,,,,,,,,,,,,,,,,,,,,
464.876,3.3996,1.03477,10,,,,,,,,,,,,,,,,,,,,,,,,,,,,,,,,,,,,,
465.576,3.3996,1.05245,10,,,,,,,,,,,,,,,,,,,,,,,,,,,,,,,,,,,,,
466.276,3.3996,1.03796,10,,,,,,,,,,,,,,,,,,,,,,,,,,,,,,,,,,,,,
466.976,3.3996,1.11231,10,,,,,,,,,,,,,,,,,,,,,,,,,,,,,,,,,,,,,
467.676,3.3996,1.01179,10,,,,,,,,,,,,,,,,,,,,,,,,,,,,,,,,,,,,,
468.376,3.3996,1.05523,10,,,,,,,,,,,,,,,,,,,,,,,,,,,,,,,,,,,,,
469.076,3.3996,1.03652,10,,,,,,,,,,,,,,,,,,,,,,,,,,,,,,,,,,,,,
469.776,3.3996,1.06836,10,,,,,,,,,,,,,,,,,,,,,,,,,,,,,,,,,,,,,
470.476,3.3996,1.05256,10,,,,,,,,,,,,,,,,,,,,,,,,,,,,,,,,,,,,,
471.176,3.3996,1.0576,10,,,,,,,,,,,,,,,,,,,,,,,,,,,,,,,,,,,,,
471.876,3.3996,1.03289,10,,,,,,,,,,,,,,,,,,,,,,,,,,,,,,,,,,,,,
472.576,3.3996,1.07172,10,,,,,,,,,,,,,,,,,,,,,,,,,,,,,,,,,,,,,
473.276,3.3996,1.07045,10,,,,,,,,,,,,,,,,,,,,,,,,,,,,,,,,,,,,,
473.976,3.3996,1.09125,10,,,,,,,,,,,,,,,,,,,,,,,,,,,,,,,,,,,,,
474.676,3.3996,1.02171,10,,,,,,,,,,,,,,,,,,,,,,,,,,,,,,,,,,,,,
475.376,3.3996,1.06158,10,,,,,,,,,,,,,,,,,,,,,,,,,,,,,,,,,,,,,
476.076,3.3996,1.03555,10,,,,,,,,,,,,,,,,,,,,,,,,,,,,,,,,,,,,,
476.776,3.3996,1.05947,10,,,,,,,,,,,,,,,,,,,,,,,,,,,,,,,,,,,,,
477.476,3.3996,1.0849,10,,,,,,,,,,,,,,,,,,,,,,,,,,,,,,,,,,,,,
478.176,3.3996,1.07278,10,,,,,,,,,,,,,,,,,,,,,,,,,,,,,,,,,,,,,
478.876,3.3996,1.03588,10,,,,,,,,,,,,,,,,,,,,,,,,,,,,,,,,,,,,,
479.576,3.3996,1.06652,10,,,,,,,,,,,,,,,,,,,,,,,,,,,,,,,,,,,,,
480.276,3.3996,0.9965,10,,,,,,,,,,,,,,,,,,,,,,,,,,,,,,,,,,,,,
480.976,3.3996,1.10608,10,,,,,,,,,,,,,,,,,,,,,,,,,,,,,,,,,,,,,
481.676,3.3996,1.00308,10,,,,,,,,,,,,,,,,,,,,,,,,,,,,,,,,,,,,,
482.376,3.3996,1.06653,10,,,,,,,,,,,,,,,,,,,,,,,,,,,,,,,,,,,,,
483.076,3.3996,1.05086,10,,,,,,,,,,,,,,,,,,,,,,,,,,,,,,,,,,,,,
483.776,3.39943,1.09262,10,,,,,,,,,,,,,,,,,,,,,,,,,,,,,,,,,,,,,
484.476,3.39955,0.93345,10,,,,,,,,,,,,,,,,,,,,,,,,,,,,,,,,,,,,,
485.176,3.39977,1.13444,10,,,,,,,,,,,,,,,,,,,,,,,,,,,,,,,,,,,,,
485.876,3.39938,1.25315,10,,,,,,,,,,,,,,,,,,,,,,,,,,,,,,,,,,,,,
486.576,3.39416,1.22996,10,,,,,,,,,,,,,,,,,,,,,,,,,,,,,,,,,,,,,
487.276,3.35784,1.0035,10,,,,,,,,,,,,,,,,,,,,,,,,,,,,,,,,,,,,,
487.976,3.3197,1.01186,10,,,,,,,,,,,,,,,,,,,,,,,,,,,,,,,,,,,,,
488.676,3.3133,0.97711,10,,,,,,,,,,,,,,,,,,,,,,,,,,,,,,,,,,,,,
489.376,3.31336,1.01511,10,,,,,,,,,,,,,,,,,,,,,,,,,,,,,,,,,,,,,
490.076,3.31353,0.95293,10,,,,,,,,,,,,,,,,,,,,,,,,,,,,,,,,,,,,,
490.776,3.3137,0.9626,10,,,,,,,,,,,,,,,,,,,,,,,,,,,,,,,,,,,,,
491.476,3.31398,0.95362,10,,,,,,,,,,,,,,,,,,,,,,,,,,,,,,,,,,,,,
492.176,3.31449,0.92285,10,,,,,,,,,,,,,,,,,,,,,,,,,,,,,,,,,,,,,
492.876,3.31551,0.94144,10,,,,,,,,,,,,,,,,,,,,,,,,,,,,,,,,,,,,,
493.576,3.31874,0.98783,10,,,,,,,,,,,,,,,,,,,,,,,,,,,,,,,,,,,,,
494.276,3.33716,1.05484,10,,,,,,,,,,,,,,,,,,,,,,,,,,,,,,,,,,,,,
494.976,3.37201,1.14852,10,,,,,,,,,,,,,,,,,,,,,,,,,,,,,,,,,,,,,
495.676,3.37603,1.15411,10,,,,,,,,,,,,,,,,,,,,,,,,,,,,,,,,,,,,,
496.376,3.37586,1.17264,10,,,,,,,,,,,,,,,,,,,,,,,,,,,,,,,,,,,,,
497.076,3.37541,1.18095,10,,,,,,,,,,,,,,,,,,,,,,,,,,,,,,,,,,,,,
497.678,4.71501,17.99047,10,,,,,,,,,,,,,,,,,,,,,,,,,,,,,,,,,,,,,
498.378,10.55762,1336.48828,10,,,,,,,,,,,,,,,,,,,,,,,,,,,,,,,,,,,,,
499.078,16.39112,9.80585,10,,,,,,,,,,,,,,,,,,,,,,,,,,,,,,,,,,,,,
499.778,22.22438,0.70204,10,,,,,,,,,,,,,,,,,,,,,,,,,,,,,,,,,,,,,
500.478,28.0577,0.81042,10,,,,,,,,,,,,,,,,,,,,,,,,,,,,,,,,,,,,,
501.178,33.89097,0.84989,10,,,,,,,,,,,,,,,,,,,,,,,,,,,,,,,,,,,,,
501.552,37.00764,0.81442,10,,,,,,,,,,,,,,,,,,,,,,,,,,,,,,,,,,,,,