File: combined_ligament_solver/data/processed/Data Sheet 3_S152678_MCL.csv
Specimen properties : Length,121,mm,Unnamed: 3,Unnamed: 4,Unnamed: 5,Unnamed: 6,Unnamed: 7,Unnamed: 8,Unnamed: 9,Unnamed: 10,Unnamed: 11,Stress-Strain,Unnamed: 13,Unnamed: 14,Unnamed: 15,Unnamed: 16,Unnamed: 17,Unnamed: 18,Unnamed: 19,Unnamed: 20,Unnamed: 21,Unnamed: 22,Unnamed: 23,Unnamed: 24,Unnamed: 25,Unnamed: 26,Unnamed: 27,Linear,Unnamed: 29,Unnamed: 30,Unnamed: 31,Unnamed: 32,Unnamed: 33,Modulus,Unnamed: 35,Failure,Unnamed: 37,Unnamed: 38,Unnamed: 39,Unnamed: 40
Cross Section Average,33.4105,mm2,,,,,,,,,,Polynomial Coefficients,,,,,,,,,,,,,,,,Force,,Stress,Extension,Strain,,Secant,Tangent,Load,Stress,Extension,Strain,Stiffness
Time,Extension,Load,Total cycle count,,,Extension,Load,Strain,Stress,E-tan,,X6,-929912182.766597,,,,,,,,,Strain,Stress,E-tan,,,,(N),,(MPa),(mm),(%),,(MPa),(MPa),(N),(MPa),(mm),(%),(N/mm)
(s),(mm),(N),,,,(mm),(N),(mm/mm),(MPa),(MPa),,X5,133422311.41898128,,,,,,,,,(mm/mm),(MPa),(MPa),,,,188.08720476669734,,5.629583656835346,5.687,4.7,,119.7783756773478,255.18409092146638,458.46619,13.697091333562803,10.533479999999999,8.705355371900826,33.07318529395065
0.8,1.0425,1.11766,0,,,8.32541,235.8766,0.05261710743801653,7.034826776013529,207.25157958390392,,,,,,,,,,,,0.008,0.10833664920609531,17.246303084978788,,,,,,,,,,,,,,,,
1.7,1.19266,1.47953,0,,,15.82547,90.96141,,,,,,,,,,,,,,,0.017,0.4757816445195669,63.80387719840841,,,,,,,,,,,,,,,,
2.6,1.34243,1.91411,0,,,23.32553,41.33448,,,,,,,,,,,,,,,0.026,1.355629135114694,126.12701487635036,,,,,,,,,,,,,,,,
3.5,1.49243,2.42848,0,,,,,,,,,,,,,,,,,,,0.035,2.8271631171687286,193.59029476030702,,,,,,,,,,,,,,,,
4.4,1.64265,3.03264,0,,,,,,,,,,,,,,,,,,,0.044,4.868468682455974,248.5971653786059,,,,,,,,,,,,,,,,
5.3,1.79237,3.71154,0,,,,,,,,,,,,,,,,,,,0.053,7.096014463200451,227.04446832061788,,,,,,,,,,,,,,,,
6.2,1.94242,4.48846,0,,,,,,,,,,,,,,,,,,,0.062,,,,,,,,,,,,,,,,,,
7.1,2.09253,5.3495,0,,,,,,,,,,,,,,,,,,,0.071,,,,,,,,,,,,,,,,,,
8,2.24241,6.18604,0,,,,,,,,,,,,,,,,,,,0.08,,,,,,,,,,,,,,,,,,
8.9,2.39252,6.92344,0,,,,,,,,,,,,,,,,,,,0.089,,,,,,,,,,,,,,,,,,
9.8,2.54252,7.916,0,,,,,,,,,,,,,,,,,,,0.098,,,,,,,,,,,,,,,,,,
10.7,2.69246,8.93986,0,,,,,,,,,,,,,,,,,,,0.107,,,,,,,,,,,,,,,,,,
11.6,2.84257,10.02577,0,,,,,,,,,,,,,,,,,,,0.116,,,,,,,,,,,,,,,,,,
12.5,2.99245,11.42806,0,,,,,,,,,,,,,,,,,,,0.125,,,,,,,,,,,,,,,,,,
13.4,3.14245,13.00097,0,,,,,,,,,,,,,,,,,,,0.134,,,,,,,,,,,,,,,,,,
14.3,3.2925,14.77821,0,,,,,,,,,,,,,,,,,,,0.143,,,,,,,,,,,,,,,,,,
15.2,3.44239,16.63283,0,,,,,,,,,,,,,,,,,,,0.152,,,,,,,,,,,,,,,,,,
16.1,3.59238,18.65196,0,,,,,,,,,,,,,,,,,,,0.161,,,,,,,,,,,,,,,,,,
17,3.74255,20.98483,0,,,,,,,,,,,,,,,,,,,0.17,,,,,,,,,,,,,,,,,,
17.9,3.89249,23.57501,0,,,,,,,,,,,,,,,,,,,0.179,,,,,,,,,,,,,,,,,,
18.8,4.04249,26.36622,0,,,,,,,,,,,,,,,,,,,0.188,,,,,,,,,,,,,,,,,,
19.7,4.1926,28.43013,0,,,,,,,,,,,,,,,,,,,0.197,,,,,,,,,,,,,,,,,,
20.6,4.34248,32.15629,0,,,,,,,,,,,,,,,,,,,,,,,,,,,,,,,,,,,,,
21.5,4.49242,36.00082,0,,,,,,,,,,,,,,,,,,,,,,,,,,,,,,,,,,,,,
22.4,4.64253,39.737,0,,,,,,,,,,,,,,,,,,,,,,,,,,,,,,,,,,,,,
23.164,4.53628,35.042,0.5,,,,,,,,,,,,,,,,,,,,,,,,,,,,,,,,,,,,,
24.064,4.38617,29.58624,0.5,,,,,,,,,,,,,,,,,,,,,,,,,,,,,,,,,,,,,
24.964,4.23606,25.10484,0.5,,,,,,,,,,,,,,,,,,,,,,,,,,,,,,,,,,,,,
25.864,4.08623,21.23105,0.5,,,,,,,,,,,,,,,,,,,,,,,,,,,,,,,,,,,,,
26.764,3.93618,18.08922,0.5,,,,,,,,,,,,,,,,,,,,,,,,,,,,,,,,,,,,,
27.664,3.78613,15.39211,0.5,,,,,,,,,,,,,,,,,,,,,,,,,,,,,,,,,,,,,
28.564,3.63624,12.94159,0.5,,,,,,,,,,,,,,,,,,,,,,,,,,,,,,,,,,,,,
29.464,3.48613,10.76129,0.5,,,,,,,,,,,,,,,,,,,,,,,,,,,,,,,,,,,,,
30.364,3.33614,9.142,0.5,,,,,,,,,,,,,,,,,,,,,,,,,,,,,,,,,,,,,
31.264,3.18614,7.83165,0.5,,,,,,,,,,,,,,,,,,,,,,,,,,,,,,,,,,,,,
32.164,3.03609,6.6817,0.5,,,,,,,,,,,,,,,,,,,,,,,,,,,,,,,,,,,,,
33.064,2.88615,5.5285,0.5,,,,,,,,,,,,,,,,,,,,,,,,,,,,,,,,,,,,,
33.964,2.73621,4.61374,0.5,,,,,,,,,,,,,,,,,,,,,,,,,,,,,,,,,,,,,
34.864,2.5861,3.71366,0.5,,,,,,,,,,,,,,,,,,,,,,,,,,,,,,,,,,,,,
35.764,2.43627,3.02808,0.5,,,,,,,,,,,,,,,,,,,,,,,,,,,,,,,,,,,,,
36.664,2.28627,2.30691,0.5,,,,,,,,,,,,,,,,,,,,,,,,,,,,,,,,,,,,,
37.564,2.13605,1.78168,0.5,,,,,,,,,,,,,,,,,,,,,,,,,,,,,,,,,,,,,
38.464,1.98622,1.35805,0.5,,,,,,,,,,,,,,,,,,,,,,,,,,,,,,,,,,,,,
39.252,1.85476,0.99416,1,,,,,,,,,,,,,,,,,,,,,,,,,,,,,,,,,,,,,
40.054,1.98883,1.40602,1,,,,,,,,,,,,,,,,,,,,,,,,,,,,,,,,,,,,,
40.954,2.13871,2.00062,1,,,,,,,,,,,,,,,,,,,,,,,,,,,,,,,,,,,,,
41.854,2.28877,2.70092,1,,,,,,,,,,,,,,,,,,,,,,,,,,,,,,,,,,,,,
42.754,2.43888,3.4902,1,,,,,,,,,,,,,,,,,,,,,,,,,,,,,,,,,,,,,
43.654,2.5887,4.44654,1,,,,,,,,,,,,,,,,,,,,,,,,,,,,,,,,,,,,,
44.554,2.73876,5.53757,1,,,,,,,,,,,,,,,,,,,,,,,,,,,,,,,,,,,,,
45.454,2.88892,6.6237,1,,,,,,,,,,,,,,,,,,,,,,,,,,,,,,,,,,,,,
46.354,3.03881,7.82644,1,,,,,,,,,,,,,,,,,,,,,,,,,,,,,,,,,,,,,
47.254,3.1888,9.13102,1,,,,,,,,,,,,,,,,,,,,,,,,,,,,,,,,,,,,,
48.154,3.33891,10.64432,1,,,,,,,,,,,,,,,,,,,,,,,,,,,,,,,,,,,,,
49.054,3.48874,12.59156,1,,,,,,,,,,,,,,,,,,,,,,,,,,,,,,,,,,,,,
49.954,3.63879,14.89069,1,,,,,,,,,,,,,,,,,,,,,,,,,,,,,,,,,,,,,
50.854,3.78879,17.29008,1,,,,,,,,,,,,,,,,,,,,,,,,,,,,,,,,,,,,,
51.754,3.93873,20.02201,1,,,,,,,,,,,,,,,,,,,,,,,,,,,,,,,,,,,,,
52.654,4.08884,23.17019,1,,,,,,,,,,,,,,,,,,,,,,,,,,,,,,,,,,,,,
53.554,4.23878,26.66972,1,,,,,,,,,,,,,,,,,,,,,,,,,,,,,,,,,,,,,
54.454,4.38883,29.89877,1,,,,,,,,,,,,,,,,,,,,,,,,,,,,,,,,,,,,,
55.354,4.53889,34.32226,1,,,,,,,,,,,,,,,,,,,,,,,,,,,,,,,,,,,,,
56.254,4.68877,39.08077,1,,,,,,,,,,,,,,,,,,,,,,,,,,,,,,,,,,,,,
57.024,4.61686,35.91069,1.5,,,,,,,,,,,,,,,,,,,,,,,,,,,,,,,,,,,,,
57.924,4.46686,30.46952,1.5,,,,,,,,,,,,,,,,,,,,,,,,,,,,,,,,,,,,,
58.824,4.31692,25.84713,1.5,,,,,,,,,,,,,,,,,,,,,,,,,,,,,,,,,,,,,
59.724,4.16687,21.90996,1.5,,,,,,,,,,,,,,,,,,,,,,,,,,,,,,,,,,,,,
60.624,4.01682,18.67108,1.5,,,,,,,,,,,,,,,,,,,,,,,,,,,,,,,,,,,,,
61.524,3.86682,15.88941,1.5,,,,,,,,,,,,,,,,,,,,,,,,,,,,,,,,,,,,,
62.424,3.71671,13.40576,1.5,,,,,,,,,,,,,,,,,,,,,,,,,,,,,,,,,,,,,
63.324,3.56688,11.22464,1.5,,,,,,,,,,,,,,,,,,,,,,,,,,,,,,,,,,,,,
64.224,3.41689,9.39929,1.5,,,,,,,,,,,,,,,,,,,,,,,,,,,,,,,,,,,,,
65.124,3.26678,8.02673,1.5,,,,,,,,,,,,,,,,,,,,,,,,,,,,,,,,,,,,,
66.024,3.11689,6.75713,1.5,,,,,,,,,,,,,,,,,,,,,,,,,,,,,,,,,,,,,
66.924,2.9669,5.72425,1.5,,,,,,,,,,,,,,,,,,,,,,,,,,,,,,,,,,,,,
67.824,2.81673,4.60641,1.5,,,,,,,,,,,,,,,,,,,,,,,,,,,,,,,,,,,,,
68.724,2.6669,3.77579,1.5,,,,,,,,,,,,,,,,,,,,,,,,,,,,,,,,,,,,,
69.624,2.51679,2.97704,1.5,,,,,,,,,,,,,,,,,,,,,,,,,,,,,,,,,,,,,
70.524,2.36668,2.35413,1.5,,,,,,,,,,,,,,,,,,,,,,,,,,,,,,,,,,,,,
71.424,2.21686,1.81969,1.5,,,,,,,,,,,,,,,,,,,,,,,,,,,,,,,,,,,,,
72.324,2.0668,1.37077,1.5,,,,,,,,,,,,,,,,,,,,,,,,,,,,,,,,,,,,,
73.182,1.92383,0.99964,2,,,,,,,,,,,,,,,,,,,,,,,,,,,,,,,,,,,,,
73.886,2.04085,1.31982,2,,,,,,,,,,,,,,,,,,,,,,,,,,,,,,,,,,,,,
74.786,2.19068,1.90578,2,,,,,,,,,,,,,,,,,,,,,,,,,,,,,,,,,,,,,
75.686,2.34079,2.6186,2,,,,,,,,,,,,,,,,,,,,,,,,,,,,,,,,,,,,,
76.586,2.49084,3.38626,2,,,,,,,,,,,,,,,,,,,,,,,,,,,,,,,,,,,,,
77.486,2.64084,4.37428,2,,,,,,,,,,,,,,,,,,,,,,,,,,,,,,,,,,,,,
78.386,2.79089,5.45615,2,,,,,,,,,,,,,,,,,,,,,,,,,,,,,,,,,,,,,
79.286,2.94083,6.62401,2,,,,,,,,,,,,,,,,,,,,,,,,,,,,,,,,,,,,,
80.186,3.09083,7.66199,2,,,,,,,,,,,,,,,,,,,,,,,,,,,,,,,,,,,,,
81.086,3.24088,9.05267,2,,,,,,,,,,,,,,,,,,,,,,,,,,,,,,,,,,,,,
81.986,3.39076,10.57771,2,,,,,,,,,,,,,,,,,,,,,,,,,,,,,,,,,,,,,
82.886,3.54076,12.6186,2,,,,,,,,,,,,,,,,,,,,,,,,,,,,,,,,,,,,,
83.786,3.69087,14.80154,2,,,,,,,,,,,,,,,,,,,,,,,,,,,,,,,,,,,,,
84.686,3.8407,17.34244,2,,,,,,,,,,,,,,,,,,,,,,,,,,,,,,,,,,,,,
85.586,3.99075,20.03731,2,,,,,,,,,,,,,,,,,,,,,,,,,,,,,,,,,,,,,
86.486,4.14097,23.21766,2,,,,,,,,,,,,,,,,,,,,,,,,,,,,,,,,,,,,,
87.386,4.29074,26.75409,2,,,,,,,,,,,,,,,,,,,,,,,,,,,,,,,,,,,,,
88.286,4.44085,30.18402,2,,,,,,,,,,,,,,,,,,,,,,,,,,,,,,,,,,,,,
89.186,4.59096,34.79637,2,,,,,,,,,,,,,,,,,,,,,,,,,,,,,,,,,,,,,
90.086,4.74073,39.71828,2,,,,,,,,,,,,,,,,,,,,,,,,,,,,,,,,,,,,,
90.842,4.63312,35.32712,2.5,,,,,,,,,,,,,,,,,,,,,,,,,,,,,,,,,,,,,
91.742,4.48318,29.96963,2.5,,,,,,,,,,,,,,,,,,,,,,,,,,,,,,,,,,,,,
92.642,4.33313,25.46805,2.5,,,,,,,,,,,,,,,,,,,,,,,,,,,,,,,,,,,,,
93.542,4.18308,21.6887,2.5,,,,,,,,,,,,,,,,,,,,,,,,,,,,,,,,,,,,,
94.442,4.03319,18.41382,2.5,,,,,,,,,,,,,,,,,,,,,,,,,,,,,,,,,,,,,
95.342,3.88314,15.58015,2.5,,,,,,,,,,,,,,,,,,,,,,,,,,,,,,,,,,,,,
96.242,3.73314,13.11583,2.5,,,,,,,,,,,,,,,,,,,,,,,,,,,,,,,,,,,,,
97.142,3.5832,11.00607,2.5,,,,,,,,,,,,,,,,,,,,,,,,,,,,,,,,,,,,,
98.042,3.43309,9.29454,2.5,,,,,,,,,,,,,,,,,,,,,,,,,,,,,,,,,,,,,
98.942,3.28321,7.92148,2.5,,,,,,,,,,,,,,,,,,,,,,,,,,,,,,,,,,,,,
99.842,3.13316,6.69986,2.5,,,,,,,,,,,,,,,,,,,,,,,,,,,,,,,,,,,,,
100.742,2.98305,5.55073,2.5,,,,,,,,,,,,,,,,,,,,,,,,,,,,,,,,,,,,,
101.642,2.83316,4.47892,2.5,,,,,,,,,,,,,,,,,,,,,,,,,,,,,,,,,,,,,
102.542,2.68328,3.58769,2.5,,,,,,,,,,,,,,,,,,,,,,,,,,,,,,,,,,,,,
103.442,2.53306,2.88687,2.5,,,,,,,,,,,,,,,,,,,,,,,,,,,,,,,,,,,,,
104.342,2.38323,2.23127,2.5,,,,,,,,,,,,,,,,,,,,,,,,,,,,,,,,,,,,,
105.242,2.23323,1.67641,2.5,,,,,,,,,,,,,,,,,,,,,,,,,,,,,,,,,,,,,
106.142,2.08301,1.25557,2.5,,,,,,,,,,,,,,,,,,,,,,,,,,,,,,,,,,,,,
106.852,1.96475,0.99473,3,,,,,,,,,,,,,,,,,,,,,,,,,,,,,,,,,,,,,
107.654,2.09888,1.35037,3,,,,,,,,,,,,,,,,,,,,,,,,,,,,,,,,,,,,,
108.554,2.2487,1.946,3,,,,,,,,,,,,,,,,,,,,,,,,,,,,,,,,,,,,,
109.454,2.39881,2.68557,3,,,,,,,,,,,,,,,,,,,,,,,,,,,,,,,,,,,,,
110.354,2.54887,3.50011,3,,,,,,,,,,,,,,,,,,,,,,,,,,,,,,,,,,,,,
111.254,2.69869,4.4781,3,,,,,,,,,,,,,,,,,,,,,,,,,,,,,,,,,,,,,
112.154,2.8488,5.61586,3,,,,,,,,,,,,,,,,,,,,,,,,,,,,,,,,,,,,,
113.054,2.99886,6.65673,3,,,,,,,,,,,,,,,,,,,,,,,,,,,,,,,,,,,,,
113.954,3.1488,7.8655,3,,,,,,,,,,,,,,,,,,,,,,,,,,,,,,,,,,,,,
114.854,3.29885,9.27379,3,,,,,,,,,,,,,,,,,,,,,,,,,,,,,,,,,,,,,
115.754,3.44885,10.85964,3,,,,,,,,,,,,,,,,,,,,,,,,,,,,,,,,,,,,,
116.654,3.59879,12.90223,3,,,,,,,,,,,,,,,,,,,,,,,,,,,,,,,,,,,,,
117.554,3.7489,15.21658,3,,,,,,,,,,,,,,,,,,,,,,,,,,,,,,,,,,,,,
118.454,3.89878,17.75685,3,,,,,,,,,,,,,,,,,,,,,,,,,,,,,,,,,,,,,
119.354,4.04872,20.62128,3,,,,,,,,,,,,,,,,,,,,,,,,,,,,,,,,,,,,,
120.254,4.19889,23.81109,3,,,,,,,,,,,,,,,,,,,,,,,,,,,,,,,,,,,,,
121.154,4.34871,27.42139,3,,,,,,,,,,,,,,,,,,,,,,,,,,,,,,,,,,,,,
122.054,4.49877,30.82408,3,,,,,,,,,,,,,,,,,,,,,,,,,,,,,,,,,,,,,
122.954,4.64893,35.72981,3,,,,,,,,,,,,,,,,,,,,,,,,,,,,,,,,,,,,,
123.702,4.77349,40.00786,3.5,,,,,,,,,,,,,,,,,,,,,,,,,,,,,,,,,,,,,
124.602,4.62315,34.1188,3.5,,,,,,,,,,,,,,,,,,,,,,,,,,,,,,,,,,,,,
125.502,4.47321,28.97468,3.5,,,,,,,,,,,,,,,,,,,,,,,,,,,,,,,,,,,,,
126.402,4.32321,24.50352,3.5,,,,,,,,,,,,,,,,,,,,,,,,,,,,,,,,,,,,,
127.302,4.17305,20.77497,3.5,,,,,,,,,,,,,,,,,,,,,,,,,,,,,,,,,,,,,
128.202,4.02328,17.66488,3.5,,,,,,,,,,,,,,,,,,,,,,,,,,,,,,,,,,,,,
129.102,3.87322,15.0236,3.5,,,,,,,,,,,,,,,,,,,,,,,,,,,,,,,,,,,,,
130.002,3.72311,12.55571,3.5,,,,,,,,,,,,,,,,,,,,,,,,,,,,,,,,,,,,,
130.902,3.57323,10.46834,3.5,,,,,,,,,,,,,,,,,,,,,,,,,,,,,,,,,,,,,
131.802,3.42312,8.84202,3.5,,,,,,,,,,,,,,,,,,,,,,,,,,,,,,,,,,,,,
132.702,3.27307,7.65367,3.5,,,,,,,,,,,,,,,,,,,,,,,,,,,,,,,,,,,,,
133.602,3.12318,6.38532,3.5,,,,,,,,,,,,,,,,,,,,,,,,,,,,,,,,,,,,,
134.502,2.97313,5.33215,3.5,,,,,,,,,,,,,,,,,,,,,,,,,,,,,,,,,,,,,
135.402,2.82313,4.35925,3.5,,,,,,,,,,,,,,,,,,,,,,,,,,,,,,,,,,,,,
136.302,2.67331,3.46944,3.5,,,,,,,,,,,,,,,,,,,,,,,,,,,,,,,,,,,,,
137.202,2.52314,2.78836,3.5,,,,,,,,,,,,,,,,,,,,,,,,,,,,,,,,,,,,,
138.102,2.37314,2.11935,3.5,,,,,,,,,,,,,,,,,,,,,,,,,,,,,,,,,,,,,
139.002,2.22326,1.60273,3.5,,,,,,,,,,,,,,,,,,,,,,,,,,,,,,,,,,,,,
139.902,2.07309,1.24093,3.5,,,,,,,,,,,,,,,,,,,,,,,,,,,,,,,,,,,,,
140.542,2.03377,1.04073,4,,,,,,,,,,,,,,,,,,,,,,,,,,,,,,,,,,,,,
141.442,2.1841,1.60157,4,,,,,,,,,,,,,,,,,,,,,,,,,,,,,,,,,,,,,
142.342,2.33416,2.20787,4,,,,,,,,,,,,,,,,,,,,,,,,,,,,,,,,,,,,,
143.242,2.48404,3.01249,4,,,,,,,,,,,,,,,,,,,,,,,,,,,,,,,,,,,,,
144.142,2.63409,3.85798,4,,,,,,,,,,,,,,,,,,,,,,,,,,,,,,,,,,,,,
145.042,2.7842,4.95276,4,,,,,,,,,,,,,,,,,,,,,,,,,,,,,,,,,,,,,
145.942,2.93403,6.10198,4,,,,,,,,,,,,,,,,,,,,,,,,,,,,,,,,,,,,,
146.842,3.08414,7.10598,4,,,,,,,,,,,,,,,,,,,,,,,,,,,,,,,,,,,,,
147.742,3.23425,8.45965,4,,,,,,,,,,,,,,,,,,,,,,,,,,,,,,,,,,,,,
148.642,3.38413,9.81833,4,,,,,,,,,,,,,,,,,,,,,,,,,,,,,,,,,,,,,
149.542,3.53413,11.69837,4,,,,,,,,,,,,,,,,,,,,,,,,,,,,,,,,,,,,,
150.442,3.68424,13.82205,4,,,,,,,,,,,,,,,,,,,,,,,,,,,,,,,,,,,,,
151.342,3.83407,16.29423,4,,,,,,,,,,,,,,,,,,,,,,,,,,,,,,,,,,,,,
152.242,3.98412,18.94148,4,,,,,,,,,,,,,,,,,,,,,,,,,,,,,,,,,,,,,
153.142,4.13423,21.90946,4,,,,,,,,,,,,,,,,,,,,,,,,,,,,,,,,,,,,,
154.042,4.28406,25.38003,4,,,,,,,,,,,,,,,,,,,,,,,,,,,,,,,,,,,,,
154.942,4.43411,28.4246,4,,,,,,,,,,,,,,,,,,,,,,,,,,,,,,,,,,,,,
155.842,4.58422,33.05684,4,,,,,,,,,,,,,,,,,,,,,,,,,,,,,,,,,,,,,
156.742,4.73416,38.06949,4,,,,,,,,,,,,,,,,,,,,,,,,,,,,,,,,,,,,,
157.474,4.7226,37.39861,4.5,,,,,,,,,,,,,,,,,,,,,,,,,,,,,,,,,,,,,
158.374,4.57238,31.72807,4.5,,,,,,,,,,,,,,,,,,,,,,,,,,,,,,,,,,,,,
159.274,4.42255,26.91862,4.5,,,,,,,,,,,,,,,,,,,,,,,,,,,,,,,,,,,,,
160.174,4.27261,22.79867,4.5,,,,,,,,,,,,,,,,,,,,,,,,,,,,,,,,,,,,,
161.074,4.12239,19.32356,4.5,,,,,,,,,,,,,,,,,,,,,,,,,,,,,,,,,,,,,
161.974,3.97256,16.41964,4.5,,,,,,,,,,,,,,,,,,,,,,,,,,,,,,,,,,,,,
162.874,3.82245,13.85192,4.5,,,,,,,,,,,,,,,,,,,,,,,,,,,,,,,,,,,,,
163.774,3.67234,11.51273,4.5,,,,,,,,,,,,,,,,,,,,,,,,,,,,,,,,,,,,,
164.674,3.52251,9.6725,4.5,,,,,,,,,,,,,,,,,,,,,,,,,,,,,,,,,,,,,
165.574,3.37246,8.21466,4.5,,,,,,,,,,,,,,,,,,,,,,,,,,,,,,,,,,,,,
166.474,3.22246,6.96905,4.5,,,,,,,,,,,,,,,,,,,,,,,,,,,,,,,,,,,,,
167.374,3.07264,5.90186,4.5,,,,,,,,,,,,,,,,,,,,,,,,,,,,,,,,,,,,,
168.274,2.92247,4.89954,4.5,,,,,,,,,,,,,,,,,,,,,,,,,,,,,,,,,,,,,
169.174,2.77253,3.89481,4.5,,,,,,,,,,,,,,,,,,,,,,,,,,,,,,,,,,,,,
170.074,2.62259,3.0917,4.5,,,,,,,,,,,,,,,,,,,,,,,,,,,,,,,,,,,,,
170.974,2.47237,2.44454,4.5,,,,,,,,,,,,,,,,,,,,,,,,,,,,,,,,,,,,,
171.874,2.32254,1.83679,4.5,,,,,,,,,,,,,,,,,,,,,,,,,,,,,,,,,,,,,
172.774,2.17249,1.38266,4.5,,,,,,,,,,,,,,,,,,,,,,,,,,,,,,,,,,,,,
173.674,2.02232,1.03849,4.5,,,,,,,,,,,,,,,,,,,,,,,,,,,,,,,,,,,,,
174.336,2.1131,1.29032,5,,,,,,,,,,,,,,,,,,,,,,,,,,,,,,,,,,,,,
175.236,2.26321,1.84644,5,,,,,,,,,,,,,,,,,,,,,,,,,,,,,,,,,,,,,
176.136,2.41315,2.49975,5,,,,,,,,,,,,,,,,,,,,,,,,,,,,,,,,,,,,,
177.036,2.5632,3.30677,5,,,,,,,,,,,,,,,,,,,,,,,,,,,,,,,,,,,,,
177.936,2.7132,4.31276,5,,,,,,,,,,,,,,,,,,,,,,,,,,,,,,,,,,,,,
178.836,2.86314,5.37614,5,,,,,,,,,,,,,,,,,,,,,,,,,,,,,,,,,,,,,
179.736,3.01325,6.46111,5,,,,,,,,,,,,,,,,,,,,,,,,,,,,,,,,,,,,,
180.636,3.16308,7.72895,5,,,,,,,,,,,,,,,,,,,,,,,,,,,,,,,,,,,,,
181.536,3.31307,9.05325,5,,,,,,,,,,,,,,,,,,,,,,,,,,,,,,,,,,,,,
182.436,3.46324,10.57681,5,,,,,,,,,,,,,,,,,,,,,,,,,,,,,,,,,,,,,
183.336,3.61307,12.53357,5,,,,,,,,,,,,,,,,,,,,,,,,,,,,,,,,,,,,,
184.236,3.76318,14.8197,5,,,,,,,,,,,,,,,,,,,,,,,,,,,,,,,,,,,,,
185.136,3.91329,17.32131,5,,,,,,,,,,,,,,,,,,,,,,,,,,,,,,,,,,,,,
186.036,4.06311,20.10938,5,,,,,,,,,,,,,,,,,,,,,,,,,,,,,,,,,,,,,
186.936,4.21311,23.35656,5,,,,,,,,,,,,,,,,,,,,,,,,,,,,,,,,,,,,,
187.836,4.36322,26.10515,5,,,,,,,,,,,,,,,,,,,,,,,,,,,,,,,,,,,,,
188.736,4.51305,30.38039,5,,,,,,,,,,,,,,,,,,,,,,,,,,,,,,,,,,,,,
189.636,4.66304,35.18946,5,,,,,,,,,,,,,,,,,,,,,,,,,,,,,,,,,,,,,
190.474,4.80273,40.01693,5.5,,,,,,,,,,,,,,,,,,,,,,,,,,,,,,,,,,,,,
191.276,4.66962,34.83835,5.5,,,,,,,,,,,,,,,,,,,,,,,,,,,,,,,,,,,,,
192.176,4.51945,29.5647,5.5,,,,,,,,,,,,,,,,,,,,,,,,,,,,,,,,,,,,,
193.076,4.36957,25.05468,5.5,,,,,,,,,,,,,,,,,,,,,,,,,,,,,,,,,,,,,
193.976,4.21957,21.19186,5.5,,,,,,,,,,,,,,,,,,,,,,,,,,,,,,,,,,,,,
194.876,4.06946,17.95555,5.5,,,,,,,,,,,,,,,,,,,,,,,,,,,,,,,,,,,,,
195.776,3.91952,15.23395,5.5,,,,,,,,,,,,,,,,,,,,,,,,,,,,,,,,,,,,,
196.676,3.76947,12.7526,5.5,,,,,,,,,,,,,,,,,,,,,,,,,,,,,,,,,,,,,
197.576,3.61941,10.65174,5.5,,,,,,,,,,,,,,,,,,,,,,,,,,,,,,,,,,,,,
198.476,3.46953,9.01882,5.5,,,,,,,,,,,,,,,,,,,,,,,,,,,,,,,,,,,,,
199.376,3.31942,7.85688,5.5,,,,,,,,,,,,,,,,,,,,,,,,,,,,,,,,,,,,,
200.276,3.16954,6.44352,5.5,,,,,,,,,,,,,,,,,,,,,,,,,,,,,,,,,,,,,
201.176,3.0196,5.45149,5.5,,,,,,,,,,,,,,,,,,,,,,,,,,,,,,,,,,,,,
202.076,2.86943,4.44876,5.5,,,,,,,,,,,,,,,,,,,,,,,,,,,,,,,,,,,,,
202.976,2.7196,3.52793,5.5,,,,,,,,,,,,,,,,,,,,,,,,,,,,,,,,,,,,,
203.876,2.56955,2.79289,5.5,,,,,,,,,,,,,,,,,,,,,,,,,,,,,,,,,,,,,
204.776,2.41933,2.16866,5.5,,,,,,,,,,,,,,,,,,,,,,,,,,,,,,,,,,,,,
205.676,2.2695,1.65134,5.5,,,,,,,,,,,,,,,,,,,,,,,,,,,,,,,,,,,,,
206.576,2.1195,1.21409,5.5,,,,,,,,,,,,,,,,,,,,,,,,,,,,,,,,,,,,,
207.268,2.07128,1.08801,6,,,,,,,,,,,,,,,,,,,,,,,,,,,,,,,,,,,,,
208.168,2.22179,1.58852,6,,,,,,,,,,,,,,,,,,,,,,,,,,,,,,,,,,,,,
209.068,2.37178,2.21998,6,,,,,,,,,,,,,,,,,,,,,,,,,,,,,,,,,,,,,
209.968,2.52184,2.9955,6,,,,,,,,,,,,,,,,,,,,,,,,,,,,,,,,,,,,,
210.868,2.67195,3.86707,6,,,,,,,,,,,,,,,,,,,,,,,,,,,,,,,,,,,,,
211.768,2.82183,4.96686,6,,,,,,,,,,,,,,,,,,,,,,,,,,,,,,,,,,,,,
212.668,2.97183,6.06799,6,,,,,,,,,,,,,,,,,,,,,,,,,,,,,,,,,,,,,
213.568,3.12194,7.20165,6,,,,,,,,,,,,,,,,,,,,,,,,,,,,,,,,,,,,,
214.468,3.27176,8.48258,6,,,,,,,,,,,,,,,,,,,,,,,,,,,,,,,,,,,,,
215.368,3.4217,9.86531,6,,,,,,,,,,,,,,,,,,,,,,,,,,,,,,,,,,,,,
216.268,3.57193,11.80055,6,,,,,,,,,,,,,,,,,,,,,,,,,,,,,,,,,,,,,
217.168,3.7217,13.96179,6,,,,,,,,,,,,,,,,,,,,,,,,,,,,,,,,,,,,,
218.068,3.87181,16.42818,6,,,,,,,,,,,,,,,,,,,,,,,,,,,,,,,,,,,,,
218.968,4.02197,19.08993,6,,,,,,,,,,,,,,,,,,,,,,,,,,,,,,,,,,,,,
219.868,4.1718,22.13431,6,,,,,,,,,,,,,,,,,,,,,,,,,,,,,,,,,,,,,
220.768,4.32185,25.6254,6,,,,,,,,,,,,,,,,,,,,,,,,,,,,,,,,,,,,,
221.668,4.47191,28.80672,6,,,,,,,,,,,,,,,,,,,,,,,,,,,,,,,,,,,,,
222.568,4.62179,33.46391,6,,,,,,,,,,,,,,,,,,,,,,,,,,,,,,,,,,,,,
223.468,4.77184,38.5311,6,,,,,,,,,,,,,,,,,,,,,,,,,,,,,,,,,,,,,
224.21,4.72861,36.81743,6.5,,,,,,,,,,,,,,,,,,,,,,,,,,,,,,,,,,,,,
225.11,4.57838,31.259,6.5,,,,,,,,,,,,,,,,,,,,,,,,,,,,,,,,,,,,,
226.01,4.4285,26.43337,6.5,,,,,,,,,,,,,,,,,,,,,,,,,,,,,,,,,,,,,
226.91,4.27845,22.38051,6.5,,,,,,,,,,,,,,,,,,,,,,,,,,,,,,,,,,,,,
227.81,4.12839,19.03098,6.5,,,,,,,,,,,,,,,,,,,,,,,,,,,,,,,,,,,,,
228.71,3.97857,16.12263,6.5,,,,,,,,,,,,,,,,,,,,,,,,,,,,,,,,,,,,,
229.61,3.82846,13.57974,6.5,,,,,,,,,,,,,,,,,,,,,,,,,,,,,,,,,,,,,
230.51,3.67852,11.32036,6.5,,,,,,,,,,,,,,,,,,,,,,,,,,,,,,,,,,,,,
231.41,3.52858,9.49202,6.5,,,,,,,,,,,,,,,,,,,,,,,,,,,,,,,,,,,,,
232.31,3.37841,8.28942,6.5,,,,,,,,,,,,,,,,,,,,,,,,,,,,,,,,,,,,,
233.21,3.22853,6.85763,6.5,,,,,,,,,,,,,,,,,,,,,,,,,,,,,,,,,,,,,
234.11,3.07853,5.79352,6.5,,,,,,,,,,,,,,,,,,,,,,,,,,,,,,,,,,,,,
235.01,2.92831,4.71735,6.5,,,,,,,,,,,,,,,,,,,,,,,,,,,,,,,,,,,,,
235.91,2.77859,3.82117,6.5,,,,,,,,,,,,,,,,,,,,,,,,,,,,,,,,,,,,,
236.81,2.62865,3.03605,6.5,,,,,,,,,,,,,,,,,,,,,,,,,,,,,,,,,,,,,
237.71,2.47837,2.35603,6.5,,,,,,,,,,,,,,,,,,,,,,,,,,,,,,,,,,,,,
238.61,2.32855,1.8095,6.5,,,,,,,,,,,,,,,,,,,,,,,,,,,,,,,,,,,,,
239.51,2.17861,1.35357,6.5,,,,,,,,,,,,,,,,,,,,,,,,,,,,,,,,,,,,,
240.254,2.05445,0.99325,7,,,,,,,,,,,,,,,,,,,,,,,,,,,,,,,,,,,,,
241.056,2.18841,1.38549,7,,,,,,,,,,,,,,,,,,,,,,,,,,,,,,,,,,,,,
241.956,2.33852,2.05057,7,,,,,,,,,,,,,,,,,,,,,,,,,,,,,,,,,,,,,
242.856,2.48857,2.70795,7,,,,,,,,,,,,,,,,,,,,,,,,,,,,,,,,,,,,,
243.756,2.63846,3.62905,7,,,,,,,,,,,,,,,,,,,,,,,,,,,,,,,,,,,,,
244.656,2.78857,4.62977,7,,,,,,,,,,,,,,,,,,,,,,,,,,,,,,,,,,,,,
245.556,2.93845,5.78138,7,,,,,,,,,,,,,,,,,,,,,,,,,,,,,,,,,,,,,
246.456,3.08839,6.83228,7,,,,,,,,,,,,,,,,,,,,,,,,,,,,,,,,,,,,,
247.356,3.2385,8.10062,7,,,,,,,,,,,,,,,,,,,,,,,,,,,,,,,,,,,,,
248.256,3.38838,9.43425,7,,,,,,,,,,,,,,,,,,,,,,,,,,,,,,,,,,,,,
249.156,3.53844,11.13964,7,,,,,,,,,,,,,,,,,,,,,,,,,,,,,,,,,,,,,
250.056,3.68855,13.30114,7,,,,,,,,,,,,,,,,,,,,,,,,,,,,,,,,,,,,,
250.956,3.83843,15.74606,7,,,,,,,,,,,,,,,,,,,,,,,,,,,,,,,,,,,,,
251.856,3.98848,18.23899,7,,,,,,,,,,,,,,,,,,,,,,,,,,,,,,,,,,,,,
252.756,4.13865,21.19576,7,,,,,,,,,,,,,,,,,,,,,,,,,,,,,,,,,,,,,
253.656,4.28842,24.58332,7,,,,,,,,,,,,,,,,,,,,,,,,,,,,,,,,,,,,,
254.556,4.43842,27.50097,7,,,,,,,,,,,,,,,,,,,,,,,,,,,,,,,,,,,,,
255.456,4.58858,32.10706,7,,,,,,,,,,,,,,,,,,,,,,,,,,,,,,,,,,,,,
256.356,4.73841,37.11316,7,,,,,,,,,,,,,,,,,,,,,,,,,,,,,,,,,,,,,
257.144,4.76963,38.07368,7.5,,,,,,,,,,,,,,,,,,,,,,,,,,,,,,,,,,,,,
258.044,4.61952,32.3891,7.5,,,,,,,,,,,,,,,,,,,,,,,,,,,,,,,,,,,,,
258.944,4.46953,27.40156,7.5,,,,,,,,,,,,,,,,,,,,,,,,,,,,,,,,,,,,,
259.844,4.31947,23.08205,7.5,,,,,,,,,,,,,,,,,,,,,,,,,,,,,,,,,,,,,
260.744,4.16942,19.65316,7.5,,,,,,,,,,,,,,,,,,,,,,,,,,,,,,,,,,,,,
261.644,4.01948,16.64381,7.5,,,,,,,,,,,,,,,,,,,,,,,,,,,,,,,,,,,,,
262.544,3.86954,14.05568,7.5,,,,,,,,,,,,,,,,,,,,,,,,,,,,,,,,,,,,,
263.444,3.71943,11.76304,7.5,,,,,,,,,,,,,,,,,,,,,,,,,,,,,,,,,,,,,
264.344,3.56955,9.79191,7.5,,,,,,,,,,,,,,,,,,,,,,,,,,,,,,,,,,,,,
265.244,3.41955,8.33187,7.5,,,,,,,,,,,,,,,,,,,,,,,,,,,,,,,,,,,,,
266.144,3.26944,7.08294,7.5,,,,,,,,,,,,,,,,,,,,,,,,,,,,,,,,,,,,,
267.044,3.11956,5.91934,7.5,,,,,,,,,,,,,,,,,,,,,,,,,,,,,,,,,,,,,
267.944,2.9695,4.91805,7.5,,,,,,,,,,,,,,,,,,,,,,,,,,,,,,,,,,,,,
268.844,2.81939,3.92077,7.5,,,,,,,,,,,,,,,,,,,,,,,,,,,,,,,,,,,,,
269.744,2.66951,3.12119,7.5,,,,,,,,,,,,,,,,,,,,,,,,,,,,,,,,,,,,,
270.644,2.51946,2.44082,7.5,,,,,,,,,,,,,,,,,,,,,,,,,,,,,,,,,,,,,
271.544,2.3694,1.88358,7.5,,,,,,,,,,,,,,,,,,,,,,,,,,,,,,,,,,,,,
272.444,2.21958,1.42418,7.5,,,,,,,,,,,,,,,,,,,,,,,,,,,,,,,,,,,,,
273.26,2.08329,0.99781,8,,,,,,,,,,,,,,,,,,,,,,,,,,,,,,,,,,,,,
273.964,2.20042,1.37968,8,,,,,,,,,,,,,,,,,,,,,,,,,,,,,,,,,,,,,
274.864,2.35048,1.9846,8,,,,,,,,,,,,,,,,,,,,,,,,,,,,,,,,,,,,,
275.764,2.50059,2.68587,8,,,,,,,,,,,,,,,,,,,,,,,,,,,,,,,,,,,,,
276.664,2.65047,3.55155,8,,,,,,,,,,,,,,,,,,,,,,,,,,,,,,,,,,,,,
277.564,2.80052,4.60395,8,,,,,,,,,,,,,,,,,,,,,,,,,,,,,,,,,,,,,
278.464,2.95058,5.76473,8,,,,,,,,,,,,,,,,,,,,,,,,,,,,,,,,,,,,,
279.364,3.1004,6.85329,8,,,,,,,,,,,,,,,,,,,,,,,,,,,,,,,,,,,,,
280.264,3.25046,8.07084,8,,,,,,,,,,,,,,,,,,,,,,,,,,,,,,,,,,,,,
281.164,3.40051,9.36101,8,,,,,,,,,,,,,,,,,,,,,,,,,,,,,,,,,,,,,
282.064,3.55039,11.12432,8,,,,,,,,,,,,,,,,,,,,,,,,,,,,,,,,,,,,,
282.964,3.70045,13.3192,8,,,,,,,,,,,,,,,,,,,,,,,,,,,,,,,,,,,,,
283.864,3.85056,15.70914,8,,,,,,,,,,,,,,,,,,,,,,,,,,,,,,,,,,,,,
284.764,4.0005,18.26816,8,,,,,,,,,,,,,,,,,,,,,,,,,,,,,,,,,,,,,
285.664,4.15049,21.209,8,,,,,,,,,,,,,,,,,,,,,,,,,,,,,,,,,,,,,
286.564,4.30055,24.62419,8,,,,,,,,,,,,,,,,,,,,,,,,,,,,,,,,,,,,,
287.464,4.45049,27.60691,8,,,,,,,,,,,,,,,,,,,,,,,,,,,,,,,,,,,,,
288.364,4.60048,32.13675,8,,,,,,,,,,,,,,,,,,,,,,,,,,,,,,,,,,,,,
289.264,4.75042,37.20848,8,,,,,,,,,,,,,,,,,,,,,,,,,,,,,,,,,,,,,
290.04,4.77966,38.11243,8.5,,,,,,,,,,,,,,,,,,,,,,,,,,,,,,,,,,,,,
290.94,4.6295,32.34528,8.5,,,,,,,,,,,,,,,,,,,,,,,,,,,,,,,,,,,,,
291.84,4.47956,27.44482,8.5,,,,,,,,,,,,,,,,,,,,,,,,,,,,,,,,,,,,,
292.74,4.32956,23.14066,8.5,,,,,,,,,,,,,,,,,,,,,,,,,,,,,,,,,,,,,
293.64,4.17939,19.66405,8.5,,,,,,,,,,,,,,,,,,,,,,,,,,,,,,,,,,,,,
294.54,4.02951,16.67657,8.5,,,,,,,,,,,,,,,,,,,,,,,,,,,,,,,,,,,,,
295.44,3.87946,14.0204,8.5,,,,,,,,,,,,,,,,,,,,,,,,,,,,,,,,,,,,,
296.34,3.7294,11.70481,8.5,,,,,,,,,,,,,,,,,,,,,,,,,,,,,,,,,,,,,
297.24,3.57958,9.81121,8.5,,,,,,,,,,,,,,,,,,,,,,,,,,,,,,,,,,,,,
298.14,3.42958,8.33432,8.5,,,,,,,,,,,,,,,,,,,,,,,,,,,,,,,,,,,,,
299.04,3.27953,7.06518,8.5,,,,,,,,,,,,,,,,,,,,,,,,,,,,,,,,,,,,,
299.94,3.12953,5.92777,8.5,,,,,,,,,,,,,,,,,,,,,,,,,,,,,,,,,,,,,
300.84,2.97948,4.91629,8.5,,,,,,,,,,,,,,,,,,,,,,,,,,,,,,,,,,,,,
301.74,2.82948,3.93624,8.5,,,,,,,,,,,,,,,,,,,,,,,,,,,,,,,,,,,,,
302.64,2.67948,3.1228,8.5,,,,,,,,,,,,,,,,,,,,,,,,,,,,,,,,,,,,,
303.54,2.52937,2.44017,8.5,,,,,,,,,,,,,,,,,,,,,,,,,,,,,,,,,,,,,
304.44,2.37949,1.87137,8.5,,,,,,,,,,,,,,,,,,,,,,,,,,,,,,,,,,,,,
305.34,2.22955,1.38968,8.5,,,,,,,,,,,,,,,,,,,,,,,,,,,,,,,,,,,,,
306.18,2.08947,0.99838,9,,,,,,,,,,,,,,,,,,,,,,,,,,,,,,,,,,,,,
306.884,2.2066,1.36521,9,,,,,,,,,,,,,,,,,,,,,,,,,,,,,,,,,,,,,
307.784,2.35643,1.93325,9,,,,,,,,,,,,,,,,,,,,,,,,,,,,,,,,,,,,,
308.684,2.50648,2.68701,9,,,,,,,,,,,,,,,,,,,,,,,,,,,,,,,,,,,,,
309.584,2.65642,3.49287,9,,,,,,,,,,,,,,,,,,,,,,,,,,,,,,,,,,,,,
310.484,2.80647,4.54784,9,,,,,,,,,,,,,,,,,,,,,,,,,,,,,,,,,,,,,
311.384,2.95653,5.70706,9,,,,,,,,,,,,,,,,,,,,,,,,,,,,,,,,,,,,,
312.284,3.10641,6.8359,9,,,,,,,,,,,,,,,,,,,,,,,,,,,,,,,,,,,,,
313.184,3.25646,8.04876,9,,,,,,,,,,,,,,,,,,,,,,,,,,,,,,,,,,,,,
314.084,3.40657,9.36116,9,,,,,,,,,,,,,,,,,,,,,,,,,,,,,,,,,,,,,
314.984,3.5564,11.13865,9,,,,,,,,,,,,,,,,,,,,,,,,,,,,,,,,,,,,,
315.884,3.70651,13.22653,9,,,,,,,,,,,,,,,,,,,,,,,,,,,,,,,,,,,,,
316.784,3.85662,15.65315,9,,,,,,,,,,,,,,,,,,,,,,,,,,,,,,,,,,,,,
317.684,4.00639,18.19597,9,,,,,,,,,,,,,,,,,,,,,,,,,,,,,,,,,,,,,
318.584,4.15644,21.17204,9,,,,,,,,,,,,,,,,,,,,,,,,,,,,,,,,,,,,,
319.484,4.3065,24.59329,9,,,,,,,,,,,,,,,,,,,,,,,,,,,,,,,,,,,,,
320.384,4.45644,27.60778,9,,,,,,,,,,,,,,,,,,,,,,,,,,,,,,,,,,,,,
321.284,4.60649,32.13028,9,,,,,,,,,,,,,,,,,,,,,,,,,,,,,,,,,,,,,
322.184,4.75654,37.1152,9,,,,,,,,,,,,,,,,,,,,,,,,,,,,,,,,,,,,,
322.97,4.7872,38.13505,9.5,,,,,,,,,,,,,,,,,,,,,,,,,,,,,,,,,,,,,
323.87,4.63715,32.3747,9.5,,,,,,,,,,,,,,,,,,,,,,,,,,,,,,,,,,,,,
324.77,4.48726,27.42447,9.5,,,,,,,,,,,,,,,,,,,,,,,,,,,,,,,,,,,,,
325.67,4.33715,23.17819,9.5,,,,,,,,,,,,,,,,,,,,,,,,,,,,,,,,,,,,,
326.57,4.18716,19.68702,9.5,,,,,,,,,,,,,,,,,,,,,,,,,,,,,,,,,,,,,
327.47,4.03722,16.71044,9.5,,,,,,,,,,,,,,,,,,,,,,,,,,,,,,,,,,,,,
328.37,3.88705,14.07,9.5,,,,,,,,,,,,,,,,,,,,,,,,,,,,,,,,,,,,,
329.27,3.73711,11.75893,9.5,,,,,,,,,,,,,,,,,,,,,,,,,,,,,,,,,,,,,
330.17,3.58717,9.87313,9.5,,,,,,,,,,,,,,,,,,,,,,,,,,,,,,,,,,,,,
331.07,3.43717,8.38347,9.5,,,,,,,,,,,,,,,,,,,,,,,,,,,,,,,,,,,,,
331.97,3.28718,7.13582,9.5,,,,,,,,,,,,,,,,,,,,,,,,,,,,,,,,,,,,,
332.87,3.13724,5.85991,9.5,,,,,,,,,,,,,,,,,,,,,,,,,,,,,,,,,,,,,
333.77,2.98718,4.91974,9.5,,,,,,,,,,,,,,,,,,,,,,,,,,,,,,,,,,,,,
334.67,2.83724,3.9175,9.5,,,,,,,,,,,,,,,,,,,,,,,,,,,,,,,,,,,,,
335.57,2.68725,3.18512,9.5,,,,,,,,,,,,,,,,,,,,,,,,,,,,,,,,,,,,,
336.47,2.53714,2.4492,9.5,,,,,,,,,,,,,,,,,,,,,,,,,,,,,,,,,,,,,
337.37,2.3872,1.85446,9.5,,,,,,,,,,,,,,,,,,,,,,,,,,,,,,,,,,,,,
338.27,2.23709,1.43151,9.5,,,,,,,,,,,,,,,,,,,,,,,,,,,,,,,,,,,,,
339.138,2.09253,0.99704,10,,,,,,,,,,,,,,,,,,,,,,,,,,,,,,,,,,,,,
339.94,1.98447,0.85668,10,,,,,,,,,,,,,,,,,,,,,,,,,,,,,,,,,,,,,
340.84,1.96225,0.77089,10,,,,,,,,,,,,,,,,,,,,,,,,,,,,,,,,,,,,,
341.74,1.96339,0.71782,10,,,,,,,,,,,,,,,,,,,,,,,,,,,,,,,,,,,,,
342.64,1.98452,0.7876,10,,,,,,,,,,,,,,,,,,,,,,,,,,,,,,,,,,,,,
343.54,2.09089,1.06871,10,,,,,,,,,,,,,,,,,,,,,,,,,,,,,,,,,,,,,
344.44,2.13514,1.27588,10,,,,,,,,,,,,,,,,,,,,,,,,,,,,,,,,,,,,,
345.34,2.13424,1.26825,10,,,,,,,,,,,,,,,,,,,,,,,,,,,,,,,,,,,,,
346.24,2.10256,1.16144,10,,,,,,,,,,,,,,,,,,,,,,,,,,,,,,,,,,,,,
347.14,2.01767,0.93534,10,,,,,,,,,,,,,,,,,,,,,,,,,,,,,,,,,,,,,
348.04,1.99875,0.84338,10,,,,,,,,,,,,,,,,,,,,,,,,,,,,,,,,,,,,,
348.94,1.99903,0.90652,10,,,,,,,,,,,,,,,,,,,,,,,,,,,,,,,,,,,,,
349.84,1.99982,0.83728,10,,,,,,,,,,,,,,,,,,,,,,,,,,,,,,,,,,,,,
350.74,2.00577,0.87258,10,,,,,,,,,,,,,,,,,,,,,,,,,,,,,,,,,,,,,
351.64,2.05813,1.04491,10,,,,,,,,,,,,,,,,,,,,,,,,,,,,,,,,,,,,,
352.54,2.09015,1.08712,10,,,,,,,,,,,,,,,,,,,,,,,,,,,,,,,,,,,,,
353.44,2.09049,1.1607,10,,,,,,,,,,,,,,,,,,,,,,,,,,,,,,,,,,,,,
354.34,2.09009,1.15013,10,,,,,,,,,,,,,,,,,,,,,,,,,,,,,,,,,,,,,
355.24,2.08386,1.14981,10,,,,,,,,,,,,,,,,,,,,,,,,,,,,,,,,,,,,,
356.14,2.04006,1.02775,10,,,,,,,,,,,,,,,,,,,,,,,,,,,,,,,,,,,,,
357.04,2.00781,0.93069,10,,,,,,,,,,,,,,,,,,,,,,,,,,,,,,,,,,,,,
357.94,2.00526,0.92073,10,,,,,,,,,,,,,,,,,,,,,,,,,,,,,,,,,,,,,
358.84,2.00543,0.92438,10,,,,,,,,,,,,,,,,,,,,,,,,,,,,,,,,,,,,,
359.74,2.00589,0.87409,10,,,,,,,,,,,,,,,,,,,,,,,,,,,,,,,,,,,,,
360.64,2.00764,0.88295,10,,,,,,,,,,,,,,,,,,,,,,,,,,,,,,,,,,,,,
361.54,2.02385,0.93877,10,,,,,,,,,,,,,,,,,,,,,,,,,,,,,,,,,,,,,
362.44,2.07049,1.12652,10,,,,,,,,,,,,,,,,,,,,,,,,,,,,,,,,,,,,,
363.34,2.07774,1.08393,10,,,,,,,,,,,,,,,,,,,,,,,,,,,,,,,,,,,,,
364.24,2.07746,1.11911,10,,,,,,,,,,,,,,,,,,,,,,,,,,,,,,,,,,,,,
365.14,2.07627,1.2173,10,,,,,,,,,,,,,,,,,,,,,,,,,,,,,,,,,,,,,
366.04,2.06454,1.1266,10,,,,,,,,,,,,,,,,,,,,,,,,,,,,,,,,,,,,,
366.94,2.02901,1.04893,10,,,,,,,,,,,,,,,,,,,,,,,,,,,,,,,,,,,,,
367.84,2.00764,0.92872,10,,,,,,,,,,,,,,,,,,,,,,,,,,,,,,,,,,,,,
368.74,2.00662,0.90709,10,,,,,,,,,,,,,,,,,,,,,,,,,,,,,,,,,,,,,
369.64,2.00685,0.94139,10,,,,,,,,,,,,,,,,,,,,,,,,,,,,,,,,,,,,,
370.54,2.00708,0.85152,10,,,,,,,,,,,,,,,,,,,,,,,,,,,,,,,,,,,,,
371.44,2.00764,0.91518,10,,,,,,,,,,,,,,,,,,,,,,,,,,,,,,,,,,,,,
372.34,2.0098,0.90798,10,,,,,,,,,,,,,,,,,,,,,,,,,,,,,,,,,,,,,
373.24,2.02045,0.92365,10,,,,,,,,,,,,,,,,,,,,,,,,,,,,,,,,,,,,,
374.14,2.06267,1.04166,10,,,,,,,,,,,,,,,,,,,,,,,,,,,,,,,,,,,,,
375.04,2.06998,1.17789,10,,,,,,,,,,,,,,,,,,,,,,,,,,,,,,,,,,,,,
375.94,2.06975,1.12703,10,,,,,,,,,,,,,,,,,,,,,,,,,,,,,,,,,,,,,
376.84,2.06913,1.09944,10,,,,,,,,,,,,,,,,,,,,,,,,,,,,,,,,,,,,,
377.74,2.06301,1.07856,10,,,,,,,,,,,,,,,,,,,,,,,,,,,,,,,,,,,,,
378.64,2.03314,1.01974,10,,,,,,,,,,,,,,,,,,,,,,,,,,,,,,,,,,,,,
379.54,2.00736,0.92482,10,,,,,,,,,,,,,,,,,,,,,,,,,,,,,,,,,,,,,
380.44,2.00532,0.98543,10,,,,,,,,,,,,,,,,,,,,,,,,,,,,,,,,,,,,,
381.34,2.00549,0.93946,10,,,,,,,,,,,,,,,,,,,,,,,,,,,,,,,,,,,,,
382.24,2.0056,0.93126,10,,,,,,,,,,,,,,,,,,,,,,,,,,,,,,,,,,,,,
383.14,2.00594,0.93713,10,,,,,,,,,,,,,,,,,,,,,,,,,,,,,,,,,,,,,
384.04,2.00691,0.91523,10,,,,,,,,,,,,,,,,,,,,,,,,,,,,,,,,,,,,,
384.94,2.01065,0.93944,10,,,,,,,,,,,,,,,,,,,,,,,,,,,,,,,,,,,,,
385.84,2.02719,0.95901,10,,,,,,,,,,,,,,,,,,,,,,,,,,,,,,,,,,,,,
386.74,2.06731,1.11329,10,,,,,,,,,,,,,,,,,,,,,,,,,,,,,,,,,,,,,
387.64,2.06913,1.10193,10,,,,,,,,,,,,,,,,,,,,,,,,,,,,,,,,,,,,,
388.54,2.06879,1.09884,10,,,,,,,,,,,,,,,,,,,,,,,,,,,,,,,,,,,,,
389.44,2.0651,1.22436,10,,,,,,,,,,,,,,,,,,,,,,,,,,,,,,,,,,,,,
390.34,2.03105,1.03573,10,,,,,,,,,,,,,,,,,,,,,,,,,,,,,,,,,,,,,
391.24,1.99591,0.9406,10,,,,,,,,,,,,,,,,,,,,,,,,,,,,,,,,,,,,,
392.14,1.99376,0.95155,10,,,,,,,,,,,,,,,,,,,,,,,,,,,,,,,,,,,,,
393.04,1.99382,0.88436,10,,,,,,,,,,,,,,,,,,,,,,,,,,,,,,,,,,,,,
393.94,1.99404,0.98612,10,,,,,,,,,,,,,,,,,,,,,,,,,,,,,,,,,,,,,
394.84,1.99438,0.87854,10,,,,,,,,,,,,,,,,,,,,,,,,,,,,,,,,,,,,,
395.74,1.99535,0.92685,10,,,,,,,,,,,,,,,,,,,,,,,,,,,,,,,,,,,,,
396.64,1.99982,0.92787,10,,,,,,,,,,,,,,,,,,,,,,,,,,,,,,,,,,,,,
397.54,2.01892,0.93172,10,,,,,,,,,,,,,,,,,,,,,,,,,,,,,,,,,,,,,
398.44,2.05762,1.09929,10,,,,,,,,,,,,,,,,,,,,,,,,,,,,,,,,,,,,,
399.34,2.06125,1.09073,10,,,,,,,,,,,,,,,,,,,,,,,,,,,,,,,,,,,,,
400.24,2.06091,1.11968,10,,,,,,,,,,,,,,,,,,,,,,,,,,,,,,,,,,,,,
401.14,2.05932,1.19366,10,,,,,,,,,,,,,,,,,,,,,,,,,,,,,,,,,,,,,
402.04,2.03853,1.07466,10,,,,,,,,,,,,,,,,,,,,,,,,,,,,,,,,,,,,,
402.94,1.99795,0.98154,10,,,,,,,,,,,,,,,,,,,,,,,,,,,,,,,,,,,,,
403.84,1.99438,0.95502,10,,,,,,,,,,,,,,,,,,,,,,,,,,,,,,,,,,,,,
404.74,1.99444,0.92857,10,,,,,,,,,,,,,,,,,,,,,,,,,,,,,,,,,,,,,
405.64,1.99461,0.96399,10,,,,,,,,,,,,,,,,,,,,,,,,,,,,,,,,,,,,,
406.54,1.99472,0.93,10,,,,,,,,,,,,,,,,,,,,,,,,,,,,,,,,,,,,,
407.44,1.99535,0.95822,10,,,,,,,,,,,,,,,,,,,,,,,,,,,,,,,,,,,,,
408.34,1.99727,0.9483,10,,,,,,,,,,,,,,,,,,,,,,,,,,,,,,,,,,,,,
409.24,2.00447,0.91665,10,,,,,,,,,,,,,,,,,,,,,,,,,,,,,,,,,,,,,
410.14,2.04249,1.05309,10,,,,,,,,,,,,,,,,,,,,,,,,,,,,,,,,,,,,,
411.04,2.06284,1.13319,10,,,,,,,,,,,,,,,,,,,,,,,,,,,,,,,,,,,,,
411.94,2.06278,1.17714,10,,,,,,,,,,,,,,,,,,,,,,,,,,,,,,,,,,,,,
412.84,2.06216,1.1407,10,,,,,,,,,,,,,,,,,,,,,,,,,,,,,,,,,,,,,
413.74,2.05094,1.14897,10,,,,,,,,,,,,,,,,,,,,,,,,,,,,,,,,,,,,,
414.64,2.00441,0.9743,10,,,,,,,,,,,,,,,,,,,,,,,,,,,,,,,,,,,,,
415.54,1.99206,0.9619,10,,,,,,,,,,,,,,,,,,,,,,,,,,,,,,,,,,,,,
416.44,1.99195,0.9766,10,,,,,,,,,,,,,,,,,,,,,,,,,,,,,,,,,,,,,
417.34,1.99212,0.92631,10,,,,,,,,,,,,,,,,,,,,,,,,,,,,,,,,,,,,,
418.24,1.99223,0.94707,10,,,,,,,,,,,,,,,,,,,,,,,,,,,,,,,,,,,,,
419.14,1.99257,0.96833,10,,,,,,,,,,,,,,,,,,,,,,,,,,,,,,,,,,,,,
420.04,1.99353,0.89081,10,,,,,,,,,,,,,,,,,,,,,,,,,,,,,,,,,,,,,
420.94,1.99716,0.92312,10,,,,,,,,,,,,,,,,,,,,,,,,,,,,,,,,,,,,,
421.84,2.01155,0.96189,10,,,,,,,,,,,,,,,,,,,,,,,,,,,,,,,,,,,,,
422.74,2.04839,1.07351,10,,,,,,,,,,,,,,,,,,,,,,,,,,,,,,,,,,,,,
423.64,2.0591,1.11322,10,,,,,,,,,,,,,,,,,,,,,,,,,,,,,,,,,,,,,
424.54,2.05887,1.11803,10,,,,,,,,,,,,,,,,,,,,,,,,,,,,,,,,,,,,,
425.44,2.05734,1.15419,10,,,,,,,,,,,,,,,,,,,,,,,,,,,,,,,,,,,,,
426.34,2.0464,1.11348,10,,,,,,,,,,,,,,,,,,,,,,,,,,,,,,,,,,,,,
427.24,2.00776,0.95012,10,,,,,,,,,,,,,,,,,,,,,,,,,,,,,,,,,,,,,
428.14,1.99501,1.08321,10,,,,,,,,,,,,,,,,,,,,,,,,,,,,,,,,,,,,,
429.04,1.99501,0.89699,10,,,,,,,,,,,,,,,,,,,,,,,,,,,,,,,,,,,,,
429.94,1.99518,1.00129,10,,,,,,,,,,,,,,,,,,,,,,,,,,,,,,,,,,,,,
430.84,1.9954,0.87367,10,,,,,,,,,,,,,,,,,,,,,,,,,,,,,,,,,,,,,
431.74,1.99603,0.90209,10,,,,,,,,,,,,,,,,,,,,,,,,,,,,,,,,,,,,,
432.64,1.99778,0.89698,10,,,,,,,,,,,,,,,,,,,,,,,,,,,,,,,,,,,,,
433.54,2.00487,0.8991,10,,,,,,,,,,,,,,,,,,,,,,,,,,,,,,,,,,,,,
434.44,2.05275,1.10811,10,,,,,,,,,,,,,,,,,,,,,,,,,,,,,,,,,,,,,
435.34,2.06811,1.13946,10,,,,,,,,,,,,,,,,,,,,,,,,,,,,,,,,,,,,,
436.24,2.06771,1.15597,10,,,,,,,,,,,,,,,,,,,,,,,,,,,,,,,,,,,,,
437.14,2.06442,1.20212,10,,,,,,,,,,,,,,,,,,,,,,,,,,,,,,,,,,,,,
438.04,2.02895,1.05739,10,,,,,,,,,,,,,,,,,,,,,,,,,,,,,,,,,,,,,
438.94,1.98696,0.92831,10,,,,,,,,,,,,,,,,,,,,,,,,,,,,,,,,,,,,,
439.84,1.98605,0.89467,10,,,,,,,,,,,,,,,,,,,,,,,,,,,,,,,,,,,,,
440.74,1.98622,0.94944,10,,,,,,,,,,,,,,,,,,,,,,,,,,,,,,,,,,,,,
441.64,1.98662,0.94536,10,,,,,,,,,,,,,,,,,,,,,,,,,,,,,,,,,,,,,
442.54,1.98804,0.85668,10,,,,,,,,,,,,,,,,,,,,,,,,,,,,,,,,,,,,,
443.44,1.99614,0.91333,10,,,,,,,,,,,,,,,,,,,,,,,,,,,,,,,,,,,,,
444.34,2.03513,1.03663,10,,,,,,,,,,,,,,,,,,,,,,,,,,,,,,,,,,,,,
445.24,2.06703,1.10869,10,,,,,,,,,,,,,,,,,,,,,,,,,,,,,,,,,,,,,
446.14,2.0668,1.14206,10,,,,,,,,,,,,,,,,,,,,,,,,,,,,,,,,,,,,,
447.04,2.06505,1.18331,10,,,,,,,,,,,,,,,,,,,,,,,,,,,,,,,,,,,,,
447.94,2.04215,1.15769,10,,,,,,,,,,,,,,,,,,,,,,,,,,,,,,,,,,,,,
448.84,1.98974,0.94916,10,,,,,,,,,,,,,,,,,,,,,,,,,,,,,,,,,,,,,
449.74,1.98696,0.86357,10,,,,,,,,,,,,,,,,,,,,,,,,,,,,,,,,,,,,,
450.64,1.98713,0.96573,10,,,,,,,,,,,,,,,,,,,,,,,,,,,,,,,,,,,,,
451.54,1.98736,0.91122,10,,,,,,,,,,,,,,,,,,,,,,,,,,,,,,,,,,,,,
452.44,1.98775,0.9325,10,,,,,,,,,,,,,,,,,,,,,,,,,,,,,,,,,,,,,
453.34,1.98928,0.90192,10,,,,,,,,,,,,,,,,,,,,,,,,,,,,,,,,,,,,,
454.24,1.99648,0.92483,10,,,,,,,,,,,,,,,,,,,,,,,,,,,,,,,,,,,,,
455.14,2.03326,1.01427,10,,,,,,,,,,,,,,,,,,,,,,,,,,,,,,,,,,,,,
456.04,2.06363,1.12753,10,,,,,,,,,,,,,,,,,,,,,,,,,,,,,,,,,,,,,
456.94,2.06454,1.2265,10,,,,,,,,,,,,,,,,,,,,,,,,,,,,,,,,,,,,,
457.84,2.06374,1.15565,10,,,,,,,,,,,,,,,,,,,,,,,,,,,,,,,,,,,,,
458.74,2.05048,1.10023,10,,,,,,,,,,,,,,,,,,,,,,,,,,,,,,,,,,,,,
459.64,1.99671,0.94835,10,,,,,,,,,,,,,,,,,,,,,,,,,,,,,,,,,,,,,
460.54,1.98747,0.92425,10,,,,,,,,,,,,,,,,,,,,,,,,,,,,,,,,,,,,,
461.44,1.9877,0.92351,10,,,,,,,,,,,,,,,,,,,,,,,,,,,,,,,,,,,,,
462.34,1.98792,0.92277,10,,,,,,,,,,,,,,,,,,,,,,,,,,,,,,,,,,,,,
463.24,1.98843,0.92524,10,,,,,,,,,,,,,,,,,,,,,,,,,,,,,,,,,,,,,
464.14,1.99036,0.91107,10,,,,,,,,,,,,,,,,,,,,,,,,,,,,,,,,,,,,,
465.04,1.99716,0.93867,10,,,,,,,,,,,,,,,,,,,,,,,,,,,,,,,,,,,,,
465.94,2.03926,1.07107,10,,,,,,,,,,,,,,,,,,,,,,,,,,,,,,,,,,,,,
466.84,2.06522,1.12593,10,,,,,,,,,,,,,,,,,,,,,,,,,,,,,,,,,,,,,
467.74,2.06499,1.1357,10,,,,,,,,,,,,,,,,,,,,,,,,,,,,,,,,,,,,,
468.64,2.06363,1.18631,10,,,,,,,,,,,,,,,,,,,,,,,,,,,,,,,,,,,,,
469.54,2.0417,1.09317,10,,,,,,,,,,,,,,,,,,,,,,,,,,,,,,,,,,,,,
470.44,1.98724,0.98921,10,,,,,,,,,,,,,,,,,,,,,,,,,,,,,,,,,,,,,
471.34,1.98379,0.98359,10,,,,,,,,,,,,,,,,,,,,,,,,,,,,,,,,,,,,,
472.24,1.98384,1.03599,10,,,,,,,,,,,,,,,,,,,,,,,,,,,,,,,,,,,,,
473.14,1.98418,0.93514,10,,,,,,,,,,,,,,,,,,,,,,,,,,,,,,,,,,,,,
474.04,1.98458,0.87776,10,,,,,,,,,,,,,,,,,,,,,,,,,,,,,,,,,,,,,
474.94,1.98605,0.90618,10,,,,,,,,,,,,,,,,,,,,,,,,,,,,,,,,,,,,,
475.84,1.99342,0.93643,10,,,,,,,,,,,,,,,,,,,,,,,,,,,,,,,,,,,,,
476.74,2.03467,1.04253,10,,,,,,,,,,,,,,,,,,,,,,,,,,,,,,,,,,,,,
477.64,2.06612,1.15056,10,,,,,,,,,,,,,,,,,,,,,,,,,,,,,,,,,,,,,
478.54,2.06601,1.14742,10,,,,,,,,,,,,,,,,,,,,,,,,,,,,,,,,,,,,,
479.44,2.06386,1.23459,10,,,,,,,,,,,,,,,,,,,,,,,,,,,,,,,,,,,,,
480.34,2.03309,1.02848,10,,,,,,,,,,,,,,,,,,,,,,,,,,,,,,,,,,,,,
481.24,1.98333,0.94469,10,,,,,,,,,,,,,,,,,,,,,,,,,,,,,,,,,,,,,
482.14,1.98084,0.93069,10,,,,,,,,,,,,,,,,,,,,,,,,,,,,,,,,,,,,,
483.04,1.98101,0.97881,10,,,,,,,,,,,,,,,,,,,,,,,,,,,,,,,,,,,,,
483.94,1.98118,0.95282,10,,,,,,,,,,,,,,,,,,,,,,,,,,,,,,,,,,,,,
484.84,1.98146,0.90804,10,,,,,,,,,,,,,,,,,,,,,,,,,,,,,,,,,,,,,
485.74,1.98214,0.92745,10,,,,,,,,,,,,,,,,,,,,,,,,,,,,,,,,,,,,,
486.64,1.98418,0.92087,10,,,,,,,,,,,,,,,,,,,,,,,,,,,,,,,,,,,,,
487.54,1.99331,0.96144,10,,,,,,,,,,,,,,,,,,,,,,,,,,,,,,,,,,,,,
488.44,2.0336,1.07724,10,,,,,,,,,,,,,,,,,,,,,,,,,,,,,,,,,,,,,
489.34,2.06312,1.13132,10,,,,,,,,,,,,,,,,,,,,,,,,,,,,,,,,,,,,,
490.24,2.06357,1.14182,10,,,,,,,,,,,,,,,,,,,,,,,,,,,,,,,,,,,,,
491.14,2.06261,1.19919,10,,,,,,,,,,,,,,,,,,,,,,,,,,,,,,,,,,,,,
492.04,2.0438,1.09772,10,,,,,,,,,,,,,,,,,,,,,,,,,,,,,,,,,,,,,
492.94,1.98554,0.95985,10,,,,,,,,,,,,,,,,,,,,,,,,,,,,,,,,,,,,,
493.84,1.98044,0.94315,10,,,,,,,,,,,,,,,,,,,,,,,,,,,,,,,,,,,,,
494.74,1.9805,0.88384,10,,,,,,,,,,,,,,,,,,,,,,,,,,,,,,,,,,,,,
495.64,1.98073,0.91229,10,,,,,,,,,,,,,,,,,,,,,,,,,,,,,,,,,,,,,
496.54,1.98095,0.90672,10,,,,,,,,,,,,,,,,,,,,,,,,,,,,,,,,,,,,,
497.44,1.98169,0.91928,10,,,,,,,,,,,,,,,,,,,,,,,,,,,,,,,,,,,,,
498.34,1.98435,0.87319,10,,,,,,,,,,,,,,,,,,,,,,,,,,,,,,,,,,,,,
499.24,1.99688,0.92336,10,,,,,,,,,,,,,,,,,,,,,,,,,,,,,,,,,,,,,
500.14,2.05082,1.10308,10,,,,,,,,,,,,,,,,,,,,,,,,,,,,,,,,,,,,,
501.04,2.06748,1.18917,10,,,,,,,,,,,,,,,,,,,,,,,,,,,,,,,,,,,,,
501.94,2.06697,1.22005,10,,,,,,,,,,,,,,,,,,,,,,,,,,,,,,,,,,,,,
502.84,2.06012,1.16601,10,,,,,,,,,,,,,,,,,,,,,,,,,,,,,,,,,,,,,
503.74,2.00487,0.9802,10,,,,,,,,,,,,,,,,,,,,,,,,,,,,,,,,,,,,,
504.64,1.97506,0.91734,10,,,,,,,,,,,,,,,,,,,,,,,,,,,,,,,,,,,,,
505.54,1.975,0.88879,10,,,,,,,,,,,,,,,,,,,,,,,,,,,,,,,,,,,,,
506.44,1.97529,0.88016,10,,,,,,,,,,,,,,,,,,,,,,,,,,,,,,,,,,,,,
507.34,1.97597,0.88875,10,,,,,,,,,,,,,,,,,,,,,,,,,,,,,,,,,,,,,
508.24,1.97914,0.89401,10,,,,,,,,,,,,,,,,,,,,,,,,,,,,,,,,,,,,,
509.14,1.99495,0.90498,10,,,,,,,,,,,,,,,,,,,,,,,,,,,,,,,,,,,,,
510.04,2.05224,1.08122,10,,,,,,,,,,,,,,,,,,,,,,,,,,,,,,,,,,,,,
510.94,2.06924,1.20782,10,,,,,,,,,,,,,,,,,,,,,,,,,,,,,,,,,,,,,
511.84,2.06873,1.18662,10,,,,,,,,,,,,,,,,,,,,,,,,,,,,,,,,,,,,,
512.74,2.06102,1.14671,10,,,,,,,,,,,,,,,,,,,,,,,,,,,,,,,,,,,,,
513.64,2.00436,1.00019,10,,,,,,,,,,,,,,,,,,,,,,,,,,,,,,,,,,,,,
514.54,1.97631,0.8902,10,,,,,,,,,,,,,,,,,,,,,,,,,,,,,,,,,,,,,
515.44,1.97636,0.93319,10,,,,,,,,,,,,,,,,,,,,,,,,,,,,,,,,,,,,,
516.34,1.97665,0.90981,10,,,,,,,,,,,,,,,,,,,,,,,,,,,,,,,,,,,,,
517.24,1.97733,0.87664,10,,,,,,,,,,,,,,,,,,,,,,,,,,,,,,,,,,,,,
518.14,1.97999,0.91514,10,,,,,,,,,,,,,,,,,,,,,,,,,,,,,,,,,,,,,
519.04,1.99297,0.88345,10,,,,,,,,,,,,,,,,,,,,,,,,,,,,,,,,,,,,,
519.94,2.05054,1.12675,10,,,,,,,,,,,,,,,,,,,,,,,,,,,,,,,,,,,,,
520.84,2.06743,1.18454,10,,,,,,,,,,,,,,,,,,,,,,,,,,,,,,,,,,,,,
521.74,2.06692,1.20803,10,,,,,,,,,,,,,,,,,,,,,,,,,,,,,,,,,,,,,
522.64,2.05949,1.21256,10,,,,,,,,,,,,,,,,,,,,,,,,,,,,,,,,,,,,,
523.54,1.99903,0.98686,10,,,,,,,,,,,,,,,,,,,,,,,,,,,,,,,,,,,,,
524.44,1.97285,0.93612,10,,,,,,,,,,,,,,,,,,,,,,,,,,,,,,,,,,,,,
525.34,1.97285,0.9945,10,,,,,,,,,,,,,,,,,,,,,,,,,,,,,,,,,,,,,
526.24,1.97313,0.90785,10,,,,,,,,,,,,,,,,,,,,,,,,,,,,,,,,,,,,,
527.14,1.97393,0.86481,10,,,,,,,,,,,,,,,,,,,,,,,,,,,,,,,,,,,,,
528.04,1.97914,0.86804,10,,,,,,,,,,,,,,,,,,,,,,,,,,,,,,,,,,,,,
528.94,2.00594,0.96938,10,,,,,,,,,,,,,,,,,,,,,,,,,,,,,,,,,,,,,
529.84,2.05683,1.09685,10,,,,,,,,,,,,,,,,,,,,,,,,,,,,,,,,,,,,,
530.74,2.06771,1.17833,10,,,,,,,,,,,,,,,,,,,,,,,,,,,,,,,,,,,,,
531.64,2.06686,1.21993,10,,,,,,,,,,,,,,,,,,,,,,,,,,,,,,,,,,,,,
532.54,2.05541,1.13602,10,,,,,,,,,,,,,,,,,,,,,,,,,,,,,,,,,,,,,
533.44,1.98758,0.96741,10,,,,,,,,,,,,,,,,,,,,,,,,,,,,,,,,,,,,,
534.34,1.97172,0.96516,10,,,,,,,,,,,,,,,,,,,,,,,,,,,,,,,,,,,,,
535.24,1.97194,0.90778,10,,,,,,,,,,,,,,,,,,,,,,,,,,,,,,,,,,,,,
536.14,1.97228,0.83796,10,,,,,,,,,,,,,,,,,,,,,,,,,,,,,,,,,,,,,
537.04,1.9733,0.83244,10,,,,,,,,,,,,,,,,,,,,,,,,,,,,,,,,,,,,,
537.94,1.97993,0.91902,10,,,,,,,,,,,,,,,,,,,,,,,,,,,,,,,,,,,,,
538.84,2.02056,0.9702,10,,,,,,,,,,,,,,,,,,,,,,,,,,,,,,,,,,,,,
539.74,2.06969,1.19023,10,,,,,,,,,,,,,,,,,,,,,,,,,,,,,,,,,,,,,
540.64,2.07032,1.20472,10,,,,,,,,,,,,,,,,,,,,,,,,,,,,,,,,,,,,,
541.54,2.06748,1.17738,10,,,,,,,,,,,,,,,,,,,,,,,,,,,,,,,,,,,,,
542.44,2.03343,1.12488,10,,,,,,,,,,,,,,,,,,,,,,,,,,,,,,,,,,,,,
543.34,1.97262,0.88031,10,,,,,,,,,,,,,,,,,,,,,,,,,,,,,,,,,,,,,
544.24,1.96979,0.88822,10,,,,,,,,,,,,,,,,,,,,,,,,,,,,,,,,,,,,,
545.14,1.97007,0.8677,10,,,,,,,,,,,,,,,,,,,,,,,,,,,,,,,,,,,,,
546.04,1.97058,0.87388,10,,,,,,,,,,,,,,,,,,,,,,,,,,,,,,,,,,,,,
546.94,1.97353,0.88845,10,,,,,,,,,,,,,,,,,,,,,,,,,,,,,,,,,,,,,
547.84,1.99597,0.93203,10,,,,,,,,,,,,,,,,,,,,,,,,,,,,,,,,,,,,,
548.74,2.05813,1.19081,10,,,,,,,,,,,,,,,,,,,,,,,,,,,,,,,,,,,,,
549.64,2.07009,1.18232,10,,,,,,,,,,,,,,,,,,,,,,,,,,,,,,,,,,,,,
550.54,2.06879,1.229,10,,,,,,,,,,,,,,,,,,,,,,,,,,,,,,,,,,,,,
551.44,2.04884,1.15881,10,,,,,,,,,,,,,,,,,,,,,,,,,,,,,,,,,,,,,
552.34,1.97342,0.88423,10,,,,,,,,,,,,,,,,,,,,,,,,,,,,,,,,,,,,,
553.24,1.96594,0.9164,10,,,,,,,,,,,,,,,,,,,,,,,,,,,,,,,,,,,,,
554.14,1.96622,0.89996,10,,,,,,,,,,,,,,,,,,,,,,,,,,,,,,,,,,,,,
555.04,1.96684,0.83028,10,,,,,,,,,,,,,,,,,,,,,,,,,,,,,,,,,,,,,
555.94,1.96905,0.88629,10,,,,,,,,,,,,,,,,,,,,,,,,,,,,,,,,,,,,,
556.84,1.99291,0.91655,10,,,,,,,,,,,,,,,,,,,,,,,,,,,,,,,,,,,,,
557.74,2.06023,1.14318,10,,,,,,,,,,,,,,,,,,,,,,,,,,,,,,,,,,,,,
558.64,2.07304,1.18624,10,,,,,,,,,,,,,,,,,,,,,,,,,,,,,,,,,,,,,
559.54,2.07224,1.22808,10,,,,,,,,,,,,,,,,,,,,,,,,,,,,,,,,,,,,,
560.44,2.05825,1.20483,10,,,,,,,,,,,,,,,,,,,,,,,,,,,,,,,,,,,,,
561.34,1.99115,0.91735,10,,,,,,,,,,,,,,,,,,,,,,,,,,,,,,,,,,,,,
562.24,1.96866,0.87928,10,,,,,,,,,,,,,,,,,,,,,,,,,,,,,,,,,,,,,
563.14,1.96888,0.91451,10,,,,,,,,,,,,,,,,,,,,,,,,,,,,,,,,,,,,,
564.04,1.96934,0.9583,10,,,,,,,,,,,,,,,,,,,,,,,,,,,,,,,,,,,,,
564.94,1.97115,0.90398,10,,,,,,,,,,,,,,,,,,,,,,,,,,,,,,,,,,,,,
565.84,1.99002,0.86489,10,,,,,,,,,,,,,,,,,,,,,,,,,,,,,,,,,,,,,
566.74,2.06136,1.14358,10,,,,,,,,,,,,,,,,,,,,,,,,,,,,,,,,,,,,,
567.64,2.07553,1.2011,10,,,,,,,,,,,,,,,,,,,,,,,,,,,,,,,,,,,,,
568.54,2.07428,1.24641,10,,,,,,,,,,,,,,,,,,,,,,,,,,,,,,,,,,,,,
569.44,2.05145,1.21881,10,,,,,,,,,,,,,,,,,,,,,,,,,,,,,,,,,,,,,
570.34,1.97274,0.88682,10,,,,,,,,,,,,,,,,,,,,,,,,,,,,,,,,,,,,,
571.24,1.96333,0.87422,10,,,,,,,,,,,,,,,,,,,,,,,,,,,,,,,,,,,,,
572.14,1.96361,0.84968,10,,,,,,,,,,,,,,,,,,,,,,,,,,,,,,,,,,,,,
573.04,1.96412,0.84528,10,,,,,,,,,,,,,,,,,,,,,,,,,,,,,,,,,,,,,
573.94,1.96684,0.8755,10,,,,,,,,,,,,,,,,,,,,,,,,,,,,,,,,,,,,,
574.84,1.99342,0.9218,10,,,,,,,,,,,,,,,,,,,,,,,,,,,,,,,,,,,,,
575.74,2.06743,1.15418,10,,,,,,,,,,,,,,,,,,,,,,,,,,,,,,,,,,,,,
576.64,2.07695,1.16786,10,,,,,,,,,,,,,,,,,,,,,,,,,,,,,,,,,,,,,
577.54,2.07508,1.22337,10,,,,,,,,,,,,,,,,,,,,,,,,,,,,,,,,,,,,,
578.44,2.04351,1.273,10,,,,,,,,,,,,,,,,,,,,,,,,,,,,,,,,,,,,,
579.34,1.97557,0.91453,10,,,,,,,,,,,,,,,,,,,,,,,,,,,,,,,,,,,,,
580.24,1.96616,0.90991,10,,,,,,,,,,,,,,,,,,,,,,,,,,,,,,,,,,,,,
581.14,1.9665,0.90422,10,,,,,,,,,,,,,,,,,,,,,,,,,,,,,,,,,,,,,
582.04,1.96724,0.8143,10,,,,,,,,,,,,,,,,,,,,,,,,,,,,,,,,,,,,,
582.94,1.97098,0.84474,10,,,,,,,,,,,,,,,,,,,,,,,,,,,,,,,,,,,,,
583.84,2.02164,1.00123,10,,,,,,,,,,,,,,,,,,,,,,,,,,,,,,,,,,,,,
584.74,2.07819,1.2193,10,,,,,,,,,,,,,,,,,,,,,,,,,,,,,,,,,,,,,
585.64,2.07802,1.19103,10,,,,,,,,,,,,,,,,,,,,,,,,,,,,,,,,,,,,,
586.54,2.07196,1.15422,10,,,,,,,,,,,,,,,,,,,,,,,,,,,,,,,,,,,,,
587.44,2.01705,1.04974,10,,,,,,,,,,,,,,,,,,,,,,,,,,,,,,,,,,,,,
588.34,1.96599,0.86837,10,,,,,,,,,,,,,,,,,,,,,,,,,,,,,,,,,,,,,
589.24,1.96537,0.84582,10,,,,,,,,,,,,,,,,,,,,,,,,,,,,,,,,,,,,,
590.14,1.96571,0.80907,10,,,,,,,,,,,,,,,,,,,,,,,,,,,,,,,,,,,,,
591.04,1.96673,0.82664,10,,,,,,,,,,,,,,,,,,,,,,,,,,,,,,,,,,,,,
591.94,1.97359,0.8505,10,,,,,,,,,,,,,,,,,,,,,,,,,,,,,,,,,,,,,
592.84,2.04187,1.08078,10,,,,,,,,,,,,,,,,,,,,,,,,,,,,,,,,,,,,,
593.74,2.07836,1.17857,10,,,,,,,,,,,,,,,,,,,,,,,,,,,,,,,,,,,,,
594.64,2.07774,1.25252,10,,,,,,,,,,,,,,,,,,,,,,,,,,,,,,,,,,,,,
595.54,2.0651,1.18147,10,,,,,,,,,,,,,,,,,,,,,,,,,,,,,,,,,,,,,
596.44,1.99223,0.95866,10,,,,,,,,,,,,,,,,,,,,,,,,,,,,,,,,,,,,,
597.34,1.96503,0.88318,10,,,,,,,,,,,,,,,,,,,,,,,,,,,,,,,,,,,,,
598.24,1.9652,0.86433,10,,,,,,,,,,,,,,,,,,,,,,,,,,,,,,,,,,,,,
599.14,1.96565,0.82332,10,,,,,,,,,,,,,,,,,,,,,,,,,,,,,,,,,,,,,
600.04,1.9669,0.87315,10,,,,,,,,,,,,,,,,,,,,,,,,,,,,,,,,,,,,,
600.94,1.97172,0.92969,10,,,,,,,,,,,,,,,,,,,,,,,,,,,,,,,,,,,,,
601.84,2.02396,1.09457,10,,,,,,,,,,,,,,,,,,,,,,,,,,,,,,,,,,,,,
602.74,2.05184,1.22641,10,,,,,,,,,,,,,,,,,,,,,,,,,,,,,,,,,,,,,
603.64,2.05156,1.19855,10,,,,,,,,,,,,,,,,,,,,,,,,,,,,,,,,,,,,,
604.54,2.04822,1.17362,10,,,,,,,,,,,,,,,,,,,,,,,,,,,,,,,,,,,,,
605.44,2.00957,1.098,10,,,,,,,,,,,,,,,,,,,,,,,,,,,,,,,,,,,,,
606.34,1.97449,0.91476,10,,,,,,,,,,,,,,,,,,,,,,,,,,,,,,,,,,,,,
607.24,1.96492,0.8835,10,,,,,,,,,,,,,,,,,,,,,,,,,,,,,,,,,,,,,
608.14,1.96509,0.90831,10,,,,,,,,,,,,,,,,,,,,,,,,,,,,,,,,,,,,,
609.04,1.96531,0.89195,10,,,,,,,,,,,,,,,,,,,,,,,,,,,,,,,,,,,,,
609.94,1.96582,0.88508,10,,,,,,,,,,,,,,,,,,,,,,,,,,,,,,,,,,,,,
610.84,1.96786,0.8531,10,,,,,,,,,,,,,,,,,,,,,,,,,,,,,,,,,,,,,
611.74,1.97914,0.86393,10,,,,,,,,,,,,,,,,,,,,,,,,,,,,,,,,,,,,,
612.64,2.05128,1.14456,10,,,,,,,,,,,,,,,,,,,,,,,,,,,,,,,,,,,,,
613.54,2.05921,1.24464,10,,,,,,,,,,,,,,,,,,,,,,,,,,,,,,,,,,,,,
614.44,2.05745,1.29245,10,,,,,,,,,,,,,,,,,,,,,,,,,,,,,,,,,,,,,
615.34,2.02045,1.05447,10,,,,,,,,,,,,,,,,,,,,,,,,,,,,,,,,,,,,,
616.24,1.97098,0.92254,10,,,,,,,,,,,,,,,,,,,,,,,,,,,,,,,,,,,,,
617.14,1.96163,0.95291,10,,,,,,,,,,,,,,,,,,,,,,,,,,,,,,,,,,,,,
618.04,1.96174,0.96162,10,,,,,,,,,,,,,,,,,,,,,,,,,,,,,,,,,,,,,
618.94,1.96191,0.94025,10,,,,,,,,,,,,,,,,,,,,,,,,,,,,,,,,,,,,,
619.84,1.96225,0.87175,10,,,,,,,,,,,,,,,,,,,,,,,,,,,,,,,,,,,,,
620.74,1.9635,0.84861,10,,,,,,,,,,,,,,,,,,,,,,,,,,,,,,,,,,,,,
621.64,1.97013,0.83948,10,,,,,,,,,,,,,,,,,,,,,,,,,,,,,,,,,,,,,
622.54,2.02544,1.09798,10,,,,,,,,,,,,,,,,,,,,,,,,,,,,,,,,,,,,,
623.44,2.05768,1.16306,10,,,,,,,,,,,,,,,,,,,,,,,,,,,,,,,,,,,,,
624.34,2.05734,1.1307,10,,,,,,,,,,,,,,,,,,,,,,,,,,,,,,,,,,,,,
625.24,2.05156,1.16898,10,,,,,,,,,,,,,,,,,,,,,,,,,,,,,,,,,,,,,
626.14,2.00045,1.03763,10,,,,,,,,,,,,,,,,,,,,,,,,,,,,,,,,,,,,,
627.04,1.96208,0.91592,10,,,,,,,,,,,,,,,,,,,,,,,,,,,,,,,,,,,,,
627.94,1.96129,0.87258,10,,,,,,,,,,,,,,,,,,,,,,,,,,,,,,,,,,,,,
628.84,1.96152,0.88655,10,,,,,,,,,,,,,,,,,,,,,,,,,,,,,,,,,,,,,
629.74,1.96191,0.8444,10,,,,,,,,,,,,,,,,,,,,,,,,,,,,,,,,,,,,,
630.64,1.9635,0.87927,10,,,,,,,,,,,,,,,,,,,,,,,,,,,,,,,,,,,,,
631.54,1.97245,0.94608,10,,,,,,,,,,,,,,,,,,,,,,,,,,,,,,,,,,,,,
632.44,2.04232,1.14138,10,,,,,,,,,,,,,,,,,,,,,,,,,,,,,,,,,,,,,
633.34,2.06522,1.25156,10,,,,,,,,,,,,,,,,,,,,,,,,,,,,,,,,,,,,,
634.24,2.06454,1.26283,10,,,,,,,,,,,,,,,,,,,,,,,,,,,,,,,,,,,,,
635.14,2.03615,1.16797,10,,,,,,,,,,,,,,,,,,,,,,,,,,,,,,,,,,,,,
636.04,1.97121,0.95292,10,,,,,,,,,,,,,,,,,,,,,,,,,,,,,,,,,,,,,
636.94,1.95795,0.9116,10,,,,,,,,,,,,,,,,,,,,,,,,,,,,,,,,,,,,,
637.84,1.95812,0.89678,10,,,,,,,,,,,,,,,,,,,,,,,,,,,,,,,,,,,,,
638.74,1.9584,0.86149,10,,,,,,,,,,,,,,,,,,,,,,,,,,,,,,,,,,,,,
639.542,4.99205,40.5812,10,,,,,,,,,,,,,,,,,,,,,,,,,,,,,,,,,,,,,
640.442,12.49222,458.46619,10,,,,,,,,,,,,,,,,,,,,,,,,,,,,,,,,,,,,,
641.342,19.99223,57.69966,10,,,,,,,,,,,,,,,,,,,,,,,,,,,,,,,,,,,,,
642.242,27.49206,34.76847,10,,,,,,,,,,,,,,,,,,,,,,,,,,,,,,,,,,,,,
643.142,34.99217,24.44587,10,,,,,,,,,,,,,,,,,,,,,,,,,,,,,,,,,,,,,
644.042,42.49212,18.07477,10,,,,,,,,,,,,,,,,,,,,,,,,,,,,,,,,,,,,,
644.942,49.99218,18.15674,10,,,,,,,,,,,,,,,,,,,,,,,,,,,,,,,,,,,,,
645.842,57.49207,7.86787,10,,,,,,,,,,,,,,,,,,,,,,,,,,,,,,,,,,,,,
646.742,64.99213,0.03145,10,,,,,,,,,,,,,,,,,,,,,,,,,,,,,,,,,,,,,
647.642,72.49202,-0.02159,10,,,,,,,,,,,,,,,,,,,,,,,,,,,,,,,,,,,,,
648.542,79.99208,-0.02294,10,,,,,,,,,,,,,,,,,,,,,,,,,,,,,,,,,,,,,
648.854,82.59212,0.02515,10,,,,,,,,,,,,,,,,,,,,,,,,,,,,,,,,,,,,,