File: combined_ligament_solver/data/processed/Data Sheet 3_S151568_LCL.csv
Specimen properties : Length,50,mm,Unnamed: 3,Unnamed: 4,Unnamed: 5,Unnamed: 6,Unnamed: 7,Unnamed: 8,Unnamed: 9,Unnamed: 10,Unnamed: 11,Stress-Strain,Unnamed: 13,Unnamed: 14,Unnamed: 15,Unnamed: 16,Unnamed: 17,Unnamed: 18,Unnamed: 19,Unnamed: 20,Unnamed: 21,Unnamed: 22,Unnamed: 23,Unnamed: 24,Unnamed: 25,Unnamed: 26,Unnamed: 27,Linear,Unnamed: 29,Unnamed: 30,Unnamed: 31,Unnamed: 32,Unnamed: 33,Modulus,Unnamed: 35,Failure,Unnamed: 37,Unnamed: 38,Unnamed: 39,Unnamed: 40
Cross Section Average,39.912000000000006,mm2,,,,,,,,,,Polynomial Coefficients,,,,,,,,,,,,,,,,Force,,Stress,Extension,Strain,,Secant,Tangent,Load,Stress,Extension,Strain,Stiffness
Time,Extension,Load,Total cycle count,,,Extension,Load,Strain,Stress,E-tan,,X6,4572544.664309147,,,,,,,,,Strain,Stress,E-tan,,,,(N),,(MPa),(mm),(%),,(MPa),(MPa),(N),(MPa),(mm),(%),(N/mm)
(s),(mm),(N),,,,(mm),(N),(mm/mm),(MPa),(MPa),,X5,-1755243.0227116218,,,,,,,,,(mm/mm),(MPa),(MPa),,,,178.58004105618423,,4.474344584490484,5.7,11.4,,39.24863670605688,82.16936403692091,279.39996,6.973308528763278,7.200009999999998,14.400019999999996,31.32983176424285
0.9,7.25509,0.98959,0,,,15.88412,279.39996,0.14400019999999997,6.973308528763278,,,,,,,,,,,,,0.009,0.019335626258995837,2.7913894725042896,,,,,,,,,,,,,,,,
1.9,7.42175,1.03364,0,,,24.21746,181.33638,,,,,,,,,,,,,,,0.019,0.05554552924784771,4.478149835774314,,,,,,,,,,,,,,,,
2.9,7.58846,1.18741,0,,,32.55086,41.60419,,,,,,,,,,,,,,,0.029,0.11907793759936666,8.328097431492173,,,,,,,,,,,,,,,,
3.9,7.75506,1.27761,0,,,,,,,,,,,,,,,,,,,0.039,0.23849654271030024,15.401670439562627,,,,,,,,,,,,,,,,
4.9,7.92172,1.40283,0,,,,,,,,,,,,,,,,,,,0.049,0.44627377858162454,25.591301577752386,,,,,,,,,,,,,,,,
5.9,8.08832,1.63707,0,,,,,,,,,,,,,,,,,,,0.059,0.7689214948842334,37.95064131752136,,,,,,,,,,,,,,,,
6.9,8.25492,1.88807,0,,,,,,,,,,,,,,,,,,,0.069,1.2204138621829292,51.02378109984946,,,,,,,,,,,,,,,,
7.9,8.42169,2.17604,0,,,,,,,,,,,,,,,,,,,0.079,1.7989025093187216,63.17447655107549,,,,,,,,,,,,,,,,
8.9,8.58823,2.67467,0,,,,,,,,,,,,,,,,,,,0.089,2.48672389294942,72.91537069871882,,,,,,,,,,,,,,,,
9.9,8.755,3.18806,0,,,,,,,,,,,,,,,,,,,0.099,3.2536988992485343,79.23721718730629,,,,,,,,,,,,,,,,
10.9,8.9216,3.8056,0,,,,,,,,,,,,,,,,,,,0.109,4.063724677762469,81.93810349421585,,,,,,,,,,,,,,,,
11.9,9.08837,4.58766,0,,,,,,,,,,,,,,,,,,,0.119,4.884658707426063,81.9526741454987,,,,,,,,,,,,,,,,
12.9,9.25497,5.40828,0,,,,,,,,,,,,,,,,,,,0.129,5.701495094736337,81.68135393171907,,,,,,,,,,,,,,,,
13.9,9.42168,6.33674,0,,,,,,,,,,,,,,,,,,,0.139,,,,,,,,,,,,,,,,,,
14.9,9.58834,7.36751,0,,,,,,,,,,,,,,,,,,,0.149,,,,,,,,,,,,,,,,,,
15.9,9.755,8.76633,0,,,,,,,,,,,,,,,,,,,0.159,,,,,,,,,,,,,,,,,,
16.9,9.92182,10.43435,0,,,,,,,,,,,,,,,,,,,0.169,,,,,,,,,,,,,,,,,,
17.9,10.08837,12.28205,0,,,,,,,,,,,,,,,,,,,0.179,,,,,,,,,,,,,,,,,,
18.9,10.25519,14.47074,0,,,,,,,,,,,,,,,,,,,0.189,,,,,,,,,,,,,,,,,,
19.9,10.42174,17.14199,0,,,,,,,,,,,,,,,,,,,0.199,,,,,,,,,,,,,,,,,,
20.9,10.58839,19.1718,0,,,,,,,,,,,,,,,,,,,,,,,,,,,,,,,,,,,,,
21.9,10.75505,22.23894,0,,,,,,,,,,,,,,,,,,,,,,,,,,,,,,,,,,,,,
22.9,10.92165,25.75902,0,,,,,,,,,,,,,,,,,,,,,,,,,,,,,,,,,,,,,
23.9,11.08831,29.77657,0,,,,,,,,,,,,,,,,,,,,,,,,,,,,,,,,,,,,,
24.9,11.25491,34.13564,0,,,,,,,,,,,,,,,,,,,,,,,,,,,,,,,,,,,,,
25.9,11.42173,38.96906,0,,,,,,,,,,,,,,,,,,,,,,,,,,,,,,,,,,,,,
26.716,11.35742,35.53643,0.5,,,,,,,,,,,,,,,,,,,,,,,,,,,,,,,,,,,,,
27.716,11.1907,28.99936,0.5,,,,,,,,,,,,,,,,,,,,,,,,,,,,,,,,,,,,,
28.716,11.02399,23.61924,0.5,,,,,,,,,,,,,,,,,,,,,,,,,,,,,,,,,,,,,
29.716,10.85722,19.22107,0.5,,,,,,,,,,,,,,,,,,,,,,,,,,,,,,,,,,,,,
30.716,10.69062,15.41741,0.5,,,,,,,,,,,,,,,,,,,,,,,,,,,,,,,,,,,,,
31.716,10.52396,12.39602,0.5,,,,,,,,,,,,,,,,,,,,,,,,,,,,,,,,,,,,,
32.716,10.35731,10.19293,0.5,,,,,,,,,,,,,,,,,,,,,,,,,,,,,,,,,,,,,
33.716,10.19065,8.16344,0.5,,,,,,,,,,,,,,,,,,,,,,,,,,,,,,,,,,,,,
34.716,10.02411,6.75176,0.5,,,,,,,,,,,,,,,,,,,,,,,,,,,,,,,,,,,,,
35.716,9.85745,5.52206,0.5,,,,,,,,,,,,,,,,,,,,,,,,,,,,,,,,,,,,,
36.716,9.69074,4.43446,0.5,,,,,,,,,,,,,,,,,,,,,,,,,,,,,,,,,,,,,
37.716,9.52414,3.58855,0.5,,,,,,,,,,,,,,,,,,,,,,,,,,,,,,,,,,,,,
38.716,9.35737,2.86521,0.5,,,,,,,,,,,,,,,,,,,,,,,,,,,,,,,,,,,,,
39.716,9.19077,2.35231,0.5,,,,,,,,,,,,,,,,,,,,,,,,,,,,,,,,,,,,,
40.716,9.02411,1.9585,0.5,,,,,,,,,,,,,,,,,,,,,,,,,,,,,,,,,,,,,
41.716,8.8574,1.67546,0.5,,,,,,,,,,,,,,,,,,,,,,,,,,,,,,,,,,,,,
42.716,8.69074,1.48176,0.5,,,,,,,,,,,,,,,,,,,,,,,,,,,,,,,,,,,,,
43.716,8.52408,1.27268,0.5,,,,,,,,,,,,,,,,,,,,,,,,,,,,,,,,,,,,,
44.716,8.35737,1.12319,0.5,,,,,,,,,,,,,,,,,,,,,,,,,,,,,,,,,,,,,
45.5,8.29385,1.06641,1,,,,,,,,,,,,,,,,,,,,,,,,,,,,,,,,,,,,,
46.5,8.46101,1.2267,1,,,,,,,,,,,,,,,,,,,,,,,,,,,,,,,,,,,,,
47.5,8.62767,1.47506,1,,,,,,,,,,,,,,,,,,,,,,,,,,,,,,,,,,,,,
48.5,8.79427,1.75755,1,,,,,,,,,,,,,,,,,,,,,,,,,,,,,,,,,,,,,
49.5,8.9611,2.10374,1,,,,,,,,,,,,,,,,,,,,,,,,,,,,,,,,,,,,,
50.5,9.12775,2.60715,1,,,,,,,,,,,,,,,,,,,,,,,,,,,,,,,,,,,,,
51.5,9.29452,3.3168,1,,,,,,,,,,,,,,,,,,,,,,,,,,,,,,,,,,,,,
52.5,9.46107,4.24232,1,,,,,,,,,,,,,,,,,,,,,,,,,,,,,,,,,,,,,
53.5,9.62784,5.27804,1,,,,,,,,,,,,,,,,,,,,,,,,,,,,,,,,,,,,,
54.5,9.79438,6.42143,1,,,,,,,,,,,,,,,,,,,,,,,,,,,,,,,,,,,,,
55.5,9.96098,7.62735,1,,,,,,,,,,,,,,,,,,,,,,,,,,,,,,,,,,,,,
56.5,10.12769,9.33532,1,,,,,,,,,,,,,,,,,,,,,,,,,,,,,,,,,,,,,
57.5,10.29429,11.54523,1,,,,,,,,,,,,,,,,,,,,,,,,,,,,,,,,,,,,,
58.5,10.46095,13.99149,1,,,,,,,,,,,,,,,,,,,,,,,,,,,,,,,,,,,,,
59.5,10.62755,16.72447,1,,,,,,,,,,,,,,,,,,,,,,,,,,,,,,,,,,,,,
60.5,10.79438,19.16509,1,,,,,,,,,,,,,,,,,,,,,,,,,,,,,,,,,,,,,
61.5,10.96098,22.85651,1,,,,,,,,,,,,,,,,,,,,,,,,,,,,,,,,,,,,,
62.5,11.12769,26.94105,1,,,,,,,,,,,,,,,,,,,,,,,,,,,,,,,,,,,,,
63.5,11.29434,31.81365,1,,,,,,,,,,,,,,,,,,,,,,,,,,,,,,,,,,,,,
64.5,11.46095,37.05312,1,,,,,,,,,,,,,,,,,,,,,,,,,,,,,,,,,,,,,
65.348,11.5022,37.94549,1.5,,,,,,,,,,,,,,,,,,,,,,,,,,,,,,,,,,,,,
66.348,11.33549,30.94071,1.5,,,,,,,,,,,,,,,,,,,,,,,,,,,,,,,,,,,,,
67.348,11.16872,25.30848,1.5,,,,,,,,,,,,,,,,,,,,,,,,,,,,,,,,,,,,,
68.348,11.00212,20.45067,1.5,,,,,,,,,,,,,,,,,,,,,,,,,,,,,,,,,,,,,
69.348,10.8354,16.5306,1.5,,,,,,,,,,,,,,,,,,,,,,,,,,,,,,,,,,,,,
70.348,10.6688,13.24938,1.5,,,,,,,,,,,,,,,,,,,,,,,,,,,,,,,,,,,,,
71.348,10.50203,10.77016,1.5,,,,,,,,,,,,,,,,,,,,,,,,,,,,,,,,,,,,,
72.348,10.33543,8.62088,1.5,,,,,,,,,,,,,,,,,,,,,,,,,,,,,,,,,,,,,
73.348,10.16872,7.14153,1.5,,,,,,,,,,,,,,,,,,,,,,,,,,,,,,,,,,,,,
74.348,10.002,5.7961,1.5,,,,,,,,,,,,,,,,,,,,,,,,,,,,,,,,,,,,,
75.348,9.83529,4.60898,1.5,,,,,,,,,,,,,,,,,,,,,,,,,,,,,,,,,,,,,
76.348,9.66858,3.67918,1.5,,,,,,,,,,,,,,,,,,,,,,,,,,,,,,,,,,,,,
77.348,9.50198,2.96673,1.5,,,,,,,,,,,,,,,,,,,,,,,,,,,,,,,,,,,,,
78.348,9.33527,2.42053,1.5,,,,,,,,,,,,,,,,,,,,,,,,,,,,,,,,,,,,,
79.348,9.16867,2.01543,1.5,,,,,,,,,,,,,,,,,,,,,,,,,,,,,,,,,,,,,
80.348,9.00201,1.70714,1.5,,,,,,,,,,,,,,,,,,,,,,,,,,,,,,,,,,,,,
81.348,8.83547,1.47397,1.5,,,,,,,,,,,,,,,,,,,,,,,,,,,,,,,,,,,,,
82.348,8.66875,1.27274,1.5,,,,,,,,,,,,,,,,,,,,,,,,,,,,,,,,,,,,,
83.348,8.5021,1.14928,1.5,,,,,,,,,,,,,,,,,,,,,,,,,,,,,,,,,,,,,
84.222,8.35635,1.00035,2,,,,,,,,,,,,,,,,,,,,,,,,,,,,,,,,,,,,,
85.124,8.50708,1.1557,2,,,,,,,,,,,,,,,,,,,,,,,,,,,,,,,,,,,,,
86.124,8.67374,1.33168,2,,,,,,,,,,,,,,,,,,,,,,,,,,,,,,,,,,,,,
87.124,8.84045,1.59822,2,,,,,,,,,,,,,,,,,,,,,,,,,,,,,,,,,,,,,
88.124,9.00711,1.95015,2,,,,,,,,,,,,,,,,,,,,,,,,,,,,,,,,,,,,,
89.124,9.17377,2.37127,2,,,,,,,,,,,,,,,,,,,,,,,,,,,,,,,,,,,,,
90.124,9.34042,3.01083,2,,,,,,,,,,,,,,,,,,,,,,,,,,,,,,,,,,,,,
91.124,9.50697,3.86092,2,,,,,,,,,,,,,,,,,,,,,,,,,,,,,,,,,,,,,
92.124,9.67368,4.92928,2,,,,,,,,,,,,,,,,,,,,,,,,,,,,,,,,,,,,,
93.124,9.84022,6.05092,2,,,,,,,,,,,,,,,,,,,,,,,,,,,,,,,,,,,,,
94.124,10.00699,7.18898,2,,,,,,,,,,,,,,,,,,,,,,,,,,,,,,,,,,,,,
95.124,10.17359,8.79283,2,,,,,,,,,,,,,,,,,,,,,,,,,,,,,,,,,,,,,
96.124,10.34036,10.98804,2,,,,,,,,,,,,,,,,,,,,,,,,,,,,,,,,,,,,,
97.124,10.50702,13.37719,2,,,,,,,,,,,,,,,,,,,,,,,,,,,,,,,,,,,,,
98.124,10.67368,16.13803,2,,,,,,,,,,,,,,,,,,,,,,,,,,,,,,,,,,,,,
99.124,10.84033,18.72766,2,,,,,,,,,,,,,,,,,,,,,,,,,,,,,,,,,,,,,
100.124,11.00699,22.07446,2,,,,,,,,,,,,,,,,,,,,,,,,,,,,,,,,,,,,,
101.124,11.17376,26.23108,2,,,,,,,,,,,,,,,,,,,,,,,,,,,,,,,,,,,,,
102.124,11.34036,31.12245,2,,,,,,,,,,,,,,,,,,,,,,,,,,,,,,,,,,,,,
103.124,11.50713,36.57164,2,,,,,,,,,,,,,,,,,,,,,,,,,,,,,,,,,,,,,
103.928,11.57462,38.72794,2.5,,,,,,,,,,,,,,,,,,,,,,,,,,,,,,,,,,,,,
104.928,11.40745,31.49923,2.5,,,,,,,,,,,,,,,,,,,,,,,,,,,,,,,,,,,,,
105.928,11.24074,25.69448,2.5,,,,,,,,,,,,,,,,,,,,,,,,,,,,,,,,,,,,,
106.928,11.07403,20.87281,2.5,,,,,,,,,,,,,,,,,,,,,,,,,,,,,,,,,,,,,
107.928,10.90737,16.82045,2.5,,,,,,,,,,,,,,,,,,,,,,,,,,,,,,,,,,,,,
108.928,10.7406,13.47204,2.5,,,,,,,,,,,,,,,,,,,,,,,,,,,,,,,,,,,,,
109.928,10.57394,10.95733,2.5,,,,,,,,,,,,,,,,,,,,,,,,,,,,,,,,,,,,,
110.928,10.40723,8.77956,2.5,,,,,,,,,,,,,,,,,,,,,,,,,,,,,,,,,,,,,
111.928,10.24057,7.41208,2.5,,,,,,,,,,,,,,,,,,,,,,,,,,,,,,,,,,,,,
112.928,10.07397,5.88968,2.5,,,,,,,,,,,,,,,,,,,,,,,,,,,,,,,,,,,,,
113.928,9.90732,4.60986,2.5,,,,,,,,,,,,,,,,,,,,,,,,,,,,,,,,,,,,,
114.928,9.74072,3.71893,2.5,,,,,,,,,,,,,,,,,,,,,,,,,,,,,,,,,,,,,
115.928,9.57406,2.97073,2.5,,,,,,,,,,,,,,,,,,,,,,,,,,,,,,,,,,,,,
116.928,9.40746,2.44426,2.5,,,,,,,,,,,,,,,,,,,,,,,,,,,,,,,,,,,,,
117.928,9.24075,2.05946,2.5,,,,,,,,,,,,,,,,,,,,,,,,,,,,,,,,,,,,,
118.928,9.07409,1.7455,2.5,,,,,,,,,,,,,,,,,,,,,,,,,,,,,,,,,,,,,
119.928,8.90738,1.53019,2.5,,,,,,,,,,,,,,,,,,,,,,,,,,,,,,,,,,,,,
120.928,8.74072,1.28884,2.5,,,,,,,,,,,,,,,,,,,,,,,,,,,,,,,,,,,,,
121.928,8.57412,1.15695,2.5,,,,,,,,,,,,,,,,,,,,,,,,,,,,,,,,,,,,,
122.928,8.40735,0.99457,2.5,,,,,,,,,,,,,,,,,,,,,,,,,,,,,,,,,,,,,
123.732,8.54097,1.1935,3,,,,,,,,,,,,,,,,,,,,,,,,,,,,,,,,,,,,,
124.732,8.70757,1.34321,3,,,,,,,,,,,,,,,,,,,,,,,,,,,,,,,,,,,,,
125.732,8.87434,1.54182,3,,,,,,,,,,,,,,,,,,,,,,,,,,,,,,,,,,,,,
126.732,9.04094,1.86554,3,,,,,,,,,,,,,,,,,,,,,,,,,,,,,,,,,,,,,
127.732,9.20771,2.24468,3,,,,,,,,,,,,,,,,,,,,,,,,,,,,,,,,,,,,,
128.732,9.37437,2.85129,3,,,,,,,,,,,,,,,,,,,,,,,,,,,,,,,,,,,,,
129.732,9.54097,3.6598,3,,,,,,,,,,,,,,,,,,,,,,,,,,,,,,,,,,,,,
130.732,9.70768,4.66453,3,,,,,,,,,,,,,,,,,,,,,,,,,,,,,,,,,,,,,
131.732,9.87434,5.76652,3,,,,,,,,,,,,,,,,,,,,,,,,,,,,,,,,,,,,,
132.732,10.04105,6.94155,3,,,,,,,,,,,,,,,,,,,,,,,,,,,,,,,,,,,,,
133.732,10.20765,8.38092,3,,,,,,,,,,,,,,,,,,,,,,,,,,,,,,,,,,,,,
134.732,10.37448,10.6491,3,,,,,,,,,,,,,,,,,,,,,,,,,,,,,,,,,,,,,
135.732,10.54108,13.02819,3,,,,,,,,,,,,,,,,,,,,,,,,,,,,,,,,,,,,,
136.732,10.70779,15.74176,3,,,,,,,,,,,,,,,,,,,,,,,,,,,,,,,,,,,,,
137.732,10.8745,18.31768,3,,,,,,,,,,,,,,,,,,,,,,,,,,,,,,,,,,,,,
138.732,11.04105,21.6686,3,,,,,,,,,,,,,,,,,,,,,,,,,,,,,,,,,,,,,
139.732,11.2077,25.78801,3,,,,,,,,,,,,,,,,,,,,,,,,,,,,,,,,,,,,,
140.732,11.37425,30.69063,3,,,,,,,,,,,,,,,,,,,,,,,,,,,,,,,,,,,,,
141.732,11.54096,36.20993,3,,,,,,,,,,,,,,,,,,,,,,,,,,,,,,,,,,,,,
142.592,11.61797,38.72316,3.5,,,,,,,,,,,,,,,,,,,,,,,,,,,,,,,,,,,,,
143.592,11.45075,31.55246,3.5,,,,,,,,,,,,,,,,,,,,,,,,,,,,,,,,,,,,,
144.592,11.28415,25.74349,3.5,,,,,,,,,,,,,,,,,,,,,,,,,,,,,,,,,,,,,
145.592,11.11738,20.82539,3.5,,,,,,,,,,,,,,,,,,,,,,,,,,,,,,,,,,,,,
146.592,10.95078,16.84477,3.5,,,,,,,,,,,,,,,,,,,,,,,,,,,,,,,,,,,,,
147.592,10.78406,13.48376,3.5,,,,,,,,,,,,,,,,,,,,,,,,,,,,,,,,,,,,,
148.592,10.6174,10.97359,3.5,,,,,,,,,,,,,,,,,,,,,,,,,,,,,,,,,,,,,
149.592,10.45069,8.76624,3.5,,,,,,,,,,,,,,,,,,,,,,,,,,,,,,,,,,,,,
150.592,10.28404,7.34781,3.5,,,,,,,,,,,,,,,,,,,,,,,,,,,,,,,,,,,,,
151.592,10.11732,5.8483,3.5,,,,,,,,,,,,,,,,,,,,,,,,,,,,,,,,,,,,,
152.592,9.95061,4.63267,3.5,,,,,,,,,,,,,,,,,,,,,,,,,,,,,,,,,,,,,
153.592,9.7839,3.6789,3.5,,,,,,,,,,,,,,,,,,,,,,,,,,,,,,,,,,,,,
154.592,9.6173,2.9598,3.5,,,,,,,,,,,,,,,,,,,,,,,,,,,,,,,,,,,,,
155.592,9.45064,2.40956,3.5,,,,,,,,,,,,,,,,,,,,,,,,,,,,,,,,,,,,,
156.592,9.28404,2.10757,3.5,,,,,,,,,,,,,,,,,,,,,,,,,,,,,,,,,,,,,
157.592,9.11738,1.72936,3.5,,,,,,,,,,,,,,,,,,,,,,,,,,,,,,,,,,,,,
158.592,8.95073,1.476,3.5,,,,,,,,,,,,,,,,,,,,,,,,,,,,,,,,,,,,,
159.592,8.78407,1.38,3.5,,,,,,,,,,,,,,,,,,,,,,,,,,,,,,,,,,,,,
160.592,8.61747,1.2758,3.5,,,,,,,,,,,,,,,,,,,,,,,,,,,,,,,,,,,,,
161.54,8.45943,0.99764,4,,,,,,,,,,,,,,,,,,,,,,,,,,,,,,,,,,,,,
162.344,8.59293,1.16988,4,,,,,,,,,,,,,,,,,,,,,,,,,,,,,,,,,,,,,
163.344,8.75959,1.38167,4,,,,,,,,,,,,,,,,,,,,,,,,,,,,,,,,,,,,,
164.344,8.9263,1.59193,4,,,,,,,,,,,,,,,,,,,,,,,,,,,,,,,,,,,,,
165.344,9.09296,1.81803,4,,,,,,,,,,,,,,,,,,,,,,,,,,,,,,,,,,,,,
166.344,9.25962,2.24721,4,,,,,,,,,,,,,,,,,,,,,,,,,,,,,,,,,,,,,
167.344,9.42639,2.78643,4,,,,,,,,,,,,,,,,,,,,,,,,,,,,,,,,,,,,,
168.344,9.59293,3.53913,4,,,,,,,,,,,,,,,,,,,,,,,,,,,,,,,,,,,,,
169.344,9.75976,4.62849,4,,,,,,,,,,,,,,,,,,,,,,,,,,,,,,,,,,,,,
170.344,9.92636,5.78854,4,,,,,,,,,,,,,,,,,,,,,,,,,,,,,,,,,,,,,
171.344,10.09313,6.90849,4,,,,,,,,,,,,,,,,,,,,,,,,,,,,,,,,,,,,,
172.344,10.25978,8.49874,4,,,,,,,,,,,,,,,,,,,,,,,,,,,,,,,,,,,,,
173.344,10.4265,10.68296,4,,,,,,,,,,,,,,,,,,,,,,,,,,,,,,,,,,,,,
174.344,10.5931,13.13861,4,,,,,,,,,,,,,,,,,,,,,,,,,,,,,,,,,,,,,
175.344,10.75981,16.02848,4,,,,,,,,,,,,,,,,,,,,,,,,,,,,,,,,,,,,,
176.344,10.92641,18.44692,4,,,,,,,,,,,,,,,,,,,,,,,,,,,,,,,,,,,,,
177.344,11.0929,21.91797,4,,,,,,,,,,,,,,,,,,,,,,,,,,,,,,,,,,,,,
178.344,11.25967,26.11291,4,,,,,,,,,,,,,,,,,,,,,,,,,,,,,,,,,,,,,
179.344,11.42627,31.10566,4,,,,,,,,,,,,,,,,,,,,,,,,,,,,,,,,,,,,,
180.344,11.59298,36.67931,4,,,,,,,,,,,,,,,,,,,,,,,,,,,,,,,,,,,,,
181.202,11.63582,37.92032,4.5,,,,,,,,,,,,,,,,,,,,,,,,,,,,,,,,,,,,,
182.202,11.46911,30.91994,4.5,,,,,,,,,,,,,,,,,,,,,,,,,,,,,,,,,,,,,
183.202,11.30234,25.21532,4.5,,,,,,,,,,,,,,,,,,,,,,,,,,,,,,,,,,,,,
184.202,11.13568,20.38058,4.5,,,,,,,,,,,,,,,,,,,,,,,,,,,,,,,,,,,,,
185.202,10.96891,16.39442,4.5,,,,,,,,,,,,,,,,,,,,,,,,,,,,,,,,,,,,,
186.202,10.80225,13.06747,4.5,,,,,,,,,,,,,,,,,,,,,,,,,,,,,,,,,,,,,
187.202,10.6356,10.77295,4.5,,,,,,,,,,,,,,,,,,,,,,,,,,,,,,,,,,,,,
188.202,10.46894,8.4947,4.5,,,,,,,,,,,,,,,,,,,,,,,,,,,,,,,,,,,,,
189.202,10.30234,7.12448,4.5,,,,,,,,,,,,,,,,,,,,,,,,,,,,,,,,,,,,,
190.202,10.13568,5.66058,4.5,,,,,,,,,,,,,,,,,,,,,,,,,,,,,,,,,,,,,
191.202,9.96908,4.43314,4.5,,,,,,,,,,,,,,,,,,,,,,,,,,,,,,,,,,,,,
192.202,9.80237,3.50663,4.5,,,,,,,,,,,,,,,,,,,,,,,,,,,,,,,,,,,,,
193.202,9.63577,2.86825,4.5,,,,,,,,,,,,,,,,,,,,,,,,,,,,,,,,,,,,,
194.202,9.46911,2.33148,4.5,,,,,,,,,,,,,,,,,,,,,,,,,,,,,,,,,,,,,
195.202,9.3024,1.96507,4.5,,,,,,,,,,,,,,,,,,,,,,,,,,,,,,,,,,,,,
196.202,9.1358,1.70445,4.5,,,,,,,,,,,,,,,,,,,,,,,,,,,,,,,,,,,,,
197.202,8.96897,1.42477,4.5,,,,,,,,,,,,,,,,,,,,,,,,,,,,,,,,,,,,,
198.202,8.80243,1.24518,4.5,,,,,,,,,,,,,,,,,,,,,,,,,,,,,,,,,,,,,
199.202,8.6356,1.14014,4.5,,,,,,,,,,,,,,,,,,,,,,,,,,,,,,,,,,,,,
200.008,8.50147,0.98708,5,,,,,,,,,,,,,,,,,,,,,,,,,,,,,,,,,,,,,
200.91,8.65192,1.21872,5,,,,,,,,,,,,,,,,,,,,,,,,,,,,,,,,,,,,,
201.91,8.81864,1.34465,5,,,,,,,,,,,,,,,,,,,,,,,,,,,,,,,,,,,,,
202.91,8.98529,1.56439,5,,,,,,,,,,,,,,,,,,,,,,,,,,,,,,,,,,,,,
203.91,9.15195,1.89169,5,,,,,,,,,,,,,,,,,,,,,,,,,,,,,,,,,,,,,
204.91,9.31866,2.29368,5,,,,,,,,,,,,,,,,,,,,,,,,,,,,,,,,,,,,,
205.91,9.48532,2.8455,5,,,,,,,,,,,,,,,,,,,,,,,,,,,,,,,,,,,,,
206.91,9.65203,3.6441,5,,,,,,,,,,,,,,,,,,,,,,,,,,,,,,,,,,,,,
207.91,9.81863,4.72943,5,,,,,,,,,,,,,,,,,,,,,,,,,,,,,,,,,,,,,
208.91,9.98546,5.8542,5,,,,,,,,,,,,,,,,,,,,,,,,,,,,,,,,,,,,,
209.91,10.152,6.98944,5,,,,,,,,,,,,,,,,,,,,,,,,,,,,,,,,,,,,,
210.91,10.31877,8.71014,5,,,,,,,,,,,,,,,,,,,,,,,,,,,,,,,,,,,,,
211.91,10.48549,10.95673,5,,,,,,,,,,,,,,,,,,,,,,,,,,,,,,,,,,,,,
212.91,10.65209,13.53433,5,,,,,,,,,,,,,,,,,,,,,,,,,,,,,,,,,,,,,
213.91,10.8188,16.40649,5,,,,,,,,,,,,,,,,,,,,,,,,,,,,,,,,,,,,,
214.91,10.9854,19.04427,5,,,,,,,,,,,,,,,,,,,,,,,,,,,,,,,,,,,,,
215.91,11.15206,22.48933,5,,,,,,,,,,,,,,,,,,,,,,,,,,,,,,,,,,,,,
216.91,11.3186,26.90812,5,,,,,,,,,,,,,,,,,,,,,,,,,,,,,,,,,,,,,
217.91,11.48537,31.97621,5,,,,,,,,,,,,,,,,,,,,,,,,,,,,,,,,,,,,,
218.91,11.65191,37.72768,5,,,,,,,,,,,,,,,,,,,,,,,,,,,,,,,,,,,,,
219.802,11.63378,36.37269,5.5,,,,,,,,,,,,,,,,,,,,,,,,,,,,,,,,,,,,,
220.802,11.46712,29.66248,5.5,,,,,,,,,,,,,,,,,,,,,,,,,,,,,,,,,,,,,
221.802,11.3003,24.1293,5.5,,,,,,,,,,,,,,,,,,,,,,,,,,,,,,,,,,,,,
222.802,11.1337,19.48412,5.5,,,,,,,,,,,,,,,,,,,,,,,,,,,,,,,,,,,,,
223.802,10.96692,15.65809,5.5,,,,,,,,,,,,,,,,,,,,,,,,,,,,,,,,,,,,,
224.802,10.80033,12.45752,5.5,,,,,,,,,,,,,,,,,,,,,,,,,,,,,,,,,,,,,
225.802,10.63361,10.22961,5.5,,,,,,,,,,,,,,,,,,,,,,,,,,,,,,,,,,,,,
226.802,10.4669,8.16056,5.5,,,,,,,,,,,,,,,,,,,,,,,,,,,,,,,,,,,,,
227.802,10.3003,6.83512,5.5,,,,,,,,,,,,,,,,,,,,,,,,,,,,,,,,,,,,,
228.802,10.1337,5.31188,5.5,,,,,,,,,,,,,,,,,,,,,,,,,,,,,,,,,,,,,
229.802,9.9671,4.15742,5.5,,,,,,,,,,,,,,,,,,,,,,,,,,,,,,,,,,,,,
230.802,9.80039,3.28368,5.5,,,,,,,,,,,,,,,,,,,,,,,,,,,,,,,,,,,,,
231.802,9.63373,2.66022,5.5,,,,,,,,,,,,,,,,,,,,,,,,,,,,,,,,,,,,,
232.802,9.46702,2.18737,5.5,,,,,,,,,,,,,,,,,,,,,,,,,,,,,,,,,,,,,
233.802,9.30047,1.8703,5.5,,,,,,,,,,,,,,,,,,,,,,,,,,,,,,,,,,,,,
234.802,9.1337,1.56982,5.5,,,,,,,,,,,,,,,,,,,,,,,,,,,,,,,,,,,,,
235.802,8.96705,1.39892,5.5,,,,,,,,,,,,,,,,,,,,,,,,,,,,,,,,,,,,,
236.802,8.80045,1.28415,5.5,,,,,,,,,,,,,,,,,,,,,,,,,,,,,,,,,,,,,
237.802,8.63368,1.07106,5.5,,,,,,,,,,,,,,,,,,,,,,,,,,,,,,,,,,,,,
238.552,8.60965,1.03089,6,,,,,,,,,,,,,,,,,,,,,,,,,,,,,,,,,,,,,
239.552,8.77642,1.2134,6,,,,,,,,,,,,,,,,,,,,,,,,,,,,,,,,,,,,,
240.552,8.94302,1.39868,6,,,,,,,,,,,,,,,,,,,,,,,,,,,,,,,,,,,,,
241.552,9.10973,1.67884,6,,,,,,,,,,,,,,,,,,,,,,,,,,,,,,,,,,,,,
242.552,9.27628,1.99267,6,,,,,,,,,,,,,,,,,,,,,,,,,,,,,,,,,,,,,
243.552,9.44293,2.54447,6,,,,,,,,,,,,,,,,,,,,,,,,,,,,,,,,,,,,,
244.552,9.60965,3.13764,6,,,,,,,,,,,,,,,,,,,,,,,,,,,,,,,,,,,,,
245.552,9.77625,4.13809,6,,,,,,,,,,,,,,,,,,,,,,,,,,,,,,,,,,,,,
246.552,9.94302,5.31798,6,,,,,,,,,,,,,,,,,,,,,,,,,,,,,,,,,,,,,
247.552,10.10967,6.40478,6,,,,,,,,,,,,,,,,,,,,,,,,,,,,,,,,,,,,,
248.552,10.27639,7.80875,6,,,,,,,,,,,,,,,,,,,,,,,,,,,,,,,,,,,,,
249.552,10.44299,9.81695,6,,,,,,,,,,,,,,,,,,,,,,,,,,,,,,,,,,,,,
250.552,10.60964,12.22259,6,,,,,,,,,,,,,,,,,,,,,,,,,,,,,,,,,,,,,
251.552,10.77636,15.05306,6,,,,,,,,,,,,,,,,,,,,,,,,,,,,,,,,,,,,,
252.552,10.94307,17.70749,6,,,,,,,,,,,,,,,,,,,,,,,,,,,,,,,,,,,,,
253.552,11.10978,20.58907,6,,,,,,,,,,,,,,,,,,,,,,,,,,,,,,,,,,,,,
254.552,11.27638,24.81426,6,,,,,,,,,,,,,,,,,,,,,,,,,,,,,,,,,,,,,
255.552,11.44315,29.64484,6,,,,,,,,,,,,,,,,,,,,,,,,,,,,,,,,,,,,,
256.552,11.6097,35.1722,6,,,,,,,,,,,,,,,,,,,,,,,,,,,,,,,,,,,,,
257.37,11.74609,40.02096,6.5,,,,,,,,,,,,,,,,,,,,,,,,,,,,,,,,,,,,,
258.37,11.57915,32.85641,6.5,,,,,,,,,,,,,,,,,,,,,,,,,,,,,,,,,,,,,
259.37,11.41244,26.75122,6.5,,,,,,,,,,,,,,,,,,,,,,,,,,,,,,,,,,,,,
260.37,11.24567,21.70178,6.5,,,,,,,,,,,,,,,,,,,,,,,,,,,,,,,,,,,,,
261.37,11.07901,17.46305,6.5,,,,,,,,,,,,,,,,,,,,,,,,,,,,,,,,,,,,,
262.37,10.91224,13.96226,6.5,,,,,,,,,,,,,,,,,,,,,,,,,,,,,,,,,,,,,
263.37,10.74564,11.18804,6.5,,,,,,,,,,,,,,,,,,,,,,,,,,,,,,,,,,,,,
264.37,10.57887,9.04995,6.5,,,,,,,,,,,,,,,,,,,,,,,,,,,,,,,,,,,,,
265.37,10.41227,7.52972,6.5,,,,,,,,,,,,,,,,,,,,,,,,,,,,,,,,,,,,,
266.37,10.24567,5.91185,6.5,,,,,,,,,,,,,,,,,,,,,,,,,,,,,,,,,,,,,
267.37,10.07907,4.61966,6.5,,,,,,,,,,,,,,,,,,,,,,,,,,,,,,,,,,,,,
268.37,9.91247,3.63675,6.5,,,,,,,,,,,,,,,,,,,,,,,,,,,,,,,,,,,,,
269.37,9.74582,2.93496,6.5,,,,,,,,,,,,,,,,,,,,,,,,,,,,,,,,,,,,,
270.37,9.57916,2.37216,6.5,,,,,,,,,,,,,,,,,,,,,,,,,,,,,,,,,,,,,
271.37,9.41239,1.96723,6.5,,,,,,,,,,,,,,,,,,,,,,,,,,,,,,,,,,,,,
272.37,9.24579,1.65145,6.5,,,,,,,,,,,,,,,,,,,,,,,,,,,,,,,,,,,,,
273.37,9.07908,1.42971,6.5,,,,,,,,,,,,,,,,,,,,,,,,,,,,,,,,,,,,,
274.37,8.91248,1.22037,6.5,,,,,,,,,,,,,,,,,,,,,,,,,,,,,,,,,,,,,
275.37,8.74565,1.13597,6.5,,,,,,,,,,,,,,,,,,,,,,,,,,,,,,,,,,,,,
276.144,8.64535,1.01412,7,,,,,,,,,,,,,,,,,,,,,,,,,,,,,,,,,,,,,
277.144,8.81756,1.19835,7,,,,,,,,,,,,,,,,,,,,,,,,,,,,,,,,,,,,,
278.144,8.98433,1.32477,7,,,,,,,,,,,,,,,,,,,,,,,,,,,,,,,,,,,,,
279.144,9.15093,1.66564,7,,,,,,,,,,,,,,,,,,,,,,,,,,,,,,,,,,,,,
280.144,9.3177,1.94331,7,,,,,,,,,,,,,,,,,,,,,,,,,,,,,,,,,,,,,
281.144,9.4843,2.43218,7,,,,,,,,,,,,,,,,,,,,,,,,,,,,,,,,,,,,,
282.144,9.65101,3.14272,7,,,,,,,,,,,,,,,,,,,,,,,,,,,,,,,,,,,,,
283.144,9.81761,4.06969,7,,,,,,,,,,,,,,,,,,,,,,,,,,,,,,,,,,,,,
284.144,9.98438,5.2829,7,,,,,,,,,,,,,,,,,,,,,,,,,,,,,,,,,,,,,
285.144,10.15104,6.4565,7,,,,,,,,,,,,,,,,,,,,,,,,,,,,,,,,,,,,,
286.144,10.31775,7.85238,7,,,,,,,,,,,,,,,,,,,,,,,,,,,,,,,,,,,,,
287.144,10.48452,9.95035,7,,,,,,,,,,,,,,,,,,,,,,,,,,,,,,,,,,,,,
288.144,10.65101,12.4114,7,,,,,,,,,,,,,,,,,,,,,,,,,,,,,,,,,,,,,
289.144,10.81778,15.26425,7,,,,,,,,,,,,,,,,,,,,,,,,,,,,,,,,,,,,,
290.144,10.98438,17.99451,7,,,,,,,,,,,,,,,,,,,,,,,,,,,,,,,,,,,,,
291.144,11.15104,20.95413,7,,,,,,,,,,,,,,,,,,,,,,,,,,,,,,,,,,,,,
292.144,11.31758,25.20853,7,,,,,,,,,,,,,,,,,,,,,,,,,,,,,,,,,,,,,
293.144,11.48435,30.13061,7,,,,,,,,,,,,,,,,,,,,,,,,,,,,,,,,,,,,,
294.144,11.65095,35.76902,7,,,,,,,,,,,,,,,,,,,,,,,,,,,,,,,,,,,,,
295.04,11.73397,38.64693,7.5,,,,,,,,,,,,,,,,,,,,,,,,,,,,,,,,,,,,,
296.04,11.56686,31.41862,7.5,,,,,,,,,,,,,,,,,,,,,,,,,,,,,,,,,,,,,
297.04,11.40009,25.54866,7.5,,,,,,,,,,,,,,,,,,,,,,,,,,,,,,,,,,,,,
298.04,11.23343,20.67167,7.5,,,,,,,,,,,,,,,,,,,,,,,,,,,,,,,,,,,,,
299.04,11.06677,16.56831,7.5,,,,,,,,,,,,,,,,,,,,,,,,,,,,,,,,,,,,,
300.04,10.90006,13.12881,7.5,,,,,,,,,,,,,,,,,,,,,,,,,,,,,,,,,,,,,
301.04,10.7334,10.73265,7.5,,,,,,,,,,,,,,,,,,,,,,,,,,,,,,,,,,,,,
302.04,10.56663,8.56925,7.5,,,,,,,,,,,,,,,,,,,,,,,,,,,,,,,,,,,,,
303.04,10.39998,7.03391,7.5,,,,,,,,,,,,,,,,,,,,,,,,,,,,,,,,,,,,,
304.04,10.23332,5.53704,7.5,,,,,,,,,,,,,,,,,,,,,,,,,,,,,,,,,,,,,
305.04,10.06661,4.38812,7.5,,,,,,,,,,,,,,,,,,,,,,,,,,,,,,,,,,,,,
306.04,9.89995,3.37814,7.5,,,,,,,,,,,,,,,,,,,,,,,,,,,,,,,,,,,,,
307.04,9.73335,2.73591,7.5,,,,,,,,,,,,,,,,,,,,,,,,,,,,,,,,,,,,,
308.04,9.56675,2.27313,7.5,,,,,,,,,,,,,,,,,,,,,,,,,,,,,,,,,,,,,
309.04,9.40004,1.81708,7.5,,,,,,,,,,,,,,,,,,,,,,,,,,,,,,,,,,,,,
310.04,9.23344,1.60326,7.5,,,,,,,,,,,,,,,,,,,,,,,,,,,,,,,,,,,,,
311.04,9.06672,1.37189,7.5,,,,,,,,,,,,,,,,,,,,,,,,,,,,,,,,,,,,,
312.04,8.90007,1.14698,7.5,,,,,,,,,,,,,,,,,,,,,,,,,,,,,,,,,,,,,
313.04,8.73335,1.07903,7.5,,,,,,,,,,,,,,,,,,,,,,,,,,,,,,,,,,,,,
313.806,8.73993,1.04355,8,,,,,,,,,,,,,,,,,,,,,,,,,,,,,,,,,,,,,
314.806,8.9067,1.22211,8,,,,,,,,,,,,,,,,,,,,,,,,,,,,,,,,,,,,,
315.806,9.0733,1.40989,8,,,,,,,,,,,,,,,,,,,,,,,,,,,,,,,,,,,,,
316.806,9.24018,1.72931,8,,,,,,,,,,,,,,,,,,,,,,,,,,,,,,,,,,,,,
317.806,9.40678,2.10815,8,,,,,,,,,,,,,,,,,,,,,,,,,,,,,,,,,,,,,
318.806,9.57349,2.65194,8,,,,,,,,,,,,,,,,,,,,,,,,,,,,,,,,,,,,,
319.806,9.74009,3.52059,8,,,,,,,,,,,,,,,,,,,,,,,,,,,,,,,,,,,,,
320.806,9.90664,4.51062,8,,,,,,,,,,,,,,,,,,,,,,,,,,,,,,,,,,,,,
321.806,10.07335,5.72786,8,,,,,,,,,,,,,,,,,,,,,,,,,,,,,,,,,,,,,
322.806,10.23995,6.90106,8,,,,,,,,,,,,,,,,,,,,,,,,,,,,,,,,,,,,,
323.806,10.40655,8.57126,8,,,,,,,,,,,,,,,,,,,,,,,,,,,,,,,,,,,,,
324.806,10.57326,10.86834,8,,,,,,,,,,,,,,,,,,,,,,,,,,,,,,,,,,,,,
325.806,10.73998,13.50587,8,,,,,,,,,,,,,,,,,,,,,,,,,,,,,,,,,,,,,
326.806,10.90663,16.43578,8,,,,,,,,,,,,,,,,,,,,,,,,,,,,,,,,,,,,,
327.806,11.07335,18.97975,8,,,,,,,,,,,,,,,,,,,,,,,,,,,,,,,,,,,,,
328.806,11.24,22.53927,8,,,,,,,,,,,,,,,,,,,,,,,,,,,,,,,,,,,,,
329.806,11.40666,27.09215,8,,,,,,,,,,,,,,,,,,,,,,,,,,,,,,,,,,,,,
330.806,11.57337,32.30717,8,,,,,,,,,,,,,,,,,,,,,,,,,,,,,,,,,,,,,
331.806,11.74003,38.18941,8,,,,,,,,,,,,,,,,,,,,,,,,,,,,,,,,,,,,,
332.708,11.69016,35.64994,8.5,,,,,,,,,,,,,,,,,,,,,,,,,,,,,,,,,,,,,
333.708,11.52345,29.01905,8.5,,,,,,,,,,,,,,,,,,,,,,,,,,,,,,,,,,,,,
334.708,11.35674,23.57177,8.5,,,,,,,,,,,,,,,,,,,,,,,,,,,,,,,,,,,,,
335.708,11.19002,19.00567,8.5,,,,,,,,,,,,,,,,,,,,,,,,,,,,,,,,,,,,,
336.708,11.02331,15.14279,8.5,,,,,,,,,,,,,,,,,,,,,,,,,,,,,,,,,,,,,
337.708,10.8566,12.07816,8.5,,,,,,,,,,,,,,,,,,,,,,,,,,,,,,,,,,,,,
338.708,10.68994,9.80735,8.5,,,,,,,,,,,,,,,,,,,,,,,,,,,,,,,,,,,,,
339.708,10.52328,7.91798,8.5,,,,,,,,,,,,,,,,,,,,,,,,,,,,,,,,,,,,,
340.708,10.35663,6.47018,8.5,,,,,,,,,,,,,,,,,,,,,,,,,,,,,,,,,,,,,
341.708,10.19003,5.05692,8.5,,,,,,,,,,,,,,,,,,,,,,,,,,,,,,,,,,,,,
342.708,10.02343,3.94,8.5,,,,,,,,,,,,,,,,,,,,,,,,,,,,,,,,,,,,,
343.708,9.85671,3.10002,8.5,,,,,,,,,,,,,,,,,,,,,,,,,,,,,,,,,,,,,
344.708,9.69,2.51714,8.5,,,,,,,,,,,,,,,,,,,,,,,,,,,,,,,,,,,,,
345.708,9.52346,2.08248,8.5,,,,,,,,,,,,,,,,,,,,,,,,,,,,,,,,,,,,,
346.708,9.35663,1.71025,8.5,,,,,,,,,,,,,,,,,,,,,,,,,,,,,,,,,,,,,
347.708,9.19003,1.43955,8.5,,,,,,,,,,,,,,,,,,,,,,,,,,,,,,,,,,,,,
348.708,9.02337,1.30678,8.5,,,,,,,,,,,,,,,,,,,,,,,,,,,,,,,,,,,,,
349.708,8.85683,1.15393,8.5,,,,,,,,,,,,,,,,,,,,,,,,,,,,,,,,,,,,,
350.458,8.73165,0.99365,9,,,,,,,,,,,,,,,,,,,,,,,,,,,,,,,,,,,,,
351.458,8.89944,1.15122,9,,,,,,,,,,,,,,,,,,,,,,,,,,,,,,,,,,,,,
352.458,9.06604,1.35201,9,,,,,,,,,,,,,,,,,,,,,,,,,,,,,,,,,,,,,
353.458,9.23276,1.59313,9,,,,,,,,,,,,,,,,,,,,,,,,,,,,,,,,,,,,,
354.458,9.39936,1.97902,9,,,,,,,,,,,,,,,,,,,,,,,,,,,,,,,,,,,,,
355.458,9.56607,2.47987,9,,,,,,,,,,,,,,,,,,,,,,,,,,,,,,,,,,,,,
356.458,9.73267,3.24754,9,,,,,,,,,,,,,,,,,,,,,,,,,,,,,,,,,,,,,
357.458,9.89933,4.21466,9,,,,,,,,,,,,,,,,,,,,,,,,,,,,,,,,,,,,,
358.458,10.06593,5.45214,9,,,,,,,,,,,,,,,,,,,,,,,,,,,,,,,,,,,,,
359.458,10.23264,6.66299,9,,,,,,,,,,,,,,,,,,,,,,,,,,,,,,,,,,,,,
360.458,10.39924,8.09295,9,,,,,,,,,,,,,,,,,,,,,,,,,,,,,,,,,,,,,
361.458,10.56601,10.35323,9,,,,,,,,,,,,,,,,,,,,,,,,,,,,,,,,,,,,,
362.458,10.73267,12.91118,9,,,,,,,,,,,,,,,,,,,,,,,,,,,,,,,,,,,,,
363.458,10.89927,15.81102,9,,,,,,,,,,,,,,,,,,,,,,,,,,,,,,,,,,,,,
364.458,11.06604,18.56293,9,,,,,,,,,,,,,,,,,,,,,,,,,,,,,,,,,,,,,
365.458,11.23269,21.8371,9,,,,,,,,,,,,,,,,,,,,,,,,,,,,,,,,,,,,,
366.458,11.39941,26.21106,9,,,,,,,,,,,,,,,,,,,,,,,,,,,,,,,,,,,,,
367.458,11.56601,31.37431,9,,,,,,,,,,,,,,,,,,,,,,,,,,,,,,,,,,,,,
368.458,11.73278,37.13768,9,,,,,,,,,,,,,,,,,,,,,,,,,,,,,,,,,,,,,
369.318,11.74252,37.14676,9.5,,,,,,,,,,,,,,,,,,,,,,,,,,,,,,,,,,,,,
370.318,11.57575,30.27908,9.5,,,,,,,,,,,,,,,,,,,,,,,,,,,,,,,,,,,,,
371.318,11.40904,24.47392,9.5,,,,,,,,,,,,,,,,,,,,,,,,,,,,,,,,,,,,,
372.318,11.24238,19.80956,9.5,,,,,,,,,,,,,,,,,,,,,,,,,,,,,,,,,,,,,
373.318,11.07567,15.81772,9.5,,,,,,,,,,,,,,,,,,,,,,,,,,,,,,,,,,,,,
374.318,10.90901,12.57221,9.5,,,,,,,,,,,,,,,,,,,,,,,,,,,,,,,,,,,,,
375.318,10.7423,10.20685,9.5,,,,,,,,,,,,,,,,,,,,,,,,,,,,,,,,,,,,,
376.318,10.57559,8.23026,9.5,,,,,,,,,,,,,,,,,,,,,,,,,,,,,,,,,,,,,
377.318,10.40899,6.63467,9.5,,,,,,,,,,,,,,,,,,,,,,,,,,,,,,,,,,,,,
378.318,10.24216,5.27574,9.5,,,,,,,,,,,,,,,,,,,,,,,,,,,,,,,,,,,,,
379.318,10.07567,4.09254,9.5,,,,,,,,,,,,,,,,,,,,,,,,,,,,,,,,,,,,,
380.318,9.90902,3.2043,9.5,,,,,,,,,,,,,,,,,,,,,,,,,,,,,,,,,,,,,
381.318,9.74247,2.61303,9.5,,,,,,,,,,,,,,,,,,,,,,,,,,,,,,,,,,,,,
382.318,9.57576,2.1539,9.5,,,,,,,,,,,,,,,,,,,,,,,,,,,,,,,,,,,,,
383.318,9.40905,1.80174,9.5,,,,,,,,,,,,,,,,,,,,,,,,,,,,,,,,,,,,,
384.318,9.24245,1.52306,9.5,,,,,,,,,,,,,,,,,,,,,,,,,,,,,,,,,,,,,
385.318,9.07568,1.3306,9.5,,,,,,,,,,,,,,,,,,,,,,,,,,,,,,,,,,,,,
386.318,8.90902,1.20366,9.5,,,,,,,,,,,,,,,,,,,,,,,,,,,,,,,,,,,,,
387.26,8.75205,0.99908,10,,,,,,,,,,,,,,,,,,,,,,,,,,,,,,,,,,,,,
388.162,8.64535,0.86886,10,,,,,,,,,,,,,,,,,,,,,,,,,,,,,,,,,,,,,
389.162,8.63011,0.87748,10,,,,,,,,,,,,,,,,,,,,,,,,,,,,,,,,,,,,,
390.162,8.63067,0.91691,10,,,,,,,,,,,,,,,,,,,,,,,,,,,,,,,,,,,,,
391.162,8.63175,0.90941,10,,,,,,,,,,,,,,,,,,,,,,,,,,,,,,,,,,,,,
392.162,8.63487,0.90676,10,,,,,,,,,,,,,,,,,,,,,,,,,,,,,,,,,,,,,
393.162,8.67317,0.99641,10,,,,,,,,,,,,,,,,,,,,,,,,,,,,,,,,,,,,,
394.162,8.76514,1.06646,10,,,,,,,,,,,,,,,,,,,,,,,,,,,,,,,,,,,,,
395.162,8.82895,1.16706,10,,,,,,,,,,,,,,,,,,,,,,,,,,,,,,,,,,,,,
396.162,8.83603,1.16961,10,,,,,,,,,,,,,,,,,,,,,,,,,,,,,,,,,,,,,
397.162,8.83586,1.16966,10,,,,,,,,,,,,,,,,,,,,,,,,,,,,,,,,,,,,,
398.162,8.83547,1.0927,10,,,,,,,,,,,,,,,,,,,,,,,,,,,,,,,,,,,,,
399.162,8.83507,1.07975,10,,,,,,,,,,,,,,,,,,,,,,,,,,,,,,,,,,,,,
400.162,8.83309,1.08877,10,,,,,,,,,,,,,,,,,,,,,,,,,,,,,,,,,,,,,
401.162,8.82736,1.10497,10,,,,,,,,,,,,,,,,,,,,,,,,,,,,,,,,,,,,,
402.162,8.79308,1.05058,10,,,,,,,,,,,,,,,,,,,,,,,,,,,,,,,,,,,,,
403.162,8.74729,1.04639,10,,,,,,,,,,,,,,,,,,,,,,,,,,,,,,,,,,,,,
404.162,8.72978,1.01594,10,,,,,,,,,,,,,,,,,,,,,,,,,,,,,,,,,,,,,
405.162,8.72893,1.00147,10,,,,,,,,,,,,,,,,,,,,,,,,,,,,,,,,,,,,,
406.162,8.72882,1.00853,10,,,,,,,,,,,,,,,,,,,,,,,,,,,,,,,,,,,,,
407.162,8.72899,1.01835,10,,,,,,,,,,,,,,,,,,,,,,,,,,,,,,,,,,,,,
408.162,8.72905,1.02184,10,,,,,,,,,,,,,,,,,,,,,,,,,,,,,,,,,,,,,
409.162,8.72916,1.00045,10,,,,,,,,,,,,,,,,,,,,,,,,,,,,,,,,,,,,,
410.162,8.72927,1.02733,10,,,,,,,,,,,,,,,,,,,,,,,,,,,,,,,,,,,,,
411.162,8.72939,1.01202,10,,,,,,,,,,,,,,,,,,,,,,,,,,,,,,,,,,,,,
412.162,8.72944,1.03719,10,,,,,,,,,,,,,,,,,,,,,,,,,,,,,,,,,,,,,
413.162,8.7295,1.07063,10,,,,,,,,,,,,,,,,,,,,,,,,,,,,,,,,,,,,,
414.162,8.72956,1.02385,10,,,,,,,,,,,,,,,,,,,,,,,,,,,,,,,,,,,,,
415.162,8.72961,1.02442,10,,,,,,,,,,,,,,,,,,,,,,,,,,,,,,,,,,,,,
416.162,8.72967,1.0607,10,,,,,,,,,,,,,,,,,,,,,,,,,,,,,,,,,,,,,
417.162,8.72967,1.06479,10,,,,,,,,,,,,,,,,,,,,,,,,,,,,,,,,,,,,,
418.162,8.72967,1.04189,10,,,,,,,,,,,,,,,,,,,,,,,,,,,,,,,,,,,,,
419.162,8.72967,1.07344,10,,,,,,,,,,,,,,,,,,,,,,,,,,,,,,,,,,,,,
420.162,8.72956,1.05195,10,,,,,,,,,,,,,,,,,,,,,,,,,,,,,,,,,,,,,
421.162,8.72956,1.0306,10,,,,,,,,,,,,,,,,,,,,,,,,,,,,,,,,,,,,,
422.162,8.72956,1.02718,10,,,,,,,,,,,,,,,,,,,,,,,,,,,,,,,,,,,,,
423.162,8.72956,0.99035,10,,,,,,,,,,,,,,,,,,,,,,,,,,,,,,,,,,,,,
424.162,8.72956,1.03974,10,,,,,,,,,,,,,,,,,,,,,,,,,,,,,,,,,,,,,
425.162,8.72956,1.05048,10,,,,,,,,,,,,,,,,,,,,,,,,,,,,,,,,,,,,,
426.162,8.72956,1.00418,10,,,,,,,,,,,,,,,,,,,,,,,,,,,,,,,,,,,,,
427.162,8.72956,1.02497,10,,,,,,,,,,,,,,,,,,,,,,,,,,,,,,,,,,,,,
428.162,8.72956,1.02226,10,,,,,,,,,,,,,,,,,,,,,,,,,,,,,,,,,,,,,
429.162,8.72961,1.02506,10,,,,,,,,,,,,,,,,,,,,,,,,,,,,,,,,,,,,,
430.162,8.72961,1.03875,10,,,,,,,,,,,,,,,,,,,,,,,,,,,,,,,,,,,,,
431.162,8.72961,1.065,10,,,,,,,,,,,,,,,,,,,,,,,,,,,,,,,,,,,,,
432.162,8.72961,1.0598,10,,,,,,,,,,,,,,,,,,,,,,,,,,,,,,,,,,,,,
433.162,8.72961,1.05075,10,,,,,,,,,,,,,,,,,,,,,,,,,,,,,,,,,,,,,
434.162,8.72961,1.02364,10,,,,,,,,,,,,,,,,,,,,,,,,,,,,,,,,,,,,,
435.162,8.72961,1.01762,10,,,,,,,,,,,,,,,,,,,,,,,,,,,,,,,,,,,,,
436.162,8.72961,1.05059,10,,,,,,,,,,,,,,,,,,,,,,,,,,,,,,,,,,,,,
437.162,8.72961,1.05432,10,,,,,,,,,,,,,,,,,,,,,,,,,,,,,,,,,,,,,
438.162,8.72961,1.02561,10,,,,,,,,,,,,,,,,,,,,,,,,,,,,,,,,,,,,,
439.162,8.72961,1.02283,10,,,,,,,,,,,,,,,,,,,,,,,,,,,,,,,,,,,,,
440.162,8.7295,1.10733,10,,,,,,,,,,,,,,,,,,,,,,,,,,,,,,,,,,,,,
441.162,8.7295,1.08241,10,,,,,,,,,,,,,,,,,,,,,,,,,,,,,,,,,,,,,
442.162,8.72944,1.07497,10,,,,,,,,,,,,,,,,,,,,,,,,,,,,,,,,,,,,,
443.162,8.72933,1.08251,10,,,,,,,,,,,,,,,,,,,,,,,,,,,,,,,,,,,,,
444.162,8.72916,1.06082,10,,,,,,,,,,,,,,,,,,,,,,,,,,,,,,,,,,,,,
445.162,8.72893,1.06242,10,,,,,,,,,,,,,,,,,,,,,,,,,,,,,,,,,,,,,
446.162,8.72848,1.10533,10,,,,,,,,,,,,,,,,,,,,,,,,,,,,,,,,,,,,,
447.162,8.72582,1.0491,10,,,,,,,,,,,,,,,,,,,,,,,,,,,,,,,,,,,,,
448.162,8.72021,1.07331,10,,,,,,,,,,,,,,,,,,,,,,,,,,,,,,,,,,,,,
449.162,8.71069,1.06694,10,,,,,,,,,,,,,,,,,,,,,,,,,,,,,,,,,,,,,
450.162,8.70003,1.03791,10,,,,,,,,,,,,,,,,,,,,,,,,,,,,,,,,,,,,,
451.162,8.69584,1.02041,10,,,,,,,,,,,,,,,,,,,,,,,,,,,,,,,,,,,,,
452.162,8.69403,1.07219,10,,,,,,,,,,,,,,,,,,,,,,,,,,,,,,,,,,,,,
453.162,8.6934,1.07163,10,,,,,,,,,,,,,,,,,,,,,,,,,,,,,,,,,,,,,
454.162,8.69323,1.02144,10,,,,,,,,,,,,,,,,,,,,,,,,,,,,,,,,,,,,,
455.162,8.69329,1.05478,10,,,,,,,,,,,,,,,,,,,,,,,,,,,,,,,,,,,,,
456.162,8.69335,1.0595,10,,,,,,,,,,,,,,,,,,,,,,,,,,,,,,,,,,,,,
457.162,8.6934,1.05161,10,,,,,,,,,,,,,,,,,,,,,,,,,,,,,,,,,,,,,
458.162,8.69352,1.10143,10,,,,,,,,,,,,,,,,,,,,,,,,,,,,,,,,,,,,,
459.162,8.69357,1.0967,10,,,,,,,,,,,,,,,,,,,,,,,,,,,,,,,,,,,,,
460.162,8.69363,1.05896,10,,,,,,,,,,,,,,,,,,,,,,,,,,,,,,,,,,,,,
461.162,8.69369,1.07732,10,,,,,,,,,,,,,,,,,,,,,,,,,,,,,,,,,,,,,
462.162,8.69374,1.03327,10,,,,,,,,,,,,,,,,,,,,,,,,,,,,,,,,,,,,,
463.162,8.69374,1.06625,10,,,,,,,,,,,,,,,,,,,,,,,,,,,,,,,,,,,,,
464.162,8.6938,1.11429,10,,,,,,,,,,,,,,,,,,,,,,,,,,,,,,,,,,,,,
465.162,8.6938,1.07725,10,,,,,,,,,,,,,,,,,,,,,,,,,,,,,,,,,,,,,
466.162,8.69386,1.11289,10,,,,,,,,,,,,,,,,,,,,,,,,,,,,,,,,,,,,,
467.162,8.69386,1.09805,10,,,,,,,,,,,,,,,,,,,,,,,,,,,,,,,,,,,,,
468.162,8.69386,1.1288,10,,,,,,,,,,,,,,,,,,,,,,,,,,,,,,,,,,,,,
469.162,8.69391,1.11303,10,,,,,,,,,,,,,,,,,,,,,,,,,,,,,,,,,,,,,
470.162,8.69391,1.13413,10,,,,,,,,,,,,,,,,,,,,,,,,,,,,,,,,,,,,,
471.162,8.69386,1.03918,10,,,,,,,,,,,,,,,,,,,,,,,,,,,,,,,,,,,,,
472.162,8.69386,1.02482,10,,,,,,,,,,,,,,,,,,,,,,,,,,,,,,,,,,,,,
473.162,8.69397,1.13673,10,,,,,,,,,,,,,,,,,,,,,,,,,,,,,,,,,,,,,
474.162,8.69397,1.09893,10,,,,,,,,,,,,,,,,,,,,,,,,,,,,,,,,,,,,,
475.162,8.69391,1.03661,10,,,,,,,,,,,,,,,,,,,,,,,,,,,,,,,,,,,,,
476.162,8.69403,1.07099,10,,,,,,,,,,,,,,,,,,,,,,,,,,,,,,,,,,,,,
477.162,8.69403,1.07304,10,,,,,,,,,,,,,,,,,,,,,,,,,,,,,,,,,,,,,
478.162,8.69403,1.05271,10,,,,,,,,,,,,,,,,,,,,,,,,,,,,,,,,,,,,,
479.162,8.69403,1.0321,10,,,,,,,,,,,,,,,,,,,,,,,,,,,,,,,,,,,,,
480.162,8.69403,1.08333,10,,,,,,,,,,,,,,,,,,,,,,,,,,,,,,,,,,,,,
481.162,8.69403,1.01143,10,,,,,,,,,,,,,,,,,,,,,,,,,,,,,,,,,,,,,
482.162,8.69408,1.05907,10,,,,,,,,,,,,,,,,,,,,,,,,,,,,,,,,,,,,,
483.162,8.69414,1.05459,10,,,,,,,,,,,,,,,,,,,,,,,,,,,,,,,,,,,,,
484.162,8.69414,1.05178,10,,,,,,,,,,,,,,,,,,,,,,,,,,,,,,,,,,,,,
485.162,8.69414,1.05373,10,,,,,,,,,,,,,,,,,,,,,,,,,,,,,,,,,,,,,
486.162,8.69403,1.08246,10,,,,,,,,,,,,,,,,,,,,,,,,,,,,,,,,,,,,,
487.162,8.69414,1.01693,10,,,,,,,,,,,,,,,,,,,,,,,,,,,,,,,,,,,,,
488.162,8.69414,1.03686,10,,,,,,,,,,,,,,,,,,,,,,,,,,,,,,,,,,,,,
489.162,8.69414,1.11114,10,,,,,,,,,,,,,,,,,,,,,,,,,,,,,,,,,,,,,
490.162,8.69414,1.014,10,,,,,,,,,,,,,,,,,,,,,,,,,,,,,,,,,,,,,
491.162,8.69414,1.09123,10,,,,,,,,,,,,,,,,,,,,,,,,,,,,,,,,,,,,,
492.162,8.69403,1.07653,10,,,,,,,,,,,,,,,,,,,,,,,,,,,,,,,,,,,,,
493.162,8.69403,1.04356,10,,,,,,,,,,,,,,,,,,,,,,,,,,,,,,,,,,,,,
494.162,8.69403,1.11966,10,,,,,,,,,,,,,,,,,,,,,,,,,,,,,,,,,,,,,
495.162,8.69408,1.04655,10,,,,,,,,,,,,,,,,,,,,,,,,,,,,,,,,,,,,,
496.162,8.69397,1.05005,10,,,,,,,,,,,,,,,,,,,,,,,,,,,,,,,,,,,,,
497.162,8.69397,1.08713,10,,,,,,,,,,,,,,,,,,,,,,,,,,,,,,,,,,,,,
498.162,8.69391,1.0496,10,,,,,,,,,,,,,,,,,,,,,,,,,,,,,,,,,,,,,
499.162,8.69391,1.05647,10,,,,,,,,,,,,,,,,,,,,,,,,,,,,,,,,,,,,,
500.162,8.69391,1.04724,10,,,,,,,,,,,,,,,,,,,,,,,,,,,,,,,,,,,,,
501.162,8.69391,1.10977,10,,,,,,,,,,,,,,,,,,,,,,,,,,,,,,,,,,,,,
502.162,8.69386,1.06139,10,,,,,,,,,,,,,,,,,,,,,,,,,,,,,,,,,,,,,
503.162,8.69391,1.06419,10,,,,,,,,,,,,,,,,,,,,,,,,,,,,,,,,,,,,,
504.162,8.69391,1.05713,10,,,,,,,,,,,,,,,,,,,,,,,,,,,,,,,,,,,,,
505.162,8.69391,1.07515,10,,,,,,,,,,,,,,,,,,,,,,,,,,,,,,,,,,,,,
506.162,8.6938,1.10348,10,,,,,,,,,,,,,,,,,,,,,,,,,,,,,,,,,,,,,
507.162,8.6938,1.06918,10,,,,,,,,,,,,,,,,,,,,,,,,,,,,,,,,,,,,,
508.162,8.69369,1.06287,10,,,,,,,,,,,,,,,,,,,,,,,,,,,,,,,,,,,,,
509.162,8.69357,1.12525,10,,,,,,,,,,,,,,,,,,,,,,,,,,,,,,,,,,,,,
510.162,8.69329,1.07254,10,,,,,,,,,,,,,,,,,,,,,,,,,,,,,,,,,,,,,
511.162,8.69261,1.06273,10,,,,,,,,,,,,,,,,,,,,,,,,,,,,,,,,,,,,,
512.162,8.69102,1.08088,10,,,,,,,,,,,,,,,,,,,,,,,,,,,,,,,,,,,,,
513.162,8.68904,1.20584,10,,,,,,,,,,,,,,,,,,,,,,,,,,,,,,,,,,,,,
514.162,8.68507,1.07908,10,,,,,,,,,,,,,,,,,,,,,,,,,,,,,,,,,,,,,
515.162,8.67669,1.07958,10,,,,,,,,,,,,,,,,,,,,,,,,,,,,,,,,,,,,,
516.162,8.66836,1.05553,10,,,,,,,,,,,,,,,,,,,,,,,,,,,,,,,,,,,,,
517.162,8.66456,0.9843,10,,,,,,,,,,,,,,,,,,,,,,,,,,,,,,,,,,,,,
518.162,8.66292,1.07186,10,,,,,,,,,,,,,,,,,,,,,,,,,,,,,,,,,,,,,
519.162,8.66201,1.01772,10,,,,,,,,,,,,,,,,,,,,,,,,,,,,,,,,,,,,,
520.162,8.66156,1.04067,10,,,,,,,,,,,,,,,,,,,,,,,,,,,,,,,,,,,,,
521.162,8.66127,1.05856,10,,,,,,,,,,,,,,,,,,,,,,,,,,,,,,,,,,,,,
522.162,8.66116,1.0528,10,,,,,,,,,,,,,,,,,,,,,,,,,,,,,,,,,,,,,
523.162,8.66116,1.032,10,,,,,,,,,,,,,,,,,,,,,,,,,,,,,,,,,,,,,
524.162,8.66122,1.04177,10,,,,,,,,,,,,,,,,,,,,,,,,,,,,,,,,,,,,,
525.162,8.66127,0.98357,10,,,,,,,,,,,,,,,,,,,,,,,,,,,,,,,,,,,,,
526.162,8.66133,1.02308,10,,,,,,,,,,,,,,,,,,,,,,,,,,,,,,,,,,,,,
527.162,8.66139,1.11547,10,,,,,,,,,,,,,,,,,,,,,,,,,,,,,,,,,,,,,
528.162,8.66144,1.07012,10,,,,,,,,,,,,,,,,,,,,,,,,,,,,,,,,,,,,,
529.162,8.6615,0.98802,10,,,,,,,,,,,,,,,,,,,,,,,,,,,,,,,,,,,,,
530.162,8.66161,1.0763,10,,,,,,,,,,,,,,,,,,,,,,,,,,,,,,,,,,,,,
531.162,8.66167,1.07339,10,,,,,,,,,,,,,,,,,,,,,,,,,,,,,,,,,,,,,
532.162,8.66173,1.04008,10,,,,,,,,,,,,,,,,,,,,,,,,,,,,,,,,,,,,,
533.162,8.66173,1.11376,10,,,,,,,,,,,,,,,,,,,,,,,,,,,,,,,,,,,,,
534.162,8.66173,1.02783,10,,,,,,,,,,,,,,,,,,,,,,,,,,,,,,,,,,,,,
535.162,8.66173,1.02027,10,,,,,,,,,,,,,,,,,,,,,,,,,,,,,,,,,,,,,
536.162,8.66173,1.063,10,,,,,,,,,,,,,,,,,,,,,,,,,,,,,,,,,,,,,
537.162,8.66173,1.05076,10,,,,,,,,,,,,,,,,,,,,,,,,,,,,,,,,,,,,,
538.162,8.66173,1.04925,10,,,,,,,,,,,,,,,,,,,,,,,,,,,,,,,,,,,,,
539.162,8.66173,1.08377,10,,,,,,,,,,,,,,,,,,,,,,,,,,,,,,,,,,,,,
540.162,8.66173,1.04762,10,,,,,,,,,,,,,,,,,,,,,,,,,,,,,,,,,,,,,
541.162,8.66173,1.03845,10,,,,,,,,,,,,,,,,,,,,,,,,,,,,,,,,,,,,,
542.162,8.66173,1.04084,10,,,,,,,,,,,,,,,,,,,,,,,,,,,,,,,,,,,,,
543.162,8.66173,1.09334,10,,,,,,,,,,,,,,,,,,,,,,,,,,,,,,,,,,,,,
544.162,8.66173,1.06062,10,,,,,,,,,,,,,,,,,,,,,,,,,,,,,,,,,,,,,
545.162,8.66161,1.08673,10,,,,,,,,,,,,,,,,,,,,,,,,,,,,,,,,,,,,,
546.162,8.66173,1.03946,10,,,,,,,,,,,,,,,,,,,,,,,,,,,,,,,,,,,,,
547.162,8.66173,1.01643,10,,,,,,,,,,,,,,,,,,,,,,,,,,,,,,,,,,,,,
548.162,8.66173,1.07781,10,,,,,,,,,,,,,,,,,,,,,,,,,,,,,,,,,,,,,
549.162,8.66167,1.04556,10,,,,,,,,,,,,,,,,,,,,,,,,,,,,,,,,,,,,,
550.162,8.66173,1.02713,10,,,,,,,,,,,,,,,,,,,,,,,,,,,,,,,,,,,,,
551.162,8.66161,1.03102,10,,,,,,,,,,,,,,,,,,,,,,,,,,,,,,,,,,,,,
552.162,8.66173,1.03767,10,,,,,,,,,,,,,,,,,,,,,,,,,,,,,,,,,,,,,
553.162,8.66173,1.01019,10,,,,,,,,,,,,,,,,,,,,,,,,,,,,,,,,,,,,,
554.162,8.66161,1.08713,10,,,,,,,,,,,,,,,,,,,,,,,,,,,,,,,,,,,,,
555.162,8.66173,1.07037,10,,,,,,,,,,,,,,,,,,,,,,,,,,,,,,,,,,,,,
556.162,8.66161,1.02395,10,,,,,,,,,,,,,,,,,,,,,,,,,,,,,,,,,,,,,
557.162,8.66173,1.05812,10,,,,,,,,,,,,,,,,,,,,,,,,,,,,,,,,,,,,,
558.162,8.66161,0.99403,10,,,,,,,,,,,,,,,,,,,,,,,,,,,,,,,,,,,,,
559.162,8.66173,1.07098,10,,,,,,,,,,,,,,,,,,,,,,,,,,,,,,,,,,,,,
560.162,8.66156,1.06357,10,,,,,,,,,,,,,,,,,,,,,,,,,,,,,,,,,,,,,
561.162,8.66161,1.02376,10,,,,,,,,,,,,,,,,,,,,,,,,,,,,,,,,,,,,,
562.162,8.66161,1.05588,10,,,,,,,,,,,,,,,,,,,,,,,,,,,,,,,,,,,,,
563.162,8.66173,1.0242,10,,,,,,,,,,,,,,,,,,,,,,,,,,,,,,,,,,,,,
564.162,8.66161,1.09903,10,,,,,,,,,,,,,,,,,,,,,,,,,,,,,,,,,,,,,
565.162,8.66161,1.03879,10,,,,,,,,,,,,,,,,,,,,,,,,,,,,,,,,,,,,,
566.162,8.66173,1.08548,10,,,,,,,,,,,,,,,,,,,,,,,,,,,,,,,,,,,,,
567.162,8.66173,1.02988,10,,,,,,,,,,,,,,,,,,,,,,,,,,,,,,,,,,,,,
568.162,8.66173,1.03434,10,,,,,,,,,,,,,,,,,,,,,,,,,,,,,,,,,,,,,
569.162,8.66173,1.05835,10,,,,,,,,,,,,,,,,,,,,,,,,,,,,,,,,,,,,,
570.162,8.66173,1.075,10,,,,,,,,,,,,,,,,,,,,,,,,,,,,,,,,,,,,,
571.162,8.66161,1.05312,10,,,,,,,,,,,,,,,,,,,,,,,,,,,,,,,,,,,,,
572.162,8.66167,1.04849,10,,,,,,,,,,,,,,,,,,,,,,,,,,,,,,,,,,,,,
573.162,8.66167,1.01895,10,,,,,,,,,,,,,,,,,,,,,,,,,,,,,,,,,,,,,
574.162,8.66167,1.05016,10,,,,,,,,,,,,,,,,,,,,,,,,,,,,,,,,,,,,,
575.162,8.66167,1.07903,10,,,,,,,,,,,,,,,,,,,,,,,,,,,,,,,,,,,,,
576.162,8.66173,1.06229,10,,,,,,,,,,,,,,,,,,,,,,,,,,,,,,,,,,,,,
577.162,8.66173,1.01215,10,,,,,,,,,,,,,,,,,,,,,,,,,,,,,,,,,,,,,
578.162,8.66173,1.11669,10,,,,,,,,,,,,,,,,,,,,,,,,,,,,,,,,,,,,,
579.162,8.66173,1.02434,10,,,,,,,,,,,,,,,,,,,,,,,,,,,,,,,,,,,,,
580.162,8.66173,1.02422,10,,,,,,,,,,,,,,,,,,,,,,,,,,,,,,,,,,,,,
581.162,8.66173,1.05483,10,,,,,,,,,,,,,,,,,,,,,,,,,,,,,,,,,,,,,
582.162,8.66173,1.03256,10,,,,,,,,,,,,,,,,,,,,,,,,,,,,,,,,,,,,,
583.162,8.66173,1.0356,10,,,,,,,,,,,,,,,,,,,,,,,,,,,,,,,,,,,,,
584.162,8.66173,1.08473,10,,,,,,,,,,,,,,,,,,,,,,,,,,,,,,,,,,,,,
585.162,8.66173,1.07879,10,,,,,,,,,,,,,,,,,,,,,,,,,,,,,,,,,,,,,
586.162,8.66161,1.08198,10,,,,,,,,,,,,,,,,,,,,,,,,,,,,,,,,,,,,,
587.162,8.66173,1.03153,10,,,,,,,,,,,,,,,,,,,,,,,,,,,,,,,,,,,,,
588.162,8.66173,1.02042,10,,,,,,,,,,,,,,,,,,,,,,,,,,,,,,,,,,,,,
589.162,8.66161,1.03263,10,,,,,,,,,,,,,,,,,,,,,,,,,,,,,,,,,,,,,
590.162,8.66161,1.04632,10,,,,,,,,,,,,,,,,,,,,,,,,,,,,,,,,,,,,,
591.162,8.66161,1.00578,10,,,,,,,,,,,,,,,,,,,,,,,,,,,,,,,,,,,,,
592.162,8.66161,1.03201,10,,,,,,,,,,,,,,,,,,,,,,,,,,,,,,,,,,,,,
593.162,8.66161,1.04836,10,,,,,,,,,,,,,,,,,,,,,,,,,,,,,,,,,,,,,
594.162,8.66167,1.02922,10,,,,,,,,,,,,,,,,,,,,,,,,,,,,,,,,,,,,,
595.162,8.66167,1.05175,10,,,,,,,,,,,,,,,,,,,,,,,,,,,,,,,,,,,,,
596.162,8.66167,1.03097,10,,,,,,,,,,,,,,,,,,,,,,,,,,,,,,,,,,,,,
597.162,8.66167,1.0531,10,,,,,,,,,,,,,,,,,,,,,,,,,,,,,,,,,,,,,
598.162,8.66167,1.03685,10,,,,,,,,,,,,,,,,,,,,,,,,,,,,,,,,,,,,,
599.162,8.66167,1.02531,10,,,,,,,,,,,,,,,,,,,,,,,,,,,,,,,,,,,,,
600.162,8.66167,1.00861,10,,,,,,,,,,,,,,,,,,,,,,,,,,,,,,,,,,,,,
601.162,8.66167,1.02793,10,,,,,,,,,,,,,,,,,,,,,,,,,,,,,,,,,,,,,
602.162,8.66167,1.04137,10,,,,,,,,,,,,,,,,,,,,,,,,,,,,,,,,,,,,,
603.162,8.66167,1.06251,10,,,,,,,,,,,,,,,,,,,,,,,,,,,,,,,,,,,,,
604.162,8.66167,1.0526,10,,,,,,,,,,,,,,,,,,,,,,,,,,,,,,,,,,,,,
605.162,8.66156,1.02217,10,,,,,,,,,,,,,,,,,,,,,,,,,,,,,,,,,,,,,
606.162,8.66156,1.03153,10,,,,,,,,,,,,,,,,,,,,,,,,,,,,,,,,,,,,,
607.162,8.6615,1.03901,10,,,,,,,,,,,,,,,,,,,,,,,,,,,,,,,,,,,,,
608.162,8.66144,1.11656,10,,,,,,,,,,,,,,,,,,,,,,,,,,,,,,,,,,,,,
609.162,8.66133,1.10746,10,,,,,,,,,,,,,,,,,,,,,,,,,,,,,,,,,,,,,
610.162,8.66133,1.06321,10,,,,,,,,,,,,,,,,,,,,,,,,,,,,,,,,,,,,,
611.162,8.66139,1.04189,10,,,,,,,,,,,,,,,,,,,,,,,,,,,,,,,,,,,,,
612.162,8.66139,1.03808,10,,,,,,,,,,,,,,,,,,,,,,,,,,,,,,,,,,,,,
613.162,8.66139,1.0421,10,,,,,,,,,,,,,,,,,,,,,,,,,,,,,,,,,,,,,
614.162,8.66139,1.04489,10,,,,,,,,,,,,,,,,,,,,,,,,,,,,,,,,,,,,,
615.162,8.66139,1.07108,10,,,,,,,,,,,,,,,,,,,,,,,,,,,,,,,,,,,,,
616.162,8.66139,1.07094,10,,,,,,,,,,,,,,,,,,,,,,,,,,,,,,,,,,,,,
617.162,8.66139,1.0555,10,,,,,,,,,,,,,,,,,,,,,,,,,,,,,,,,,,,,,
618.162,8.66139,1.03945,10,,,,,,,,,,,,,,,,,,,,,,,,,,,,,,,,,,,,,
619.162,8.66133,1.0299,10,,,,,,,,,,,,,,,,,,,,,,,,,,,,,,,,,,,,,
620.162,8.66133,1.05352,10,,,,,,,,,,,,,,,,,,,,,,,,,,,,,,,,,,,,,
621.162,8.66144,1.08106,10,,,,,,,,,,,,,,,,,,,,,,,,,,,,,,,,,,,,,
622.162,8.66133,1.06684,10,,,,,,,,,,,,,,,,,,,,,,,,,,,,,,,,,,,,,
623.162,8.66133,1.05171,10,,,,,,,,,,,,,,,,,,,,,,,,,,,,,,,,,,,,,
624.162,8.66139,1.00132,10,,,,,,,,,,,,,,,,,,,,,,,,,,,,,,,,,,,,,
625.162,8.66139,1.01177,10,,,,,,,,,,,,,,,,,,,,,,,,,,,,,,,,,,,,,
626.162,8.66139,1.08012,10,,,,,,,,,,,,,,,,,,,,,,,,,,,,,,,,,,,,,
627.162,8.66139,0.99971,10,,,,,,,,,,,,,,,,,,,,,,,,,,,,,,,,,,,,,
628.162,8.66139,1.05596,10,,,,,,,,,,,,,,,,,,,,,,,,,,,,,,,,,,,,,
629.162,8.66139,1.05643,10,,,,,,,,,,,,,,,,,,,,,,,,,,,,,,,,,,,,,
630.162,8.66133,1.0383,10,,,,,,,,,,,,,,,,,,,,,,,,,,,,,,,,,,,,,
631.162,8.66139,1.02946,10,,,,,,,,,,,,,,,,,,,,,,,,,,,,,,,,,,,,,
632.162,8.66139,1.05649,10,,,,,,,,,,,,,,,,,,,,,,,,,,,,,,,,,,,,,
633.162,8.66139,1.02545,10,,,,,,,,,,,,,,,,,,,,,,,,,,,,,,,,,,,,,
634.162,8.66139,1.0406,10,,,,,,,,,,,,,,,,,,,,,,,,,,,,,,,,,,,,,
635.162,8.66139,1.07748,10,,,,,,,,,,,,,,,,,,,,,,,,,,,,,,,,,,,,,
636.162,8.66127,1.09238,10,,,,,,,,,,,,,,,,,,,,,,,,,,,,,,,,,,,,,
637.162,8.66127,1.02974,10,,,,,,,,,,,,,,,,,,,,,,,,,,,,,,,,,,,,,
638.162,8.66122,1.02212,10,,,,,,,,,,,,,,,,,,,,,,,,,,,,,,,,,,,,,
639.162,8.66122,1.02761,10,,,,,,,,,,,,,,,,,,,,,,,,,,,,,,,,,,,,,
640.162,8.66133,1.0244,10,,,,,,,,,,,,,,,,,,,,,,,,,,,,,,,,,,,,,
641.162,8.66133,1.05531,10,,,,,,,,,,,,,,,,,,,,,,,,,,,,,,,,,,,,,
642.162,8.66133,1.00524,10,,,,,,,,,,,,,,,,,,,,,,,,,,,,,,,,,,,,,
643.162,8.66139,1.01464,10,,,,,,,,,,,,,,,,,,,,,,,,,,,,,,,,,,,,,
644.162,8.66139,1.04858,10,,,,,,,,,,,,,,,,,,,,,,,,,,,,,,,,,,,,,
645.162,8.66139,1.0129,10,,,,,,,,,,,,,,,,,,,,,,,,,,,,,,,,,,,,,
646.162,8.66139,1.04443,10,,,,,,,,,,,,,,,,,,,,,,,,,,,,,,,,,,,,,
647.162,8.66139,1.0766,10,,,,,,,,,,,,,,,,,,,,,,,,,,,,,,,,,,,,,
648.162,8.66139,1.07219,10,,,,,,,,,,,,,,,,,,,,,,,,,,,,,,,,,,,,,
649.162,8.66139,1.03088,10,,,,,,,,,,,,,,,,,,,,,,,,,,,,,,,,,,,,,
650.162,8.66139,1.05217,10,,,,,,,,,,,,,,,,,,,,,,,,,,,,,,,,,,,,,
651.162,8.66139,1.09312,10,,,,,,,,,,,,,,,,,,,,,,,,,,,,,,,,,,,,,
652.162,8.66139,1.05823,10,,,,,,,,,,,,,,,,,,,,,,,,,,,,,,,,,,,,,
653.162,8.66139,1.04443,10,,,,,,,,,,,,,,,,,,,,,,,,,,,,,,,,,,,,,
654.162,8.66127,1.08932,10,,,,,,,,,,,,,,,,,,,,,,,,,,,,,,,,,,,,,
655.162,8.66122,1.05432,10,,,,,,,,,,,,,,,,,,,,,,,,,,,,,,,,,,,,,
656.162,8.66116,1.07825,10,,,,,,,,,,,,,,,,,,,,,,,,,,,,,,,,,,,,,
657.162,8.6611,1.06054,10,,,,,,,,,,,,,,,,,,,,,,,,,,,,,,,,,,,,,
658.162,8.66105,1.03593,10,,,,,,,,,,,,,,,,,,,,,,,,,,,,,,,,,,,,,
659.162,8.66059,1.05665,10,,,,,,,,,,,,,,,,,,,,,,,,,,,,,,,,,,,,,
660.162,8.65963,1.03635,10,,,,,,,,,,,,,,,,,,,,,,,,,,,,,,,,,,,,,
661.162,8.65742,1.06564,10,,,,,,,,,,,,,,,,,,,,,,,,,,,,,,,,,,,,,
662.162,8.65408,1.03023,10,,,,,,,,,,,,,,,,,,,,,,,,,,,,,,,,,,,,,
663.162,8.64847,1.01509,10,,,,,,,,,,,,,,,,,,,,,,,,,,,,,,,,,,,,,
664.162,8.64354,1.08747,10,,,,,,,,,,,,,,,,,,,,,,,,,,,,,,,,,,,,,
665.162,8.63288,1.0492,10,,,,,,,,,,,,,,,,,,,,,,,,,,,,,,,,,,,,,
666.162,8.62036,1.05882,10,,,,,,,,,,,,,,,,,,,,,,,,,,,,,,,,,,,,,
667.162,8.61039,1.02765,10,,,,,,,,,,,,,,,,,,,,,,,,,,,,,,,,,,,,,
668.162,8.60801,1.04157,10,,,,,,,,,,,,,,,,,,,,,,,,,,,,,,,,,,,,,
669.162,8.60778,1.01279,10,,,,,,,,,,,,,,,,,,,,,,,,,,,,,,,,,,,,,
670.162,8.60789,1.03671,10,,,,,,,,,,,,,,,,,,,,,,,,,,,,,,,,,,,,,
671.162,8.60795,1.06501,10,,,,,,,,,,,,,,,,,,,,,,,,,,,,,,,,,,,,,
672.162,8.60812,0.96903,10,,,,,,,,,,,,,,,,,,,,,,,,,,,,,,,,,,,,,
673.162,8.60829,1.01778,10,,,,,,,,,,,,,,,,,,,,,,,,,,,,,,,,,,,,,
674.162,8.60852,1.0301,10,,,,,,,,,,,,,,,,,,,,,,,,,,,,,,,,,,,,,
675.162,8.60874,1.00347,10,,,,,,,,,,,,,,,,,,,,,,,,,,,,,,,,,,,,,
676.162,8.60903,1.03512,10,,,,,,,,,,,,,,,,,,,,,,,,,,,,,,,,,,,,,
677.162,8.60925,1.01365,10,,,,,,,,,,,,,,,,,,,,,,,,,,,,,,,,,,,,,
678.162,8.60959,0.99249,10,,,,,,,,,,,,,,,,,,,,,,,,,,,,,,,,,,,,,
679.162,8.60988,1.0645,10,,,,,,,,,,,,,,,,,,,,,,,,,,,,,,,,,,,,,
680.162,8.61044,1.04372,10,,,,,,,,,,,,,,,,,,,,,,,,,,,,,,,,,,,,,
681.162,8.61129,0.98504,10,,,,,,,,,,,,,,,,,,,,,,,,,,,,,,,,,,,,,
682.162,8.61294,1.019,10,,,,,,,,,,,,,,,,,,,,,,,,,,,,,,,,,,,,,
683.162,8.61486,1.05907,10,,,,,,,,,,,,,,,,,,,,,,,,,,,,,,,,,,,,,
684.162,8.61702,1.03064,10,,,,,,,,,,,,,,,,,,,,,,,,,,,,,,,,,,,,,
685.162,8.62467,1.03038,10,,,,,,,,,,,,,,,,,,,,,,,,,,,,,,,,,,,,,
686.162,8.66773,1.09609,10,,,,,,,,,,,,,,,,,,,,,,,,,,,,,,,,,,,,,
687.162,8.68394,1.09893,10,,,,,,,,,,,,,,,,,,,,,,,,,,,,,,,,,,,,,
688.064,15.05084,223.30623,10,,,,,,,,,,,,,,,,,,,,,,,,,,,,,,,,,,,,,
689.064,23.38424,176.8721,10,,,,,,,,,,,,,,,,,,,,,,,,,,,,,,,,,,,,,
690.064,31.71746,61.65833,10,,,,,,,,,,,,,,,,,,,,,,,,,,,,,,,,,,,,,
691.064,40.0508,15.78829,10,,,,,,,,,,,,,,,,,,,,,,,,,,,,,,,,,,,,,
692.064,48.3842,2.35377,10,,,,,,,,,,,,,,,,,,,,,,,,,,,,,,,,,,,,,
693.064,56.71749,0.46946,10,,,,,,,,,,,,,,,,,,,,,,,,,,,,,,,,,,,,,
693.824,63.0509,0.46594,10,,,,,,,,,,,,,,,,,,,,,,,,,,,,,,,,,,,,,