File: combined_ligament_solver/data/processed/Data Sheet 3_S160302_PCL.csv
Specimen properties : Length,34,mm,Unnamed: 3,Unnamed: 4,Unnamed: 5,Unnamed: 6,Unnamed: 7,Unnamed: 8,Unnamed: 9,Unnamed: 10,Unnamed: 11,Stress-Strain,Unnamed: 13,Unnamed: 14,Unnamed: 15,Unnamed: 16,Unnamed: 17,Unnamed: 18,Unnamed: 19,Unnamed: 20,Unnamed: 21,Unnamed: 22,Unnamed: 23,Unnamed: 24,Unnamed: 25,Unnamed: 26,Unnamed: 27,Linear,Unnamed: 29,Unnamed: 30,Unnamed: 31,Unnamed: 32,Unnamed: 33,Modulus,Unnamed: 35,Failure,Unnamed: 37,Unnamed: 38,Unnamed: 39,Unnamed: 40
Cross Section Average,59.239999999999995,mm2,,,,,,,,,,Polynomial Coefficients,,,,,,,,,,,,,,,,Force,,Stress,Extension,Strain,,Secant,Tangent,Load,Stress,Extension,Strain,Stiffness
Time,Extension,Load,Total cycle count,,,Extension,Load,Strain,Stress,E-tan,,X6,-4237893.711825525,,,,,,,,,Strain,Stress,E-tan,,,,(N),,(MPa),(mm),(%),,(MPa),(MPa),(N),(MPa),(mm),(%),(N/mm)
(s),(mm),(N),,,,(mm),(N),(mm/mm),(MPa),(MPa),,X5,1406335.172111326,,,,,,,,,(mm/mm),(MPa),(MPa),,,,300.8298665746607,,5.078154398626953,4.045999999999999,11.899999999999999,,42.67356637501642,73.90557865364836,378.2424,6.374745273463876,4.699990000000001,13.823500000000003,74.35241388399919
0.5,0.13441,2.91342,0,,,4.0545,278.03986,0.11372323529411765,4.683277683997299,67.41715872576542,,,,,,,,,,,,0.005,0.012727910815305834,4.492974740189361,,,,,,,,,,,,,,,,
1.1,0.23454,5.36064,0,,,9.05448,619.07867,,,,,,,,,,,,,,,0.011,0.061110113178490875,10.643174183125971,,,,,,,,,,,,,,,,
1.7,0.33445,7.77435,0,,,14.05458,942.9325,,,,,,,,,,,,,,,0.017,0.1465048515742921,16.761747424581014,,,,,,,,,,,,,,,,
2.3,0.43446,10.406,0,,,19.05468,363.82806,,,,,,,,,,,,,,,0.023,0.26733819902907224,22.476179609791625,,,,,,,,,,,,,,,,
2.9,0.53448,13.20122,0,,,24.05454,42.63652,,,,,,,,,,,,,,,0.029,0.42034979939281053,27.567420484185675,,,,,,,,,,,,,,,,
3.5,0.6345,16.33533,0,,,,,,,,,,,,,,,,,,,0.035,0.601430611209257,31.9461576130989,,,,,,,,,,,,,,,,
4.1,0.73451,19.69219,0,,,,,,,,,,,,,,,,,,,0.041,0.8063182909043951,35.62908960149343,,,,,,,,,,,,,,,,
4.7,0.83447,23.39832,0,,,,,,,,,,,,,,,,,,,0.047,1.0311502152932082,38.71519931367503,,,,,,,,,,,,,,,,
5.3,0.93443,27.27782,0,,,,,,,,,,,,,,,,,,,0.053,1.2728741434047548,41.36202709301036,,,,,,,,,,,,,,,,
5.9,1.03451,31.41336,0,,,,,,,,,,,,,,,,,,,0.059,1.5295165176255487,43.76194398164572,,,,,,,,,,,,,,,,
6.5,1.13452,35.64752,0,,,,,,,,,,,,,,,,,,,0.065,1.8003084041612465,46.11842494022395,,,,,,,,,,,,,,,,
7.068,1.2291,40.01083,0.5,,,,,,,,,,,,,,,,,,,0.071,2.0856690728166387,48.62232206760383,,,,,,,,,,,,,,,,
7.57,1.14597,34.92621,0.5,,,,,,,,,,,,,,,,,,,0.077,2.3870472160939533,51.428137820573156,,,,,,,,,,,,,,,,
8.17,1.0459,29.36271,0.5,,,,,,,,,,,,,,,,,,,0.083,2.706619807609459,54.630298233575076,,,,,,,,,,,,,,,,
8.77,0.94577,24.475,0.5,,,,,,,,,,,,,,,,,,,0.089,3.0468485998283747,58.23942613841554,,,,,,,,,,,,,,,,
9.37,0.84581,20.12355,0.5,,,,,,,,,,,,,,,,,,,0.095,3.4098942611180982,62.15861438398778,,,,,,,,,,,,,,,,
9.97,0.74585,16.23173,0.5,,,,,,,,,,,,,,,,,,,0.101,3.7968881521197164,66.15969905598357,,,,,,,,,,,,,,,,
10.57,0.64589,12.6647,0.5,,,,,,,,,,,,,,,,,,,0.107,4.20706174143786,69.85953269663528,,,,,,,,,,,,,,,,
11.17,0.54581,9.4814,0.5,,,,,,,,,,,,,,,,,,,0.113,4.636733660648807,72.69625752438894,,,,,,,,,,,,,,,,
11.77,0.44574,6.71087,0.5,,,,,,,,,,,,,,,,,,MAX,0.119,5.078154398626953,73.90557865364836,,,,,,,,,,,,,,,,
12.37,0.34589,4.2549,0.5,,,,,,,,,,,,,,,,,,,0.125,5.518208635189573,72.49703731451255,,,,,,,,,,,,,,,,
12.97,0.24588,2.05835,0.5,,,,,,,,,,,,,,,,,,,0.131,5.936975214059833,67.23028407245386,,,,,,,,,,,,,,,,
13.292,0.19221,0.97346,1,,,,,,,,,,,,,,,,,,,0.137,6.306144755148224,56.591352048076025,,,,,,,,,,,,,,,,
13.892,0.29331,3.21391,1,,,,,,,,,,,,,,,,,,,0.143,6.587294906152113,38.76893013678191,,,,,,,,,,,,,,,,
14.492,0.39315,5.83351,1,,,,,,,,,,,,,,,,,,,0.149,6.730023233473858,11.63063622849857,,,,,,,,,,,,,,,,
15.092,0.493,8.71941,1,,,,,,,,,,,,,,,,,,,0.155,,,,,,,,,,,,,,,,,,
15.692,0.59319,11.86876,1,,,,,,,,,,,,,,,,,,,0.161,,,,,,,,,,,,,,,,,,
16.292,0.69326,15.29183,1,,,,,,,,,,,,,,,,,,,0.167,,,,,,,,,,,,,,,,,,
16.892,0.79316,19.01932,1,,,,,,,,,,,,,,,,,,,0.173,,,,,,,,,,,,,,,,,,
17.492,0.89301,22.99949,1,,,,,,,,,,,,,,,,,,,0.179,,,,,,,,,,,,,,,,,,
18.092,0.99314,27.45135,1,,,,,,,,,,,,,,,,,,,0.185,,,,,,,,,,,,,,,,,,
18.692,1.09327,32.10386,1,,,,,,,,,,,,,,,,,,,0.191,,,,,,,,,,,,,,,,,,
19.292,1.19323,37.04838,1,,,,,,,,,,,,,,,,,,,0.197,,,,,,,,,,,,,,,,,,
19.734,1.23777,39.77295,1.5,,,,,,,,,,,,,,,,,,,,,,,,,,,,,,,,,,,,,
20.334,1.13322,33.08378,1.5,,,,,,,,,,,,,,,,,,,,,,,,,,,,,,,,,,,,,
20.934,1.03326,27.8205,1.5,,,,,,,,,,,,,,,,,,,,,,,,,,,,,,,,,,,,,
21.534,0.9333,23.0968,1.5,,,,,,,,,,,,,,,,,,,,,,,,,,,,,,,,,,,,,
22.134,0.83306,18.90292,1.5,,,,,,,,,,,,,,,,,,,,,,,,,,,,,,,,,,,,,
22.734,0.73315,15.07323,1.5,,,,,,,,,,,,,,,,,,,,,,,,,,,,,,,,,,,,,
23.334,0.63325,11.66612,1.5,,,,,,,,,,,,,,,,,,,,,,,,,,,,,,,,,,,,,
23.934,0.53329,8.70663,1.5,,,,,,,,,,,,,,,,,,,,,,,,,,,,,,,,,,,,,
24.534,0.43316,5.98347,1.5,,,,,,,,,,,,,,,,,,,,,,,,,,,,,,,,,,,,,
25.134,0.33303,3.58833,1.5,,,,,,,,,,,,,,,,,,,,,,,,,,,,,,,,,,,,,
25.734,0.23324,1.49146,1.5,,,,,,,,,,,,,,,,,,,,,,,,,,,,,,,,,,,,,
26.082,0.24248,1.58393,2,,,,,,,,,,,,,,,,,,,,,,,,,,,,,,,,,,,,,
26.682,0.34283,4.06142,2,,,,,,,,,,,,,,,,,,,,,,,,,,,,,,,,,,,,,
27.282,0.44274,6.84221,2,,,,,,,,,,,,,,,,,,,,,,,,,,,,,,,,,,,,,
27.882,0.54281,9.77099,2,,,,,,,,,,,,,,,,,,,,,,,,,,,,,,,,,,,,,
28.482,0.64277,13.01113,2,,,,,,,,,,,,,,,,,,,,,,,,,,,,,,,,,,,,,
29.082,0.7429,16.51121,2,,,,,,,,,,,,,,,,,,,,,,,,,,,,,,,,,,,,,
29.682,0.8428,20.35604,2,,,,,,,,,,,,,,,,,,,,,,,,,,,,,,,,,,,,,
30.282,0.94282,24.60724,2,,,,,,,,,,,,,,,,,,,,,,,,,,,,,,,,,,,,,
30.882,1.04278,29.05834,2,,,,,,,,,,,,,,,,,,,,,,,,,,,,,,,,,,,,,
31.482,1.14291,33.89737,2,,,,,,,,,,,,,,,,,,,,,,,,,,,,,,,,,,,,,
32.082,1.24281,38.95767,2,,,,,,,,,,,,,,,,,,,,,,,,,,,,,,,,,,,,,
32.5,1.21233,37.16989,2.5,,,,,,,,,,,,,,,,,,,,,,,,,,,,,,,,,,,,,
33.1,1.1122,31.39809,2.5,,,,,,,,,,,,,,,,,,,,,,,,,,,,,,,,,,,,,
33.7,1.01207,26.28496,2.5,,,,,,,,,,,,,,,,,,,,,,,,,,,,,,,,,,,,,
34.3,0.91228,21.75396,2.5,,,,,,,,,,,,,,,,,,,,,,,,,,,,,,,,,,,,,
34.9,0.81215,17.6404,2.5,,,,,,,,,,,,,,,,,,,,,,,,,,,,,,,,,,,,,
35.5,0.71219,13.99713,2.5,,,,,,,,,,,,,,,,,,,,,,,,,,,,,,,,,,,,,
36.1,0.61211,10.71358,2.5,,,,,,,,,,,,,,,,,,,,,,,,,,,,,,,,,,,,,
36.7,0.51221,7.74381,2.5,,,,,,,,,,,,,,,,,,,,,,,,,,,,,,,,,,,,,
37.3,0.41219,5.16603,2.5,,,,,,,,,,,,,,,,,,,,,,,,,,,,,,,,,,,,,
37.9,0.31212,2.84952,2.5,,,,,,,,,,,,,,,,,,,,,,,,,,,,,,,,,,,,,
38.46,0.21873,0.99384,3,,,,,,,,,,,,,,,,,,,,,,,,,,,,,,,,,,,,,
38.864,0.28588,2.33578,3,,,,,,,,,,,,,,,,,,,,,,,,,,,,,,,,,,,,,
39.464,0.38567,4.9368,3,,,,,,,,,,,,,,,,,,,,,,,,,,,,,,,,,,,,,
40.064,0.48575,7.72304,3,,,,,,,,,,,,,,,,,,,,,,,,,,,,,,,,,,,,,
40.664,0.58588,10.81446,3,,,,,,,,,,,,,,,,,,,,,,,,,,,,,,,,,,,,,
41.264,0.68589,14.11226,3,,,,,,,,,,,,,,,,,,,,,,,,,,,,,,,,,,,,,
41.864,0.78568,17.73706,3,,,,,,,,,,,,,,,,,,,,,,,,,,,,,,,,,,,,,
42.464,0.88576,21.84694,3,,,,,,,,,,,,,,,,,,,,,,,,,,,,,,,,,,,,,
43.064,0.98589,26.073,3,,,,,,,,,,,,,,,,,,,,,,,,,,,,,,,,,,,,,
43.664,1.08585,30.70844,3,,,,,,,,,,,,,,,,,,,,,,,,,,,,,,,,,,,,,
44.264,1.18575,35.67387,3,,,,,,,,,,,,,,,,,,,,,,,,,,,,,,,,,,,,,
44.76,1.26843,40.03604,3.5,,,,,,,,,,,,,,,,,,,,,,,,,,,,,,,,,,,,,
45.36,1.16824,34.23287,3.5,,,,,,,,,,,,,,,,,,,,,,,,,,,,,,,,,,,,,
45.96,1.06817,28.86305,3.5,,,,,,,,,,,,,,,,,,,,,,,,,,,,,,,,,,,,,
46.56,0.96826,24.05044,3.5,,,,,,,,,,,,,,,,,,,,,,,,,,,,,,,,,,,,,
47.16,0.86825,19.74624,3.5,,,,,,,,,,,,,,,,,,,,,,,,,,,,,,,,,,,,,
47.76,0.76812,15.83765,3.5,,,,,,,,,,,,,,,,,,,,,,,,,,,,,,,,,,,,,
48.36,0.6681,12.30847,3.5,,,,,,,,,,,,,,,,,,,,,,,,,,,,,,,,,,,,,
48.96,0.5682,9.22497,3.5,,,,,,,,,,,,,,,,,,,,,,,,,,,,,,,,,,,,,
49.56,0.46824,6.43839,3.5,,,,,,,,,,,,,,,,,,,,,,,,,,,,,,,,,,,,,
50.16,0.36816,4.01866,3.5,,,,,,,,,,,,,,,,,,,,,,,,,,,,,,,,,,,,,
50.76,0.26803,1.80848,3.5,,,,,,,,,,,,,,,,,,,,,,,,,,,,,,,,,,,,,
51.11,0.23919,0.96102,4,,,,,,,,,,,,,,,,,,,,,,,,,,,,,,,,,,,,,
51.71,0.34419,3.58363,4,,,,,,,,,,,,,,,,,,,,,,,,,,,,,,,,,,,,,
52.31,0.44404,6.2821,4,,,,,,,,,,,,,,,,,,,,,,,,,,,,,,,,,,,,,
52.91,0.54411,9.22385,4,,,,,,,,,,,,,,,,,,,,,,,,,,,,,,,,,,,,,
53.51,0.64407,12.43422,4,,,,,,,,,,,,,,,,,,,,,,,,,,,,,,,,,,,,,
54.11,0.74426,15.89315,4,,,,,,,,,,,,,,,,,,,,,,,,,,,,,,,,,,,,,
54.71,0.84416,19.79187,4,,,,,,,,,,,,,,,,,,,,,,,,,,,,,,,,,,,,,
55.31,0.94407,23.93174,4,,,,,,,,,,,,,,,,,,,,,,,,,,,,,,,,,,,,,
55.91,1.04414,28.44604,4,,,,,,,,,,,,,,,,,,,,,,,,,,,,,,,,,,,,,
56.51,1.14427,33.29205,4,,,,,,,,,,,,,,,,,,,,,,,,,,,,,,,,,,,,,
57.11,1.24417,38.49649,4,,,,,,,,,,,,,,,,,,,,,,,,,,,,,,,,,,,,,
57.586,1.22326,37.22611,4.5,,,,,,,,,,,,,,,,,,,,,,,,,,,,,,,,,,,,,
58.186,1.12313,31.42804,4.5,,,,,,,,,,,,,,,,,,,,,,,,,,,,,,,,,,,,,
58.786,1.02329,26.36806,4.5,,,,,,,,,,,,,,,,,,,,,,,,,,,,,,,,,,,,,
59.386,0.92333,21.79477,4.5,,,,,,,,,,,,,,,,,,,,,,,,,,,,,,,,,,,,,
59.986,0.82314,17.70676,4.5,,,,,,,,,,,,,,,,,,,,,,,,,,,,,,,,,,,,,
60.586,0.72307,14.03556,4.5,,,,,,,,,,,,,,,,,,,,,,,,,,,,,,,,,,,,,
61.186,0.62322,10.76733,4.5,,,,,,,,,,,,,,,,,,,,,,,,,,,,,,,,,,,,,
61.786,0.52326,7.79905,4.5,,,,,,,,,,,,,,,,,,,,,,,,,,,,,,,,,,,,,
62.386,0.4233,5.16811,4.5,,,,,,,,,,,,,,,,,,,,,,,,,,,,,,,,,,,,,
62.986,0.323,2.84515,4.5,,,,,,,,,,,,,,,,,,,,,,,,,,,,,,,,,,,,,
63.524,0.23352,0.99721,5,,,,,,,,,,,,,,,,,,,,,,,,,,,,,,,,,,,,,
63.928,0.30045,2.36704,5,,,,,,,,,,,,,,,,,,,,,,,,,,,,,,,,,,,,,
64.528,0.40063,5.00798,5,,,,,,,,,,,,,,,,,,,,,,,,,,,,,,,,,,,,,
65.128,0.50042,7.81501,5,,,,,,,,,,,,,,,,,,,,,,,,,,,,,,,,,,,,,
65.728,0.6005,10.86222,5,,,,,,,,,,,,,,,,,,,,,,,,,,,,,,,,,,,,,
66.328,0.70046,14.17997,5,,,,,,,,,,,,,,,,,,,,,,,,,,,,,,,,,,,,,
66.928,0.80064,17.93176,5,,,,,,,,,,,,,,,,,,,,,,,,,,,,,,,,,,,,,
67.528,0.90043,21.92498,5,,,,,,,,,,,,,,,,,,,,,,,,,,,,,,,,,,,,,
68.128,1.00039,26.20782,5,,,,,,,,,,,,,,,,,,,,,,,,,,,,,,,,,,,,,
68.728,1.10052,30.91858,5,,,,,,,,,,,,,,,,,,,,,,,,,,,,,,,,,,,,,
69.328,1.2006,35.95917,5,,,,,,,,,,,,,,,,,,,,,,,,,,,,,,,,,,,,,
69.786,1.27687,40.03097,5.5,,,,,,,,,,,,,,,,,,,,,,,,,,,,,,,,,,,,,
70.386,1.17646,34.29269,5.5,,,,,,,,,,,,,,,,,,,,,,,,,,,,,,,,,,,,,
70.986,1.07661,28.86917,5.5,,,,,,,,,,,,,,,,,,,,,,,,,,,,,,,,,,,,,
71.586,0.97659,24.06763,5.5,,,,,,,,,,,,,,,,,,,,,,,,,,,,,,,,,,,,,
72.186,0.87658,19.79638,5.5,,,,,,,,,,,,,,,,,,,,,,,,,,,,,,,,,,,,,
72.786,0.77639,15.83583,5.5,,,,,,,,,,,,,,,,,,,,,,,,,,,,,,,,,,,,,
73.386,0.67649,12.38499,5.5,,,,,,,,,,,,,,,,,,,,,,,,,,,,,,,,,,,,,
73.986,0.57653,9.2474,5.5,,,,,,,,,,,,,,,,,,,,,,,,,,,,,,,,,,,,,
74.586,0.47657,6.42961,5.5,,,,,,,,,,,,,,,,,,,,,,,,,,,,,,,,,,,,,
75.186,0.37649,3.95552,5.5,,,,,,,,,,,,,,,,,,,,,,,,,,,,,,,,,,,,,
75.786,0.27648,1.7678,5.5,,,,,,,,,,,,,,,,,,,,,,,,,,,,,,,,,,,,,
76.148,0.24548,0.96069,6,,,,,,,,,,,,,,,,,,,,,,,,,,,,,,,,,,,,,
76.748,0.3506,3.6168,6,,,,,,,,,,,,,,,,,,,,,,,,,,,,,,,,,,,,,
77.348,0.45044,6.25875,6,,,,,,,,,,,,,,,,,,,,,,,,,,,,,,,,,,,,,
77.948,0.5504,9.20961,6,,,,,,,,,,,,,,,,,,,,,,,,,,,,,,,,,,,,,
78.548,0.65053,12.41086,6,,,,,,,,,,,,,,,,,,,,,,,,,,,,,,,,,,,,,
79.148,0.75055,15.91918,6,,,,,,,,,,,,,,,,,,,,,,,,,,,,,,,,,,,,,
79.748,0.85051,19.69651,6,,,,,,,,,,,,,,,,,,,,,,,,,,,,,,,,,,,,,
80.348,0.95047,23.95305,6,,,,,,,,,,,,,,,,,,,,,,,,,,,,,,,,,,,,,
80.948,1.05049,28.37471,6,,,,,,,,,,,,,,,,,,,,,,,,,,,,,,,,,,,,,
81.548,1.1505,33.31449,6,,,,,,,,,,,,,,,,,,,,,,,,,,,,,,,,,,,,,
82.148,1.25063,38.49847,6,,,,,,,,,,,,,,,,,,,,,,,,,,,,,,,,,,,,,
82.62,1.22882,37.23064,6.5,,,,,,,,,,,,,,,,,,,,,,,,,,,,,,,,,,,,,
83.22,1.12886,31.41432,6.5,,,,,,,,,,,,,,,,,,,,,,,,,,,,,,,,,,,,,
83.82,1.0289,26.34778,6.5,,,,,,,,,,,,,,,,,,,,,,,,,,,,,,,,,,,,,
84.42,0.92894,21.84588,6.5,,,,,,,,,,,,,,,,,,,,,,,,,,,,,,,,,,,,,
85.02,0.82881,17.71388,6.5,,,,,,,,,,,,,,,,,,,,,,,,,,,,,,,,,,,,,
85.62,0.72879,14.0437,6.5,,,,,,,,,,,,,,,,,,,,,,,,,,,,,,,,,,,,,
86.22,0.62889,10.71596,6.5,,,,,,,,,,,,,,,,,,,,,,,,,,,,,,,,,,,,,
86.82,0.52887,7.73941,6.5,,,,,,,,,,,,,,,,,,,,,,,,,,,,,,,,,,,,,
87.42,0.42891,5.11798,6.5,,,,,,,,,,,,,,,,,,,,,,,,,,,,,,,,,,,,,
88.02,0.32872,2.80437,6.5,,,,,,,,,,,,,,,,,,,,,,,,,,,,,,,,,,,,,
88.57,0.23721,0.98871,7,,,,,,,,,,,,,,,,,,,,,,,,,,,,,,,,,,,,,
88.974,0.30413,2.3585,7,,,,,,,,,,,,,,,,,,,,,,,,,,,,,,,,,,,,,
89.574,0.4042,4.91048,7,,,,,,,,,,,,,,,,,,,,,,,,,,,,,,,,,,,,,
90.174,0.50405,7.68674,7,,,,,,,,,,,,,,,,,,,,,,,,,,,,,,,,,,,,,
90.774,0.60412,10.74363,7,,,,,,,,,,,,,,,,,,,,,,,,,,,,,,,,,,,,,
91.374,0.7042,14.0994,7,,,,,,,,,,,,,,,,,,,,,,,,,,,,,,,,,,,,,
91.974,0.80427,17.77785,7,,,,,,,,,,,,,,,,,,,,,,,,,,,,,,,,,,,,,
92.574,0.90412,21.78024,7,,,,,,,,,,,,,,,,,,,,,,,,,,,,,,,,,,,,,
93.174,1.00413,26.15249,7,,,,,,,,,,,,,,,,,,,,,,,,,,,,,,,,,,,,,
93.774,1.10421,30.80117,7,,,,,,,,,,,,,,,,,,,,,,,,,,,,,,,,,,,,,
94.374,1.20417,35.89746,7,,,,,,,,,,,,,,,,,,,,,,,,,,,,,,,,,,,,,
94.836,1.28106,40.02693,7.5,,,,,,,,,,,,,,,,,,,,,,,,,,,,,,,,,,,,,
95.436,1.18082,34.26287,7.5,,,,,,,,,,,,,,,,,,,,,,,,,,,,,,,,,,,,,
96.036,1.08092,28.83381,7.5,,,,,,,,,,,,,,,,,,,,,,,,,,,,,,,,,,,,,
96.636,0.98084,24.08665,7.5,,,,,,,,,,,,,,,,,,,,,,,,,,,,,,,,,,,,,
97.236,0.88088,19.7154,7.5,,,,,,,,,,,,,,,,,,,,,,,,,,,,,,,,,,,,,
97.836,0.7807,15.90639,7.5,,,,,,,,,,,,,,,,,,,,,,,,,,,,,,,,,,,,,
98.436,0.68085,12.29929,7.5,,,,,,,,,,,,,,,,,,,,,,,,,,,,,,,,,,,,,
99.036,0.58083,9.2577,7.5,,,,,,,,,,,,,,,,,,,,,,,,,,,,,,,,,,,,,
99.636,0.48093,6.36366,7.5,,,,,,,,,,,,,,,,,,,,,,,,,,,,,,,,,,,,,
100.236,0.38069,3.92717,7.5,,,,,,,,,,,,,,,,,,,,,,,,,,,,,,,,,,,,,
100.836,0.28084,1.74782,7.5,,,,,,,,,,,,,,,,,,,,,,,,,,,,,,,,,,,,,
101.178,0.25319,0.97403,8,,,,,,,,,,,,,,,,,,,,,,,,,,,,,,,,,,,,,
101.778,0.35819,3.59384,8,,,,,,,,,,,,,,,,,,,,,,,,,,,,,,,,,,,,,
102.378,0.45826,6.28848,8,,,,,,,,,,,,,,,,,,,,,,,,,,,,,,,,,,,,,
102.978,0.558,9.24854,8,,,,,,,,,,,,,,,,,,,,,,,,,,,,,,,,,,,,,
103.578,0.65813,12.53083,8,,,,,,,,,,,,,,,,,,,,,,,,,,,,,,,,,,,,,
104.178,0.7582,16.02419,8,,,,,,,,,,,,,,,,,,,,,,,,,,,,,,,,,,,,,
104.778,0.85827,19.87276,8,,,,,,,,,,,,,,,,,,,,,,,,,,,,,,,,,,,,,
105.378,0.95806,24.02395,8,,,,,,,,,,,,,,,,,,,,,,,,,,,,,,,,,,,,,
105.978,1.05808,28.54022,8,,,,,,,,,,,,,,,,,,,,,,,,,,,,,,,,,,,,,
106.578,1.15815,33.44417,8,,,,,,,,,,,,,,,,,,,,,,,,,,,,,,,,,,,,,
107.178,1.25823,38.68927,8,,,,,,,,,,,,,,,,,,,,,,,,,,,,,,,,,,,,,
107.628,1.23284,37.2863,8.5,,,,,,,,,,,,,,,,,,,,,,,,,,,,,,,,,,,,,
108.228,1.13288,31.46576,8.5,,,,,,,,,,,,,,,,,,,,,,,,,,,,,,,,,,,,,
108.828,1.03292,26.39831,8.5,,,,,,,,,,,,,,,,,,,,,,,,,,,,,,,,,,,,,
109.428,0.93296,21.84698,8.5,,,,,,,,,,,,,,,,,,,,,,,,,,,,,,,,,,,,,
110.028,0.83272,17.77096,8.5,,,,,,,,,,,,,,,,,,,,,,,,,,,,,,,,,,,,,
110.628,0.73276,14.02628,8.5,,,,,,,,,,,,,,,,,,,,,,,,,,,,,,,,,,,,,
111.228,0.63297,10.76343,8.5,,,,,,,,,,,,,,,,,,,,,,,,,,,,,,,,,,,,,
111.828,0.53289,7.79027,8.5,,,,,,,,,,,,,,,,,,,,,,,,,,,,,,,,,,,,,
112.428,0.43288,5.1393,8.5,,,,,,,,,,,,,,,,,,,,,,,,,,,,,,,,,,,,,
113.028,0.33269,2.81938,8.5,,,,,,,,,,,,,,,,,,,,,,,,,,,,,,,,,,,,,
113.568,0.24287,0.98875,9,,,,,,,,,,,,,,,,,,,,,,,,,,,,,,,,,,,,,
113.972,0.30968,2.41138,9,,,,,,,,,,,,,,,,,,,,,,,,,,,,,,,,,,,,,
114.572,0.40987,4.93886,9,,,,,,,,,,,,,,,,,,,,,,,,,,,,,,,,,,,,,
115.172,0.50989,7.76133,9,,,,,,,,,,,,,,,,,,,,,,,,,,,,,,,,,,,,,
115.772,0.60973,10.83418,9,,,,,,,,,,,,,,,,,,,,,,,,,,,,,,,,,,,,,
116.372,0.70975,14.20319,9,,,,,,,,,,,,,,,,,,,,,,,,,,,,,,,,,,,,,
116.972,0.80988,17.85131,9,,,,,,,,,,,,,,,,,,,,,,,,,,,,,,,,,,,,,
117.572,0.90995,21.88904,9,,,,,,,,,,,,,,,,,,,,,,,,,,,,,,,,,,,,,
118.172,1.00969,26.20193,9,,,,,,,,,,,,,,,,,,,,,,,,,,,,,,,,,,,,,
118.772,1.10982,30.92256,9,,,,,,,,,,,,,,,,,,,,,,,,,,,,,,,,,,,,,
119.372,1.20983,36.02893,9,,,,,,,,,,,,,,,,,,,,,,,,,,,,,,,,,,,,,
119.818,1.28407,40.03157,9.5,,,,,,,,,,,,,,,,,,,,,,,,,,,,,,,,,,,,,
120.418,1.18388,34.2234,9.5,,,,,,,,,,,,,,,,,,,,,,,,,,,,,,,,,,,,,
121.018,1.08392,28.83801,9.5,,,,,,,,,,,,,,,,,,,,,,,,,,,,,,,,,,,,,
121.618,0.98385,24.0445,9.5,,,,,,,,,,,,,,,,,,,,,,,,,,,,,,,,,,,,,
122.218,0.88383,19.75827,9.5,,,,,,,,,,,,,,,,,,,,,,,,,,,,,,,,,,,,,
122.818,0.78376,15.83818,9.5,,,,,,,,,,,,,,,,,,,,,,,,,,,,,,,,,,,,,
123.418,0.68391,12.30641,9.5,,,,,,,,,,,,,,,,,,,,,,,,,,,,,,,,,,,,,
124.018,0.58384,9.2519,9.5,,,,,,,,,,,,,,,,,,,,,,,,,,,,,,,,,,,,,
124.618,0.48388,6.49905,9.5,,,,,,,,,,,,,,,,,,,,,,,,,,,,,,,,,,,,,
125.218,0.38369,3.91011,9.5,,,,,,,,,,,,,,,,,,,,,,,,,,,,,,,,,,,,,
125.818,0.2839,1.73512,9.5,,,,,,,,,,,,,,,,,,,,,,,,,,,,,,,,,,,,,
126.254,0.21006,0.3632,10,,,,,,,,,,,,,,,,,,,,,,,,,,,,,,,,,,,,,
126.854,0.19,0.00871,10,,,,,,,,,,,,,,,,,,,,,,,,,,,,,,,,,,,,,
127.454,0.20434,0.24188,10,,,,,,,,,,,,,,,,,,,,,,,,,,,,,,,,,,,,,
128.054,0.24027,1.11438,10,,,,,,,,,,,,,,,,,,,,,,,,,,,,,,,,,,,,,
128.654,0.23811,1.1208,10,,,,,,,,,,,,,,,,,,,,,,,,,,,,,,,,,,,,,
129.254,0.20927,0.48897,10,,,,,,,,,,,,,,,,,,,,,,,,,,,,,,,,,,,,,
129.854,0.20451,0.43157,10,,,,,,,,,,,,,,,,,,,,,,,,,,,,,,,,,,,,,
130.454,0.20491,0.34815,10,,,,,,,,,,,,,,,,,,,,,,,,,,,,,,,,,,,,,
131.054,0.207,0.448,10,,,,,,,,,,,,,,,,,,,,,,,,,,,,,,,,,,,,,
131.654,0.21675,0.69833,10,,,,,,,,,,,,,,,,,,,,,,,,,,,,,,,,,,,,,
132.254,0.22259,0.82352,10,,,,,,,,,,,,,,,,,,,,,,,,,,,,,,,,,,,,,
132.854,0.22236,0.83764,10,,,,,,,,,,,,,,,,,,,,,,,,,,,,,,,,,,,,,
133.454,0.22157,0.85128,10,,,,,,,,,,,,,,,,,,,,,,,,,,,,,,,,,,,,,
134.054,0.21505,0.76057,10,,,,,,,,,,,,,,,,,,,,,,,,,,,,,,,,,,,,,
134.654,0.20842,0.62354,10,,,,,,,,,,,,,,,,,,,,,,,,,,,,,,,,,,,,,
135.254,0.2078,0.58561,10,,,,,,,,,,,,,,,,,,,,,,,,,,,,,,,,,,,,,
135.854,0.20768,0.61004,10,,,,,,,,,,,,,,,,,,,,,,,,,,,,,,,,,,,,,
136.454,0.2078,0.54886,10,,,,,,,,,,,,,,,,,,,,,,,,,,,,,,,,,,,,,
137.054,0.20785,0.54843,10,,,,,,,,,,,,,,,,,,,,,,,,,,,,,,,,,,,,,
137.654,0.20791,0.67266,10,,,,,,,,,,,,,,,,,,,,,,,,,,,,,,,,,,,,,
138.254,0.20791,0.60243,10,,,,,,,,,,,,,,,,,,,,,,,,,,,,,,,,,,,,,
138.854,0.20797,0.58448,10,,,,,,,,,,,,,,,,,,,,,,,,,,,,,,,,,,,,,
139.454,0.20814,0.59498,10,,,,,,,,,,,,,,,,,,,,,,,,,,,,,,,,,,,,,
140.054,0.20825,0.60601,10,,,,,,,,,,,,,,,,,,,,,,,,,,,,,,,,,,,,,
140.654,0.20853,0.69868,10,,,,,,,,,,,,,,,,,,,,,,,,,,,,,,,,,,,,,
141.254,0.20876,0.5651,10,,,,,,,,,,,,,,,,,,,,,,,,,,,,,,,,,,,,,
141.854,0.2091,0.66107,10,,,,,,,,,,,,,,,,,,,,,,,,,,,,,,,,,,,,,
142.454,0.20933,0.62954,10,,,,,,,,,,,,,,,,,,,,,,,,,,,,,,,,,,,,,
143.054,0.2095,0.65607,10,,,,,,,,,,,,,,,,,,,,,,,,,,,,,,,,,,,,,
143.654,0.20955,0.71901,10,,,,,,,,,,,,,,,,,,,,,,,,,,,,,,,,,,,,,
144.254,0.20955,0.69456,10,,,,,,,,,,,,,,,,,,,,,,,,,,,,,,,,,,,,,
144.854,0.20944,0.64618,10,,,,,,,,,,,,,,,,,,,,,,,,,,,,,,,,,,,,,
145.454,0.20938,0.66169,10,,,,,,,,,,,,,,,,,,,,,,,,,,,,,,,,,,,,,
146.054,0.20933,0.70052,10,,,,,,,,,,,,,,,,,,,,,,,,,,,,,,,,,,,,,
146.654,0.20921,0.74153,10,,,,,,,,,,,,,,,,,,,,,,,,,,,,,,,,,,,,,
147.254,0.20916,0.70806,10,,,,,,,,,,,,,,,,,,,,,,,,,,,,,,,,,,,,,
147.854,0.20904,0.70611,10,,,,,,,,,,,,,,,,,,,,,,,,,,,,,,,,,,,,,
148.454,0.20882,0.68366,10,,,,,,,,,,,,,,,,,,,,,,,,,,,,,,,,,,,,,
149.054,0.20842,0.64821,10,,,,,,,,,,,,,,,,,,,,,,,,,,,,,,,,,,,,,
149.654,0.20791,0.73243,10,,,,,,,,,,,,,,,,,,,,,,,,,,,,,,,,,,,,,
150.254,0.20695,0.67941,10,,,,,,,,,,,,,,,,,,,,,,,,,,,,,,,,,,,,,
150.854,0.20525,0.65995,10,,,,,,,,,,,,,,,,,,,,,,,,,,,,,,,,,,,,,
151.454,0.20394,0.6369,10,,,,,,,,,,,,,,,,,,,,,,,,,,,,,,,,,,,,,
152.054,0.20349,0.62073,10,,,,,,,,,,,,,,,,,,,,,,,,,,,,,,,,,,,,,
152.654,0.20332,0.55056,10,,,,,,,,,,,,,,,,,,,,,,,,,,,,,,,,,,,,,
153.254,0.20343,0.55491,10,,,,,,,,,,,,,,,,,,,,,,,,,,,,,,,,,,,,,
153.854,0.20343,0.66796,10,,,,,,,,,,,,,,,,,,,,,,,,,,,,,,,,,,,,,
154.454,0.20349,0.64083,10,,,,,,,,,,,,,,,,,,,,,,,,,,,,,,,,,,,,,
155.054,0.20349,0.68953,10,,,,,,,,,,,,,,,,,,,,,,,,,,,,,,,,,,,,,
155.654,0.20355,0.58888,10,,,,,,,,,,,,,,,,,,,,,,,,,,,,,,,,,,,,,
156.254,0.20355,0.64804,10,,,,,,,,,,,,,,,,,,,,,,,,,,,,,,,,,,,,,
156.854,0.20349,0.5916,10,,,,,,,,,,,,,,,,,,,,,,,,,,,,,,,,,,,,,
157.454,0.2036,0.65051,10,,,,,,,,,,,,,,,,,,,,,,,,,,,,,,,,,,,,,
158.054,0.20372,0.60684,10,,,,,,,,,,,,,,,,,,,,,,,,,,,,,,,,,,,,,
158.654,0.20377,0.58933,10,,,,,,,,,,,,,,,,,,,,,,,,,,,,,,,,,,,,,
159.254,0.20377,0.62366,10,,,,,,,,,,,,,,,,,,,,,,,,,,,,,,,,,,,,,
159.854,0.20383,0.64152,10,,,,,,,,,,,,,,,,,,,,,,,,,,,,,,,,,,,,,
160.454,0.20389,0.65982,10,,,,,,,,,,,,,,,,,,,,,,,,,,,,,,,,,,,,,
161.054,0.20394,0.619,10,,,,,,,,,,,,,,,,,,,,,,,,,,,,,,,,,,,,,
161.654,0.204,0.63839,10,,,,,,,,,,,,,,,,,,,,,,,,,,,,,,,,,,,,,
162.254,0.20411,0.65702,10,,,,,,,,,,,,,,,,,,,,,,,,,,,,,,,,,,,,,
162.854,0.20428,0.57496,10,,,,,,,,,,,,,,,,,,,,,,,,,,,,,,,,,,,,,
163.454,0.20445,0.66378,10,,,,,,,,,,,,,,,,,,,,,,,,,,,,,,,,,,,,,
164.054,0.20462,0.5642,10,,,,,,,,,,,,,,,,,,,,,,,,,,,,,,,,,,,,,
164.654,0.20479,0.70021,10,,,,,,,,,,,,,,,,,,,,,,,,,,,,,,,,,,,,,
165.254,0.20491,0.67928,10,,,,,,,,,,,,,,,,,,,,,,,,,,,,,,,,,,,,,
165.854,0.20479,0.67822,10,,,,,,,,,,,,,,,,,,,,,,,,,,,,,,,,,,,,,
166.454,0.20479,0.65558,10,,,,,,,,,,,,,,,,,,,,,,,,,,,,,,,,,,,,,
167.054,0.20474,0.69502,10,,,,,,,,,,,,,,,,,,,,,,,,,,,,,,,,,,,,,
167.654,0.20479,0.69749,10,,,,,,,,,,,,,,,,,,,,,,,,,,,,,,,,,,,,,
168.254,0.20462,0.63089,10,,,,,,,,,,,,,,,,,,,,,,,,,,,,,,,,,,,,,
168.854,0.20457,0.65199,10,,,,,,,,,,,,,,,,,,,,,,,,,,,,,,,,,,,,,
169.454,0.20451,0.59544,10,,,,,,,,,,,,,,,,,,,,,,,,,,,,,,,,,,,,,
170.054,0.20445,0.68796,10,,,,,,,,,,,,,,,,,,,,,,,,,,,,,,,,,,,,,
170.654,0.20428,0.70048,10,,,,,,,,,,,,,,,,,,,,,,,,,,,,,,,,,,,,,
171.254,0.20406,0.72883,10,,,,,,,,,,,,,,,,,,,,,,,,,,,,,,,,,,,,,
171.854,0.20349,0.70008,10,,,,,,,,,,,,,,,,,,,,,,,,,,,,,,,,,,,,,
172.454,0.20258,0.67636,10,,,,,,,,,,,,,,,,,,,,,,,,,,,,,,,,,,,,,
173.054,0.20105,0.6761,10,,,,,,,,,,,,,,,,,,,,,,,,,,,,,,,,,,,,,
173.654,0.2002,0.64161,10,,,,,,,,,,,,,,,,,,,,,,,,,,,,,,,,,,,,,
174.254,0.19969,0.60668,10,,,,,,,,,,,,,,,,,,,,,,,,,,,,,,,,,,,,,
174.854,0.19947,0.57624,10,,,,,,,,,,,,,,,,,,,,,,,,,,,,,,,,,,,,,
175.454,0.19952,0.59346,10,,,,,,,,,,,,,,,,,,,,,,,,,,,,,,,,,,,,,
176.054,0.19952,0.57284,10,,,,,,,,,,,,,,,,,,,,,,,,,,,,,,,,,,,,,
176.654,0.19958,0.62933,10,,,,,,,,,,,,,,,,,,,,,,,,,,,,,,,,,,,,,
177.254,0.19969,0.59604,10,,,,,,,,,,,,,,,,,,,,,,,,,,,,,,,,,,,,,
177.854,0.19975,0.63446,10,,,,,,,,,,,,,,,,,,,,,,,,,,,,,,,,,,,,,
178.454,0.19981,0.58087,10,,,,,,,,,,,,,,,,,,,,,,,,,,,,,,,,,,,,,
179.054,0.19992,0.61293,10,,,,,,,,,,,,,,,,,,,,,,,,,,,,,,,,,,,,,
179.654,0.20003,0.55585,10,,,,,,,,,,,,,,,,,,,,,,,,,,,,,,,,,,,,,
180.254,0.20032,0.60476,10,,,,,,,,,,,,,,,,,,,,,,,,,,,,,,,,,,,,,
180.854,0.2006,0.55026,10,,,,,,,,,,,,,,,,,,,,,,,,,,,,,,,,,,,,,
181.454,0.20088,0.58618,10,,,,,,,,,,,,,,,,,,,,,,,,,,,,,,,,,,,,,
182.054,0.20134,0.59997,10,,,,,,,,,,,,,,,,,,,,,,,,,,,,,,,,,,,,,
182.654,0.20207,0.62208,10,,,,,,,,,,,,,,,,,,,,,,,,,,,,,,,,,,,,,
183.254,0.20264,0.61295,10,,,,,,,,,,,,,,,,,,,,,,,,,,,,,,,,,,,,,
183.854,0.20304,0.65665,10,,,,,,,,,,,,,,,,,,,,,,,,,,,,,,,,,,,,,
184.454,0.20315,0.63263,10,,,,,,,,,,,,,,,,,,,,,,,,,,,,,,,,,,,,,
185.054,0.20326,0.6567,10,,,,,,,,,,,,,,,,,,,,,,,,,,,,,,,,,,,,,
185.654,0.20326,0.61112,10,,,,,,,,,,,,,,,,,,,,,,,,,,,,,,,,,,,,,
186.254,0.20321,0.64871,10,,,,,,,,,,,,,,,,,,,,,,,,,,,,,,,,,,,,,
186.854,0.20326,0.71116,10,,,,,,,,,,,,,,,,,,,,,,,,,,,,,,,,,,,,,
187.454,0.20321,0.72337,10,,,,,,,,,,,,,,,,,,,,,,,,,,,,,,,,,,,,,
188.054,0.20304,0.70647,10,,,,,,,,,,,,,,,,,,,,,,,,,,,,,,,,,,,,,
188.654,0.20298,0.70676,10,,,,,,,,,,,,,,,,,,,,,,,,,,,,,,,,,,,,,
189.254,0.20292,0.67302,10,,,,,,,,,,,,,,,,,,,,,,,,,,,,,,,,,,,,,
189.854,0.20281,0.70536,10,,,,,,,,,,,,,,,,,,,,,,,,,,,,,,,,,,,,,
190.454,0.20258,0.68214,10,,,,,,,,,,,,,,,,,,,,,,,,,,,,,,,,,,,,,
191.054,0.20219,0.74508,10,,,,,,,,,,,,,,,,,,,,,,,,,,,,,,,,,,,,,
191.654,0.20162,0.70414,10,,,,,,,,,,,,,,,,,,,,,,,,,,,,,,,,,,,,,
192.254,0.20094,0.68019,10,,,,,,,,,,,,,,,,,,,,,,,,,,,,,,,,,,,,,
192.854,0.20015,0.66661,10,,,,,,,,,,,,,,,,,,,,,,,,,,,,,,,,,,,,,
193.454,0.19941,0.64877,10,,,,,,,,,,,,,,,,,,,,,,,,,,,,,,,,,,,,,
194.054,0.19884,0.63124,10,,,,,,,,,,,,,,,,,,,,,,,,,,,,,,,,,,,,,
194.654,0.19845,0.59199,10,,,,,,,,,,,,,,,,,,,,,,,,,,,,,,,,,,,,,
195.254,0.19816,0.59753,10,,,,,,,,,,,,,,,,,,,,,,,,,,,,,,,,,,,,,
195.854,0.19799,0.66843,10,,,,,,,,,,,,,,,,,,,,,,,,,,,,,,,,,,,,,
196.454,0.19777,0.62204,10,,,,,,,,,,,,,,,,,,,,,,,,,,,,,,,,,,,,,
197.054,0.19765,0.5896,10,,,,,,,,,,,,,,,,,,,,,,,,,,,,,,,,,,,,,
197.654,0.19777,0.57588,10,,,,,,,,,,,,,,,,,,,,,,,,,,,,,,,,,,,,,
198.254,0.19782,0.6532,10,,,,,,,,,,,,,,,,,,,,,,,,,,,,,,,,,,,,,
198.854,0.19788,0.59104,10,,,,,,,,,,,,,,,,,,,,,,,,,,,,,,,,,,,,,
199.454,0.19788,0.60684,10,,,,,,,,,,,,,,,,,,,,,,,,,,,,,,,,,,,,,
200.054,0.19788,0.66326,10,,,,,,,,,,,,,,,,,,,,,,,,,,,,,,,,,,,,,
200.654,0.19794,0.59101,10,,,,,,,,,,,,,,,,,,,,,,,,,,,,,,,,,,,,,
201.254,0.19799,0.62965,10,,,,,,,,,,,,,,,,,,,,,,,,,,,,,,,,,,,,,
201.854,0.19805,0.59502,10,,,,,,,,,,,,,,,,,,,,,,,,,,,,,,,,,,,,,
202.454,0.19811,0.63654,10,,,,,,,,,,,,,,,,,,,,,,,,,,,,,,,,,,,,,
203.054,0.19822,0.60506,10,,,,,,,,,,,,,,,,,,,,,,,,,,,,,,,,,,,,,
203.654,0.19833,0.61625,10,,,,,,,,,,,,,,,,,,,,,,,,,,,,,,,,,,,,,
204.254,0.1985,0.59496,10,,,,,,,,,,,,,,,,,,,,,,,,,,,,,,,,,,,,,
204.854,0.19873,0.5916,10,,,,,,,,,,,,,,,,,,,,,,,,,,,,,,,,,,,,,
205.454,0.19913,0.60423,10,,,,,,,,,,,,,,,,,,,,,,,,,,,,,,,,,,,,,
206.054,0.19975,0.602,10,,,,,,,,,,,,,,,,,,,,,,,,,,,,,,,,,,,,,
206.654,0.20032,0.64764,10,,,,,,,,,,,,,,,,,,,,,,,,,,,,,,,,,,,,,
207.254,0.201,0.64302,10,,,,,,,,,,,,,,,,,,,,,,,,,,,,,,,,,,,,,
207.854,0.20162,0.69321,10,,,,,,,,,,,,,,,,,,,,,,,,,,,,,,,,,,,,,
208.454,0.20185,0.61984,10,,,,,,,,,,,,,,,,,,,,,,,,,,,,,,,,,,,,,
209.054,0.20196,0.66046,10,,,,,,,,,,,,,,,,,,,,,,,,,,,,,,,,,,,,,
209.654,0.20185,0.69212,10,,,,,,,,,,,,,,,,,,,,,,,,,,,,,,,,,,,,,
210.254,0.20185,0.66214,10,,,,,,,,,,,,,,,,,,,,,,,,,,,,,,,,,,,,,
210.854,0.20173,0.67823,10,,,,,,,,,,,,,,,,,,,,,,,,,,,,,,,,,,,,,
211.454,0.20173,0.67796,10,,,,,,,,,,,,,,,,,,,,,,,,,,,,,,,,,,,,,
212.054,0.20156,0.6758,10,,,,,,,,,,,,,,,,,,,,,,,,,,,,,,,,,,,,,
212.654,0.20145,0.75155,10,,,,,,,,,,,,,,,,,,,,,,,,,,,,,,,,,,,,,
213.254,0.20117,0.72643,10,,,,,,,,,,,,,,,,,,,,,,,,,,,,,,,,,,,,,
213.854,0.20071,0.7192,10,,,,,,,,,,,,,,,,,,,,,,,,,,,,,,,,,,,,,
214.454,0.19975,0.69632,10,,,,,,,,,,,,,,,,,,,,,,,,,,,,,,,,,,,,,
215.054,0.19788,0.70016,10,,,,,,,,,,,,,,,,,,,,,,,,,,,,,,,,,,,,,
215.654,0.19618,0.64318,10,,,,,,,,,,,,,,,,,,,,,,,,,,,,,,,,,,,,,
216.254,0.19454,0.641,10,,,,,,,,,,,,,,,,,,,,,,,,,,,,,,,,,,,,,
216.854,0.19391,0.61258,10,,,,,,,,,,,,,,,,,,,,,,,,,,,,,,,,,,,,,
217.454,0.19363,0.54941,10,,,,,,,,,,,,,,,,,,,,,,,,,,,,,,,,,,,,,
218.054,0.19374,0.58047,10,,,,,,,,,,,,,,,,,,,,,,,,,,,,,,,,,,,,,
218.654,0.1938,0.63424,10,,,,,,,,,,,,,,,,,,,,,,,,,,,,,,,,,,,,,
219.254,0.19386,0.64217,10,,,,,,,,,,,,,,,,,,,,,,,,,,,,,,,,,,,,,
219.854,0.19397,0.58838,10,,,,,,,,,,,,,,,,,,,,,,,,,,,,,,,,,,,,,
220.454,0.19408,0.62784,10,,,,,,,,,,,,,,,,,,,,,,,,,,,,,,,,,,,,,
221.054,0.19414,0.6087,10,,,,,,,,,,,,,,,,,,,,,,,,,,,,,,,,,,,,,
221.654,0.19442,0.57857,10,,,,,,,,,,,,,,,,,,,,,,,,,,,,,,,,,,,,,
222.254,0.19482,0.5747,10,,,,,,,,,,,,,,,,,,,,,,,,,,,,,,,,,,,,,
222.854,0.19539,0.61298,10,,,,,,,,,,,,,,,,,,,,,,,,,,,,,,,,,,,,,
223.454,0.19629,0.57213,10,,,,,,,,,,,,,,,,,,,,,,,,,,,,,,,,,,,,,
224.054,0.19754,0.63338,10,,,,,,,,,,,,,,,,,,,,,,,,,,,,,,,,,,,,,
224.654,0.19799,0.69995,10,,,,,,,,,,,,,,,,,,,,,,,,,,,,,,,,,,,,,
225.254,0.19816,0.64322,10,,,,,,,,,,,,,,,,,,,,,,,,,,,,,,,,,,,,,
225.854,0.19822,0.69479,10,,,,,,,,,,,,,,,,,,,,,,,,,,,,,,,,,,,,,
226.454,0.19816,0.70185,10,,,,,,,,,,,,,,,,,,,,,,,,,,,,,,,,,,,,,
227.054,0.19799,0.71809,10,,,,,,,,,,,,,,,,,,,,,,,,,,,,,,,,,,,,,
227.654,0.19794,0.67071,10,,,,,,,,,,,,,,,,,,,,,,,,,,,,,,,,,,,,,
228.254,0.19788,0.70241,10,,,,,,,,,,,,,,,,,,,,,,,,,,,,,,,,,,,,,
228.854,0.19765,0.75348,10,,,,,,,,,,,,,,,,,,,,,,,,,,,,,,,,,,,,,
229.454,0.19748,0.69495,10,,,,,,,,,,,,,,,,,,,,,,,,,,,,,,,,,,,,,
230.054,0.19714,0.71935,10,,,,,,,,,,,,,,,,,,,,,,,,,,,,,,,,,,,,,
230.654,0.19646,0.71877,10,,,,,,,,,,,,,,,,,,,,,,,,,,,,,,,,,,,,,
231.254,0.19561,0.64573,10,,,,,,,,,,,,,,,,,,,,,,,,,,,,,,,,,,,,,
231.854,0.19482,0.69971,10,,,,,,,,,,,,,,,,,,,,,,,,,,,,,,,,,,,,,
232.454,0.19408,0.68802,10,,,,,,,,,,,,,,,,,,,,,,,,,,,,,,,,,,,,,
233.054,0.19357,0.64468,10,,,,,,,,,,,,,,,,,,,,,,,,,,,,,,,,,,,,,
233.654,0.19335,0.64583,10,,,,,,,,,,,,,,,,,,,,,,,,,,,,,,,,,,,,,
234.254,0.19323,0.60758,10,,,,,,,,,,,,,,,,,,,,,,,,,,,,,,,,,,,,,
234.854,0.19318,0.63575,10,,,,,,,,,,,,,,,,,,,,,,,,,,,,,,,,,,,,,
235.454,0.19329,0.56265,10,,,,,,,,,,,,,,,,,,,,,,,,,,,,,,,,,,,,,
236.054,0.19329,0.6513,10,,,,,,,,,,,,,,,,,,,,,,,,,,,,,,,,,,,,,
236.654,0.19329,0.62739,10,,,,,,,,,,,,,,,,,,,,,,,,,,,,,,,,,,,,,
237.254,0.19329,0.64013,10,,,,,,,,,,,,,,,,,,,,,,,,,,,,,,,,,,,,,
237.854,0.19335,0.65667,10,,,,,,,,,,,,,,,,,,,,,,,,,,,,,,,,,,,,,
238.454,0.19335,0.65083,10,,,,,,,,,,,,,,,,,,,,,,,,,,,,,,,,,,,,,
239.054,0.1934,0.62586,10,,,,,,,,,,,,,,,,,,,,,,,,,,,,,,,,,,,,,
239.654,0.1934,0.60857,10,,,,,,,,,,,,,,,,,,,,,,,,,,,,,,,,,,,,,
240.254,0.19346,0.57501,10,,,,,,,,,,,,,,,,,,,,,,,,,,,,,,,,,,,,,
240.854,0.19346,0.68308,10,,,,,,,,,,,,,,,,,,,,,,,,,,,,,,,,,,,,,
241.454,0.19346,0.67521,10,,,,,,,,,,,,,,,,,,,,,,,,,,,,,,,,,,,,,
242.054,0.19346,0.66439,10,,,,,,,,,,,,,,,,,,,,,,,,,,,,,,,,,,,,,
242.654,0.19346,0.61855,10,,,,,,,,,,,,,,,,,,,,,,,,,,,,,,,,,,,,,
243.254,0.19346,0.60458,10,,,,,,,,,,,,,,,,,,,,,,,,,,,,,,,,,,,,,
243.854,0.19346,0.59875,10,,,,,,,,,,,,,,,,,,,,,,,,,,,,,,,,,,,,,
244.454,0.19346,0.66007,10,,,,,,,,,,,,,,,,,,,,,,,,,,,,,,,,,,,,,
245.054,0.1934,0.66645,10,,,,,,,,,,,,,,,,,,,,,,,,,,,,,,,,,,,,,
245.654,0.1934,0.68416,10,,,,,,,,,,,,,,,,,,,,,,,,,,,,,,,,,,,,,
246.254,0.19335,0.67685,10,,,,,,,,,,,,,,,,,,,,,,,,,,,,,,,,,,,,,
246.854,0.19335,0.7423,10,,,,,,,,,,,,,,,,,,,,,,,,,,,,,,,,,,,,,
247.454,0.19335,0.62817,10,,,,,,,,,,,,,,,,,,,,,,,,,,,,,,,,,,,,,
248.054,0.19346,0.67947,10,,,,,,,,,,,,,,,,,,,,,,,,,,,,,,,,,,,,,
248.654,0.19346,0.62818,10,,,,,,,,,,,,,,,,,,,,,,,,,,,,,,,,,,,,,
249.254,0.19346,0.62497,10,,,,,,,,,,,,,,,,,,,,,,,,,,,,,,,,,,,,,
249.854,0.19335,0.67332,10,,,,,,,,,,,,,,,,,,,,,,,,,,,,,,,,,,,,,
250.454,0.19335,0.63944,10,,,,,,,,,,,,,,,,,,,,,,,,,,,,,,,,,,,,,
251.054,0.19335,0.63043,10,,,,,,,,,,,,,,,,,,,,,,,,,,,,,,,,,,,,,
251.654,0.19346,0.68658,10,,,,,,,,,,,,,,,,,,,,,,,,,,,,,,,,,,,,,
252.254,0.19335,0.59173,10,,,,,,,,,,,,,,,,,,,,,,,,,,,,,,,,,,,,,
252.854,0.19335,0.66771,10,,,,,,,,,,,,,,,,,,,,,,,,,,,,,,,,,,,,,
253.454,0.1934,0.66825,10,,,,,,,,,,,,,,,,,,,,,,,,,,,,,,,,,,,,,
254.054,0.1934,0.70053,10,,,,,,,,,,,,,,,,,,,,,,,,,,,,,,,,,,,,,
254.654,0.1934,0.704,10,,,,,,,,,,,,,,,,,,,,,,,,,,,,,,,,,,,,,
255.254,0.1934,0.6619,10,,,,,,,,,,,,,,,,,,,,,,,,,,,,,,,,,,,,,
255.854,0.19329,0.65935,10,,,,,,,,,,,,,,,,,,,,,,,,,,,,,,,,,,,,,
256.454,0.19335,0.6203,10,,,,,,,,,,,,,,,,,,,,,,,,,,,,,,,,,,,,,
257.054,0.19335,0.62832,10,,,,,,,,,,,,,,,,,,,,,,,,,,,,,,,,,,,,,
257.654,0.19335,0.6552,10,,,,,,,,,,,,,,,,,,,,,,,,,,,,,,,,,,,,,
258.254,0.19335,0.62161,10,,,,,,,,,,,,,,,,,,,,,,,,,,,,,,,,,,,,,
258.854,0.19335,0.70587,10,,,,,,,,,,,,,,,,,,,,,,,,,,,,,,,,,,,,,
259.454,0.19323,0.6799,10,,,,,,,,,,,,,,,,,,,,,,,,,,,,,,,,,,,,,
260.054,0.19323,0.66034,10,,,,,,,,,,,,,,,,,,,,,,,,,,,,,,,,,,,,,
260.654,0.19323,0.73345,10,,,,,,,,,,,,,,,,,,,,,,,,,,,,,,,,,,,,,
261.254,0.19329,0.67936,10,,,,,,,,,,,,,,,,,,,,,,,,,,,,,,,,,,,,,
261.854,0.19329,0.67145,10,,,,,,,,,,,,,,,,,,,,,,,,,,,,,,,,,,,,,
262.454,0.19312,0.61355,10,,,,,,,,,,,,,,,,,,,,,,,,,,,,,,,,,,,,,
263.054,0.19284,0.67567,10,,,,,,,,,,,,,,,,,,,,,,,,,,,,,,,,,,,,,
263.654,0.19193,0.69412,10,,,,,,,,,,,,,,,,,,,,,,,,,,,,,,,,,,,,,
264.254,0.18938,0.64232,10,,,,,,,,,,,,,,,,,,,,,,,,,,,,,,,,,,,,,
264.854,0.18842,0.58115,10,,,,,,,,,,,,,,,,,,,,,,,,,,,,,,,,,,,,,
265.454,0.18819,0.54922,10,,,,,,,,,,,,,,,,,,,,,,,,,,,,,,,,,,,,,
266.054,0.1883,0.57585,10,,,,,,,,,,,,,,,,,,,,,,,,,,,,,,,,,,,,,
266.654,0.18847,0.60401,10,,,,,,,,,,,,,,,,,,,,,,,,,,,,,,,,,,,,,
267.254,0.18853,0.58385,10,,,,,,,,,,,,,,,,,,,,,,,,,,,,,,,,,,,,,
267.854,0.18864,0.58838,10,,,,,,,,,,,,,,,,,,,,,,,,,,,,,,,,,,,,,
268.454,0.18893,0.54953,10,,,,,,,,,,,,,,,,,,,,,,,,,,,,,,,,,,,,,
269.054,0.18961,0.60621,10,,,,,,,,,,,,,,,,,,,,,,,,,,,,,,,,,,,,,
269.654,0.19063,0.58591,10,,,,,,,,,,,,,,,,,,,,,,,,,,,,,,,,,,,,,
270.254,0.19272,0.57432,10,,,,,,,,,,,,,,,,,,,,,,,,,,,,,,,,,,,,,
270.854,0.19573,0.68726,10,,,,,,,,,,,,,,,,,,,,,,,,,,,,,,,,,,,,,
271.454,0.19618,0.72765,10,,,,,,,,,,,,,,,,,,,,,,,,,,,,,,,,,,,,,
272.054,0.19624,0.72432,10,,,,,,,,,,,,,,,,,,,,,,,,,,,,,,,,,,,,,
272.654,0.19612,0.64309,10,,,,,,,,,,,,,,,,,,,,,,,,,,,,,,,,,,,,,
273.254,0.19612,0.73781,10,,,,,,,,,,,,,,,,,,,,,,,,,,,,,,,,,,,,,
273.854,0.19595,0.65372,10,,,,,,,,,,,,,,,,,,,,,,,,,,,,,,,,,,,,,
274.454,0.19584,0.68693,10,,,,,,,,,,,,,,,,,,,,,,,,,,,,,,,,,,,,,
275.054,0.19567,0.69836,10,,,,,,,,,,,,,,,,,,,,,,,,,,,,,,,,,,,,,
275.654,0.19539,0.76267,10,,,,,,,,,,,,,,,,,,,,,,,,,,,,,,,,,,,,,
276.254,0.19454,0.68723,10,,,,,,,,,,,,,,,,,,,,,,,,,,,,,,,,,,,,,
276.854,0.19346,0.62006,10,,,,,,,,,,,,,,,,,,,,,,,,,,,,,,,,,,,,,
277.454,0.1925,0.68077,10,,,,,,,,,,,,,,,,,,,,,,,,,,,,,,,,,,,,,
278.054,0.1917,0.65502,10,,,,,,,,,,,,,,,,,,,,,,,,,,,,,,,,,,,,,
278.654,0.19074,0.66759,10,,,,,,,,,,,,,,,,,,,,,,,,,,,,,,,,,,,,,
279.254,0.1904,0.6326,10,,,,,,,,,,,,,,,,,,,,,,,,,,,,,,,,,,,,,
279.854,0.19006,0.66389,10,,,,,,,,,,,,,,,,,,,,,,,,,,,,,,,,,,,,,
280.454,0.18983,0.63565,10,,,,,,,,,,,,,,,,,,,,,,,,,,,,,,,,,,,,,
281.054,0.18966,0.64293,10,,,,,,,,,,,,,,,,,,,,,,,,,,,,,,,,,,,,,
281.654,0.18961,0.63224,10,,,,,,,,,,,,,,,,,,,,,,,,,,,,,,,,,,,,,
282.254,0.18955,0.61576,10,,,,,,,,,,,,,,,,,,,,,,,,,,,,,,,,,,,,,
282.854,0.18966,0.56701,10,,,,,,,,,,,,,,,,,,,,,,,,,,,,,,,,,,,,,
283.454,0.18972,0.63044,10,,,,,,,,,,,,,,,,,,,,,,,,,,,,,,,,,,,,,
284.054,0.18978,0.61945,10,,,,,,,,,,,,,,,,,,,,,,,,,,,,,,,,,,,,,
284.654,0.18983,0.69279,10,,,,,,,,,,,,,,,,,,,,,,,,,,,,,,,,,,,,,
285.254,0.18989,0.61092,10,,,,,,,,,,,,,,,,,,,,,,,,,,,,,,,,,,,,,
285.854,0.18995,0.57568,10,,,,,,,,,,,,,,,,,,,,,,,,,,,,,,,,,,,,,
286.454,0.18995,0.65049,10,,,,,,,,,,,,,,,,,,,,,,,,,,,,,,,,,,,,,
287.054,0.19006,0.64142,10,,,,,,,,,,,,,,,,,,,,,,,,,,,,,,,,,,,,,
287.654,0.19017,0.60072,10,,,,,,,,,,,,,,,,,,,,,,,,,,,,,,,,,,,,,
288.254,0.1904,0.61751,10,,,,,,,,,,,,,,,,,,,,,,,,,,,,,,,,,,,,,
288.854,0.19063,0.6015,10,,,,,,,,,,,,,,,,,,,,,,,,,,,,,,,,,,,,,
289.454,0.19108,0.57224,10,,,,,,,,,,,,,,,,,,,,,,,,,,,,,,,,,,,,,
290.054,0.19238,0.59726,10,,,,,,,,,,,,,,,,,,,,,,,,,,,,,,,,,,,,,
290.654,0.19374,0.62084,10,,,,,,,,,,,,,,,,,,,,,,,,,,,,,,,,,,,,,
291.254,0.19459,0.67082,10,,,,,,,,,,,,,,,,,,,,,,,,,,,,,,,,,,,,,
291.854,0.19488,0.66486,10,,,,,,,,,,,,,,,,,,,,,,,,,,,,,,,,,,,,,
292.454,0.19493,0.6844,10,,,,,,,,,,,,,,,,,,,,,,,,,,,,,,,,,,,,,
293.054,0.19488,0.7239,10,,,,,,,,,,,,,,,,,,,,,,,,,,,,,,,,,,,,,
293.654,0.19471,0.74832,10,,,,,,,,,,,,,,,,,,,,,,,,,,,,,,,,,,,,,
294.254,0.19465,0.66033,10,,,,,,,,,,,,,,,,,,,,,,,,,,,,,,,,,,,,,
294.854,0.19459,0.71476,10,,,,,,,,,,,,,,,,,,,,,,,,,,,,,,,,,,,,,
295.454,0.19442,0.69763,10,,,,,,,,,,,,,,,,,,,,,,,,,,,,,,,,,,,,,
296.054,0.19414,0.73245,10,,,,,,,,,,,,,,,,,,,,,,,,,,,,,,,,,,,,,
296.654,0.19363,0.69154,10,,,,,,,,,,,,,,,,,,,,,,,,,,,,,,,,,,,,,
297.254,0.19289,0.67176,10,,,,,,,,,,,,,,,,,,,,,,,,,,,,,,,,,,,,,
297.854,0.19187,0.72526,10,,,,,,,,,,,,,,,,,,,,,,,,,,,,,,,,,,,,,
298.454,0.1908,0.60944,10,,,,,,,,,,,,,,,,,,,,,,,,,,,,,,,,,,,,,
299.054,0.19017,0.66298,10,,,,,,,,,,,,,,,,,,,,,,,,,,,,,,,,,,,,,
299.654,0.18966,0.63994,10,,,,,,,,,,,,,,,,,,,,,,,,,,,,,,,,,,,,,
300.254,0.18944,0.62563,10,,,,,,,,,,,,,,,,,,,,,,,,,,,,,,,,,,,,,
300.854,0.18944,0.55527,10,,,,,,,,,,,,,,,,,,,,,,,,,,,,,,,,,,,,,
301.454,0.18944,0.61944,10,,,,,,,,,,,,,,,,,,,,,,,,,,,,,,,,,,,,,
302.054,0.18944,0.59207,10,,,,,,,,,,,,,,,,,,,,,,,,,,,,,,,,,,,,,
302.654,0.18955,0.65198,10,,,,,,,,,,,,,,,,,,,,,,,,,,,,,,,,,,,,,
303.254,0.18961,0.58934,10,,,,,,,,,,,,,,,,,,,,,,,,,,,,,,,,,,,,,
303.854,0.18966,0.60792,10,,,,,,,,,,,,,,,,,,,,,,,,,,,,,,,,,,,,,
304.454,0.18972,0.61685,10,,,,,,,,,,,,,,,,,,,,,,,,,,,,,,,,,,,,,
305.054,0.18978,0.59892,10,,,,,,,,,,,,,,,,,,,,,,,,,,,,,,,,,,,,,
305.654,0.18989,0.58684,10,,,,,,,,,,,,,,,,,,,,,,,,,,,,,,,,,,,,,
306.254,0.19006,0.55375,10,,,,,,,,,,,,,,,,,,,,,,,,,,,,,,,,,,,,,
306.854,0.1904,0.61587,10,,,,,,,,,,,,,,,,,,,,,,,,,,,,,,,,,,,,,
307.454,0.1908,0.57631,10,,,,,,,,,,,,,,,,,,,,,,,,,,,,,,,,,,,,,
308.054,0.19165,0.59284,10,,,,,,,,,,,,,,,,,,,,,,,,,,,,,,,,,,,,,
308.654,0.19295,0.66077,10,,,,,,,,,,,,,,,,,,,,,,,,,,,,,,,,,,,,,
309.254,0.19369,0.64342,10,,,,,,,,,,,,,,,,,,,,,,,,,,,,,,,,,,,,,
309.854,0.19425,0.6818,10,,,,,,,,,,,,,,,,,,,,,,,,,,,,,,,,,,,,,
310.454,0.19437,0.69301,10,,,,,,,,,,,,,,,,,,,,,,,,,,,,,,,,,,,,,
311.054,0.1942,0.7102,10,,,,,,,,,,,,,,,,,,,,,,,,,,,,,,,,,,,,,
311.654,0.1942,0.68552,10,,,,,,,,,,,,,,,,,,,,,,,,,,,,,,,,,,,,,
312.254,0.19414,0.6772,10,,,,,,,,,,,,,,,,,,,,,,,,,,,,,,,,,,,,,
312.854,0.19403,0.63155,10,,,,,,,,,,,,,,,,,,,,,,,,,,,,,,,,,,,,,
313.454,0.19397,0.68508,10,,,,,,,,,,,,,,,,,,,,,,,,,,,,,,,,,,,,,
314.054,0.19386,0.76888,10,,,,,,,,,,,,,,,,,,,,,,,,,,,,,,,,,,,,,
314.654,0.19369,0.62475,10,,,,,,,,,,,,,,,,,,,,,,,,,,,,,,,,,,,,,
315.254,0.19346,0.75662,10,,,,,,,,,,,,,,,,,,,,,,,,,,,,,,,,,,,,,
315.854,0.19312,0.71104,10,,,,,,,,,,,,,,,,,,,,,,,,,,,,,,,,,,,,,
316.454,0.19227,0.67445,10,,,,,,,,,,,,,,,,,,,,,,,,,,,,,,,,,,,,,
317.054,0.19131,0.68844,10,,,,,,,,,,,,,,,,,,,,,,,,,,,,,,,,,,,,,
317.654,0.19051,0.67769,10,,,,,,,,,,,,,,,,,,,,,,,,,,,,,,,,,,,,,
318.254,0.18983,0.6654,10,,,,,,,,,,,,,,,,,,,,,,,,,,,,,,,,,,,,,
318.854,0.18927,0.67035,10,,,,,,,,,,,,,,,,,,,,,,,,,,,,,,,,,,,,,
319.454,0.18898,0.60547,10,,,,,,,,,,,,,,,,,,,,,,,,,,,,,,,,,,,,,
320.054,0.18887,0.68822,10,,,,,,,,,,,,,,,,,,,,,,,,,,,,,,,,,,,,,
320.654,0.18893,0.59427,10,,,,,,,,,,,,,,,,,,,,,,,,,,,,,,,,,,,,,
321.254,0.18898,0.56196,10,,,,,,,,,,,,,,,,,,,,,,,,,,,,,,,,,,,,,
321.854,0.18904,0.62398,10,,,,,,,,,,,,,,,,,,,,,,,,,,,,,,,,,,,,,
322.454,0.18904,0.59132,10,,,,,,,,,,,,,,,,,,,,,,,,,,,,,,,,,,,,,
323.054,0.1891,0.65657,10,,,,,,,,,,,,,,,,,,,,,,,,,,,,,,,,,,,,,
323.654,0.18921,0.61214,10,,,,,,,,,,,,,,,,,,,,,,,,,,,,,,,,,,,,,
324.254,0.18932,0.59443,10,,,,,,,,,,,,,,,,,,,,,,,,,,,,,,,,,,,,,
324.854,0.18949,0.59791,10,,,,,,,,,,,,,,,,,,,,,,,,,,,,,,,,,,,,,
325.454,0.18978,0.57523,10,,,,,,,,,,,,,,,,,,,,,,,,,,,,,,,,,,,,,
326.054,0.19012,0.65278,10,,,,,,,,,,,,,,,,,,,,,,,,,,,,,,,,,,,,,
326.654,0.19046,0.58364,10,,,,,,,,,,,,,,,,,,,,,,,,,,,,,,,,,,,,,
327.254,0.19119,0.57044,10,,,,,,,,,,,,,,,,,,,,,,,,,,,,,,,,,,,,,
327.854,0.19238,0.63,10,,,,,,,,,,,,,,,,,,,,,,,,,,,,,,,,,,,,,
328.454,0.19323,0.64708,10,,,,,,,,,,,,,,,,,,,,,,,,,,,,,,,,,,,,,
329.054,0.19363,0.73507,10,,,,,,,,,,,,,,,,,,,,,,,,,,,,,,,,,,,,,
329.654,0.19374,0.67382,10,,,,,,,,,,,,,,,,,,,,,,,,,,,,,,,,,,,,,
330.254,0.19363,0.72879,10,,,,,,,,,,,,,,,,,,,,,,,,,,,,,,,,,,,,,
330.854,0.19363,0.66821,10,,,,,,,,,,,,,,,,,,,,,,,,,,,,,,,,,,,,,
331.454,0.19357,0.69994,10,,,,,,,,,,,,,,,,,,,,,,,,,,,,,,,,,,,,,
332.054,0.19352,0.69074,10,,,,,,,,,,,,,,,,,,,,,,,,,,,,,,,,,,,,,
332.654,0.19346,0.62362,10,,,,,,,,,,,,,,,,,,,,,,,,,,,,,,,,,,,,,
333.254,0.1934,0.66368,10,,,,,,,,,,,,,,,,,,,,,,,,,,,,,,,,,,,,,
333.854,0.19335,0.75098,10,,,,,,,,,,,,,,,,,,,,,,,,,,,,,,,,,,,,,
334.454,0.19318,0.73211,10,,,,,,,,,,,,,,,,,,,,,,,,,,,,,,,,,,,,,
335.054,0.19267,0.76769,10,,,,,,,,,,,,,,,,,,,,,,,,,,,,,,,,,,,,,
335.654,0.1921,0.70099,10,,,,,,,,,,,,,,,,,,,,,,,,,,,,,,,,,,,,,
336.254,0.19097,0.69164,10,,,,,,,,,,,,,,,,,,,,,,,,,,,,,,,,,,,,,
336.854,0.19012,0.67153,10,,,,,,,,,,,,,,,,,,,,,,,,,,,,,,,,,,,,,
337.454,0.18915,0.63554,10,,,,,,,,,,,,,,,,,,,,,,,,,,,,,,,,,,,,,
338.054,0.18881,0.74104,10,,,,,,,,,,,,,,,,,,,,,,,,,,,,,,,,,,,,,
338.654,0.18864,0.64936,10,,,,,,,,,,,,,,,,,,,,,,,,,,,,,,,,,,,,,
339.254,0.18842,0.59522,10,,,,,,,,,,,,,,,,,,,,,,,,,,,,,,,,,,,,,
339.854,0.18842,0.56408,10,,,,,,,,,,,,,,,,,,,,,,,,,,,,,,,,,,,,,
340.454,0.18859,0.57947,10,,,,,,,,,,,,,,,,,,,,,,,,,,,,,,,,,,,,,
341.054,0.18864,0.70024,10,,,,,,,,,,,,,,,,,,,,,,,,,,,,,,,,,,,,,
341.654,0.18864,0.59654,10,,,,,,,,,,,,,,,,,,,,,,,,,,,,,,,,,,,,,
342.254,0.1887,0.5614,10,,,,,,,,,,,,,,,,,,,,,,,,,,,,,,,,,,,,,
342.854,0.18876,0.62796,10,,,,,,,,,,,,,,,,,,,,,,,,,,,,,,,,,,,,,
343.454,0.18881,0.58076,10,,,,,,,,,,,,,,,,,,,,,,,,,,,,,,,,,,,,,
344.054,0.18887,0.671,10,,,,,,,,,,,,,,,,,,,,,,,,,,,,,,,,,,,,,
344.654,0.18893,0.59175,10,,,,,,,,,,,,,,,,,,,,,,,,,,,,,,,,,,,,,
345.254,0.18915,0.55398,10,,,,,,,,,,,,,,,,,,,,,,,,,,,,,,,,,,,,,
345.854,0.18955,0.56846,10,,,,,,,,,,,,,,,,,,,,,,,,,,,,,,,,,,,,,
346.454,0.18989,0.60977,10,,,,,,,,,,,,,,,,,,,,,,,,,,,,,,,,,,,,,
347.054,0.19029,0.72386,10,,,,,,,,,,,,,,,,,,,,,,,,,,,,,,,,,,,,,
347.654,0.19097,0.5934,10,,,,,,,,,,,,,,,,,,,,,,,,,,,,,,,,,,,,,
348.254,0.1917,0.5897,10,,,,,,,,,,,,,,,,,,,,,,,,,,,,,,,,,,,,,
348.854,0.19255,0.66688,10,,,,,,,,,,,,,,,,,,,,,,,,,,,,,,,,,,,,,
349.454,0.19323,0.66186,10,,,,,,,,,,,,,,,,,,,,,,,,,,,,,,,,,,,,,
350.054,0.19352,0.67586,10,,,,,,,,,,,,,,,,,,,,,,,,,,,,,,,,,,,,,
350.654,0.19363,0.72342,10,,,,,,,,,,,,,,,,,,,,,,,,,,,,,,,,,,,,,
351.254,0.19357,0.67795,10,,,,,,,,,,,,,,,,,,,,,,,,,,,,,,,,,,,,,
351.854,0.19346,0.67851,10,,,,,,,,,,,,,,,,,,,,,,,,,,,,,,,,,,,,,
352.454,0.1934,0.66287,10,,,,,,,,,,,,,,,,,,,,,,,,,,,,,,,,,,,,,
353.054,0.19335,0.68483,10,,,,,,,,,,,,,,,,,,,,,,,,,,,,,,,,,,,,,
353.654,0.19323,0.74672,10,,,,,,,,,,,,,,,,,,,,,,,,,,,,,,,,,,,,,
354.254,0.19301,0.73061,10,,,,,,,,,,,,,,,,,,,,,,,,,,,,,,,,,,,,,
354.854,0.1925,0.66516,10,,,,,,,,,,,,,,,,,,,,,,,,,,,,,,,,,,,,,
355.454,0.1917,0.66982,10,,,,,,,,,,,,,,,,,,,,,,,,,,,,,,,,,,,,,
356.054,0.19063,0.70282,10,,,,,,,,,,,,,,,,,,,,,,,,,,,,,,,,,,,,,
356.654,0.18972,0.7164,10,,,,,,,,,,,,,,,,,,,,,,,,,,,,,,,,,,,,,
357.254,0.18876,0.67789,10,,,,,,,,,,,,,,,,,,,,,,,,,,,,,,,,,,,,,
357.854,0.18836,0.6418,10,,,,,,,,,,,,,,,,,,,,,,,,,,,,,,,,,,,,,
358.454,0.18819,0.64984,10,,,,,,,,,,,,,,,,,,,,,,,,,,,,,,,,,,,,,
359.054,0.18808,0.60607,10,,,,,,,,,,,,,,,,,,,,,,,,,,,,,,,,,,,,,
359.654,0.18813,0.55993,10,,,,,,,,,,,,,,,,,,,,,,,,,,,,,,,,,,,,,
360.254,0.18813,0.62778,10,,,,,,,,,,,,,,,,,,,,,,,,,,,,,,,,,,,,,
360.854,0.18819,0.62292,10,,,,,,,,,,,,,,,,,,,,,,,,,,,,,,,,,,,,,
361.454,0.18819,0.60945,10,,,,,,,,,,,,,,,,,,,,,,,,,,,,,,,,,,,,,
362.054,0.18825,0.61495,10,,,,,,,,,,,,,,,,,,,,,,,,,,,,,,,,,,,,,
362.654,0.18825,0.66424,10,,,,,,,,,,,,,,,,,,,,,,,,,,,,,,,,,,,,,
363.254,0.1883,0.58268,10,,,,,,,,,,,,,,,,,,,,,,,,,,,,,,,,,,,,,
363.854,0.1883,0.60752,10,,,,,,,,,,,,,,,,,,,,,,,,,,,,,,,,,,,,,
364.454,0.18836,0.5577,10,,,,,,,,,,,,,,,,,,,,,,,,,,,,,,,,,,,,,
365.054,0.18842,0.61308,10,,,,,,,,,,,,,,,,,,,,,,,,,,,,,,,,,,,,,
365.654,0.18847,0.62201,10,,,,,,,,,,,,,,,,,,,,,,,,,,,,,,,,,,,,,
366.254,0.18859,0.55556,10,,,,,,,,,,,,,,,,,,,,,,,,,,,,,,,,,,,,,
366.854,0.18881,0.61454,10,,,,,,,,,,,,,,,,,,,,,,,,,,,,,,,,,,,,,
367.454,0.1891,0.64693,10,,,,,,,,,,,,,,,,,,,,,,,,,,,,,,,,,,,,,
368.054,0.18938,0.5686,10,,,,,,,,,,,,,,,,,,,,,,,,,,,,,,,,,,,,,
368.654,0.18972,0.64216,10,,,,,,,,,,,,,,,,,,,,,,,,,,,,,,,,,,,,,
369.254,0.19006,0.62481,10,,,,,,,,,,,,,,,,,,,,,,,,,,,,,,,,,,,,,
369.854,0.1904,0.6441,10,,,,,,,,,,,,,,,,,,,,,,,,,,,,,,,,,,,,,
370.454,0.19068,0.65939,10,,,,,,,,,,,,,,,,,,,,,,,,,,,,,,,,,,,,,
371.054,0.19097,0.5936,10,,,,,,,,,,,,,,,,,,,,,,,,,,,,,,,,,,,,,
371.654,0.19136,0.62666,10,,,,,,,,,,,,,,,,,,,,,,,,,,,,,,,,,,,,,
372.254,0.1917,0.62512,10,,,,,,,,,,,,,,,,,,,,,,,,,,,,,,,,,,,,,
372.854,0.19193,0.69814,10,,,,,,,,,,,,,,,,,,,,,,,,,,,,,,,,,,,,,
373.454,0.19199,0.65038,10,,,,,,,,,,,,,,,,,,,,,,,,,,,,,,,,,,,,,
374.054,0.19204,0.71482,10,,,,,,,,,,,,,,,,,,,,,,,,,,,,,,,,,,,,,
374.654,0.19193,0.66607,10,,,,,,,,,,,,,,,,,,,,,,,,,,,,,,,,,,,,,
375.254,0.19187,0.7125,10,,,,,,,,,,,,,,,,,,,,,,,,,,,,,,,,,,,,,
375.854,0.19187,0.6611,10,,,,,,,,,,,,,,,,,,,,,,,,,,,,,,,,,,,,,
376.454,0.19176,0.68751,10,,,,,,,,,,,,,,,,,,,,,,,,,,,,,,,,,,,,,
377.054,0.1917,0.68965,10,,,,,,,,,,,,,,,,,,,,,,,,,,,,,,,,,,,,,
377.654,0.19159,0.66531,10,,,,,,,,,,,,,,,,,,,,,,,,,,,,,,,,,,,,,
378.254,0.19142,0.67211,10,,,,,,,,,,,,,,,,,,,,,,,,,,,,,,,,,,,,,
378.854,0.19125,0.72804,10,,,,,,,,,,,,,,,,,,,,,,,,,,,,,,,,,,,,,
379.454,0.19091,0.68349,10,,,,,,,,,,,,,,,,,,,,,,,,,,,,,,,,,,,,,
380.054,0.19046,0.67431,10,,,,,,,,,,,,,,,,,,,,,,,,,,,,,,,,,,,,,
380.654,0.18961,0.68388,10,,,,,,,,,,,,,,,,,,,,,,,,,,,,,,,,,,,,,
381.254,0.18876,0.66898,10,,,,,,,,,,,,,,,,,,,,,,,,,,,,,,,,,,,,,
381.854,0.1883,0.64312,10,,,,,,,,,,,,,,,,,,,,,,,,,,,,,,,,,,,,,
382.454,0.18791,0.61987,10,,,,,,,,,,,,,,,,,,,,,,,,,,,,,,,,,,,,,
383.054,0.18779,0.6454,10,,,,,,,,,,,,,,,,,,,,,,,,,,,,,,,,,,,,,
383.654,0.18768,0.59095,10,,,,,,,,,,,,,,,,,,,,,,,,,,,,,,,,,,,,,
384.254,0.18762,0.58526,10,,,,,,,,,,,,,,,,,,,,,,,,,,,,,,,,,,,,,
384.854,0.18762,0.60682,10,,,,,,,,,,,,,,,,,,,,,,,,,,,,,,,,,,,,,
385.454,0.18774,0.65754,10,,,,,,,,,,,,,,,,,,,,,,,,,,,,,,,,,,,,,
386.054,0.18774,0.67133,10,,,,,,,,,,,,,,,,,,,,,,,,,,,,,,,,,,,,,
386.654,0.18774,0.58033,10,,,,,,,,,,,,,,,,,,,,,,,,,,,,,,,,,,,,,
387.254,0.18774,0.6177,10,,,,,,,,,,,,,,,,,,,,,,,,,,,,,,,,,,,,,
387.854,0.18779,0.55807,10,,,,,,,,,,,,,,,,,,,,,,,,,,,,,,,,,,,,,
388.454,0.18779,0.66418,10,,,,,,,,,,,,,,,,,,,,,,,,,,,,,,,,,,,,,
389.054,0.18779,0.63081,10,,,,,,,,,,,,,,,,,,,,,,,,,,,,,,,,,,,,,
389.654,0.18785,0.644,10,,,,,,,,,,,,,,,,,,,,,,,,,,,,,,,,,,,,,
390.254,0.18791,0.61905,10,,,,,,,,,,,,,,,,,,,,,,,,,,,,,,,,,,,,,
390.854,0.18791,0.67017,10,,,,,,,,,,,,,,,,,,,,,,,,,,,,,,,,,,,,,
391.454,0.18796,0.64369,10,,,,,,,,,,,,,,,,,,,,,,,,,,,,,,,,,,,,,
392.054,0.18796,0.67051,10,,,,,,,,,,,,,,,,,,,,,,,,,,,,,,,,,,,,,
392.654,0.18796,0.6437,10,,,,,,,,,,,,,,,,,,,,,,,,,,,,,,,,,,,,,
393.254,0.18802,0.60945,10,,,,,,,,,,,,,,,,,,,,,,,,,,,,,,,,,,,,,
393.854,0.18802,0.66552,10,,,,,,,,,,,,,,,,,,,,,,,,,,,,,,,,,,,,,
394.454,0.18802,0.62569,10,,,,,,,,,,,,,,,,,,,,,,,,,,,,,,,,,,,,,
395.054,0.18802,0.70774,10,,,,,,,,,,,,,,,,,,,,,,,,,,,,,,,,,,,,,
395.654,0.18802,0.5896,10,,,,,,,,,,,,,,,,,,,,,,,,,,,,,,,,,,,,,
396.254,0.18802,0.62791,10,,,,,,,,,,,,,,,,,,,,,,,,,,,,,,,,,,,,,
396.854,0.18796,0.58558,10,,,,,,,,,,,,,,,,,,,,,,,,,,,,,,,,,,,,,
397.454,0.18808,0.63034,10,,,,,,,,,,,,,,,,,,,,,,,,,,,,,,,,,,,,,
398.054,0.18808,0.70538,10,,,,,,,,,,,,,,,,,,,,,,,,,,,,,,,,,,,,,
398.654,0.18808,0.62039,10,,,,,,,,,,,,,,,,,,,,,,,,,,,,,,,,,,,,,
399.254,0.18808,0.63939,10,,,,,,,,,,,,,,,,,,,,,,,,,,,,,,,,,,,,,
399.854,0.18808,0.62928,10,,,,,,,,,,,,,,,,,,,,,,,,,,,,,,,,,,,,,
400.454,0.18808,0.67008,10,,,,,,,,,,,,,,,,,,,,,,,,,,,,,,,,,,,,,
401.054,0.18808,0.68727,10,,,,,,,,,,,,,,,,,,,,,,,,,,,,,,,,,,,,,
401.654,0.18808,0.67041,10,,,,,,,,,,,,,,,,,,,,,,,,,,,,,,,,,,,,,
402.254,0.18808,0.63538,10,,,,,,,,,,,,,,,,,,,,,,,,,,,,,,,,,,,,,
402.854,0.18808,0.65655,10,,,,,,,,,,,,,,,,,,,,,,,,,,,,,,,,,,,,,
403.454,0.18808,0.64106,10,,,,,,,,,,,,,,,,,,,,,,,,,,,,,,,,,,,,,
404.054,0.18808,0.66486,10,,,,,,,,,,,,,,,,,,,,,,,,,,,,,,,,,,,,,
404.654,0.18808,0.62033,10,,,,,,,,,,,,,,,,,,,,,,,,,,,,,,,,,,,,,
405.254,0.18808,0.61337,10,,,,,,,,,,,,,,,,,,,,,,,,,,,,,,,,,,,,,
405.854,0.18808,0.63877,10,,,,,,,,,,,,,,,,,,,,,,,,,,,,,,,,,,,,,
406.454,0.18808,0.60067,10,,,,,,,,,,,,,,,,,,,,,,,,,,,,,,,,,,,,,
407.054,0.18808,0.68147,10,,,,,,,,,,,,,,,,,,,,,,,,,,,,,,,,,,,,,
407.654,0.18802,0.60055,10,,,,,,,,,,,,,,,,,,,,,,,,,,,,,,,,,,,,,
408.254,0.18802,0.57471,10,,,,,,,,,,,,,,,,,,,,,,,,,,,,,,,,,,,,,
408.854,0.18802,0.61132,10,,,,,,,,,,,,,,,,,,,,,,,,,,,,,,,,,,,,,
409.454,0.18808,0.58539,10,,,,,,,,,,,,,,,,,,,,,,,,,,,,,,,,,,,,,
410.054,0.18808,0.66713,10,,,,,,,,,,,,,,,,,,,,,,,,,,,,,,,,,,,,,
410.654,0.18802,0.66062,10,,,,,,,,,,,,,,,,,,,,,,,,,,,,,,,,,,,,,
411.254,0.18802,0.68681,10,,,,,,,,,,,,,,,,,,,,,,,,,,,,,,,,,,,,,
411.854,0.18802,0.65188,10,,,,,,,,,,,,,,,,,,,,,,,,,,,,,,,,,,,,,
412.454,0.18808,0.6798,10,,,,,,,,,,,,,,,,,,,,,,,,,,,,,,,,,,,,,
413.054,0.18791,0.71108,10,,,,,,,,,,,,,,,,,,,,,,,,,,,,,,,,,,,,,
413.654,0.18791,0.6618,10,,,,,,,,,,,,,,,,,,,,,,,,,,,,,,,,,,,,,
414.254,0.18796,0.66481,10,,,,,,,,,,,,,,,,,,,,,,,,,,,,,,,,,,,,,
414.854,0.18796,0.65177,10,,,,,,,,,,,,,,,,,,,,,,,,,,,,,,,,,,,,,
415.454,0.18796,0.67344,10,,,,,,,,,,,,,,,,,,,,,,,,,,,,,,,,,,,,,
416.054,0.18796,0.66265,10,,,,,,,,,,,,,,,,,,,,,,,,,,,,,,,,,,,,,
416.654,0.18796,0.68767,10,,,,,,,,,,,,,,,,,,,,,,,,,,,,,,,,,,,,,
417.254,0.18796,0.60893,10,,,,,,,,,,,,,,,,,,,,,,,,,,,,,,,,,,,,,
417.854,0.18785,0.61766,10,,,,,,,,,,,,,,,,,,,,,,,,,,,,,,,,,,,,,
418.454,0.18785,0.60874,10,,,,,,,,,,,,,,,,,,,,,,,,,,,,,,,,,,,,,
419.054,0.18779,0.62281,10,,,,,,,,,,,,,,,,,,,,,,,,,,,,,,,,,,,,,
419.654,0.18791,0.6362,10,,,,,,,,,,,,,,,,,,,,,,,,,,,,,,,,,,,,,
420.254,0.18791,0.58975,10,,,,,,,,,,,,,,,,,,,,,,,,,,,,,,,,,,,,,
420.854,0.18779,0.65112,10,,,,,,,,,,,,,,,,,,,,,,,,,,,,,,,,,,,,,
421.454,0.18791,0.6272,10,,,,,,,,,,,,,,,,,,,,,,,,,,,,,,,,,,,,,
422.054,0.18791,0.65905,10,,,,,,,,,,,,,,,,,,,,,,,,,,,,,,,,,,,,,
422.654,0.18791,0.62647,10,,,,,,,,,,,,,,,,,,,,,,,,,,,,,,,,,,,,,
423.254,0.18791,0.67269,10,,,,,,,,,,,,,,,,,,,,,,,,,,,,,,,,,,,,,
423.854,0.18791,0.61174,10,,,,,,,,,,,,,,,,,,,,,,,,,,,,,,,,,,,,,
424.454,0.18791,0.62353,10,,,,,,,,,,,,,,,,,,,,,,,,,,,,,,,,,,,,,
425.054,0.18791,0.67368,10,,,,,,,,,,,,,,,,,,,,,,,,,,,,,,,,,,,,,
425.654,0.18791,0.64133,10,,,,,,,,,,,,,,,,,,,,,,,,,,,,,,,,,,,,,
426.156,0.62056,5.28088,10,,,,,,,,,,,,,,,,,,,,,,,,,,,,,,,,,,,,,
426.756,5.72124,365.4892,10,,,,,,,,,,,,,,,,,,,,,,,,,,,,,,,,,,,,,
427.356,10.72122,781.95416,10,,,,,,,,,,,,,,,,,,,,,,,,,,,,,,,,,,,,,
427.956,15.7212,1052.6084,10,,,,,,,,,,,,,,,,,,,,,,,,,,,,,,,,,,,,,
428.556,20.72124,56.14511,10,,,,,,,,,,,,,,,,,,,,,,,,,,,,,,,,,,,,,
429.156,25.72128,22.61328,10,,,,,,,,,,,,,,,,,,,,,,,,,,,,,,,,,,,,,
429.756,30.72127,12.20231,10,,,,,,,,,,,,,,,,,,,,,,,,,,,,,,,,,,,,,
430.356,35.72124,6.67048,10,,,,,,,,,,,,,,,,,,,,,,,,,,,,,,,,,,,,,
430.956,40.72128,-0.64365,10,,,,,,,,,,,,,,,,,,,,,,,,,,,,,,,,,,,,,
431.556,45.72133,-4.15706,10,,,,,,,,,,,,,,,,,,,,,,,,,,,,,,,,,,,,,
432.156,50.72131,-5.25919,10,,,,,,,,,,,,,,,,,,,,,,,,,,,,,,,,,,,,,
432.756,55.72123,-4.05486,10,,,,,,,,,,,,,,,,,,,,,,,,,,,,,,,,,,,,,
433.356,60.72134,-4.83936,10,,,,,,,,,,,,,,,,,,,,,,,,,,,,,,,,,,,,,
433.956,65.72131,-7.61425,10,,,,,,,,,,,,,,,,,,,,,,,,,,,,,,,,,,,,,
434.556,70.72124,-7.67765,10,,,,,,,,,,,,,,,,,,,,,,,,,,,,,,,,,,,,,
435.156,75.72123,-7.65119,10,,,,,,,,,,,,,,,,,,,,,,,,,,,,,,,,,,,,,
435.314,77.03793,-7.6855,10,,,,,,,,,,,,,,,,,,,,,,,,,,,,,,,,,,,,,