File: combined_ligament_solver/data/processed/Data Sheet 3_S152678_ACL.csv
Specimen properties : Length,34,mm,Unnamed: 3,Unnamed: 4,Unnamed: 5,Unnamed: 6,Unnamed: 7,Unnamed: 8,Unnamed: 9,Unnamed: 10,Unnamed: 11,Stress-Strain,Unnamed: 13,Unnamed: 14,Unnamed: 15,Unnamed: 16,Unnamed: 17,Unnamed: 18,Unnamed: 19,Unnamed: 20,Unnamed: 21,Unnamed: 22,Unnamed: 23,Unnamed: 24,Unnamed: 25,Unnamed: 26,Unnamed: 27,Linear,Unnamed: 29,Unnamed: 30,Unnamed: 31,Unnamed: 32,Unnamed: 33,Modulus,Unnamed: 35,Failure,Unnamed: 37,Unnamed: 38,Unnamed: 39,Unnamed: 40
Cross Section Average,49.751000000000005,mm2,,,,,,,,,,Polynomial Coefficients,,,,,,,,,,,,,,,,Force,,Stress,Extension,Strain,,Secant,Tangent,Load,Stress,Extension,Strain,Stiffness
Time,Extension,Load,Total cycle count,,,Extension,Load,Strain,Stress,E-tan,,X6,-7609876.05589933,,,,,,,,,Strain,Stress,E-tan,,,,(N),,(MPa),(mm),(%),,(MPa),(MPa),(N),(MPa),(mm),(%),(N/mm)
(s),(mm),(N),,,,(mm),(N),(mm/mm),(MPa),(MPa),,X5,3873637.143742031,,,,,,,,,(mm/mm),(MPa),(MPa),,,,300.1015108667209,,6.032069925563724,2.4819999999999998,7.3,,82.63109487073595,138.907863124606,808.3371,16.231100681393336,5.53333,16.2745,120.91116473276425
0.5,0.11968,3.5869,0,,,3.96276,569.37799,0.11372176470588234,11.42799903519527,115.02244740855951,,,,,,,,,,,,0.005,0.05025787820588845,10.866071535776765,,,,,,,,,,,,,,,,
1.1,0.21964,7.16167,0,,,8.96308,93.3426,,,,,,,,,,,,,,,0.011,0.14143337337705117,19.239929572300447,,,,,,,,,,,,,,,,
1.7,0.31977,11.53218,0,,,13.96284,41.13647,,,,,,,,,,,,,,,0.017,0.30327682081176965,33.073090999629095,,,,,,,,,,,,,,,,
2.3,0.4199,16.60591,0,,,18.96288,29.31889,,,,,,,,,,,,,,,0.023,0.5597100119858823,49.91190389263695,,,,,,,,,,,,,,,,
2.9,0.51963,22.41151,0,,,,,,,,,,,,,,,,,,,0.029,0.9216519574674886,67.78797907029592,,,,,,,,,,,,,,,,
3.5,0.61971,28.61275,0,,,,,,,,,,,,,,,,,,,0.035,1.389781343903083,85.175584530404,,,,,,,,,,,,,,,,
4.1,0.71978,35.9832,0,,,,,,,,,,,,,,,,,,,0.041,1.9570433576120587,100.94903988431172,,,,,,,,,,,,,,,,
4.586,0.73423,37.07714,0.5,,,,,,,,,,,,,,,,,,,0.047,2.6109008747895848,114.34011079165518,,,,,,,,,,,,,,,,
5.186,0.63376,27.5632,0.5,,,,,,,,,,,,,,,,,,,0.053,3.3353300183178503,124.89540339507809,,,,,,,,,,,,,,,,
5.786,0.5338,20.14664,0.5,,,,,,,,,,,,,,,,,,,0.059,4.112560081185678,132.4337587549661,,,,,,,,,,,,,,,,
6.386,0.4339,14.03776,0.5,,,,,,,,,,,,,,,,,,,0.065,4.92455781651651,137.00364728417455,,,,,,,,,,,,,,,,
6.986,0.33377,9.04981,0.5,,,,,,,,,,,,,,,,,,,0.071,5.754256094204751,138.84056318274412,,,,,,,,,,,,,,,,
7.586,0.23364,5.15161,0.5,,,,,,,,,,,,,,,,,,,0.077,6.586526924160518,138.32441887265722,,,,,,,,,,,,,,,,
8.186,0.13385,2.1321,0.5,,,,,,,,,,,,,,,,,,,0.083,7.408898846162709,135.93693943252902,,,,,,,,,,,,,,,,
8.538,0.10461,1.0178,1,,,,,,,,,,,,,,,,,,,0.089,8.212018686320468,132.21905703237613,,,,,,,,,,,,,,,,
9.138,0.20933,4.71293,1,,,,,,,,,,,,,,,,,,,0.095,8.989857680143057,127.7283053683059,,,,,,,,,,,,,,,,
9.738,0.30951,8.86649,1,,,,,,,,,,,,,,,,,,,0.101,9.739661962217971,122.99621409724169,,,,,,,,,,,,,,,,
10.338,0.40942,13.81793,1,,,,,,,,,,,,,,,,,,,0.107,10.461647422497657,118.48570327177643,,,,,,,,,,,,,,,,
10.938,0.50932,19.76625,1,,,,,,,,,,,,,,,,,,,0.113,11.158438929194286,114.54847777465093,,,,,,,,,,,,,,,,
11.538,0.60939,26.49024,1,,,,,,,,,,,,,,,,,,,0.119,11.834253918283203,111.38242175370993,,,,,,,,,,,,,,,,
12.138,0.70952,34.12918,1,,,,,,,,,,,,,,,,,,,0.125,12.493830349614537,108.98899305658094,,,,,,,,,,,,,,,,
12.552,0.77832,40.05873,1.5,,,,,,,,,,,,,,,,,,,0.131,13.141099029633267,107.13061766524658,,,,,,,,,,,,,,,,
13.152,0.67807,30.57579,1.5,,,,,,,,,,,,,,,,,,,0.137,13.777600300707707,105.28808413107517,,,,,,,,,,,,,,,,
13.752,0.57806,22.52098,1.5,,,,,,,,,,,,,,,,,,,0.143,14.40064509706617,102.61793800920483,,,,,,,,,,,,,,,,
14.352,0.47815,15.93077,1.5,,,,,,,,,,,,,,,,,,,0.149,15.001220367342214,97.90987629344617,,,,,,,,,,,,,,,,
14.952,0.37819,10.59899,1.5,,,,,,,,,,,,,,,,,,,0.155,,,,,,,,,,,,,,,,,,
15.552,0.27812,6.32358,1.5,,,,,,,,,,,,,,,,,,,0.161,,,,,,,,,,,,,,,,,,
16.152,0.17799,2.96402,1.5,,,,,,,,,,,,,,,,,,,0.167,,,,,,,,,,,,,,,,,,
16.628,0.09883,0.98011,2,,,,,,,,,,,,,,,,,,,0.173,,,,,,,,,,,,,,,,,,
17.13,0.18275,3.43951,2,,,,,,,,,,,,,,,,,,,0.179,,,,,,,,,,,,,,,,,,
17.73,0.2826,7.29078,2,,,,,,,,,,,,,,,,,,,0.185,,,,,,,,,,,,,,,,,,
18.33,0.38273,12.02609,2,,,,,,,,,,,,,,,,,,,0.191,,,,,,,,,,,,,,,,,,
18.93,0.48286,17.52526,2,,,,,,,,,,,,,,,,,,,0.197,,,,,,,,,,,,,,,,,,
19.53,0.58276,24.04247,2,,,,,,,,,,,,,,,,,,,,,,,,,,,,,,,,,,,,,
20.13,0.68261,31.39222,2,,,,,,,,,,,,,,,,,,,,,,,,,,,,,,,,,,,,,
20.73,0.78268,39.87259,2,,,,,,,,,,,,,,,,,,,,,,,,,,,,,,,,,,,,,
21.142,0.71785,33.73398,2.5,,,,,,,,,,,,,,,,,,,,,,,,,,,,,,,,,,,,,
21.742,0.61784,24.99871,2.5,,,,,,,,,,,,,,,,,,,,,,,,,,,,,,,,,,,,,
22.342,0.51771,17.97063,2.5,,,,,,,,,,,,,,,,,,,,,,,,,,,,,,,,,,,,,
22.942,0.4178,12.22434,2.5,,,,,,,,,,,,,,,,,,,,,,,,,,,,,,,,,,,,,
23.542,0.31779,7.67164,2.5,,,,,,,,,,,,,,,,,,,,,,,,,,,,,,,,,,,,,
24.142,0.21777,4.01435,2.5,,,,,,,,,,,,,,,,,,,,,,,,,,,,,,,,,,,,,
24.742,0.11758,1.20075,2.5,,,,,,,,,,,,,,,,,,,,,,,,,,,,,,,,,,,,,
25.138,0.1526,2.22675,3,,,,,,,,,,,,,,,,,,,,,,,,,,,,,,,,,,,,,
25.738,0.25279,5.78626,3,,,,,,,,,,,,,,,,,,,,,,,,,,,,,,,,,,,,,
26.338,0.35281,10.23137,3,,,,,,,,,,,,,,,,,,,,,,,,,,,,,,,,,,,,,
26.938,0.45265,15.41485,3,,,,,,,,,,,,,,,,,,,,,,,,,,,,,,,,,,,,,
27.538,0.55267,21.56588,3,,,,,,,,,,,,,,,,,,,,,,,,,,,,,,,,,,,,,
28.138,0.65286,28.61661,3,,,,,,,,,,,,,,,,,,,,,,,,,,,,,,,,,,,,,
28.738,0.75287,36.77554,3,,,,,,,,,,,,,,,,,,,,,,,,,,,,,,,,,,,,,
29.16,0.75667,37.21753,3.5,,,,,,,,,,,,,,,,,,,,,,,,,,,,,,,,,,,,,
29.76,0.6562,27.65105,3.5,,,,,,,,,,,,,,,,,,,,,,,,,,,,,,,,,,,,,
30.36,0.55618,20.13134,3.5,,,,,,,,,,,,,,,,,,,,,,,,,,,,,,,,,,,,,
30.96,0.45605,14.04284,3.5,,,,,,,,,,,,,,,,,,,,,,,,,,,,,,,,,,,,,
31.56,0.35615,9.03126,3.5,,,,,,,,,,,,,,,,,,,,,,,,,,,,,,,,,,,,,
32.16,0.25613,5.15721,3.5,,,,,,,,,,,,,,,,,,,,,,,,,,,,,,,,,,,,,
32.76,0.15617,1.99755,3.5,,,,,,,,,,,,,,,,,,,,,,,,,,,,,,,,,,,,,
33.116,0.12625,1.0241,4,,,,,,,,,,,,,,,,,,,,,,,,,,,,,,,,,,,,,
33.716,0.23103,4.73526,4,,,,,,,,,,,,,,,,,,,,,,,,,,,,,,,,,,,,,
34.316,0.33105,8.90968,4,,,,,,,,,,,,,,,,,,,,,,,,,,,,,,,,,,,,,
34.916,0.43106,13.92597,4,,,,,,,,,,,,,,,,,,,,,,,,,,,,,,,,,,,,,
35.516,0.53114,19.82474,4,,,,,,,,,,,,,,,,,,,,,,,,,,,,,,,,,,,,,
36.116,0.63104,26.62017,4,,,,,,,,,,,,,,,,,,,,,,,,,,,,,,,,,,,,,
36.716,0.73111,34.48267,4,,,,,,,,,,,,,,,,,,,,,,,,,,,,,,,,,,,,,
37.192,0.78138,39.74252,4.5,,,,,,,,,,,,,,,,,,,,,,,,,,,,,,,,,,,,,
37.792,0.67683,29.11844,4.5,,,,,,,,,,,,,,,,,,,,,,,,,,,,,,,,,,,,,
38.392,0.5767,21.30992,4.5,,,,,,,,,,,,,,,,,,,,,,,,,,,,,,,,,,,,,
38.992,0.47685,14.9437,4.5,,,,,,,,,,,,,,,,,,,,,,,,,,,,,,,,,,,,,
39.592,0.37683,9.78306,4.5,,,,,,,,,,,,,,,,,,,,,,,,,,,,,,,,,,,,,
40.192,0.27676,5.68641,4.5,,,,,,,,,,,,,,,,,,,,,,,,,,,,,,,,,,,,,
40.792,0.17663,2.46955,4.5,,,,,,,,,,,,,,,,,,,,,,,,,,,,,,,,,,,,,
41.136,0.11928,0.98106,5,,,,,,,,,,,,,,,,,,,,,,,,,,,,,,,,,,,,,
41.736,0.22032,4.12473,5,,,,,,,,,,,,,,,,,,,,,,,,,,,,,,,,,,,,,
42.336,0.32045,8.20398,5,,,,,,,,,,,,,,,,,,,,,,,,,,,,,,,,,,,,,
42.936,0.42052,13.00981,5,,,,,,,,,,,,,,,,,,,,,,,,,,,,,,,,,,,,,
43.536,0.52031,18.90679,5,,,,,,,,,,,,,,,,,,,,,,,,,,,,,,,,,,,,,
44.136,0.62033,25.59077,5,,,,,,,,,,,,,,,,,,,,,,,,,,,,,,,,,,,,,
44.736,0.72046,33.31014,5,,,,,,,,,,,,,,,,,,,,,,,,,,,,,,,,,,,,,
45.196,0.79702,40.052,5.5,,,,,,,,,,,,,,,,,,,,,,,,,,,,,,,,,,,,,
45.796,0.69683,30.61158,5.5,,,,,,,,,,,,,,,,,,,,,,,,,,,,,,,,,,,,,
46.396,0.59687,22.51961,5.5,,,,,,,,,,,,,,,,,,,,,,,,,,,,,,,,,,,,,
46.996,0.49685,15.89947,5.5,,,,,,,,,,,,,,,,,,,,,,,,,,,,,,,,,,,,,
47.596,0.39667,10.57167,5.5,,,,,,,,,,,,,,,,,,,,,,,,,,,,,,,,,,,,,
48.196,0.29671,6.30082,5.5,,,,,,,,,,,,,,,,,,,,,,,,,,,,,,,,,,,,,
48.796,0.19686,2.97643,5.5,,,,,,,,,,,,,,,,,,,,,,,,,,,,,,,,,,,,,
49.236,0.12325,0.98207,6,,,,,,,,,,,,,,,,,,,,,,,,,,,,,,,,,,,,,
49.738,0.20734,3.51059,6,,,,,,,,,,,,,,,,,,,,,,,,,,,,,,,,,,,,,
50.338,0.30753,7.44969,6,,,,,,,,,,,,,,,,,,,,,,,,,,,,,,,,,,,,,
50.938,0.40738,12.20313,6,,,,,,,,,,,,,,,,,,,,,,,,,,,,,,,,,,,,,
51.538,0.50734,17.87016,6,,,,,,,,,,,,,,,,,,,,,,,,,,,,,,,,,,,,,
52.138,0.60741,24.36276,6,,,,,,,,,,,,,,,,,,,,,,,,,,,,,,,,,,,,,
52.738,0.70748,31.90116,6,,,,,,,,,,,,,,,,,,,,,,,,,,,,,,,,,,,,,
53.294,0.79996,40.0217,6.5,,,,,,,,,,,,,,,,,,,,,,,,,,,,,,,,,,,,,
53.796,0.71689,32.18723,6.5,,,,,,,,,,,,,,,,,,,,,,,,,,,,,,,,,,,,,
54.396,0.61682,23.68931,6.5,,,,,,,,,,,,,,,,,,,,,,,,,,,,,,,,,,,,,
54.996,0.51669,16.89864,6.5,,,,,,,,,,,,,,,,,,,,,,,,,,,,,,,,,,,,,
55.596,0.41678,11.38875,6.5,,,,,,,,,,,,,,,,,,,,,,,,,,,,,,,,,,,,,
56.196,0.31682,6.9044,6.5,,,,,,,,,,,,,,,,,,,,,,,,,,,,,,,,,,,,,
56.796,0.21681,3.46149,6.5,,,,,,,,,,,,,,,,,,,,,,,,,,,,,,,,,,,,,
57.336,0.12665,0.99889,7,,,,,,,,,,,,,,,,,,,,,,,,,,,,,,,,,,,,,
57.74,0.1938,2.91981,7,,,,,,,,,,,,,,,,,,,,,,,,,,,,,,,,,,,,,
58.34,0.29365,6.71012,7,,,,,,,,,,,,,,,,,,,,,,,,,,,,,,,,,,,,,
58.94,0.39372,11.32536,7,,,,,,,,,,,,,,,,,,,,,,,,,,,,,,,,,,,,,
59.54,0.49379,16.80508,7,,,,,,,,,,,,,,,,,,,,,,,,,,,,,,,,,,,,,
60.14,0.59381,23.21983,7,,,,,,,,,,,,,,,,,,,,,,,,,,,,,,,,,,,,,
60.74,0.69371,30.58634,7,,,,,,,,,,,,,,,,,,,,,,,,,,,,,,,,,,,,,
61.34,0.79367,39.18531,7,,,,,,,,,,,,,,,,,,,,,,,,,,,,,,,,,,,,,
61.792,0.73548,33.69684,7.5,,,,,,,,,,,,,,,,,,,,,,,,,,,,,,,,,,,,,
62.392,0.63546,24.88439,7.5,,,,,,,,,,,,,,,,,,,,,,,,,,,,,,,,,,,,,
62.992,0.53544,17.87549,7.5,,,,,,,,,,,,,,,,,,,,,,,,,,,,,,,,,,,,,
63.592,0.43554,12.14476,7.5,,,,,,,,,,,,,,,,,,,,,,,,,,,,,,,,,,,,,
64.192,0.33541,7.58426,7.5,,,,,,,,,,,,,,,,,,,,,,,,,,,,,,,,,,,,,
64.792,0.23539,3.91015,7.5,,,,,,,,,,,,,,,,,,,,,,,,,,,,,,,,,,,,,
65.392,0.13543,1.14168,7.5,,,,,,,,,,,,,,,,,,,,,,,,,,,,,,,,,,,,,
65.726,0.18071,2.38327,8,,,,,,,,,,,,,,,,,,,,,,,,,,,,,,,,,,,,,
66.326,0.28067,6.07058,8,,,,,,,,,,,,,,,,,,,,,,,,,,,,,,,,,,,,,
66.926,0.38069,10.54315,8,,,,,,,,,,,,,,,,,,,,,,,,,,,,,,,,,,,,,
67.526,0.48082,15.93571,8,,,,,,,,,,,,,,,,,,,,,,,,,,,,,,,,,,,,,
68.126,0.58072,22.1803,8,,,,,,,,,,,,,,,,,,,,,,,,,,,,,,,,,,,,,
68.726,0.68068,29.31524,8,,,,,,,,,,,,,,,,,,,,,,,,,,,,,,,,,,,,,
69.326,0.78081,37.78217,8,,,,,,,,,,,,,,,,,,,,,,,,,,,,,,,,,,,,,
69.78,0.75622,35.46577,8.5,,,,,,,,,,,,,,,,,,,,,,,,,,,,,,,,,,,,,
70.38,0.65614,26.3571,8.5,,,,,,,,,,,,,,,,,,,,,,,,,,,,,,,,,,,,,
70.98,0.55613,19.08821,8.5,,,,,,,,,,,,,,,,,,,,,,,,,,,,,,,,,,,,,
71.58,0.45605,13.13163,8.5,,,,,,,,,,,,,,,,,,,,,,,,,,,,,,,,,,,,,
72.18,0.35609,8.33955,8.5,,,,,,,,,,,,,,,,,,,,,,,,,,,,,,,,,,,,,
72.78,0.25613,4.52607,8.5,,,,,,,,,,,,,,,,,,,,,,,,,,,,,,,,,,,,,
73.38,0.15617,1.57714,8.5,,,,,,,,,,,,,,,,,,,,,,,,,,,,,,,,,,,,,
73.726,0.16569,1.80394,9,,,,,,,,,,,,,,,,,,,,,,,,,,,,,,,,,,,,,
74.326,0.26605,5.35827,9,,,,,,,,,,,,,,,,,,,,,,,,,,,,,,,,,,,,,
74.926,0.36618,9.8123,9,,,,,,,,,,,,,,,,,,,,,,,,,,,,,,,,,,,,,
75.526,0.46603,14.96532,9,,,,,,,,,,,,,,,,,,,,,,,,,,,,,,,,,,,,,
76.126,0.56599,21.01044,9,,,,,,,,,,,,,,,,,,,,,,,,,,,,,,,,,,,,,
76.726,0.66612,28.05565,9,,,,,,,,,,,,,,,,,,,,,,,,,,,,,,,,,,,,,
77.326,0.76613,36.24228,9,,,,,,,,,,,,,,,,,,,,,,,,,,,,,,,,,,,,,
77.778,0.77497,37.28035,9.5,,,,,,,,,,,,,,,,,,,,,,,,,,,,,,,,,,,,,
78.378,0.6745,27.67987,9.5,,,,,,,,,,,,,,,,,,,,,,,,,,,,,,,,,,,,,
78.978,0.57437,20.12187,9.5,,,,,,,,,,,,,,,,,,,,,,,,,,,,,,,,,,,,,
79.578,0.47453,13.98203,9.5,,,,,,,,,,,,,,,,,,,,,,,,,,,,,,,,,,,,,
80.178,0.37445,9.02706,9.5,,,,,,,,,,,,,,,,,,,,,,,,,,,,,,,,,,,,,
80.778,0.27444,5.04777,9.5,,,,,,,,,,,,,,,,,,,,,,,,,,,,,,,,,,,,,
81.378,0.17436,1.99031,9.5,,,,,,,,,,,,,,,,,,,,,,,,,,,,,,,,,,,,,
81.82,0.10489,0.27414,10,,,,,,,,,,,,,,,,,,,,,,,,,,,,,,,,,,,,,
82.42,0.09798,0.19486,10,,,,,,,,,,,,,,,,,,,,,,,,,,,,,,,,,,,,,
83.02,0.12489,0.86126,10,,,,,,,,,,,,,,,,,,,,,,,,,,,,,,,,,,,,,
83.62,0.13776,1.31215,10,,,,,,,,,,,,,,,,,,,,,,,,,,,,,,,,,,,,,
84.22,0.12795,1.0763,10,,,,,,,,,,,,,,,,,,,,,,,,,,,,,,,,,,,,,
84.82,0.11169,0.70194,10,,,,,,,,,,,,,,,,,,,,,,,,,,,,,,,,,,,,,
85.42,0.1118,0.7012,10,,,,,,,,,,,,,,,,,,,,,,,,,,,,,,,,,,,,,
86.02,0.11214,0.67783,10,,,,,,,,,,,,,,,,,,,,,,,,,,,,,,,,,,,,,
86.62,0.1135,0.72906,10,,,,,,,,,,,,,,,,,,,,,,,,,,,,,,,,,,,,,
87.22,0.11605,0.77135,10,,,,,,,,,,,,,,,,,,,,,,,,,,,,,,,,,,,,,
87.82,0.11832,0.89864,10,,,,,,,,,,,,,,,,,,,,,,,,,,,,,,,,,,,,,
88.42,0.11894,0.93111,10,,,,,,,,,,,,,,,,,,,,,,,,,,,,,,,,,,,,,
89.02,0.11894,0.96887,10,,,,,,,,,,,,,,,,,,,,,,,,,,,,,,,,,,,,,
89.62,0.11877,0.92352,10,,,,,,,,,,,,,,,,,,,,,,,,,,,,,,,,,,,,,
90.22,0.1186,0.94943,10,,,,,,,,,,,,,,,,,,,,,,,,,,,,,,,,,,,,,
90.82,0.11798,0.98052,10,,,,,,,,,,,,,,,,,,,,,,,,,,,,,,,,,,,,,
91.42,0.11611,0.90722,10,,,,,,,,,,,,,,,,,,,,,,,,,,,,,,,,,,,,,
92.02,0.1139,0.87206,10,,,,,,,,,,,,,,,,,,,,,,,,,,,,,,,,,,,,,
92.62,0.1126,0.8214,10,,,,,,,,,,,,,,,,,,,,,,,,,,,,,,,,,,,,,
93.22,0.1122,0.84733,10,,,,,,,,,,,,,,,,,,,,,,,,,,,,,,,,,,,,,
93.82,0.11197,0.80002,10,,,,,,,,,,,,,,,,,,,,,,,,,,,,,,,,,,,,,
94.42,0.11192,0.78164,10,,,,,,,,,,,,,,,,,,,,,,,,,,,,,,,,,,,,,
95.02,0.11203,0.80359,10,,,,,,,,,,,,,,,,,,,,,,,,,,,,,,,,,,,,,
95.62,0.11203,0.88567,10,,,,,,,,,,,,,,,,,,,,,,,,,,,,,,,,,,,,,
96.22,0.11209,0.84932,10,,,,,,,,,,,,,,,,,,,,,,,,,,,,,,,,,,,,,
96.82,0.11209,0.85942,10,,,,,,,,,,,,,,,,,,,,,,,,,,,,,,,,,,,,,
97.42,0.11209,0.83675,10,,,,,,,,,,,,,,,,,,,,,,,,,,,,,,,,,,,,,
98.02,0.11209,0.90293,10,,,,,,,,,,,,,,,,,,,,,,,,,,,,,,,,,,,,,
98.62,0.11209,0.84929,10,,,,,,,,,,,,,,,,,,,,,,,,,,,,,,,,,,,,,
99.22,0.11209,0.85253,10,,,,,,,,,,,,,,,,,,,,,,,,,,,,,,,,,,,,,
99.82,0.11209,0.87839,10,,,,,,,,,,,,,,,,,,,,,,,,,,,,,,,,,,,,,
100.42,0.11209,0.87166,10,,,,,,,,,,,,,,,,,,,,,,,,,,,,,,,,,,,,,
101.02,0.11209,0.843,10,,,,,,,,,,,,,,,,,,,,,,,,,,,,,,,,,,,,,
101.62,0.11209,0.84531,10,,,,,,,,,,,,,,,,,,,,,,,,,,,,,,,,,,,,,
102.22,0.11209,0.84888,10,,,,,,,,,,,,,,,,,,,,,,,,,,,,,,,,,,,,,
102.82,0.11209,0.89278,10,,,,,,,,,,,,,,,,,,,,,,,,,,,,,,,,,,,,,
103.42,0.11197,0.82357,10,,,,,,,,,,,,,,,,,,,,,,,,,,,,,,,,,,,,,
104.02,0.11197,0.89193,10,,,,,,,,,,,,,,,,,,,,,,,,,,,,,,,,,,,,,
104.62,0.11197,0.86712,10,,,,,,,,,,,,,,,,,,,,,,,,,,,,,,,,,,,,,
105.22,0.11203,0.88585,10,,,,,,,,,,,,,,,,,,,,,,,,,,,,,,,,,,,,,
105.82,0.11203,0.92661,10,,,,,,,,,,,,,,,,,,,,,,,,,,,,,,,,,,,,,
106.42,0.11186,0.85736,10,,,,,,,,,,,,,,,,,,,,,,,,,,,,,,,,,,,,,
107.02,0.11169,0.91301,10,,,,,,,,,,,,,,,,,,,,,,,,,,,,,,,,,,,,,
107.62,0.11101,0.90682,10,,,,,,,,,,,,,,,,,,,,,,,,,,,,,,,,,,,,,
108.22,0.10942,0.84864,10,,,,,,,,,,,,,,,,,,,,,,,,,,,,,,,,,,,,,
108.82,0.10852,0.81898,10,,,,,,,,,,,,,,,,,,,,,,,,,,,,,,,,,,,,,
109.42,0.10829,0.84847,10,,,,,,,,,,,,,,,,,,,,,,,,,,,,,,,,,,,,,
110.02,0.10812,0.82622,10,,,,,,,,,,,,,,,,,,,,,,,,,,,,,,,,,,,,,
110.62,0.10823,0.76099,10,,,,,,,,,,,,,,,,,,,,,,,,,,,,,,,,,,,,,
111.22,0.10829,0.77513,10,,,,,,,,,,,,,,,,,,,,,,,,,,,,,,,,,,,,,
111.82,0.10835,0.86076,10,,,,,,,,,,,,,,,,,,,,,,,,,,,,,,,,,,,,,
112.42,0.1084,0.82419,10,,,,,,,,,,,,,,,,,,,,,,,,,,,,,,,,,,,,,
113.02,0.10846,0.81097,10,,,,,,,,,,,,,,,,,,,,,,,,,,,,,,,,,,,,,
113.62,0.10857,0.81349,10,,,,,,,,,,,,,,,,,,,,,,,,,,,,,,,,,,,,,
114.22,0.1088,0.76475,10,,,,,,,,,,,,,,,,,,,,,,,,,,,,,,,,,,,,,
114.82,0.10908,0.83988,10,,,,,,,,,,,,,,,,,,,,,,,,,,,,,,,,,,,,,
115.42,0.10942,0.79198,10,,,,,,,,,,,,,,,,,,,,,,,,,,,,,,,,,,,,,
116.02,0.10988,0.83166,10,,,,,,,,,,,,,,,,,,,,,,,,,,,,,,,,,,,,,
116.62,0.11044,0.80561,10,,,,,,,,,,,,,,,,,,,,,,,,,,,,,,,,,,,,,
117.22,0.11095,0.86826,10,,,,,,,,,,,,,,,,,,,,,,,,,,,,,,,,,,,,,
117.82,0.11112,0.87321,10,,,,,,,,,,,,,,,,,,,,,,,,,,,,,,,,,,,,,
118.42,0.11118,0.90548,10,,,,,,,,,,,,,,,,,,,,,,,,,,,,,,,,,,,,,
119.02,0.11107,0.92237,10,,,,,,,,,,,,,,,,,,,,,,,,,,,,,,,,,,,,,
119.62,0.11107,0.8535,10,,,,,,,,,,,,,,,,,,,,,,,,,,,,,,,,,,,,,
120.22,0.11101,0.90886,10,,,,,,,,,,,,,,,,,,,,,,,,,,,,,,,,,,,,,
120.82,0.11095,0.89646,10,,,,,,,,,,,,,,,,,,,,,,,,,,,,,,,,,,,,,
121.42,0.11095,0.8427,10,,,,,,,,,,,,,,,,,,,,,,,,,,,,,,,,,,,,,
122.02,0.11084,0.93429,10,,,,,,,,,,,,,,,,,,,,,,,,,,,,,,,,,,,,,
122.62,0.11078,0.94144,10,,,,,,,,,,,,,,,,,,,,,,,,,,,,,,,,,,,,,
123.22,0.11044,0.90179,10,,,,,,,,,,,,,,,,,,,,,,,,,,,,,,,,,,,,,
123.82,0.11016,0.90712,10,,,,,,,,,,,,,,,,,,,,,,,,,,,,,,,,,,,,,
124.42,0.10959,0.91085,10,,,,,,,,,,,,,,,,,,,,,,,,,,,,,,,,,,,,,
125.02,0.10846,0.98455,10,,,,,,,,,,,,,,,,,,,,,,,,,,,,,,,,,,,,,
125.62,0.10738,0.87934,10,,,,,,,,,,,,,,,,,,,,,,,,,,,,,,,,,,,,,
126.22,0.10619,0.83353,10,,,,,,,,,,,,,,,,,,,,,,,,,,,,,,,,,,,,,
126.82,0.10585,0.82333,10,,,,,,,,,,,,,,,,,,,,,,,,,,,,,,,,,,,,,
127.42,0.10585,0.76673,10,,,,,,,,,,,,,,,,,,,,,,,,,,,,,,,,,,,,,
128.02,0.10591,0.83861,10,,,,,,,,,,,,,,,,,,,,,,,,,,,,,,,,,,,,,
128.62,0.10585,0.85307,10,,,,,,,,,,,,,,,,,,,,,,,,,,,,,,,,,,,,,
129.22,0.10602,0.75306,10,,,,,,,,,,,,,,,,,,,,,,,,,,,,,,,,,,,,,
129.82,0.10608,0.83236,10,,,,,,,,,,,,,,,,,,,,,,,,,,,,,,,,,,,,,
130.42,0.10614,0.83102,10,,,,,,,,,,,,,,,,,,,,,,,,,,,,,,,,,,,,,
131.02,0.10625,0.79599,10,,,,,,,,,,,,,,,,,,,,,,,,,,,,,,,,,,,,,
131.62,0.10653,0.77258,10,,,,,,,,,,,,,,,,,,,,,,,,,,,,,,,,,,,,,
132.22,0.10693,0.73811,10,,,,,,,,,,,,,,,,,,,,,,,,,,,,,,,,,,,,,
132.82,0.1075,0.82239,10,,,,,,,,,,,,,,,,,,,,,,,,,,,,,,,,,,,,,
133.42,0.10823,0.83328,10,,,,,,,,,,,,,,,,,,,,,,,,,,,,,,,,,,,,,
134.02,0.1088,0.85483,10,,,,,,,,,,,,,,,,,,,,,,,,,,,,,,,,,,,,,
134.62,0.10925,0.88539,10,,,,,,,,,,,,,,,,,,,,,,,,,,,,,,,,,,,,,
135.22,0.10942,0.88243,10,,,,,,,,,,,,,,,,,,,,,,,,,,,,,,,,,,,,,
135.82,0.10942,0.94021,10,,,,,,,,,,,,,,,,,,,,,,,,,,,,,,,,,,,,,
136.42,0.10931,0.88097,10,,,,,,,,,,,,,,,,,,,,,,,,,,,,,,,,,,,,,
137.02,0.10925,0.895,10,,,,,,,,,,,,,,,,,,,,,,,,,,,,,,,,,,,,,
137.62,0.1092,0.88285,10,,,,,,,,,,,,,,,,,,,,,,,,,,,,,,,,,,,,,
138.22,0.10914,0.82611,10,,,,,,,,,,,,,,,,,,,,,,,,,,,,,,,,,,,,,
138.82,0.10908,0.9308,10,,,,,,,,,,,,,,,,,,,,,,,,,,,,,,,,,,,,,
139.42,0.10891,0.89484,10,,,,,,,,,,,,,,,,,,,,,,,,,,,,,,,,,,,,,
140.02,0.1088,0.91845,10,,,,,,,,,,,,,,,,,,,,,,,,,,,,,,,,,,,,,
140.62,0.10857,0.92353,10,,,,,,,,,,,,,,,,,,,,,,,,,,,,,,,,,,,,,
141.22,0.10806,0.93107,10,,,,,,,,,,,,,,,,,,,,,,,,,,,,,,,,,,,,,
141.82,0.10744,0.88995,10,,,,,,,,,,,,,,,,,,,,,,,,,,,,,,,,,,,,,
142.42,0.1067,0.87611,10,,,,,,,,,,,,,,,,,,,,,,,,,,,,,,,,,,,,,
143.02,0.10597,0.8711,10,,,,,,,,,,,,,,,,,,,,,,,,,,,,,,,,,,,,,
143.62,0.10551,0.82667,10,,,,,,,,,,,,,,,,,,,,,,,,,,,,,,,,,,,,,
144.22,0.10534,0.88354,10,,,,,,,,,,,,,,,,,,,,,,,,,,,,,,,,,,,,,
144.82,0.10517,0.84039,10,,,,,,,,,,,,,,,,,,,,,,,,,,,,,,,,,,,,,
145.42,0.10506,0.84507,10,,,,,,,,,,,,,,,,,,,,,,,,,,,,,,,,,,,,,
146.02,0.10512,0.79532,10,,,,,,,,,,,,,,,,,,,,,,,,,,,,,,,,,,,,,
146.62,0.10512,0.84233,10,,,,,,,,,,,,,,,,,,,,,,,,,,,,,,,,,,,,,
147.22,0.10517,0.77166,10,,,,,,,,,,,,,,,,,,,,,,,,,,,,,,,,,,,,,
147.82,0.10523,0.84682,10,,,,,,,,,,,,,,,,,,,,,,,,,,,,,,,,,,,,,
148.42,0.10523,0.83606,10,,,,,,,,,,,,,,,,,,,,,,,,,,,,,,,,,,,,,
149.02,0.10523,0.84537,10,,,,,,,,,,,,,,,,,,,,,,,,,,,,,,,,,,,,,
149.62,0.10523,0.89476,10,,,,,,,,,,,,,,,,,,,,,,,,,,,,,,,,,,,,,
150.22,0.10523,0.81752,10,,,,,,,,,,,,,,,,,,,,,,,,,,,,,,,,,,,,,
150.82,0.10529,0.87789,10,,,,,,,,,,,,,,,,,,,,,,,,,,,,,,,,,,,,,
151.42,0.10529,0.85434,10,,,,,,,,,,,,,,,,,,,,,,,,,,,,,,,,,,,,,
152.02,0.1054,0.83707,10,,,,,,,,,,,,,,,,,,,,,,,,,,,,,,,,,,,,,
152.62,0.1054,0.89295,10,,,,,,,,,,,,,,,,,,,,,,,,,,,,,,,,,,,,,
153.22,0.10551,0.78426,10,,,,,,,,,,,,,,,,,,,,,,,,,,,,,,,,,,,,,
153.82,0.10563,0.81523,10,,,,,,,,,,,,,,,,,,,,,,,,,,,,,,,,,,,,,
154.42,0.1058,0.82607,10,,,,,,,,,,,,,,,,,,,,,,,,,,,,,,,,,,,,,
155.02,0.10602,0.82174,10,,,,,,,,,,,,,,,,,,,,,,,,,,,,,,,,,,,,,
155.62,0.10614,0.80539,10,,,,,,,,,,,,,,,,,,,,,,,,,,,,,,,,,,,,,
156.22,0.10625,0.80697,10,,,,,,,,,,,,,,,,,,,,,,,,,,,,,,,,,,,,,
156.82,0.10642,0.84057,10,,,,,,,,,,,,,,,,,,,,,,,,,,,,,,,,,,,,,
157.42,0.10659,0.86433,10,,,,,,,,,,,,,,,,,,,,,,,,,,,,,,,,,,,,,
158.02,0.10676,0.87524,10,,,,,,,,,,,,,,,,,,,,,,,,,,,,,,,,,,,,,
158.62,0.10682,0.92244,10,,,,,,,,,,,,,,,,,,,,,,,,,,,,,,,,,,,,,
159.22,0.1067,0.88083,10,,,,,,,,,,,,,,,,,,,,,,,,,,,,,,,,,,,,,
159.82,0.1067,0.85597,10,,,,,,,,,,,,,,,,,,,,,,,,,,,,,,,,,,,,,
160.42,0.10665,0.86389,10,,,,,,,,,,,,,,,,,,,,,,,,,,,,,,,,,,,,,
161.02,0.10665,0.85879,10,,,,,,,,,,,,,,,,,,,,,,,,,,,,,,,,,,,,,
161.62,0.1067,0.87415,10,,,,,,,,,,,,,,,,,,,,,,,,,,,,,,,,,,,,,
162.22,0.10653,0.89807,10,,,,,,,,,,,,,,,,,,,,,,,,,,,,,,,,,,,,,
162.82,0.10653,0.87404,10,,,,,,,,,,,,,,,,,,,,,,,,,,,,,,,,,,,,,
163.42,0.10648,0.86843,10,,,,,,,,,,,,,,,,,,,,,,,,,,,,,,,,,,,,,
164.02,0.10642,0.89096,10,,,,,,,,,,,,,,,,,,,,,,,,,,,,,,,,,,,,,
164.62,0.10631,0.86621,10,,,,,,,,,,,,,,,,,,,,,,,,,,,,,,,,,,,,,
165.22,0.10619,0.90388,10,,,,,,,,,,,,,,,,,,,,,,,,,,,,,,,,,,,,,
165.82,0.10602,0.91771,10,,,,,,,,,,,,,,,,,,,,,,,,,,,,,,,,,,,,,
166.42,0.10574,0.89258,10,,,,,,,,,,,,,,,,,,,,,,,,,,,,,,,,,,,,,
167.02,0.1054,0.88659,10,,,,,,,,,,,,,,,,,,,,,,,,,,,,,,,,,,,,,
167.62,0.10483,0.93664,10,,,,,,,,,,,,,,,,,,,,,,,,,,,,,,,,,,,,,
168.22,0.10404,0.81577,10,,,,,,,,,,,,,,,,,,,,,,,,,,,,,,,,,,,,,
168.82,0.10353,0.84841,10,,,,,,,,,,,,,,,,,,,,,,,,,,,,,,,,,,,,,
169.42,0.10319,0.87622,10,,,,,,,,,,,,,,,,,,,,,,,,,,,,,,,,,,,,,
170.02,0.10308,0.81228,10,,,,,,,,,,,,,,,,,,,,,,,,,,,,,,,,,,,,,
170.62,0.10302,0.76591,10,,,,,,,,,,,,,,,,,,,,,,,,,,,,,,,,,,,,,
171.22,0.10313,0.77455,10,,,,,,,,,,,,,,,,,,,,,,,,,,,,,,,,,,,,,
171.82,0.10319,0.78651,10,,,,,,,,,,,,,,,,,,,,,,,,,,,,,,,,,,,,,
172.42,0.10319,0.81429,10,,,,,,,,,,,,,,,,,,,,,,,,,,,,,,,,,,,,,
173.02,0.10319,0.85993,10,,,,,,,,,,,,,,,,,,,,,,,,,,,,,,,,,,,,,
173.62,0.10325,0.80872,10,,,,,,,,,,,,,,,,,,,,,,,,,,,,,,,,,,,,,
174.22,0.10325,0.83884,10,,,,,,,,,,,,,,,,,,,,,,,,,,,,,,,,,,,,,
174.82,0.1033,0.85333,10,,,,,,,,,,,,,,,,,,,,,,,,,,,,,,,,,,,,,
175.42,0.10336,0.81706,10,,,,,,,,,,,,,,,,,,,,,,,,,,,,,,,,,,,,,
176.02,0.10342,0.83334,10,,,,,,,,,,,,,,,,,,,,,,,,,,,,,,,,,,,,,
176.62,0.10353,0.75278,10,,,,,,,,,,,,,,,,,,,,,,,,,,,,,,,,,,,,,
177.22,0.10376,0.77579,10,,,,,,,,,,,,,,,,,,,,,,,,,,,,,,,,,,,,,
177.82,0.10398,0.8043,10,,,,,,,,,,,,,,,,,,,,,,,,,,,,,,,,,,,,,
178.42,0.10438,0.79902,10,,,,,,,,,,,,,,,,,,,,,,,,,,,,,,,,,,,,,
179.02,0.10483,0.83699,10,,,,,,,,,,,,,,,,,,,,,,,,,,,,,,,,,,,,,
179.62,0.10523,0.87804,10,,,,,,,,,,,,,,,,,,,,,,,,,,,,,,,,,,,,,
180.22,0.10563,0.84671,10,,,,,,,,,,,,,,,,,,,,,,,,,,,,,,,,,,,,,
180.82,0.10591,0.91574,10,,,,,,,,,,,,,,,,,,,,,,,,,,,,,,,,,,,,,
181.42,0.10602,0.87541,10,,,,,,,,,,,,,,,,,,,,,,,,,,,,,,,,,,,,,
182.02,0.10597,0.92345,10,,,,,,,,,,,,,,,,,,,,,,,,,,,,,,,,,,,,,
182.62,0.10591,0.93795,10,,,,,,,,,,,,,,,,,,,,,,,,,,,,,,,,,,,,,
183.22,0.10574,0.88214,10,,,,,,,,,,,,,,,,,,,,,,,,,,,,,,,,,,,,,
183.82,0.10574,0.88052,10,,,,,,,,,,,,,,,,,,,,,,,,,,,,,,,,,,,,,
184.42,0.10568,0.87501,10,,,,,,,,,,,,,,,,,,,,,,,,,,,,,,,,,,,,,
185.02,0.10563,0.87895,10,,,,,,,,,,,,,,,,,,,,,,,,,,,,,,,,,,,,,
185.62,0.10551,0.82273,10,,,,,,,,,,,,,,,,,,,,,,,,,,,,,,,,,,,,,
186.22,0.1054,0.87981,10,,,,,,,,,,,,,,,,,,,,,,,,,,,,,,,,,,,,,
186.82,0.10523,0.90161,10,,,,,,,,,,,,,,,,,,,,,,,,,,,,,,,,,,,,,
187.42,0.10512,0.91864,10,,,,,,,,,,,,,,,,,,,,,,,,,,,,,,,,,,,,,
188.02,0.105,0.88694,10,,,,,,,,,,,,,,,,,,,,,,,,,,,,,,,,,,,,,
188.62,0.10483,0.92559,10,,,,,,,,,,,,,,,,,,,,,,,,,,,,,,,,,,,,,
189.22,0.10444,0.92109,10,,,,,,,,,,,,,,,,,,,,,,,,,,,,,,,,,,,,,
189.82,0.10393,0.88281,10,,,,,,,,,,,,,,,,,,,,,,,,,,,,,,,,,,,,,
190.42,0.10347,0.82377,10,,,,,,,,,,,,,,,,,,,,,,,,,,,,,,,,,,,,,
191.02,0.10325,0.82078,10,,,,,,,,,,,,,,,,,,,,,,,,,,,,,,,,,,,,,
191.62,0.10308,0.87555,10,,,,,,,,,,,,,,,,,,,,,,,,,,,,,,,,,,,,,
192.22,0.10296,0.84274,10,,,,,,,,,,,,,,,,,,,,,,,,,,,,,,,,,,,,,
192.82,0.10302,0.84618,10,,,,,,,,,,,,,,,,,,,,,,,,,,,,,,,,,,,,,
193.42,0.10302,0.83104,10,,,,,,,,,,,,,,,,,,,,,,,,,,,,,,,,,,,,,
194.02,0.10308,0.7911,10,,,,,,,,,,,,,,,,,,,,,,,,,,,,,,,,,,,,,
194.62,0.10308,0.82615,10,,,,,,,,,,,,,,,,,,,,,,,,,,,,,,,,,,,,,
195.22,0.10308,0.81413,10,,,,,,,,,,,,,,,,,,,,,,,,,,,,,,,,,,,,,
195.82,0.10319,0.87651,10,,,,,,,,,,,,,,,,,,,,,,,,,,,,,,,,,,,,,
196.42,0.10319,0.84629,10,,,,,,,,,,,,,,,,,,,,,,,,,,,,,,,,,,,,,
197.02,0.10325,0.80597,10,,,,,,,,,,,,,,,,,,,,,,,,,,,,,,,,,,,,,
197.62,0.10325,0.89435,10,,,,,,,,,,,,,,,,,,,,,,,,,,,,,,,,,,,,,
198.22,0.1033,0.82815,10,,,,,,,,,,,,,,,,,,,,,,,,,,,,,,,,,,,,,
198.82,0.1033,0.83057,10,,,,,,,,,,,,,,,,,,,,,,,,,,,,,,,,,,,,,
199.42,0.10342,0.79475,10,,,,,,,,,,,,,,,,,,,,,,,,,,,,,,,,,,,,,
200.02,0.10353,0.83488,10,,,,,,,,,,,,,,,,,,,,,,,,,,,,,,,,,,,,,
200.62,0.10364,0.79852,10,,,,,,,,,,,,,,,,,,,,,,,,,,,,,,,,,,,,,
201.22,0.10381,0.78905,10,,,,,,,,,,,,,,,,,,,,,,,,,,,,,,,,,,,,,
201.82,0.1041,0.86274,10,,,,,,,,,,,,,,,,,,,,,,,,,,,,,,,,,,,,,
202.42,0.10444,0.87044,10,,,,,,,,,,,,,,,,,,,,,,,,,,,,,,,,,,,,,
203.02,0.10466,0.84286,10,,,,,,,,,,,,,,,,,,,,,,,,,,,,,,,,,,,,,
203.62,0.10495,0.82701,10,,,,,,,,,,,,,,,,,,,,,,,,,,,,,,,,,,,,,
204.22,0.10529,0.90283,10,,,,,,,,,,,,,,,,,,,,,,,,,,,,,,,,,,,,,
204.82,0.10546,0.88519,10,,,,,,,,,,,,,,,,,,,,,,,,,,,,,,,,,,,,,
205.42,0.10563,0.83914,10,,,,,,,,,,,,,,,,,,,,,,,,,,,,,,,,,,,,,
206.02,0.10574,0.86149,10,,,,,,,,,,,,,,,,,,,,,,,,,,,,,,,,,,,,,
206.62,0.10574,0.93544,10,,,,,,,,,,,,,,,,,,,,,,,,,,,,,,,,,,,,,
207.22,0.10563,0.85136,10,,,,,,,,,,,,,,,,,,,,,,,,,,,,,,,,,,,,,
207.82,0.10568,0.89319,10,,,,,,,,,,,,,,,,,,,,,,,,,,,,,,,,,,,,,
208.42,0.10551,0.8816,10,,,,,,,,,,,,,,,,,,,,,,,,,,,,,,,,,,,,,
209.02,0.10551,0.83839,10,,,,,,,,,,,,,,,,,,,,,,,,,,,,,,,,,,,,,
209.62,0.10551,0.83476,10,,,,,,,,,,,,,,,,,,,,,,,,,,,,,,,,,,,,,
210.22,0.10546,0.95353,10,,,,,,,,,,,,,,,,,,,,,,,,,,,,,,,,,,,,,
210.82,0.10546,0.85486,10,,,,,,,,,,,,,,,,,,,,,,,,,,,,,,,,,,,,,
211.42,0.1054,0.86852,10,,,,,,,,,,,,,,,,,,,,,,,,,,,,,,,,,,,,,
212.02,0.1054,0.89241,10,,,,,,,,,,,,,,,,,,,,,,,,,,,,,,,,,,,,,
212.62,0.10529,0.92041,10,,,,,,,,,,,,,,,,,,,,,,,,,,,,,,,,,,,,,
213.22,0.10517,0.87932,10,,,,,,,,,,,,,,,,,,,,,,,,,,,,,,,,,,,,,
213.82,0.10506,0.88495,10,,,,,,,,,,,,,,,,,,,,,,,,,,,,,,,,,,,,,
214.42,0.10495,0.90635,10,,,,,,,,,,,,,,,,,,,,,,,,,,,,,,,,,,,,,
215.02,0.10472,0.92652,10,,,,,,,,,,,,,,,,,,,,,,,,,,,,,,,,,,,,,
215.62,0.10427,0.89402,10,,,,,,,,,,,,,,,,,,,,,,,,,,,,,,,,,,,,,
216.22,0.10376,0.85135,10,,,,,,,,,,,,,,,,,,,,,,,,,,,,,,,,,,,,,
216.82,0.10342,0.88185,10,,,,,,,,,,,,,,,,,,,,,,,,,,,,,,,,,,,,,
217.42,0.10313,0.84176,10,,,,,,,,,,,,,,,,,,,,,,,,,,,,,,,,,,,,,
218.02,0.10291,0.85036,10,,,,,,,,,,,,,,,,,,,,,,,,,,,,,,,,,,,,,
218.62,0.10285,0.78776,10,,,,,,,,,,,,,,,,,,,,,,,,,,,,,,,,,,,,,
219.22,0.10296,0.88949,10,,,,,,,,,,,,,,,,,,,,,,,,,,,,,,,,,,,,,
219.82,0.10302,0.85856,10,,,,,,,,,,,,,,,,,,,,,,,,,,,,,,,,,,,,,
220.42,0.10302,0.84233,10,,,,,,,,,,,,,,,,,,,,,,,,,,,,,,,,,,,,,
221.02,0.10302,0.8444,10,,,,,,,,,,,,,,,,,,,,,,,,,,,,,,,,,,,,,
221.62,0.10296,0.85903,10,,,,,,,,,,,,,,,,,,,,,,,,,,,,,,,,,,,,,
222.22,0.10296,0.94277,10,,,,,,,,,,,,,,,,,,,,,,,,,,,,,,,,,,,,,
222.82,0.10302,0.91608,10,,,,,,,,,,,,,,,,,,,,,,,,,,,,,,,,,,,,,
223.42,0.10302,0.85996,10,,,,,,,,,,,,,,,,,,,,,,,,,,,,,,,,,,,,,
224.02,0.10296,0.86802,10,,,,,,,,,,,,,,,,,,,,,,,,,,,,,,,,,,,,,
224.62,0.10308,0.83359,10,,,,,,,,,,,,,,,,,,,,,,,,,,,,,,,,,,,,,
225.22,0.10308,0.95637,10,,,,,,,,,,,,,,,,,,,,,,,,,,,,,,,,,,,,,
225.82,0.10308,0.84605,10,,,,,,,,,,,,,,,,,,,,,,,,,,,,,,,,,,,,,
226.42,0.10308,0.7909,10,,,,,,,,,,,,,,,,,,,,,,,,,,,,,,,,,,,,,
227.02,0.10308,0.8724,10,,,,,,,,,,,,,,,,,,,,,,,,,,,,,,,,,,,,,
227.62,0.10313,0.82595,10,,,,,,,,,,,,,,,,,,,,,,,,,,,,,,,,,,,,,
228.22,0.10313,0.87821,10,,,,,,,,,,,,,,,,,,,,,,,,,,,,,,,,,,,,,
228.82,0.10319,0.86309,10,,,,,,,,,,,,,,,,,,,,,,,,,,,,,,,,,,,,,
229.42,0.10319,0.83644,10,,,,,,,,,,,,,,,,,,,,,,,,,,,,,,,,,,,,,
230.02,0.10319,0.84059,10,,,,,,,,,,,,,,,,,,,,,,,,,,,,,,,,,,,,,
230.62,0.10319,0.81909,10,,,,,,,,,,,,,,,,,,,,,,,,,,,,,,,,,,,,,
231.22,0.10319,0.86758,10,,,,,,,,,,,,,,,,,,,,,,,,,,,,,,,,,,,,,
231.82,0.10319,0.9176,10,,,,,,,,,,,,,,,,,,,,,,,,,,,,,,,,,,,,,
232.42,0.10319,0.87101,10,,,,,,,,,,,,,,,,,,,,,,,,,,,,,,,,,,,,,
233.02,0.10319,0.85045,10,,,,,,,,,,,,,,,,,,,,,,,,,,,,,,,,,,,,,
233.62,0.10325,0.80832,10,,,,,,,,,,,,,,,,,,,,,,,,,,,,,,,,,,,,,
234.22,0.10325,0.89139,10,,,,,,,,,,,,,,,,,,,,,,,,,,,,,,,,,,,,,
234.82,0.10325,0.86409,10,,,,,,,,,,,,,,,,,,,,,,,,,,,,,,,,,,,,,
235.42,0.1033,0.82088,10,,,,,,,,,,,,,,,,,,,,,,,,,,,,,,,,,,,,,
236.02,0.1033,0.88535,10,,,,,,,,,,,,,,,,,,,,,,,,,,,,,,,,,,,,,
236.62,0.10336,0.83492,10,,,,,,,,,,,,,,,,,,,,,,,,,,,,,,,,,,,,,
237.22,0.10342,0.79609,10,,,,,,,,,,,,,,,,,,,,,,,,,,,,,,,,,,,,,
237.82,0.10353,0.80186,10,,,,,,,,,,,,,,,,,,,,,,,,,,,,,,,,,,,,,
238.42,0.10353,0.8219,10,,,,,,,,,,,,,,,,,,,,,,,,,,,,,,,,,,,,,
239.02,0.10364,0.83056,10,,,,,,,,,,,,,,,,,,,,,,,,,,,,,,,,,,,,,
239.62,0.10376,0.85471,10,,,,,,,,,,,,,,,,,,,,,,,,,,,,,,,,,,,,,
240.22,0.10387,0.8556,10,,,,,,,,,,,,,,,,,,,,,,,,,,,,,,,,,,,,,
240.82,0.10398,0.9075,10,,,,,,,,,,,,,,,,,,,,,,,,,,,,,,,,,,,,,
241.42,0.1041,0.84045,10,,,,,,,,,,,,,,,,,,,,,,,,,,,,,,,,,,,,,
242.02,0.10421,0.82696,10,,,,,,,,,,,,,,,,,,,,,,,,,,,,,,,,,,,,,
242.62,0.10432,0.83978,10,,,,,,,,,,,,,,,,,,,,,,,,,,,,,,,,,,,,,
243.22,0.10449,0.85244,10,,,,,,,,,,,,,,,,,,,,,,,,,,,,,,,,,,,,,
243.82,0.10472,0.89753,10,,,,,,,,,,,,,,,,,,,,,,,,,,,,,,,,,,,,,
244.42,0.10478,0.86811,10,,,,,,,,,,,,,,,,,,,,,,,,,,,,,,,,,,,,,
245.02,0.10478,0.90249,10,,,,,,,,,,,,,,,,,,,,,,,,,,,,,,,,,,,,,
245.62,0.10466,0.863,10,,,,,,,,,,,,,,,,,,,,,,,,,,,,,,,,,,,,,
246.22,0.10461,0.88076,10,,,,,,,,,,,,,,,,,,,,,,,,,,,,,,,,,,,,,
246.82,0.10461,0.88364,10,,,,,,,,,,,,,,,,,,,,,,,,,,,,,,,,,,,,,
247.42,0.10455,0.894,10,,,,,,,,,,,,,,,,,,,,,,,,,,,,,,,,,,,,,
248.02,0.10449,0.8935,10,,,,,,,,,,,,,,,,,,,,,,,,,,,,,,,,,,,,,
248.62,0.10455,0.86724,10,,,,,,,,,,,,,,,,,,,,,,,,,,,,,,,,,,,,,
249.22,0.10444,0.88081,10,,,,,,,,,,,,,,,,,,,,,,,,,,,,,,,,,,,,,
249.82,0.10438,0.8882,10,,,,,,,,,,,,,,,,,,,,,,,,,,,,,,,,,,,,,
250.42,0.10432,0.90998,10,,,,,,,,,,,,,,,,,,,,,,,,,,,,,,,,,,,,,
251.02,0.10415,0.84998,10,,,,,,,,,,,,,,,,,,,,,,,,,,,,,,,,,,,,,
251.62,0.1041,0.84214,10,,,,,,,,,,,,,,,,,,,,,,,,,,,,,,,,,,,,,
252.22,0.10404,0.85097,10,,,,,,,,,,,,,,,,,,,,,,,,,,,,,,,,,,,,,
252.82,0.10398,0.82254,10,,,,,,,,,,,,,,,,,,,,,,,,,,,,,,,,,,,,,
253.42,0.10398,0.89343,10,,,,,,,,,,,,,,,,,,,,,,,,,,,,,,,,,,,,,
254.02,0.10398,0.91387,10,,,,,,,,,,,,,,,,,,,,,,,,,,,,,,,,,,,,,
254.62,0.10387,0.86288,10,,,,,,,,,,,,,,,,,,,,,,,,,,,,,,,,,,,,,
255.22,0.10387,0.86011,10,,,,,,,,,,,,,,,,,,,,,,,,,,,,,,,,,,,,,
255.82,0.10376,0.92427,10,,,,,,,,,,,,,,,,,,,,,,,,,,,,,,,,,,,,,
256.42,0.10347,0.87172,10,,,,,,,,,,,,,,,,,,,,,,,,,,,,,,,,,,,,,
257.02,0.1033,0.8632,10,,,,,,,,,,,,,,,,,,,,,,,,,,,,,,,,,,,,,
257.62,0.10291,0.884,10,,,,,,,,,,,,,,,,,,,,,,,,,,,,,,,,,,,,,
258.22,0.10257,0.85386,10,,,,,,,,,,,,,,,,,,,,,,,,,,,,,,,,,,,,,
258.82,0.10228,0.86447,10,,,,,,,,,,,,,,,,,,,,,,,,,,,,,,,,,,,,,
259.42,0.10211,0.84716,10,,,,,,,,,,,,,,,,,,,,,,,,,,,,,,,,,,,,,
260.02,0.10206,0.85359,10,,,,,,,,,,,,,,,,,,,,,,,,,,,,,,,,,,,,,
260.62,0.10217,0.79871,10,,,,,,,,,,,,,,,,,,,,,,,,,,,,,,,,,,,,,
261.22,0.10217,0.80444,10,,,,,,,,,,,,,,,,,,,,,,,,,,,,,,,,,,,,,
261.82,0.10223,0.81134,10,,,,,,,,,,,,,,,,,,,,,,,,,,,,,,,,,,,,,
262.42,0.10217,0.82105,10,,,,,,,,,,,,,,,,,,,,,,,,,,,,,,,,,,,,,
263.02,0.10223,0.83041,10,,,,,,,,,,,,,,,,,,,,,,,,,,,,,,,,,,,,,
263.62,0.1024,0.83293,10,,,,,,,,,,,,,,,,,,,,,,,,,,,,,,,,,,,,,
264.22,0.10245,0.82034,10,,,,,,,,,,,,,,,,,,,,,,,,,,,,,,,,,,,,,
264.82,0.10251,0.90339,10,,,,,,,,,,,,,,,,,,,,,,,,,,,,,,,,,,,,,
265.42,0.10251,0.83498,10,,,,,,,,,,,,,,,,,,,,,,,,,,,,,,,,,,,,,
266.02,0.10257,0.83305,10,,,,,,,,,,,,,,,,,,,,,,,,,,,,,,,,,,,,,
266.62,0.10268,0.82164,10,,,,,,,,,,,,,,,,,,,,,,,,,,,,,,,,,,,,,
267.22,0.10296,0.76835,10,,,,,,,,,,,,,,,,,,,,,,,,,,,,,,,,,,,,,
267.82,0.10313,0.79313,10,,,,,,,,,,,,,,,,,,,,,,,,,,,,,,,,,,,,,
268.42,0.10342,0.8335,10,,,,,,,,,,,,,,,,,,,,,,,,,,,,,,,,,,,,,
269.02,0.10381,0.83494,10,,,,,,,,,,,,,,,,,,,,,,,,,,,,,,,,,,,,,
269.62,0.10432,0.78682,10,,,,,,,,,,,,,,,,,,,,,,,,,,,,,,,,,,,,,
270.22,0.10483,0.83701,10,,,,,,,,,,,,,,,,,,,,,,,,,,,,,,,,,,,,,
270.82,0.10517,0.84045,10,,,,,,,,,,,,,,,,,,,,,,,,,,,,,,,,,,,,,
271.42,0.10534,0.89272,10,,,,,,,,,,,,,,,,,,,,,,,,,,,,,,,,,,,,,
272.02,0.1054,0.86036,10,,,,,,,,,,,,,,,,,,,,,,,,,,,,,,,,,,,,,
272.62,0.10529,0.91221,10,,,,,,,,,,,,,,,,,,,,,,,,,,,,,,,,,,,,,
273.22,0.10529,0.85128,10,,,,,,,,,,,,,,,,,,,,,,,,,,,,,,,,,,,,,
273.82,0.10517,0.9313,10,,,,,,,,,,,,,,,,,,,,,,,,,,,,,,,,,,,,,
274.42,0.10512,0.90707,10,,,,,,,,,,,,,,,,,,,,,,,,,,,,,,,,,,,,,
275.02,0.10506,0.89233,10,,,,,,,,,,,,,,,,,,,,,,,,,,,,,,,,,,,,,
275.62,0.10495,0.92529,10,,,,,,,,,,,,,,,,,,,,,,,,,,,,,,,,,,,,,
276.22,0.10478,0.921,10,,,,,,,,,,,,,,,,,,,,,,,,,,,,,,,,,,,,,
276.82,0.10444,0.92819,10,,,,,,,,,,,,,,,,,,,,,,,,,,,,,,,,,,,,,
277.42,0.10404,0.89479,10,,,,,,,,,,,,,,,,,,,,,,,,,,,,,,,,,,,,,
278.02,0.10347,0.88351,10,,,,,,,,,,,,,,,,,,,,,,,,,,,,,,,,,,,,,
278.62,0.10285,0.85419,10,,,,,,,,,,,,,,,,,,,,,,,,,,,,,,,,,,,,,
279.22,0.10251,0.84828,10,,,,,,,,,,,,,,,,,,,,,,,,,,,,,,,,,,,,,
279.82,0.10223,0.88735,10,,,,,,,,,,,,,,,,,,,,,,,,,,,,,,,,,,,,,
280.42,0.10206,0.82666,10,,,,,,,,,,,,,,,,,,,,,,,,,,,,,,,,,,,,,
281.02,0.102,0.83893,10,,,,,,,,,,,,,,,,,,,,,,,,,,,,,,,,,,,,,
281.62,0.10206,0.8233,10,,,,,,,,,,,,,,,,,,,,,,,,,,,,,,,,,,,,,
282.22,0.10206,0.85171,10,,,,,,,,,,,,,,,,,,,,,,,,,,,,,,,,,,,,,
282.82,0.10211,0.83872,10,,,,,,,,,,,,,,,,,,,,,,,,,,,,,,,,,,,,,
283.42,0.10211,0.83649,10,,,,,,,,,,,,,,,,,,,,,,,,,,,,,,,,,,,,,
284.02,0.10206,0.82168,10,,,,,,,,,,,,,,,,,,,,,,,,,,,,,,,,,,,,,
284.62,0.10217,0.8637,10,,,,,,,,,,,,,,,,,,,,,,,,,,,,,,,,,,,,,
285.22,0.10223,0.84246,10,,,,,,,,,,,,,,,,,,,,,,,,,,,,,,,,,,,,,
285.82,0.10223,0.87793,10,,,,,,,,,,,,,,,,,,,,,,,,,,,,,,,,,,,,,
286.42,0.10223,0.80857,10,,,,,,,,,,,,,,,,,,,,,,,,,,,,,,,,,,,,,
287.02,0.10234,0.80313,10,,,,,,,,,,,,,,,,,,,,,,,,,,,,,,,,,,,,,
287.62,0.10245,0.85646,10,,,,,,,,,,,,,,,,,,,,,,,,,,,,,,,,,,,,,
288.22,0.10245,0.84443,10,,,,,,,,,,,,,,,,,,,,,,,,,,,,,,,,,,,,,
288.82,0.10245,0.86677,10,,,,,,,,,,,,,,,,,,,,,,,,,,,,,,,,,,,,,
289.42,0.10245,0.81564,10,,,,,,,,,,,,,,,,,,,,,,,,,,,,,,,,,,,,,
290.02,0.10245,0.88078,10,,,,,,,,,,,,,,,,,,,,,,,,,,,,,,,,,,,,,
290.62,0.10251,0.83455,10,,,,,,,,,,,,,,,,,,,,,,,,,,,,,,,,,,,,,
291.22,0.10257,0.76287,10,,,,,,,,,,,,,,,,,,,,,,,,,,,,,,,,,,,,,
291.82,0.10279,0.87573,10,,,,,,,,,,,,,,,,,,,,,,,,,,,,,,,,,,,,,
292.42,0.10302,0.81681,10,,,,,,,,,,,,,,,,,,,,,,,,,,,,,,,,,,,,,
293.02,0.10319,0.87149,10,,,,,,,,,,,,,,,,,,,,,,,,,,,,,,,,,,,,,
293.62,0.10336,0.81032,10,,,,,,,,,,,,,,,,,,,,,,,,,,,,,,,,,,,,,
294.22,0.10364,0.82328,10,,,,,,,,,,,,,,,,,,,,,,,,,,,,,,,,,,,,,
294.82,0.10398,0.81038,10,,,,,,,,,,,,,,,,,,,,,,,,,,,,,,,,,,,,,
295.42,0.10444,0.83755,10,,,,,,,,,,,,,,,,,,,,,,,,,,,,,,,,,,,,,
296.02,0.10472,0.87934,10,,,,,,,,,,,,,,,,,,,,,,,,,,,,,,,,,,,,,
296.62,0.10478,0.85861,10,,,,,,,,,,,,,,,,,,,,,,,,,,,,,,,,,,,,,
297.22,0.10466,0.90515,10,,,,,,,,,,,,,,,,,,,,,,,,,,,,,,,,,,,,,
297.82,0.10472,0.88619,10,,,,,,,,,,,,,,,,,,,,,,,,,,,,,,,,,,,,,
298.42,0.10461,0.90408,10,,,,,,,,,,,,,,,,,,,,,,,,,,,,,,,,,,,,,
299.02,0.10449,0.90614,10,,,,,,,,,,,,,,,,,,,,,,,,,,,,,,,,,,,,,
299.62,0.10449,0.8295,10,,,,,,,,,,,,,,,,,,,,,,,,,,,,,,,,,,,,,
300.22,0.10449,0.86791,10,,,,,,,,,,,,,,,,,,,,,,,,,,,,,,,,,,,,,
300.82,0.10438,0.89808,10,,,,,,,,,,,,,,,,,,,,,,,,,,,,,,,,,,,,,
301.42,0.10421,0.90405,10,,,,,,,,,,,,,,,,,,,,,,,,,,,,,,,,,,,,,
302.02,0.10415,0.87994,10,,,,,,,,,,,,,,,,,,,,,,,,,,,,,,,,,,,,,
302.62,0.10404,0.8996,10,,,,,,,,,,,,,,,,,,,,,,,,,,,,,,,,,,,,,
303.22,0.10381,0.88189,10,,,,,,,,,,,,,,,,,,,,,,,,,,,,,,,,,,,,,
303.82,0.10359,0.88893,10,,,,,,,,,,,,,,,,,,,,,,,,,,,,,,,,,,,,,
304.42,0.1033,0.87453,10,,,,,,,,,,,,,,,,,,,,,,,,,,,,,,,,,,,,,
305.02,0.10308,0.90462,10,,,,,,,,,,,,,,,,,,,,,,,,,,,,,,,,,,,,,
305.62,0.10274,0.86251,10,,,,,,,,,,,,,,,,,,,,,,,,,,,,,,,,,,,,,
306.22,0.1024,0.87816,10,,,,,,,,,,,,,,,,,,,,,,,,,,,,,,,,,,,,,
306.82,0.102,0.82261,10,,,,,,,,,,,,,,,,,,,,,,,,,,,,,,,,,,,,,
307.42,0.10183,0.85401,10,,,,,,,,,,,,,,,,,,,,,,,,,,,,,,,,,,,,,
308.02,0.10172,0.82342,10,,,,,,,,,,,,,,,,,,,,,,,,,,,,,,,,,,,,,
308.62,0.10166,0.84436,10,,,,,,,,,,,,,,,,,,,,,,,,,,,,,,,,,,,,,
309.22,0.10177,0.82068,10,,,,,,,,,,,,,,,,,,,,,,,,,,,,,,,,,,,,,
309.82,0.10177,0.86596,10,,,,,,,,,,,,,,,,,,,,,,,,,,,,,,,,,,,,,
310.42,0.10183,0.80872,10,,,,,,,,,,,,,,,,,,,,,,,,,,,,,,,,,,,,,
311.02,0.10183,0.83224,10,,,,,,,,,,,,,,,,,,,,,,,,,,,,,,,,,,,,,
311.62,0.10189,0.84369,10,,,,,,,,,,,,,,,,,,,,,,,,,,,,,,,,,,,,,
312.22,0.10189,0.8559,10,,,,,,,,,,,,,,,,,,,,,,,,,,,,,,,,,,,,,
312.82,0.10189,0.83888,10,,,,,,,,,,,,,,,,,,,,,,,,,,,,,,,,,,,,,
313.42,0.10189,0.78911,10,,,,,,,,,,,,,,,,,,,,,,,,,,,,,,,,,,,,,
314.02,0.10189,0.90667,10,,,,,,,,,,,,,,,,,,,,,,,,,,,,,,,,,,,,,
314.62,0.10189,0.85969,10,,,,,,,,,,,,,,,,,,,,,,,,,,,,,,,,,,,,,
315.22,0.10189,0.83675,10,,,,,,,,,,,,,,,,,,,,,,,,,,,,,,,,,,,,,
315.82,0.10189,0.87992,10,,,,,,,,,,,,,,,,,,,,,,,,,,,,,,,,,,,,,
316.42,0.10189,0.83661,10,,,,,,,,,,,,,,,,,,,,,,,,,,,,,,,,,,,,,
317.02,0.102,0.84236,10,,,,,,,,,,,,,,,,,,,,,,,,,,,,,,,,,,,,,
317.62,0.10206,0.77446,10,,,,,,,,,,,,,,,,,,,,,,,,,,,,,,,,,,,,,
318.22,0.10211,0.84079,10,,,,,,,,,,,,,,,,,,,,,,,,,,,,,,,,,,,,,
318.82,0.10223,0.82259,10,,,,,,,,,,,,,,,,,,,,,,,,,,,,,,,,,,,,,
319.42,0.10245,0.89064,10,,,,,,,,,,,,,,,,,,,,,,,,,,,,,,,,,,,,,
320.02,0.10268,0.81336,10,,,,,,,,,,,,,,,,,,,,,,,,,,,,,,,,,,,,,
320.62,0.10302,0.76911,10,,,,,,,,,,,,,,,,,,,,,,,,,,,,,,,,,,,,,
321.22,0.10336,0.81322,10,,,,,,,,,,,,,,,,,,,,,,,,,,,,,,,,,,,,,
321.82,0.10387,0.84767,10,,,,,,,,,,,,,,,,,,,,,,,,,,,,,,,,,,,,,
322.42,0.10444,0.90033,10,,,,,,,,,,,,,,,,,,,,,,,,,,,,,,,,,,,,,
323.02,0.10461,0.83872,10,,,,,,,,,,,,,,,,,,,,,,,,,,,,,,,,,,,,,
323.62,0.10472,0.87316,10,,,,,,,,,,,,,,,,,,,,,,,,,,,,,,,,,,,,,
324.22,0.10472,0.872,10,,,,,,,,,,,,,,,,,,,,,,,,,,,,,,,,,,,,,
324.82,0.10472,0.92686,10,,,,,,,,,,,,,,,,,,,,,,,,,,,,,,,,,,,,,
325.42,0.10466,0.96657,10,,,,,,,,,,,,,,,,,,,,,,,,,,,,,,,,,,,,,
326.02,0.10461,0.87944,10,,,,,,,,,,,,,,,,,,,,,,,,,,,,,,,,,,,,,
326.62,0.10444,0.88197,10,,,,,,,,,,,,,,,,,,,,,,,,,,,,,,,,,,,,,
327.22,0.10438,0.85485,10,,,,,,,,,,,,,,,,,,,,,,,,,,,,,,,,,,,,,
327.82,0.10432,0.93257,10,,,,,,,,,,,,,,,,,,,,,,,,,,,,,,,,,,,,,
328.42,0.10427,0.91572,10,,,,,,,,,,,,,,,,,,,,,,,,,,,,,,,,,,,,,
329.02,0.10415,0.88261,10,,,,,,,,,,,,,,,,,,,,,,,,,,,,,,,,,,,,,
329.62,0.10398,0.87447,10,,,,,,,,,,,,,,,,,,,,,,,,,,,,,,,,,,,,,
330.22,0.10381,0.88859,10,,,,,,,,,,,,,,,,,,,,,,,,,,,,,,,,,,,,,
330.82,0.10353,0.89868,10,,,,,,,,,,,,,,,,,,,,,,,,,,,,,,,,,,,,,
331.42,0.10325,0.92058,10,,,,,,,,,,,,,,,,,,,,,,,,,,,,,,,,,,,,,
332.02,0.10291,0.87664,10,,,,,,,,,,,,,,,,,,,,,,,,,,,,,,,,,,,,,
332.62,0.10257,0.83324,10,,,,,,,,,,,,,,,,,,,,,,,,,,,,,,,,,,,,,
333.22,0.10228,0.81882,10,,,,,,,,,,,,,,,,,,,,,,,,,,,,,,,,,,,,,
333.82,0.10211,0.87133,10,,,,,,,,,,,,,,,,,,,,,,,,,,,,,,,,,,,,,
334.42,0.102,0.86116,10,,,,,,,,,,,,,,,,,,,,,,,,,,,,,,,,,,,,,
335.02,0.10206,0.7882,10,,,,,,,,,,,,,,,,,,,,,,,,,,,,,,,,,,,,,
335.62,0.10206,0.81675,10,,,,,,,,,,,,,,,,,,,,,,,,,,,,,,,,,,,,,
336.22,0.10206,0.8454,10,,,,,,,,,,,,,,,,,,,,,,,,,,,,,,,,,,,,,
336.82,0.10206,0.84859,10,,,,,,,,,,,,,,,,,,,,,,,,,,,,,,,,,,,,,
337.42,0.10217,0.8588,10,,,,,,,,,,,,,,,,,,,,,,,,,,,,,,,,,,,,,
338.02,0.10223,0.79648,10,,,,,,,,,,,,,,,,,,,,,,,,,,,,,,,,,,,,,
338.62,0.10217,0.84084,10,,,,,,,,,,,,,,,,,,,,,,,,,,,,,,,,,,,,,
339.22,0.10228,0.84187,10,,,,,,,,,,,,,,,,,,,,,,,,,,,,,,,,,,,,,
339.82,0.10234,0.84689,10,,,,,,,,,,,,,,,,,,,,,,,,,,,,,,,,,,,,,
340.42,0.10234,0.81983,10,,,,,,,,,,,,,,,,,,,,,,,,,,,,,,,,,,,,,
341.02,0.1024,0.79753,10,,,,,,,,,,,,,,,,,,,,,,,,,,,,,,,,,,,,,
341.62,0.1024,0.8543,10,,,,,,,,,,,,,,,,,,,,,,,,,,,,,,,,,,,,,
342.22,0.10245,0.82773,10,,,,,,,,,,,,,,,,,,,,,,,,,,,,,,,,,,,,,
342.82,0.10262,0.83076,10,,,,,,,,,,,,,,,,,,,,,,,,,,,,,,,,,,,,,
343.42,0.10274,0.84524,10,,,,,,,,,,,,,,,,,,,,,,,,,,,,,,,,,,,,,
344.02,0.10291,0.7559,10,,,,,,,,,,,,,,,,,,,,,,,,,,,,,,,,,,,,,
344.62,0.10313,0.83222,10,,,,,,,,,,,,,,,,,,,,,,,,,,,,,,,,,,,,,
345.22,0.1033,0.82146,10,,,,,,,,,,,,,,,,,,,,,,,,,,,,,,,,,,,,,
345.82,0.10347,0.89811,10,,,,,,,,,,,,,,,,,,,,,,,,,,,,,,,,,,,,,
346.42,0.10376,0.86619,10,,,,,,,,,,,,,,,,,,,,,,,,,,,,,,,,,,,,,
347.02,0.10393,0.81827,10,,,,,,,,,,,,,,,,,,,,,,,,,,,,,,,,,,,,,
347.62,0.10404,0.86175,10,,,,,,,,,,,,,,,,,,,,,,,,,,,,,,,,,,,,,
348.22,0.10415,0.83954,10,,,,,,,,,,,,,,,,,,,,,,,,,,,,,,,,,,,,,
348.82,0.10432,0.89833,10,,,,,,,,,,,,,,,,,,,,,,,,,,,,,,,,,,,,,
349.42,0.10438,0.9175,10,,,,,,,,,,,,,,,,,,,,,,,,,,,,,,,,,,,,,
350.02,0.10427,0.87914,10,,,,,,,,,,,,,,,,,,,,,,,,,,,,,,,,,,,,,
350.62,0.10427,0.86649,10,,,,,,,,,,,,,,,,,,,,,,,,,,,,,,,,,,,,,
351.22,0.10421,0.91277,10,,,,,,,,,,,,,,,,,,,,,,,,,,,,,,,,,,,,,
351.82,0.10421,0.87206,10,,,,,,,,,,,,,,,,,,,,,,,,,,,,,,,,,,,,,
352.42,0.10415,0.88575,10,,,,,,,,,,,,,,,,,,,,,,,,,,,,,,,,,,,,,
353.02,0.1041,0.84219,10,,,,,,,,,,,,,,,,,,,,,,,,,,,,,,,,,,,,,
353.62,0.10404,0.86995,10,,,,,,,,,,,,,,,,,,,,,,,,,,,,,,,,,,,,,
354.22,0.10398,0.85769,10,,,,,,,,,,,,,,,,,,,,,,,,,,,,,,,,,,,,,
354.82,0.10404,0.88455,10,,,,,,,,,,,,,,,,,,,,,,,,,,,,,,,,,,,,,
355.42,0.10393,0.90834,10,,,,,,,,,,,,,,,,,,,,,,,,,,,,,,,,,,,,,
356.02,0.10381,0.90882,10,,,,,,,,,,,,,,,,,,,,,,,,,,,,,,,,,,,,,
356.62,0.1037,0.89116,10,,,,,,,,,,,,,,,,,,,,,,,,,,,,,,,,,,,,,
357.22,0.10347,0.85201,10,,,,,,,,,,,,,,,,,,,,,,,,,,,,,,,,,,,,,
357.82,0.10319,0.91408,10,,,,,,,,,,,,,,,,,,,,,,,,,,,,,,,,,,,,,
358.42,0.10274,0.87478,10,,,,,,,,,,,,,,,,,,,,,,,,,,,,,,,,,,,,,
359.02,0.10234,0.81105,10,,,,,,,,,,,,,,,,,,,,,,,,,,,,,,,,,,,,,
359.62,0.10206,0.87853,10,,,,,,,,,,,,,,,,,,,,,,,,,,,,,,,,,,,,,
360.22,0.10194,0.85046,10,,,,,,,,,,,,,,,,,,,,,,,,,,,,,,,,,,,,,
360.82,0.10183,0.85459,10,,,,,,,,,,,,,,,,,,,,,,,,,,,,,,,,,,,,,
361.42,0.1016,0.879,10,,,,,,,,,,,,,,,,,,,,,,,,,,,,,,,,,,,,,
362.02,0.10143,0.84143,10,,,,,,,,,,,,,,,,,,,,,,,,,,,,,,,,,,,,,
362.62,0.10132,0.87312,10,,,,,,,,,,,,,,,,,,,,,,,,,,,,,,,,,,,,,
363.22,0.10109,0.85595,10,,,,,,,,,,,,,,,,,,,,,,,,,,,,,,,,,,,,,
363.82,0.10098,0.85594,10,,,,,,,,,,,,,,,,,,,,,,,,,,,,,,,,,,,,,
364.42,0.10092,0.81973,10,,,,,,,,,,,,,,,,,,,,,,,,,,,,,,,,,,,,,
365.02,0.10104,0.82517,10,,,,,,,,,,,,,,,,,,,,,,,,,,,,,,,,,,,,,
365.62,0.10109,0.79171,10,,,,,,,,,,,,,,,,,,,,,,,,,,,,,,,,,,,,,
366.22,0.10109,0.81781,10,,,,,,,,,,,,,,,,,,,,,,,,,,,,,,,,,,,,,
366.82,0.10115,0.84423,10,,,,,,,,,,,,,,,,,,,,,,,,,,,,,,,,,,,,,
367.42,0.10121,0.83788,10,,,,,,,,,,,,,,,,,,,,,,,,,,,,,,,,,,,,,
368.02,0.10121,0.83956,10,,,,,,,,,,,,,,,,,,,,,,,,,,,,,,,,,,,,,
368.62,0.10126,0.79567,10,,,,,,,,,,,,,,,,,,,,,,,,,,,,,,,,,,,,,
369.22,0.10132,0.82528,10,,,,,,,,,,,,,,,,,,,,,,,,,,,,,,,,,,,,,
369.82,0.10138,0.84657,10,,,,,,,,,,,,,,,,,,,,,,,,,,,,,,,,,,,,,
370.42,0.10143,0.76336,10,,,,,,,,,,,,,,,,,,,,,,,,,,,,,,,,,,,,,
371.02,0.10149,0.81951,10,,,,,,,,,,,,,,,,,,,,,,,,,,,,,,,,,,,,,
371.62,0.10132,1.03106,10,,,,,,,,,,,,,,,,,,,,,,,,,,,,,,,,,,,,,
372.22,0.10115,1.00881,10,,,,,,,,,,,,,,,,,,,,,,,,,,,,,,,,,,,,,
372.82,0.10019,0.95903,10,,,,,,,,,,,,,,,,,,,,,,,,,,,,,,,,,,,,,
373.42,0.09316,0.76934,10,,,,,,,,,,,,,,,,,,,,,,,,,,,,,,,,,,,,,
374.02,0.09231,0.72283,10,,,,,,,,,,,,,,,,,,,,,,,,,,,,,,,,,,,,,
374.62,0.09254,0.73942,10,,,,,,,,,,,,,,,,,,,,,,,,,,,,,,,,,,,,,
375.22,0.09282,0.70258,10,,,,,,,,,,,,,,,,,,,,,,,,,,,,,,,,,,,,,
375.82,0.09344,0.67962,10,,,,,,,,,,,,,,,,,,,,,,,,,,,,,,,,,,,,,
376.42,0.09548,0.76102,10,,,,,,,,,,,,,,,,,,,,,,,,,,,,,,,,,,,,,
377.02,0.0999,0.88172,10,,,,,,,,,,,,,,,,,,,,,,,,,,,,,,,,,,,,,
377.62,0.10183,0.98328,10,,,,,,,,,,,,,,,,,,,,,,,,,,,,,,,,,,,,,
378.22,0.10166,0.97692,10,,,,,,,,,,,,,,,,,,,,,,,,,,,,,,,,,,,,,
378.82,0.10155,0.99213,10,,,,,,,,,,,,,,,,,,,,,,,,,,,,,,,,,,,,,
379.42,0.10138,0.96125,10,,,,,,,,,,,,,,,,,,,,,,,,,,,,,,,,,,,,,
380.02,0.10047,0.97466,10,,,,,,,,,,,,,,,,,,,,,,,,,,,,,,,,,,,,,
380.62,0.09832,0.92941,10,,,,,,,,,,,,,,,,,,,,,,,,,,,,,,,,,,,,,
381.22,0.09662,0.83923,10,,,,,,,,,,,,,,,,,,,,,,,,,,,,,,,,,,,,,
381.722,0.53159,7.73922,10,,,,,,,,,,,,,,,,,,,,,,,,,,,,,,,,,,,,,
382.322,5.62955,808.3371,10,,,,,,,,,,,,,,,,,,,,,,,,,,,,,,,,,,,,,
382.922,10.6297,64.42771,10,,,,,,,,,,,,,,,,,,,,,,,,,,,,,,,,,,,,,
383.522,15.62957,37.32758,10,,,,,,,,,,,,,,,,,,,,,,,,,,,,,,,,,,,,,
384.122,20.6295,29.21191,10,,,,,,,,,,,,,,,,,,,,,,,,,,,,,,,,,,,,,
384.722,25.62954,23.11591,10,,,,,,,,,,,,,,,,,,,,,,,,,,,,,,,,,,,,,
385.322,30.62947,18.73121,10,,,,,,,,,,,,,,,,,,,,,,,,,,,,,,,,,,,,,
385.922,35.62956,7.98249,10,,,,,,,,,,,,,,,,,,,,,,,,,,,,,,,,,,,,,
386.522,40.62954,3.02174,10,,,,,,,,,,,,,,,,,,,,,,,,,,,,,,,,,,,,,
387.122,45.62952,-2.5384,10,,,,,,,,,,,,,,,,,,,,,,,,,,,,,,,,,,,,,
387.722,50.62951,-5.0476,10,,,,,,,,,,,,,,,,,,,,,,,,,,,,,,,,,,,,,
388.322,55.62955,-5.62606,10,,,,,,,,,,,,,,,,,,,,,,,,,,,,,,,,,,,,,
388.922,60.62953,-5.80453,10,,,,,,,,,,,,,,,,,,,,,,,,,,,,,,,,,,,,,
389.522,65.62957,-5.81835,10,,,,,,,,,,,,,,,,,,,,,,,,,,,,,,,,,,,,,
390.122,70.6295,-5.81397,10,,,,,,,,,,,,,,,,,,,,,,,,,,,,,,,,,,,,,
390.722,75.62954,-5.82655,10,,,,,,,,,,,,,,,,,,,,,,,,,,,,,,,,,,,,,
391.322,80.62958,-5.79754,10,,,,,,,,,,,,,,,,,,,,,,,,,,,,,,,,,,,,,
391.574,82.72947,-5.79146,10,,,,,,,,,,,,,,,,,,,,,,,,,,,,,,,,,,,,,