File: combined_ligament_solver/data/processed/Data Sheet 3_S160302_MCL.csv
Specimen properties : Length,114,mm,Unnamed: 3,Unnamed: 4,Unnamed: 5,Unnamed: 6,Unnamed: 7,Unnamed: 8,Unnamed: 9,Unnamed: 10,Unnamed: 11,Stress-Strain,Unnamed: 13,Unnamed: 14,Unnamed: 15,Unnamed: 16,Unnamed: 17,Unnamed: 18,Unnamed: 19,Unnamed: 20,Unnamed: 21,Unnamed: 22,Unnamed: 23,Unnamed: 24,Unnamed: 25,Unnamed: 26,Unnamed: 27,Linear,Unnamed: 29,Unnamed: 30,Unnamed: 31,Unnamed: 32,Unnamed: 33,Modulus,Unnamed: 35,Failure,Unnamed: 37,Unnamed: 38,Unnamed: 39,Unnamed: 40
Cross Section Average,41.175,mm2,,,,,,,,,,Polynomial Coefficients,,,,,,,,,,,,,,,,Force,,Stress,Extension,Strain,,Secant,Tangent,Load,Stress,Extension,Strain,Stiffness
Time,Extension,Load,Total cycle count,,,Extension,Load,Strain,Stress,E-tan,,X6,-1683699474.5343356,,,,,,,,,Strain,Stress,E-tan,,,,(N),,(MPa),(mm),(%),,(MPa),(MPa),(N),(MPa),(mm),(%),(N/mm)
(s),(mm),(N),,,,(mm),(N),(mm/mm),(MPa),(MPa),,X5,254344157.27365533,,,,,,,,,(mm/mm),(MPa),(MPa),,,,235.5664050273938,,5.72110273290574,5.7,5,,114.42205465811479,181.67945821611104,280.80557,6.7882319368548885,7.24993,6.359587719298246,41.327439478490135
0.6,0.17255,2.40635,0,,,5.65647,177.94556,0.041666929824561404,4.2901139040680025,158.7188566834611,,,,,,,,,,,,0.006,0.17221236031018733,42.97208657837347,,,,,,,,,,,,,,,,
1.3,0.28923,3.82288,0,,,11.4899,299.29105,,,,,,,,,,,,,,,0.013,0.659875906585505,88.3684465773021,,,,,,,,,,,,,,,,
2,0.4059,5.32824,0,,,17.32311,68.33524,,,,,,,,,,,,,,,0.02,1.3988900010013339,115.1868084191766,,,,,,,,,,,,,,,,
2.7,0.52258,6.83967,0,,,23.15638,32.6445,,,,,,,,,,,,,,,0.027,2.2475570220905805,124.33016626975657,,,,,,,,,,,,,,,,
3.4,0.6392,8.55275,0,,,,,,,,,,,,,,,,,,,0.034,3.1482391352055448,133.22557625395012,,,,,,,,,,,,,,,,
4.1,0.75582,10.20256,0,,,,,,,,,,,,,,,,,,,0.041,4.161528667474734,155.4496417665144,,,,,,,,,,,,,,,,
4.8,0.8725,11.93941,0,,,,,,,,,,,,,,,,,,,0.048,5.357796879934407,180.3539987827099,,,,,,,,,,,,,,,,
5.5,0.98917,13.82835,0,,,,,,,,,,,,,,,,,,,0.055,6.56612113683496,152.69080116897877,,,,,,,,,,,,,,,,
6.2,1.10585,15.79596,0,,,,,,,,,,,,,,,,,,,0.062,6.980590472121964,-47.7617940063268,,,,,,,,,,,,,,,,
6.9,1.22241,18.04268,0,,,,,,,,,,,,,,,,,,,0.069,4.623989553092108,-626.574141162249,,,,,,,,,,,,,,,,
7.6,1.33903,20.25663,0,,,,,,,,,,,,,,,,,,,0.076,-4.331138958776251,-1895.0396208947502,,,,,,,,,,,,,,,,
8.3,1.45577,22.57794,0,,,,,,,,,,,,,,,,,,,0.083,-26.384053649817687,-4290.5491546658,,,,,,,,,,,,,,,,
9,1.57256,25.05043,0,,,,,,,,,,,,,,,,,,,0.09,-71.66999519899899,-8396.965719492577,,,,,,,,,,,,,,,,
9.7,1.68923,27.45718,0,,,,,,,,,,,,,,,,,,,0.097,-155.06698882556555,-14964.99886263696,,,,,,,,,,,,,,,,
10.4,1.80591,29.96101,0,,,,,,,,,,,,,,,,,,,0.104,-297.44526833951,-24932.579216295755,,,,,,,,,,,,,,,,
11.1,1.92259,32.59867,0,,,,,,,,,,,,,,,,,,,0.111,-527.0593217948698,-39445.23301228806,,,,,,,,,,,,,,,,
11.8,2.03921,35.33892,0,,,,,,,,,,,,,,,,,,,0.118,-881.0825587458438,-59876.45659674557,,,,,,,,,,,,,,,,
12.5,2.156,37.88249,0,,,,,,,,,,,,,,,,,,,0.125,-1407.2845991057457,-87848.0909448032,,,,,,,,,,,,,,,,
13.098,2.2555,40.01437,0.5,,,,,,,,,,,,,,,,,,,0.132,-2165.851183608765,-125250.69617528071,,,,,,,,,,,,,,,,
13.798,2.13843,34.50897,0.5,,,,,,,,,,,,,,,,,,,0.139,-3231.3467058745805,-174263.92606539986,,,,,,,,,,,,,,,,
14.498,2.02187,29.84987,0.5,,,,,,,,,,,,,,,,,,,0.146,-4694.819366075751,-237376.90256541804,,,,,,,,,,,,,,,,
15.198,1.90508,25.72945,0.5,,,,,,,,,,,,,,,,,,,0.153,,,,,,,,,,,,,,,,,,
15.898,1.78846,22.08539,0.5,,,,,,,,,,,,,,,,,,,0.16,,,,,,,,,,,,,,,,,,
16.598,1.67184,18.81991,0.5,,,,,,,,,,,,,,,,,,,0.167,,,,,,,,,,,,,,,,,,
17.298,1.55522,15.92296,0.5,,,,,,,,,,,,,,,,,,,0.174,,,,,,,,,,,,,,,,,,
17.998,1.43848,13.25821,0.5,,,,,,,,,,,,,,,,,,,0.181,,,,,,,,,,,,,,,,,,
18.698,1.32192,10.78382,0.5,,,,,,,,,,,,,,,,,,,0.188,,,,,,,,,,,,,,,,,,
19.398,1.2053,8.62485,0.5,,,,,,,,,,,,,,,,,,,0.195,,,,,,,,,,,,,,,,,,
20.098,1.08857,6.62633,0.5,,,,,,,,,,,,,,,,,,,,,,,,,,,,,,,,,,,,,
20.798,0.97189,4.92206,0.5,,,,,,,,,,,,,,,,,,,,,,,,,,,,,,,,,,,,,
21.498,0.85527,3.43249,0.5,,,,,,,,,,,,,,,,,,,,,,,,,,,,,,,,,,,,,
22.198,0.73859,2.15234,0.5,,,,,,,,,,,,,,,,,,,,,,,,,,,,,,,,,,,,,
22.882,0.62464,0.99933,1,,,,,,,,,,,,,,,,,,,,,,,,,,,,,,,,,,,,,
23.386,0.70816,2.15944,1,,,,,,,,,,,,,,,,,,,,,,,,,,,,,,,,,,,,,
24.086,0.82484,3.89222,1,,,,,,,,,,,,,,,,,,,,,,,,,,,,,,,,,,,,,
24.786,0.94146,5.55831,1,,,,,,,,,,,,,,,,,,,,,,,,,,,,,,,,,,,,,
25.486,1.05802,7.45112,1,,,,,,,,,,,,,,,,,,,,,,,,,,,,,,,,,,,,,
26.186,1.17476,9.41694,1,,,,,,,,,,,,,,,,,,,,,,,,,,,,,,,,,,,,,
26.886,1.29155,11.63932,1,,,,,,,,,,,,,,,,,,,,,,,,,,,,,,,,,,,,,
27.586,1.40822,14.13194,1,,,,,,,,,,,,,,,,,,,,,,,,,,,,,,,,,,,,,
28.286,1.52501,16.75491,1,,,,,,,,,,,,,,,,,,,,,,,,,,,,,,,,,,,,,
28.986,1.64158,19.65101,1,,,,,,,,,,,,,,,,,,,,,,,,,,,,,,,,,,,,,
29.686,1.75825,22.69127,1,,,,,,,,,,,,,,,,,,,,,,,,,,,,,,,,,,,,,
30.386,1.87493,25.96906,1,,,,,,,,,,,,,,,,,,,,,,,,,,,,,,,,,,,,,
31.086,1.99161,29.19111,1,,,,,,,,,,,,,,,,,,,,,,,,,,,,,,,,,,,,,
31.786,2.10817,32.64902,1,,,,,,,,,,,,,,,,,,,,,,,,,,,,,,,,,,,,,
32.486,2.22485,36.05895,1,,,,,,,,,,,,,,,,,,,,,,,,,,,,,,,,,,,,,
33.186,2.34141,39.52617,1,,,,,,,,,,,,,,,,,,,,,,,,,,,,,,,,,,,,,
33.772,2.27233,36.12811,1.5,,,,,,,,,,,,,,,,,,,,,,,,,,,,,,,,,,,,,
34.472,2.15566,31.34361,1.5,,,,,,,,,,,,,,,,,,,,,,,,,,,,,,,,,,,,,
35.172,2.03898,27.09729,1.5,,,,,,,,,,,,,,,,,,,,,,,,,,,,,,,,,,,,,
35.872,1.92225,23.41152,1.5,,,,,,,,,,,,,,,,,,,,,,,,,,,,,,,,,,,,,
36.572,1.80557,19.98962,1.5,,,,,,,,,,,,,,,,,,,,,,,,,,,,,,,,,,,,,
37.272,1.68872,16.93009,1.5,,,,,,,,,,,,,,,,,,,,,,,,,,,,,,,,,,,,,
37.972,1.5721,14.17776,1.5,,,,,,,,,,,,,,,,,,,,,,,,,,,,,,,,,,,,,
38.672,1.45543,11.62716,1.5,,,,,,,,,,,,,,,,,,,,,,,,,,,,,,,,,,,,,
39.372,1.33875,9.39114,1.5,,,,,,,,,,,,,,,,,,,,,,,,,,,,,,,,,,,,,
40.072,1.22207,7.32832,1.5,,,,,,,,,,,,,,,,,,,,,,,,,,,,,,,,,,,,,
40.772,1.10545,5.51263,1.5,,,,,,,,,,,,,,,,,,,,,,,,,,,,,,,,,,,,,
41.472,0.98889,3.93714,1.5,,,,,,,,,,,,,,,,,,,,,,,,,,,,,,,,,,,,,
42.172,0.87227,2.63318,1.5,,,,,,,,,,,,,,,,,,,,,,,,,,,,,,,,,,,,,
42.872,0.75565,1.37515,1.5,,,,,,,,,,,,,,,,,,,,,,,,,,,,,,,,,,,,,
43.288,0.75338,1.39798,2,,,,,,,,,,,,,,,,,,,,,,,,,,,,,,,,,,,,,
43.988,0.87051,3.18499,2,,,,,,,,,,,,,,,,,,,,,,,,,,,,,,,,,,,,,
44.688,0.98713,4.81945,2,,,,,,,,,,,,,,,,,,,,,,,,,,,,,,,,,,,,,
45.388,1.10381,6.60184,2,,,,,,,,,,,,,,,,,,,,,,,,,,,,,,,,,,,,,
46.088,1.22043,8.53283,2,,,,,,,,,,,,,,,,,,,,,,,,,,,,,,,,,,,,,
46.788,1.33705,10.63869,2,,,,,,,,,,,,,,,,,,,,,,,,,,,,,,,,,,,,,
47.488,1.45378,13.07536,2,,,,,,,,,,,,,,,,,,,,,,,,,,,,,,,,,,,,,
48.188,1.57052,15.77535,2,,,,,,,,,,,,,,,,,,,,,,,,,,,,,,,,,,,,,
48.888,1.68719,18.57797,2,,,,,,,,,,,,,,,,,,,,,,,,,,,,,,,,,,,,,
49.588,1.80387,21.5605,2,,,,,,,,,,,,,,,,,,,,,,,,,,,,,,,,,,,,,
50.288,1.92055,24.76858,2,,,,,,,,,,,,,,,,,,,,,,,,,,,,,,,,,,,,,
50.988,2.03728,28.13106,2,,,,,,,,,,,,,,,,,,,,,,,,,,,,,,,,,,,,,
51.688,2.15401,31.6162,2,,,,,,,,,,,,,,,,,,,,,,,,,,,,,,,,,,,,,
52.388,2.27063,35.33656,2,,,,,,,,,,,,,,,,,,,,,,,,,,,,,,,,,,,,,
53.088,2.38725,39.00437,2,,,,,,,,,,,,,,,,,,,,,,,,,,,,,,,,,,,,,
53.66,2.34895,36.95245,2.5,,,,,,,,,,,,,,,,,,,,,,,,,,,,,,,,,,,,,
54.36,2.23233,32.07257,2.5,,,,,,,,,,,,,,,,,,,,,,,,,,,,,,,,,,,,,
55.06,2.11565,27.91043,2.5,,,,,,,,,,,,,,,,,,,,,,,,,,,,,,,,,,,,,
55.76,1.99886,24.02468,2.5,,,,,,,,,,,,,,,,,,,,,,,,,,,,,,,,,,,,,
56.46,1.88218,20.6163,2.5,,,,,,,,,,,,,,,,,,,,,,,,,,,,,,,,,,,,,
57.16,1.76556,17.43627,2.5,,,,,,,,,,,,,,,,,,,,,,,,,,,,,,,,,,,,,
57.86,1.64894,14.64224,2.5,,,,,,,,,,,,,,,,,,,,,,,,,,,,,,,,,,,,,
58.56,1.53227,12.05165,2.5,,,,,,,,,,,,,,,,,,,,,,,,,,,,,,,,,,,,,
59.26,1.41559,9.74321,2.5,,,,,,,,,,,,,,,,,,,,,,,,,,,,,,,,,,,,,
59.96,1.29891,7.6875,2.5,,,,,,,,,,,,,,,,,,,,,,,,,,,,,,,,,,,,,
60.66,1.18224,5.7976,2.5,,,,,,,,,,,,,,,,,,,,,,,,,,,,,,,,,,,,,
61.36,1.0655,4.23494,2.5,,,,,,,,,,,,,,,,,,,,,,,,,,,,,,,,,,,,,
62.06,0.94883,2.79039,2.5,,,,,,,,,,,,,,,,,,,,,,,,,,,,,,,,,,,,,
62.76,0.83209,1.53838,2.5,,,,,,,,,,,,,,,,,,,,,,,,,,,,,,,,,,,,,
63.18,0.79146,1.01714,3,,,,,,,,,,,,,,,,,,,,,,,,,,,,,,,,,,,,,
63.88,0.91324,2.97912,3,,,,,,,,,,,,,,,,,,,,,,,,,,,,,,,,,,,,,
64.58,1.02992,4.65546,3,,,,,,,,,,,,,,,,,,,,,,,,,,,,,,,,,,,,,
65.28,1.14648,6.3734,3,,,,,,,,,,,,,,,,,,,,,,,,,,,,,,,,,,,,,
65.98,1.2631,8.27498,3,,,,,,,,,,,,,,,,,,,,,,,,,,,,,,,,,,,,,
66.68,1.37995,10.43604,3,,,,,,,,,,,,,,,,,,,,,,,,,,,,,,,,,,,,,
67.38,1.49651,12.77334,3,,,,,,,,,,,,,,,,,,,,,,,,,,,,,,,,,,,,,
68.08,1.61319,15.44915,3,,,,,,,,,,,,,,,,,,,,,,,,,,,,,,,,,,,,,
68.78,1.72981,18.26049,3,,,,,,,,,,,,,,,,,,,,,,,,,,,,,,,,,,,,,
69.48,1.84643,21.22964,3,,,,,,,,,,,,,,,,,,,,,,,,,,,,,,,,,,,,,
70.18,1.9631,24.46722,3,,,,,,,,,,,,,,,,,,,,,,,,,,,,,,,,,,,,,
70.88,2.07978,27.88786,3,,,,,,,,,,,,,,,,,,,,,,,,,,,,,,,,,,,,,
71.58,2.19657,31.45475,3,,,,,,,,,,,,,,,,,,,,,,,,,,,,,,,,,,,,,
72.28,2.31325,35.23426,3,,,,,,,,,,,,,,,,,,,,,,,,,,,,,,,,,,,,,
72.98,2.42987,38.97908,3,,,,,,,,,,,,,,,,,,,,,,,,,,,,,,,,,,,,,
73.56,2.39298,37.03302,3.5,,,,,,,,,,,,,,,,,,,,,,,,,,,,,,,,,,,,,
74.26,2.2763,32.23975,3.5,,,,,,,,,,,,,,,,,,,,,,,,,,,,,,,,,,,,,
74.96,2.15957,27.97262,3.5,,,,,,,,,,,,,,,,,,,,,,,,,,,,,,,,,,,,,
75.66,2.04289,24.1552,3.5,,,,,,,,,,,,,,,,,,,,,,,,,,,,,,,,,,,,,
76.36,1.92621,20.71472,3.5,,,,,,,,,,,,,,,,,,,,,,,,,,,,,,,,,,,,,
77.06,1.80959,17.52473,3.5,,,,,,,,,,,,,,,,,,,,,,,,,,,,,,,,,,,,,
77.76,1.69292,14.66632,3.5,,,,,,,,,,,,,,,,,,,,,,,,,,,,,,,,,,,,,
78.46,1.57613,12.17532,3.5,,,,,,,,,,,,,,,,,,,,,,,,,,,,,,,,,,,,,
79.16,1.45945,9.74114,3.5,,,,,,,,,,,,,,,,,,,,,,,,,,,,,,,,,,,,,
79.86,1.34272,7.69697,3.5,,,,,,,,,,,,,,,,,,,,,,,,,,,,,,,,,,,,,
80.56,1.22604,5.85889,3.5,,,,,,,,,,,,,,,,,,,,,,,,,,,,,,,,,,,,,
81.26,1.10942,4.27253,3.5,,,,,,,,,,,,,,,,,,,,,,,,,,,,,,,,,,,,,
81.96,0.99286,2.82543,3.5,,,,,,,,,,,,,,,,,,,,,,,,,,,,,,,,,,,,,
82.66,0.87624,1.5892,3.5,,,,,,,,,,,,,,,,,,,,,,,,,,,,,,,,,,,,,
83.094,0.83294,1.05276,4,,,,,,,,,,,,,,,,,,,,,,,,,,,,,,,,,,,,,
83.794,0.95489,2.93323,4,,,,,,,,,,,,,,,,,,,,,,,,,,,,,,,,,,,,,
84.494,1.07157,4.63746,4,,,,,,,,,,,,,,,,,,,,,,,,,,,,,,,,,,,,,
85.194,1.18824,6.36522,4,,,,,,,,,,,,,,,,,,,,,,,,,,,,,,,,,,,,,
85.894,1.30486,8.2606,4,,,,,,,,,,,,,,,,,,,,,,,,,,,,,,,,,,,,,
86.594,1.4216,10.42053,4,,,,,,,,,,,,,,,,,,,,,,,,,,,,,,,,,,,,,
87.294,1.53827,12.79692,4,,,,,,,,,,,,,,,,,,,,,,,,,,,,,,,,,,,,,
87.994,1.65478,15.46171,4,,,,,,,,,,,,,,,,,,,,,,,,,,,,,,,,,,,,,
88.694,1.77146,18.28712,4,,,,,,,,,,,,,,,,,,,,,,,,,,,,,,,,,,,,,
89.394,1.88813,21.31722,4,,,,,,,,,,,,,,,,,,,,,,,,,,,,,,,,,,,,,
90.094,2.00481,24.541,4,,,,,,,,,,,,,,,,,,,,,,,,,,,,,,,,,,,,,
90.794,2.12154,27.9523,4,,,,,,,,,,,,,,,,,,,,,,,,,,,,,,,,,,,,,
91.494,2.23816,31.55084,4,,,,,,,,,,,,,,,,,,,,,,,,,,,,,,,,,,,,,
92.194,2.35478,35.36406,4,,,,,,,,,,,,,,,,,,,,,,,,,,,,,,,,,,,,,
92.894,2.4714,39.22895,4,,,,,,,,,,,,,,,,,,,,,,,,,,,,,,,,,,,,,
93.432,2.4276,37.06752,4.5,,,,,,,,,,,,,,,,,,,,,,,,,,,,,,,,,,,,,
94.132,2.31087,32.22319,4.5,,,,,,,,,,,,,,,,,,,,,,,,,,,,,,,,,,,,,
94.832,2.19413,28.04297,4.5,,,,,,,,,,,,,,,,,,,,,,,,,,,,,,,,,,,,,
95.532,2.07746,24.15522,4.5,,,,,,,,,,,,,,,,,,,,,,,,,,,,,,,,,,,,,
96.232,1.96078,20.70374,4.5,,,,,,,,,,,,,,,,,,,,,,,,,,,,,,,,,,,,,
96.932,1.84416,17.58579,4.5,,,,,,,,,,,,,,,,,,,,,,,,,,,,,,,,,,,,,
97.632,1.72754,14.73096,4.5,,,,,,,,,,,,,,,,,,,,,,,,,,,,,,,,,,,,,
98.332,1.61081,12.12592,4.5,,,,,,,,,,,,,,,,,,,,,,,,,,,,,,,,,,,,,
99.032,1.49419,9.83348,4.5,,,,,,,,,,,,,,,,,,,,,,,,,,,,,,,,,,,,,
99.732,1.37762,7.79653,4.5,,,,,,,,,,,,,,,,,,,,,,,,,,,,,,,,,,,,,
100.432,1.26095,5.88909,4.5,,,,,,,,,,,,,,,,,,,,,,,,,,,,,,,,,,,,,
101.132,1.14427,4.3008,4.5,,,,,,,,,,,,,,,,,,,,,,,,,,,,,,,,,,,,,
101.832,1.02754,2.79066,4.5,,,,,,,,,,,,,,,,,,,,,,,,,,,,,,,,,,,,,
102.532,0.91086,1.52528,4.5,,,,,,,,,,,,,,,,,,,,,,,,,,,,,,,,,,,,,
102.948,0.87068,1.07135,5,,,,,,,,,,,,,,,,,,,,,,,,,,,,,,,,,,,,,
103.648,0.9924,2.97647,5,,,,,,,,,,,,,,,,,,,,,,,,,,,,,,,,,,,,,
104.348,1.10908,4.68447,5,,,,,,,,,,,,,,,,,,,,,,,,,,,,,,,,,,,,,
105.048,1.22576,6.46838,5,,,,,,,,,,,,,,,,,,,,,,,,,,,,,,,,,,,,,
105.748,1.34249,8.37533,5,,,,,,,,,,,,,,,,,,,,,,,,,,,,,,,,,,,,,
106.448,1.45917,10.45183,5,,,,,,,,,,,,,,,,,,,,,,,,,,,,,,,,,,,,,
107.148,1.57584,12.92106,5,,,,,,,,,,,,,,,,,,,,,,,,,,,,,,,,,,,,,
107.848,1.69252,15.53991,5,,,,,,,,,,,,,,,,,,,,,,,,,,,,,,,,,,,,,
108.548,1.80925,18.41238,5,,,,,,,,,,,,,,,,,,,,,,,,,,,,,,,,,,,,,
109.248,1.92599,21.43181,5,,,,,,,,,,,,,,,,,,,,,,,,,,,,,,,,,,,,,
109.948,2.04255,24.68708,5,,,,,,,,,,,,,,,,,,,,,,,,,,,,,,,,,,,,,
110.648,2.15923,28.1407,5,,,,,,,,,,,,,,,,,,,,,,,,,,,,,,,,,,,,,
111.348,2.27585,31.76506,5,,,,,,,,,,,,,,,,,,,,,,,,,,,,,,,,,,,,,
112.048,2.39252,35.58535,5,,,,,,,,,,,,,,,,,,,,,,,,,,,,,,,,,,,,,
112.748,2.5092,39.64191,5,,,,,,,,,,,,,,,,,,,,,,,,,,,,,,,,,,,,,
113.31,2.43599,36.33126,5.5,,,,,,,,,,,,,,,,,,,,,,,,,,,,,,,,,,,,,
114.01,2.31931,31.63451,5.5,,,,,,,,,,,,,,,,,,,,,,,,,,,,,,,,,,,,,
114.71,2.20258,27.44563,5.5,,,,,,,,,,,,,,,,,,,,,,,,,,,,,,,,,,,,,
115.41,2.08579,23.66558,5.5,,,,,,,,,,,,,,,,,,,,,,,,,,,,,,,,,,,,,
116.11,1.96911,20.2836,5.5,,,,,,,,,,,,,,,,,,,,,,,,,,,,,,,,,,,,,
116.81,1.85249,17.20951,5.5,,,,,,,,,,,,,,,,,,,,,,,,,,,,,,,,,,,,,
117.51,1.73587,14.41241,5.5,,,,,,,,,,,,,,,,,,,,,,,,,,,,,,,,,,,,,
118.21,1.61914,11.79656,5.5,,,,,,,,,,,,,,,,,,,,,,,,,,,,,,,,,,,,,
118.91,1.50246,9.53502,5.5,,,,,,,,,,,,,,,,,,,,,,,,,,,,,,,,,,,,,
119.61,1.3859,7.42744,5.5,,,,,,,,,,,,,,,,,,,,,,,,,,,,,,,,,,,,,
120.31,1.26922,5.58677,5.5,,,,,,,,,,,,,,,,,,,,,,,,,,,,,,,,,,,,,
121.01,1.1526,4.11605,5.5,,,,,,,,,,,,,,,,,,,,,,,,,,,,,,,,,,,,,
121.71,1.03592,2.67026,5.5,,,,,,,,,,,,,,,,,,,,,,,,,,,,,,,,,,,,,
122.41,0.91919,1.41809,5.5,,,,,,,,,,,,,,,,,,,,,,,,,,,,,,,,,,,,,
122.84,0.91483,1.40261,6,,,,,,,,,,,,,,,,,,,,,,,,,,,,,,,,,,,,,
123.54,1.0319,3.22269,6,,,,,,,,,,,,,,,,,,,,,,,,,,,,,,,,,,,,,
124.24,1.14852,4.96891,6,,,,,,,,,,,,,,,,,,,,,,,,,,,,,,,,,,,,,
124.94,1.26514,6.70001,6,,,,,,,,,,,,,,,,,,,,,,,,,,,,,,,,,,,,,
125.64,1.38182,8.58165,6,,,,,,,,,,,,,,,,,,,,,,,,,,,,,,,,,,,,,
126.34,1.49849,10.75364,6,,,,,,,,,,,,,,,,,,,,,,,,,,,,,,,,,,,,,
127.04,1.61517,13.26977,6,,,,,,,,,,,,,,,,,,,,,,,,,,,,,,,,,,,,,
127.74,1.73179,15.92904,6,,,,,,,,,,,,,,,,,,,,,,,,,,,,,,,,,,,,,
128.44,1.84852,18.77592,6,,,,,,,,,,,,,,,,,,,,,,,,,,,,,,,,,,,,,
129.14,1.96509,21.84426,6,,,,,,,,,,,,,,,,,,,,,,,,,,,,,,,,,,,,,
129.84,2.08176,25.1402,6,,,,,,,,,,,,,,,,,,,,,,,,,,,,,,,,,,,,,
130.54,2.19855,28.58755,6,,,,,,,,,,,,,,,,,,,,,,,,,,,,,,,,,,,,,
131.24,2.31523,32.30784,6,,,,,,,,,,,,,,,,,,,,,,,,,,,,,,,,,,,,,
131.94,2.43191,36.16924,6,,,,,,,,,,,,,,,,,,,,,,,,,,,,,,,,,,,,,
132.608,2.5432,40.00441,6.5,,,,,,,,,,,,,,,,,,,,,,,,,,,,,,,,,,,,,
133.21,2.44324,35.55101,6.5,,,,,,,,,,,,,,,,,,,,,,,,,,,,,,,,,,,,,
133.91,2.32662,30.8746,6.5,,,,,,,,,,,,,,,,,,,,,,,,,,,,,,,,,,,,,
134.61,2.20994,26.76942,6.5,,,,,,,,,,,,,,,,,,,,,,,,,,,,,,,,,,,,,
135.31,2.09327,23.06816,6.5,,,,,,,,,,,,,,,,,,,,,,,,,,,,,,,,,,,,,
136.01,1.97653,19.77282,6.5,,,,,,,,,,,,,,,,,,,,,,,,,,,,,,,,,,,,,
136.71,1.8598,16.7245,6.5,,,,,,,,,,,,,,,,,,,,,,,,,,,,,,,,,,,,,
137.41,1.74318,13.93074,6.5,,,,,,,,,,,,,,,,,,,,,,,,,,,,,,,,,,,,,
138.11,1.62639,11.47158,6.5,,,,,,,,,,,,,,,,,,,,,,,,,,,,,,,,,,,,,
138.81,1.50977,9.12724,6.5,,,,,,,,,,,,,,,,,,,,,,,,,,,,,,,,,,,,,
139.51,1.39309,7.13931,6.5,,,,,,,,,,,,,,,,,,,,,,,,,,,,,,,,,,,,,
140.21,1.27642,5.35303,6.5,,,,,,,,,,,,,,,,,,,,,,,,,,,,,,,,,,,,,
140.91,1.1598,3.81596,6.5,,,,,,,,,,,,,,,,,,,,,,,,,,,,,,,,,,,,,
141.61,1.04323,2.38807,6.5,,,,,,,,,,,,,,,,,,,,,,,,,,,,,,,,,,,,,
142.31,0.92661,1.19633,6.5,,,,,,,,,,,,,,,,,,,,,,,,,,,,,,,,,,,,,
142.764,0.95177,1.58256,7,,,,,,,,,,,,,,,,,,,,,,,,,,,,,,,,,,,,,
143.464,1.06845,3.40736,7,,,,,,,,,,,,,,,,,,,,,,,,,,,,,,,,,,,,,
144.164,1.18524,5.05164,7,,,,,,,,,,,,,,,,,,,,,,,,,,,,,,,,,,,,,
144.864,1.30192,6.81637,7,,,,,,,,,,,,,,,,,,,,,,,,,,,,,,,,,,,,,
145.564,1.41871,8.75485,7,,,,,,,,,,,,,,,,,,,,,,,,,,,,,,,,,,,,,
146.264,1.53527,10.99491,7,,,,,,,,,,,,,,,,,,,,,,,,,,,,,,,,,,,,,
146.964,1.65183,13.44946,7,,,,,,,,,,,,,,,,,,,,,,,,,,,,,,,,,,,,,
147.664,1.76851,16.14221,7,,,,,,,,,,,,,,,,,,,,,,,,,,,,,,,,,,,,,
148.364,1.88519,19.03716,7,,,,,,,,,,,,,,,,,,,,,,,,,,,,,,,,,,,,,
149.064,2.00186,22.15963,7,,,,,,,,,,,,,,,,,,,,,,,,,,,,,,,,,,,,,
149.764,2.11854,25.47628,7,,,,,,,,,,,,,,,,,,,,,,,,,,,,,,,,,,,,,
150.464,2.2351,29.01224,7,,,,,,,,,,,,,,,,,,,,,,,,,,,,,,,,,,,,,
151.164,2.35184,32.69646,7,,,,,,,,,,,,,,,,,,,,,,,,,,,,,,,,,,,,,
151.864,2.46851,36.60325,7,,,,,,,,,,,,,,,,,,,,,,,,,,,,,,,,,,,,,
152.444,2.56519,40.02256,7.5,,,,,,,,,,,,,,,,,,,,,,,,,,,,,,,,,,,,,
153.144,2.44828,34.86371,7.5,,,,,,,,,,,,,,,,,,,,,,,,,,,,,,,,,,,,,
153.844,2.33161,30.32473,7.5,,,,,,,,,,,,,,,,,,,,,,,,,,,,,,,,,,,,,
154.544,2.21493,26.3404,7.5,,,,,,,,,,,,,,,,,,,,,,,,,,,,,,,,,,,,,
155.244,2.0982,22.61458,7.5,,,,,,,,,,,,,,,,,,,,,,,,,,,,,,,,,,,,,
155.944,1.98158,19.30131,7.5,,,,,,,,,,,,,,,,,,,,,,,,,,,,,,,,,,,,,
156.644,1.8649,16.35101,7.5,,,,,,,,,,,,,,,,,,,,,,,,,,,,,,,,,,,,,
157.344,1.74828,13.62106,7.5,,,,,,,,,,,,,,,,,,,,,,,,,,,,,,,,,,,,,
158.044,1.63149,11.13592,7.5,,,,,,,,,,,,,,,,,,,,,,,,,,,,,,,,,,,,,
158.744,1.5147,8.8782,7.5,,,,,,,,,,,,,,,,,,,,,,,,,,,,,,,,,,,,,
159.444,1.39808,6.88202,7.5,,,,,,,,,,,,,,,,,,,,,,,,,,,,,,,,,,,,,
160.144,1.28146,5.12644,7.5,,,,,,,,,,,,,,,,,,,,,,,,,,,,,,,,,,,,,
160.844,1.16478,3.649,7.5,,,,,,,,,,,,,,,,,,,,,,,,,,,,,,,,,,,,,
161.544,1.04822,2.19863,7.5,,,,,,,,,,,,,,,,,,,,,,,,,,,,,,,,,,,,,
162.244,0.93149,1.00429,7.5,,,,,,,,,,,,,,,,,,,,,,,,,,,,,,,,,,,,,
162.65,0.99807,2.05716,8,,,,,,,,,,,,,,,,,,,,,,,,,,,,,,,,,,,,,
163.35,1.11475,3.77406,8,,,,,,,,,,,,,,,,,,,,,,,,,,,,,,,,,,,,,
164.05,1.23142,5.39242,8,,,,,,,,,,,,,,,,,,,,,,,,,,,,,,,,,,,,,
164.75,1.34804,7.2655,8,,,,,,,,,,,,,,,,,,,,,,,,,,,,,,,,,,,,,
165.45,1.46489,9.21854,8,,,,,,,,,,,,,,,,,,,,,,,,,,,,,,,,,,,,,
166.15,1.58157,11.51339,8,,,,,,,,,,,,,,,,,,,,,,,,,,,,,,,,,,,,,
166.85,1.69836,14.01501,8,,,,,,,,,,,,,,,,,,,,,,,,,,,,,,,,,,,,,
167.55,1.81492,16.81971,8,,,,,,,,,,,,,,,,,,,,,,,,,,,,,,,,,,,,,
168.25,1.9316,19.74035,8,,,,,,,,,,,,,,,,,,,,,,,,,,,,,,,,,,,,,
168.95,2.04822,22.87755,8,,,,,,,,,,,,,,,,,,,,,,,,,,,,,,,,,,,,,
169.65,2.16489,26.23225,8,,,,,,,,,,,,,,,,,,,,,,,,,,,,,,,,,,,,,
170.35,2.28157,29.81588,8,,,,,,,,,,,,,,,,,,,,,,,,,,,,,,,,,,,,,
171.05,2.39813,33.57753,8,,,,,,,,,,,,,,,,,,,,,,,,,,,,,,,,,,,,,
171.75,2.51481,37.55256,8,,,,,,,,,,,,,,,,,,,,,,,,,,,,,,,,,,,,,
172.256,2.57012,39.7625,8.5,,,,,,,,,,,,,,,,,,,,,,,,,,,,,,,,,,,,,
172.956,2.44896,34.21762,8.5,,,,,,,,,,,,,,,,,,,,,,,,,,,,,,,,,,,,,
173.656,2.33229,29.68397,8.5,,,,,,,,,,,,,,,,,,,,,,,,,,,,,,,,,,,,,
174.356,2.21561,25.75492,8.5,,,,,,,,,,,,,,,,,,,,,,,,,,,,,,,,,,,,,
175.056,2.09893,22.1612,8.5,,,,,,,,,,,,,,,,,,,,,,,,,,,,,,,,,,,,,
175.756,1.98231,18.85356,8.5,,,,,,,,,,,,,,,,,,,,,,,,,,,,,,,,,,,,,
176.456,1.86558,15.91877,8.5,,,,,,,,,,,,,,,,,,,,,,,,,,,,,,,,,,,,,
177.156,1.7489,13.18889,8.5,,,,,,,,,,,,,,,,,,,,,,,,,,,,,,,,,,,,,
177.856,1.63217,10.79834,8.5,,,,,,,,,,,,,,,,,,,,,,,,,,,,,,,,,,,,,
178.556,1.51538,8.60419,8.5,,,,,,,,,,,,,,,,,,,,,,,,,,,,,,,,,,,,,
179.256,1.39876,6.63389,8.5,,,,,,,,,,,,,,,,,,,,,,,,,,,,,,,,,,,,,
179.956,1.28214,4.86302,8.5,,,,,,,,,,,,,,,,,,,,,,,,,,,,,,,,,,,,,
180.656,1.16546,3.37514,8.5,,,,,,,,,,,,,,,,,,,,,,,,,,,,,,,,,,,,,
181.356,1.04884,2.08636,8.5,,,,,,,,,,,,,,,,,,,,,,,,,,,,,,,,,,,,,
181.974,0.94577,0.99981,9,,,,,,,,,,,,,,,,,,,,,,,,,,,,,,,,,,,,,
182.478,1.02958,2.16753,9,,,,,,,,,,,,,,,,,,,,,,,,,,,,,,,,,,,,,
183.178,1.14614,3.95071,9,,,,,,,,,,,,,,,,,,,,,,,,,,,,,,,,,,,,,
183.878,1.2627,5.60824,9,,,,,,,,,,,,,,,,,,,,,,,,,,,,,,,,,,,,,
184.578,1.37944,7.45802,9,,,,,,,,,,,,,,,,,,,,,,,,,,,,,,,,,,,,,
185.278,1.49623,9.45915,9,,,,,,,,,,,,,,,,,,,,,,,,,,,,,,,,,,,,,
185.978,1.61285,11.83574,9,,,,,,,,,,,,,,,,,,,,,,,,,,,,,,,,,,,,,
186.678,1.72941,14.37414,9,,,,,,,,,,,,,,,,,,,,,,,,,,,,,,,,,,,,,
187.378,1.84609,17.13198,9,,,,,,,,,,,,,,,,,,,,,,,,,,,,,,,,,,,,,
188.078,1.96276,20.07125,9,,,,,,,,,,,,,,,,,,,,,,,,,,,,,,,,,,,,,
188.778,2.07944,23.24306,9,,,,,,,,,,,,,,,,,,,,,,,,,,,,,,,,,,,,,
189.478,2.19623,26.64613,9,,,,,,,,,,,,,,,,,,,,,,,,,,,,,,,,,,,,,
190.178,2.31291,30.2624,9,,,,,,,,,,,,,,,,,,,,,,,,,,,,,,,,,,,,,
190.878,2.42953,34.07581,9,,,,,,,,,,,,,,,,,,,,,,,,,,,,,,,,,,,,,
191.578,2.54626,38.17311,9,,,,,,,,,,,,,,,,,,,,,,,,,,,,,,,,,,,,,
192.096,2.56609,38.67284,9.5,,,,,,,,,,,,,,,,,,,,,,,,,,,,,,,,,,,,,
192.796,2.44896,33.56498,9.5,,,,,,,,,,,,,,,,,,,,,,,,,,,,,,,,,,,,,
193.496,2.33229,29.1976,9.5,,,,,,,,,,,,,,,,,,,,,,,,,,,,,,,,,,,,,
194.196,2.21561,25.32873,9.5,,,,,,,,,,,,,,,,,,,,,,,,,,,,,,,,,,,,,
194.896,2.09888,21.71609,9.5,,,,,,,,,,,,,,,,,,,,,,,,,,,,,,,,,,,,,
195.596,1.98226,18.47753,9.5,,,,,,,,,,,,,,,,,,,,,,,,,,,,,,,,,,,,,
196.296,1.86558,15.64571,9.5,,,,,,,,,,,,,,,,,,,,,,,,,,,,,,,,,,,,,
196.996,1.7489,12.92387,9.5,,,,,,,,,,,,,,,,,,,,,,,,,,,,,,,,,,,,,
197.696,1.63217,10.52083,9.5,,,,,,,,,,,,,,,,,,,,,,,,,,,,,,,,,,,,,
198.396,1.51532,8.37013,9.5,,,,,,,,,,,,,,,,,,,,,,,,,,,,,,,,,,,,,
199.096,1.39876,6.39026,9.5,,,,,,,,,,,,,,,,,,,,,,,,,,,,,,,,,,,,,
199.796,1.28214,4.77447,9.5,,,,,,,,,,,,,,,,,,,,,,,,,,,,,,,,,,,,,
200.496,1.16552,3.27939,9.5,,,,,,,,,,,,,,,,,,,,,,,,,,,,,,,,,,,,,
201.196,1.04884,1.85413,9.5,,,,,,,,,,,,,,,,,,,,,,,,,,,,,,,,,,,,,
201.746,0.95721,0.98457,10,,,,,,,,,,,,,,,,,,,,,,,,,,,,,,,,,,,,,
202.446,0.92599,0.73508,10,,,,,,,,,,,,,,,,,,,,,,,,,,,,,,,,,,,,,
203.146,0.93041,0.88685,10,,,,,,,,,,,,,,,,,,,,,,,,,,,,,,,,,,,,,
203.846,0.97149,1.42547,10,,,,,,,,,,,,,,,,,,,,,,,,,,,,,,,,,,,,,
204.546,0.97438,1.53163,10,,,,,,,,,,,,,,,,,,,,,,,,,,,,,,,,,,,,,
205.246,0.96747,1.53092,10,,,,,,,,,,,,,,,,,,,,,,,,,,,,,,,,,,,,,
205.946,0.93795,1.10286,10,,,,,,,,,,,,,,,,,,,,,,,,,,,,,,,,,,,,,
206.646,0.93749,1.07413,10,,,,,,,,,,,,,,,,,,,,,,,,,,,,,,,,,,,,,
207.346,0.93766,1.15055,10,,,,,,,,,,,,,,,,,,,,,,,,,,,,,,,,,,,,,
208.046,0.93817,1.08779,10,,,,,,,,,,,,,,,,,,,,,,,,,,,,,,,,,,,,,
208.746,0.93987,1.10068,10,,,,,,,,,,,,,,,,,,,,,,,,,,,,,,,,,,,,,
209.446,0.9439,1.17973,10,,,,,,,,,,,,,,,,,,,,,,,,,,,,,,,,,,,,,
210.146,0.94667,1.24216,10,,,,,,,,,,,,,,,,,,,,,,,,,,,,,,,,,,,,,
210.846,0.94764,1.25668,10,,,,,,,,,,,,,,,,,,,,,,,,,,,,,,,,,,,,,
211.546,0.94758,1.31534,10,,,,,,,,,,,,,,,,,,,,,,,,,,,,,,,,,,,,,
212.246,0.94741,1.2827,10,,,,,,,,,,,,,,,,,,,,,,,,,,,,,,,,,,,,,
212.946,0.94718,1.32951,10,,,,,,,,,,,,,,,,,,,,,,,,,,,,,,,,,,,,,
213.646,0.9452,1.40591,10,,,,,,,,,,,,,,,,,,,,,,,,,,,,,,,,,,,,,
214.346,0.94072,1.30598,10,,,,,,,,,,,,,,,,,,,,,,,,,,,,,,,,,,,,,
215.046,0.93608,1.25277,10,,,,,,,,,,,,,,,,,,,,,,,,,,,,,,,,,,,,,
215.746,0.93347,1.25168,10,,,,,,,,,,,,,,,,,,,,,,,,,,,,,,,,,,,,,
216.446,0.93285,1.20425,10,,,,,,,,,,,,,,,,,,,,,,,,,,,,,,,,,,,,,
217.146,0.93251,1.20758,10,,,,,,,,,,,,,,,,,,,,,,,,,,,,,,,,,,,,,
217.846,0.93228,1.1967,10,,,,,,,,,,,,,,,,,,,,,,,,,,,,,,,,,,,,,
218.546,0.93239,1.22856,10,,,,,,,,,,,,,,,,,,,,,,,,,,,,,,,,,,,,,
219.246,0.93239,1.23458,10,,,,,,,,,,,,,,,,,,,,,,,,,,,,,,,,,,,,,
219.946,0.93234,1.23752,10,,,,,,,,,,,,,,,,,,,,,,,,,,,,,,,,,,,,,
220.646,0.93245,1.23537,10,,,,,,,,,,,,,,,,,,,,,,,,,,,,,,,,,,,,,
221.346,0.93245,1.20314,10,,,,,,,,,,,,,,,,,,,,,,,,,,,,,,,,,,,,,
222.046,0.93245,1.26065,10,,,,,,,,,,,,,,,,,,,,,,,,,,,,,,,,,,,,,
222.746,0.93234,1.23788,10,,,,,,,,,,,,,,,,,,,,,,,,,,,,,,,,,,,,,
223.446,0.93234,1.30312,10,,,,,,,,,,,,,,,,,,,,,,,,,,,,,,,,,,,,,
224.146,0.93228,1.30757,10,,,,,,,,,,,,,,,,,,,,,,,,,,,,,,,,,,,,,
224.846,0.93166,1.27726,10,,,,,,,,,,,,,,,,,,,,,,,,,,,,,,,,,,,,,
225.546,0.92899,1.21863,10,,,,,,,,,,,,,,,,,,,,,,,,,,,,,,,,,,,,,
226.246,0.92599,1.24471,10,,,,,,,,,,,,,,,,,,,,,,,,,,,,,,,,,,,,,
226.946,0.92486,1.19832,10,,,,,,,,,,,,,,,,,,,,,,,,,,,,,,,,,,,,,
227.646,0.92457,1.1775,10,,,,,,,,,,,,,,,,,,,,,,,,,,,,,,,,,,,,,
228.346,0.92469,1.20423,10,,,,,,,,,,,,,,,,,,,,,,,,,,,,,,,,,,,,,
229.046,0.92474,1.19129,10,,,,,,,,,,,,,,,,,,,,,,,,,,,,,,,,,,,,,
229.746,0.92486,1.16024,10,,,,,,,,,,,,,,,,,,,,,,,,,,,,,,,,,,,,,
230.446,0.92491,1.19319,10,,,,,,,,,,,,,,,,,,,,,,,,,,,,,,,,,,,,,
231.146,0.92497,1.13819,10,,,,,,,,,,,,,,,,,,,,,,,,,,,,,,,,,,,,,
231.846,0.92503,1.16362,10,,,,,,,,,,,,,,,,,,,,,,,,,,,,,,,,,,,,,
232.546,0.92503,1.2357,10,,,,,,,,,,,,,,,,,,,,,,,,,,,,,,,,,,,,,
233.246,0.92503,1.20863,10,,,,,,,,,,,,,,,,,,,,,,,,,,,,,,,,,,,,,
233.946,0.92508,1.19348,10,,,,,,,,,,,,,,,,,,,,,,,,,,,,,,,,,,,,,
234.646,0.92508,1.28051,10,,,,,,,,,,,,,,,,,,,,,,,,,,,,,,,,,,,,,
235.346,0.9252,1.20883,10,,,,,,,,,,,,,,,,,,,,,,,,,,,,,,,,,,,,,
236.046,0.9252,1.19885,10,,,,,,,,,,,,,,,,,,,,,,,,,,,,,,,,,,,,,
236.746,0.92525,1.28106,10,,,,,,,,,,,,,,,,,,,,,,,,,,,,,,,,,,,,,
237.446,0.92531,1.21732,10,,,,,,,,,,,,,,,,,,,,,,,,,,,,,,,,,,,,,
238.146,0.92531,1.21099,10,,,,,,,,,,,,,,,,,,,,,,,,,,,,,,,,,,,,,
238.846,0.92531,1.18162,10,,,,,,,,,,,,,,,,,,,,,,,,,,,,,,,,,,,,,
239.546,0.92537,1.31428,10,,,,,,,,,,,,,,,,,,,,,,,,,,,,,,,,,,,,,
240.246,0.92525,1.28129,10,,,,,,,,,,,,,,,,,,,,,,,,,,,,,,,,,,,,,
240.946,0.92531,1.26434,10,,,,,,,,,,,,,,,,,,,,,,,,,,,,,,,,,,,,,
241.646,0.92531,1.26349,10,,,,,,,,,,,,,,,,,,,,,,,,,,,,,,,,,,,,,
242.346,0.9252,1.20735,10,,,,,,,,,,,,,,,,,,,,,,,,,,,,,,,,,,,,,
243.046,0.9252,1.268,10,,,,,,,,,,,,,,,,,,,,,,,,,,,,,,,,,,,,,
243.746,0.92508,1.25466,10,,,,,,,,,,,,,,,,,,,,,,,,,,,,,,,,,,,,,
244.446,0.9252,1.22103,10,,,,,,,,,,,,,,,,,,,,,,,,,,,,,,,,,,,,,
245.146,0.9252,1.26008,10,,,,,,,,,,,,,,,,,,,,,,,,,,,,,,,,,,,,,
245.846,0.92514,1.23659,10,,,,,,,,,,,,,,,,,,,,,,,,,,,,,,,,,,,,,
246.546,0.92503,1.24783,10,,,,,,,,,,,,,,,,,,,,,,,,,,,,,,,,,,,,,
247.246,0.92497,1.36407,10,,,,,,,,,,,,,,,,,,,,,,,,,,,,,,,,,,,,,
247.946,0.92474,1.30537,10,,,,,,,,,,,,,,,,,,,,,,,,,,,,,,,,,,,,,
248.646,0.92435,1.29175,10,,,,,,,,,,,,,,,,,,,,,,,,,,,,,,,,,,,,,
249.346,0.9218,1.28107,10,,,,,,,,,,,,,,,,,,,,,,,,,,,,,,,,,,,,,
250.046,0.91834,1.18805,10,,,,,,,,,,,,,,,,,,,,,,,,,,,,,,,,,,,,,
250.746,0.91653,1.17392,10,,,,,,,,,,,,,,,,,,,,,,,,,,,,,,,,,,,,,
251.446,0.91619,1.22318,10,,,,,,,,,,,,,,,,,,,,,,,,,,,,,,,,,,,,,
252.146,0.91624,1.16523,10,,,,,,,,,,,,,,,,,,,,,,,,,,,,,,,,,,,,,
252.846,0.91636,1.14394,10,,,,,,,,,,,,,,,,,,,,,,,,,,,,,,,,,,,,,
253.546,0.91641,1.20304,10,,,,,,,,,,,,,,,,,,,,,,,,,,,,,,,,,,,,,
254.246,0.91664,1.15809,10,,,,,,,,,,,,,,,,,,,,,,,,,,,,,,,,,,,,,
254.946,0.91681,1.1009,10,,,,,,,,,,,,,,,,,,,,,,,,,,,,,,,,,,,,,
255.646,0.91726,1.16258,10,,,,,,,,,,,,,,,,,,,,,,,,,,,,,,,,,,,,,
256.346,0.91794,1.18342,10,,,,,,,,,,,,,,,,,,,,,,,,,,,,,,,,,,,,,
257.046,0.91925,1.14888,10,,,,,,,,,,,,,,,,,,,,,,,,,,,,,,,,,,,,,
257.746,0.92168,1.22115,10,,,,,,,,,,,,,,,,,,,,,,,,,,,,,,,,,,,,,
258.446,0.92287,1.20875,10,,,,,,,,,,,,,,,,,,,,,,,,,,,,,,,,,,,,,
259.146,0.92333,1.1924,10,,,,,,,,,,,,,,,,,,,,,,,,,,,,,,,,,,,,,
259.846,0.92372,1.23514,10,,,,,,,,,,,,,,,,,,,,,,,,,,,,,,,,,,,,,
260.546,0.92367,1.32646,10,,,,,,,,,,,,,,,,,,,,,,,,,,,,,,,,,,,,,
261.246,0.92361,1.2248,10,,,,,,,,,,,,,,,,,,,,,,,,,,,,,,,,,,,,,
261.946,0.92355,1.28383,10,,,,,,,,,,,,,,,,,,,,,,,,,,,,,,,,,,,,,
262.646,0.9235,1.29052,10,,,,,,,,,,,,,,,,,,,,,,,,,,,,,,,,,,,,,
263.346,0.92327,1.2895,10,,,,,,,,,,,,,,,,,,,,,,,,,,,,,,,,,,,,,
264.046,0.92293,1.30752,10,,,,,,,,,,,,,,,,,,,,,,,,,,,,,,,,,,,,,
264.746,0.92214,1.31603,10,,,,,,,,,,,,,,,,,,,,,,,,,,,,,,,,,,,,,
265.446,0.92066,1.2399,10,,,,,,,,,,,,,,,,,,,,,,,,,,,,,,,,,,,,,
266.146,0.91857,1.30943,10,,,,,,,,,,,,,,,,,,,,,,,,,,,,,,,,,,,,,
266.846,0.91675,1.23073,10,,,,,,,,,,,,,,,,,,,,,,,,,,,,,,,,,,,,,
267.546,0.91494,1.17182,10,,,,,,,,,,,,,,,,,,,,,,,,,,,,,,,,,,,,,
268.246,0.91347,1.24896,10,,,,,,,,,,,,,,,,,,,,,,,,,,,,,,,,,,,,,
268.946,0.91279,1.21652,10,,,,,,,,,,,,,,,,,,,,,,,,,,,,,,,,,,,,,
269.646,0.91222,1.14992,10,,,,,,,,,,,,,,,,,,,,,,,,,,,,,,,,,,,,,
270.346,0.91211,1.22166,10,,,,,,,,,,,,,,,,,,,,,,,,,,,,,,,,,,,,,
271.046,0.91222,1.17876,10,,,,,,,,,,,,,,,,,,,,,,,,,,,,,,,,,,,,,
271.746,0.91233,1.1637,10,,,,,,,,,,,,,,,,,,,,,,,,,,,,,,,,,,,,,
272.446,0.91245,1.16756,10,,,,,,,,,,,,,,,,,,,,,,,,,,,,,,,,,,,,,
273.146,0.91256,1.18146,10,,,,,,,,,,,,,,,,,,,,,,,,,,,,,,,,,,,,,
273.846,0.91267,1.1979,10,,,,,,,,,,,,,,,,,,,,,,,,,,,,,,,,,,,,,
274.546,0.91284,1.20651,10,,,,,,,,,,,,,,,,,,,,,,,,,,,,,,,,,,,,,
275.246,0.91318,1.18763,10,,,,,,,,,,,,,,,,,,,,,,,,,,,,,,,,,,,,,
275.946,0.91352,1.18106,10,,,,,,,,,,,,,,,,,,,,,,,,,,,,,,,,,,,,,
276.646,0.91398,1.19267,10,,,,,,,,,,,,,,,,,,,,,,,,,,,,,,,,,,,,,
277.346,0.91466,1.20581,10,,,,,,,,,,,,,,,,,,,,,,,,,,,,,,,,,,,,,
278.046,0.91539,1.18655,10,,,,,,,,,,,,,,,,,,,,,,,,,,,,,,,,,,,,,
278.746,0.9167,1.23622,10,,,,,,,,,,,,,,,,,,,,,,,,,,,,,,,,,,,,,
279.446,0.91857,1.22232,10,,,,,,,,,,,,,,,,,,,,,,,,,,,,,,,,,,,,,
280.146,0.9197,1.25026,10,,,,,,,,,,,,,,,,,,,,,,,,,,,,,,,,,,,,,
280.846,0.91993,1.26494,10,,,,,,,,,,,,,,,,,,,,,,,,,,,,,,,,,,,,,
281.546,0.91993,1.25151,10,,,,,,,,,,,,,,,,,,,,,,,,,,,,,,,,,,,,,
282.246,0.91981,1.25414,10,,,,,,,,,,,,,,,,,,,,,,,,,,,,,,,,,,,,,
282.946,0.91976,1.28605,10,,,,,,,,,,,,,,,,,,,,,,,,,,,,,,,,,,,,,
283.646,0.91964,1.3245,10,,,,,,,,,,,,,,,,,,,,,,,,,,,,,,,,,,,,,
284.346,0.91959,1.2336,10,,,,,,,,,,,,,,,,,,,,,,,,,,,,,,,,,,,,,
285.046,0.91936,1.35784,10,,,,,,,,,,,,,,,,,,,,,,,,,,,,,,,,,,,,,
285.746,0.91891,1.35425,10,,,,,,,,,,,,,,,,,,,,,,,,,,,,,,,,,,,,,
286.446,0.91772,1.31302,10,,,,,,,,,,,,,,,,,,,,,,,,,,,,,,,,,,,,,
287.146,0.91596,1.24529,10,,,,,,,,,,,,,,,,,,,,,,,,,,,,,,,,,,,,,
287.846,0.91352,1.26817,10,,,,,,,,,,,,,,,,,,,,,,,,,,,,,,,,,,,,,
288.546,0.91109,1.16704,10,,,,,,,,,,,,,,,,,,,,,,,,,,,,,,,,,,,,,
289.246,0.90973,1.2362,10,,,,,,,,,,,,,,,,,,,,,,,,,,,,,,,,,,,,,
289.946,0.90876,1.2057,10,,,,,,,,,,,,,,,,,,,,,,,,,,,,,,,,,,,,,
290.646,0.90842,1.17397,10,,,,,,,,,,,,,,,,,,,,,,,,,,,,,,,,,,,,,
291.346,0.90854,1.22171,10,,,,,,,,,,,,,,,,,,,,,,,,,,,,,,,,,,,,,
292.046,0.90865,1.17856,10,,,,,,,,,,,,,,,,,,,,,,,,,,,,,,,,,,,,,
292.746,0.90876,1.21818,10,,,,,,,,,,,,,,,,,,,,,,,,,,,,,,,,,,,,,
293.446,0.90893,1.17056,10,,,,,,,,,,,,,,,,,,,,,,,,,,,,,,,,,,,,,
294.146,0.90905,1.17243,10,,,,,,,,,,,,,,,,,,,,,,,,,,,,,,,,,,,,,
294.846,0.90927,1.15504,10,,,,,,,,,,,,,,,,,,,,,,,,,,,,,,,,,,,,,
295.546,0.90961,1.18777,10,,,,,,,,,,,,,,,,,,,,,,,,,,,,,,,,,,,,,
296.246,0.91001,1.18219,10,,,,,,,,,,,,,,,,,,,,,,,,,,,,,,,,,,,,,
296.946,0.91046,1.16294,10,,,,,,,,,,,,,,,,,,,,,,,,,,,,,,,,,,,,,
297.646,0.9112,1.21306,10,,,,,,,,,,,,,,,,,,,,,,,,,,,,,,,,,,,,,
298.346,0.91222,1.25529,10,,,,,,,,,,,,,,,,,,,,,,,,,,,,,,,,,,,,,
299.046,0.91347,1.18833,10,,,,,,,,,,,,,,,,,,,,,,,,,,,,,,,,,,,,,
299.746,0.91477,1.22766,10,,,,,,,,,,,,,,,,,,,,,,,,,,,,,,,,,,,,,
300.446,0.91539,1.21931,10,,,,,,,,,,,,,,,,,,,,,,,,,,,,,,,,,,,,,
301.146,0.91562,1.23003,10,,,,,,,,,,,,,,,,,,,,,,,,,,,,,,,,,,,,,
301.846,0.91568,1.26189,10,,,,,,,,,,,,,,,,,,,,,,,,,,,,,,,,,,,,,
302.546,0.91556,1.25819,10,,,,,,,,,,,,,,,,,,,,,,,,,,,,,,,,,,,,,
303.246,0.91551,1.28946,10,,,,,,,,,,,,,,,,,,,,,,,,,,,,,,,,,,,,,
303.946,0.91539,1.30402,10,,,,,,,,,,,,,,,,,,,,,,,,,,,,,,,,,,,,,
304.646,0.91528,1.2995,10,,,,,,,,,,,,,,,,,,,,,,,,,,,,,,,,,,,,,
305.346,0.91517,1.23946,10,,,,,,,,,,,,,,,,,,,,,,,,,,,,,,,,,,,,,
306.046,0.91505,1.30109,10,,,,,,,,,,,,,,,,,,,,,,,,,,,,,,,,,,,,,
306.746,0.91477,1.24212,10,,,,,,,,,,,,,,,,,,,,,,,,,,,,,,,,,,,,,
307.446,0.91443,1.19399,10,,,,,,,,,,,,,,,,,,,,,,,,,,,,,,,,,,,,,
308.146,0.91398,1.27668,10,,,,,,,,,,,,,,,,,,,,,,,,,,,,,,,,,,,,,
308.846,0.91324,1.25197,10,,,,,,,,,,,,,,,,,,,,,,,,,,,,,,,,,,,,,
309.546,0.91262,1.26062,10,,,,,,,,,,,,,,,,,,,,,,,,,,,,,,,,,,,,,
310.246,0.9116,1.25328,10,,,,,,,,,,,,,,,,,,,,,,,,,,,,,,,,,,,,,
310.946,0.91063,1.28534,10,,,,,,,,,,,,,,,,,,,,,,,,,,,,,,,,,,,,,
311.646,0.9099,1.1773,10,,,,,,,,,,,,,,,,,,,,,,,,,,,,,,,,,,,,,
312.346,0.90944,1.20699,10,,,,,,,,,,,,,,,,,,,,,,,,,,,,,,,,,,,,,
313.046,0.90933,1.1792,10,,,,,,,,,,,,,,,,,,,,,,,,,,,,,,,,,,,,,
313.746,0.9095,1.19591,10,,,,,,,,,,,,,,,,,,,,,,,,,,,,,,,,,,,,,
314.446,0.90956,1.2116,10,,,,,,,,,,,,,,,,,,,,,,,,,,,,,,,,,,,,,
315.146,0.90961,1.24853,10,,,,,,,,,,,,,,,,,,,,,,,,,,,,,,,,,,,,,
315.846,0.90961,1.20639,10,,,,,,,,,,,,,,,,,,,,,,,,,,,,,,,,,,,,,
316.546,0.90967,1.25671,10,,,,,,,,,,,,,,,,,,,,,,,,,,,,,,,,,,,,,
317.246,0.90973,1.17409,10,,,,,,,,,,,,,,,,,,,,,,,,,,,,,,,,,,,,,
317.946,0.90984,1.21297,10,,,,,,,,,,,,,,,,,,,,,,,,,,,,,,,,,,,,,
318.646,0.9099,1.22207,10,,,,,,,,,,,,,,,,,,,,,,,,,,,,,,,,,,,,,
319.346,0.90995,1.26298,10,,,,,,,,,,,,,,,,,,,,,,,,,,,,,,,,,,,,,
320.046,0.91001,1.23303,10,,,,,,,,,,,,,,,,,,,,,,,,,,,,,,,,,,,,,
320.746,0.91001,1.21637,10,,,,,,,,,,,,,,,,,,,,,,,,,,,,,,,,,,,,,
321.446,0.91001,1.19801,10,,,,,,,,,,,,,,,,,,,,,,,,,,,,,,,,,,,,,
322.146,0.91007,1.22454,10,,,,,,,,,,,,,,,,,,,,,,,,,,,,,,,,,,,,,
322.846,0.91012,1.20881,10,,,,,,,,,,,,,,,,,,,,,,,,,,,,,,,,,,,,,
323.546,0.91018,1.19586,10,,,,,,,,,,,,,,,,,,,,,,,,,,,,,,,,,,,,,
324.246,0.91024,1.23595,10,,,,,,,,,,,,,,,,,,,,,,,,,,,,,,,,,,,,,
324.946,0.91035,1.21249,10,,,,,,,,,,,,,,,,,,,,,,,,,,,,,,,,,,,,,
325.646,0.91046,1.17874,10,,,,,,,,,,,,,,,,,,,,,,,,,,,,,,,,,,,,,
326.346,0.91069,1.23705,10,,,,,,,,,,,,,,,,,,,,,,,,,,,,,,,,,,,,,
327.046,0.9108,1.1997,10,,,,,,,,,,,,,,,,,,,,,,,,,,,,,,,,,,,,,
327.746,0.91097,1.21347,10,,,,,,,,,,,,,,,,,,,,,,,,,,,,,,,,,,,,,
328.446,0.9112,1.22857,10,,,,,,,,,,,,,,,,,,,,,,,,,,,,,,,,,,,,,
329.146,0.91143,1.21449,10,,,,,,,,,,,,,,,,,,,,,,,,,,,,,,,,,,,,,
329.846,0.91177,1.28164,10,,,,,,,,,,,,,,,,,,,,,,,,,,,,,,,,,,,,,
330.546,0.91194,1.21221,10,,,,,,,,,,,,,,,,,,,,,,,,,,,,,,,,,,,,,
331.246,0.91216,1.23243,10,,,,,,,,,,,,,,,,,,,,,,,,,,,,,,,,,,,,,
331.946,0.91228,1.22737,10,,,,,,,,,,,,,,,,,,,,,,,,,,,,,,,,,,,,,
332.646,0.9125,1.2092,10,,,,,,,,,,,,,,,,,,,,,,,,,,,,,,,,,,,,,
333.346,0.91262,1.31384,10,,,,,,,,,,,,,,,,,,,,,,,,,,,,,,,,,,,,,
334.046,0.91267,1.21593,10,,,,,,,,,,,,,,,,,,,,,,,,,,,,,,,,,,,,,
334.746,0.91267,1.27976,10,,,,,,,,,,,,,,,,,,,,,,,,,,,,,,,,,,,,,
335.446,0.91256,1.20079,10,,,,,,,,,,,,,,,,,,,,,,,,,,,,,,,,,,,,,
336.146,0.9125,1.24754,10,,,,,,,,,,,,,,,,,,,,,,,,,,,,,,,,,,,,,
336.846,0.91245,1.27173,10,,,,,,,,,,,,,,,,,,,,,,,,,,,,,,,,,,,,,
337.546,0.91239,1.26265,10,,,,,,,,,,,,,,,,,,,,,,,,,,,,,,,,,,,,,
338.246,0.91233,1.24055,10,,,,,,,,,,,,,,,,,,,,,,,,,,,,,,,,,,,,,
338.946,0.91222,1.23388,10,,,,,,,,,,,,,,,,,,,,,,,,,,,,,,,,,,,,,
339.646,0.91211,1.30196,10,,,,,,,,,,,,,,,,,,,,,,,,,,,,,,,,,,,,,
340.346,0.91194,1.32027,10,,,,,,,,,,,,,,,,,,,,,,,,,,,,,,,,,,,,,
341.046,0.91171,1.19693,10,,,,,,,,,,,,,,,,,,,,,,,,,,,,,,,,,,,,,
341.746,0.91154,1.34521,10,,,,,,,,,,,,,,,,,,,,,,,,,,,,,,,,,,,,,
342.446,0.9112,1.25641,10,,,,,,,,,,,,,,,,,,,,,,,,,,,,,,,,,,,,,
343.146,0.9108,1.2919,10,,,,,,,,,,,,,,,,,,,,,,,,,,,,,,,,,,,,,
343.846,0.91012,1.26757,10,,,,,,,,,,,,,,,,,,,,,,,,,,,,,,,,,,,,,
344.546,0.90933,1.2824,10,,,,,,,,,,,,,,,,,,,,,,,,,,,,,,,,,,,,,
345.246,0.90859,1.24266,10,,,,,,,,,,,,,,,,,,,,,,,,,,,,,,,,,,,,,
345.946,0.90774,1.18012,10,,,,,,,,,,,,,,,,,,,,,,,,,,,,,,,,,,,,,
346.646,0.90695,1.21706,10,,,,,,,,,,,,,,,,,,,,,,,,,,,,,,,,,,,,,
347.346,0.9061,1.18553,10,,,,,,,,,,,,,,,,,,,,,,,,,,,,,,,,,,,,,
348.046,0.9057,1.19824,10,,,,,,,,,,,,,,,,,,,,,,,,,,,,,,,,,,,,,
348.746,0.90542,1.15777,10,,,,,,,,,,,,,,,,,,,,,,,,,,,,,,,,,,,,,
349.446,0.90548,1.19163,10,,,,,,,,,,,,,,,,,,,,,,,,,,,,,,,,,,,,,
350.146,0.90553,1.19919,10,,,,,,,,,,,,,,,,,,,,,,,,,,,,,,,,,,,,,
350.846,0.90559,1.15364,10,,,,,,,,,,,,,,,,,,,,,,,,,,,,,,,,,,,,,
351.546,0.9057,1.14809,10,,,,,,,,,,,,,,,,,,,,,,,,,,,,,,,,,,,,,
352.246,0.90582,1.16674,10,,,,,,,,,,,,,,,,,,,,,,,,,,,,,,,,,,,,,
352.946,0.90587,1.17397,10,,,,,,,,,,,,,,,,,,,,,,,,,,,,,,,,,,,,,
353.646,0.90599,1.15655,10,,,,,,,,,,,,,,,,,,,,,,,,,,,,,,,,,,,,,
354.346,0.90604,1.1844,10,,,,,,,,,,,,,,,,,,,,,,,,,,,,,,,,,,,,,
355.046,0.90627,1.15791,10,,,,,,,,,,,,,,,,,,,,,,,,,,,,,,,,,,,,,
355.746,0.90667,1.17838,10,,,,,,,,,,,,,,,,,,,,,,,,,,,,,,,,,,,,,
356.446,0.90712,1.19865,10,,,,,,,,,,,,,,,,,,,,,,,,,,,,,,,,,,,,,
357.146,0.90803,1.1759,10,,,,,,,,,,,,,,,,,,,,,,,,,,,,,,,,,,,,,
357.846,0.90961,1.1904,10,,,,,,,,,,,,,,,,,,,,,,,,,,,,,,,,,,,,,
358.546,0.91114,1.2151,10,,,,,,,,,,,,,,,,,,,,,,,,,,,,,,,,,,,,,
359.246,0.91194,1.25077,10,,,,,,,,,,,,,,,,,,,,,,,,,,,,,,,,,,,,,
359.946,0.91216,1.27247,10,,,,,,,,,,,,,,,,,,,,,,,,,,,,,,,,,,,,,
360.646,0.91205,1.24853,10,,,,,,,,,,,,,,,,,,,,,,,,,,,,,,,,,,,,,
361.346,0.91199,1.2616,10,,,,,,,,,,,,,,,,,,,,,,,,,,,,,,,,,,,,,
362.046,0.91188,1.24942,10,,,,,,,,,,,,,,,,,,,,,,,,,,,,,,,,,,,,,
362.746,0.91182,1.26628,10,,,,,,,,,,,,,,,,,,,,,,,,,,,,,,,,,,,,,
363.446,0.91171,1.19021,10,,,,,,,,,,,,,,,,,,,,,,,,,,,,,,,,,,,,,
364.146,0.91148,1.22227,10,,,,,,,,,,,,,,,,,,,,,,,,,,,,,,,,,,,,,
364.846,0.91137,1.31074,10,,,,,,,,,,,,,,,,,,,,,,,,,,,,,,,,,,,,,
365.546,0.91097,1.28708,10,,,,,,,,,,,,,,,,,,,,,,,,,,,,,,,,,,,,,
366.246,0.91024,1.30327,10,,,,,,,,,,,,,,,,,,,,,,,,,,,,,,,,,,,,,
366.946,0.90865,1.29115,10,,,,,,,,,,,,,,,,,,,,,,,,,,,,,,,,,,,,,
367.646,0.90752,1.2713,10,,,,,,,,,,,,,,,,,,,,,,,,,,,,,,,,,,,,,
368.346,0.90621,1.19155,10,,,,,,,,,,,,,,,,,,,,,,,,,,,,,,,,,,,,,
369.046,0.90559,1.26318,10,,,,,,,,,,,,,,,,,,,,,,,,,,,,,,,,,,,,,
369.746,0.90508,1.20618,10,,,,,,,,,,,,,,,,,,,,,,,,,,,,,,,,,,,,,
370.446,0.90491,1.14369,10,,,,,,,,,,,,,,,,,,,,,,,,,,,,,,,,,,,,,
371.146,0.90502,1.21356,10,,,,,,,,,,,,,,,,,,,,,,,,,,,,,,,,,,,,,
371.846,0.90508,1.1923,10,,,,,,,,,,,,,,,,,,,,,,,,,,,,,,,,,,,,,
372.546,0.90519,1.1563,10,,,,,,,,,,,,,,,,,,,,,,,,,,,,,,,,,,,,,
373.246,0.90525,1.23723,10,,,,,,,,,,,,,,,,,,,,,,,,,,,,,,,,,,,,,
373.946,0.90531,1.26577,10,,,,,,,,,,,,,,,,,,,,,,,,,,,,,,,,,,,,,
374.646,0.90542,1.16013,10,,,,,,,,,,,,,,,,,,,,,,,,,,,,,,,,,,,,,
375.346,0.90548,1.17937,10,,,,,,,,,,,,,,,,,,,,,,,,,,,,,,,,,,,,,
376.046,0.90576,1.18395,10,,,,,,,,,,,,,,,,,,,,,,,,,,,,,,,,,,,,,
376.746,0.90604,1.20766,10,,,,,,,,,,,,,,,,,,,,,,,,,,,,,,,,,,,,,
377.446,0.90616,1.1879,10,,,,,,,,,,,,,,,,,,,,,,,,,,,,,,,,,,,,,
378.146,0.90633,1.15017,10,,,,,,,,,,,,,,,,,,,,,,,,,,,,,,,,,,,,,
378.846,0.90661,1.16801,10,,,,,,,,,,,,,,,,,,,,,,,,,,,,,,,,,,,,,
379.546,0.90701,1.20613,10,,,,,,,,,,,,,,,,,,,,,,,,,,,,,,,,,,,,,
380.246,0.90757,1.25551,10,,,,,,,,,,,,,,,,,,,,,,,,,,,,,,,,,,,,,
380.946,0.9082,1.26575,10,,,,,,,,,,,,,,,,,,,,,,,,,,,,,,,,,,,,,
381.646,0.90888,1.27055,10,,,,,,,,,,,,,,,,,,,,,,,,,,,,,,,,,,,,,
382.346,0.90956,1.24189,10,,,,,,,,,,,,,,,,,,,,,,,,,,,,,,,,,,,,,
383.046,0.9099,1.20185,10,,,,,,,,,,,,,,,,,,,,,,,,,,,,,,,,,,,,,
383.746,0.90995,1.34734,10,,,,,,,,,,,,,,,,,,,,,,,,,,,,,,,,,,,,,
384.446,0.9099,1.24198,10,,,,,,,,,,,,,,,,,,,,,,,,,,,,,,,,,,,,,
385.146,0.90973,1.24599,10,,,,,,,,,,,,,,,,,,,,,,,,,,,,,,,,,,,,,
385.846,0.90967,1.27069,10,,,,,,,,,,,,,,,,,,,,,,,,,,,,,,,,,,,,,
386.546,0.90961,1.24565,10,,,,,,,,,,,,,,,,,,,,,,,,,,,,,,,,,,,,,
387.246,0.9095,1.23912,10,,,,,,,,,,,,,,,,,,,,,,,,,,,,,,,,,,,,,
387.946,0.90944,1.33355,10,,,,,,,,,,,,,,,,,,,,,,,,,,,,,,,,,,,,,
388.646,0.90933,1.30759,10,,,,,,,,,,,,,,,,,,,,,,,,,,,,,,,,,,,,,
389.346,0.90916,1.16271,10,,,,,,,,,,,,,,,,,,,,,,,,,,,,,,,,,,,,,
390.046,0.90893,1.29053,10,,,,,,,,,,,,,,,,,,,,,,,,,,,,,,,,,,,,,
390.746,0.90865,1.33724,10,,,,,,,,,,,,,,,,,,,,,,,,,,,,,,,,,,,,,
391.446,0.9082,1.28602,10,,,,,,,,,,,,,,,,,,,,,,,,,,,,,,,,,,,,,
392.146,0.90746,1.2914,10,,,,,,,,,,,,,,,,,,,,,,,,,,,,,,,,,,,,,
392.846,0.90672,1.23049,10,,,,,,,,,,,,,,,,,,,,,,,,,,,,,,,,,,,,,
393.546,0.90587,1.26791,10,,,,,,,,,,,,,,,,,,,,,,,,,,,,,,,,,,,,,
394.246,0.90525,1.22851,10,,,,,,,,,,,,,,,,,,,,,,,,,,,,,,,,,,,,,
394.946,0.9048,1.21675,10,,,,,,,,,,,,,,,,,,,,,,,,,,,,,,,,,,,,,
395.646,0.90446,1.20782,10,,,,,,,,,,,,,,,,,,,,,,,,,,,,,,,,,,,,,
396.346,0.90423,1.26337,10,,,,,,,,,,,,,,,,,,,,,,,,,,,,,,,,,,,,,
397.046,0.90406,1.14083,10,,,,,,,,,,,,,,,,,,,,,,,,,,,,,,,,,,,,,
397.746,0.90417,1.1851,10,,,,,,,,,,,,,,,,,,,,,,,,,,,,,,,,,,,,,
398.446,0.90423,1.25116,10,,,,,,,,,,,,,,,,,,,,,,,,,,,,,,,,,,,,,
399.146,0.90429,1.21429,10,,,,,,,,,,,,,,,,,,,,,,,,,,,,,,,,,,,,,
399.846,0.90434,1.20906,10,,,,,,,,,,,,,,,,,,,,,,,,,,,,,,,,,,,,,
400.546,0.90446,1.17201,10,,,,,,,,,,,,,,,,,,,,,,,,,,,,,,,,,,,,,
401.246,0.90451,1.18287,10,,,,,,,,,,,,,,,,,,,,,,,,,,,,,,,,,,,,,
401.946,0.90457,1.22677,10,,,,,,,,,,,,,,,,,,,,,,,,,,,,,,,,,,,,,
402.646,0.90463,1.18807,10,,,,,,,,,,,,,,,,,,,,,,,,,,,,,,,,,,,,,
403.346,0.9048,1.17154,10,,,,,,,,,,,,,,,,,,,,,,,,,,,,,,,,,,,,,
404.046,0.90508,1.1291,10,,,,,,,,,,,,,,,,,,,,,,,,,,,,,,,,,,,,,
404.746,0.90565,1.2174,10,,,,,,,,,,,,,,,,,,,,,,,,,,,,,,,,,,,,,
405.446,0.9061,1.17905,10,,,,,,,,,,,,,,,,,,,,,,,,,,,,,,,,,,,,,
406.146,0.90684,1.22059,10,,,,,,,,,,,,,,,,,,,,,,,,,,,,,,,,,,,,,
406.846,0.90791,1.22113,10,,,,,,,,,,,,,,,,,,,,,,,,,,,,,,,,,,,,,
407.546,0.90916,1.21782,10,,,,,,,,,,,,,,,,,,,,,,,,,,,,,,,,,,,,,
408.246,0.91001,1.23604,10,,,,,,,,,,,,,,,,,,,,,,,,,,,,,,,,,,,,,
408.946,0.91018,1.22856,10,,,,,,,,,,,,,,,,,,,,,,,,,,,,,,,,,,,,,
409.646,0.91024,1.27493,10,,,,,,,,,,,,,,,,,,,,,,,,,,,,,,,,,,,,,
410.346,0.91007,1.25065,10,,,,,,,,,,,,,,,,,,,,,,,,,,,,,,,,,,,,,
411.046,0.90995,1.29571,10,,,,,,,,,,,,,,,,,,,,,,,,,,,,,,,,,,,,,
411.746,0.9099,1.25455,10,,,,,,,,,,,,,,,,,,,,,,,,,,,,,,,,,,,,,
412.446,0.90978,1.22059,10,,,,,,,,,,,,,,,,,,,,,,,,,,,,,,,,,,,,,
413.146,0.9095,1.28682,10,,,,,,,,,,,,,,,,,,,,,,,,,,,,,,,,,,,,,
413.846,0.90922,1.29755,10,,,,,,,,,,,,,,,,,,,,,,,,,,,,,,,,,,,,,
414.546,0.90876,1.277,10,,,,,,,,,,,,,,,,,,,,,,,,,,,,,,,,,,,,,
415.246,0.90803,1.32144,10,,,,,,,,,,,,,,,,,,,,,,,,,,,,,,,,,,,,,
415.946,0.90706,1.24232,10,,,,,,,,,,,,,,,,,,,,,,,,,,,,,,,,,,,,,
416.646,0.90599,1.27445,10,,,,,,,,,,,,,,,,,,,,,,,,,,,,,,,,,,,,,
417.346,0.90474,1.2461,10,,,,,,,,,,,,,,,,,,,,,,,,,,,,,,,,,,,,,
418.046,0.904,1.20816,10,,,,,,,,,,,,,,,,,,,,,,,,,,,,,,,,,,,,,
418.746,0.90355,1.23616,10,,,,,,,,,,,,,,,,,,,,,,,,,,,,,,,,,,,,,
419.446,0.90338,1.24717,10,,,,,,,,,,,,,,,,,,,,,,,,,,,,,,,,,,,,,
420.146,0.90344,1.20516,10,,,,,,,,,,,,,,,,,,,,,,,,,,,,,,,,,,,,,
420.846,0.90349,1.1932,10,,,,,,,,,,,,,,,,,,,,,,,,,,,,,,,,,,,,,
421.546,0.90349,1.21597,10,,,,,,,,,,,,,,,,,,,,,,,,,,,,,,,,,,,,,
422.246,0.90355,1.24273,10,,,,,,,,,,,,,,,,,,,,,,,,,,,,,,,,,,,,,
422.946,0.90355,1.18941,10,,,,,,,,,,,,,,,,,,,,,,,,,,,,,,,,,,,,,
423.646,0.90366,1.22064,10,,,,,,,,,,,,,,,,,,,,,,,,,,,,,,,,,,,,,
424.346,0.90372,1.24382,10,,,,,,,,,,,,,,,,,,,,,,,,,,,,,,,,,,,,,
425.046,0.90378,1.19354,10,,,,,,,,,,,,,,,,,,,,,,,,,,,,,,,,,,,,,
425.746,0.90383,1.22738,10,,,,,,,,,,,,,,,,,,,,,,,,,,,,,,,,,,,,,
426.446,0.90389,1.18736,10,,,,,,,,,,,,,,,,,,,,,,,,,,,,,,,,,,,,,
427.146,0.904,1.22138,10,,,,,,,,,,,,,,,,,,,,,,,,,,,,,,,,,,,,,
427.846,0.90429,1.15201,10,,,,,,,,,,,,,,,,,,,,,,,,,,,,,,,,,,,,,
428.546,0.9048,1.15244,10,,,,,,,,,,,,,,,,,,,,,,,,,,,,,,,,,,,,,
429.246,0.90542,1.2034,10,,,,,,,,,,,,,,,,,,,,,,,,,,,,,,,,,,,,,
429.946,0.9061,1.19573,10,,,,,,,,,,,,,,,,,,,,,,,,,,,,,,,,,,,,,
430.646,0.90661,1.19954,10,,,,,,,,,,,,,,,,,,,,,,,,,,,,,,,,,,,,,
431.346,0.90701,1.2146,10,,,,,,,,,,,,,,,,,,,,,,,,,,,,,,,,,,,,,
432.046,0.90718,1.21121,10,,,,,,,,,,,,,,,,,,,,,,,,,,,,,,,,,,,,,
432.746,0.90712,1.27978,10,,,,,,,,,,,,,,,,,,,,,,,,,,,,,,,,,,,,,
433.446,0.90718,1.283,10,,,,,,,,,,,,,,,,,,,,,,,,,,,,,,,,,,,,,
434.146,0.90706,1.24126,10,,,,,,,,,,,,,,,,,,,,,,,,,,,,,,,,,,,,,
434.846,0.90706,1.20306,10,,,,,,,,,,,,,,,,,,,,,,,,,,,,,,,,,,,,,
435.546,0.90701,1.2217,10,,,,,,,,,,,,,,,,,,,,,,,,,,,,,,,,,,,,,
436.246,0.90695,1.28835,10,,,,,,,,,,,,,,,,,,,,,,,,,,,,,,,,,,,,,
436.946,0.90695,1.23476,10,,,,,,,,,,,,,,,,,,,,,,,,,,,,,,,,,,,,,
437.646,0.90689,1.21335,10,,,,,,,,,,,,,,,,,,,,,,,,,,,,,,,,,,,,,
438.346,0.90684,1.27466,10,,,,,,,,,,,,,,,,,,,,,,,,,,,,,,,,,,,,,
439.046,0.90684,1.26344,10,,,,,,,,,,,,,,,,,,,,,,,,,,,,,,,,,,,,,
439.746,0.90684,1.19711,10,,,,,,,,,,,,,,,,,,,,,,,,,,,,,,,,,,,,,
440.446,0.90684,1.29399,10,,,,,,,,,,,,,,,,,,,,,,,,,,,,,,,,,,,,,
441.146,0.90672,1.21726,10,,,,,,,,,,,,,,,,,,,,,,,,,,,,,,,,,,,,,
441.846,0.90678,1.1819,10,,,,,,,,,,,,,,,,,,,,,,,,,,,,,,,,,,,,,
442.546,0.90678,1.21337,10,,,,,,,,,,,,,,,,,,,,,,,,,,,,,,,,,,,,,
443.246,0.90678,1.21915,10,,,,,,,,,,,,,,,,,,,,,,,,,,,,,,,,,,,,,
443.946,0.90678,1.2164,10,,,,,,,,,,,,,,,,,,,,,,,,,,,,,,,,,,,,,
444.646,0.90678,1.2441,10,,,,,,,,,,,,,,,,,,,,,,,,,,,,,,,,,,,,,
445.346,0.90678,1.22531,10,,,,,,,,,,,,,,,,,,,,,,,,,,,,,,,,,,,,,
446.046,0.90678,1.19074,10,,,,,,,,,,,,,,,,,,,,,,,,,,,,,,,,,,,,,
446.746,0.90667,1.239,10,,,,,,,,,,,,,,,,,,,,,,,,,,,,,,,,,,,,,
447.446,0.90667,1.17788,10,,,,,,,,,,,,,,,,,,,,,,,,,,,,,,,,,,,,,
448.146,0.90661,1.24206,10,,,,,,,,,,,,,,,,,,,,,,,,,,,,,,,,,,,,,
448.846,0.9065,1.26831,10,,,,,,,,,,,,,,,,,,,,,,,,,,,,,,,,,,,,,
449.546,0.90633,1.33827,10,,,,,,,,,,,,,,,,,,,,,,,,,,,,,,,,,,,,,
450.246,0.90604,1.26333,10,,,,,,,,,,,,,,,,,,,,,,,,,,,,,,,,,,,,,
450.946,0.90576,1.27015,10,,,,,,,,,,,,,,,,,,,,,,,,,,,,,,,,,,,,,
451.646,0.90548,1.27181,10,,,,,,,,,,,,,,,,,,,,,,,,,,,,,,,,,,,,,
452.346,0.90485,1.24506,10,,,,,,,,,,,,,,,,,,,,,,,,,,,,,,,,,,,,,
453.046,0.90429,1.29509,10,,,,,,,,,,,,,,,,,,,,,,,,,,,,,,,,,,,,,
453.746,0.90338,1.22394,10,,,,,,,,,,,,,,,,,,,,,,,,,,,,,,,,,,,,,
454.446,0.90293,1.23607,10,,,,,,,,,,,,,,,,,,,,,,,,,,,,,,,,,,,,,
455.146,0.90253,1.25288,10,,,,,,,,,,,,,,,,,,,,,,,,,,,,,,,,,,,,,
455.846,0.9023,1.17598,10,,,,,,,,,,,,,,,,,,,,,,,,,,,,,,,,,,,,,
456.546,0.90219,1.20377,10,,,,,,,,,,,,,,,,,,,,,,,,,,,,,,,,,,,,,
457.246,0.90219,1.16527,10,,,,,,,,,,,,,,,,,,,,,,,,,,,,,,,,,,,,,
457.946,0.9023,1.21718,10,,,,,,,,,,,,,,,,,,,,,,,,,,,,,,,,,,,,,
458.646,0.90236,1.1973,10,,,,,,,,,,,,,,,,,,,,,,,,,,,,,,,,,,,,,
459.346,0.90242,1.22337,10,,,,,,,,,,,,,,,,,,,,,,,,,,,,,,,,,,,,,
460.046,0.90247,1.162,10,,,,,,,,,,,,,,,,,,,,,,,,,,,,,,,,,,,,,
460.746,0.90253,1.20831,10,,,,,,,,,,,,,,,,,,,,,,,,,,,,,,,,,,,,,
461.446,0.90259,1.25401,10,,,,,,,,,,,,,,,,,,,,,,,,,,,,,,,,,,,,,
462.146,0.90264,1.21687,10,,,,,,,,,,,,,,,,,,,,,,,,,,,,,,,,,,,,,
462.846,0.90264,1.21639,10,,,,,,,,,,,,,,,,,,,,,,,,,,,,,,,,,,,,,
463.546,0.9027,1.23537,10,,,,,,,,,,,,,,,,,,,,,,,,,,,,,,,,,,,,,
464.246,0.90281,1.17279,10,,,,,,,,,,,,,,,,,,,,,,,,,,,,,,,,,,,,,
464.946,0.90304,1.18223,10,,,,,,,,,,,,,,,,,,,,,,,,,,,,,,,,,,,,,
465.646,0.90338,1.19141,10,,,,,,,,,,,,,,,,,,,,,,,,,,,,,,,,,,,,,
466.346,0.90366,1.17737,10,,,,,,,,,,,,,,,,,,,,,,,,,,,,,,,,,,,,,
467.046,0.90406,1.14442,10,,,,,,,,,,,,,,,,,,,,,,,,,,,,,,,,,,,,,
467.746,0.90468,1.22462,10,,,,,,,,,,,,,,,,,,,,,,,,,,,,,,,,,,,,,
468.446,0.90593,1.18543,10,,,,,,,,,,,,,,,,,,,,,,,,,,,,,,,,,,,,,
469.146,0.90712,1.24469,10,,,,,,,,,,,,,,,,,,,,,,,,,,,,,,,,,,,,,
469.846,0.90746,1.25265,10,,,,,,,,,,,,,,,,,,,,,,,,,,,,,,,,,,,,,
470.546,0.90763,1.27023,10,,,,,,,,,,,,,,,,,,,,,,,,,,,,,,,,,,,,,
471.246,0.90763,1.27944,10,,,,,,,,,,,,,,,,,,,,,,,,,,,,,,,,,,,,,
471.946,0.90752,1.25356,10,,,,,,,,,,,,,,,,,,,,,,,,,,,,,,,,,,,,,
472.646,0.90746,1.22874,10,,,,,,,,,,,,,,,,,,,,,,,,,,,,,,,,,,,,,
473.346,0.9074,1.26895,10,,,,,,,,,,,,,,,,,,,,,,,,,,,,,,,,,,,,,
474.046,0.90735,1.30404,10,,,,,,,,,,,,,,,,,,,,,,,,,,,,,,,,,,,,,
474.746,0.90729,1.26264,10,,,,,,,,,,,,,,,,,,,,,,,,,,,,,,,,,,,,,
475.446,0.90723,1.29206,10,,,,,,,,,,,,,,,,,,,,,,,,,,,,,,,,,,,,,
476.146,0.90695,1.31662,10,,,,,,,,,,,,,,,,,,,,,,,,,,,,,,,,,,,,,
476.846,0.90661,1.25343,10,,,,,,,,,,,,,,,,,,,,,,,,,,,,,,,,,,,,,
477.546,0.90621,1.26416,10,,,,,,,,,,,,,,,,,,,,,,,,,,,,,,,,,,,,,
478.246,0.90559,1.32134,10,,,,,,,,,,,,,,,,,,,,,,,,,,,,,,,,,,,,,
478.946,0.90491,1.23338,10,,,,,,,,,,,,,,,,,,,,,,,,,,,,,,,,,,,,,
479.646,0.904,1.2387,10,,,,,,,,,,,,,,,,,,,,,,,,,,,,,,,,,,,,,
480.346,0.90304,1.25217,10,,,,,,,,,,,,,,,,,,,,,,,,,,,,,,,,,,,,,
481.046,0.90236,1.23019,10,,,,,,,,,,,,,,,,,,,,,,,,,,,,,,,,,,,,,
481.746,0.90191,1.21639,10,,,,,,,,,,,,,,,,,,,,,,,,,,,,,,,,,,,,,
482.446,0.90168,1.27817,10,,,,,,,,,,,,,,,,,,,,,,,,,,,,,,,,,,,,,
483.146,0.90157,1.24571,10,,,,,,,,,,,,,,,,,,,,,,,,,,,,,,,,,,,,,
483.846,0.90157,1.16656,10,,,,,,,,,,,,,,,,,,,,,,,,,,,,,,,,,,,,,
484.546,0.90162,1.19148,10,,,,,,,,,,,,,,,,,,,,,,,,,,,,,,,,,,,,,
485.246,0.90179,1.14852,10,,,,,,,,,,,,,,,,,,,,,,,,,,,,,,,,,,,,,
485.946,0.90179,1.16763,10,,,,,,,,,,,,,,,,,,,,,,,,,,,,,,,,,,,,,
486.646,0.90185,1.22354,10,,,,,,,,,,,,,,,,,,,,,,,,,,,,,,,,,,,,,
487.346,0.90191,1.21927,10,,,,,,,,,,,,,,,,,,,,,,,,,,,,,,,,,,,,,
488.046,0.90196,1.23537,10,,,,,,,,,,,,,,,,,,,,,,,,,,,,,,,,,,,,,
488.746,0.90196,1.27167,10,,,,,,,,,,,,,,,,,,,,,,,,,,,,,,,,,,,,,
489.446,0.90196,1.20778,10,,,,,,,,,,,,,,,,,,,,,,,,,,,,,,,,,,,,,
490.146,0.90202,1.31264,10,,,,,,,,,,,,,,,,,,,,,,,,,,,,,,,,,,,,,
490.846,0.90208,1.21471,10,,,,,,,,,,,,,,,,,,,,,,,,,,,,,,,,,,,,,
491.546,0.90208,1.24183,10,,,,,,,,,,,,,,,,,,,,,,,,,,,,,,,,,,,,,
492.246,0.90213,1.17019,10,,,,,,,,,,,,,,,,,,,,,,,,,,,,,,,,,,,,,
492.946,0.90225,1.17856,10,,,,,,,,,,,,,,,,,,,,,,,,,,,,,,,,,,,,,
493.646,0.90247,1.12939,10,,,,,,,,,,,,,,,,,,,,,,,,,,,,,,,,,,,,,
494.346,0.90276,1.1704,10,,,,,,,,,,,,,,,,,,,,,,,,,,,,,,,,,,,,,
495.046,0.90315,1.17884,10,,,,,,,,,,,,,,,,,,,,,,,,,,,,,,,,,,,,,
495.746,0.90366,1.18052,10,,,,,,,,,,,,,,,,,,,,,,,,,,,,,,,,,,,,,
496.446,0.90468,1.18697,10,,,,,,,,,,,,,,,,,,,,,,,,,,,,,,,,,,,,,
497.146,0.90604,1.27029,10,,,,,,,,,,,,,,,,,,,,,,,,,,,,,,,,,,,,,
497.846,0.90661,1.21531,10,,,,,,,,,,,,,,,,,,,,,,,,,,,,,,,,,,,,,
498.546,0.90678,1.20783,10,,,,,,,,,,,,,,,,,,,,,,,,,,,,,,,,,,,,,
499.246,0.90667,1.2791,10,,,,,,,,,,,,,,,,,,,,,,,,,,,,,,,,,,,,,
499.946,0.90667,1.22139,10,,,,,,,,,,,,,,,,,,,,,,,,,,,,,,,,,,,,,
500.646,0.90661,1.21851,10,,,,,,,,,,,,,,,,,,,,,,,,,,,,,,,,,,,,,
501.346,0.9065,1.24397,10,,,,,,,,,,,,,,,,,,,,,,,,,,,,,,,,,,,,,
501.948,2.31534,26.66341,10,,,,,,,,,,,,,,,,,,,,,,,,,,,,,,,,,,,,,
502.648,8.15637,280.80557,10,,,,,,,,,,,,,,,,,,,,,,,,,,,,,,,,,,,,,
503.348,13.98975,354.32944,10,,,,,,,,,,,,,,,,,,,,,,,,,,,,,,,,,,,,,
504.048,19.82307,40.94267,10,,,,,,,,,,,,,,,,,,,,,,,,,,,,,,,,,,,,,
504.748,25.65651,20.84065,10,,,,,,,,,,,,,,,,,,,,,,,,,,,,,,,,,,,,,
505.448,31.48978,-0.58928,10,,,,,,,,,,,,,,,,,,,,,,,,,,,,,,,,,,,,,
506.148,37.3231,-5.12103,10,,,,,,,,,,,,,,,,,,,,,,,,,,,,,,,,,,,,,
506.848,43.15643,-6.74496,10,,,,,,,,,,,,,,,,,,,,,,,,,,,,,,,,,,,,,
507.548,48.98975,-6.71563,10,,,,,,,,,,,,,,,,,,,,,,,,,,,,,,,,,,,,,
508.248,54.82301,-8.43797,10,,,,,,,,,,,,,,,,,,,,,,,,,,,,,,,,,,,,,
508.948,60.65651,-8.62918,10,,,,,,,,,,,,,,,,,,,,,,,,,,,,,,,,,,,,,
509.648,66.48971,-8.71695,10,,,,,,,,,,,,,,,,,,,,,,,,,,,,,,,,,,,,,
509.924,68.78976,-8.66752,10,,,,,,,,,,,,,,,,,,,,,,,,,,,,,,,,,,,,,