File: combined_ligament_solver/data/processed/Data Sheet 3_S160134_MCL.csv
Specimen properties : Length,40,mm,Unnamed: 3,Unnamed: 4,Unnamed: 5,Unnamed: 6,Unnamed: 7,Unnamed: 8,Unnamed: 9,Unnamed: 10,Unnamed: 11,Stress-Strain,Unnamed: 13,Unnamed: 14,Unnamed: 15,Unnamed: 16,Unnamed: 17,Unnamed: 18,Unnamed: 19,Unnamed: 20,Unnamed: 21,Unnamed: 22,Unnamed: 23,Unnamed: 24,Unnamed: 25,Unnamed: 26,Unnamed: 27,Linear,Unnamed: 29,Unnamed: 30,Unnamed: 31,Unnamed: 32,Unnamed: 33,Modulus,Unnamed: 35,Failure,Unnamed: 37,Unnamed: 38,Unnamed: 39,Unnamed: 40
Cross Section Average,18.191499999999998,mm2,,,,,,,,,,Polynomial Coefficients,,,,,,,,,,,,,,,,Force,,Stress,Extension,Strain,,Secant,Tangent,Load,Stress,Extension,Strain,Stiffness
Time,Extension,Load,Total cycle count,,,Extension,Load,Strain,Stress,E-tan,,X6,-18426171.980517384,,,,,,,,,Strain,Stress,E-tan,,,,(N),,(MPa),(mm),(%),,(MPa),(MPa),(N),(MPa),(mm),(%),(N/mm)
(s),(mm),(N),,,,(mm),(N),(mm/mm),(MPa),(MPa),,X5,4962702.116787944,,,,,,,,,(mm/mm),(MPa),(MPa),,,,39.55822585227874,,2.1745444769413598,3.5999999999999996,9,,24.161605299348444,40.91318352654079,41.60432,2.2390764917681336,4.86676,12.1669,10.98839607007743
0.9,0.28934,2.24257,0,,,8.22868,23.80864,,,,,,,,,,,,,,,0.009,0.07464141450447369,10.006722440508076,,,,,,,,,,,,,,,,
1.9,0.45594,3.5813,0,,,16.56196,0.87919,,,,,,,,,,,,,,,0.019,0.20796703393504148,16.09111771108247,,,,,,,,,,,,,,,,
2.9,0.62265,4.95137,0,,,24.89537,-4.45307,,,,,,,,,,,,,,,0.029,0.39726137458589655,20.902095905224996,,,,,,,,,,,,,,,,
3.9,0.78914,6.27404,0,,,,,,,,,,,,,,,,,,,0.039,0.6215473376868683,23.366572976209785,,,,,,,,,,,,,,,,
4.9,0.95585,7.53609,0,,,,,,,,,,,,,,,,,,,0.049,0.8621695548897617,24.58565692705503,,,,,,,,,,,,,,,,
5.9,1.12245,8.89011,0,,,,,,,,,,,,,,,,,,,0.059,1.1172395446615022,26.507963427923436,,,,,,,,,,,,,,,,
6.9,1.28911,10.54333,0,,,,,,,,,,,,,,,,,,,0.069,1.402814024851316,30.602931433527182,,,,,,,,,,,,,,,,
7.9,1.45588,12.28414,0,,,,,,,,,,,,,,,,,,,0.079,1.7408063814319354,36.534138800535096,,,,,,,,,,,,,,,,
8.9,1.62242,14.01649,0,,,,,,,,,,,,,,,,,,,0.089,2.133631293414819,40.83261790495692,,,,,,,,,,,,,,,,
9.9,1.78925,15.86508,0,,,,,,,,,,,,,,,,,,,0.099,2.5255825139394323,35.57017125958058,,,,,,,,,,,,,,,,
10.9,1.95579,17.63908,0,,,,,,,,,,,,,,,,,,,0.109,,,,,,,,,,,,,,,,,,
11.9,2.12256,19.49753,0,,,,,,,,,,,,,,,,,,,0.119,,,,,,,,,,,,,,,,,,
12.9,2.28922,21.34936,0,,,,,,,,,,,,,,,,,,,0.129,,,,,,,,,,,,,,,,,,
13.9,2.45588,23.1741,0,,,,,,,,,,,,,,,,,,,0.139,,,,,,,,,,,,,,,,,,
14.9,2.62259,25.08341,0,,,,,,,,,,,,,,,,,,,0.149,,,,,,,,,,,,,,,,,,
15.9,2.7893,27.04103,0,,,,,,,,,,,,,,,,,,,0.159,,,,,,,,,,,,,,,,,,
16.9,2.95602,28.94087,0,,,,,,,,,,,,,,,,,,,0.169,,,,,,,,,,,,,,,,,,
17.9,3.12262,31.03397,0,,,,,,,,,,,,,,,,,,,0.179,,,,,,,,,,,,,,,,,,
18.9,3.28927,33.05175,0,,,,,,,,,,,,,,,,,,,0.189,,,,,,,,,,,,,,,,,,
19.9,3.45587,35.19223,0,,,,,,,,,,,,,,,,,,,0.199,,,,,,,,,,,,,,,,,,
20.9,3.62253,37.34879,0,,,,,,,,,,,,,,,,,,,,,,,,,,,,,,,,,,,,,
21.9,3.78913,39.48568,0,,,,,,,,,,,,,,,,,,,,,,,,,,,,,,,,,,,,,
22.736,3.72821,37.1034,0.5,,,,,,,,,,,,,,,,,,,,,,,,,,,,,,,,,,,,,
23.736,3.5615,33.29893,0.5,,,,,,,,,,,,,,,,,,,,,,,,,,,,,,,,,,,,,
24.736,3.39473,30.17545,0.5,,,,,,,,,,,,,,,,,,,,,,,,,,,,,,,,,,,,,
25.736,3.22824,27.3345,0.5,,,,,,,,,,,,,,,,,,,,,,,,,,,,,,,,,,,,,
26.736,3.06153,24.86455,0.5,,,,,,,,,,,,,,,,,,,,,,,,,,,,,,,,,,,,,
27.736,2.89493,22.50545,0.5,,,,,,,,,,,,,,,,,,,,,,,,,,,,,,,,,,,,,
28.736,2.72833,20.33347,0.5,,,,,,,,,,,,,,,,,,,,,,,,,,,,,,,,,,,,,
29.736,2.56162,18.32284,0.5,,,,,,,,,,,,,,,,,,,,,,,,,,,,,,,,,,,,,
30.736,2.39496,16.42967,0.5,,,,,,,,,,,,,,,,,,,,,,,,,,,,,,,,,,,,,
31.736,2.22825,14.65864,0.5,,,,,,,,,,,,,,,,,,,,,,,,,,,,,,,,,,,,,
32.736,2.06165,12.92292,0.5,,,,,,,,,,,,,,,,,,,,,,,,,,,,,,,,,,,,,
33.736,1.89488,11.2837,0.5,,,,,,,,,,,,,,,,,,,,,,,,,,,,,,,,,,,,,
34.736,1.72833,9.81029,0.5,,,,,,,,,,,,,,,,,,,,,,,,,,,,,,,,,,,,,
35.736,1.56156,8.3369,0.5,,,,,,,,,,,,,,,,,,,,,,,,,,,,,,,,,,,,,
36.736,1.39491,6.89098,0.5,,,,,,,,,,,,,,,,,,,,,,,,,,,,,,,,,,,,,
37.736,1.22819,5.65959,0.5,,,,,,,,,,,,,,,,,,,,,,,,,,,,,,,,,,,,,
38.736,1.06142,4.4183,0.5,,,,,,,,,,,,,,,,,,,,,,,,,,,,,,,,,,,,,
39.736,0.89477,3.30043,0.5,,,,,,,,,,,,,,,,,,,,,,,,,,,,,,,,,,,,,
40.736,0.72817,2.22837,0.5,,,,,,,,,,,,,,,,,,,,,,,,,,,,,,,,,,,,,
41.736,0.56151,1.31566,0.5,,,,,,,,,,,,,,,,,,,,,,,,,,,,,,,,,,,,,
42.534,0.59608,1.60662,1,,,,,,,,,,,,,,,,,,,,,,,,,,,,,,,,,,,,,
43.534,0.7629,2.86341,1,,,,,,,,,,,,,,,,,,,,,,,,,,,,,,,,,,,,,
44.534,0.9295,4.17814,1,,,,,,,,,,,,,,,,,,,,,,,,,,,,,,,,,,,,,
45.534,1.09627,5.55314,1,,,,,,,,,,,,,,,,,,,,,,,,,,,,,,,,,,,,,
46.534,1.26293,6.96714,1,,,,,,,,,,,,,,,,,,,,,,,,,,,,,,,,,,,,,
47.534,1.42959,8.41741,1,,,,,,,,,,,,,,,,,,,,,,,,,,,,,,,,,,,,,
48.534,1.59636,9.97266,1,,,,,,,,,,,,,,,,,,,,,,,,,,,,,,,,,,,,,
49.534,1.76296,11.64626,1,,,,,,,,,,,,,,,,,,,,,,,,,,,,,,,,,,,,,
50.534,1.92967,13.35703,1,,,,,,,,,,,,,,,,,,,,,,,,,,,,,,,,,,,,,
51.534,2.09621,15.13636,1,,,,,,,,,,,,,,,,,,,,,,,,,,,,,,,,,,,,,
52.534,2.26287,16.97619,1,,,,,,,,,,,,,,,,,,,,,,,,,,,,,,,,,,,,,
53.534,2.42947,18.91299,1,,,,,,,,,,,,,,,,,,,,,,,,,,,,,,,,,,,,,
54.534,2.59618,20.87484,1,,,,,,,,,,,,,,,,,,,,,,,,,,,,,,,,,,,,,
55.534,2.76278,22.92078,1,,,,,,,,,,,,,,,,,,,,,,,,,,,,,,,,,,,,,
56.534,2.9295,25.10316,1,,,,,,,,,,,,,,,,,,,,,,,,,,,,,,,,,,,,,
57.534,3.09621,27.33012,1,,,,,,,,,,,,,,,,,,,,,,,,,,,,,,,,,,,,,
58.534,3.26281,29.6705,1,,,,,,,,,,,,,,,,,,,,,,,,,,,,,,,,,,,,,
59.534,3.42952,32.20368,1,,,,,,,,,,,,,,,,,,,,,,,,,,,,,,,,,,,,,
60.534,3.59618,34.6217,1,,,,,,,,,,,,,,,,,,,,,,,,,,,,,,,,,,,,,
61.534,3.76289,37.13576,1,,,,,,,,,,,,,,,,,,,,,,,,,,,,,,,,,,,,,
62.534,3.92955,39.72366,1,,,,,,,,,,,,,,,,,,,,,,,,,,,,,,,,,,,,,
63.354,3.83265,36.84954,1.5,,,,,,,,,,,,,,,,,,,,,,,,,,,,,,,,,,,,,
64.354,3.66588,33.21428,1.5,,,,,,,,,,,,,,,,,,,,,,,,,,,,,,,,,,,,,
65.354,3.49917,30.09513,1.5,,,,,,,,,,,,,,,,,,,,,,,,,,,,,,,,,,,,,
66.354,3.33245,27.40619,1.5,,,,,,,,,,,,,,,,,,,,,,,,,,,,,,,,,,,,,
67.354,3.1658,24.84898,1.5,,,,,,,,,,,,,,,,,,,,,,,,,,,,,,,,,,,,,
68.354,2.9992,22.57651,1.5,,,,,,,,,,,,,,,,,,,,,,,,,,,,,,,,,,,,,
69.354,2.83248,20.41872,1.5,,,,,,,,,,,,,,,,,,,,,,,,,,,,,,,,,,,,,
70.354,2.66594,18.45679,1.5,,,,,,,,,,,,,,,,,,,,,,,,,,,,,,,,,,,,,
71.354,2.49928,16.62947,1.5,,,,,,,,,,,,,,,,,,,,,,,,,,,,,,,,,,,,,
72.354,2.33263,14.77524,1.5,,,,,,,,,,,,,,,,,,,,,,,,,,,,,,,,,,,,,
73.354,2.16597,13.06786,1.5,,,,,,,,,,,,,,,,,,,,,,,,,,,,,,,,,,,,,
74.354,1.99931,11.47529,1.5,,,,,,,,,,,,,,,,,,,,,,,,,,,,,,,,,,,,,
75.354,1.8326,9.92382,1.5,,,,,,,,,,,,,,,,,,,,,,,,,,,,,,,,,,,,,
76.354,1.66594,8.53965,1.5,,,,,,,,,,,,,,,,,,,,,,,,,,,,,,,,,,,,,
77.354,1.49929,7.162,1.5,,,,,,,,,,,,,,,,,,,,,,,,,,,,,,,,,,,,,
78.354,1.33257,5.81189,1.5,,,,,,,,,,,,,,,,,,,,,,,,,,,,,,,,,,,,,
79.354,1.16592,4.60624,1.5,,,,,,,,,,,,,,,,,,,,,,,,,,,,,,,,,,,,,
80.354,0.9992,3.51078,1.5,,,,,,,,,,,,,,,,,,,,,,,,,,,,,,,,,,,,,
81.354,0.83255,2.45684,1.5,,,,,,,,,,,,,,,,,,,,,,,,,,,,,,,,,,,,,
82.354,0.66578,1.51598,1.5,,,,,,,,,,,,,,,,,,,,,,,,,,,,,,,,,,,,,
83.14,0.60208,1.2408,2,,,,,,,,,,,,,,,,,,,,,,,,,,,,,,,,,,,,,
84.14,0.76908,2.4741,2,,,,,,,,,,,,,,,,,,,,,,,,,,,,,,,,,,,,,
85.14,0.93591,3.75545,2,,,,,,,,,,,,,,,,,,,,,,,,,,,,,,,,,,,,,
86.14,1.10251,5.04219,2,,,,,,,,,,,,,,,,,,,,,,,,,,,,,,,,,,,,,
87.14,1.26922,6.37484,2,,,,,,,,,,,,,,,,,,,,,,,,,,,,,,,,,,,,,
88.14,1.43588,7.79107,2,,,,,,,,,,,,,,,,,,,,,,,,,,,,,,,,,,,,,
89.14,1.60265,9.29712,2,,,,,,,,,,,,,,,,,,,,,,,,,,,,,,,,,,,,,
90.14,1.76936,10.94873,2,,,,,,,,,,,,,,,,,,,,,,,,,,,,,,,,,,,,,
91.14,1.9359,12.58504,2,,,,,,,,,,,,,,,,,,,,,,,,,,,,,,,,,,,,,
92.14,2.10267,14.36796,2,,,,,,,,,,,,,,,,,,,,,,,,,,,,,,,,,,,,,
93.14,2.26927,16.16764,2,,,,,,,,,,,,,,,,,,,,,,,,,,,,,,,,,,,,,
94.14,2.43593,18.09851,2,,,,,,,,,,,,,,,,,,,,,,,,,,,,,,,,,,,,,
95.14,2.60253,19.9048,2,,,,,,,,,,,,,,,,,,,,,,,,,,,,,,,,,,,,,
96.14,2.76919,21.95132,2,,,,,,,,,,,,,,,,,,,,,,,,,,,,,,,,,,,,,
97.14,2.93579,24.04862,2,,,,,,,,,,,,,,,,,,,,,,,,,,,,,,,,,,,,,
98.14,3.1025,26.27305,2,,,,,,,,,,,,,,,,,,,,,,,,,,,,,,,,,,,,,
99.14,3.26916,28.61829,2,,,,,,,,,,,,,,,,,,,,,,,,,,,,,,,,,,,,,
100.14,3.43576,31.06349,2,,,,,,,,,,,,,,,,,,,,,,,,,,,,,,,,,,,,,
101.14,3.60253,33.53806,2,,,,,,,,,,,,,,,,,,,,,,,,,,,,,,,,,,,,,
102.14,3.76913,36.11582,2,,,,,,,,,,,,,,,,,,,,,,,,,,,,,,,,,,,,,
103.14,3.9359,38.77634,2,,,,,,,,,,,,,,,,,,,,,,,,,,,,,,,,,,,,,
104,3.94559,38.23422,2.5,,,,,,,,,,,,,,,,,,,,,,,,,,,,,,,,,,,,,
105,3.77887,34.30219,2.5,,,,,,,,,,,,,,,,,,,,,,,,,,,,,,,,,,,,,
106,3.6121,31.04137,2.5,,,,,,,,,,,,,,,,,,,,,,,,,,,,,,,,,,,,,
107,3.44556,28.21686,2.5,,,,,,,,,,,,,,,,,,,,,,,,,,,,,,,,,,,,,
108,3.27879,25.69166,2.5,,,,,,,,,,,,,,,,,,,,,,,,,,,,,,,,,,,,,
109,3.11219,23.3244,2.5,,,,,,,,,,,,,,,,,,,,,,,,,,,,,,,,,,,,,
110,2.94553,21.13309,2.5,,,,,,,,,,,,,,,,,,,,,,,,,,,,,,,,,,,,,
111,2.77888,19.12771,2.5,,,,,,,,,,,,,,,,,,,,,,,,,,,,,,,,,,,,,
112,2.61228,17.21449,2.5,,,,,,,,,,,,,,,,,,,,,,,,,,,,,,,,,,,,,
113,2.44562,15.43252,2.5,,,,,,,,,,,,,,,,,,,,,,,,,,,,,,,,,,,,,
114,2.27896,13.79401,2.5,,,,,,,,,,,,,,,,,,,,,,,,,,,,,,,,,,,,,
115,2.11231,12.09001,2.5,,,,,,,,,,,,,,,,,,,,,,,,,,,,,,,,,,,,,
116,1.94565,10.56523,2.5,,,,,,,,,,,,,,,,,,,,,,,,,,,,,,,,,,,,,
117,1.77888,9.15268,2.5,,,,,,,,,,,,,,,,,,,,,,,,,,,,,,,,,,,,,
118,1.61228,7.68461,2.5,,,,,,,,,,,,,,,,,,,,,,,,,,,,,,,,,,,,,
119,1.44562,6.42205,2.5,,,,,,,,,,,,,,,,,,,,,,,,,,,,,,,,,,,,,
120,1.27891,5.16013,2.5,,,,,,,,,,,,,,,,,,,,,,,,,,,,,,,,,,,,,
121,1.11225,3.99466,2.5,,,,,,,,,,,,,,,,,,,,,,,,,,,,,,,,,,,,,
122,0.94543,2.9308,2.5,,,,,,,,,,,,,,,,,,,,,,,,,,,,,,,,,,,,,
123,0.77883,1.93589,2.5,,,,,,,,,,,,,,,,,,,,,,,,,,,,,,,,,,,,,
124,0.61211,1.09774,2.5,,,,,,,,,,,,,,,,,,,,,,,,,,,,,,,,,,,,,
124.76,0.71989,1.79672,3,,,,,,,,,,,,,,,,,,,,,,,,,,,,,,,,,,,,,
125.76,0.88644,3.08534,3,,,,,,,,,,,,,,,,,,,,,,,,,,,,,,,,,,,,,
126.76,1.05315,4.28412,3,,,,,,,,,,,,,,,,,,,,,,,,,,,,,,,,,,,,,
127.76,1.21986,5.6764,3,,,,,,,,,,,,,,,,,,,,,,,,,,,,,,,,,,,,,
128.76,1.38652,7.02975,3,,,,,,,,,,,,,,,,,,,,,,,,,,,,,,,,,,,,,
129.76,1.55323,8.42623,3,,,,,,,,,,,,,,,,,,,,,,,,,,,,,,,,,,,,,
130.76,1.71989,9.98994,3,,,,,,,,,,,,,,,,,,,,,,,,,,,,,,,,,,,,,
131.76,1.88666,11.57577,3,,,,,,,,,,,,,,,,,,,,,,,,,,,,,,,,,,,,,
132.76,2.05326,13.29144,3,,,,,,,,,,,,,,,,,,,,,,,,,,,,,,,,,,,,,
133.76,2.22003,15.04642,3,,,,,,,,,,,,,,,,,,,,,,,,,,,,,,,,,,,,,
134.76,2.38657,16.89039,3,,,,,,,,,,,,,,,,,,,,,,,,,,,,,,,,,,,,,
135.76,2.55334,18.71415,3,,,,,,,,,,,,,,,,,,,,,,,,,,,,,,,,,,,,,
136.76,2.71994,20.67726,3,,,,,,,,,,,,,,,,,,,,,,,,,,,,,,,,,,,,,
137.76,2.88654,22.75242,3,,,,,,,,,,,,,,,,,,,,,,,,,,,,,,,,,,,,,
138.76,3.0532,24.84082,3,,,,,,,,,,,,,,,,,,,,,,,,,,,,,,,,,,,,,
139.76,3.21974,27.11635,3,,,,,,,,,,,,,,,,,,,,,,,,,,,,,,,,,,,,,
140.76,3.38651,29.53699,3,,,,,,,,,,,,,,,,,,,,,,,,,,,,,,,,,,,,,
141.76,3.55311,31.99923,3,,,,,,,,,,,,,,,,,,,,,,,,,,,,,,,,,,,,,
142.76,3.71994,34.66646,3,,,,,,,,,,,,,,,,,,,,,,,,,,,,,,,,,,,,,
143.76,3.88654,37.19334,3,,,,,,,,,,,,,,,,,,,,,,,,,,,,,,,,,,,,,
144.76,4.0532,39.89546,3,,,,,,,,,,,,,,,,,,,,,,,,,,,,,,,,,,,,,
145.582,3.92332,36.432,3.5,,,,,,,,,,,,,,,,,,,,,,,,,,,,,,,,,,,,,
146.582,3.75666,32.87878,3.5,,,,,,,,,,,,,,,,,,,,,,,,,,,,,,,,,,,,,
147.582,3.58989,29.82098,3.5,,,,,,,,,,,,,,,,,,,,,,,,,,,,,,,,,,,,,
148.582,3.42335,27.13701,3.5,,,,,,,,,,,,,,,,,,,,,,,,,,,,,,,,,,,,,
149.582,3.25658,24.65543,3.5,,,,,,,,,,,,,,,,,,,,,,,,,,,,,,,,,,,,,
150.582,3.08992,22.38062,3.5,,,,,,,,,,,,,,,,,,,,,,,,,,,,,,,,,,,,,
151.582,2.92321,20.28966,3.5,,,,,,,,,,,,,,,,,,,,,,,,,,,,,,,,,,,,,
152.582,2.75649,18.24478,3.5,,,,,,,,,,,,,,,,,,,,,,,,,,,,,,,,,,,,,
153.582,2.58984,16.45548,3.5,,,,,,,,,,,,,,,,,,,,,,,,,,,,,,,,,,,,,
154.582,2.42312,14.75158,3.5,,,,,,,,,,,,,,,,,,,,,,,,,,,,,,,,,,,,,
155.582,2.25647,13.03292,3.5,,,,,,,,,,,,,,,,,,,,,,,,,,,,,,,,,,,,,
156.582,2.08975,11.4968,3.5,,,,,,,,,,,,,,,,,,,,,,,,,,,,,,,,,,,,,
157.582,1.92321,10.00234,3.5,,,,,,,,,,,,,,,,,,,,,,,,,,,,,,,,,,,,,
158.582,1.75655,8.56181,3.5,,,,,,,,,,,,,,,,,,,,,,,,,,,,,,,,,,,,,
159.582,1.59001,7.20397,3.5,,,,,,,,,,,,,,,,,,,,,,,,,,,,,,,,,,,,,
160.582,1.4233,5.90167,3.5,,,,,,,,,,,,,,,,,,,,,,,,,,,,,,,,,,,,,
161.582,1.25658,4.71824,3.5,,,,,,,,,,,,,,,,,,,,,,,,,,,,,,,,,,,,,
162.582,1.08998,3.60284,3.5,,,,,,,,,,,,,,,,,,,,,,,,,,,,,,,,,,,,,
163.582,0.92321,2.5519,3.5,,,,,,,,,,,,,,,,,,,,,,,,,,,,,,,,,,,,,
164.582,0.75661,1.63815,3.5,,,,,,,,,,,,,,,,,,,,,,,,,,,,,,,,,,,,,
165.326,0.63257,0.9846,4,,,,,,,,,,,,,,,,,,,,,,,,,,,,,,,,,,,,,
166.326,0.80025,2.21281,4,,,,,,,,,,,,,,,,,,,,,,,,,,,,,,,,,,,,,
167.326,0.96702,3.35757,4,,,,,,,,,,,,,,,,,,,,,,,,,,,,,,,,,,,,,
168.326,1.13356,4.67737,4,,,,,,,,,,,,,,,,,,,,,,,,,,,,,,,,,,,,,
169.326,1.30016,6.01317,4,,,,,,,,,,,,,,,,,,,,,,,,,,,,,,,,,,,,,
170.326,1.46687,7.46373,4,,,,,,,,,,,,,,,,,,,,,,,,,,,,,,,,,,,,,
171.326,1.63342,8.8842,4,,,,,,,,,,,,,,,,,,,,,,,,,,,,,,,,,,,,,
172.326,1.80024,10.45714,4,,,,,,,,,,,,,,,,,,,,,,,,,,,,,,,,,,,,,
173.326,1.96679,11.998,4,,,,,,,,,,,,,,,,,,,,,,,,,,,,,,,,,,,,,
174.326,2.1335,13.76963,4,,,,,,,,,,,,,,,,,,,,,,,,,,,,,,,,,,,,,
175.326,2.30016,15.49044,4,,,,,,,,,,,,,,,,,,,,,,,,,,,,,,,,,,,,,
176.326,2.46693,17.28039,4,,,,,,,,,,,,,,,,,,,,,,,,,,,,,,,,,,,,,
177.326,2.63347,19.14991,4,,,,,,,,,,,,,,,,,,,,,,,,,,,,,,,,,,,,,
178.326,2.80018,21.10657,4,,,,,,,,,,,,,,,,,,,,,,,,,,,,,,,,,,,,,
179.326,2.96695,23.14703,4,,,,,,,,,,,,,,,,,,,,,,,,,,,,,,,,,,,,,
180.326,3.13355,25.36384,4,,,,,,,,,,,,,,,,,,,,,,,,,,,,,,,,,,,,,
181.326,3.30038,27.65666,4,,,,,,,,,,,,,,,,,,,,,,,,,,,,,,,,,,,,,
182.326,3.46692,30.0368,4,,,,,,,,,,,,,,,,,,,,,,,,,,,,,,,,,,,,,
183.326,3.63364,32.56792,4,,,,,,,,,,,,,,,,,,,,,,,,,,,,,,,,,,,,,
184.326,3.80029,35.18861,4,,,,,,,,,,,,,,,,,,,,,,,,,,,,,,,,,,,,,
185.326,3.96695,37.83101,4,,,,,,,,,,,,,,,,,,,,,,,,,,,,,,,,,,,,,
186.146,4.10352,40.0106,4.5,,,,,,,,,,,,,,,,,,,,,,,,,,,,,,,,,,,,,
187.146,3.93669,35.7336,4.5,,,,,,,,,,,,,,,,,,,,,,,,,,,,,,,,,,,,,
188.146,3.76998,32.29082,4.5,,,,,,,,,,,,,,,,,,,,,,,,,,,,,,,,,,,,,
189.146,3.60321,29.33411,4.5,,,,,,,,,,,,,,,,,,,,,,,,,,,,,,,,,,,,,
190.146,3.43655,26.67577,4.5,,,,,,,,,,,,,,,,,,,,,,,,,,,,,,,,,,,,,
191.146,3.26984,24.20284,4.5,,,,,,,,,,,,,,,,,,,,,,,,,,,,,,,,,,,,,
192.146,3.10307,22.01408,4.5,,,,,,,,,,,,,,,,,,,,,,,,,,,,,,,,,,,,,
193.146,2.93647,19.87441,4.5,,,,,,,,,,,,,,,,,,,,,,,,,,,,,,,,,,,,,
194.146,2.76981,17.9471,4.5,,,,,,,,,,,,,,,,,,,,,,,,,,,,,,,,,,,,,
195.146,2.60315,16.143,4.5,,,,,,,,,,,,,,,,,,,,,,,,,,,,,,,,,,,,,
196.146,2.43655,14.46267,4.5,,,,,,,,,,,,,,,,,,,,,,,,,,,,,,,,,,,,,
197.146,2.26995,12.76235,4.5,,,,,,,,,,,,,,,,,,,,,,,,,,,,,,,,,,,,,
198.146,2.10324,11.2026,4.5,,,,,,,,,,,,,,,,,,,,,,,,,,,,,,,,,,,,,
199.146,1.93664,9.73749,4.5,,,,,,,,,,,,,,,,,,,,,,,,,,,,,,,,,,,,,
200.146,1.76993,8.36054,4.5,,,,,,,,,,,,,,,,,,,,,,,,,,,,,,,,,,,,,
201.146,1.60321,7.01259,4.5,,,,,,,,,,,,,,,,,,,,,,,,,,,,,,,,,,,,,
202.146,1.43667,5.79218,4.5,,,,,,,,,,,,,,,,,,,,,,,,,,,,,,,,,,,,,
203.146,1.26996,4.54719,4.5,,,,,,,,,,,,,,,,,,,,,,,,,,,,,,,,,,,,,
204.146,1.1033,3.45306,4.5,,,,,,,,,,,,,,,,,,,,,,,,,,,,,,,,,,,,,
205.146,0.93659,2.45099,4.5,,,,,,,,,,,,,,,,,,,,,,,,,,,,,,,,,,,,,
206.146,0.76999,1.47566,4.5,,,,,,,,,,,,,,,,,,,,,,,,,,,,,,,,,,,,,
206.944,0.70408,1.22295,5,,,,,,,,,,,,,,,,,,,,,,,,,,,,,,,,,,,,,
207.944,0.87119,2.44127,5,,,,,,,,,,,,,,,,,,,,,,,,,,,,,,,,,,,,,
208.944,1.03785,3.69158,5,,,,,,,,,,,,,,,,,,,,,,,,,,,,,,,,,,,,,
209.944,1.20462,4.95978,5,,,,,,,,,,,,,,,,,,,,,,,,,,,,,,,,,,,,,
210.944,1.37133,6.28954,5,,,,,,,,,,,,,,,,,,,,,,,,,,,,,,,,,,,,,
211.944,1.53799,7.67966,5,,,,,,,,,,,,,,,,,,,,,,,,,,,,,,,,,,,,,
212.944,1.70465,9.13787,5,,,,,,,,,,,,,,,,,,,,,,,,,,,,,,,,,,,,,
213.944,1.87119,10.66571,5,,,,,,,,,,,,,,,,,,,,,,,,,,,,,,,,,,,,,
214.944,2.0379,12.34069,5,,,,,,,,,,,,,,,,,,,,,,,,,,,,,,,,,,,,,
215.944,2.20445,14.03066,5,,,,,,,,,,,,,,,,,,,,,,,,,,,,,,,,,,,,,
216.944,2.37116,15.76353,5,,,,,,,,,,,,,,,,,,,,,,,,,,,,,,,,,,,,,
217.944,2.53776,17.5934,5,,,,,,,,,,,,,,,,,,,,,,,,,,,,,,,,,,,,,
218.944,2.70453,19.52553,5,,,,,,,,,,,,,,,,,,,,,,,,,,,,,,,,,,,,,
219.944,2.87113,21.41701,5,,,,,,,,,,,,,,,,,,,,,,,,,,,,,,,,,,,,,
220.944,3.0379,23.48433,5,,,,,,,,,,,,,,,,,,,,,,,,,,,,,,,,,,,,,
221.944,3.20456,25.71302,5,,,,,,,,,,,,,,,,,,,,,,,,,,,,,,,,,,,,,
222.944,3.37116,28.01745,5,,,,,,,,,,,,,,,,,,,,,,,,,,,,,,,,,,,,,
223.944,3.53793,30.44621,5,,,,,,,,,,,,,,,,,,,,,,,,,,,,,,,,,,,,,
224.944,3.70453,32.98139,5,,,,,,,,,,,,,,,,,,,,,,,,,,,,,,,,,,,,,
225.944,3.87124,35.56725,5,,,,,,,,,,,,,,,,,,,,,,,,,,,,,,,,,,,,,
226.944,4.0379,38.26713,5,,,,,,,,,,,,,,,,,,,,,,,,,,,,,,,,,,,,,
227.822,4.11763,39.0689,5.5,,,,,,,,,,,,,,,,,,,,,,,,,,,,,,,,,,,,,
228.822,3.95052,34.12502,5.5,,,,,,,,,,,,,,,,,,,,,,,,,,,,,,,,,,,,,
229.822,3.7838,30.86972,5.5,,,,,,,,,,,,,,,,,,,,,,,,,,,,,,,,,,,,,
230.822,3.61709,27.96393,5.5,,,,,,,,,,,,,,,,,,,,,,,,,,,,,,,,,,,,,
231.822,3.45049,25.36808,5.5,,,,,,,,,,,,,,,,,,,,,,,,,,,,,,,,,,,,,
232.822,3.28389,22.95079,5.5,,,,,,,,,,,,,,,,,,,,,,,,,,,,,,,,,,,,,
233.822,3.11723,20.80443,5.5,,,,,,,,,,,,,,,,,,,,,,,,,,,,,,,,,,,,,
234.822,2.95058,18.72121,5.5,,,,,,,,,,,,,,,,,,,,,,,,,,,,,,,,,,,,,
235.822,2.78398,16.81872,5.5,,,,,,,,,,,,,,,,,,,,,,,,,,,,,,,,,,,,,
236.822,2.61726,15.06414,5.5,,,,,,,,,,,,,,,,,,,,,,,,,,,,,,,,,,,,,
237.822,2.45061,13.46767,5.5,,,,,,,,,,,,,,,,,,,,,,,,,,,,,,,,,,,,,
238.822,2.28389,11.87103,5.5,,,,,,,,,,,,,,,,,,,,,,,,,,,,,,,,,,,,,
239.822,2.11729,10.36494,5.5,,,,,,,,,,,,,,,,,,,,,,,,,,,,,,,,,,,,,
240.822,1.95058,8.84545,5.5,,,,,,,,,,,,,,,,,,,,,,,,,,,,,,,,,,,,,
241.822,1.78392,7.52588,5.5,,,,,,,,,,,,,,,,,,,,,,,,,,,,,,,,,,,,,
242.822,1.61727,6.27347,5.5,,,,,,,,,,,,,,,,,,,,,,,,,,,,,,,,,,,,,
243.822,1.45055,5.02651,5.5,,,,,,,,,,,,,,,,,,,,,,,,,,,,,,,,,,,,,
244.822,1.2839,3.90643,5.5,,,,,,,,,,,,,,,,,,,,,,,,,,,,,,,,,,,,,
245.822,1.11707,2.88391,5.5,,,,,,,,,,,,,,,,,,,,,,,,,,,,,,,,,,,,,
246.822,0.95047,1.94901,5.5,,,,,,,,,,,,,,,,,,,,,,,,,,,,,,,,,,,,,
247.822,0.78376,1.16712,5.5,,,,,,,,,,,,,,,,,,,,,,,,,,,,,,,,,,,,,
248.558,0.8955,1.78579,6,,,,,,,,,,,,,,,,,,,,,,,,,,,,,,,,,,,,,
249.558,1.06205,3.00343,6,,,,,,,,,,,,,,,,,,,,,,,,,,,,,,,,,,,,,
250.558,1.22887,4.26141,6,,,,,,,,,,,,,,,,,,,,,,,,,,,,,,,,,,,,,
251.558,1.39553,5.55491,6,,,,,,,,,,,,,,,,,,,,,,,,,,,,,,,,,,,,,
252.558,1.56219,6.92989,6,,,,,,,,,,,,,,,,,,,,,,,,,,,,,,,,,,,,,
253.558,1.72884,8.28007,6,,,,,,,,,,,,,,,,,,,,,,,,,,,,,,,,,,,,,
254.558,1.89556,9.77477,6,,,,,,,,,,,,,,,,,,,,,,,,,,,,,,,,,,,,,
255.558,2.06216,11.34297,6,,,,,,,,,,,,,,,,,,,,,,,,,,,,,,,,,,,,,
256.558,2.22893,12.96695,6,,,,,,,,,,,,,,,,,,,,,,,,,,,,,,,,,,,,,
257.558,2.39558,14.72272,6,,,,,,,,,,,,,,,,,,,,,,,,,,,,,,,,,,,,,
258.558,2.56224,16.47174,6,,,,,,,,,,,,,,,,,,,,,,,,,,,,,,,,,,,,,
259.558,2.72907,18.32148,6,,,,,,,,,,,,,,,,,,,,,,,,,,,,,,,,,,,,,
260.558,2.89561,20.24898,6,,,,,,,,,,,,,,,,,,,,,,,,,,,,,,,,,,,,,
261.558,3.06227,22.2604,6,,,,,,,,,,,,,,,,,,,,,,,,,,,,,,,,,,,,,
262.558,3.22887,24.44018,6,,,,,,,,,,,,,,,,,,,,,,,,,,,,,,,,,,,,,
263.558,3.39558,26.73502,6,,,,,,,,,,,,,,,,,,,,,,,,,,,,,,,,,,,,,
264.558,3.56207,29.1546,6,,,,,,,,,,,,,,,,,,,,,,,,,,,,,,,,,,,,,
265.558,3.72878,31.64083,6,,,,,,,,,,,,,,,,,,,,,,,,,,,,,,,,,,,,,
266.558,3.89549,34.3054,6,,,,,,,,,,,,,,,,,,,,,,,,,,,,,,,,,,,,,
267.558,4.06209,36.9659,6,,,,,,,,,,,,,,,,,,,,,,,,,,,,,,,,,,,,,
268.558,4.22886,39.75509,6,,,,,,,,,,,,,,,,,,,,,,,,,,,,,,,,,,,,,
269.362,4.12919,36.80986,6.5,,,,,,,,,,,,,,,,,,,,,,,,,,,,,,,,,,,,,
270.362,3.96253,33.1501,6.5,,,,,,,,,,,,,,,,,,,,,,,,,,,,,,,,,,,,,
271.362,3.79587,30.00568,6.5,,,,,,,,,,,,,,,,,,,,,,,,,,,,,,,,,,,,,
272.362,3.62933,27.24536,6.5,,,,,,,,,,,,,,,,,,,,,,,,,,,,,,,,,,,,,
273.362,3.46262,24.71227,6.5,,,,,,,,,,,,,,,,,,,,,,,,,,,,,,,,,,,,,
274.362,3.29596,22.391,6.5,,,,,,,,,,,,,,,,,,,,,,,,,,,,,,,,,,,,,
275.362,3.12925,20.27117,6.5,,,,,,,,,,,,,,,,,,,,,,,,,,,,,,,,,,,,,
276.362,2.96253,18.31283,6.5,,,,,,,,,,,,,,,,,,,,,,,,,,,,,,,,,,,,,
277.362,2.79593,16.40834,6.5,,,,,,,,,,,,,,,,,,,,,,,,,,,,,,,,,,,,,
278.362,2.62928,14.68704,6.5,,,,,,,,,,,,,,,,,,,,,,,,,,,,,,,,,,,,,
279.362,2.46268,13.06009,6.5,,,,,,,,,,,,,,,,,,,,,,,,,,,,,,,,,,,,,
280.362,2.29591,11.46114,6.5,,,,,,,,,,,,,,,,,,,,,,,,,,,,,,,,,,,,,
281.362,2.12925,10.03859,6.5,,,,,,,,,,,,,,,,,,,,,,,,,,,,,,,,,,,,,
282.362,1.96248,8.57276,6.5,,,,,,,,,,,,,,,,,,,,,,,,,,,,,,,,,,,,,
283.362,1.79582,7.22866,6.5,,,,,,,,,,,,,,,,,,,,,,,,,,,,,,,,,,,,,
284.362,1.62917,5.98296,6.5,,,,,,,,,,,,,,,,,,,,,,,,,,,,,,,,,,,,,
285.362,1.46245,4.86712,6.5,,,,,,,,,,,,,,,,,,,,,,,,,,,,,,,,,,,,,
286.362,1.29585,3.7265,6.5,,,,,,,,,,,,,,,,,,,,,,,,,,,,,,,,,,,,,
287.362,1.12908,2.73491,6.5,,,,,,,,,,,,,,,,,,,,,,,,,,,,,,,,,,,,,
288.362,0.9626,1.80543,6.5,,,,,,,,,,,,,,,,,,,,,,,,,,,,,,,,,,,,,
289.274,0.81062,0.99921,7,,,,,,,,,,,,,,,,,,,,,,,,,,,,,,,,,,,,,
290.078,0.94418,1.90416,7,,,,,,,,,,,,,,,,,,,,,,,,,,,,,,,,,,,,,
291.078,1.11078,3.12269,7,,,,,,,,,,,,,,,,,,,,,,,,,,,,,,,,,,,,,
292.078,1.27749,4.34099,7,,,,,,,,,,,,,,,,,,,,,,,,,,,,,,,,,,,,,
293.078,1.44421,5.60303,7,,,,,,,,,,,,,,,,,,,,,,,,,,,,,,,,,,,,,
294.078,1.61081,6.93185,7,,,,,,,,,,,,,,,,,,,,,,,,,,,,,,,,,,,,,
295.078,1.77758,8.28091,7,,,,,,,,,,,,,,,,,,,,,,,,,,,,,,,,,,,,,
296.078,1.94423,9.79838,7,,,,,,,,,,,,,,,,,,,,,,,,,,,,,,,,,,,,,
297.078,2.111,11.36839,7,,,,,,,,,,,,,,,,,,,,,,,,,,,,,,,,,,,,,
298.078,2.27766,13.02587,7,,,,,,,,,,,,,,,,,,,,,,,,,,,,,,,,,,,,,
299.078,2.44426,14.74541,7,,,,,,,,,,,,,,,,,,,,,,,,,,,,,,,,,,,,,
300.078,2.61097,16.52276,7,,,,,,,,,,,,,,,,,,,,,,,,,,,,,,,,,,,,,
301.078,2.77763,18.31189,7,,,,,,,,,,,,,,,,,,,,,,,,,,,,,,,,,,,,,
302.078,2.94423,20.24739,7,,,,,,,,,,,,,,,,,,,,,,,,,,,,,,,,,,,,,
303.078,3.11077,22.3074,7,,,,,,,,,,,,,,,,,,,,,,,,,,,,,,,,,,,,,
304.078,3.27749,24.50239,7,,,,,,,,,,,,,,,,,,,,,,,,,,,,,,,,,,,,,
305.078,3.44409,26.75887,7,,,,,,,,,,,,,,,,,,,,,,,,,,,,,,,,,,,,,
306.078,3.61086,29.11448,7,,,,,,,,,,,,,,,,,,,,,,,,,,,,,,,,,,,,,
307.078,3.77751,31.62778,7,,,,,,,,,,,,,,,,,,,,,,,,,,,,,,,,,,,,,
308.078,3.94411,34.27721,7,,,,,,,,,,,,,,,,,,,,,,,,,,,,,,,,,,,,,
309.078,4.11094,36.98558,7,,,,,,,,,,,,,,,,,,,,,,,,,,,,,,,,,,,,,
310.078,4.27748,39.82268,7,,,,,,,,,,,,,,,,,,,,,,,,,,,,,,,,,,,,,
310.942,4.15463,36.38095,7.5,,,,,,,,,,,,,,,,,,,,,,,,,,,,,,,,,,,,,
311.942,3.98792,32.74683,7.5,,,,,,,,,,,,,,,,,,,,,,,,,,,,,,,,,,,,,
312.942,3.82132,29.7103,7.5,,,,,,,,,,,,,,,,,,,,,,,,,,,,,,,,,,,,,
313.942,3.6546,26.93334,7.5,,,,,,,,,,,,,,,,,,,,,,,,,,,,,,,,,,,,,
314.942,3.488,24.42403,7.5,,,,,,,,,,,,,,,,,,,,,,,,,,,,,,,,,,,,,
315.942,3.32118,22.12709,7.5,,,,,,,,,,,,,,,,,,,,,,,,,,,,,,,,,,,,,
316.942,3.15452,19.99697,7.5,,,,,,,,,,,,,,,,,,,,,,,,,,,,,,,,,,,,,
317.942,2.98781,18.01233,7.5,,,,,,,,,,,,,,,,,,,,,,,,,,,,,,,,,,,,,
318.942,2.82109,16.19291,7.5,,,,,,,,,,,,,,,,,,,,,,,,,,,,,,,,,,,,,
319.942,2.65444,14.50449,7.5,,,,,,,,,,,,,,,,,,,,,,,,,,,,,,,,,,,,,
320.942,2.48778,12.90583,7.5,,,,,,,,,,,,,,,,,,,,,,,,,,,,,,,,,,,,,
321.942,2.32124,11.32069,7.5,,,,,,,,,,,,,,,,,,,,,,,,,,,,,,,,,,,,,
322.942,2.15458,9.85302,7.5,,,,,,,,,,,,,,,,,,,,,,,,,,,,,,,,,,,,,
323.942,1.98787,8.46274,7.5,,,,,,,,,,,,,,,,,,,,,,,,,,,,,,,,,,,,,
324.942,1.82127,7.1398,7.5,,,,,,,,,,,,,,,,,,,,,,,,,,,,,,,,,,,,,
325.942,1.65467,5.90144,7.5,,,,,,,,,,,,,,,,,,,,,,,,,,,,,,,,,,,,,
326.942,1.48801,4.73363,7.5,,,,,,,,,,,,,,,,,,,,,,,,,,,,,,,,,,,,,
327.942,1.32118,3.5994,7.5,,,,,,,,,,,,,,,,,,,,,,,,,,,,,,,,,,,,,
328.942,1.15453,2.62065,7.5,,,,,,,,,,,,,,,,,,,,,,,,,,,,,,,,,,,,,
329.942,0.98787,1.74738,7.5,,,,,,,,,,,,,,,,,,,,,,,,,,,,,,,,,,,,,
330.698,0.86196,0.99882,8,,,,,,,,,,,,,,,,,,,,,,,,,,,,,,,,,,,,,
331.698,1.02963,2.1907,8,,,,,,,,,,,,,,,,,,,,,,,,,,,,,,,,,,,,,
332.698,1.19629,3.35473,8,,,,,,,,,,,,,,,,,,,,,,,,,,,,,,,,,,,,,
333.698,1.36295,4.59606,8,,,,,,,,,,,,,,,,,,,,,,,,,,,,,,,,,,,,,
334.698,1.52966,5.98693,8,,,,,,,,,,,,,,,,,,,,,,,,,,,,,,,,,,,,,
335.698,1.69615,7.24954,8,,,,,,,,,,,,,,,,,,,,,,,,,,,,,,,,,,,,,
336.698,1.86286,8.65077,8,,,,,,,,,,,,,,,,,,,,,,,,,,,,,,,,,,,,,
337.698,2.02952,10.22589,8,,,,,,,,,,,,,,,,,,,,,,,,,,,,,,,,,,,,,
338.698,2.19612,11.81743,8,,,,,,,,,,,,,,,,,,,,,,,,,,,,,,,,,,,,,
339.698,2.36289,13.39185,8,,,,,,,,,,,,,,,,,,,,,,,,,,,,,,,,,,,,,
340.698,2.52949,15.17798,8,,,,,,,,,,,,,,,,,,,,,,,,,,,,,,,,,,,,,
341.698,2.69626,16.93478,8,,,,,,,,,,,,,,,,,,,,,,,,,,,,,,,,,,,,,
342.698,2.8628,18.80724,8,,,,,,,,,,,,,,,,,,,,,,,,,,,,,,,,,,,,,
343.698,3.02963,20.80698,8,,,,,,,,,,,,,,,,,,,,,,,,,,,,,,,,,,,,,
344.698,3.19617,22.74548,8,,,,,,,,,,,,,,,,,,,,,,,,,,,,,,,,,,,,,
345.698,3.36294,24.98752,8,,,,,,,,,,,,,,,,,,,,,,,,,,,,,,,,,,,,,
346.698,3.5296,27.32556,8,,,,,,,,,,,,,,,,,,,,,,,,,,,,,,,,,,,,,
347.698,3.69625,29.77511,8,,,,,,,,,,,,,,,,,,,,,,,,,,,,,,,,,,,,,
348.698,3.86297,32.31973,8,,,,,,,,,,,,,,,,,,,,,,,,,,,,,,,,,,,,,
349.698,4.02962,34.98833,8,,,,,,,,,,,,,,,,,,,,,,,,,,,,,,,,,,,,,
350.698,4.19628,37.76595,8,,,,,,,,,,,,,,,,,,,,,,,,,,,,,,,,,,,,,
351.516,4.33251,40.0214,8.5,,,,,,,,,,,,,,,,,,,,,,,,,,,,,,,,,,,,,
352.516,4.16574,35.56635,8.5,,,,,,,,,,,,,,,,,,,,,,,,,,,,,,,,,,,,,
353.516,3.99885,32.05675,8.5,,,,,,,,,,,,,,,,,,,,,,,,,,,,,,,,,,,,,
354.516,3.83225,29.02813,8.5,,,,,,,,,,,,,,,,,,,,,,,,,,,,,,,,,,,,,
355.516,3.66548,26.30806,8.5,,,,,,,,,,,,,,,,,,,,,,,,,,,,,,,,,,,,,
356.516,3.49888,23.82256,8.5,,,,,,,,,,,,,,,,,,,,,,,,,,,,,,,,,,,,,
357.516,3.33211,21.52902,8.5,,,,,,,,,,,,,,,,,,,,,,,,,,,,,,,,,,,,,
358.516,3.16551,19.50725,8.5,,,,,,,,,,,,,,,,,,,,,,,,,,,,,,,,,,,,,
359.516,2.99886,17.51043,8.5,,,,,,,,,,,,,,,,,,,,,,,,,,,,,,,,,,,,,
360.516,2.83214,15.68506,8.5,,,,,,,,,,,,,,,,,,,,,,,,,,,,,,,,,,,,,
361.516,2.6656,14.04818,8.5,,,,,,,,,,,,,,,,,,,,,,,,,,,,,,,,,,,,,
362.516,2.499,12.4597,8.5,,,,,,,,,,,,,,,,,,,,,,,,,,,,,,,,,,,,,
363.516,2.33234,10.9156,8.5,,,,,,,,,,,,,,,,,,,,,,,,,,,,,,,,,,,,,
364.516,2.16557,9.51297,8.5,,,,,,,,,,,,,,,,,,,,,,,,,,,,,,,,,,,,,
365.516,1.99886,8.09016,8.5,,,,,,,,,,,,,,,,,,,,,,,,,,,,,,,,,,,,,
366.516,1.83226,6.75849,8.5,,,,,,,,,,,,,,,,,,,,,,,,,,,,,,,,,,,,,
367.516,1.6656,5.57823,8.5,,,,,,,,,,,,,,,,,,,,,,,,,,,,,,,,,,,,,
368.516,1.49895,4.42915,8.5,,,,,,,,,,,,,,,,,,,,,,,,,,,,,,,,,,,,,
369.516,1.33223,3.3552,8.5,,,,,,,,,,,,,,,,,,,,,,,,,,,,,,,,,,,,,
370.516,1.16558,2.38958,8.5,,,,,,,,,,,,,,,,,,,,,,,,,,,,,,,,,,,,,
371.516,0.99881,1.50566,8.5,,,,,,,,,,,,,,,,,,,,,,,,,,,,,,,,,,,,,
372.292,0.93676,1.16433,9,,,,,,,,,,,,,,,,,,,,,,,,,,,,,,,,,,,,,
373.292,1.10381,2.44745,9,,,,,,,,,,,,,,,,,,,,,,,,,,,,,,,,,,,,,
374.292,1.27058,3.61412,9,,,,,,,,,,,,,,,,,,,,,,,,,,,,,,,,,,,,,
375.292,1.43718,4.79877,9,,,,,,,,,,,,,,,,,,,,,,,,,,,,,,,,,,,,,
376.292,1.60395,6.11745,9,,,,,,,,,,,,,,,,,,,,,,,,,,,,,,,,,,,,,
377.292,1.77061,7.48514,9,,,,,,,,,,,,,,,,,,,,,,,,,,,,,,,,,,,,,
378.292,1.93726,8.83697,9,,,,,,,,,,,,,,,,,,,,,,,,,,,,,,,,,,,,,
379.292,2.10398,10.36534,9,,,,,,,,,,,,,,,,,,,,,,,,,,,,,,,,,,,,,
380.292,2.27063,11.94897,9,,,,,,,,,,,,,,,,,,,,,,,,,,,,,,,,,,,,,
381.292,2.43723,13.67218,9,,,,,,,,,,,,,,,,,,,,,,,,,,,,,,,,,,,,,
382.292,2.60383,15.35328,9,,,,,,,,,,,,,,,,,,,,,,,,,,,,,,,,,,,,,
383.292,2.77055,17.21044,9,,,,,,,,,,,,,,,,,,,,,,,,,,,,,,,,,,,,,
384.292,2.93715,19.03391,9,,,,,,,,,,,,,,,,,,,,,,,,,,,,,,,,,,,,,
385.292,3.10386,20.95481,9,,,,,,,,,,,,,,,,,,,,,,,,,,,,,,,,,,,,,
386.292,3.27052,23.04397,9,,,,,,,,,,,,,,,,,,,,,,,,,,,,,,,,,,,,,
387.292,3.43717,25.30482,9,,,,,,,,,,,,,,,,,,,,,,,,,,,,,,,,,,,,,
388.292,3.60389,27.6128,9,,,,,,,,,,,,,,,,,,,,,,,,,,,,,,,,,,,,,
389.292,3.77049,30.05769,9,,,,,,,,,,,,,,,,,,,,,,,,,,,,,,,,,,,,,
390.292,3.9372,32.70953,9,,,,,,,,,,,,,,,,,,,,,,,,,,,,,,,,,,,,,
391.292,4.10386,35.41475,9,,,,,,,,,,,,,,,,,,,,,,,,,,,,,,,,,,,,,
392.292,4.27057,38.22132,9,,,,,,,,,,,,,,,,,,,,,,,,,,,,,,,,,,,,,
393.138,4.34497,39.08318,9.5,,,,,,,,,,,,,,,,,,,,,,,,,,,,,,,,,,,,,
394.138,4.17786,34.85466,9.5,,,,,,,,,,,,,,,,,,,,,,,,,,,,,,,,,,,,,
395.138,4.01109,31.50903,9.5,,,,,,,,,,,,,,,,,,,,,,,,,,,,,,,,,,,,,
396.138,3.84449,28.52808,9.5,,,,,,,,,,,,,,,,,,,,,,,,,,,,,,,,,,,,,
397.138,3.67784,25.90642,9.5,,,,,,,,,,,,,,,,,,,,,,,,,,,,,,,,,,,,,
398.138,3.51118,23.45462,9.5,,,,,,,,,,,,,,,,,,,,,,,,,,,,,,,,,,,,,
399.138,3.34458,21.2304,9.5,,,,,,,,,,,,,,,,,,,,,,,,,,,,,,,,,,,,,
400.138,3.17792,19.1129,9.5,,,,,,,,,,,,,,,,,,,,,,,,,,,,,,,,,,,,,
401.138,3.01132,17.19852,9.5,,,,,,,,,,,,,,,,,,,,,,,,,,,,,,,,,,,,,
402.138,2.84455,15.45267,9.5,,,,,,,,,,,,,,,,,,,,,,,,,,,,,,,,,,,,,
403.138,2.67801,13.79803,9.5,,,,,,,,,,,,,,,,,,,,,,,,,,,,,,,,,,,,,
404.138,2.51124,12.17239,9.5,,,,,,,,,,,,,,,,,,,,,,,,,,,,,,,,,,,,,
405.138,2.34464,10.66897,9.5,,,,,,,,,,,,,,,,,,,,,,,,,,,,,,,,,,,,,
406.138,2.17793,9.23402,9.5,,,,,,,,,,,,,,,,,,,,,,,,,,,,,,,,,,,,,
407.138,2.01127,7.84019,9.5,,,,,,,,,,,,,,,,,,,,,,,,,,,,,,,,,,,,,
408.138,1.84461,6.581,9.5,,,,,,,,,,,,,,,,,,,,,,,,,,,,,,,,,,,,,
409.138,1.6779,5.38839,9.5,,,,,,,,,,,,,,,,,,,,,,,,,,,,,,,,,,,,,
410.138,1.51124,4.28372,9.5,,,,,,,,,,,,,,,,,,,,,,,,,,,,,,,,,,,,,
411.138,1.34442,3.25813,9.5,,,,,,,,,,,,,,,,,,,,,,,,,,,,,,,,,,,,,
412.138,1.17782,2.26465,9.5,,,,,,,,,,,,,,,,,,,,,,,,,,,,,,,,,,,,,
413.138,1.0111,1.34897,9.5,,,,,,,,,,,,,,,,,,,,,,,,,,,,,,,,,,,,,
413.96,0.87731,0.67598,10,,,,,,,,,,,,,,,,,,,,,,,,,,,,,,,,,,,,,
414.96,0.84666,0.49555,10,,,,,,,,,,,,,,,,,,,,,,,,,,,,,,,,,,,,,
415.96,0.85816,0.64314,10,,,,,,,,,,,,,,,,,,,,,,,,,,,,,,,,,,,,,
416.96,0.93285,1.14682,10,,,,,,,,,,,,,,,,,,,,,,,,,,,,,,,,,,,,,
417.96,0.93392,1.15278,10,,,,,,,,,,,,,,,,,,,,,,,,,,,,,,,,,,,,,
418.96,0.90984,1.00496,10,,,,,,,,,,,,,,,,,,,,,,,,,,,,,,,,,,,,,
419.96,0.87295,0.79184,10,,,,,,,,,,,,,,,,,,,,,,,,,,,,,,,,,,,,,
420.96,0.87306,0.78246,10,,,,,,,,,,,,,,,,,,,,,,,,,,,,,,,,,,,,,
421.96,0.87357,0.75441,10,,,,,,,,,,,,,,,,,,,,,,,,,,,,,,,,,,,,,
422.96,0.87675,0.8245,10,,,,,,,,,,,,,,,,,,,,,,,,,,,,,,,,,,,,,
423.96,0.89669,0.95817,10,,,,,,,,,,,,,,,,,,,,,,,,,,,,,,,,,,,,,
424.96,0.90395,0.96511,10,,,,,,,,,,,,,,,,,,,,,,,,,,,,,,,,,,,,,
425.96,0.90372,1.03428,10,,,,,,,,,,,,,,,,,,,,,,,,,,,,,,,,,,,,,
426.96,0.9031,1.02495,10,,,,,,,,,,,,,,,,,,,,,,,,,,,,,,,,,,,,,
427.96,0.8963,0.98497,10,,,,,,,,,,,,,,,,,,,,,,,,,,,,,,,,,,,,,
428.96,0.87998,0.91496,10,,,,,,,,,,,,,,,,,,,,,,,,,,,,,,,,,,,,,
429.96,0.87879,0.87156,10,,,,,,,,,,,,,,,,,,,,,,,,,,,,,,,,,,,,,
430.96,0.87873,0.8742,10,,,,,,,,,,,,,,,,,,,,,,,,,,,,,,,,,,,,,
431.96,0.87884,0.88974,10,,,,,,,,,,,,,,,,,,,,,,,,,,,,,,,,,,,,,
432.96,0.87896,0.88461,10,,,,,,,,,,,,,,,,,,,,,,,,,,,,,,,,,,,,,
433.96,0.87907,0.87073,10,,,,,,,,,,,,,,,,,,,,,,,,,,,,,,,,,,,,,
434.96,0.87924,0.83728,10,,,,,,,,,,,,,,,,,,,,,,,,,,,,,,,,,,,,,
435.96,0.87947,0.83998,10,,,,,,,,,,,,,,,,,,,,,,,,,,,,,,,,,,,,,
436.96,0.87992,0.85543,10,,,,,,,,,,,,,,,,,,,,,,,,,,,,,,,,,,,,,
437.96,0.88071,0.87626,10,,,,,,,,,,,,,,,,,,,,,,,,,,,,,,,,,,,,,
438.96,0.88196,0.88468,10,,,,,,,,,,,,,,,,,,,,,,,,,,,,,,,,,,,,,
439.96,0.88287,0.85499,10,,,,,,,,,,,,,,,,,,,,,,,,,,,,,,,,,,,,,
440.96,0.88428,0.94788,10,,,,,,,,,,,,,,,,,,,,,,,,,,,,,,,,,,,,,
441.96,0.88508,0.88445,10,,,,,,,,,,,,,,,,,,,,,,,,,,,,,,,,,,,,,
442.96,0.88564,0.91139,10,,,,,,,,,,,,,,,,,,,,,,,,,,,,,,,,,,,,,
443.96,0.88593,0.92028,10,,,,,,,,,,,,,,,,,,,,,,,,,,,,,,,,,,,,,
444.96,0.88598,0.9969,10,,,,,,,,,,,,,,,,,,,,,,,,,,,,,,,,,,,,,
445.96,0.88581,0.93129,10,,,,,,,,,,,,,,,,,,,,,,,,,,,,,,,,,,,,,
446.96,0.88576,0.90493,10,,,,,,,,,,,,,,,,,,,,,,,,,,,,,,,,,,,,,
447.96,0.8857,0.92785,10,,,,,,,,,,,,,,,,,,,,,,,,,,,,,,,,,,,,,
448.96,0.88559,0.88434,10,,,,,,,,,,,,,,,,,,,,,,,,,,,,,,,,,,,,,
449.96,0.88542,0.9569,10,,,,,,,,,,,,,,,,,,,,,,,,,,,,,,,,,,,,,
450.96,0.88485,0.97536,10,,,,,,,,,,,,,,,,,,,,,,,,,,,,,,,,,,,,,
451.96,0.88332,0.93506,10,,,,,,,,,,,,,,,,,,,,,,,,,,,,,,,,,,,,,
452.96,0.88105,0.93323,10,,,,,,,,,,,,,,,,,,,,,,,,,,,,,,,,,,,,,
453.96,0.87884,0.92054,10,,,,,,,,,,,,,,,,,,,,,,,,,,,,,,,,,,,,,
454.96,0.87629,0.88882,10,,,,,,,,,,,,,,,,,,,,,,,,,,,,,,,,,,,,,
455.96,0.87408,0.93334,10,,,,,,,,,,,,,,,,,,,,,,,,,,,,,,,,,,,,,
456.96,0.87306,0.89528,10,,,,,,,,,,,,,,,,,,,,,,,,,,,,,,,,,,,,,
457.96,0.87284,0.87532,10,,,,,,,,,,,,,,,,,,,,,,,,,,,,,,,,,,,,,
458.96,0.87272,0.94969,10,,,,,,,,,,,,,,,,,,,,,,,,,,,,,,,,,,,,,
459.96,0.87284,0.89323,10,,,,,,,,,,,,,,,,,,,,,,,,,,,,,,,,,,,,,
460.96,0.87289,0.85684,10,,,,,,,,,,,,,,,,,,,,,,,,,,,,,,,,,,,,,
461.96,0.87289,0.92575,10,,,,,,,,,,,,,,,,,,,,,,,,,,,,,,,,,,,,,
462.96,0.87289,0.90906,10,,,,,,,,,,,,,,,,,,,,,,,,,,,,,,,,,,,,,
463.96,0.87295,0.90038,10,,,,,,,,,,,,,,,,,,,,,,,,,,,,,,,,,,,,,
464.96,0.87306,0.9134,10,,,,,,,,,,,,,,,,,,,,,,,,,,,,,,,,,,,,,
465.96,0.87312,0.88266,10,,,,,,,,,,,,,,,,,,,,,,,,,,,,,,,,,,,,,
466.96,0.87329,0.84337,10,,,,,,,,,,,,,,,,,,,,,,,,,,,,,,,,,,,,,
467.96,0.87357,0.90163,10,,,,,,,,,,,,,,,,,,,,,,,,,,,,,,,,,,,,,
468.96,0.87391,0.88948,10,,,,,,,,,,,,,,,,,,,,,,,,,,,,,,,,,,,,,
469.96,0.87414,0.90029,10,,,,,,,,,,,,,,,,,,,,,,,,,,,,,,,,,,,,,
470.96,0.87454,0.90056,10,,,,,,,,,,,,,,,,,,,,,,,,,,,,,,,,,,,,,
471.96,0.87499,0.90063,10,,,,,,,,,,,,,,,,,,,,,,,,,,,,,,,,,,,,,
472.96,0.87601,0.86218,10,,,,,,,,,,,,,,,,,,,,,,,,,,,,,,,,,,,,,
473.96,0.87692,0.92062,10,,,,,,,,,,,,,,,,,,,,,,,,,,,,,,,,,,,,,
474.96,0.87743,0.92359,10,,,,,,,,,,,,,,,,,,,,,,,,,,,,,,,,,,,,,
475.96,0.87777,0.89919,10,,,,,,,,,,,,,,,,,,,,,,,,,,,,,,,,,,,,,
476.96,0.87805,0.89201,10,,,,,,,,,,,,,,,,,,,,,,,,,,,,,,,,,,,,,
477.96,0.87816,0.90003,10,,,,,,,,,,,,,,,,,,,,,,,,,,,,,,,,,,,,,
478.96,0.87811,0.91876,10,,,,,,,,,,,,,,,,,,,,,,,,,,,,,,,,,,,,,
479.96,0.87805,0.94636,10,,,,,,,,,,,,,,,,,,,,,,,,,,,,,,,,,,,,,
480.96,0.87805,0.92288,10,,,,,,,,,,,,,,,,,,,,,,,,,,,,,,,,,,,,,
481.96,0.87794,0.91783,10,,,,,,,,,,,,,,,,,,,,,,,,,,,,,,,,,,,,,
482.96,0.87788,0.92984,10,,,,,,,,,,,,,,,,,,,,,,,,,,,,,,,,,,,,,
483.96,0.87782,0.90546,10,,,,,,,,,,,,,,,,,,,,,,,,,,,,,,,,,,,,,
484.96,0.87777,0.92833,10,,,,,,,,,,,,,,,,,,,,,,,,,,,,,,,,,,,,,
485.96,0.87765,0.97587,10,,,,,,,,,,,,,,,,,,,,,,,,,,,,,,,,,,,,,
486.96,0.87714,0.93255,10,,,,,,,,,,,,,,,,,,,,,,,,,,,,,,,,,,,,,
487.96,0.87658,0.93282,10,,,,,,,,,,,,,,,,,,,,,,,,,,,,,,,,,,,,,
488.96,0.8751,0.93946,10,,,,,,,,,,,,,,,,,,,,,,,,,,,,,,,,,,,,,
489.96,0.87323,0.93961,10,,,,,,,,,,,,,,,,,,,,,,,,,,,,,,,,,,,,,
490.96,0.87131,0.92135,10,,,,,,,,,,,,,,,,,,,,,,,,,,,,,,,,,,,,,
491.96,0.86927,0.92259,10,,,,,,,,,,,,,,,,,,,,,,,,,,,,,,,,,,,,,
492.96,0.86825,0.88805,10,,,,,,,,,,,,,,,,,,,,,,,,,,,,,,,,,,,,,
493.96,0.86785,0.91195,10,,,,,,,,,,,,,,,,,,,,,,,,,,,,,,,,,,,,,
494.96,0.86762,0.91434,10,,,,,,,,,,,,,,,,,,,,,,,,,,,,,,,,,,,,,
495.96,0.8674,0.8768,10,,,,,,,,,,,,,,,,,,,,,,,,,,,,,,,,,,,,,
496.96,0.86734,0.85346,10,,,,,,,,,,,,,,,,,,,,,,,,,,,,,,,,,,,,,
497.96,0.86751,0.88078,10,,,,,,,,,,,,,,,,,,,,,,,,,,,,,,,,,,,,,
498.96,0.86745,0.87204,10,,,,,,,,,,,,,,,,,,,,,,,,,,,,,,,,,,,,,
499.96,0.86757,0.91413,10,,,,,,,,,,,,,,,,,,,,,,,,,,,,,,,,,,,,,
500.96,0.86762,0.88985,10,,,,,,,,,,,,,,,,,,,,,,,,,,,,,,,,,,,,,
501.96,0.86768,0.90105,10,,,,,,,,,,,,,,,,,,,,,,,,,,,,,,,,,,,,,
502.96,0.86774,0.91014,10,,,,,,,,,,,,,,,,,,,,,,,,,,,,,,,,,,,,,
503.96,0.86779,0.91535,10,,,,,,,,,,,,,,,,,,,,,,,,,,,,,,,,,,,,,
504.96,0.86796,0.8896,10,,,,,,,,,,,,,,,,,,,,,,,,,,,,,,,,,,,,,
505.96,0.86825,0.85263,10,,,,,,,,,,,,,,,,,,,,,,,,,,,,,,,,,,,,,
506.96,0.8687,0.87706,10,,,,,,,,,,,,,,,,,,,,,,,,,,,,,,,,,,,,,
507.96,0.86961,0.89309,10,,,,,,,,,,,,,,,,,,,,,,,,,,,,,,,,,,,,,
508.96,0.87148,0.87922,10,,,,,,,,,,,,,,,,,,,,,,,,,,,,,,,,,,,,,
509.96,0.87329,0.96685,10,,,,,,,,,,,,,,,,,,,,,,,,,,,,,,,,,,,,,
510.96,0.87482,0.93147,10,,,,,,,,,,,,,,,,,,,,,,,,,,,,,,,,,,,,,
511.96,0.87578,0.87186,10,,,,,,,,,,,,,,,,,,,,,,,,,,,,,,,,,,,,,
512.96,0.87635,0.94271,10,,,,,,,,,,,,,,,,,,,,,,,,,,,,,,,,,,,,,
513.96,0.87646,0.9224,10,,,,,,,,,,,,,,,,,,,,,,,,,,,,,,,,,,,,,
514.96,0.87635,0.94107,10,,,,,,,,,,,,,,,,,,,,,,,,,,,,,,,,,,,,,
515.96,0.87624,0.92454,10,,,,,,,,,,,,,,,,,,,,,,,,,,,,,,,,,,,,,
516.96,0.87612,0.92003,10,,,,,,,,,,,,,,,,,,,,,,,,,,,,,,,,,,,,,
517.96,0.87607,0.88801,10,,,,,,,,,,,,,,,,,,,,,,,,,,,,,,,,,,,,,
518.96,0.87584,0.96419,10,,,,,,,,,,,,,,,,,,,,,,,,,,,,,,,,,,,,,
519.96,0.8755,0.93736,10,,,,,,,,,,,,,,,,,,,,,,,,,,,,,,,,,,,,,
520.96,0.87437,0.92971,10,,,,,,,,,,,,,,,,,,,,,,,,,,,,,,,,,,,,,
521.96,0.87278,0.96685,10,,,,,,,,,,,,,,,,,,,,,,,,,,,,,,,,,,,,,
522.96,0.8704,0.89678,10,,,,,,,,,,,,,,,,,,,,,,,,,,,,,,,,,,,,,
523.96,0.86859,0.8895,10,,,,,,,,,,,,,,,,,,,,,,,,,,,,,,,,,,,,,
524.96,0.86768,0.89653,10,,,,,,,,,,,,,,,,,,,,,,,,,,,,,,,,,,,,,
525.96,0.86706,0.90596,10,,,,,,,,,,,,,,,,,,,,,,,,,,,,,,,,,,,,,
526.96,0.86632,0.9164,10,,,,,,,,,,,,,,,,,,,,,,,,,,,,,,,,,,,,,
527.96,0.86553,0.86101,10,,,,,,,,,,,,,,,,,,,,,,,,,,,,,,,,,,,,,
528.96,0.86513,0.83578,10,,,,,,,,,,,,,,,,,,,,,,,,,,,,,,,,,,,,,
529.96,0.86496,0.92725,10,,,,,,,,,,,,,,,,,,,,,,,,,,,,,,,,,,,,,
530.96,0.8649,0.91007,10,,,,,,,,,,,,,,,,,,,,,,,,,,,,,,,,,,,,,
531.96,0.86485,0.913,10,,,,,,,,,,,,,,,,,,,,,,,,,,,,,,,,,,,,,
532.96,0.86485,0.90327,10,,,,,,,,,,,,,,,,,,,,,,,,,,,,,,,,,,,,,
533.96,0.86496,0.847,10,,,,,,,,,,,,,,,,,,,,,,,,,,,,,,,,,,,,,
534.96,0.86496,0.92622,10,,,,,,,,,,,,,,,,,,,,,,,,,,,,,,,,,,,,,
535.96,0.86507,0.86786,10,,,,,,,,,,,,,,,,,,,,,,,,,,,,,,,,,,,,,
536.96,0.86519,0.91643,10,,,,,,,,,,,,,,,,,,,,,,,,,,,,,,,,,,,,,
537.96,0.86524,0.93323,10,,,,,,,,,,,,,,,,,,,,,,,,,,,,,,,,,,,,,
538.96,0.86547,0.89651,10,,,,,,,,,,,,,,,,,,,,,,,,,,,,,,,,,,,,,
539.96,0.86587,0.88754,10,,,,,,,,,,,,,,,,,,,,,,,,,,,,,,,,,,,,,
540.96,0.86649,0.86269,10,,,,,,,,,,,,,,,,,,,,,,,,,,,,,,,,,,,,,
541.96,0.86779,0.89341,10,,,,,,,,,,,,,,,,,,,,,,,,,,,,,,,,,,,,,
542.96,0.8704,0.95287,10,,,,,,,,,,,,,,,,,,,,,,,,,,,,,,,,,,,,,
543.96,0.87233,0.9376,10,,,,,,,,,,,,,,,,,,,,,,,,,,,,,,,,,,,,,
544.96,0.87335,0.91497,10,,,,,,,,,,,,,,,,,,,,,,,,,,,,,,,,,,,,,
545.96,0.8738,0.93146,10,,,,,,,,,,,,,,,,,,,,,,,,,,,,,,,,,,,,,
546.96,0.87403,0.92993,10,,,,,,,,,,,,,,,,,,,,,,,,,,,,,,,,,,,,,
547.96,0.87397,0.90642,10,,,,,,,,,,,,,,,,,,,,,,,,,,,,,,,,,,,,,
548.96,0.87386,0.96394,10,,,,,,,,,,,,,,,,,,,,,,,,,,,,,,,,,,,,,
549.96,0.87374,0.92094,10,,,,,,,,,,,,,,,,,,,,,,,,,,,,,,,,,,,,,
550.96,0.87357,0.93975,10,,,,,,,,,,,,,,,,,,,,,,,,,,,,,,,,,,,,,
551.96,0.87318,0.98777,10,,,,,,,,,,,,,,,,,,,,,,,,,,,,,,,,,,,,,
552.96,0.87199,0.94961,10,,,,,,,,,,,,,,,,,,,,,,,,,,,,,,,,,,,,,
553.96,0.86978,0.9099,10,,,,,,,,,,,,,,,,,,,,,,,,,,,,,,,,,,,,,
554.96,0.86791,0.93477,10,,,,,,,,,,,,,,,,,,,,,,,,,,,,,,,,,,,,,
555.96,0.86626,0.91064,10,,,,,,,,,,,,,,,,,,,,,,,,,,,,,,,,,,,,,
556.96,0.8649,0.89417,10,,,,,,,,,,,,,,,,,,,,,,,,,,,,,,,,,,,,,
557.96,0.86411,0.92256,10,,,,,,,,,,,,,,,,,,,,,,,,,,,,,,,,,,,,,
558.96,0.86337,0.91948,10,,,,,,,,,,,,,,,,,,,,,,,,,,,,,,,,,,,,,
559.96,0.86281,0.90702,10,,,,,,,,,,,,,,,,,,,,,,,,,,,,,,,,,,,,,
560.96,0.86252,0.8728,10,,,,,,,,,,,,,,,,,,,,,,,,,,,,,,,,,,,,,
561.96,0.86264,0.88035,10,,,,,,,,,,,,,,,,,,,,,,,,,,,,,,,,,,,,,
562.96,0.86269,0.86228,10,,,,,,,,,,,,,,,,,,,,,,,,,,,,,,,,,,,,,
563.96,0.86275,0.89585,10,,,,,,,,,,,,,,,,,,,,,,,,,,,,,,,,,,,,,
564.96,0.86281,0.90497,10,,,,,,,,,,,,,,,,,,,,,,,,,,,,,,,,,,,,,
565.96,0.86292,0.83862,10,,,,,,,,,,,,,,,,,,,,,,,,,,,,,,,,,,,,,
566.96,0.86303,0.84202,10,,,,,,,,,,,,,,,,,,,,,,,,,,,,,,,,,,,,,
567.96,0.86303,0.9111,10,,,,,,,,,,,,,,,,,,,,,,,,,,,,,,,,,,,,,
568.96,0.86326,0.91995,10,,,,,,,,,,,,,,,,,,,,,,,,,,,,,,,,,,,,,
569.96,0.86354,0.90985,10,,,,,,,,,,,,,,,,,,,,,,,,,,,,,,,,,,,,,
570.96,0.86405,0.89998,10,,,,,,,,,,,,,,,,,,,,,,,,,,,,,,,,,,,,,
571.96,0.86496,0.8826,10,,,,,,,,,,,,,,,,,,,,,,,,,,,,,,,,,,,,,
572.96,0.86666,0.91598,10,,,,,,,,,,,,,,,,,,,,,,,,,,,,,,,,,,,,,
573.96,0.86898,0.89499,10,,,,,,,,,,,,,,,,,,,,,,,,,,,,,,,,,,,,,
574.96,0.87051,0.94641,10,,,,,,,,,,,,,,,,,,,,,,,,,,,,,,,,,,,,,
575.96,0.87131,0.91882,10,,,,,,,,,,,,,,,,,,,,,,,,,,,,,,,,,,,,,
576.96,0.87182,0.91132,10,,,,,,,,,,,,,,,,,,,,,,,,,,,,,,,,,,,,,
577.96,0.87216,0.94028,10,,,,,,,,,,,,,,,,,,,,,,,,,,,,,,,,,,,,,
578.96,0.87227,0.98527,10,,,,,,,,,,,,,,,,,,,,,,,,,,,,,,,,,,,,,
579.96,0.87216,0.89976,10,,,,,,,,,,,,,,,,,,,,,,,,,,,,,,,,,,,,,
580.96,0.8721,0.9317,10,,,,,,,,,,,,,,,,,,,,,,,,,,,,,,,,,,,,,
581.96,0.87204,0.91567,10,,,,,,,,,,,,,,,,,,,,,,,,,,,,,,,,,,,,,
582.96,0.87199,0.95484,10,,,,,,,,,,,,,,,,,,,,,,,,,,,,,,,,,,,,,
583.96,0.87193,0.95358,10,,,,,,,,,,,,,,,,,,,,,,,,,,,,,,,,,,,,,
584.96,0.87182,0.95972,10,,,,,,,,,,,,,,,,,,,,,,,,,,,,,,,,,,,,,
585.96,0.8717,0.99261,10,,,,,,,,,,,,,,,,,,,,,,,,,,,,,,,,,,,,,
586.96,0.87102,0.96365,10,,,,,,,,,,,,,,,,,,,,,,,,,,,,,,,,,,,,,
587.96,0.86927,0.9476,10,,,,,,,,,,,,,,,,,,,,,,,,,,,,,,,,,,,,,
588.96,0.8674,0.93336,10,,,,,,,,,,,,,,,,,,,,,,,,,,,,,,,,,,,,,
589.96,0.86536,0.90948,10,,,,,,,,,,,,,,,,,,,,,,,,,,,,,,,,,,,,,
590.96,0.86332,0.92885,10,,,,,,,,,,,,,,,,,,,,,,,,,,,,,,,,,,,,,
591.96,0.86235,0.91815,10,,,,,,,,,,,,,,,,,,,,,,,,,,,,,,,,,,,,,
592.96,0.8619,0.94623,10,,,,,,,,,,,,,,,,,,,,,,,,,,,,,,,,,,,,,
593.96,0.86162,0.86655,10,,,,,,,,,,,,,,,,,,,,,,,,,,,,,,,,,,,,,
594.96,0.86162,0.88755,10,,,,,,,,,,,,,,,,,,,,,,,,,,,,,,,,,,,,,
595.96,0.86167,0.85843,10,,,,,,,,,,,,,,,,,,,,,,,,,,,,,,,,,,,,,
596.96,0.86173,0.93253,10,,,,,,,,,,,,,,,,,,,,,,,,,,,,,,,,,,,,,
597.96,0.86179,0.89718,10,,,,,,,,,,,,,,,,,,,,,,,,,,,,,,,,,,,,,
598.96,0.8619,0.85877,10,,,,,,,,,,,,,,,,,,,,,,,,,,,,,,,,,,,,,
599.96,0.86196,0.86473,10,,,,,,,,,,,,,,,,,,,,,,,,,,,,,,,,,,,,,
600.96,0.86201,0.91565,10,,,,,,,,,,,,,,,,,,,,,,,,,,,,,,,,,,,,,
601.96,0.86207,0.88094,10,,,,,,,,,,,,,,,,,,,,,,,,,,,,,,,,,,,,,
602.96,0.86241,0.92138,10,,,,,,,,,,,,,,,,,,,,,,,,,,,,,,,,,,,,,
603.96,0.86281,0.88702,10,,,,,,,,,,,,,,,,,,,,,,,,,,,,,,,,,,,,,
604.96,0.86377,0.85488,10,,,,,,,,,,,,,,,,,,,,,,,,,,,,,,,,,,,,,
605.96,0.86632,0.87422,10,,,,,,,,,,,,,,,,,,,,,,,,,,,,,,,,,,,,,
606.96,0.86893,0.882,10,,,,,,,,,,,,,,,,,,,,,,,,,,,,,,,,,,,,,
607.96,0.87029,0.94454,10,,,,,,,,,,,,,,,,,,,,,,,,,,,,,,,,,,,,,
608.96,0.87068,0.92144,10,,,,,,,,,,,,,,,,,,,,,,,,,,,,,,,,,,,,,
609.96,0.87074,0.96855,10,,,,,,,,,,,,,,,,,,,,,,,,,,,,,,,,,,,,,
610.96,0.87063,0.93598,10,,,,,,,,,,,,,,,,,,,,,,,,,,,,,,,,,,,,,
611.96,0.87057,0.94318,10,,,,,,,,,,,,,,,,,,,,,,,,,,,,,,,,,,,,,
612.96,0.87057,0.96267,10,,,,,,,,,,,,,,,,,,,,,,,,,,,,,,,,,,,,,
613.96,0.87034,0.92407,10,,,,,,,,,,,,,,,,,,,,,,,,,,,,,,,,,,,,,
614.96,0.87006,0.97067,10,,,,,,,,,,,,,,,,,,,,,,,,,,,,,,,,,,,,,
615.96,0.86944,0.94561,10,,,,,,,,,,,,,,,,,,,,,,,,,,,,,,,,,,,,,
616.96,0.8683,0.93676,10,,,,,,,,,,,,,,,,,,,,,,,,,,,,,,,,,,,,,
617.96,0.86683,0.95922,10,,,,,,,,,,,,,,,,,,,,,,,,,,,,,,,,,,,,,
618.96,0.86485,0.91252,10,,,,,,,,,,,,,,,,,,,,,,,,,,,,,,,,,,,,,
619.96,0.86275,0.97287,10,,,,,,,,,,,,,,,,,,,,,,,,,,,,,,,,,,,,,
620.96,0.86145,0.93107,10,,,,,,,,,,,,,,,,,,,,,,,,,,,,,,,,,,,,,
621.96,0.86105,0.89533,10,,,,,,,,,,,,,,,,,,,,,,,,,,,,,,,,,,,,,
622.96,0.86088,0.90712,10,,,,,,,,,,,,,,,,,,,,,,,,,,,,,,,,,,,,,
623.96,0.86071,0.85984,10,,,,,,,,,,,,,,,,,,,,,,,,,,,,,,,,,,,,,
624.96,0.86082,0.85834,10,,,,,,,,,,,,,,,,,,,,,,,,,,,,,,,,,,,,,
625.96,0.86088,0.86411,10,,,,,,,,,,,,,,,,,,,,,,,,,,,,,,,,,,,,,
626.96,0.86099,0.82834,10,,,,,,,,,,,,,,,,,,,,,,,,,,,,,,,,,,,,,
627.96,0.86105,0.90411,10,,,,,,,,,,,,,,,,,,,,,,,,,,,,,,,,,,,,,
628.96,0.86122,0.78981,10,,,,,,,,,,,,,,,,,,,,,,,,,,,,,,,,,,,,,
629.96,0.86145,0.89541,10,,,,,,,,,,,,,,,,,,,,,,,,,,,,,,,,,,,,,
630.96,0.86179,0.8962,10,,,,,,,,,,,,,,,,,,,,,,,,,,,,,,,,,,,,,
631.96,0.8623,0.83168,10,,,,,,,,,,,,,,,,,,,,,,,,,,,,,,,,,,,,,
632.96,0.8632,0.88934,10,,,,,,,,,,,,,,,,,,,,,,,,,,,,,,,,,,,,,
633.96,0.86519,0.86418,10,,,,,,,,,,,,,,,,,,,,,,,,,,,,,,,,,,,,,
634.96,0.86904,0.89532,10,,,,,,,,,,,,,,,,,,,,,,,,,,,,,,,,,,,,,
635.96,0.87057,0.89503,10,,,,,,,,,,,,,,,,,,,,,,,,,,,,,,,,,,,,,
636.96,0.87085,0.9165,10,,,,,,,,,,,,,,,,,,,,,,,,,,,,,,,,,,,,,
637.96,0.87097,0.92468,10,,,,,,,,,,,,,,,,,,,,,,,,,,,,,,,,,,,,,
638.96,0.87085,0.92626,10,,,,,,,,,,,,,,,,,,,,,,,,,,,,,,,,,,,,,
639.96,0.87085,0.96036,10,,,,,,,,,,,,,,,,,,,,,,,,,,,,,,,,,,,,,
640.96,0.87068,0.90163,10,,,,,,,,,,,,,,,,,,,,,,,,,,,,,,,,,,,,,
641.96,0.87057,0.92713,10,,,,,,,,,,,,,,,,,,,,,,,,,,,,,,,,,,,,,
642.96,0.87051,0.89386,10,,,,,,,,,,,,,,,,,,,,,,,,,,,,,,,,,,,,,
643.96,0.87029,0.97465,10,,,,,,,,,,,,,,,,,,,,,,,,,,,,,,,,,,,,,
644.96,0.86938,0.98677,10,,,,,,,,,,,,,,,,,,,,,,,,,,,,,,,,,,,,,
645.96,0.86762,0.99654,10,,,,,,,,,,,,,,,,,,,,,,,,,,,,,,,,,,,,,
646.96,0.86547,0.96403,10,,,,,,,,,,,,,,,,,,,,,,,,,,,,,,,,,,,,,
647.96,0.86428,0.96953,10,,,,,,,,,,,,,,,,,,,,,,,,,,,,,,,,,,,,,
648.96,0.86292,0.99346,10,,,,,,,,,,,,,,,,,,,,,,,,,,,,,,,,,,,,,
649.96,0.8619,0.93764,10,,,,,,,,,,,,,,,,,,,,,,,,,,,,,,,,,,,,,
650.96,0.86122,0.91016,10,,,,,,,,,,,,,,,,,,,,,,,,,,,,,,,,,,,,,
651.96,0.86099,0.95776,10,,,,,,,,,,,,,,,,,,,,,,,,,,,,,,,,,,,,,
652.96,0.86099,0.87743,10,,,,,,,,,,,,,,,,,,,,,,,,,,,,,,,,,,,,,
653.96,0.86099,0.98372,10,,,,,,,,,,,,,,,,,,,,,,,,,,,,,,,,,,,,,
654.96,0.86105,0.88773,10,,,,,,,,,,,,,,,,,,,,,,,,,,,,,,,,,,,,,
655.96,0.86116,0.91155,10,,,,,,,,,,,,,,,,,,,,,,,,,,,,,,,,,,,,,
656.96,0.86122,0.9474,10,,,,,,,,,,,,,,,,,,,,,,,,,,,,,,,,,,,,,
657.96,0.86128,0.95242,10,,,,,,,,,,,,,,,,,,,,,,,,,,,,,,,,,,,,,
658.96,0.86133,1.00412,10,,,,,,,,,,,,,,,,,,,,,,,,,,,,,,,,,,,,,
659.96,0.8615,0.94844,10,,,,,,,,,,,,,,,,,,,,,,,,,,,,,,,,,,,,,
660.96,0.86184,0.89717,10,,,,,,,,,,,,,,,,,,,,,,,,,,,,,,,,,,,,,
661.96,0.86235,0.96225,10,,,,,,,,,,,,,,,,,,,,,,,,,,,,,,,,,,,,,
662.96,0.86417,0.93637,10,,,,,,,,,,,,,,,,,,,,,,,,,,,,,,,,,,,,,
663.96,0.86717,0.92722,10,,,,,,,,,,,,,,,,,,,,,,,,,,,,,,,,,,,,,
664.96,0.86932,0.90572,10,,,,,,,,,,,,,,,,,,,,,,,,,,,,,,,,,,,,,
665.96,0.87017,0.99398,10,,,,,,,,,,,,,,,,,,,,,,,,,,,,,,,,,,,,,
666.96,0.87012,0.96653,10,,,,,,,,,,,,,,,,,,,,,,,,,,,,,,,,,,,,,
667.96,0.87012,0.94136,10,,,,,,,,,,,,,,,,,,,,,,,,,,,,,,,,,,,,,
668.96,0.87006,0.97099,10,,,,,,,,,,,,,,,,,,,,,,,,,,,,,,,,,,,,,
669.96,0.86995,0.92412,10,,,,,,,,,,,,,,,,,,,,,,,,,,,,,,,,,,,,,
670.96,0.86989,0.94555,10,,,,,,,,,,,,,,,,,,,,,,,,,,,,,,,,,,,,,
671.96,0.86983,0.96723,10,,,,,,,,,,,,,,,,,,,,,,,,,,,,,,,,,,,,,
672.96,0.86972,0.90971,10,,,,,,,,,,,,,,,,,,,,,,,,,,,,,,,,,,,,,
673.96,0.86966,0.9417,10,,,,,,,,,,,,,,,,,,,,,,,,,,,,,,,,,,,,,
674.96,0.86938,0.9285,10,,,,,,,,,,,,,,,,,,,,,,,,,,,,,,,,,,,,,
675.96,0.86859,0.99431,10,,,,,,,,,,,,,,,,,,,,,,,,,,,,,,,,,,,,,
676.96,0.86757,0.92183,10,,,,,,,,,,,,,,,,,,,,,,,,,,,,,,,,,,,,,
677.96,0.86592,0.9501,10,,,,,,,,,,,,,,,,,,,,,,,,,,,,,,,,,,,,,
678.96,0.86456,0.91377,10,,,,,,,,,,,,,,,,,,,,,,,,,,,,,,,,,,,,,
679.96,0.86309,0.89966,10,,,,,,,,,,,,,,,,,,,,,,,,,,,,,,,,,,,,,
680.96,0.8623,0.92935,10,,,,,,,,,,,,,,,,,,,,,,,,,,,,,,,,,,,,,
681.96,0.86184,0.93499,10,,,,,,,,,,,,,,,,,,,,,,,,,,,,,,,,,,,,,
682.96,0.8615,0.85871,10,,,,,,,,,,,,,,,,,,,,,,,,,,,,,,,,,,,,,
683.96,0.86145,0.86276,10,,,,,,,,,,,,,,,,,,,,,,,,,,,,,,,,,,,,,
684.96,0.86162,0.85479,10,,,,,,,,,,,,,,,,,,,,,,,,,,,,,,,,,,,,,
685.96,0.86162,0.90158,10,,,,,,,,,,,,,,,,,,,,,,,,,,,,,,,,,,,,,
686.96,0.86173,0.88491,10,,,,,,,,,,,,,,,,,,,,,,,,,,,,,,,,,,,,,
687.96,0.86184,0.83402,10,,,,,,,,,,,,,,,,,,,,,,,,,,,,,,,,,,,,,
688.96,0.86201,0.8348,10,,,,,,,,,,,,,,,,,,,,,,,,,,,,,,,,,,,,,
689.96,0.86224,0.87508,10,,,,,,,,,,,,,,,,,,,,,,,,,,,,,,,,,,,,,
690.96,0.86264,0.85523,10,,,,,,,,,,,,,,,,,,,,,,,,,,,,,,,,,,,,,
691.96,0.86349,0.88342,10,,,,,,,,,,,,,,,,,,,,,,,,,,,,,,,,,,,,,
692.96,0.86553,0.87657,10,,,,,,,,,,,,,,,,,,,,,,,,,,,,,,,,,,,,,
693.96,0.86762,0.8943,10,,,,,,,,,,,,,,,,,,,,,,,,,,,,,,,,,,,,,
694.96,0.8691,0.95321,10,,,,,,,,,,,,,,,,,,,,,,,,,,,,,,,,,,,,,
695.96,0.86978,0.95308,10,,,,,,,,,,,,,,,,,,,,,,,,,,,,,,,,,,,,,
696.96,0.87006,0.91932,10,,,,,,,,,,,,,,,,,,,,,,,,,,,,,,,,,,,,,
697.96,0.86995,0.93394,10,,,,,,,,,,,,,,,,,,,,,,,,,,,,,,,,,,,,,
698.96,0.86983,0.91374,10,,,,,,,,,,,,,,,,,,,,,,,,,,,,,,,,,,,,,
699.96,0.86972,0.89518,10,,,,,,,,,,,,,,,,,,,,,,,,,,,,,,,,,,,,,
700.96,0.86972,0.92051,10,,,,,,,,,,,,,,,,,,,,,,,,,,,,,,,,,,,,,
701.96,0.86966,0.92673,10,,,,,,,,,,,,,,,,,,,,,,,,,,,,,,,,,,,,,
702.96,0.86955,0.94242,10,,,,,,,,,,,,,,,,,,,,,,,,,,,,,,,,,,,,,
703.96,0.86938,0.9666,10,,,,,,,,,,,,,,,,,,,,,,,,,,,,,,,,,,,,,
704.96,0.8687,0.94769,10,,,,,,,,,,,,,,,,,,,,,,,,,,,,,,,,,,,,,
705.96,0.86779,0.94951,10,,,,,,,,,,,,,,,,,,,,,,,,,,,,,,,,,,,,,
706.96,0.86632,0.92769,10,,,,,,,,,,,,,,,,,,,,,,,,,,,,,,,,,,,,,
707.96,0.86468,0.92753,10,,,,,,,,,,,,,,,,,,,,,,,,,,,,,,,,,,,,,
708.96,0.8636,0.90253,10,,,,,,,,,,,,,,,,,,,,,,,,,,,,,,,,,,,,,
709.96,0.86241,0.91566,10,,,,,,,,,,,,,,,,,,,,,,,,,,,,,,,,,,,,,
710.96,0.8619,0.8943,10,,,,,,,,,,,,,,,,,,,,,,,,,,,,,,,,,,,,,
711.96,0.86184,0.92288,10,,,,,,,,,,,,,,,,,,,,,,,,,,,,,,,,,,,,,
712.96,0.8619,0.854,10,,,,,,,,,,,,,,,,,,,,,,,,,,,,,,,,,,,,,
713.862,3.22807,21.27055,10,,,,,,,,,,,,,,,,,,,,,,,,,,,,,,,,,,,,,
714.862,11.56198,17.59894,10,,,,,,,,,,,,,,,,,,,,,,,,,,,,,,,,,,,,,
715.862,19.89538,-2.28577,10,,,,,,,,,,,,,,,,,,,,,,,,,,,,,,,,,,,,,
716.862,28.22856,-4.55612,10,,,,,,,,,,,,,,,,,,,,,,,,,,,,,,,,,,,,,
717.862,36.56201,-4.46312,10,,,,,,,,,,,,,,,,,,,,,,,,,,,,,,,,,,,,,
718.332,40.47858,-4.37035,10,,,,,,,,,,,,,,,,,,,,,,,,,,,,,,,,,,,,,