File: combined_ligament_solver/data/processed/Data Sheet 3_S151624_ACL.csv
Specimen properties : Length,40,mm,Unnamed: 3,Unnamed: 4,Unnamed: 5,Unnamed: 6,Unnamed: 7,Unnamed: 8,Unnamed: 9,Unnamed: 10,Unnamed: 11,Stress-Strain,Unnamed: 13,Unnamed: 14,Unnamed: 15,Unnamed: 16,Unnamed: 17,Unnamed: 18,Unnamed: 19,Unnamed: 20,Unnamed: 21,Unnamed: 22,Unnamed: 23,Unnamed: 24,Unnamed: 25,Unnamed: 26,Unnamed: 27,Linear,Unnamed: 29,Unnamed: 30,Unnamed: 31,Unnamed: 32,Unnamed: 33,Modulus,Unnamed: 35,Failure,Unnamed: 37,Unnamed: 38,Unnamed: 39,Unnamed: 40
Cross Section Average,63.8025,mm2,,,,,,,,,,Polynomial Coefficients,,,,,,,,,,,,,,,,Force,,Stress,Extension,Strain,,Secant,Tangent,Load,Stress,Extension,Strain,Stiffness
Time,Extension,Load,Total cycle count,,,Extension,Load,Strain,Stress,E-tan,,X6,,,,,,,,,,Strain,Stress,E-tan,,,,(N),,(MPa),(mm),(%),,(MPa),(MPa),(N),(MPa),(mm),(%),(N/mm)
(s),(mm),(N),,,,(mm),(N),(mm/mm),(MPa),(MPa),,X5,-258653.51791675593,,,,,,,,,(mm/mm),(MPa),(MPa),,,,399.3357787484723,,6.258936228963948,3.84,9.6,,65.19725238504112,122.5942385848534,629.94043,9.873287567101602,5.66661,14.166525000000002,103.99369238241465
0.5,0.14546,2.5211,0,,,4.12647,432.24939,0.09999975000000001,6.774803338427177,114.74387755115418,,,,,,,,,,,,0.005,0.03287234971906547,7.95906514908473,,,,,,,,,,,,,,,,
1.1,0.24537,4.47578,0,,,9.12656,359.03745,,,,,,,,,,,,,,,0.011,0.09739854933458239,12.897091401954256,,,,,,,,,,,,,,,,
1.7,0.34527,6.82627,0,,,14.12655,84.2683,,,,,,,,,,,,,,,0.017,0.19522814947175568,18.88350394018191,,,,,,,,,,,,,,,,
2.3,0.44534,9.39293,0,,,19.12653,46.00158,,,,,,,,,,,,,,,0.023,0.3325582116663144,25.88607122594647,,,,,,,,,,,,,,,,
2.9,0.54553,12.26558,0,,,24.12657,18.90612,,,,,,,,,,,,,,,0.029,0.5152516179441884,33.83233592632037,,,,,,,,,,,,,,,,
3.5,0.64543,14.99624,0,,,,,,,,,,,,,,,,,,,0.035,0.74859571605087,42.60961491326994,,,,,,,,,,,,,,,,
4.1,0.74528,18.50767,0,,,,,,,,,,,,,,,,,,,0.041,1.037060964680775,52.06499926365455,,,,,,,,,,,,,,,,
4.7,0.84535,22.46465,0,,,,,,,,,,,,,,,,,,,0.047,1.3840595787066037,62.00535425922732,,,,,,,,,,,,,,,,
5.3,0.94548,26.74142,0,,,,,,,,,,,,,,,,,,,0.053,1.7917041744087046,72.19731938663467,,,,,,,,,,,,,,,,
5.9,1.04544,31.77357,0,,,,,,,,,,,,,,,,,,,0.059,2.2605664147044338,82.3673083374184,,,,,,,,,,,,,,,,
6.5,1.14523,37.21284,0,,,,,,,,,,,,,,,,,,,0.065,2.789435654377518,92.20150900801096,,,,,,,,,,,,,,,,
6.99,1.16059,38.03151,0.5,,,,,,,,,,,,,,,,,,,0.071,3.3750775853074124,101.34588349974072,,,,,,,,,,,,,,,,
7.59,1.06012,31.23015,0.5,,,,,,,,,,,,,,,,,,,0.077,4.01199288169867,109.40616811882843,,,,,,,,,,,,,,,,
8.19,0.9601,25.6406,0.5,,,,,,,,,,,,,,,,,,,0.083,4.692175845310293,115.94787337638823,,,,,,,,,,,,,,,,
8.79,0.85992,20.81881,0.5,,,,,,,,,,,,,,,,,,,0.089,5.404873050685101,120.49628398843014,,,,,,,,,,,,,,,,
9.39,0.76001,16.93481,0.5,,,,,,,,,,,,,,,,,,,0.095,6.136341990379094,122.53645887585382,,,,,,,,,,,,,,,,
9.99,0.66011,13.28519,0.5,,,,,,,,,,,,,,,,,,,0.101,6.869609720190808,121.51323116445654,,,,,,,,,,,,,,,,
10.59,0.56015,10.27167,0.5,,,,,,,,,,,,,,,,,,,0.107,7.5842315043906785,116.83120818492908,,,,,,,,,,,,,,,,
11.19,0.45991,7.48579,0.5,,,,,,,,,,,,,,,,,,,0.113,8.256049460950406,107.85477147284605,,,,,,,,,,,,,,,,
11.79,0.36,5.39842,0.5,,,,,,,,,,,,,,,,,,,0.119,8.856951206772314,93.90807676869518,,,,,,,,,,,,,,,,
12.39,0.26016,3.36663,0.5,,,,,,,,,,,,,,,,,,,0.125,9.354628502918708,74.27505401783911,,,,,,,,,,,,,,,,
12.99,0.16014,1.55485,0.5,,,,,,,,,,,,,,,,,,,0.131,9.712335899841243,48.199407370542914,,,,,,,,,,,,,,,,
13.32,0.13436,1.08249,1,,,,,,,,,,,,,,,,,,,0.137,9.88864938261028,14.884615181962587,,,,,,,,,,,,,,,,
13.92,0.2393,3.30422,1,,,,,,,,,,,,,,,,,,,0.143,9.837225016144249,-26.506069987853184,,,,,,,,,,,,,,,,
14.52,0.33932,5.65683,1,,,,,,,,,,,,,,,,,,,0.149,9.506557590439018,-76.84962137395061,,,,,,,,,,,,,,,,
15.12,0.43939,8.32389,1,,,,,,,,,,,,,,,,,,,0.155,8.839739265797235,-137.06323800650276,,,,,,,,,,,,,,,,
15.72,0.53941,11.19446,1,,,,,,,,,,,,,,,,,,,0.161,7.774218218057709,-208.10434471078202,,,,,,,,,,,,,,,,
16.32,0.63931,13.84248,1,,,,,,,,,,,,,,,,,,,0.167,6.241557283824763,-290.970592107153,,,,,,,,,,,,,,,,
16.92,0.73939,17.27739,1,,,,,,,,,,,,,,,,,,,0.173,4.1671926056976325,-386.6998566110805,,,,,,,,,,,,,,,,
17.52,0.83935,21.19923,1,,,,,,,,,,,,,,,,,,,0.179,1.4701922774997014,-496.37024043320105,,,,,,,,,,,,,,,,
18.12,0.93942,25.68307,1,,,,,,,,,,,,,,,,,,,0.185,-1.9369850104919482,-621.1000715791533,,,,,,,,,,,,,,,,
18.72,1.03938,30.70826,1,,,,,,,,,,,,,,,,,,,0.191,-6.148731326317348,-762.0479038497898,,,,,,,,,,,,,,,,
19.32,1.13934,36.33113,1,,,,,,,,,,,,,,,,,,,0.197,-11.266530851104125,-920.4125168409573,,,,,,,,,,,,,,,,
19.786,1.18807,39.79828,1.5,,,,,,,,,,,,,,,,,,,,,,,,,,,,,,,,,,,,,
20.386,1.0833,32.26938,1.5,,,,,,,,,,,,,,,,,,,,,,,,,,,,,,,,,,,,,
20.986,0.98339,26.5345,1.5,,,,,,,,,,,,,,,,,,,,,,,,,,,,,,,,,,,,,
21.586,0.88349,21.68867,1.5,,,,,,,,,,,,,,,,,,,,,,,,,,,,,,,,,,,,,
22.186,0.78347,17.49119,1.5,,,,,,,,,,,,,,,,,,,,,,,,,,,,,,,,,,,,,
22.786,0.68329,13.803,1.5,,,,,,,,,,,,,,,,,,,,,,,,,,,,,,,,,,,,,
23.386,0.58333,10.65159,1.5,,,,,,,,,,,,,,,,,,,,,,,,,,,,,,,,,,,,,
23.986,0.48342,7.9478,1.5,,,,,,,,,,,,,,,,,,,,,,,,,,,,,,,,,,,,,
24.586,0.38341,5.63182,1.5,,,,,,,,,,,,,,,,,,,,,,,,,,,,,,,,,,,,,
25.186,0.28339,3.583,1.5,,,,,,,,,,,,,,,,,,,,,,,,,,,,,,,,,,,,,
25.786,0.18326,1.74044,1.5,,,,,,,,,,,,,,,,,,,,,,,,,,,,,,,,,,,,,
26.176,0.14779,0.965,2,,,,,,,,,,,,,,,,,,,,,,,,,,,,,,,,,,,,,
26.776,0.25279,3.27565,2,,,,,,,,,,,,,,,,,,,,,,,,,,,,,,,,,,,,,
27.376,0.35264,5.64359,2,,,,,,,,,,,,,,,,,,,,,,,,,,,,,,,,,,,,,
27.976,0.45254,8.35398,2,,,,,,,,,,,,,,,,,,,,,,,,,,,,,,,,,,,,,
28.576,0.55267,11.32831,2,,,,,,,,,,,,,,,,,,,,,,,,,,,,,,,,,,,,,
29.176,0.65286,13.94472,2,,,,,,,,,,,,,,,,,,,,,,,,,,,,,,,,,,,,,
29.776,0.75265,17.48481,2,,,,,,,,,,,,,,,,,,,,,,,,,,,,,,,,,,,,,
30.376,0.85261,21.5514,2,,,,,,,,,,,,,,,,,,,,,,,,,,,,,,,,,,,,,
30.976,0.95268,26.05417,2,,,,,,,,,,,,,,,,,,,,,,,,,,,,,,,,,,,,,
31.576,1.05281,31.20731,2,,,,,,,,,,,,,,,,,,,,,,,,,,,,,,,,,,,,,
32.176,1.15266,36.95421,2,,,,,,,,,,,,,,,,,,,,,,,,,,,,,,,,,,,,,
32.58,1.19102,39.85704,2.5,,,,,,,,,,,,,,,,,,,,,,,,,,,,,,,,,,,,,
33.18,1.0863,32.24886,2.5,,,,,,,,,,,,,,,,,,,,,,,,,,,,,,,,,,,,,
33.78,0.9864,26.52127,2.5,,,,,,,,,,,,,,,,,,,,,,,,,,,,,,,,,,,,,
34.38,0.88644,21.69956,2.5,,,,,,,,,,,,,,,,,,,,,,,,,,,,,,,,,,,,,
34.98,0.78648,17.39131,2.5,,,,,,,,,,,,,,,,,,,,,,,,,,,,,,,,,,,,,
35.58,0.68629,13.7186,2.5,,,,,,,,,,,,,,,,,,,,,,,,,,,,,,,,,,,,,
36.18,0.58639,10.69791,2.5,,,,,,,,,,,,,,,,,,,,,,,,,,,,,,,,,,,,,
36.78,0.48648,7.87681,2.5,,,,,,,,,,,,,,,,,,,,,,,,,,,,,,,,,,,,,
37.38,0.38647,5.62049,2.5,,,,,,,,,,,,,,,,,,,,,,,,,,,,,,,,,,,,,
37.98,0.28634,3.45544,2.5,,,,,,,,,,,,,,,,,,,,,,,,,,,,,,,,,,,,,
38.58,0.18626,1.69696,2.5,,,,,,,,,,,,,,,,,,,,,,,,,,,,,,,,,,,,,
38.954,0.15334,0.9764,3,,,,,,,,,,,,,,,,,,,,,,,,,,,,,,,,,,,,,
39.554,0.2584,3.26887,3,,,,,,,,,,,,,,,,,,,,,,,,,,,,,,,,,,,,,
40.154,0.3583,5.67433,3,,,,,,,,,,,,,,,,,,,,,,,,,,,,,,,,,,,,,
40.754,0.45832,8.32244,3,,,,,,,,,,,,,,,,,,,,,,,,,,,,,,,,,,,,,
41.354,0.55834,11.31469,3,,,,,,,,,,,,,,,,,,,,,,,,,,,,,,,,,,,,,
41.954,0.65841,13.92269,3,,,,,,,,,,,,,,,,,,,,,,,,,,,,,,,,,,,,,
42.554,0.75837,17.55925,3,,,,,,,,,,,,,,,,,,,,,,,,,,,,,,,,,,,,,
43.154,0.85833,21.65128,3,,,,,,,,,,,,,,,,,,,,,,,,,,,,,,,,,,,,,
43.754,0.95829,26.22891,3,,,,,,,,,,,,,,,,,,,,,,,,,,,,,,,,,,,,,
44.354,1.05842,31.47266,3,,,,,,,,,,,,,,,,,,,,,,,,,,,,,,,,,,,,,
44.954,1.15844,37.18952,3,,,,,,,,,,,,,,,,,,,,,,,,,,,,,,,,,,,,,
45.448,1.1743,37.05158,3.5,,,,,,,,,,,,,,,,,,,,,,,,,,,,,,,,,,,,,
46.048,1.07378,30.40214,3.5,,,,,,,,,,,,,,,,,,,,,,,,,,,,,,,,,,,,,
46.648,0.97365,24.87534,3.5,,,,,,,,,,,,,,,,,,,,,,,,,,,,,,,,,,,,,
47.248,0.8738,20.23697,3.5,,,,,,,,,,,,,,,,,,,,,,,,,,,,,,,,,,,,,
47.848,0.77378,16.32159,3.5,,,,,,,,,,,,,,,,,,,,,,,,,,,,,,,,,,,,,
48.448,0.67371,12.86203,3.5,,,,,,,,,,,,,,,,,,,,,,,,,,,,,,,,,,,,,
49.048,0.57358,10.07746,3.5,,,,,,,,,,,,,,,,,,,,,,,,,,,,,,,,,,,,,
49.648,0.47373,7.26341,3.5,,,,,,,,,,,,,,,,,,,,,,,,,,,,,,,,,,,,,
50.248,0.37377,4.98237,3.5,,,,,,,,,,,,,,,,,,,,,,,,,,,,,,,,,,,,,
50.848,0.27376,3.26886,3.5,,,,,,,,,,,,,,,,,,,,,,,,,,,,,,,,,,,,,
51.448,0.17374,1.53721,3.5,,,,,,,,,,,,,,,,,,,,,,,,,,,,,,,,,,,,,
51.76,0.15107,1.02392,4,,,,,,,,,,,,,,,,,,,,,,,,,,,,,,,,,,,,,
52.36,0.25613,3.33285,4,,,,,,,,,,,,,,,,,,,,,,,,,,,,,,,,,,,,,
52.96,0.35592,5.60078,4,,,,,,,,,,,,,,,,,,,,,,,,,,,,,,,,,,,,,
53.56,0.45594,8.28069,4,,,,,,,,,,,,,,,,,,,,,,,,,,,,,,,,,,,,,
54.16,0.55607,11.07452,4,,,,,,,,,,,,,,,,,,,,,,,,,,,,,,,,,,,,,
54.76,0.65614,13.83947,4,,,,,,,,,,,,,,,,,,,,,,,,,,,,,,,,,,,,,
55.36,0.75599,17.10438,4,,,,,,,,,,,,,,,,,,,,,,,,,,,,,,,,,,,,,
55.96,0.85601,21.13313,4,,,,,,,,,,,,,,,,,,,,,,,,,,,,,,,,,,,,,
56.56,0.95602,25.57759,4,,,,,,,,,,,,,,,,,,,,,,,,,,,,,,,,,,,,,
57.16,1.0561,30.66336,4,,,,,,,,,,,,,,,,,,,,,,,,,,,,,,,,,,,,,
57.76,1.156,36.3633,4,,,,,,,,,,,,,,,,,,,,,,,,,,,,,,,,,,,,,
58.22,1.20354,39.82884,4.5,,,,,,,,,,,,,,,,,,,,,,,,,,,,,,,,,,,,,
58.82,1.09911,32.21304,4.5,,,,,,,,,,,,,,,,,,,,,,,,,,,,,,,,,,,,,
59.42,0.99915,26.50143,4.5,,,,,,,,,,,,,,,,,,,,,,,,,,,,,,,,,,,,,
60.02,0.89913,21.63515,4.5,,,,,,,,,,,,,,,,,,,,,,,,,,,,,,,,,,,,,
60.62,0.799,17.40452,4.5,,,,,,,,,,,,,,,,,,,,,,,,,,,,,,,,,,,,,
61.22,0.69898,13.79215,4.5,,,,,,,,,,,,,,,,,,,,,,,,,,,,,,,,,,,,,
61.82,0.59908,10.67808,4.5,,,,,,,,,,,,,,,,,,,,,,,,,,,,,,,,,,,,,
62.42,0.49906,7.93283,4.5,,,,,,,,,,,,,,,,,,,,,,,,,,,,,,,,,,,,,
63.02,0.39905,5.7008,4.5,,,,,,,,,,,,,,,,,,,,,,,,,,,,,,,,,,,,,
63.62,0.29892,3.64602,4.5,,,,,,,,,,,,,,,,,,,,,,,,,,,,,,,,,,,,,
64.22,0.19907,1.80772,4.5,,,,,,,,,,,,,,,,,,,,,,,,,,,,,,,,,,,,,
64.552,0.14371,0.96619,5,,,,,,,,,,,,,,,,,,,,,,,,,,,,,,,,,,,,,
65.152,0.24469,2.88736,5,,,,,,,,,,,,,,,,,,,,,,,,,,,,,,,,,,,,,
65.752,0.34459,5.20619,5,,,,,,,,,,,,,,,,,,,,,,,,,,,,,,,,,,,,,
66.352,0.44466,7.83434,5,,,,,,,,,,,,,,,,,,,,,,,,,,,,,,,,,,,,,
66.952,0.54479,10.70987,5,,,,,,,,,,,,,,,,,,,,,,,,,,,,,,,,,,,,,
67.552,0.64475,13.2845,5,,,,,,,,,,,,,,,,,,,,,,,,,,,,,,,,,,,,,
68.152,0.74466,16.63725,5,,,,,,,,,,,,,,,,,,,,,,,,,,,,,,,,,,,,,
68.752,0.84467,20.56828,5,,,,,,,,,,,,,,,,,,,,,,,,,,,,,,,,,,,,,
69.352,0.9448,24.98551,5,,,,,,,,,,,,,,,,,,,,,,,,,,,,,,,,,,,,,
69.952,1.04476,30.09978,5,,,,,,,,,,,,,,,,,,,,,,,,,,,,,,,,,,,,,
70.552,1.14455,35.77927,5,,,,,,,,,,,,,,,,,,,,,,,,,,,,,,,,,,,,,
71.012,1.22145,40.03575,5.5,,,,,,,,,,,,,,,,,,,,,,,,,,,,,,,,,,,,,
71.612,1.12121,33.33931,5.5,,,,,,,,,,,,,,,,,,,,,,,,,,,,,,,,,,,,,
72.212,1.02108,27.47742,5.5,,,,,,,,,,,,,,,,,,,,,,,,,,,,,,,,,,,,,
72.812,0.92095,22.41986,5.5,,,,,,,,,,,,,,,,,,,,,,,,,,,,,,,,,,,,,
73.412,0.8211,18.05206,5.5,,,,,,,,,,,,,,,,,,,,,,,,,,,,,,,,,,,,,
74.012,0.72108,14.3793,5.5,,,,,,,,,,,,,,,,,,,,,,,,,,,,,,,,,,,,,
74.612,0.62101,11.18734,5.5,,,,,,,,,,,,,,,,,,,,,,,,,,,,,,,,,,,,,
75.212,0.52094,8.44285,5.5,,,,,,,,,,,,,,,,,,,,,,,,,,,,,,,,,,,,,
75.812,0.42115,5.99645,5.5,,,,,,,,,,,,,,,,,,,,,,,,,,,,,,,,,,,,,
76.412,0.32113,4.07237,5.5,,,,,,,,,,,,,,,,,,,,,,,,,,,,,,,,,,,,,
77.012,0.22106,2.31312,5.5,,,,,,,,,,,,,,,,,,,,,,,,,,,,,,,,,,,,,
77.46,0.14637,0.99448,6,,,,,,,,,,,,,,,,,,,,,,,,,,,,,,,,,,,,,
77.962,0.23035,2.5668,6,,,,,,,,,,,,,,,,,,,,,,,,,,,,,,,,,,,,,
78.562,0.33037,4.81286,6,,,,,,,,,,,,,,,,,,,,,,,,,,,,,,,,,,,,,
79.162,0.43044,7.46305,6,,,,,,,,,,,,,,,,,,,,,,,,,,,,,,,,,,,,,
79.762,0.53029,10.22985,6,,,,,,,,,,,,,,,,,,,,,,,,,,,,,,,,,,,,,
80.362,0.6303,12.7349,6,,,,,,,,,,,,,,,,,,,,,,,,,,,,,,,,,,,,,
80.962,0.73043,16.0385,6,,,,,,,,,,,,,,,,,,,,,,,,,,,,,,,,,,,,,
81.562,0.83034,19.8651,6,,,,,,,,,,,,,,,,,,,,,,,,,,,,,,,,,,,,,
82.162,0.93041,24.18131,6,,,,,,,,,,,,,,,,,,,,,,,,,,,,,,,,,,,,,
82.762,1.03031,29.13622,6,,,,,,,,,,,,,,,,,,,,,,,,,,,,,,,,,,,,,
83.362,1.13033,34.68745,6,,,,,,,,,,,,,,,,,,,,,,,,,,,,,,,,,,,,,
83.918,1.22315,40.00486,6.5,,,,,,,,,,,,,,,,,,,,,,,,,,,,,,,,,,,,,
84.42,1.13968,34.49038,6.5,,,,,,,,,,,,,,,,,,,,,,,,,,,,,,,,,,,,,
85.02,1.03972,28.38485,6.5,,,,,,,,,,,,,,,,,,,,,,,,,,,,,,,,,,,,,
85.62,0.93982,23.16384,6.5,,,,,,,,,,,,,,,,,,,,,,,,,,,,,,,,,,,,,
86.22,0.8398,18.74356,6.5,,,,,,,,,,,,,,,,,,,,,,,,,,,,,,,,,,,,,
86.82,0.73967,14.94994,6.5,,,,,,,,,,,,,,,,,,,,,,,,,,,,,,,,,,,,,
87.42,0.6396,11.62556,6.5,,,,,,,,,,,,,,,,,,,,,,,,,,,,,,,,,,,,,
88.02,0.53981,8.91412,6.5,,,,,,,,,,,,,,,,,,,,,,,,,,,,,,,,,,,,,
88.62,0.43973,6.2945,6.5,,,,,,,,,,,,,,,,,,,,,,,,,,,,,,,,,,,,,
89.22,0.33972,4.41927,6.5,,,,,,,,,,,,,,,,,,,,,,,,,,,,,,,,,,,,,
89.82,0.23959,2.52919,6.5,,,,,,,,,,,,,,,,,,,,,,,,,,,,,,,,,,,,,
90.348,0.15164,0.99916,7,,,,,,,,,,,,,,,,,,,,,,,,,,,,,,,,,,,,,
90.752,0.21862,2.21396,7,,,,,,,,,,,,,,,,,,,,,,,,,,,,,,,,,,,,,
91.352,0.31881,4.4402,7,,,,,,,,,,,,,,,,,,,,,,,,,,,,,,,,,,,,,
91.952,0.41877,6.99517,7,,,,,,,,,,,,,,,,,,,,,,,,,,,,,,,,,,,,,
92.552,0.51861,9.88253,7,,,,,,,,,,,,,,,,,,,,,,,,,,,,,,,,,,,,,
93.152,0.61869,12.23081,7,,,,,,,,,,,,,,,,,,,,,,,,,,,,,,,,,,,,,
93.752,0.71882,15.43316,7,,,,,,,,,,,,,,,,,,,,,,,,,,,,,,,,,,,,,
94.352,0.81878,19.24279,7,,,,,,,,,,,,,,,,,,,,,,,,,,,,,,,,,,,,,
94.952,0.91862,23.57567,7,,,,,,,,,,,,,,,,,,,,,,,,,,,,,,,,,,,,,
95.552,1.01864,28.47915,7,,,,,,,,,,,,,,,,,,,,,,,,,,,,,,,,,,,,,
96.152,1.11871,33.87303,7,,,,,,,,,,,,,,,,,,,,,,,,,,,,,,,,,,,,,
96.752,1.21879,39.59795,7,,,,,,,,,,,,,,,,,,,,,,,,,,,,,,,,,,,,,
97.194,1.15878,35.59561,7.5,,,,,,,,,,,,,,,,,,,,,,,,,,,,,,,,,,,,,
97.794,1.05882,29.33158,7.5,,,,,,,,,,,,,,,,,,,,,,,,,,,,,,,,,,,,,
98.394,0.9588,24.08571,7.5,,,,,,,,,,,,,,,,,,,,,,,,,,,,,,,,,,,,,
98.994,0.85861,19.4007,7.5,,,,,,,,,,,,,,,,,,,,,,,,,,,,,,,,,,,,,
99.594,0.75871,15.58412,7.5,,,,,,,,,,,,,,,,,,,,,,,,,,,,,,,,,,,,,
100.194,0.65875,12.19026,7.5,,,,,,,,,,,,,,,,,,,,,,,,,,,,,,,,,,,,,
100.794,0.55885,9.38408,7.5,,,,,,,,,,,,,,,,,,,,,,,,,,,,,,,,,,,,,
101.394,0.4586,6.61576,7.5,,,,,,,,,,,,,,,,,,,,,,,,,,,,,,,,,,,,,
101.994,0.3587,4.69303,7.5,,,,,,,,,,,,,,,,,,,,,,,,,,,,,,,,,,,,,
102.594,0.2588,2.77635,7.5,,,,,,,,,,,,,,,,,,,,,,,,,,,,,,,,,,,,,
103.194,0.15872,1.10989,7.5,,,,,,,,,,,,,,,,,,,,,,,,,,,,,,,,,,,,,
103.532,0.20338,1.90641,8,,,,,,,,,,,,,,,,,,,,,,,,,,,,,,,,,,,,,
104.132,0.30334,4.12817,8,,,,,,,,,,,,,,,,,,,,,,,,,,,,,,,,,,,,,
104.732,0.4033,6.50066,8,,,,,,,,,,,,,,,,,,,,,,,,,,,,,,,,,,,,,
105.332,0.50337,9.3926,8,,,,,,,,,,,,,,,,,,,,,,,,,,,,,,,,,,,,,
105.932,0.60339,11.99468,8,,,,,,,,,,,,,,,,,,,,,,,,,,,,,,,,,,,,,
106.532,0.7034,14.90628,8,,,,,,,,,,,,,,,,,,,,,,,,,,,,,,,,,,,,,
107.132,0.80331,18.69247,8,,,,,,,,,,,,,,,,,,,,,,,,,,,,,,,,,,,,,
107.732,0.90332,22.81773,8,,,,,,,,,,,,,,,,,,,,,,,,,,,,,,,,,,,,,
108.332,1.0034,27.61228,8,,,,,,,,,,,,,,,,,,,,,,,,,,,,,,,,,,,,,
108.932,1.10347,32.94225,8,,,,,,,,,,,,,,,,,,,,,,,,,,,,,,,,,,,,,
109.532,1.20332,38.58747,8,,,,,,,,,,,,,,,,,,,,,,,,,,,,,,,,,,,,,
109.966,1.17549,36.76483,8.5,,,,,,,,,,,,,,,,,,,,,,,,,,,,,,,,,,,,,
110.566,1.07548,30.26213,8.5,,,,,,,,,,,,,,,,,,,,,,,,,,,,,,,,,,,,,
111.166,0.97529,24.84078,8.5,,,,,,,,,,,,,,,,,,,,,,,,,,,,,,,,,,,,,
111.766,0.87544,20.06477,8.5,,,,,,,,,,,,,,,,,,,,,,,,,,,,,,,,,,,,,
112.366,0.77548,16.14324,8.5,,,,,,,,,,,,,,,,,,,,,,,,,,,,,,,,,,,,,
112.966,0.67535,12.71303,8.5,,,,,,,,,,,,,,,,,,,,,,,,,,,,,,,,,,,,,
113.566,0.57528,9.92718,8.5,,,,,,,,,,,,,,,,,,,,,,,,,,,,,,,,,,,,,
114.166,0.47543,6.98933,8.5,,,,,,,,,,,,,,,,,,,,,,,,,,,,,,,,,,,,,
114.766,0.37547,4.9068,8.5,,,,,,,,,,,,,,,,,,,,,,,,,,,,,,,,,,,,,
115.366,0.27546,3.04522,8.5,,,,,,,,,,,,,,,,,,,,,,,,,,,,,,,,,,,,,
115.966,0.17527,1.26422,8.5,,,,,,,,,,,,,,,,,,,,,,,,,,,,,,,,,,,,,
116.278,0.19074,1.54191,9,,,,,,,,,,,,,,,,,,,,,,,,,,,,,,,,,,,,,
116.878,0.29087,3.7249,9,,,,,,,,,,,,,,,,,,,,,,,,,,,,,,,,,,,,,
117.478,0.391,6.05828,9,,,,,,,,,,,,,,,,,,,,,,,,,,,,,,,,,,,,,
118.078,0.49107,8.9102,9,,,,,,,,,,,,,,,,,,,,,,,,,,,,,,,,,,,,,
118.678,0.59109,11.68393,9,,,,,,,,,,,,,,,,,,,,,,,,,,,,,,,,,,,,,
119.278,0.69094,14.39431,9,,,,,,,,,,,,,,,,,,,,,,,,,,,,,,,,,,,,,
119.878,0.79101,18.09037,9,,,,,,,,,,,,,,,,,,,,,,,,,,,,,,,,,,,,,
120.478,0.89108,22.19347,9,,,,,,,,,,,,,,,,,,,,,,,,,,,,,,,,,,,,,
121.078,0.99116,26.82558,9,,,,,,,,,,,,,,,,,,,,,,,,,,,,,,,,,,,,,
121.678,1.09089,32.21434,9,,,,,,,,,,,,,,,,,,,,,,,,,,,,,,,,,,,,,
122.278,1.19102,37.80834,9,,,,,,,,,,,,,,,,,,,,,,,,,,,,,,,,,,,,,
122.698,1.19453,38.09904,9.5,,,,,,,,,,,,,,,,,,,,,,,,,,,,,,,,,,,,,
123.298,1.09395,31.29096,9.5,,,,,,,,,,,,,,,,,,,,,,,,,,,,,,,,,,,,,
123.898,0.99416,25.68705,9.5,,,,,,,,,,,,,,,,,,,,,,,,,,,,,,,,,,,,,
124.498,0.89414,20.79811,9.5,,,,,,,,,,,,,,,,,,,,,,,,,,,,,,,,,,,,,
125.098,0.79407,16.77363,9.5,,,,,,,,,,,,,,,,,,,,,,,,,,,,,,,,,,,,,
125.698,0.69394,13.26889,9.5,,,,,,,,,,,,,,,,,,,,,,,,,,,,,,,,,,,,,
126.298,0.59415,10.37121,9.5,,,,,,,,,,,,,,,,,,,,,,,,,,,,,,,,,,,,,
126.898,0.49408,7.42942,9.5,,,,,,,,,,,,,,,,,,,,,,,,,,,,,,,,,,,,,
127.498,0.394,5.29315,9.5,,,,,,,,,,,,,,,,,,,,,,,,,,,,,,,,,,,,,
128.098,0.29393,3.31825,9.5,,,,,,,,,,,,,,,,,,,,,,,,,,,,,,,,,,,,,
128.698,0.19414,1.57978,9.5,,,,,,,,,,,,,,,,,,,,,,,,,,,,,,,,,,,,,
129.114,0.12812,0.55172,10,,,,,,,,,,,,,,,,,,,,,,,,,,,,,,,,,,,,,
129.714,0.11231,0.43574,10,,,,,,,,,,,,,,,,,,,,,,,,,,,,,,,,,,,,,
130.314,0.12036,0.49299,10,,,,,,,,,,,,,,,,,,,,,,,,,,,,,,,,,,,,,
130.914,0.1666,1.41255,10,,,,,,,,,,,,,,,,,,,,,,,,,,,,,,,,,,,,,
131.514,0.16671,1.43103,10,,,,,,,,,,,,,,,,,,,,,,,,,,,,,,,,,,,,,
132.114,0.1483,1.11377,10,,,,,,,,,,,,,,,,,,,,,,,,,,,,,,,,,,,,,
132.714,0.12937,0.77664,10,,,,,,,,,,,,,,,,,,,,,,,,,,,,,,,,,,,,,
133.314,0.12954,0.78986,10,,,,,,,,,,,,,,,,,,,,,,,,,,,,,,,,,,,,,
133.914,0.13011,0.794,10,,,,,,,,,,,,,,,,,,,,,,,,,,,,,,,,,,,,,
134.514,0.13424,0.84914,10,,,,,,,,,,,,,,,,,,,,,,,,,,,,,,,,,,,,,
135.114,0.14603,1.04653,10,,,,,,,,,,,,,,,,,,,,,,,,,,,,,,,,,,,,,
135.714,0.14824,1.15268,10,,,,,,,,,,,,,,,,,,,,,,,,,,,,,,,,,,,,,
136.314,0.14796,1.10498,10,,,,,,,,,,,,,,,,,,,,,,,,,,,,,,,,,,,,,
136.914,0.14699,1.13428,10,,,,,,,,,,,,,,,,,,,,,,,,,,,,,,,,,,,,,
137.514,0.14246,1.03095,10,,,,,,,,,,,,,,,,,,,,,,,,,,,,,,,,,,,,,
138.114,0.13509,0.88877,10,,,,,,,,,,,,,,,,,,,,,,,,,,,,,,,,,,,,,
138.714,0.13402,0.92411,10,,,,,,,,,,,,,,,,,,,,,,,,,,,,,,,,,,,,,
139.314,0.13379,0.94554,10,,,,,,,,,,,,,,,,,,,,,,,,,,,,,,,,,,,,,
139.914,0.1339,0.86741,10,,,,,,,,,,,,,,,,,,,,,,,,,,,,,,,,,,,,,
140.514,0.13402,0.94831,10,,,,,,,,,,,,,,,,,,,,,,,,,,,,,,,,,,,,,
141.114,0.13407,0.97203,10,,,,,,,,,,,,,,,,,,,,,,,,,,,,,,,,,,,,,
141.714,0.13419,0.91299,10,,,,,,,,,,,,,,,,,,,,,,,,,,,,,,,,,,,,,
142.314,0.1343,0.92826,10,,,,,,,,,,,,,,,,,,,,,,,,,,,,,,,,,,,,,
142.914,0.13447,0.92263,10,,,,,,,,,,,,,,,,,,,,,,,,,,,,,,,,,,,,,
143.514,0.13481,0.93153,10,,,,,,,,,,,,,,,,,,,,,,,,,,,,,,,,,,,,,
144.114,0.13538,0.92372,10,,,,,,,,,,,,,,,,,,,,,,,,,,,,,,,,,,,,,
144.714,0.136,0.94911,10,,,,,,,,,,,,,,,,,,,,,,,,,,,,,,,,,,,,,
145.314,0.13651,0.98147,10,,,,,,,,,,,,,,,,,,,,,,,,,,,,,,,,,,,,,
145.914,0.13708,1.01669,10,,,,,,,,,,,,,,,,,,,,,,,,,,,,,,,,,,,,,
146.514,0.13764,0.966,10,,,,,,,,,,,,,,,,,,,,,,,,,,,,,,,,,,,,,
147.114,0.13804,1.00226,10,,,,,,,,,,,,,,,,,,,,,,,,,,,,,,,,,,,,,
147.714,0.13815,1.05763,10,,,,,,,,,,,,,,,,,,,,,,,,,,,,,,,,,,,,,
148.314,0.13804,1.02715,10,,,,,,,,,,,,,,,,,,,,,,,,,,,,,,,,,,,,,
148.914,0.13798,0.9686,10,,,,,,,,,,,,,,,,,,,,,,,,,,,,,,,,,,,,,
149.514,0.13787,1.06639,10,,,,,,,,,,,,,,,,,,,,,,,,,,,,,,,,,,,,,
150.114,0.13776,1.04466,10,,,,,,,,,,,,,,,,,,,,,,,,,,,,,,,,,,,,,
150.714,0.13747,1.04762,10,,,,,,,,,,,,,,,,,,,,,,,,,,,,,,,,,,,,,
151.314,0.13696,1.05362,10,,,,,,,,,,,,,,,,,,,,,,,,,,,,,,,,,,,,,
151.914,0.13549,0.99147,10,,,,,,,,,,,,,,,,,,,,,,,,,,,,,,,,,,,,,
152.514,0.13379,0.98794,10,,,,,,,,,,,,,,,,,,,,,,,,,,,,,,,,,,,,,
153.114,0.13186,0.91959,10,,,,,,,,,,,,,,,,,,,,,,,,,,,,,,,,,,,,,
153.714,0.13084,0.98333,10,,,,,,,,,,,,,,,,,,,,,,,,,,,,,,,,,,,,,
154.314,0.13022,0.89167,10,,,,,,,,,,,,,,,,,,,,,,,,,,,,,,,,,,,,,
154.914,0.12994,0.91858,10,,,,,,,,,,,,,,,,,,,,,,,,,,,,,,,,,,,,,
155.514,0.12988,0.92909,10,,,,,,,,,,,,,,,,,,,,,,,,,,,,,,,,,,,,,
156.114,0.12982,0.92477,10,,,,,,,,,,,,,,,,,,,,,,,,,,,,,,,,,,,,,
156.714,0.12994,0.96974,10,,,,,,,,,,,,,,,,,,,,,,,,,,,,,,,,,,,,,
157.314,0.12999,0.93169,10,,,,,,,,,,,,,,,,,,,,,,,,,,,,,,,,,,,,,
157.914,0.13005,0.89017,10,,,,,,,,,,,,,,,,,,,,,,,,,,,,,,,,,,,,,
158.514,0.13005,0.94662,10,,,,,,,,,,,,,,,,,,,,,,,,,,,,,,,,,,,,,
159.114,0.13011,0.89965,10,,,,,,,,,,,,,,,,,,,,,,,,,,,,,,,,,,,,,
159.714,0.13022,0.96592,10,,,,,,,,,,,,,,,,,,,,,,,,,,,,,,,,,,,,,
160.314,0.13039,0.88428,10,,,,,,,,,,,,,,,,,,,,,,,,,,,,,,,,,,,,,
160.914,0.13067,0.89674,10,,,,,,,,,,,,,,,,,,,,,,,,,,,,,,,,,,,,,
161.514,0.13101,0.97101,10,,,,,,,,,,,,,,,,,,,,,,,,,,,,,,,,,,,,,
162.114,0.13141,0.90894,10,,,,,,,,,,,,,,,,,,,,,,,,,,,,,,,,,,,,,
162.714,0.13226,0.97155,10,,,,,,,,,,,,,,,,,,,,,,,,,,,,,,,,,,,,,
163.314,0.13328,1.01323,10,,,,,,,,,,,,,,,,,,,,,,,,,,,,,,,,,,,,,
163.914,0.13373,0.97656,10,,,,,,,,,,,,,,,,,,,,,,,,,,,,,,,,,,,,,
164.514,0.13402,0.99839,10,,,,,,,,,,,,,,,,,,,,,,,,,,,,,,,,,,,,,
165.114,0.13419,1.00199,10,,,,,,,,,,,,,,,,,,,,,,,,,,,,,,,,,,,,,
165.714,0.13407,1.12841,10,,,,,,,,,,,,,,,,,,,,,,,,,,,,,,,,,,,,,
166.314,0.13407,1.00073,10,,,,,,,,,,,,,,,,,,,,,,,,,,,,,,,,,,,,,
166.914,0.13402,1.02601,10,,,,,,,,,,,,,,,,,,,,,,,,,,,,,,,,,,,,,
167.514,0.13396,1.01181,10,,,,,,,,,,,,,,,,,,,,,,,,,,,,,,,,,,,,,
168.114,0.1339,1.02523,10,,,,,,,,,,,,,,,,,,,,,,,,,,,,,,,,,,,,,
168.714,0.13379,1.03823,10,,,,,,,,,,,,,,,,,,,,,,,,,,,,,,,,,,,,,
169.314,0.13351,1.03966,10,,,,,,,,,,,,,,,,,,,,,,,,,,,,,,,,,,,,,
169.914,0.13294,1.03706,10,,,,,,,,,,,,,,,,,,,,,,,,,,,,,,,,,,,,,
170.514,0.13181,1.06295,10,,,,,,,,,,,,,,,,,,,,,,,,,,,,,,,,,,,,,
171.114,0.12999,1.00332,10,,,,,,,,,,,,,,,,,,,,,,,,,,,,,,,,,,,,,
171.714,0.1279,1.03469,10,,,,,,,,,,,,,,,,,,,,,,,,,,,,,,,,,,,,,
172.314,0.12597,0.92036,10,,,,,,,,,,,,,,,,,,,,,,,,,,,,,,,,,,,,,
172.914,0.12552,0.92565,10,,,,,,,,,,,,,,,,,,,,,,,,,,,,,,,,,,,,,
173.514,0.1254,0.94654,10,,,,,,,,,,,,,,,,,,,,,,,,,,,,,,,,,,,,,
174.114,0.12552,0.92245,10,,,,,,,,,,,,,,,,,,,,,,,,,,,,,,,,,,,,,
174.714,0.12552,0.97903,10,,,,,,,,,,,,,,,,,,,,,,,,,,,,,,,,,,,,,
175.314,0.12569,0.88863,10,,,,,,,,,,,,,,,,,,,,,,,,,,,,,,,,,,,,,
175.914,0.12569,0.96475,10,,,,,,,,,,,,,,,,,,,,,,,,,,,,,,,,,,,,,
176.514,0.1258,0.88446,10,,,,,,,,,,,,,,,,,,,,,,,,,,,,,,,,,,,,,
177.114,0.12608,0.87206,10,,,,,,,,,,,,,,,,,,,,,,,,,,,,,,,,,,,,,
177.714,0.12654,0.93309,10,,,,,,,,,,,,,,,,,,,,,,,,,,,,,,,,,,,,,
178.314,0.12739,0.92734,10,,,,,,,,,,,,,,,,,,,,,,,,,,,,,,,,,,,,,
178.914,0.12903,0.94637,10,,,,,,,,,,,,,,,,,,,,,,,,,,,,,,,,,,,,,
179.514,0.13209,0.98988,10,,,,,,,,,,,,,,,,,,,,,,,,,,,,,,,,,,,,,
180.114,0.13368,1.00138,10,,,,,,,,,,,,,,,,,,,,,,,,,,,,,,,,,,,,,
180.714,0.13373,1.014,10,,,,,,,,,,,,,,,,,,,,,,,,,,,,,,,,,,,,,
181.314,0.13373,1.05466,10,,,,,,,,,,,,,,,,,,,,,,,,,,,,,,,,,,,,,
181.914,0.13362,1.02917,10,,,,,,,,,,,,,,,,,,,,,,,,,,,,,,,,,,,,,
182.514,0.13345,1.09969,10,,,,,,,,,,,,,,,,,,,,,,,,,,,,,,,,,,,,,
183.114,0.13334,1.04012,10,,,,,,,,,,,,,,,,,,,,,,,,,,,,,,,,,,,,,
183.714,0.13288,1.11191,10,,,,,,,,,,,,,,,,,,,,,,,,,,,,,,,,,,,,,
184.314,0.13186,1.00222,10,,,,,,,,,,,,,,,,,,,,,,,,,,,,,,,,,,,,,
184.914,0.13011,1.00233,10,,,,,,,,,,,,,,,,,,,,,,,,,,,,,,,,,,,,,
185.514,0.12835,0.97264,10,,,,,,,,,,,,,,,,,,,,,,,,,,,,,,,,,,,,,
186.114,0.12693,0.97785,10,,,,,,,,,,,,,,,,,,,,,,,,,,,,,,,,,,,,,
186.714,0.12648,0.95714,10,,,,,,,,,,,,,,,,,,,,,,,,,,,,,,,,,,,,,
187.314,0.12631,0.91699,10,,,,,,,,,,,,,,,,,,,,,,,,,,,,,,,,,,,,,
187.914,0.12625,0.912,10,,,,,,,,,,,,,,,,,,,,,,,,,,,,,,,,,,,,,
188.514,0.12637,0.91579,10,,,,,,,,,,,,,,,,,,,,,,,,,,,,,,,,,,,,,
189.114,0.12642,0.89697,10,,,,,,,,,,,,,,,,,,,,,,,,,,,,,,,,,,,,,
189.714,0.12648,0.95319,10,,,,,,,,,,,,,,,,,,,,,,,,,,,,,,,,,,,,,
190.314,0.12648,0.93671,10,,,,,,,,,,,,,,,,,,,,,,,,,,,,,,,,,,,,,
190.914,0.12654,0.96393,10,,,,,,,,,,,,,,,,,,,,,,,,,,,,,,,,,,,,,
191.514,0.12665,0.95295,10,,,,,,,,,,,,,,,,,,,,,,,,,,,,,,,,,,,,,
192.114,0.12676,0.9133,10,,,,,,,,,,,,,,,,,,,,,,,,,,,,,,,,,,,,,
192.714,0.12705,0.94187,10,,,,,,,,,,,,,,,,,,,,,,,,,,,,,,,,,,,,,
193.314,0.12739,0.92246,10,,,,,,,,,,,,,,,,,,,,,,,,,,,,,,,,,,,,,
193.914,0.12778,0.92813,10,,,,,,,,,,,,,,,,,,,,,,,,,,,,,,,,,,,,,
194.514,0.12852,0.99127,10,,,,,,,,,,,,,,,,,,,,,,,,,,,,,,,,,,,,,
195.114,0.12954,0.95931,10,,,,,,,,,,,,,,,,,,,,,,,,,,,,,,,,,,,,,
195.714,0.13016,0.97869,10,,,,,,,,,,,,,,,,,,,,,,,,,,,,,,,,,,,,,
196.314,0.13056,0.99731,10,,,,,,,,,,,,,,,,,,,,,,,,,,,,,,,,,,,,,
196.914,0.13079,0.94357,10,,,,,,,,,,,,,,,,,,,,,,,,,,,,,,,,,,,,,
197.514,0.13096,1.04352,10,,,,,,,,,,,,,,,,,,,,,,,,,,,,,,,,,,,,,
198.114,0.13084,0.97951,10,,,,,,,,,,,,,,,,,,,,,,,,,,,,,,,,,,,,,
198.714,0.13079,1.0192,10,,,,,,,,,,,,,,,,,,,,,,,,,,,,,,,,,,,,,
199.314,0.13079,1.00382,10,,,,,,,,,,,,,,,,,,,,,,,,,,,,,,,,,,,,,
199.914,0.13079,0.98783,10,,,,,,,,,,,,,,,,,,,,,,,,,,,,,,,,,,,,,
200.514,0.13073,1.02749,10,,,,,,,,,,,,,,,,,,,,,,,,,,,,,,,,,,,,,
201.114,0.13067,0.97288,10,,,,,,,,,,,,,,,,,,,,,,,,,,,,,,,,,,,,,
201.714,0.13062,1.01494,10,,,,,,,,,,,,,,,,,,,,,,,,,,,,,,,,,,,,,
202.314,0.13062,0.98548,10,,,,,,,,,,,,,,,,,,,,,,,,,,,,,,,,,,,,,
202.914,0.13056,1.00943,10,,,,,,,,,,,,,,,,,,,,,,,,,,,,,,,,,,,,,
203.514,0.13045,1.01217,10,,,,,,,,,,,,,,,,,,,,,,,,,,,,,,,,,,,,,
204.114,0.13022,0.98265,10,,,,,,,,,,,,,,,,,,,,,,,,,,,,,,,,,,,,,
204.714,0.12994,1.005,10,,,,,,,,,,,,,,,,,,,,,,,,,,,,,,,,,,,,,
205.314,0.12937,0.98268,10,,,,,,,,,,,,,,,,,,,,,,,,,,,,,,,,,,,,,
205.914,0.12869,0.98735,10,,,,,,,,,,,,,,,,,,,,,,,,,,,,,,,,,,,,,
206.514,0.12767,1.03021,10,,,,,,,,,,,,,,,,,,,,,,,,,,,,,,,,,,,,,
207.114,0.12665,0.95082,10,,,,,,,,,,,,,,,,,,,,,,,,,,,,,,,,,,,,,
207.714,0.12608,0.95933,10,,,,,,,,,,,,,,,,,,,,,,,,,,,,,,,,,,,,,
208.314,0.12563,0.93124,10,,,,,,,,,,,,,,,,,,,,,,,,,,,,,,,,,,,,,
208.914,0.12546,0.98764,10,,,,,,,,,,,,,,,,,,,,,,,,,,,,,,,,,,,,,
209.514,0.1254,0.99734,10,,,,,,,,,,,,,,,,,,,,,,,,,,,,,,,,,,,,,
210.114,0.12529,0.94347,10,,,,,,,,,,,,,,,,,,,,,,,,,,,,,,,,,,,,,
210.714,0.12523,0.97616,10,,,,,,,,,,,,,,,,,,,,,,,,,,,,,,,,,,,,,
211.314,0.12518,0.96254,10,,,,,,,,,,,,,,,,,,,,,,,,,,,,,,,,,,,,,
211.914,0.12523,0.95433,10,,,,,,,,,,,,,,,,,,,,,,,,,,,,,,,,,,,,,
212.514,0.12535,0.97294,10,,,,,,,,,,,,,,,,,,,,,,,,,,,,,,,,,,,,,
213.114,0.12535,0.96566,10,,,,,,,,,,,,,,,,,,,,,,,,,,,,,,,,,,,,,
213.714,0.12535,0.97174,10,,,,,,,,,,,,,,,,,,,,,,,,,,,,,,,,,,,,,
214.314,0.12535,0.96049,10,,,,,,,,,,,,,,,,,,,,,,,,,,,,,,,,,,,,,
214.914,0.1254,0.91822,10,,,,,,,,,,,,,,,,,,,,,,,,,,,,,,,,,,,,,
215.514,0.1254,0.96986,10,,,,,,,,,,,,,,,,,,,,,,,,,,,,,,,,,,,,,
216.114,0.12535,0.91954,10,,,,,,,,,,,,,,,,,,,,,,,,,,,,,,,,,,,,,
216.714,0.12546,0.99313,10,,,,,,,,,,,,,,,,,,,,,,,,,,,,,,,,,,,,,
217.314,0.12546,0.97458,10,,,,,,,,,,,,,,,,,,,,,,,,,,,,,,,,,,,,,
217.914,0.12552,0.97104,10,,,,,,,,,,,,,,,,,,,,,,,,,,,,,,,,,,,,,
218.514,0.12552,0.96112,10,,,,,,,,,,,,,,,,,,,,,,,,,,,,,,,,,,,,,
219.114,0.12569,0.93856,10,,,,,,,,,,,,,,,,,,,,,,,,,,,,,,,,,,,,,
219.714,0.12591,0.94092,10,,,,,,,,,,,,,,,,,,,,,,,,,,,,,,,,,,,,,
220.314,0.12614,0.90116,10,,,,,,,,,,,,,,,,,,,,,,,,,,,,,,,,,,,,,
220.914,0.12654,0.9229,10,,,,,,,,,,,,,,,,,,,,,,,,,,,,,,,,,,,,,
221.514,0.1271,0.95284,10,,,,,,,,,,,,,,,,,,,,,,,,,,,,,,,,,,,,,
222.114,0.12767,0.97969,10,,,,,,,,,,,,,,,,,,,,,,,,,,,,,,,,,,,,,
222.714,0.12846,0.99496,10,,,,,,,,,,,,,,,,,,,,,,,,,,,,,,,,,,,,,
223.314,0.12914,0.98894,10,,,,,,,,,,,,,,,,,,,,,,,,,,,,,,,,,,,,,
223.914,0.12977,0.97483,10,,,,,,,,,,,,,,,,,,,,,,,,,,,,,,,,,,,,,
224.514,0.12994,1.07919,10,,,,,,,,,,,,,,,,,,,,,,,,,,,,,,,,,,,,,
225.114,0.12982,1.0391,10,,,,,,,,,,,,,,,,,,,,,,,,,,,,,,,,,,,,,
225.714,0.12982,0.98309,10,,,,,,,,,,,,,,,,,,,,,,,,,,,,,,,,,,,,,
226.314,0.12977,1.03326,10,,,,,,,,,,,,,,,,,,,,,,,,,,,,,,,,,,,,,
226.914,0.12971,1.00015,10,,,,,,,,,,,,,,,,,,,,,,,,,,,,,,,,,,,,,
227.514,0.12965,0.98714,10,,,,,,,,,,,,,,,,,,,,,,,,,,,,,,,,,,,,,
228.114,0.1296,0.98455,10,,,,,,,,,,,,,,,,,,,,,,,,,,,,,,,,,,,,,
228.714,0.12954,1.01887,10,,,,,,,,,,,,,,,,,,,,,,,,,,,,,,,,,,,,,
229.314,0.12943,1.02878,10,,,,,,,,,,,,,,,,,,,,,,,,,,,,,,,,,,,,,
229.914,0.12914,1.03237,10,,,,,,,,,,,,,,,,,,,,,,,,,,,,,,,,,,,,,
230.514,0.12875,0.97181,10,,,,,,,,,,,,,,,,,,,,,,,,,,,,,,,,,,,,,
231.114,0.12784,1.03014,10,,,,,,,,,,,,,,,,,,,,,,,,,,,,,,,,,,,,,
231.714,0.12693,1.00612,10,,,,,,,,,,,,,,,,,,,,,,,,,,,,,,,,,,,,,
232.314,0.12637,0.94021,10,,,,,,,,,,,,,,,,,,,,,,,,,,,,,,,,,,,,,
232.914,0.12591,0.9678,10,,,,,,,,,,,,,,,,,,,,,,,,,,,,,,,,,,,,,
233.514,0.12557,0.96702,10,,,,,,,,,,,,,,,,,,,,,,,,,,,,,,,,,,,,,
234.114,0.12535,0.93583,10,,,,,,,,,,,,,,,,,,,,,,,,,,,,,,,,,,,,,
234.714,0.12529,0.97908,10,,,,,,,,,,,,,,,,,,,,,,,,,,,,,,,,,,,,,
235.314,0.12518,0.97817,10,,,,,,,,,,,,,,,,,,,,,,,,,,,,,,,,,,,,,
235.914,0.12529,0.93996,10,,,,,,,,,,,,,,,,,,,,,,,,,,,,,,,,,,,,,
236.514,0.12529,0.96478,10,,,,,,,,,,,,,,,,,,,,,,,,,,,,,,,,,,,,,
237.114,0.12535,0.95773,10,,,,,,,,,,,,,,,,,,,,,,,,,,,,,,,,,,,,,
237.714,0.1254,0.9364,10,,,,,,,,,,,,,,,,,,,,,,,,,,,,,,,,,,,,,
238.314,0.1254,0.92938,10,,,,,,,,,,,,,,,,,,,,,,,,,,,,,,,,,,,,,
238.914,0.12546,0.94963,10,,,,,,,,,,,,,,,,,,,,,,,,,,,,,,,,,,,,,
239.514,0.12546,1.00201,10,,,,,,,,,,,,,,,,,,,,,,,,,,,,,,,,,,,,,
240.114,0.12546,0.95229,10,,,,,,,,,,,,,,,,,,,,,,,,,,,,,,,,,,,,,
240.714,0.12552,0.99287,10,,,,,,,,,,,,,,,,,,,,,,,,,,,,,,,,,,,,,
241.314,0.12552,0.95048,10,,,,,,,,,,,,,,,,,,,,,,,,,,,,,,,,,,,,,
241.914,0.12552,1.01079,10,,,,,,,,,,,,,,,,,,,,,,,,,,,,,,,,,,,,,
242.514,0.12552,1.02489,10,,,,,,,,,,,,,,,,,,,,,,,,,,,,,,,,,,,,,
243.114,0.12552,0.97527,10,,,,,,,,,,,,,,,,,,,,,,,,,,,,,,,,,,,,,
243.714,0.12552,0.97155,10,,,,,,,,,,,,,,,,,,,,,,,,,,,,,,,,,,,,,
244.314,0.12552,0.94343,10,,,,,,,,,,,,,,,,,,,,,,,,,,,,,,,,,,,,,
244.914,0.12546,1.00747,10,,,,,,,,,,,,,,,,,,,,,,,,,,,,,,,,,,,,,
245.514,0.12557,0.97151,10,,,,,,,,,,,,,,,,,,,,,,,,,,,,,,,,,,,,,
246.114,0.12563,0.94014,10,,,,,,,,,,,,,,,,,,,,,,,,,,,,,,,,,,,,,
246.714,0.12569,0.95373,10,,,,,,,,,,,,,,,,,,,,,,,,,,,,,,,,,,,,,
247.314,0.1258,0.92438,10,,,,,,,,,,,,,,,,,,,,,,,,,,,,,,,,,,,,,
247.914,0.12597,0.94386,10,,,,,,,,,,,,,,,,,,,,,,,,,,,,,,,,,,,,,
248.514,0.1262,0.97913,10,,,,,,,,,,,,,,,,,,,,,,,,,,,,,,,,,,,,,
249.114,0.12637,0.98188,10,,,,,,,,,,,,,,,,,,,,,,,,,,,,,,,,,,,,,
249.714,0.12665,0.98442,10,,,,,,,,,,,,,,,,,,,,,,,,,,,,,,,,,,,,,
250.314,0.12699,0.97045,10,,,,,,,,,,,,,,,,,,,,,,,,,,,,,,,,,,,,,
250.914,0.12744,1.0026,10,,,,,,,,,,,,,,,,,,,,,,,,,,,,,,,,,,,,,
251.514,0.1279,1.05579,10,,,,,,,,,,,,,,,,,,,,,,,,,,,,,,,,,,,,,
252.114,0.12818,1.01407,10,,,,,,,,,,,,,,,,,,,,,,,,,,,,,,,,,,,,,
252.714,0.12852,0.99833,10,,,,,,,,,,,,,,,,,,,,,,,,,,,,,,,,,,,,,
253.314,0.12869,1.05331,10,,,,,,,,,,,,,,,,,,,,,,,,,,,,,,,,,,,,,
253.914,0.12858,1.03087,10,,,,,,,,,,,,,,,,,,,,,,,,,,,,,,,,,,,,,
254.514,0.12852,1.06817,10,,,,,,,,,,,,,,,,,,,,,,,,,,,,,,,,,,,,,
255.114,0.12846,1.01568,10,,,,,,,,,,,,,,,,,,,,,,,,,,,,,,,,,,,,,
255.714,0.12835,1.03567,10,,,,,,,,,,,,,,,,,,,,,,,,,,,,,,,,,,,,,
256.314,0.12829,1.00968,10,,,,,,,,,,,,,,,,,,,,,,,,,,,,,,,,,,,,,
256.914,0.12824,1.00678,10,,,,,,,,,,,,,,,,,,,,,,,,,,,,,,,,,,,,,
257.514,0.12818,1.00916,10,,,,,,,,,,,,,,,,,,,,,,,,,,,,,,,,,,,,,
258.114,0.12795,0.97558,10,,,,,,,,,,,,,,,,,,,,,,,,,,,,,,,,,,,,,
258.714,0.12761,1.04686,10,,,,,,,,,,,,,,,,,,,,,,,,,,,,,,,,,,,,,
259.314,0.12716,0.98632,10,,,,,,,,,,,,,,,,,,,,,,,,,,,,,,,,,,,,,
259.914,0.12637,1.05086,10,,,,,,,,,,,,,,,,,,,,,,,,,,,,,,,,,,,,,
260.514,0.12546,0.99001,10,,,,,,,,,,,,,,,,,,,,,,,,,,,,,,,,,,,,,
261.114,0.12444,0.90775,10,,,,,,,,,,,,,,,,,,,,,,,,,,,,,,,,,,,,,
261.714,0.12376,0.97331,10,,,,,,,,,,,,,,,,,,,,,,,,,,,,,,,,,,,,,
262.314,0.12325,0.91437,10,,,,,,,,,,,,,,,,,,,,,,,,,,,,,,,,,,,,,
262.914,0.12297,0.9738,10,,,,,,,,,,,,,,,,,,,,,,,,,,,,,,,,,,,,,
263.514,0.12291,0.96054,10,,,,,,,,,,,,,,,,,,,,,,,,,,,,,,,,,,,,,
264.114,0.12291,0.93915,10,,,,,,,,,,,,,,,,,,,,,,,,,,,,,,,,,,,,,
264.714,0.12291,0.91457,10,,,,,,,,,,,,,,,,,,,,,,,,,,,,,,,,,,,,,
265.314,0.12302,0.94807,10,,,,,,,,,,,,,,,,,,,,,,,,,,,,,,,,,,,,,
265.914,0.12308,1.00777,10,,,,,,,,,,,,,,,,,,,,,,,,,,,,,,,,,,,,,
266.514,0.12314,0.93912,10,,,,,,,,,,,,,,,,,,,,,,,,,,,,,,,,,,,,,
267.114,0.12319,0.9056,10,,,,,,,,,,,,,,,,,,,,,,,,,,,,,,,,,,,,,
267.714,0.12331,0.94097,10,,,,,,,,,,,,,,,,,,,,,,,,,,,,,,,,,,,,,
268.314,0.12353,0.926,10,,,,,,,,,,,,,,,,,,,,,,,,,,,,,,,,,,,,,
268.914,0.12382,1.00994,10,,,,,,,,,,,,,,,,,,,,,,,,,,,,,,,,,,,,,
269.514,0.12416,0.94585,10,,,,,,,,,,,,,,,,,,,,,,,,,,,,,,,,,,,,,
270.114,0.12461,0.96834,10,,,,,,,,,,,,,,,,,,,,,,,,,,,,,,,,,,,,,
270.714,0.12518,0.92976,10,,,,,,,,,,,,,,,,,,,,,,,,,,,,,,,,,,,,,
271.314,0.12614,0.94358,10,,,,,,,,,,,,,,,,,,,,,,,,,,,,,,,,,,,,,
271.914,0.12756,1.02706,10,,,,,,,,,,,,,,,,,,,,,,,,,,,,,,,,,,,,,
272.514,0.12818,0.98381,10,,,,,,,,,,,,,,,,,,,,,,,,,,,,,,,,,,,,,
273.114,0.12875,1.00562,10,,,,,,,,,,,,,,,,,,,,,,,,,,,,,,,,,,,,,
273.714,0.12897,1.00188,10,,,,,,,,,,,,,,,,,,,,,,,,,,,,,,,,,,,,,
274.314,0.12892,1.07623,10,,,,,,,,,,,,,,,,,,,,,,,,,,,,,,,,,,,,,
274.914,0.12886,1.05149,10,,,,,,,,,,,,,,,,,,,,,,,,,,,,,,,,,,,,,
275.514,0.12875,1.09771,10,,,,,,,,,,,,,,,,,,,,,,,,,,,,,,,,,,,,,
276.114,0.12869,1.00666,10,,,,,,,,,,,,,,,,,,,,,,,,,,,,,,,,,,,,,
276.714,0.12852,1.02046,10,,,,,,,,,,,,,,,,,,,,,,,,,,,,,,,,,,,,,
277.314,0.12824,0.97017,10,,,,,,,,,,,,,,,,,,,,,,,,,,,,,,,,,,,,,
277.914,0.12767,1.04937,10,,,,,,,,,,,,,,,,,,,,,,,,,,,,,,,,,,,,,
278.514,0.12676,1.01607,10,,,,,,,,,,,,,,,,,,,,,,,,,,,,,,,,,,,,,
279.114,0.12557,0.98493,10,,,,,,,,,,,,,,,,,,,,,,,,,,,,,,,,,,,,,
279.714,0.12461,0.95156,10,,,,,,,,,,,,,,,,,,,,,,,,,,,,,,,,,,,,,
280.314,0.12393,0.95465,10,,,,,,,,,,,,,,,,,,,,,,,,,,,,,,,,,,,,,
280.914,0.12359,0.96365,10,,,,,,,,,,,,,,,,,,,,,,,,,,,,,,,,,,,,,
281.514,0.12336,0.96106,10,,,,,,,,,,,,,,,,,,,,,,,,,,,,,,,,,,,,,
282.114,0.12319,0.94979,10,,,,,,,,,,,,,,,,,,,,,,,,,,,,,,,,,,,,,
282.714,0.12314,0.97741,10,,,,,,,,,,,,,,,,,,,,,,,,,,,,,,,,,,,,,
283.314,0.12325,0.93336,10,,,,,,,,,,,,,,,,,,,,,,,,,,,,,,,,,,,,,
283.914,0.12331,0.94027,10,,,,,,,,,,,,,,,,,,,,,,,,,,,,,,,,,,,,,
284.514,0.12325,0.94183,10,,,,,,,,,,,,,,,,,,,,,,,,,,,,,,,,,,,,,
285.114,0.12336,0.92164,10,,,,,,,,,,,,,,,,,,,,,,,,,,,,,,,,,,,,,
285.714,0.12336,0.95721,10,,,,,,,,,,,,,,,,,,,,,,,,,,,,,,,,,,,,,
286.314,0.12336,0.95811,10,,,,,,,,,,,,,,,,,,,,,,,,,,,,,,,,,,,,,
286.914,0.12342,0.90189,10,,,,,,,,,,,,,,,,,,,,,,,,,,,,,,,,,,,,,
287.514,0.12348,0.93009,10,,,,,,,,,,,,,,,,,,,,,,,,,,,,,,,,,,,,,
288.114,0.12353,0.98596,10,,,,,,,,,,,,,,,,,,,,,,,,,,,,,,,,,,,,,
288.714,0.12365,0.91124,10,,,,,,,,,,,,,,,,,,,,,,,,,,,,,,,,,,,,,
289.314,0.12376,0.97536,10,,,,,,,,,,,,,,,,,,,,,,,,,,,,,,,,,,,,,
289.914,0.12387,0.92218,10,,,,,,,,,,,,,,,,,,,,,,,,,,,,,,,,,,,,,
290.514,0.1241,0.93636,10,,,,,,,,,,,,,,,,,,,,,,,,,,,,,,,,,,,,,
291.114,0.12444,0.92582,10,,,,,,,,,,,,,,,,,,,,,,,,,,,,,,,,,,,,,
291.714,0.12478,0.93161,10,,,,,,,,,,,,,,,,,,,,,,,,,,,,,,,,,,,,,
292.314,0.12529,0.93063,10,,,,,,,,,,,,,,,,,,,,,,,,,,,,,,,,,,,,,
292.914,0.12563,0.9607,10,,,,,,,,,,,,,,,,,,,,,,,,,,,,,,,,,,,,,
293.514,0.12614,0.98009,10,,,,,,,,,,,,,,,,,,,,,,,,,,,,,,,,,,,,,
294.114,0.12705,0.96228,10,,,,,,,,,,,,,,,,,,,,,,,,,,,,,,,,,,,,,
294.714,0.12761,0.99461,10,,,,,,,,,,,,,,,,,,,,,,,,,,,,,,,,,,,,,
295.314,0.1279,0.99077,10,,,,,,,,,,,,,,,,,,,,,,,,,,,,,,,,,,,,,
295.914,0.12801,1.06297,10,,,,,,,,,,,,,,,,,,,,,,,,,,,,,,,,,,,,,
296.514,0.1279,0.9948,10,,,,,,,,,,,,,,,,,,,,,,,,,,,,,,,,,,,,,
297.114,0.12778,1.01981,10,,,,,,,,,,,,,,,,,,,,,,,,,,,,,,,,,,,,,
297.714,0.12773,1.03094,10,,,,,,,,,,,,,,,,,,,,,,,,,,,,,,,,,,,,,
298.314,0.12773,0.96085,10,,,,,,,,,,,,,,,,,,,,,,,,,,,,,,,,,,,,,
298.914,0.12767,1.01651,10,,,,,,,,,,,,,,,,,,,,,,,,,,,,,,,,,,,,,
299.514,0.12756,1.06388,10,,,,,,,,,,,,,,,,,,,,,,,,,,,,,,,,,,,,,
300.114,0.12733,1.02823,10,,,,,,,,,,,,,,,,,,,,,,,,,,,,,,,,,,,,,
300.714,0.12705,1.03514,10,,,,,,,,,,,,,,,,,,,,,,,,,,,,,,,,,,,,,
301.314,0.12648,0.99769,10,,,,,,,,,,,,,,,,,,,,,,,,,,,,,,,,,,,,,
301.914,0.12569,0.95907,10,,,,,,,,,,,,,,,,,,,,,,,,,,,,,,,,,,,,,
302.514,0.12472,0.96564,10,,,,,,,,,,,,,,,,,,,,,,,,,,,,,,,,,,,,,
303.114,0.12416,0.93861,10,,,,,,,,,,,,,,,,,,,,,,,,,,,,,,,,,,,,,
303.714,0.12376,0.9754,10,,,,,,,,,,,,,,,,,,,,,,,,,,,,,,,,,,,,,
304.314,0.12342,0.95289,10,,,,,,,,,,,,,,,,,,,,,,,,,,,,,,,,,,,,,
304.914,0.12325,1.01544,10,,,,,,,,,,,,,,,,,,,,,,,,,,,,,,,,,,,,,
305.514,0.12302,0.97756,10,,,,,,,,,,,,,,,,,,,,,,,,,,,,,,,,,,,,,
306.114,0.12297,0.95375,10,,,,,,,,,,,,,,,,,,,,,,,,,,,,,,,,,,,,,
306.714,0.12291,0.9854,10,,,,,,,,,,,,,,,,,,,,,,,,,,,,,,,,,,,,,
307.314,0.12291,0.97182,10,,,,,,,,,,,,,,,,,,,,,,,,,,,,,,,,,,,,,
307.914,0.12302,0.9363,10,,,,,,,,,,,,,,,,,,,,,,,,,,,,,,,,,,,,,
308.514,0.12302,0.97065,10,,,,,,,,,,,,,,,,,,,,,,,,,,,,,,,,,,,,,
309.114,0.12308,0.97146,10,,,,,,,,,,,,,,,,,,,,,,,,,,,,,,,,,,,,,
309.714,0.12314,0.95201,10,,,,,,,,,,,,,,,,,,,,,,,,,,,,,,,,,,,,,
310.314,0.12314,0.93821,10,,,,,,,,,,,,,,,,,,,,,,,,,,,,,,,,,,,,,
310.914,0.12319,0.90578,10,,,,,,,,,,,,,,,,,,,,,,,,,,,,,,,,,,,,,
311.514,0.12325,0.93718,10,,,,,,,,,,,,,,,,,,,,,,,,,,,,,,,,,,,,,
312.114,0.12331,0.93849,10,,,,,,,,,,,,,,,,,,,,,,,,,,,,,,,,,,,,,
312.714,0.12342,0.91664,10,,,,,,,,,,,,,,,,,,,,,,,,,,,,,,,,,,,,,
313.314,0.12359,0.93929,10,,,,,,,,,,,,,,,,,,,,,,,,,,,,,,,,,,,,,
313.914,0.12376,0.9886,10,,,,,,,,,,,,,,,,,,,,,,,,,,,,,,,,,,,,,
314.514,0.12387,1.02007,10,,,,,,,,,,,,,,,,,,,,,,,,,,,,,,,,,,,,,
315.114,0.12387,0.92103,10,,,,,,,,,,,,,,,,,,,,,,,,,,,,,,,,,,,,,
315.714,0.12404,0.94323,10,,,,,,,,,,,,,,,,,,,,,,,,,,,,,,,,,,,,,
316.314,0.12427,0.95268,10,,,,,,,,,,,,,,,,,,,,,,,,,,,,,,,,,,,,,
316.914,0.12461,0.97546,10,,,,,,,,,,,,,,,,,,,,,,,,,,,,,,,,,,,,,
317.514,0.12501,0.97796,10,,,,,,,,,,,,,,,,,,,,,,,,,,,,,,,,,,,,,
318.114,0.12535,0.94675,10,,,,,,,,,,,,,,,,,,,,,,,,,,,,,,,,,,,,,
318.714,0.12574,0.96403,10,,,,,,,,,,,,,,,,,,,,,,,,,,,,,,,,,,,,,
319.314,0.12614,0.96706,10,,,,,,,,,,,,,,,,,,,,,,,,,,,,,,,,,,,,,
319.914,0.12648,0.94228,10,,,,,,,,,,,,,,,,,,,,,,,,,,,,,,,,,,,,,
320.514,0.12671,0.99693,10,,,,,,,,,,,,,,,,,,,,,,,,,,,,,,,,,,,,,
321.114,0.12682,1.00463,10,,,,,,,,,,,,,,,,,,,,,,,,,,,,,,,,,,,,,
321.714,0.12682,0.98471,10,,,,,,,,,,,,,,,,,,,,,,,,,,,,,,,,,,,,,
322.314,0.12665,1.01114,10,,,,,,,,,,,,,,,,,,,,,,,,,,,,,,,,,,,,,
322.914,0.12665,1.00752,10,,,,,,,,,,,,,,,,,,,,,,,,,,,,,,,,,,,,,
323.514,0.12654,1.04362,10,,,,,,,,,,,,,,,,,,,,,,,,,,,,,,,,,,,,,
324.114,0.12648,1.01811,10,,,,,,,,,,,,,,,,,,,,,,,,,,,,,,,,,,,,,
324.714,0.12642,1.0366,10,,,,,,,,,,,,,,,,,,,,,,,,,,,,,,,,,,,,,
325.314,0.12631,1.00316,10,,,,,,,,,,,,,,,,,,,,,,,,,,,,,,,,,,,,,
325.914,0.12608,1.0294,10,,,,,,,,,,,,,,,,,,,,,,,,,,,,,,,,,,,,,
326.514,0.12586,1.01513,10,,,,,,,,,,,,,,,,,,,,,,,,,,,,,,,,,,,,,
327.114,0.12546,0.9788,10,,,,,,,,,,,,,,,,,,,,,,,,,,,,,,,,,,,,,
327.714,0.12501,1.02306,10,,,,,,,,,,,,,,,,,,,,,,,,,,,,,,,,,,,,,
328.314,0.1245,0.93308,10,,,,,,,,,,,,,,,,,,,,,,,,,,,,,,,,,,,,,
328.914,0.12399,0.97562,10,,,,,,,,,,,,,,,,,,,,,,,,,,,,,,,,,,,,,
329.514,0.12348,0.95862,10,,,,,,,,,,,,,,,,,,,,,,,,,,,,,,,,,,,,,
330.114,0.1228,0.9387,10,,,,,,,,,,,,,,,,,,,,,,,,,,,,,,,,,,,,,
330.714,0.12251,0.99229,10,,,,,,,,,,,,,,,,,,,,,,,,,,,,,,,,,,,,,
331.314,0.12246,0.97727,10,,,,,,,,,,,,,,,,,,,,,,,,,,,,,,,,,,,,,
331.914,0.12257,0.89343,10,,,,,,,,,,,,,,,,,,,,,,,,,,,,,,,,,,,,,
332.514,0.12263,0.90486,10,,,,,,,,,,,,,,,,,,,,,,,,,,,,,,,,,,,,,
333.114,0.12263,0.94039,10,,,,,,,,,,,,,,,,,,,,,,,,,,,,,,,,,,,,,
333.714,0.12274,1.00026,10,,,,,,,,,,,,,,,,,,,,,,,,,,,,,,,,,,,,,
334.314,0.1228,0.88733,10,,,,,,,,,,,,,,,,,,,,,,,,,,,,,,,,,,,,,
334.914,0.12291,0.9592,10,,,,,,,,,,,,,,,,,,,,,,,,,,,,,,,,,,,,,
335.514,0.12297,0.88393,10,,,,,,,,,,,,,,,,,,,,,,,,,,,,,,,,,,,,,
336.114,0.12319,0.91788,10,,,,,,,,,,,,,,,,,,,,,,,,,,,,,,,,,,,,,
336.714,0.12348,0.91755,10,,,,,,,,,,,,,,,,,,,,,,,,,,,,,,,,,,,,,
337.314,0.12382,0.96889,10,,,,,,,,,,,,,,,,,,,,,,,,,,,,,,,,,,,,,
337.914,0.12421,0.96275,10,,,,,,,,,,,,,,,,,,,,,,,,,,,,,,,,,,,,,
338.514,0.12489,0.9634,10,,,,,,,,,,,,,,,,,,,,,,,,,,,,,,,,,,,,,
339.114,0.1258,0.92079,10,,,,,,,,,,,,,,,,,,,,,,,,,,,,,,,,,,,,,
339.714,0.12693,1.0014,10,,,,,,,,,,,,,,,,,,,,,,,,,,,,,,,,,,,,,
340.314,0.12773,0.98184,10,,,,,,,,,,,,,,,,,,,,,,,,,,,,,,,,,,,,,
340.914,0.12812,1.04253,10,,,,,,,,,,,,,,,,,,,,,,,,,,,,,,,,,,,,,
341.514,0.12824,0.98479,10,,,,,,,,,,,,,,,,,,,,,,,,,,,,,,,,,,,,,
342.114,0.12812,0.99688,10,,,,,,,,,,,,,,,,,,,,,,,,,,,,,,,,,,,,,
342.714,0.12807,1.01031,10,,,,,,,,,,,,,,,,,,,,,,,,,,,,,,,,,,,,,
343.314,0.12801,1.04895,10,,,,,,,,,,,,,,,,,,,,,,,,,,,,,,,,,,,,,
343.914,0.1279,1.04088,10,,,,,,,,,,,,,,,,,,,,,,,,,,,,,,,,,,,,,
344.514,0.12784,0.99729,10,,,,,,,,,,,,,,,,,,,,,,,,,,,,,,,,,,,,,
345.114,0.12778,0.989,10,,,,,,,,,,,,,,,,,,,,,,,,,,,,,,,,,,,,,
345.714,0.12761,1.03958,10,,,,,,,,,,,,,,,,,,,,,,,,,,,,,,,,,,,,,
346.314,0.12733,1.01898,10,,,,,,,,,,,,,,,,,,,,,,,,,,,,,,,,,,,,,
346.914,0.12705,0.99541,10,,,,,,,,,,,,,,,,,,,,,,,,,,,,,,,,,,,,,
347.514,0.12631,1.02178,10,,,,,,,,,,,,,,,,,,,,,,,,,,,,,,,,,,,,,
348.114,0.12535,0.98553,10,,,,,,,,,,,,,,,,,,,,,,,,,,,,,,,,,,,,,
348.714,0.12433,0.96392,10,,,,,,,,,,,,,,,,,,,,,,,,,,,,,,,,,,,,,
349.314,0.12342,0.96147,10,,,,,,,,,,,,,,,,,,,,,,,,,,,,,,,,,,,,,
349.914,0.12297,0.91186,10,,,,,,,,,,,,,,,,,,,,,,,,,,,,,,,,,,,,,
350.514,0.12257,0.9461,10,,,,,,,,,,,,,,,,,,,,,,,,,,,,,,,,,,,,,
351.114,0.12246,0.93554,10,,,,,,,,,,,,,,,,,,,,,,,,,,,,,,,,,,,,,
351.714,0.12246,0.94379,10,,,,,,,,,,,,,,,,,,,,,,,,,,,,,,,,,,,,,
352.314,0.12257,0.88121,10,,,,,,,,,,,,,,,,,,,,,,,,,,,,,,,,,,,,,
352.914,0.12263,0.98359,10,,,,,,,,,,,,,,,,,,,,,,,,,,,,,,,,,,,,,
353.514,0.12268,0.91213,10,,,,,,,,,,,,,,,,,,,,,,,,,,,,,,,,,,,,,
354.114,0.12274,0.95046,10,,,,,,,,,,,,,,,,,,,,,,,,,,,,,,,,,,,,,
354.714,0.12274,0.94138,10,,,,,,,,,,,,,,,,,,,,,,,,,,,,,,,,,,,,,
355.314,0.1228,0.93426,10,,,,,,,,,,,,,,,,,,,,,,,,,,,,,,,,,,,,,
355.914,0.12291,0.89662,10,,,,,,,,,,,,,,,,,,,,,,,,,,,,,,,,,,,,,
356.514,0.12302,0.96177,10,,,,,,,,,,,,,,,,,,,,,,,,,,,,,,,,,,,,,
357.114,0.12325,0.96355,10,,,,,,,,,,,,,,,,,,,,,,,,,,,,,,,,,,,,,
357.714,0.12348,0.9459,10,,,,,,,,,,,,,,,,,,,,,,,,,,,,,,,,,,,,,
358.314,0.12376,0.93519,10,,,,,,,,,,,,,,,,,,,,,,,,,,,,,,,,,,,,,
358.914,0.12427,0.92347,10,,,,,,,,,,,,,,,,,,,,,,,,,,,,,,,,,,,,,
359.514,0.12489,0.951,10,,,,,,,,,,,,,,,,,,,,,,,,,,,,,,,,,,,,,
360.114,0.12557,1.0218,10,,,,,,,,,,,,,,,,,,,,,,,,,,,,,,,,,,,,,
360.714,0.12625,0.98317,10,,,,,,,,,,,,,,,,,,,,,,,,,,,,,,,,,,,,,
361.314,0.12693,0.98366,10,,,,,,,,,,,,,,,,,,,,,,,,,,,,,,,,,,,,,
361.914,0.12733,1.02092,10,,,,,,,,,,,,,,,,,,,,,,,,,,,,,,,,,,,,,
362.514,0.12744,1.01751,10,,,,,,,,,,,,,,,,,,,,,,,,,,,,,,,,,,,,,
363.114,0.12744,1.01724,10,,,,,,,,,,,,,,,,,,,,,,,,,,,,,,,,,,,,,
363.714,0.12727,1.02858,10,,,,,,,,,,,,,,,,,,,,,,,,,,,,,,,,,,,,,
364.314,0.12727,0.99225,10,,,,,,,,,,,,,,,,,,,,,,,,,,,,,,,,,,,,,
364.914,0.12722,0.99489,10,,,,,,,,,,,,,,,,,,,,,,,,,,,,,,,,,,,,,
365.514,0.12716,1.05228,10,,,,,,,,,,,,,,,,,,,,,,,,,,,,,,,,,,,,,
366.114,0.1271,1.06934,10,,,,,,,,,,,,,,,,,,,,,,,,,,,,,,,,,,,,,
366.714,0.12705,1.02227,10,,,,,,,,,,,,,,,,,,,,,,,,,,,,,,,,,,,,,
367.314,0.12693,1.03216,10,,,,,,,,,,,,,,,,,,,,,,,,,,,,,,,,,,,,,
367.914,0.12682,1.01783,10,,,,,,,,,,,,,,,,,,,,,,,,,,,,,,,,,,,,,
368.514,0.12665,0.97499,10,,,,,,,,,,,,,,,,,,,,,,,,,,,,,,,,,,,,,
369.114,0.12625,0.99012,10,,,,,,,,,,,,,,,,,,,,,,,,,,,,,,,,,,,,,
369.714,0.12569,1.01013,10,,,,,,,,,,,,,,,,,,,,,,,,,,,,,,,,,,,,,
370.314,0.12489,0.9593,10,,,,,,,,,,,,,,,,,,,,,,,,,,,,,,,,,,,,,
370.914,0.12421,1.01527,10,,,,,,,,,,,,,,,,,,,,,,,,,,,,,,,,,,,,,
371.514,0.12359,0.96937,10,,,,,,,,,,,,,,,,,,,,,,,,,,,,,,,,,,,,,
372.114,0.12325,0.99458,10,,,,,,,,,,,,,,,,,,,,,,,,,,,,,,,,,,,,,
372.714,0.12297,0.97592,10,,,,,,,,,,,,,,,,,,,,,,,,,,,,,,,,,,,,,
373.314,0.1228,0.96361,10,,,,,,,,,,,,,,,,,,,,,,,,,,,,,,,,,,,,,
373.914,0.12268,0.96511,10,,,,,,,,,,,,,,,,,,,,,,,,,,,,,,,,,,,,,
374.514,0.12263,1.04944,10,,,,,,,,,,,,,,,,,,,,,,,,,,,,,,,,,,,,,
375.114,0.12268,0.96055,10,,,,,,,,,,,,,,,,,,,,,,,,,,,,,,,,,,,,,
375.714,0.12257,0.95787,10,,,,,,,,,,,,,,,,,,,,,,,,,,,,,,,,,,,,,
376.314,0.12268,0.96825,10,,,,,,,,,,,,,,,,,,,,,,,,,,,,,,,,,,,,,
376.914,0.12274,0.9284,10,,,,,,,,,,,,,,,,,,,,,,,,,,,,,,,,,,,,,
377.514,0.1228,0.95793,10,,,,,,,,,,,,,,,,,,,,,,,,,,,,,,,,,,,,,
378.114,0.12285,0.91183,10,,,,,,,,,,,,,,,,,,,,,,,,,,,,,,,,,,,,,
378.714,0.12297,0.95084,10,,,,,,,,,,,,,,,,,,,,,,,,,,,,,,,,,,,,,
379.314,0.12314,0.9361,10,,,,,,,,,,,,,,,,,,,,,,,,,,,,,,,,,,,,,
379.914,0.12336,0.92098,10,,,,,,,,,,,,,,,,,,,,,,,,,,,,,,,,,,,,,
380.514,0.1237,0.93282,10,,,,,,,,,,,,,,,,,,,,,,,,,,,,,,,,,,,,,
381.114,0.12416,0.92523,10,,,,,,,,,,,,,,,,,,,,,,,,,,,,,,,,,,,,,
381.714,0.12472,0.99228,10,,,,,,,,,,,,,,,,,,,,,,,,,,,,,,,,,,,,,
382.314,0.12552,0.94087,10,,,,,,,,,,,,,,,,,,,,,,,,,,,,,,,,,,,,,
382.914,0.12671,0.98366,10,,,,,,,,,,,,,,,,,,,,,,,,,,,,,,,,,,,,,
383.514,0.12767,0.95938,10,,,,,,,,,,,,,,,,,,,,,,,,,,,,,,,,,,,,,
384.114,0.12807,1.01235,10,,,,,,,,,,,,,,,,,,,,,,,,,,,,,,,,,,,,,
384.714,0.12829,1.02548,10,,,,,,,,,,,,,,,,,,,,,,,,,,,,,,,,,,,,,
385.314,0.12824,1.05827,10,,,,,,,,,,,,,,,,,,,,,,,,,,,,,,,,,,,,,
385.914,0.12818,1.1112,10,,,,,,,,,,,,,,,,,,,,,,,,,,,,,,,,,,,,,
386.514,0.12812,1.01421,10,,,,,,,,,,,,,,,,,,,,,,,,,,,,,,,,,,,,,
387.114,0.12807,1.01446,10,,,,,,,,,,,,,,,,,,,,,,,,,,,,,,,,,,,,,
387.714,0.12801,1.00693,10,,,,,,,,,,,,,,,,,,,,,,,,,,,,,,,,,,,,,
388.314,0.1279,0.99197,10,,,,,,,,,,,,,,,,,,,,,,,,,,,,,,,,,,,,,
388.914,0.12784,1.04076,10,,,,,,,,,,,,,,,,,,,,,,,,,,,,,,,,,,,,,
389.514,0.12761,1.04717,10,,,,,,,,,,,,,,,,,,,,,,,,,,,,,,,,,,,,,
390.114,0.12727,1.01335,10,,,,,,,,,,,,,,,,,,,,,,,,,,,,,,,,,,,,,
390.714,0.12659,1.00603,10,,,,,,,,,,,,,,,,,,,,,,,,,,,,,,,,,,,,,
391.314,0.12557,1.01003,10,,,,,,,,,,,,,,,,,,,,,,,,,,,,,,,,,,,,,
391.914,0.12455,0.94446,10,,,,,,,,,,,,,,,,,,,,,,,,,,,,,,,,,,,,,
392.514,0.1237,0.97721,10,,,,,,,,,,,,,,,,,,,,,,,,,,,,,,,,,,,,,
393.114,0.12319,0.94515,10,,,,,,,,,,,,,,,,,,,,,,,,,,,,,,,,,,,,,
393.714,0.12297,0.92483,10,,,,,,,,,,,,,,,,,,,,,,,,,,,,,,,,,,,,,
394.314,0.12291,0.92903,10,,,,,,,,,,,,,,,,,,,,,,,,,,,,,,,,,,,,,
394.914,0.12302,0.96402,10,,,,,,,,,,,,,,,,,,,,,,,,,,,,,,,,,,,,,
395.514,0.12308,0.96442,10,,,,,,,,,,,,,,,,,,,,,,,,,,,,,,,,,,,,,
396.114,0.12314,1.00533,10,,,,,,,,,,,,,,,,,,,,,,,,,,,,,,,,,,,,,
396.714,0.12314,0.97927,10,,,,,,,,,,,,,,,,,,,,,,,,,,,,,,,,,,,,,
397.314,0.12319,0.9354,10,,,,,,,,,,,,,,,,,,,,,,,,,,,,,,,,,,,,,
397.914,0.12331,0.94238,10,,,,,,,,,,,,,,,,,,,,,,,,,,,,,,,,,,,,,
398.514,0.12348,0.91422,10,,,,,,,,,,,,,,,,,,,,,,,,,,,,,,,,,,,,,
399.114,0.12365,0.9727,10,,,,,,,,,,,,,,,,,,,,,,,,,,,,,,,,,,,,,
399.714,0.12387,0.93853,10,,,,,,,,,,,,,,,,,,,,,,,,,,,,,,,,,,,,,
400.314,0.12416,0.90854,10,,,,,,,,,,,,,,,,,,,,,,,,,,,,,,,,,,,,,
400.914,0.12467,0.92931,10,,,,,,,,,,,,,,,,,,,,,,,,,,,,,,,,,,,,,
401.514,0.12535,0.95141,10,,,,,,,,,,,,,,,,,,,,,,,,,,,,,,,,,,,,,
402.114,0.12648,0.99401,10,,,,,,,,,,,,,,,,,,,,,,,,,,,,,,,,,,,,,
402.714,0.1271,1.01417,10,,,,,,,,,,,,,,,,,,,,,,,,,,,,,,,,,,,,,
403.314,0.12739,0.99544,10,,,,,,,,,,,,,,,,,,,,,,,,,,,,,,,,,,,,,
403.914,0.1275,0.99953,10,,,,,,,,,,,,,,,,,,,,,,,,,,,,,,,,,,,,,
404.514,0.12744,1.05344,10,,,,,,,,,,,,,,,,,,,,,,,,,,,,,,,,,,,,,
405.114,0.12739,1.02856,10,,,,,,,,,,,,,,,,,,,,,,,,,,,,,,,,,,,,,
405.714,0.12727,1.02778,10,,,,,,,,,,,,,,,,,,,,,,,,,,,,,,,,,,,,,
406.314,0.12722,1.03094,10,,,,,,,,,,,,,,,,,,,,,,,,,,,,,,,,,,,,,
406.914,0.12716,1.02537,10,,,,,,,,,,,,,,,,,,,,,,,,,,,,,,,,,,,,,
407.514,0.12705,1.0766,10,,,,,,,,,,,,,,,,,,,,,,,,,,,,,,,,,,,,,
408.114,0.12682,1.00769,10,,,,,,,,,,,,,,,,,,,,,,,,,,,,,,,,,,,,,
408.714,0.12648,1.02381,10,,,,,,,,,,,,,,,,,,,,,,,,,,,,,,,,,,,,,
409.314,0.12586,1.01301,10,,,,,,,,,,,,,,,,,,,,,,,,,,,,,,,,,,,,,
409.914,0.12501,0.98901,10,,,,,,,,,,,,,,,,,,,,,,,,,,,,,,,,,,,,,
410.514,0.12365,0.99005,10,,,,,,,,,,,,,,,,,,,,,,,,,,,,,,,,,,,,,
411.114,0.12274,0.9288,10,,,,,,,,,,,,,,,,,,,,,,,,,,,,,,,,,,,,,
411.714,0.12229,0.92672,10,,,,,,,,,,,,,,,,,,,,,,,,,,,,,,,,,,,,,
412.314,0.12223,0.95207,10,,,,,,,,,,,,,,,,,,,,,,,,,,,,,,,,,,,,,
412.914,0.12229,0.92039,10,,,,,,,,,,,,,,,,,,,,,,,,,,,,,,,,,,,,,
413.514,0.1224,0.91537,10,,,,,,,,,,,,,,,,,,,,,,,,,,,,,,,,,,,,,
414.114,0.12246,0.92275,10,,,,,,,,,,,,,,,,,,,,,,,,,,,,,,,,,,,,,
414.714,0.12251,0.94291,10,,,,,,,,,,,,,,,,,,,,,,,,,,,,,,,,,,,,,
415.314,0.12257,0.98492,10,,,,,,,,,,,,,,,,,,,,,,,,,,,,,,,,,,,,,
415.914,0.12257,0.94511,10,,,,,,,,,,,,,,,,,,,,,,,,,,,,,,,,,,,,,
416.514,0.12268,0.98582,10,,,,,,,,,,,,,,,,,,,,,,,,,,,,,,,,,,,,,
417.114,0.1228,0.90143,10,,,,,,,,,,,,,,,,,,,,,,,,,,,,,,,,,,,,,
417.714,0.12302,0.94061,10,,,,,,,,,,,,,,,,,,,,,,,,,,,,,,,,,,,,,
418.314,0.12336,0.94462,10,,,,,,,,,,,,,,,,,,,,,,,,,,,,,,,,,,,,,
418.914,0.12376,0.98802,10,,,,,,,,,,,,,,,,,,,,,,,,,,,,,,,,,,,,,
419.514,0.12427,0.97581,10,,,,,,,,,,,,,,,,,,,,,,,,,,,,,,,,,,,,,
420.114,0.12501,0.95019,10,,,,,,,,,,,,,,,,,,,,,,,,,,,,,,,,,,,,,
420.714,0.12591,0.97733,10,,,,,,,,,,,,,,,,,,,,,,,,,,,,,,,,,,,,,
421.314,0.12665,0.97383,10,,,,,,,,,,,,,,,,,,,,,,,,,,,,,,,,,,,,,
421.914,0.12727,0.97768,10,,,,,,,,,,,,,,,,,,,,,,,,,,,,,,,,,,,,,
422.514,0.12756,1.00137,10,,,,,,,,,,,,,,,,,,,,,,,,,,,,,,,,,,,,,
423.114,0.12773,0.97523,10,,,,,,,,,,,,,,,,,,,,,,,,,,,,,,,,,,,,,
423.714,0.12767,1.06918,10,,,,,,,,,,,,,,,,,,,,,,,,,,,,,,,,,,,,,
424.314,0.12761,1.00989,10,,,,,,,,,,,,,,,,,,,,,,,,,,,,,,,,,,,,,
424.914,0.12761,1.00654,10,,,,,,,,,,,,,,,,,,,,,,,,,,,,,,,,,,,,,
425.514,0.1275,1.07477,10,,,,,,,,,,,,,,,,,,,,,,,,,,,,,,,,,,,,,
426.114,0.1275,1.05258,10,,,,,,,,,,,,,,,,,,,,,,,,,,,,,,,,,,,,,
426.714,0.12733,1.01369,10,,,,,,,,,,,,,,,,,,,,,,,,,,,,,,,,,,,,,
427.314,0.12727,1.01329,10,,,,,,,,,,,,,,,,,,,,,,,,,,,,,,,,,,,,,
427.914,0.12705,1.02734,10,,,,,,,,,,,,,,,,,,,,,,,,,,,,,,,,,,,,,
428.514,0.12671,0.99927,10,,,,,,,,,,,,,,,,,,,,,,,,,,,,,,,,,,,,,
429.016,0.72732,9.63863,10,,,,,,,,,,,,,,,,,,,,,,,,,,,,,,,,,,,,,
429.616,5.79309,629.94043,10,,,,,,,,,,,,,,,,,,,,,,,,,,,,,,,,,,,,,
430.216,10.79319,251.28043,10,,,,,,,,,,,,,,,,,,,,,,,,,,,,,,,,,,,,,
430.816,15.79317,86.78069,10,,,,,,,,,,,,,,,,,,,,,,,,,,,,,,,,,,,,,
431.416,20.79309,34.50994,10,,,,,,,,,,,,,,,,,,,,,,,,,,,,,,,,,,,,,
432.016,25.79308,13.56609,10,,,,,,,,,,,,,,,,,,,,,,,,,,,,,,,,,,,,,
432.616,30.79312,0.60683,10,,,,,,,,,,,,,,,,,,,,,,,,,,,,,,,,,,,,,
433.216,35.7931,0.01235,10,,,,,,,,,,,,,,,,,,,,,,,,,,,,,,,,,,,,,
433.816,40.7932,-0.27427,10,,,,,,,,,,,,,,,,,,,,,,,,,,,,,,,,,,,,,
434.416,45.79318,-0.81292,10,,,,,,,,,,,,,,,,,,,,,,,,,,,,,,,,,,,,,
435.016,50.79322,-0.14052,10,,,,,,,,,,,,,,,,,,,,,,,,,,,,,,,,,,,,,
435.616,55.79321,1.55398,10,,,,,,,,,,,,,,,,,,,,,,,,,,,,,,,,,,,,,
436.216,60.79313,-2.67206,10,,,,,,,,,,,,,,,,,,,,,,,,,,,,,,,,,,,,,
436.816,65.79317,-4.36799,10,,,,,,,,,,,,,,,,,,,,,,,,,,,,,,,,,,,,,
437.416,70.79315,-4.36255,10,,,,,,,,,,,,,,,,,,,,,,,,,,,,,,,,,,,,,
438.016,75.79313,-4.40029,10,,,,,,,,,,,,,,,,,,,,,,,,,,,,,,,,,,,,,
438.616,80.79317,-4.4373,10,,,,,,,,,,,,,,,,,,,,,,,,,,,,,,,,,,,,,
439.092,84.75983,-4.47246,10,,,,,,,,,,,,,,,,,,,,,,,,,,,,,,,,,,,,,