File: combined_ligament_solver/data/processed/Data Sheet 3_S152635_MCL.csv
Specimen properties : Length,120,mm,Unnamed: 3,Unnamed: 4,Unnamed: 5,Unnamed: 6,Unnamed: 7,Unnamed: 8,Unnamed: 9,Unnamed: 10,Unnamed: 11,Stress-Strain,Unnamed: 13,Unnamed: 14,Unnamed: 15,Unnamed: 16,Unnamed: 17,Unnamed: 18,Unnamed: 19,Unnamed: 20,Unnamed: 21,Unnamed: 22,Unnamed: 23,Unnamed: 24,Unnamed: 25,Unnamed: 26,Unnamed: 27,Linear,Unnamed: 29,Unnamed: 30,Unnamed: 31,Unnamed: 32,Unnamed: 33,Modulus,Unnamed: 35,Failure,Unnamed: 37,Unnamed: 38,Unnamed: 39,Unnamed: 40
Cross Section Average,39.572,mm2,,,,,,,,,,Polynomial Coefficients,,,,,,,,,,,,,,,,Force,,Stress,Extension,Strain,,Secant,Tangent,Load,Stress,Extension,Strain,Stiffness
Time,Extension,Load,Total cycle count,,,Extension,Load,Strain,Stress,E-tan,,X6,-111588986.0617861,,,,,,,,,Strain,Stress,E-tan,,,,(N),,(MPa),(mm),(%),,(MPa),(MPa),(N),(MPa),(mm),(%),(N/mm)
(s),(mm),(N),,,,(mm),(N),(mm/mm),(MPa),(MPa),,X5,22113848.313626762,,,,,,,,,(mm/mm),(MPa),(MPa),,,,238.7695380221256,,6.033800111748852,7.5600000000000005,6.3,,95.77460494839448,148.53581646803335,326.72421,8.25644925705044,9.73381,8.111508333333333,31.58327222514889
0.2,0.21329,1.15489,0,,,11.18855,12.00258,0.011604416666666657,0.3033099161022945,42.4348871746244,,X2,1336.9791171502163,,,,,,,,,0.002,0.02053512054223139,11.722599061929513,,,,,,,,,,,,,,,,
0.5,0.26339,1.35335,0,,,13.6965,79.60299,0.032504,2.011598857778227,101.81782129262614,,,,,,,,,,,,0.005,0.07502904529367385,21.539544336911533,,,,,,,,,,,,,,,,
0.8,0.31337,1.526,0,,,16.19658,183.41884,0.053338,4.635066208430203,139.0918799956869,,,,,,,,,,,,0.008,0.16113745820530898,32.355151874948994,,,,,,,,,,,,,,,,
1.1,0.3634,1.78739,0,,,18.69649,299.02823,0.07417058333333333,7.556560952188415,112.38101745848124,,,,,,,,,,,,0.011,0.28049873725708996,43.51016164783597,,,,,,,,,,,,,,,,
1.4,0.4135,2.02781,0,,,20.89668,-2.43379,,,,,,,,,,,,,,,0.014,0.43311009409034046,54.51145121047152,,,,,,,,,,,,,,,,
1.7,0.46342,2.18259,0,,,,,,,,,,,,,,,,,,,0.017,0.6177869395390666,65.01251209185848,,,,,,,,,,,,,,,,
2,0.51357,2.36452,0,,,,,,,,,,,,,,,,,,,0.02,0.8325636783342655,74.79392618610184,,,,,,,,,,,,,,,,
2.3,0.56349,2.49139,0,,,,,,,,,,,,,,,,,,,0.023,1.0750359329812291,83.74384214340749,,,,,,,,,,,,,,,,
2.6,0.61336,2.69184,0,,,,,,,,,,,,,,,,,,,0.026,1.342644196809845,91.83845176108109,,,,,,,,,,,,,,,,
2.9,0.6634,2.81269,0,,,,,,,,,,,,,,,,,,,0.029,1.6328989161978915,99.1224663745264,,,,,,,,,,,,,,,,
3.2,0.71332,2.96045,0,,,,,,,,,,,,,,,,,,,0.032,1.9435470019673284,105.68959324824323,,,,,,,,,,,,,,,,
3.5,0.76341,3.09879,0,,,,,,,,,,,,,,,,,,,0.035,2.272679769953588,111.66301196682838,,,,,,,,,,,,,,,,
3.8,0.81339,3.25037,0,,,,,,,,,,,,,,,,,,,0.038,2.6187823107478545,117.17585082597093,,,,,,,,,,,,,,,,
4.1,0.86332,3.3624,0,,,,,,,,,,,,,,,,,,,0.041,2.9807242886123473,122.35166322345437,,,,,,,,,,,,,,,,
4.4,0.91352,3.50757,0,,,,,,,,,,,,,,,,,,,0.044,3.357692169568593,127.28490405015323,,,,,,,,,,,,,,,,
4.7,0.96356,3.68027,0,,,,,,,,,,,,,,,,,,,0.047,3.7490628786587,132.0214060810286,,,,,,,,,,,,,,,,
5,1.01337,3.89648,0,,,,,,,,,,,,,,,,,,,0.05,4.154218886379622,136.53885636613592,,,,,,,,,,,,,,,,
5.3,1.06335,3.86913,0,,,,,,,,,,,,,,,,,,,0.053,4.572304724290423,140.72727262161675,,,,,,,,,,,,,,,,
5.6,1.11327,4.0111,0,,,,,,,,,,,,,,,,,,,0.056,5.001924929792537,144.3694796206881,,,,,,,,,,,,,,,,
5.9,1.16331,4.08667,0,,,,,,,,,,,,,,,,,,,0.059,5.440783420083027,147.1215855846717,,,,,,,,,,,,,,,,
6.2,1.21346,4.26608,0,,,,,,,,,,,,,,,,,,,0.062,5.885264295280819,148.49345857395576,,,,,,,,,,,,,,,,
6.5,1.26333,4.37705,0,,,,,,,,,,,,,,,,,,,0.065,6.329954070725964,147.82920287900834,,,,,,,,,,,,,,,,
6.8,1.31353,4.4718,0,,,,,,,,,,,,,,,,,,,0.068,6.767105338451885,144.28763541139566,,,,,,,,,,,,,,,,
7.1,1.36351,4.61026,0,,,,,,,,,,,,,,,,,,,0.071,7.1860418578306,136.82276209474333,,,,,,,,,,,,,,,,
7.4,1.41349,4.64881,0,,,,,,,,,,,,,,,,,,,0.074,7.572505075390964,124.16425425578291,,,,,,,,,,,,,,,,
7.7,1.46342,4.78198,0,,,,,,,,,,,,,,,,,,,0.077,7.907942073809875,104.79792501525588,,,,,,,,,,,,,,,,
8,1.51334,4.98118,0,,,,,,,,,,,,,,,,,,,0.08,8.168734950076598,76.94620567908032,,,,,,,,,,,,,,,,
8.3,1.56332,4.9639,0,,,,,,,,,,,,,,,,,,,0.083,8.325371622829818,38.548622129171726,,,,,,,,,,,,,,,,
8.6,1.61341,5.03724,0,,,,,,,,,,,,,,,,,,,0.086,,,,,,,,,,,,,,,,,,
8.9,1.66334,5.10652,0,,,,,,,,,,,,,,,,,,,0.089,,,,,,,,,,,,,,,,,,
9.2,1.71343,5.19685,0,,,,,,,,,,,,,,,,,,,0.092,,,,,,,,,,,,,,,,,,
9.5,1.76352,5.31114,0,,,,,,,,,,,,,,,,,,,0.095,,,,,,,,,,,,,,,,,,
9.8,1.81345,5.4345,0,,,,,,,,,,,,,,,,,,,0.098,,,,,,,,,,,,,,,,,,
10.1,1.86348,5.50223,0,,,,,,,,,,,,,,,,,,,0.101,,,,,,,,,,,,,,,,,,
10.4,1.91341,5.58348,0,,,,,,,,,,,,,,,,,,,0.104,,,,,,,,,,,,,,,,,,
10.7,1.96327,5.58084,0,,,,,,,,,,,,,,,,,,,0.107,,,,,,,,,,,,,,,,,,
11,2.01337,5.71678,0,,,,,,,,,,,,,,,,,,,0.11,,,,,,,,,,,,,,,,,,
11.3,2.06335,5.77402,0,,,,,,,,,,,,,,,,,,,0.113,,,,,,,,,,,,,,,,,,
11.6,2.11338,5.86215,0,,,,,,,,,,,,,,,,,,,0.116,,,,,,,,,,,,,,,,,,
11.9,2.16348,5.99457,0,,,,,,,,,,,,,,,,,,,0.119,,,,,,,,,,,,,,,,,,
12.2,2.21346,6.02783,0,,,,,,,,,,,,,,,,,,,0.122,,,,,,,,,,,,,,,,,,
12.5,2.26344,6.0985,0,,,,,,,,,,,,,,,,,,,0.125,,,,,,,,,,,,,,,,,,
12.8,2.31342,6.15791,0,,,,,,,,,,,,,,,,,,,0.128,,,,,,,,,,,,,,,,,,
13.1,2.36334,6.32269,0,,,,,,,,,,,,,,,,,,,0.131,,,,,,,,,,,,,,,,,,
13.4,2.41343,6.29676,0,,,,,,,,,,,,,,,,,,,0.134,,,,,,,,,,,,,,,,,,
13.7,2.46341,6.37893,0,,,,,,,,,,,,,,,,,,,0.137,,,,,,,,,,,,,,,,,,
14,2.51334,6.40179,0,,,,,,,,,,,,,,,,,,,0.14,,,,,,,,,,,,,,,,,,
14.3,2.56349,6.38831,0,,,,,,,,,,,,,,,,,,,0.143,,,,,,,,,,,,,,,,,,
14.6,2.61347,6.39133,0,,,,,,,,,,,,,,,,,,,0.146,,,,,,,,,,,,,,,,,,
14.9,2.6635,6.32574,0,,,,,,,,,,,,,,,,,,,0.149,,,,,,,,,,,,,,,,,,
15.2,2.71343,6.32336,0,,,,,,,,,,,,,,,,,,,0.152,,,,,,,,,,,,,,,,,,
15.5,2.76329,6.42731,0,,,,,,,,,,,,,,,,,,,0.155,,,,,,,,,,,,,,,,,,
15.8,2.81333,6.46274,0,,,,,,,,,,,,,,,,,,,0.158,,,,,,,,,,,,,,,,,,
16.1,2.86342,6.55691,0,,,,,,,,,,,,,,,,,,,0.161,,,,,,,,,,,,,,,,,,
16.4,2.91335,6.39344,0,,,,,,,,,,,,,,,,,,,0.164,,,,,,,,,,,,,,,,,,
16.7,2.96344,6.64088,0,,,,,,,,,,,,,,,,,,,0.167,,,,,,,,,,,,,,,,,,
17,3.01342,6.79714,0,,,,,,,,,,,,,,,,,,,0.17,,,,,,,,,,,,,,,,,,
17.3,3.06346,6.87333,0,,,,,,,,,,,,,,,,,,,0.173,,,,,,,,,,,,,,,,,,
17.6,3.11355,6.97268,0,,,,,,,,,,,,,,,,,,,0.176,,,,,,,,,,,,,,,,,,
17.9,3.1633,7.16189,0,,,,,,,,,,,,,,,,,,,0.179,,,,,,,,,,,,,,,,,,
18.2,3.21334,7.34436,0,,,,,,,,,,,,,,,,,,,0.182,,,,,,,,,,,,,,,,,,
18.5,3.26338,7.36676,0,,,,,,,,,,,,,,,,,,,0.185,,,,,,,,,,,,,,,,,,
18.8,3.31336,7.49858,0,,,,,,,,,,,,,,,,,,,0.188,,,,,,,,,,,,,,,,,,
19.1,3.36345,7.69584,0,,,,,,,,,,,,,,,,,,,0.191,,,,,,,,,,,,,,,,,,
19.4,3.41349,7.787,0,,,,,,,,,,,,,,,,,,,0.194,,,,,,,,,,,,,,,,,,
19.7,3.46347,7.91411,0,,,,,,,,,,,,,,,,,,,0.197,,,,,,,,,,,,,,,,,,
20,3.51345,8.01119,0,,,,,,,,,,,,,,,,,,,0.2,,,,,,,,,,,,,,,,,,
20.3,3.56337,8.17085,0,,,,,,,,,,,,,,,,,,,,,,,,,,,,,,,,,,,,,
20.6,3.61335,8.33301,0,,,,,,,,,,,,,,,,,,,,,,,,,,,,,,,,,,,,,
20.9,3.66339,8.49764,0,,,,,,,,,,,,,,,,,,,,,,,,,,,,,,,,,,,,,
21.2,3.71337,8.61131,0,,,,,,,,,,,,,,,,,,,,,,,,,,,,,,,,,,,,,
21.5,3.7634,8.75043,0,,,,,,,,,,,,,,,,,,,,,,,,,,,,,,,,,,,,,
21.8,3.81338,8.92646,0,,,,,,,,,,,,,,,,,,,,,,,,,,,,,,,,,,,,,
22.1,3.86348,9.1021,0,,,,,,,,,,,,,,,,,,,,,,,,,,,,,,,,,,,,,
22.4,3.91357,9.2157,0,,,,,,,,,,,,,,,,,,,,,,,,,,,,,,,,,,,,,
22.7,3.96355,9.3246,0,,,,,,,,,,,,,,,,,,,,,,,,,,,,,,,,,,,,,
23,4.01336,9.48615,0,,,,,,,,,,,,,,,,,,,,,,,,,,,,,,,,,,,,,
23.3,4.06334,9.6885,0,,,,,,,,,,,,,,,,,,,,,,,,,,,,,,,,,,,,,
23.6,4.11338,9.77254,0,,,,,,,,,,,,,,,,,,,,,,,,,,,,,,,,,,,,,
23.9,4.16341,9.9014,0,,,,,,,,,,,,,,,,,,,,,,,,,,,,,,,,,,,,,
24.2,4.21339,10.12548,0,,,,,,,,,,,,,,,,,,,,,,,,,,,,,,,,,,,,,
24.5,4.26337,10.18288,0,,,,,,,,,,,,,,,,,,,,,,,,,,,,,,,,,,,,,
24.8,4.31352,10.34467,0,,,,,,,,,,,,,,,,,,,,,,,,,,,,,,,,,,,,,
25.1,4.36356,10.46372,0,,,,,,,,,,,,,,,,,,,,,,,,,,,,,,,,,,,,,
25.4,4.41343,10.63019,0,,,,,,,,,,,,,,,,,,,,,,,,,,,,,,,,,,,,,
25.7,4.46341,10.80464,0,,,,,,,,,,,,,,,,,,,,,,,,,,,,,,,,,,,,,
26,4.51327,11.01649,0,,,,,,,,,,,,,,,,,,,,,,,,,,,,,,,,,,,,,
26.3,4.56331,11.16206,0,,,,,,,,,,,,,,,,,,,,,,,,,,,,,,,,,,,,,
26.6,4.61346,11.21222,0,,,,,,,,,,,,,,,,,,,,,,,,,,,,,,,,,,,,,
26.9,4.66338,11.33593,0,,,,,,,,,,,,,,,,,,,,,,,,,,,,,,,,,,,,,
27.2,4.71348,11.39666,0,,,,,,,,,,,,,,,,,,,,,,,,,,,,,,,,,,,,,
27.5,4.76351,11.70877,0,,,,,,,,,,,,,,,,,,,,,,,,,,,,,,,,,,,,,
27.8,4.81344,12.07477,0,,,,,,,,,,,,,,,,,,,,,,,,,,,,,,,,,,,,,
28.1,4.86347,12.48374,0,,,,,,,,,,,,,,,,,,,,,,,,,,,,,,,,,,,,,
28.4,4.91334,12.77574,0,,,,,,,,,,,,,,,,,,,,,,,,,,,,,,,,,,,,,
28.7,4.96332,13.02662,0,,,,,,,,,,,,,,,,,,,,,,,,,,,,,,,,,,,,,
29,5.01341,13.27119,0,,,,,,,,,,,,,,,,,,,,,,,,,,,,,,,,,,,,,
29.3,5.06339,13.55393,0,,,,,,,,,,,,,,,,,,,,,,,,,,,,,,,,,,,,,
29.6,5.11343,13.89527,0,,,,,,,,,,,,,,,,,,,,,,,,,,,,,,,,,,,,,
29.9,5.16352,14.18136,0,,,,,,,,,,,,,,,,,,,,,,,,,,,,,,,,,,,,,
30.2,5.21345,14.47367,0,,,,,,,,,,,,,,,,,,,,,,,,,,,,,,,,,,,,,
30.5,5.26343,14.69479,0,,,,,,,,,,,,,,,,,,,,,,,,,,,,,,,,,,,,,
30.8,5.31341,14.93857,0,,,,,,,,,,,,,,,,,,,,,,,,,,,,,,,,,,,,,
31.1,5.36333,15.18812,0,,,,,,,,,,,,,,,,,,,,,,,,,,,,,,,,,,,,,
31.4,5.41337,14.93834,0,,,,,,,,,,,,,,,,,,,,,,,,,,,,,,,,,,,,,
31.7,5.46335,15.12529,0,,,,,,,,,,,,,,,,,,,,,,,,,,,,,,,,,,,,,
32,5.51338,15.34725,0,,,,,,,,,,,,,,,,,,,,,,,,,,,,,,,,,,,,,
32.3,5.56353,15.39917,0,,,,,,,,,,,,,,,,,,,,,,,,,,,,,,,,,,,,,
32.6,5.61346,15.58408,0,,,,,,,,,,,,,,,,,,,,,,,,,,,,,,,,,,,,,
32.9,5.66355,15.6446,0,,,,,,,,,,,,,,,,,,,,,,,,,,,,,,,,,,,,,
33.2,5.71342,15.95666,0,,,,,,,,,,,,,,,,,,,,,,,,,,,,,,,,,,,,,
33.5,5.76328,16.42484,0,,,,,,,,,,,,,,,,,,,,,,,,,,,,,,,,,,,,,
33.8,5.81338,16.72648,0,,,,,,,,,,,,,,,,,,,,,,,,,,,,,,,,,,,,,
34.1,5.86336,17.16377,0,,,,,,,,,,,,,,,,,,,,,,,,,,,,,,,,,,,,,
34.4,5.91339,17.44555,0,,,,,,,,,,,,,,,,,,,,,,,,,,,,,,,,,,,,,
34.7,5.96349,17.88215,0,,,,,,,,,,,,,,,,,,,,,,,,,,,,,,,,,,,,,
35,6.01341,18.20226,0,,,,,,,,,,,,,,,,,,,,,,,,,,,,,,,,,,,,,
35.3,6.0635,18.60135,0,,,,,,,,,,,,,,,,,,,,,,,,,,,,,,,,,,,,,
35.6,6.11348,18.97699,0,,,,,,,,,,,,,,,,,,,,,,,,,,,,,,,,,,,,,
35.9,6.16329,19.41062,0,,,,,,,,,,,,,,,,,,,,,,,,,,,,,,,,,,,,,
36.2,6.21339,19.82613,0,,,,,,,,,,,,,,,,,,,,,,,,,,,,,,,,,,,,,
36.5,6.26337,20.27761,0,,,,,,,,,,,,,,,,,,,,,,,,,,,,,,,,,,,,,
36.8,6.31335,20.66453,0,,,,,,,,,,,,,,,,,,,,,,,,,,,,,,,,,,,,,
37.1,6.36344,21.08994,0,,,,,,,,,,,,,,,,,,,,,,,,,,,,,,,,,,,,,
37.4,6.41348,21.60505,0,,,,,,,,,,,,,,,,,,,,,,,,,,,,,,,,,,,,,
37.7,6.46346,22.07321,0,,,,,,,,,,,,,,,,,,,,,,,,,,,,,,,,,,,,,
38,6.51349,22.50654,0,,,,,,,,,,,,,,,,,,,,,,,,,,,,,,,,,,,,,
38.3,6.5633,22.95019,0,,,,,,,,,,,,,,,,,,,,,,,,,,,,,,,,,,,,,
38.6,6.6134,23.33802,0,,,,,,,,,,,,,,,,,,,,,,,,,,,,,,,,,,,,,
38.9,6.66338,23.72034,0,,,,,,,,,,,,,,,,,,,,,,,,,,,,,,,,,,,,,
39.2,6.71336,24.12853,0,,,,,,,,,,,,,,,,,,,,,,,,,,,,,,,,,,,,,
39.5,6.76339,24.64922,0,,,,,,,,,,,,,,,,,,,,,,,,,,,,,,,,,,,,,
39.8,6.81343,24.99081,0,,,,,,,,,,,,,,,,,,,,,,,,,,,,,,,,,,,,,
40.1,6.86347,25.35676,0,,,,,,,,,,,,,,,,,,,,,,,,,,,,,,,,,,,,,
40.4,6.91356,25.47843,0,,,,,,,,,,,,,,,,,,,,,,,,,,,,,,,,,,,,,
40.7,6.96337,25.57576,0,,,,,,,,,,,,,,,,,,,,,,,,,,,,,,,,,,,,,
41,7.01329,25.44058,0,,,,,,,,,,,,,,,,,,,,,,,,,,,,,,,,,,,,,
41.3,7.06333,20.99631,0,,,,,,,,,,,,,,,,,,,,,,,,,,,,,,,,,,,,,
41.6,7.11337,20.83995,0,,,,,,,,,,,,,,,,,,,,,,,,,,,,,,,,,,,,,
41.9,7.16346,21.09624,0,,,,,,,,,,,,,,,,,,,,,,,,,,,,,,,,,,,,,
42.2,7.21344,21.1419,0,,,,,,,,,,,,,,,,,,,,,,,,,,,,,,,,,,,,,
42.5,7.26336,21.52556,0,,,,,,,,,,,,,,,,,,,,,,,,,,,,,,,,,,,,,
42.8,7.31357,22.11094,0,,,,,,,,,,,,,,,,,,,,,,,,,,,,,,,,,,,,,
43.1,7.36349,22.36959,0,,,,,,,,,,,,,,,,,,,,,,,,,,,,,,,,,,,,,
43.4,7.41342,22.68954,0,,,,,,,,,,,,,,,,,,,,,,,,,,,,,,,,,,,,,
43.7,7.46334,23.10752,0,,,,,,,,,,,,,,,,,,,,,,,,,,,,,,,,,,,,,
44,7.51332,23.12528,0,,,,,,,,,,,,,,,,,,,,,,,,,,,,,,,,,,,,,
44.3,7.56336,22.88941,0,,,,,,,,,,,,,,,,,,,,,,,,,,,,,,,,,,,,,
44.6,7.61345,22.85998,0,,,,,,,,,,,,,,,,,,,,,,,,,,,,,,,,,,,,,
44.9,7.66343,22.76304,0,,,,,,,,,,,,,,,,,,,,,,,,,,,,,,,,,,,,,
45.2,7.71352,22.63098,0,,,,,,,,,,,,,,,,,,,,,,,,,,,,,,,,,,,,,
45.5,7.7635,22.20318,0,,,,,,,,,,,,,,,,,,,,,,,,,,,,,,,,,,,,,
45.8,7.81343,22.13061,0,,,,,,,,,,,,,,,,,,,,,,,,,,,,,,,,,,,,,
46.1,7.86341,22.47211,0,,,,,,,,,,,,,,,,,,,,,,,,,,,,,,,,,,,,,
46.4,7.91333,22.74824,0,,,,,,,,,,,,,,,,,,,,,,,,,,,,,,,,,,,,,
46.7,7.96331,22.79023,0,,,,,,,,,,,,,,,,,,,,,,,,,,,,,,,,,,,,,
47,8.01346,22.82775,0,,,,,,,,,,,,,,,,,,,,,,,,,,,,,,,,,,,,,
47.3,8.06333,22.95766,0,,,,,,,,,,,,,,,,,,,,,,,,,,,,,,,,,,,,,
47.6,8.11348,23.24137,0,,,,,,,,,,,,,,,,,,,,,,,,,,,,,,,,,,,,,
47.9,8.16357,23.36885,0,,,,,,,,,,,,,,,,,,,,,,,,,,,,,,,,,,,,,
48.2,8.21349,22.9034,0,,,,,,,,,,,,,,,,,,,,,,,,,,,,,,,,,,,,,
48.5,8.26336,22.31121,0,,,,,,,,,,,,,,,,,,,,,,,,,,,,,,,,,,,,,
48.8,8.31334,22.3382,0,,,,,,,,,,,,,,,,,,,,,,,,,,,,,,,,,,,,,
49.1,8.36332,22.6011,0,,,,,,,,,,,,,,,,,,,,,,,,,,,,,,,,,,,,,
49.4,8.41341,22.81344,0,,,,,,,,,,,,,,,,,,,,,,,,,,,,,,,,,,,,,
49.7,8.46339,22.95562,0,,,,,,,,,,,,,,,,,,,,,,,,,,,,,,,,,,,,,
50,8.51343,23.16211,0,,,,,,,,,,,,,,,,,,,,,,,,,,,,,,,,,,,,,
50.3,8.56352,23.51827,0,,,,,,,,,,,,,,,,,,,,,,,,,,,,,,,,,,,,,
50.6,8.61345,24.01595,0,,,,,,,,,,,,,,,,,,,,,,,,,,,,,,,,,,,,,
50.9,8.66343,24.46377,0,,,,,,,,,,,,,,,,,,,,,,,,,,,,,,,,,,,,,
51.2,8.71335,24.87596,0,,,,,,,,,,,,,,,,,,,,,,,,,,,,,,,,,,,,,
51.5,8.76333,24.9502,0,,,,,,,,,,,,,,,,,,,,,,,,,,,,,,,,,,,,,
51.8,8.81342,25.25274,0,,,,,,,,,,,,,,,,,,,,,,,,,,,,,,,,,,,,,
52.1,8.8634,25.5814,0,,,,,,,,,,,,,,,,,,,,,,,,,,,,,,,,,,,,,
52.4,8.91344,25.93807,0,,,,,,,,,,,,,,,,,,,,,,,,,,,,,,,,,,,,,
52.7,8.96353,26.46474,0,,,,,,,,,,,,,,,,,,,,,,,,,,,,,,,,,,,,,
53,9.01351,26.94747,0,,,,,,,,,,,,,,,,,,,,,,,,,,,,,,,,,,,,,
53.3,9.06349,27.39598,0,,,,,,,,,,,,,,,,,,,,,,,,,,,,,,,,,,,,,
53.6,9.11342,27.80435,0,,,,,,,,,,,,,,,,,,,,,,,,,,,,,,,,,,,,,
53.9,9.16328,28.15859,0,,,,,,,,,,,,,,,,,,,,,,,,,,,,,,,,,,,,,
54.2,9.21343,28.46452,0,,,,,,,,,,,,,,,,,,,,,,,,,,,,,,,,,,,,,
54.5,9.26336,28.83894,0,,,,,,,,,,,,,,,,,,,,,,,,,,,,,,,,,,,,,
54.8,9.31339,29.26629,0,,,,,,,,,,,,,,,,,,,,,,,,,,,,,,,,,,,,,
55.1,9.36349,29.78277,0,,,,,,,,,,,,,,,,,,,,,,,,,,,,,,,,,,,,,
55.4,9.41347,30.14417,0,,,,,,,,,,,,,,,,,,,,,,,,,,,,,,,,,,,,,
55.7,9.4635,30.62912,0,,,,,,,,,,,,,,,,,,,,,,,,,,,,,,,,,,,,,
56,9.51348,31.09477,0,,,,,,,,,,,,,,,,,,,,,,,,,,,,,,,,,,,,,
56.3,9.56329,31.45213,0,,,,,,,,,,,,,,,,,,,,,,,,,,,,,,,,,,,,,
56.6,9.61333,31.75482,0,,,,,,,,,,,,,,,,,,,,,,,,,,,,,,,,,,,,,
56.9,9.66348,31.92469,0,,,,,,,,,,,,,,,,,,,,,,,,,,,,,,,,,,,,,
57.2,9.71335,31.85369,0,,,,,,,,,,,,,,,,,,,,,,,,,,,,,,,,,,,,,
57.5,9.76344,32.04903,0,,,,,,,,,,,,,,,,,,,,,,,,,,,,,,,,,,,,,
57.8,9.81342,32.20451,0,,,,,,,,,,,,,,,,,,,,,,,,,,,,,,,,,,,,,
58.1,9.86351,32.57084,0,,,,,,,,,,,,,,,,,,,,,,,,,,,,,,,,,,,,,
58.4,9.91355,32.8431,0,,,,,,,,,,,,,,,,,,,,,,,,,,,,,,,,,,,,,
58.7,9.96336,33.22977,0,,,,,,,,,,,,,,,,,,,,,,,,,,,,,,,,,,,,,
59,10.01334,33.63065,0,,,,,,,,,,,,,,,,,,,,,,,,,,,,,,,,,,,,,
59.3,10.06343,33.86273,0,,,,,,,,,,,,,,,,,,,,,,,,,,,,,,,,,,,,,
59.6,10.11335,34.11456,0,,,,,,,,,,,,,,,,,,,,,,,,,,,,,,,,,,,,,
59.9,10.16345,34.44382,0,,,,,,,,,,,,,,,,,,,,,,,,,,,,,,,,,,,,,
60.2,10.21343,34.8816,0,,,,,,,,,,,,,,,,,,,,,,,,,,,,,,,,,,,,,
60.5,10.26346,35.14028,0,,,,,,,,,,,,,,,,,,,,,,,,,,,,,,,,,,,,,
60.8,10.31356,35.36616,0,,,,,,,,,,,,,,,,,,,,,,,,,,,,,,,,,,,,,
61.1,10.36343,35.69526,0,,,,,,,,,,,,,,,,,,,,,,,,,,,,,,,,,,,,,
61.4,10.41335,35.80664,0,,,,,,,,,,,,,,,,,,,,,,,,,,,,,,,,,,,,,
61.7,10.46344,36.08055,0,,,,,,,,,,,,,,,,,,,,,,,,,,,,,,,,,,,,,
62,10.51337,36.28115,0,,,,,,,,,,,,,,,,,,,,,,,,,,,,,,,,,,,,,
62.3,10.5634,36.73409,0,,,,,,,,,,,,,,,,,,,,,,,,,,,,,,,,,,,,,
62.6,10.61338,37.19793,0,,,,,,,,,,,,,,,,,,,,,,,,,,,,,,,,,,,,,
62.9,10.66342,37.57444,0,,,,,,,,,,,,,,,,,,,,,,,,,,,,,,,,,,,,,
63.2,10.71357,37.85808,0,,,,,,,,,,,,,,,,,,,,,,,,,,,,,,,,,,,,,
63.5,10.76349,37.6692,0,,,,,,,,,,,,,,,,,,,,,,,,,,,,,,,,,,,,,
63.8,10.81336,37.47061,0,,,,,,,,,,,,,,,,,,,,,,,,,,,,,,,,,,,,,
64.1,10.86334,37.56494,0,,,,,,,,,,,,,,,,,,,,,,,,,,,,,,,,,,,,,
64.4,10.91332,37.70985,0,,,,,,,,,,,,,,,,,,,,,,,,,,,,,,,,,,,,,
64.7,10.96341,37.93538,0,,,,,,,,,,,,,,,,,,,,,,,,,,,,,,,,,,,,,
65,11.01345,37.31805,0,,,,,,,,,,,,,,,,,,,,,,,,,,,,,,,,,,,,,
65.3,11.06337,37.26266,0,,,,,,,,,,,,,,,,,,,,,,,,,,,,,,,,,,,,,
65.6,11.11346,37.61954,0,,,,,,,,,,,,,,,,,,,,,,,,,,,,,,,,,,,,,
65.9,11.16356,37.7867,0,,,,,,,,,,,,,,,,,,,,,,,,,,,,,,,,,,,,,
66.2,11.21343,38.00419,0,,,,,,,,,,,,,,,,,,,,,,,,,,,,,,,,,,,,,
66.5,11.26335,38.39887,0,,,,,,,,,,,,,,,,,,,,,,,,,,,,,,,,,,,,,
66.8,11.31333,38.7782,0,,,,,,,,,,,,,,,,,,,,,,,,,,,,,,,,,,,,,
67.1,11.36337,39.06301,0,,,,,,,,,,,,,,,,,,,,,,,,,,,,,,,,,,,,,
67.4,11.41346,39.36491,0,,,,,,,,,,,,,,,,,,,,,,,,,,,,,,,,,,,,,
67.7,11.46333,39.76236,0,,,,,,,,,,,,,,,,,,,,,,,,,,,,,,,,,,,,,
67.822,11.48367,40.00611,0.5,,,,,,,,,,,,,,,,,,,,,,,,,,,,,,,,,,,,,
68.122,11.43341,37.32255,0.5,,,,,,,,,,,,,,,,,,,,,,,,,,,,,,,,,,,,,
68.422,11.38343,34.92107,0.5,,,,,,,,,,,,,,,,,,,,,,,,,,,,,,,,,,,,,
68.722,11.33356,32.8166,0.5,,,,,,,,,,,,,,,,,,,,,,,,,,,,,,,,,,,,,
69.022,11.28347,31.07993,0.5,,,,,,,,,,,,,,,,,,,,,,,,,,,,,,,,,,,,,
69.322,11.23354,29.42926,0.5,,,,,,,,,,,,,,,,,,,,,,,,,,,,,,,,,,,,,
69.622,11.18351,27.8476,0.5,,,,,,,,,,,,,,,,,,,,,,,,,,,,,,,,,,,,,
69.922,11.13347,26.41224,0.5,,,,,,,,,,,,,,,,,,,,,,,,,,,,,,,,,,,,,
70.222,11.08338,25.00799,0.5,,,,,,,,,,,,,,,,,,,,,,,,,,,,,,,,,,,,,
70.522,11.03328,23.67033,0.5,,,,,,,,,,,,,,,,,,,,,,,,,,,,,,,,,,,,,
70.822,10.98336,22.38689,0.5,,,,,,,,,,,,,,,,,,,,,,,,,,,,,,,,,,,,,
71.122,10.93349,21.22203,0.5,,,,,,,,,,,,,,,,,,,,,,,,,,,,,,,,,,,,,
71.422,10.8834,20.0796,0.5,,,,,,,,,,,,,,,,,,,,,,,,,,,,,,,,,,,,,
71.722,10.83353,18.98269,0.5,,,,,,,,,,,,,,,,,,,,,,,,,,,,,,,,,,,,,
72.022,10.7835,18.00031,0.5,,,,,,,,,,,,,,,,,,,,,,,,,,,,,,,,,,,,,
72.322,10.73346,17.01249,0.5,,,,,,,,,,,,,,,,,,,,,,,,,,,,,,,,,,,,,
72.622,10.68342,16.04188,0.5,,,,,,,,,,,,,,,,,,,,,,,,,,,,,,,,,,,,,
72.922,10.63327,15.16267,0.5,,,,,,,,,,,,,,,,,,,,,,,,,,,,,,,,,,,,,
73.222,10.58329,14.38375,0.5,,,,,,,,,,,,,,,,,,,,,,,,,,,,,,,,,,,,,
73.522,10.53343,13.53128,0.5,,,,,,,,,,,,,,,,,,,,,,,,,,,,,,,,,,,,,
73.822,10.4835,12.81678,0.5,,,,,,,,,,,,,,,,,,,,,,,,,,,,,,,,,,,,,
74.122,10.43347,12.12075,0.5,,,,,,,,,,,,,,,,,,,,,,,,,,,,,,,,,,,,,
74.422,10.38348,11.35319,0.5,,,,,,,,,,,,,,,,,,,,,,,,,,,,,,,,,,,,,
74.722,10.33345,10.68819,0.5,,,,,,,,,,,,,,,,,,,,,,,,,,,,,,,,,,,,,
75.022,10.28341,10.0916,0.5,,,,,,,,,,,,,,,,,,,,,,,,,,,,,,,,,,,,,
75.322,10.23332,9.59269,0.5,,,,,,,,,,,,,,,,,,,,,,,,,,,,,,,,,,,,,
75.622,10.18328,8.94659,0.5,,,,,,,,,,,,,,,,,,,,,,,,,,,,,,,,,,,,,
75.922,10.13336,8.40427,0.5,,,,,,,,,,,,,,,,,,,,,,,,,,,,,,,,,,,,,
76.222,10.08344,7.87837,0.5,,,,,,,,,,,,,,,,,,,,,,,,,,,,,,,,,,,,,
76.522,10.03351,7.38642,0.5,,,,,,,,,,,,,,,,,,,,,,,,,,,,,,,,,,,,,
76.822,9.98348,6.977,0.5,,,,,,,,,,,,,,,,,,,,,,,,,,,,,,,,,,,,,
77.122,9.9335,6.49284,0.5,,,,,,,,,,,,,,,,,,,,,,,,,,,,,,,,,,,,,
77.422,9.88352,6.12754,0.5,,,,,,,,,,,,,,,,,,,,,,,,,,,,,,,,,,,,,
77.722,9.83342,5.74861,0.5,,,,,,,,,,,,,,,,,,,,,,,,,,,,,,,,,,,,,
78.022,9.78327,5.32824,0.5,,,,,,,,,,,,,,,,,,,,,,,,,,,,,,,,,,,,,
78.322,9.73335,5.05915,0.5,,,,,,,,,,,,,,,,,,,,,,,,,,,,,,,,,,,,,
78.622,9.68337,4.73972,0.5,,,,,,,,,,,,,,,,,,,,,,,,,,,,,,,,,,,,,
78.922,9.63339,4.36162,0.5,,,,,,,,,,,,,,,,,,,,,,,,,,,,,,,,,,,,,
79.222,9.58347,4.06405,0.5,,,,,,,,,,,,,,,,,,,,,,,,,,,,,,,,,,,,,
79.522,9.53343,3.77747,0.5,,,,,,,,,,,,,,,,,,,,,,,,,,,,,,,,,,,,,
79.822,9.48351,3.48615,0.5,,,,,,,,,,,,,,,,,,,,,,,,,,,,,,,,,,,,,
80.122,9.43347,3.25674,0.5,,,,,,,,,,,,,,,,,,,,,,,,,,,,,,,,,,,,,
80.422,9.38338,2.99291,0.5,,,,,,,,,,,,,,,,,,,,,,,,,,,,,,,,,,,,,
80.722,9.33334,2.77265,0.5,,,,,,,,,,,,,,,,,,,,,,,,,,,,,,,,,,,,,
81.022,9.28336,2.52945,0.5,,,,,,,,,,,,,,,,,,,,,,,,,,,,,,,,,,,,,
81.322,9.23344,2.3095,0.5,,,,,,,,,,,,,,,,,,,,,,,,,,,,,,,,,,,,,
81.622,9.18351,2.10982,0.5,,,,,,,,,,,,,,,,,,,,,,,,,,,,,,,,,,,,,
81.922,9.13342,1.84417,0.5,,,,,,,,,,,,,,,,,,,,,,,,,,,,,,,,,,,,,
82.222,9.08344,1.69822,0.5,,,,,,,,,,,,,,,,,,,,,,,,,,,,,,,,,,,,,
82.522,9.03346,1.51633,0.5,,,,,,,,,,,,,,,,,,,,,,,,,,,,,,,,,,,,,
82.822,8.98342,1.32843,0.5,,,,,,,,,,,,,,,,,,,,,,,,,,,,,,,,,,,,,
83.122,8.93333,1.13909,0.5,,,,,,,,,,,,,,,,,,,,,,,,,,,,,,,,,,,,,
83.302,8.90347,0.99354,1,,,,,,,,,,,,,,,,,,,,,,,,,,,,,,,,,,,,,
83.504,8.9369,1.22952,1,,,,,,,,,,,,,,,,,,,,,,,,,,,,,,,,,,,,,
83.804,8.98733,1.46442,1,,,,,,,,,,,,,,,,,,,,,,,,,,,,,,,,,,,,,
84.104,9.03737,1.78694,1,,,,,,,,,,,,,,,,,,,,,,,,,,,,,,,,,,,,,
84.404,9.08729,2.0184,1,,,,,,,,,,,,,,,,,,,,,,,,,,,,,,,,,,,,,
84.704,9.13739,2.29384,1,,,,,,,,,,,,,,,,,,,,,,,,,,,,,,,,,,,,,
85.004,9.18742,2.59829,1,,,,,,,,,,,,,,,,,,,,,,,,,,,,,,,,,,,,,
85.304,9.23746,2.86589,1,,,,,,,,,,,,,,,,,,,,,,,,,,,,,,,,,,,,,
85.604,9.2875,3.21514,1,,,,,,,,,,,,,,,,,,,,,,,,,,,,,,,,,,,,,
85.904,9.33731,3.52775,1,,,,,,,,,,,,,,,,,,,,,,,,,,,,,,,,,,,,,
86.204,9.38729,3.90304,1,,,,,,,,,,,,,,,,,,,,,,,,,,,,,,,,,,,,,
86.504,9.43744,4.20342,1,,,,,,,,,,,,,,,,,,,,,,,,,,,,,,,,,,,,,
86.804,9.4873,4.55511,1,,,,,,,,,,,,,,,,,,,,,,,,,,,,,,,,,,,,,
87.104,9.5374,4.9276,1,,,,,,,,,,,,,,,,,,,,,,,,,,,,,,,,,,,,,
87.404,9.58749,5.33611,1,,,,,,,,,,,,,,,,,,,,,,,,,,,,,,,,,,,,,
87.704,9.63747,5.72946,1,,,,,,,,,,,,,,,,,,,,,,,,,,,,,,,,,,,,,
88.004,9.68751,6.06891,1,,,,,,,,,,,,,,,,,,,,,,,,,,,,,,,,,,,,,
88.304,9.73732,6.57688,1,,,,,,,,,,,,,,,,,,,,,,,,,,,,,,,,,,,,,
88.604,9.78735,6.98125,1,,,,,,,,,,,,,,,,,,,,,,,,,,,,,,,,,,,,,
88.904,9.83739,7.35193,1,,,,,,,,,,,,,,,,,,,,,,,,,,,,,,,,,,,,,
89.204,9.88737,7.82049,1,,,,,,,,,,,,,,,,,,,,,,,,,,,,,,,,,,,,,
89.504,9.93741,8.314,1,,,,,,,,,,,,,,,,,,,,,,,,,,,,,,,,,,,,,
89.804,9.98744,8.82151,1,,,,,,,,,,,,,,,,,,,,,,,,,,,,,,,,,,,,,
90.104,10.03748,9.35771,1,,,,,,,,,,,,,,,,,,,,,,,,,,,,,,,,,,,,,
90.404,10.08752,9.92393,1,,,,,,,,,,,,,,,,,,,,,,,,,,,,,,,,,,,,,
90.704,10.13744,10.43124,1,,,,,,,,,,,,,,,,,,,,,,,,,,,,,,,,,,,,,
91.004,10.18731,11.01737,1,,,,,,,,,,,,,,,,,,,,,,,,,,,,,,,,,,,,,
91.304,10.2374,11.52907,1,,,,,,,,,,,,,,,,,,,,,,,,,,,,,,,,,,,,,
91.604,10.28732,12.15387,1,,,,,,,,,,,,,,,,,,,,,,,,,,,,,,,,,,,,,
91.904,10.33742,12.77541,1,,,,,,,,,,,,,,,,,,,,,,,,,,,,,,,,,,,,,
92.204,10.3874,13.45932,1,,,,,,,,,,,,,,,,,,,,,,,,,,,,,,,,,,,,,
92.504,10.43738,14.23467,1,,,,,,,,,,,,,,,,,,,,,,,,,,,,,,,,,,,,,
92.804,10.48753,14.88117,1,,,,,,,,,,,,,,,,,,,,,,,,,,,,,,,,,,,,,
93.104,10.53751,15.65403,1,,,,,,,,,,,,,,,,,,,,,,,,,,,,,,,,,,,,,
93.404,10.58737,16.43317,1,,,,,,,,,,,,,,,,,,,,,,,,,,,,,,,,,,,,,
93.704,10.63735,17.32573,1,,,,,,,,,,,,,,,,,,,,,,,,,,,,,,,,,,,,,
94.004,10.68733,18.10619,1,,,,,,,,,,,,,,,,,,,,,,,,,,,,,,,,,,,,,
94.304,10.73737,18.98743,1,,,,,,,,,,,,,,,,,,,,,,,,,,,,,,,,,,,,,
94.604,10.78741,19.93279,1,,,,,,,,,,,,,,,,,,,,,,,,,,,,,,,,,,,,,
94.904,10.83739,20.85298,1,,,,,,,,,,,,,,,,,,,,,,,,,,,,,,,,,,,,,
95.204,10.88748,21.78274,1,,,,,,,,,,,,,,,,,,,,,,,,,,,,,,,,,,,,,
95.504,10.93752,22.79233,1,,,,,,,,,,,,,,,,,,,,,,,,,,,,,,,,,,,,,
95.804,10.98738,23.75624,1,,,,,,,,,,,,,,,,,,,,,,,,,,,,,,,,,,,,,
96.104,11.03742,24.76467,1,,,,,,,,,,,,,,,,,,,,,,,,,,,,,,,,,,,,,
96.404,11.08734,25.80185,1,,,,,,,,,,,,,,,,,,,,,,,,,,,,,,,,,,,,,
96.704,11.13732,26.82352,1,,,,,,,,,,,,,,,,,,,,,,,,,,,,,,,,,,,,,
97.004,11.18742,27.79015,1,,,,,,,,,,,,,,,,,,,,,,,,,,,,,,,,,,,,,
97.304,11.2374,28.88572,1,,,,,,,,,,,,,,,,,,,,,,,,,,,,,,,,,,,,,
97.604,11.28743,29.90809,1,,,,,,,,,,,,,,,,,,,,,,,,,,,,,,,,,,,,,
97.904,11.33753,30.98465,1,,,,,,,,,,,,,,,,,,,,,,,,,,,,,,,,,,,,,
98.204,11.38745,32.04926,1,,,,,,,,,,,,,,,,,,,,,,,,,,,,,,,,,,,,,
98.504,11.43743,33.10926,1,,,,,,,,,,,,,,,,,,,,,,,,,,,,,,,,,,,,,
98.804,11.4873,34.20488,1,,,,,,,,,,,,,,,,,,,,,,,,,,,,,,,,,,,,,
99.104,11.53733,35.27066,1,,,,,,,,,,,,,,,,,,,,,,,,,,,,,,,,,,,,,
99.404,11.58743,36.31827,1,,,,,,,,,,,,,,,,,,,,,,,,,,,,,,,,,,,,,
99.704,11.63735,37.35462,1,,,,,,,,,,,,,,,,,,,,,,,,,,,,,,,,,,,,,
100.004,11.68739,38.33215,1,,,,,,,,,,,,,,,,,,,,,,,,,,,,,,,,,,,,,
100.304,11.73754,39.39124,1,,,,,,,,,,,,,,,,,,,,,,,,,,,,,,,,,,,,,
100.484,11.76729,40.00484,1.5,,,,,,,,,,,,,,,,,,,,,,,,,,,,,,,,,,,,,
100.784,11.71708,37.65965,1.5,,,,,,,,,,,,,,,,,,,,,,,,,,,,,,,,,,,,,
101.084,11.66716,35.56579,1.5,,,,,,,,,,,,,,,,,,,,,,,,,,,,,,,,,,,,,
101.384,11.61723,33.59227,1.5,,,,,,,,,,,,,,,,,,,,,,,,,,,,,,,,,,,,,
101.684,11.56719,31.76632,1.5,,,,,,,,,,,,,,,,,,,,,,,,,,,,,,,,,,,,,
101.984,11.51716,30.07002,1.5,,,,,,,,,,,,,,,,,,,,,,,,,,,,,,,,,,,,,
102.284,11.46712,28.47105,1.5,,,,,,,,,,,,,,,,,,,,,,,,,,,,,,,,,,,,,
102.584,11.41714,27.04136,1.5,,,,,,,,,,,,,,,,,,,,,,,,,,,,,,,,,,,,,
102.884,11.36705,25.55867,1.5,,,,,,,,,,,,,,,,,,,,,,,,,,,,,,,,,,,,,
103.184,11.3169,24.29408,1.5,,,,,,,,,,,,,,,,,,,,,,,,,,,,,,,,,,,,,
103.484,11.26703,22.94635,1.5,,,,,,,,,,,,,,,,,,,,,,,,,,,,,,,,,,,,,
103.784,11.21705,21.73645,1.5,,,,,,,,,,,,,,,,,,,,,,,,,,,,,,,,,,,,,
104.084,11.16713,20.59057,1.5,,,,,,,,,,,,,,,,,,,,,,,,,,,,,,,,,,,,,
104.384,11.11721,19.46581,1.5,,,,,,,,,,,,,,,,,,,,,,,,,,,,,,,,,,,,,
104.684,11.06711,18.44079,1.5,,,,,,,,,,,,,,,,,,,,,,,,,,,,,,,,,,,,,
104.984,11.01713,17.40865,1.5,,,,,,,,,,,,,,,,,,,,,,,,,,,,,,,,,,,,,
105.284,10.9671,16.44512,1.5,,,,,,,,,,,,,,,,,,,,,,,,,,,,,,,,,,,,,
105.584,10.91695,15.51082,1.5,,,,,,,,,,,,,,,,,,,,,,,,,,,,,,,,,,,,,
105.884,10.86702,14.64832,1.5,,,,,,,,,,,,,,,,,,,,,,,,,,,,,,,,,,,,,
106.184,10.81704,13.9303,1.5,,,,,,,,,,,,,,,,,,,,,,,,,,,,,,,,,,,,,
106.484,10.76712,13.08817,1.5,,,,,,,,,,,,,,,,,,,,,,,,,,,,,,,,,,,,,
106.784,10.7172,12.3473,1.5,,,,,,,,,,,,,,,,,,,,,,,,,,,,,,,,,,,,,
107.084,10.6671,11.67272,1.5,,,,,,,,,,,,,,,,,,,,,,,,,,,,,,,,,,,,,
107.384,10.61718,10.9564,1.5,,,,,,,,,,,,,,,,,,,,,,,,,,,,,,,,,,,,,
107.684,10.56709,10.33813,1.5,,,,,,,,,,,,,,,,,,,,,,,,,,,,,,,,,,,,,
107.984,10.51694,9.73132,1.5,,,,,,,,,,,,,,,,,,,,,,,,,,,,,,,,,,,,,
108.284,10.46701,9.12548,1.5,,,,,,,,,,,,,,,,,,,,,,,,,,,,,,,,,,,,,
108.584,10.41703,8.62206,1.5,,,,,,,,,,,,,,,,,,,,,,,,,,,,,,,,,,,,,
108.884,10.36711,8.12278,1.5,,,,,,,,,,,,,,,,,,,,,,,,,,,,,,,,,,,,,
109.184,10.31713,7.66921,1.5,,,,,,,,,,,,,,,,,,,,,,,,,,,,,,,,,,,,,
109.484,10.26704,7.14811,1.5,,,,,,,,,,,,,,,,,,,,,,,,,,,,,,,,,,,,,
109.784,10.21717,6.70841,1.5,,,,,,,,,,,,,,,,,,,,,,,,,,,,,,,,,,,,,
110.084,10.16713,6.27155,1.5,,,,,,,,,,,,,,,,,,,,,,,,,,,,,,,,,,,,,
110.384,10.1171,5.86518,1.5,,,,,,,,,,,,,,,,,,,,,,,,,,,,,,,,,,,,,
110.684,10.067,5.48826,1.5,,,,,,,,,,,,,,,,,,,,,,,,,,,,,,,,,,,,,
110.984,10.01697,5.13673,1.5,,,,,,,,,,,,,,,,,,,,,,,,,,,,,,,,,,,,,
111.284,9.9671,4.78623,1.5,,,,,,,,,,,,,,,,,,,,,,,,,,,,,,,,,,,,,
111.584,9.91718,4.43353,1.5,,,,,,,,,,,,,,,,,,,,,,,,,,,,,,,,,,,,,
111.884,9.8672,4.09323,1.5,,,,,,,,,,,,,,,,,,,,,,,,,,,,,,,,,,,,,
112.184,9.8171,3.81533,1.5,,,,,,,,,,,,,,,,,,,,,,,,,,,,,,,,,,,,,
112.484,9.76712,3.51156,1.5,,,,,,,,,,,,,,,,,,,,,,,,,,,,,,,,,,,,,
112.784,9.71709,3.18745,1.5,,,,,,,,,,,,,,,,,,,,,,,,,,,,,,,,,,,,,
113.084,9.66699,3.0048,1.5,,,,,,,,,,,,,,,,,,,,,,,,,,,,,,,,,,,,,
113.384,9.61701,2.79182,1.5,,,,,,,,,,,,,,,,,,,,,,,,,,,,,,,,,,,,,
113.684,9.56698,2.54627,1.5,,,,,,,,,,,,,,,,,,,,,,,,,,,,,,,,,,,,,
113.984,9.51711,2.30781,1.5,,,,,,,,,,,,,,,,,,,,,,,,,,,,,,,,,,,,,
114.284,9.46713,2.09162,1.5,,,,,,,,,,,,,,,,,,,,,,,,,,,,,,,,,,,,,
114.584,9.41709,1.87557,1.5,,,,,,,,,,,,,,,,,,,,,,,,,,,,,,,,,,,,,
114.884,9.36723,1.69646,1.5,,,,,,,,,,,,,,,,,,,,,,,,,,,,,,,,,,,,,
115.184,9.31708,1.49159,1.5,,,,,,,,,,,,,,,,,,,,,,,,,,,,,,,,,,,,,
115.484,9.26704,1.31285,1.5,,,,,,,,,,,,,,,,,,,,,,,,,,,,,,,,,,,,,
115.784,9.217,1.1287,1.5,,,,,,,,,,,,,,,,,,,,,,,,,,,,,,,,,,,,,
115.994,9.18215,0.99515,2,,,,,,,,,,,,,,,,,,,,,,,,,,,,,,,,,,,,,
116.098,9.19417,1.09589,2,,,,,,,,,,,,,,,,,,,,,,,,,,,,,,,,,,,,,
116.398,9.24902,1.33437,2,,,,,,,,,,,,,,,,,,,,,,,,,,,,,,,,,,,,,
116.698,9.29923,1.61289,2,,,,,,,,,,,,,,,,,,,,,,,,,,,,,,,,,,,,,
116.998,9.34915,1.91712,2,,,,,,,,,,,,,,,,,,,,,,,,,,,,,,,,,,,,,
117.298,9.39907,2.17322,2,,,,,,,,,,,,,,,,,,,,,,,,,,,,,,,,,,,,,
117.598,9.449,2.49349,2,,,,,,,,,,,,,,,,,,,,,,,,,,,,,,,,,,,,,
117.898,9.49898,2.73926,2,,,,,,,,,,,,,,,,,,,,,,,,,,,,,,,,,,,,,
118.198,9.54901,3.09569,2,,,,,,,,,,,,,,,,,,,,,,,,,,,,,,,,,,,,,
118.498,9.59911,3.3393,2,,,,,,,,,,,,,,,,,,,,,,,,,,,,,,,,,,,,,
118.798,9.64903,3.72806,2,,,,,,,,,,,,,,,,,,,,,,,,,,,,,,,,,,,,,
119.098,9.69918,4.0448,2,,,,,,,,,,,,,,,,,,,,,,,,,,,,,,,,,,,,,
119.398,9.7491,4.38131,2,,,,,,,,,,,,,,,,,,,,,,,,,,,,,,,,,,,,,
119.698,9.79914,4.73496,2,,,,,,,,,,,,,,,,,,,,,,,,,,,,,,,,,,,,,
119.998,9.84912,5.1342,2,,,,,,,,,,,,,,,,,,,,,,,,,,,,,,,,,,,,,
120.298,9.89899,5.46725,2,,,,,,,,,,,,,,,,,,,,,,,,,,,,,,,,,,,,,
120.598,9.94902,5.90415,2,,,,,,,,,,,,,,,,,,,,,,,,,,,,,,,,,,,,,
120.898,9.99906,6.28382,2,,,,,,,,,,,,,,,,,,,,,,,,,,,,,,,,,,,,,
121.198,10.04904,6.81183,2,,,,,,,,,,,,,,,,,,,,,,,,,,,,,,,,,,,,,
121.498,10.09913,7.18785,2,,,,,,,,,,,,,,,,,,,,,,,,,,,,,,,,,,,,,
121.798,10.14917,7.68688,2,,,,,,,,,,,,,,,,,,,,,,,,,,,,,,,,,,,,,
122.098,10.19909,8.1168,2,,,,,,,,,,,,,,,,,,,,,,,,,,,,,,,,,,,,,
122.398,10.24913,8.67767,2,,,,,,,,,,,,,,,,,,,,,,,,,,,,,,,,,,,,,
122.698,10.299,9.12261,2,,,,,,,,,,,,,,,,,,,,,,,,,,,,,,,,,,,,,
122.998,10.34898,9.71557,2,,,,,,,,,,,,,,,,,,,,,,,,,,,,,,,,,,,,,
123.298,10.39907,10.22256,2,,,,,,,,,,,,,,,,,,,,,,,,,,,,,,,,,,,,,
123.598,10.44899,10.78005,2,,,,,,,,,,,,,,,,,,,,,,,,,,,,,,,,,,,,,
123.898,10.49909,11.37215,2,,,,,,,,,,,,,,,,,,,,,,,,,,,,,,,,,,,,,
124.198,10.54912,12.03386,2,,,,,,,,,,,,,,,,,,,,,,,,,,,,,,,,,,,,,
124.498,10.59916,12.71241,2,,,,,,,,,,,,,,,,,,,,,,,,,,,,,,,,,,,,,
124.798,10.64914,13.40435,2,,,,,,,,,,,,,,,,,,,,,,,,,,,,,,,,,,,,,
125.098,10.69901,14.17049,2,,,,,,,,,,,,,,,,,,,,,,,,,,,,,,,,,,,,,
125.398,10.74893,14.92028,2,,,,,,,,,,,,,,,,,,,,,,,,,,,,,,,,,,,,,
125.698,10.79908,15.67799,2,,,,,,,,,,,,,,,,,,,,,,,,,,,,,,,,,,,,,
125.998,10.849,16.48992,2,,,,,,,,,,,,,,,,,,,,,,,,,,,,,,,,,,,,,
126.298,10.89904,17.33689,2,,,,,,,,,,,,,,,,,,,,,,,,,,,,,,,,,,,,,
126.598,10.94913,18.25987,2,,,,,,,,,,,,,,,,,,,,,,,,,,,,,,,,,,,,,
126.898,10.99911,19.11206,2,,,,,,,,,,,,,,,,,,,,,,,,,,,,,,,,,,,,,
127.198,11.04915,20.07312,2,,,,,,,,,,,,,,,,,,,,,,,,,,,,,,,,,,,,,
127.498,11.09907,21.05754,2,,,,,,,,,,,,,,,,,,,,,,,,,,,,,,,,,,,,,
127.798,11.149,22.06854,2,,,,,,,,,,,,,,,,,,,,,,,,,,,,,,,,,,,,,
128.098,11.19903,23.09092,2,,,,,,,,,,,,,,,,,,,,,,,,,,,,,,,,,,,,,
128.398,11.24901,24.128,2,,,,,,,,,,,,,,,,,,,,,,,,,,,,,,,,,,,,,
128.698,11.29905,25.25872,2,,,,,,,,,,,,,,,,,,,,,,,,,,,,,,,,,,,,,
128.998,11.34914,26.33076,2,,,,,,,,,,,,,,,,,,,,,,,,,,,,,,,,,,,,,
129.298,11.39912,27.34114,2,,,,,,,,,,,,,,,,,,,,,,,,,,,,,,,,,,,,,
129.598,11.44916,28.48508,2,,,,,,,,,,,,,,,,,,,,,,,,,,,,,,,,,,,,,
129.898,11.49914,29.56121,2,,,,,,,,,,,,,,,,,,,,,,,,,,,,,,,,,,,,,
130.198,11.54895,30.78764,2,,,,,,,,,,,,,,,,,,,,,,,,,,,,,,,,,,,,,
130.498,11.59904,31.99874,2,,,,,,,,,,,,,,,,,,,,,,,,,,,,,,,,,,,,,
130.798,11.64908,33.17405,2,,,,,,,,,,,,,,,,,,,,,,,,,,,,,,,,,,,,,
131.098,11.699,34.45247,2,,,,,,,,,,,,,,,,,,,,,,,,,,,,,,,,,,,,,
131.398,11.74909,35.6632,2,,,,,,,,,,,,,,,,,,,,,,,,,,,,,,,,,,,,,
131.698,11.79908,36.83272,2,,,,,,,,,,,,,,,,,,,,,,,,,,,,,,,,,,,,,
131.998,11.84917,38.13469,2,,,,,,,,,,,,,,,,,,,,,,,,,,,,,,,,,,,,,
132.298,11.89921,39.30385,2,,,,,,,,,,,,,,,,,,,,,,,,,,,,,,,,,,,,,
132.452,11.92471,40.02415,2.5,,,,,,,,,,,,,,,,,,,,,,,,,,,,,,,,,,,,,
132.752,11.8745,37.84225,2.5,,,,,,,,,,,,,,,,,,,,,,,,,,,,,,,,,,,,,
133.052,11.82429,35.71835,2.5,,,,,,,,,,,,,,,,,,,,,,,,,,,,,,,,,,,,,
133.352,11.77443,33.85053,2.5,,,,,,,,,,,,,,,,,,,,,,,,,,,,,,,,,,,,,
133.652,11.72445,31.98496,2.5,,,,,,,,,,,,,,,,,,,,,,,,,,,,,,,,,,,,,
133.952,11.67452,30.34411,2.5,,,,,,,,,,,,,,,,,,,,,,,,,,,,,,,,,,,,,
134.252,11.62443,28.76838,2.5,,,,,,,,,,,,,,,,,,,,,,,,,,,,,,,,,,,,,
134.552,11.57445,27.27764,2.5,,,,,,,,,,,,,,,,,,,,,,,,,,,,,,,,,,,,,
134.852,11.52453,25.81614,2.5,,,,,,,,,,,,,,,,,,,,,,,,,,,,,,,,,,,,,
135.152,11.47443,24.42363,2.5,,,,,,,,,,,,,,,,,,,,,,,,,,,,,,,,,,,,,
135.452,11.42434,23.17884,2.5,,,,,,,,,,,,,,,,,,,,,,,,,,,,,,,,,,,,,
135.752,11.3743,21.85142,2.5,,,,,,,,,,,,,,,,,,,,,,,,,,,,,,,,,,,,,
136.052,11.32438,20.66905,2.5,,,,,,,,,,,,,,,,,,,,,,,,,,,,,,,,,,,,,
136.352,11.27446,19.60456,2.5,,,,,,,,,,,,,,,,,,,,,,,,,,,,,,,,,,,,,
136.652,11.22453,18.49459,2.5,,,,,,,,,,,,,,,,,,,,,,,,,,,,,,,,,,,,,
136.952,11.17444,17.50315,2.5,,,,,,,,,,,,,,,,,,,,,,,,,,,,,,,,,,,,,
137.252,11.12446,16.547,2.5,,,,,,,,,,,,,,,,,,,,,,,,,,,,,,,,,,,,,
137.552,11.07442,15.64469,2.5,,,,,,,,,,,,,,,,,,,,,,,,,,,,,,,,,,,,,
137.852,11.02439,14.74768,2.5,,,,,,,,,,,,,,,,,,,,,,,,,,,,,,,,,,,,,
138.152,10.97435,13.98158,2.5,,,,,,,,,,,,,,,,,,,,,,,,,,,,,,,,,,,,,
138.452,10.92431,13.1277,2.5,,,,,,,,,,,,,,,,,,,,,,,,,,,,,,,,,,,,,
138.752,10.87439,12.43555,2.5,,,,,,,,,,,,,,,,,,,,,,,,,,,,,,,,,,,,,
139.052,10.82446,11.71007,2.5,,,,,,,,,,,,,,,,,,,,,,,,,,,,,,,,,,,,,
139.352,10.77443,10.99522,2.5,,,,,,,,,,,,,,,,,,,,,,,,,,,,,,,,,,,,,
139.652,10.72445,10.38048,2.5,,,,,,,,,,,,,,,,,,,,,,,,,,,,,,,,,,,,,
139.952,10.67447,9.83274,2.5,,,,,,,,,,,,,,,,,,,,,,,,,,,,,,,,,,,,,
140.252,10.62438,9.31319,2.5,,,,,,,,,,,,,,,,,,,,,,,,,,,,,,,,,,,,,
140.552,10.57434,8.74367,2.5,,,,,,,,,,,,,,,,,,,,,,,,,,,,,,,,,,,,,
140.852,10.52436,8.13985,2.5,,,,,,,,,,,,,,,,,,,,,,,,,,,,,,,,,,,,,
141.152,10.47432,7.65617,2.5,,,,,,,,,,,,,,,,,,,,,,,,,,,,,,,,,,,,,
141.452,10.42451,7.17691,2.5,,,,,,,,,,,,,,,,,,,,,,,,,,,,,,,,,,,,,
141.752,10.37442,6.76343,2.5,,,,,,,,,,,,,,,,,,,,,,,,,,,,,,,,,,,,,
142.052,10.32444,6.33417,2.5,,,,,,,,,,,,,,,,,,,,,,,,,,,,,,,,,,,,,
142.352,10.27452,5.95699,2.5,,,,,,,,,,,,,,,,,,,,,,,,,,,,,,,,,,,,,
142.652,10.22448,5.54475,2.5,,,,,,,,,,,,,,,,,,,,,,,,,,,,,,,,,,,,,
142.952,10.17439,5.21669,2.5,,,,,,,,,,,,,,,,,,,,,,,,,,,,,,,,,,,,,
143.252,10.12435,4.84962,2.5,,,,,,,,,,,,,,,,,,,,,,,,,,,,,,,,,,,,,
143.552,10.07426,4.49586,2.5,,,,,,,,,,,,,,,,,,,,,,,,,,,,,,,,,,,,,
143.852,10.02445,4.13572,2.5,,,,,,,,,,,,,,,,,,,,,,,,,,,,,,,,,,,,,
144.152,9.97447,3.843,2.5,,,,,,,,,,,,,,,,,,,,,,,,,,,,,,,,,,,,,
144.452,9.92449,3.55327,2.5,,,,,,,,,,,,,,,,,,,,,,,,,,,,,,,,,,,,,
144.752,9.87451,3.292,2.5,,,,,,,,,,,,,,,,,,,,,,,,,,,,,,,,,,,,,
145.052,9.82447,2.98913,2.5,,,,,,,,,,,,,,,,,,,,,,,,,,,,,,,,,,,,,
145.352,9.77438,2.73803,2.5,,,,,,,,,,,,,,,,,,,,,,,,,,,,,,,,,,,,,
145.652,9.72434,2.58077,2.5,,,,,,,,,,,,,,,,,,,,,,,,,,,,,,,,,,,,,
145.952,9.6743,2.2719,2.5,,,,,,,,,,,,,,,,,,,,,,,,,,,,,,,,,,,,,
146.252,9.62438,2.08372,2.5,,,,,,,,,,,,,,,,,,,,,,,,,,,,,,,,,,,,,
146.552,9.57446,1.84654,2.5,,,,,,,,,,,,,,,,,,,,,,,,,,,,,,,,,,,,,
146.852,9.52442,1.62019,2.5,,,,,,,,,,,,,,,,,,,,,,,,,,,,,,,,,,,,,
147.152,9.4745,1.44337,2.5,,,,,,,,,,,,,,,,,,,,,,,,,,,,,,,,,,,,,
147.452,9.42446,1.29976,2.5,,,,,,,,,,,,,,,,,,,,,,,,,,,,,,,,,,,,,
147.752,9.37448,1.08081,2.5,,,,,,,,,,,,,,,,,,,,,,,,,,,,,,,,,,,,,
147.884,9.35249,0.98533,3,,,,,,,,,,,,,,,,,,,,,,,,,,,,,,,,,,,,,
148.086,9.38593,1.22866,3,,,,,,,,,,,,,,,,,,,,,,,,,,,,,,,,,,,,,
148.386,9.43636,1.40555,3,,,,,,,,,,,,,,,,,,,,,,,,,,,,,,,,,,,,,
148.686,9.48628,1.72985,3,,,,,,,,,,,,,,,,,,,,,,,,,,,,,,,,,,,,,
148.986,9.53643,1.94426,3,,,,,,,,,,,,,,,,,,,,,,,,,,,,,,,,,,,,,
149.286,9.58641,2.31537,3,,,,,,,,,,,,,,,,,,,,,,,,,,,,,,,,,,,,,
149.586,9.63645,2.53039,3,,,,,,,,,,,,,,,,,,,,,,,,,,,,,,,,,,,,,
149.886,9.68643,2.90224,3,,,,,,,,,,,,,,,,,,,,,,,,,,,,,,,,,,,,,
150.186,9.7363,3.20189,3,,,,,,,,,,,,,,,,,,,,,,,,,,,,,,,,,,,,,
150.486,9.78628,3.46428,3,,,,,,,,,,,,,,,,,,,,,,,,,,,,,,,,,,,,,
150.786,9.83642,3.75984,3,,,,,,,,,,,,,,,,,,,,,,,,,,,,,,,,,,,,,
151.086,9.88641,4.16148,3,,,,,,,,,,,,,,,,,,,,,,,,,,,,,,,,,,,,,
151.386,9.93639,4.45895,3,,,,,,,,,,,,,,,,,,,,,,,,,,,,,,,,,,,,,
151.686,9.98642,4.90388,3,,,,,,,,,,,,,,,,,,,,,,,,,,,,,,,,,,,,,
151.986,10.03646,5.26429,3,,,,,,,,,,,,,,,,,,,,,,,,,,,,,,,,,,,,,
152.286,10.08655,5.69354,3,,,,,,,,,,,,,,,,,,,,,,,,,,,,,,,,,,,,,
152.586,10.13636,6.13367,3,,,,,,,,,,,,,,,,,,,,,,,,,,,,,,,,,,,,,
152.886,10.18634,6.51836,3,,,,,,,,,,,,,,,,,,,,,,,,,,,,,,,,,,,,,
153.186,10.23638,6.90886,3,,,,,,,,,,,,,,,,,,,,,,,,,,,,,,,,,,,,,
153.486,10.28636,7.43158,3,,,,,,,,,,,,,,,,,,,,,,,,,,,,,,,,,,,,,
153.786,10.3364,7.96592,3,,,,,,,,,,,,,,,,,,,,,,,,,,,,,,,,,,,,,
154.086,10.38638,8.43394,3,,,,,,,,,,,,,,,,,,,,,,,,,,,,,,,,,,,,,
154.386,10.43636,8.93647,3,,,,,,,,,,,,,,,,,,,,,,,,,,,,,,,,,,,,,
154.686,10.48656,9.47174,3,,,,,,,,,,,,,,,,,,,,,,,,,,,,,,,,,,,,,
154.986,10.53649,10.04385,3,,,,,,,,,,,,,,,,,,,,,,,,,,,,,,,,,,,,,
155.286,10.58635,10.75779,3,,,,,,,,,,,,,,,,,,,,,,,,,,,,,,,,,,,,,
155.586,10.63633,11.25093,3,,,,,,,,,,,,,,,,,,,,,,,,,,,,,,,,,,,,,
155.886,10.68631,11.94173,3,,,,,,,,,,,,,,,,,,,,,,,,,,,,,,,,,,,,,
156.186,10.73641,12.55846,3,,,,,,,,,,,,,,,,,,,,,,,,,,,,,,,,,,,,,
156.486,10.78639,13.27001,3,,,,,,,,,,,,,,,,,,,,,,,,,,,,,,,,,,,,,
156.786,10.83637,14.025,3,,,,,,,,,,,,,,,,,,,,,,,,,,,,,,,,,,,,,
157.086,10.88652,14.79756,3,,,,,,,,,,,,,,,,,,,,,,,,,,,,,,,,,,,,,
157.386,10.93655,15.52248,3,,,,,,,,,,,,,,,,,,,,,,,,,,,,,,,,,,,,,
157.686,10.98636,16.3884,3,,,,,,,,,,,,,,,,,,,,,,,,,,,,,,,,,,,,,
157.986,11.0364,17.2207,3,,,,,,,,,,,,,,,,,,,,,,,,,,,,,,,,,,,,,
158.286,11.08632,18.05728,3,,,,,,,,,,,,,,,,,,,,,,,,,,,,,,,,,,,,,
158.586,11.1363,19.05126,3,,,,,,,,,,,,,,,,,,,,,,,,,,,,,,,,,,,,,
158.886,11.18645,19.92456,3,,,,,,,,,,,,,,,,,,,,,,,,,,,,,,,,,,,,,
159.186,11.23637,20.95826,3,,,,,,,,,,,,,,,,,,,,,,,,,,,,,,,,,,,,,
159.486,11.28647,21.93747,3,,,,,,,,,,,,,,,,,,,,,,,,,,,,,,,,,,,,,
159.786,11.33656,22.97265,3,,,,,,,,,,,,,,,,,,,,,,,,,,,,,,,,,,,,,
160.086,11.38643,24.15153,3,,,,,,,,,,,,,,,,,,,,,,,,,,,,,,,,,,,,,
160.386,11.43641,25.16546,3,,,,,,,,,,,,,,,,,,,,,,,,,,,,,,,,,,,,,
160.686,11.48628,26.31153,3,,,,,,,,,,,,,,,,,,,,,,,,,,,,,,,,,,,,,
160.986,11.53631,27.39469,3,,,,,,,,,,,,,,,,,,,,,,,,,,,,,,,,,,,,,
161.286,11.58641,28.54404,3,,,,,,,,,,,,,,,,,,,,,,,,,,,,,,,,,,,,,
161.586,11.63639,29.79483,3,,,,,,,,,,,,,,,,,,,,,,,,,,,,,,,,,,,,,
161.886,11.68642,30.91589,3,,,,,,,,,,,,,,,,,,,,,,,,,,,,,,,,,,,,,
162.186,11.73652,32.2067,3,,,,,,,,,,,,,,,,,,,,,,,,,,,,,,,,,,,,,
162.486,11.78644,33.48376,3,,,,,,,,,,,,,,,,,,,,,,,,,,,,,,,,,,,,,
162.786,11.83642,34.8057,3,,,,,,,,,,,,,,,,,,,,,,,,,,,,,,,,,,,,,
163.086,11.88634,36.15416,3,,,,,,,,,,,,,,,,,,,,,,,,,,,,,,,,,,,,,
163.386,11.93627,37.4814,3,,,,,,,,,,,,,,,,,,,,,,,,,,,,,,,,,,,,,
163.686,11.98641,38.81229,3,,,,,,,,,,,,,,,,,,,,,,,,,,,,,,,,,,,,,
163.944,12.02943,40.00443,3.5,,,,,,,,,,,,,,,,,,,,,,,,,,,,,,,,,,,,,
164.146,11.9965,38.71244,3.5,,,,,,,,,,,,,,,,,,,,,,,,,,,,,,,,,,,,,
164.446,11.94607,36.42743,3.5,,,,,,,,,,,,,,,,,,,,,,,,,,,,,,,,,,,,,
164.746,11.89615,34.50127,3.5,,,,,,,,,,,,,,,,,,,,,,,,,,,,,,,,,,,,,
165.046,11.84617,32.60839,3.5,,,,,,,,,,,,,,,,,,,,,,,,,,,,,,,,,,,,,
165.346,11.79619,30.94606,3.5,,,,,,,,,,,,,,,,,,,,,,,,,,,,,,,,,,,,,
165.646,11.74615,29.30606,3.5,,,,,,,,,,,,,,,,,,,,,,,,,,,,,,,,,,,,,
165.946,11.69611,27.81411,3.5,,,,,,,,,,,,,,,,,,,,,,,,,,,,,,,,,,,,,
166.246,11.64613,26.35456,3.5,,,,,,,,,,,,,,,,,,,,,,,,,,,,,,,,,,,,,
166.546,11.59598,24.91418,3.5,,,,,,,,,,,,,,,,,,,,,,,,,,,,,,,,,,,,,
166.846,11.546,23.60828,3.5,,,,,,,,,,,,,,,,,,,,,,,,,,,,,,,,,,,,,
167.146,11.49602,22.34405,3.5,,,,,,,,,,,,,,,,,,,,,,,,,,,,,,,,,,,,,
167.446,11.4461,21.13319,3.5,,,,,,,,,,,,,,,,,,,,,,,,,,,,,,,,,,,,,
167.746,11.39612,20.02485,3.5,,,,,,,,,,,,,,,,,,,,,,,,,,,,,,,,,,,,,
168.046,11.34608,18.872,3.5,,,,,,,,,,,,,,,,,,,,,,,,,,,,,,,,,,,,,
168.346,11.29616,17.88246,3.5,,,,,,,,,,,,,,,,,,,,,,,,,,,,,,,,,,,,,
168.646,11.24612,16.89513,3.5,,,,,,,,,,,,,,,,,,,,,,,,,,,,,,,,,,,,,
168.946,11.19597,15.93859,3.5,,,,,,,,,,,,,,,,,,,,,,,,,,,,,,,,,,,,,
169.246,11.14599,15.02114,3.5,,,,,,,,,,,,,,,,,,,,,,,,,,,,,,,,,,,,,
169.546,11.09601,14.28546,3.5,,,,,,,,,,,,,,,,,,,,,,,,,,,,,,,,,,,,,
169.846,11.04609,13.37627,3.5,,,,,,,,,,,,,,,,,,,,,,,,,,,,,,,,,,,,,
170.146,10.99617,12.6797,3.5,,,,,,,,,,,,,,,,,,,,,,,,,,,,,,,,,,,,,
170.446,10.94607,11.93641,3.5,,,,,,,,,,,,,,,,,,,,,,,,,,,,,,,,,,,,,
170.746,10.89615,11.22328,3.5,,,,,,,,,,,,,,,,,,,,,,,,,,,,,,,,,,,,,
171.046,10.84617,10.56604,3.5,,,,,,,,,,,,,,,,,,,,,,,,,,,,,,,,,,,,,
171.346,10.79608,9.99015,3.5,,,,,,,,,,,,,,,,,,,,,,,,,,,,,,,,,,,,,
171.646,10.74598,9.39092,3.5,,,,,,,,,,,,,,,,,,,,,,,,,,,,,,,,,,,,,
171.946,10.69595,8.81695,3.5,,,,,,,,,,,,,,,,,,,,,,,,,,,,,,,,,,,,,
172.246,10.64602,8.29523,3.5,,,,,,,,,,,,,,,,,,,,,,,,,,,,,,,,,,,,,
172.546,10.59621,7.7881,3.5,,,,,,,,,,,,,,,,,,,,,,,,,,,,,,,,,,,,,
172.846,10.54618,7.33489,3.5,,,,,,,,,,,,,,,,,,,,,,,,,,,,,,,,,,,,,
173.146,10.49608,6.91826,3.5,,,,,,,,,,,,,,,,,,,,,,,,,,,,,,,,,,,,,
173.446,10.44616,6.43352,3.5,,,,,,,,,,,,,,,,,,,,,,,,,,,,,,,,,,,,,
173.746,10.39607,6.04295,3.5,,,,,,,,,,,,,,,,,,,,,,,,,,,,,,,,,,,,,
174.046,10.34603,5.61526,3.5,,,,,,,,,,,,,,,,,,,,,,,,,,,,,,,,,,,,,
174.346,10.29605,5.2871,3.5,,,,,,,,,,,,,,,,,,,,,,,,,,,,,,,,,,,,,
174.446,10.27945,5.18807,3.5,,,,,,,,,,,,,,,,,,,,,,,,,,,,,,,,,,,,,