File: combined_ligament_solver/data/processed/Data Sheet 3_S160798_MCL.csv
Specimen properties : Length,127,mm,Unnamed: 3,Unnamed: 4,Unnamed: 5,Unnamed: 6,Unnamed: 7,Unnamed: 8,Unnamed: 9,Unnamed: 10,Unnamed: 11,Stress-Strain,Unnamed: 13,Unnamed: 14,Unnamed: 15,Unnamed: 16,Unnamed: 17,Unnamed: 18,Unnamed: 19,Unnamed: 20,Unnamed: 21,Unnamed: 22,Unnamed: 23,Unnamed: 24,Unnamed: 25,Unnamed: 26,Unnamed: 27,Linear,Unnamed: 29,Unnamed: 30,Unnamed: 31,Unnamed: 32,Unnamed: 33,Modulus,Unnamed: 35,Failure,Unnamed: 37,Unnamed: 38,Unnamed: 39,Unnamed: 40
Cross Section Average,28.804,mm2,,,,,,,,,,Polynomial Coefficients,,,,,,,,,,,,,,,,Force,,Stress,Extension,Strain,,Secant,Tangent,Load,Stress,Extension,Strain,Stiffness
Time,Extension,Load,Total cycle count,,,Extension,Load,Strain,Stress,E-tan,,X6,35930999629.0445,,,,,,,,,Strain,Stress,E-tan,,,,(N),,(MPa),(mm),(%),,(MPa),(MPa),(N),(MPa),(mm),(%),(N/mm)
(s),(mm),(N),,,,(mm),(N),(mm/mm),(MPa),(MPa),,X5,-3696488805.4292603,,,,,,,,,(mm/mm),(MPa),(MPa),,,,66.61499287224494,,2.3126993775949503,2.921,2.3,,100.55214685195438,179.7505102525328,514.05145,17.813180113873077,12.266689999999999,9.658811023622047,22.805543605698375
0.7,0.25177,1.88166,0,,,7.85202,150.06148,0.044094251968503945,,,,,,,,,,,,,,0.007,0.30676750854240187,68.95886080611893,,,,,,,,,,,,,,,,
1.5,0.38499,2.91927,0,,,14.51874,514.05145,0.09658811023622046,17.813180113873077,,,,,,,,,,,,,0.015,1.0318366326511401,118.37079899125155,,,,,,,,,,,,,,,,
2.3,0.51827,3.86433,0,,,21.18534,53.24913,,,,,,,,,,,,,,MAX,0.023,2.3126993775949503,179.7505102525328,,,,,,,,,,,,,,,,
3.1,0.65178,4.73128,0,,,,,,,,,,,,,,,,,,,0.031,3.4891338382495767,106.025937004539,,,,,,,,,,,,,,,,
3.9,0.785,5.68417,0,,,,,,,,,,,,,,,,,,,0.039,,,,,,,,,,,,,,,,,,
4.7,0.9184,6.69074,0,,,,,,,,,,,,,,,,,,,0.047,,,,,,,,,,,,,,,,,,
5.5,1.05173,7.57914,0,,,,,,,,,,,,,,,,,,,0.055,,,,,,,,,,,,,,,,,,
6.3,1.18496,8.56472,0,,,,,,,,,,,,,,,,,,,0.063,,,,,,,,,,,,,,,,,,
7.1,1.31852,9.54752,0,,,,,,,,,,,,,,,,,,,0.071,,,,,,,,,,,,,,,,,,
7.9,1.45169,10.52825,0,,,,,,,,,,,,,,,,,,,0.079,,,,,,,,,,,,,,,,,,
8.7,1.58485,11.65984,0,,,,,,,,,,,,,,,,,,,0.087,,,,,,,,,,,,,,,,,,
9.5,1.71853,12.84526,0,,,,,,,,,,,,,,,,,,,0.095,,,,,,,,,,,,,,,,,,
10.3,1.8517,13.96988,0,,,,,,,,,,,,,,,,,,,0.103,,,,,,,,,,,,,,,,,,
11.1,1.98492,15.25667,0,,,,,,,,,,,,,,,,,,,0.111,,,,,,,,,,,,,,,,,,
11.9,2.11848,16.51385,0,,,,,,,,,,,,,,,,,,,0.119,,,,,,,,,,,,,,,,,,
12.7,2.25171,17.52288,0,,,,,,,,,,,,,,,,,,,0.127,,,,,,,,,,,,,,,,,,
13.5,2.38493,19.14207,0,,,,,,,,,,,,,,,,,,,0.135,,,,,,,,,,,,,,,,,,
14.3,2.51838,20.38112,0,,,,,,,,,,,,,,,,,,,0.143,,,,,,,,,,,,,,,,,,
15.1,2.6516,22.04533,0,,,,,,,,,,,,,,,,,,,0.151,,,,,,,,,,,,,,,,,,
15.9,2.785,23.75213,0,,,,,,,,,,,,,,,,,,,0.159,,,,,,,,,,,,,,,,,,
16.7,2.91845,25.56048,0,,,,,,,,,,,,,,,,,,,0.167,,,,,,,,,,,,,,,,,,
17.5,3.05173,27.43679,0,,,,,,,,,,,,,,,,,,,0.175,,,,,,,,,,,,,,,,,,
18.3,3.18506,28.93511,0,,,,,,,,,,,,,,,,,,,0.183,,,,,,,,,,,,,,,,,,
19.1,3.3184,31.10564,0,,,,,,,,,,,,,,,,,,,0.191,,,,,,,,,,,,,,,,,,
19.9,3.45157,33.15814,0,,,,,,,,,,,,,,,,,,,0.199,,,,,,,,,,,,,,,,,,
20.7,3.58507,35.38932,0,,,,,,,,,,,,,,,,,,,,,,,,,,,,,,,,,,,,,
21.5,3.71835,37.63591,0,,,,,,,,,,,,,,,,,,,,,,,,,,,,,,,,,,,,,
22.3,3.85158,39.99881,0,,,,,,,,,,,,,,,,,,,,,,,,,,,,,,,,,,,,,
22.904,3.75213,34.65051,0.5,,,,,,,,,,,,,,,,,,,,,,,,,,,,,,,,,,,,,
23.704,3.61868,28.99007,0.5,,,,,,,,,,,,,,,,,,,,,,,,,,,,,,,,,,,,,
24.504,3.48545,24.31355,0.5,,,,,,,,,,,,,,,,,,,,,,,,,,,,,,,,,,,,,
25.304,3.352,20.44376,0.5,,,,,,,,,,,,,,,,,,,,,,,,,,,,,,,,,,,,,
26.104,3.21867,16.99109,0.5,,,,,,,,,,,,,,,,,,,,,,,,,,,,,,,,,,,,,
26.904,3.08539,14.12019,0.5,,,,,,,,,,,,,,,,,,,,,,,,,,,,,,,,,,,,,
27.704,2.95194,11.73503,0.5,,,,,,,,,,,,,,,,,,,,,,,,,,,,,,,,,,,,,
28.504,2.81871,9.6795,0.5,,,,,,,,,,,,,,,,,,,,,,,,,,,,,,,,,,,,,
29.304,2.68543,7.99166,0.5,,,,,,,,,,,,,,,,,,,,,,,,,,,,,,,,,,,,,
30.104,2.55193,6.32434,0.5,,,,,,,,,,,,,,,,,,,,,,,,,,,,,,,,,,,,,
30.904,2.4187,5.06537,0.5,,,,,,,,,,,,,,,,,,,,,,,,,,,,,,,,,,,,,
31.704,2.28542,4.07303,0.5,,,,,,,,,,,,,,,,,,,,,,,,,,,,,,,,,,,,,
32.504,2.15192,3.04828,0.5,,,,,,,,,,,,,,,,,,,,,,,,,,,,,,,,,,,,,
33.304,2.01869,2.2926,0.5,,,,,,,,,,,,,,,,,,,,,,,,,,,,,,,,,,,,,
34.104,1.88541,1.46363,0.5,,,,,,,,,,,,,,,,,,,,,,,,,,,,,,,,,,,,,
34.704,1.81469,1.03382,1,,,,,,,,,,,,,,,,,,,,,,,,,,,,,,,,,,,,,
35.504,1.95296,2.45009,1,,,,,,,,,,,,,,,,,,,,,,,,,,,,,,,,,,,,,
36.304,2.08635,3.75333,1,,,,,,,,,,,,,,,,,,,,,,,,,,,,,,,,,,,,,
37.104,2.21975,5.05724,1,,,,,,,,,,,,,,,,,,,,,,,,,,,,,,,,,,,,,
37.904,2.35297,6.43033,1,,,,,,,,,,,,,,,,,,,,,,,,,,,,,,,,,,,,,
38.704,2.48636,8.03413,1,,,,,,,,,,,,,,,,,,,,,,,,,,,,,,,,,,,,,
39.504,2.61976,9.84218,1,,,,,,,,,,,,,,,,,,,,,,,,,,,,,,,,,,,,,
40.304,2.75292,11.72531,1,,,,,,,,,,,,,,,,,,,,,,,,,,,,,,,,,,,,,
41.104,2.88632,13.87649,1,,,,,,,,,,,,,,,,,,,,,,,,,,,,,,,,,,,,,
41.904,3.01977,16.18977,1,,,,,,,,,,,,,,,,,,,,,,,,,,,,,,,,,,,,,
42.704,3.15299,18.7007,1,,,,,,,,,,,,,,,,,,,,,,,,,,,,,,,,,,,,,
43.504,3.28633,21.47445,1,,,,,,,,,,,,,,,,,,,,,,,,,,,,,,,,,,,,,
44.304,3.41978,24.39601,1,,,,,,,,,,,,,,,,,,,,,,,,,,,,,,,,,,,,,
45.104,3.55306,27.9513,1,,,,,,,,,,,,,,,,,,,,,,,,,,,,,,,,,,,,,
45.904,3.68634,31.59693,1,,,,,,,,,,,,,,,,,,,,,,,,,,,,,,,,,,,,,
46.704,3.81973,35.15003,1,,,,,,,,,,,,,,,,,,,,,,,,,,,,,,,,,,,,,
47.504,3.95301,38.68278,1,,,,,,,,,,,,,,,,,,,,,,,,,,,,,,,,,,,,,
48.118,3.95516,37.43727,1.5,,,,,,,,,,,,,,,,,,,,,,,,,,,,,,,,,,,,,
48.918,3.82177,31.28675,1.5,,,,,,,,,,,,,,,,,,,,,,,,,,,,,,,,,,,,,
49.718,3.68838,26.35579,1.5,,,,,,,,,,,,,,,,,,,,,,,,,,,,,,,,,,,,,
50.518,3.55504,22.12072,1.5,,,,,,,,,,,,,,,,,,,,,,,,,,,,,,,,,,,,,
51.318,3.42182,18.49935,1.5,,,,,,,,,,,,,,,,,,,,,,,,,,,,,,,,,,,,,
52.118,3.28831,15.3596,1.5,,,,,,,,,,,,,,,,,,,,,,,,,,,,,,,,,,,,,
52.918,3.15503,12.75978,1.5,,,,,,,,,,,,,,,,,,,,,,,,,,,,,,,,,,,,,
53.718,3.02169,10.53737,1.5,,,,,,,,,,,,,,,,,,,,,,,,,,,,,,,,,,,,,
54.518,2.88819,8.59703,1.5,,,,,,,,,,,,,,,,,,,,,,,,,,,,,,,,,,,,,
55.318,2.75508,7.03156,1.5,,,,,,,,,,,,,,,,,,,,,,,,,,,,,,,,,,,,,
56.118,2.62174,5.49134,1.5,,,,,,,,,,,,,,,,,,,,,,,,,,,,,,,,,,,,,
56.918,2.48829,4.32939,1.5,,,,,,,,,,,,,,,,,,,,,,,,,,,,,,,,,,,,,
57.718,2.35507,3.57111,1.5,,,,,,,,,,,,,,,,,,,,,,,,,,,,,,,,,,,,,
58.518,2.22173,2.47464,1.5,,,,,,,,,,,,,,,,,,,,,,,,,,,,,,,,,,,,,
59.318,2.08828,1.62279,1.5,,,,,,,,,,,,,,,,,,,,,,,,,,,,,,,,,,,,,
60.056,1.96537,0.997,2,,,,,,,,,,,,,,,,,,,,,,,,,,,,,,,,,,,,,
60.66,2.06573,1.91128,2,,,,,,,,,,,,,,,,,,,,,,,,,,,,,,,,,,,,,
61.46,2.19895,3.2102,2,,,,,,,,,,,,,,,,,,,,,,,,,,,,,,,,,,,,,
62.26,2.33234,4.54826,2,,,,,,,,,,,,,,,,,,,,,,,,,,,,,,,,,,,,,
63.06,2.46574,5.98704,2,,,,,,,,,,,,,,,,,,,,,,,,,,,,,,,,,,,,,
63.86,2.59896,7.45014,2,,,,,,,,,,,,,,,,,,,,,,,,,,,,,,,,,,,,,
64.66,2.73247,9.20831,2,,,,,,,,,,,,,,,,,,,,,,,,,,,,,,,,,,,,,
65.46,2.86575,11.1858,2,,,,,,,,,,,,,,,,,,,,,,,,,,,,,,,,,,,,,
66.26,2.99891,13.2842,2,,,,,,,,,,,,,,,,,,,,,,,,,,,,,,,,,,,,,
67.06,3.13248,15.60187,2,,,,,,,,,,,,,,,,,,,,,,,,,,,,,,,,,,,,,
67.86,3.2657,18.21908,2,,,,,,,,,,,,,,,,,,,,,,,,,,,,,,,,,,,,,
68.66,3.39892,20.74613,2,,,,,,,,,,,,,,,,,,,,,,,,,,,,,,,,,,,,,
69.46,3.53249,23.96866,2,,,,,,,,,,,,,,,,,,,,,,,,,,,,,,,,,,,,,
70.26,3.66571,27.59603,2,,,,,,,,,,,,,,,,,,,,,,,,,,,,,,,,,,,,,
71.06,3.79893,31.1964,2,,,,,,,,,,,,,,,,,,,,,,,,,,,,,,,,,,,,,
71.86,3.93244,35.19246,2,,,,,,,,,,,,,,,,,,,,,,,,,,,,,,,,,,,,,
72.66,4.06566,39.20323,2,,,,,,,,,,,,,,,,,,,,,,,,,,,,,,,,,,,,,
73.342,4.01245,35.85764,2.5,,,,,,,,,,,,,,,,,,,,,,,,,,,,,,,,,,,,,
74.142,3.87912,30.17307,2.5,,,,,,,,,,,,,,,,,,,,,,,,,,,,,,,,,,,,,
74.942,3.74567,25.30452,2.5,,,,,,,,,,,,,,,,,,,,,,,,,,,,,,,,,,,,,
75.742,3.61239,21.26545,2.5,,,,,,,,,,,,,,,,,,,,,,,,,,,,,,,,,,,,,
76.542,3.47905,17.76709,2.5,,,,,,,,,,,,,,,,,,,,,,,,,,,,,,,,,,,,,
77.342,3.34554,14.81329,2.5,,,,,,,,,,,,,,,,,,,,,,,,,,,,,,,,,,,,,
78.142,3.21238,12.25813,2.5,,,,,,,,,,,,,,,,,,,,,,,,,,,,,,,,,,,,,
78.942,3.07904,10.05765,2.5,,,,,,,,,,,,,,,,,,,,,,,,,,,,,,,,,,,,,
79.742,2.94565,8.25634,2.5,,,,,,,,,,,,,,,,,,,,,,,,,,,,,,,,,,,,,
80.542,2.81242,6.61604,2.5,,,,,,,,,,,,,,,,,,,,,,,,,,,,,,,,,,,,,
81.342,2.67909,5.27578,2.5,,,,,,,,,,,,,,,,,,,,,,,,,,,,,,,,,,,,,
82.142,2.54564,4.12985,2.5,,,,,,,,,,,,,,,,,,,,,,,,,,,,,,,,,,,,,
82.942,2.41241,3.1958,2.5,,,,,,,,,,,,,,,,,,,,,,,,,,,,,,,,,,,,,
83.742,2.27902,2.2404,2.5,,,,,,,,,,,,,,,,,,,,,,,,,,,,,,,,,,,,,
84.542,2.14563,1.36821,2.5,,,,,,,,,,,,,,,,,,,,,,,,,,,,,,,,,,,,,
85.106,2.11905,1.30994,3,,,,,,,,,,,,,,,,,,,,,,,,,,,,,,,,,,,,,
85.906,2.25267,2.63927,3,,,,,,,,,,,,,,,,,,,,,,,,,,,,,,,,,,,,,
86.706,2.38595,4.06532,3,,,,,,,,,,,,,,,,,,,,,,,,,,,,,,,,,,,,,
87.506,2.5194,5.37396,3,,,,,,,,,,,,,,,,,,,,,,,,,,,,,,,,,,,,,
88.306,2.65262,6.90192,3,,,,,,,,,,,,,,,,,,,,,,,,,,,,,,,,,,,,,
89.106,2.78607,8.63994,3,,,,,,,,,,,,,,,,,,,,,,,,,,,,,,,,,,,,,
89.906,2.91941,10.60008,3,,,,,,,,,,,,,,,,,,,,,,,,,,,,,,,,,,,,,
90.706,3.05258,12.643,3,,,,,,,,,,,,,,,,,,,,,,,,,,,,,,,,,,,,,
91.506,3.18608,14.93749,3,,,,,,,,,,,,,,,,,,,,,,,,,,,,,,,,,,,,,
92.306,3.31936,17.53278,3,,,,,,,,,,,,,,,,,,,,,,,,,,,,,,,,,,,,,
93.106,3.45253,20.21802,3,,,,,,,,,,,,,,,,,,,,,,,,,,,,,,,,,,,,,
93.906,3.58615,23.21976,3,,,,,,,,,,,,,,,,,,,,,,,,,,,,,,,,,,,,,
94.706,3.71937,26.36373,3,,,,,,,,,,,,,,,,,,,,,,,,,,,,,,,,,,,,,
95.506,3.8526,30.34719,3,,,,,,,,,,,,,,,,,,,,,,,,,,,,,,,,,,,,,
96.306,3.98616,34.55716,3,,,,,,,,,,,,,,,,,,,,,,,,,,,,,,,,,,,,,
97.106,4.11933,38.81174,3,,,,,,,,,,,,,,,,,,,,,,,,,,,,,,,,,,,,,
97.75,4.09315,36.6987,3.5,,,,,,,,,,,,,,,,,,,,,,,,,,,,,,,,,,,,,
98.55,3.95964,30.82153,3.5,,,,,,,,,,,,,,,,,,,,,,,,,,,,,,,,,,,,,
99.35,3.82647,25.98494,3.5,,,,,,,,,,,,,,,,,,,,,,,,,,,,,,,,,,,,,
100.15,3.69302,21.7869,3.5,,,,,,,,,,,,,,,,,,,,,,,,,,,,,,,,,,,,,
100.95,3.55974,18.24057,3.5,,,,,,,,,,,,,,,,,,,,,,,,,,,,,,,,,,,,,
101.75,3.42641,15.11657,3.5,,,,,,,,,,,,,,,,,,,,,,,,,,,,,,,,,,,,,
102.55,3.29301,12.55258,3.5,,,,,,,,,,,,,,,,,,,,,,,,,,,,,,,,,,,,,
103.35,3.15973,10.28844,3.5,,,,,,,,,,,,,,,,,,,,,,,,,,,,,,,,,,,,,
104.15,3.0264,8.44298,3.5,,,,,,,,,,,,,,,,,,,,,,,,,,,,,,,,,,,,,
104.95,2.89289,6.74369,3.5,,,,,,,,,,,,,,,,,,,,,,,,,,,,,,,,,,,,,
105.75,2.75978,5.39006,3.5,,,,,,,,,,,,,,,,,,,,,,,,,,,,,,,,,,,,,
106.55,2.62639,4.2742,3.5,,,,,,,,,,,,,,,,,,,,,,,,,,,,,,,,,,,,,
107.35,2.49299,3.26443,3.5,,,,,,,,,,,,,,,,,,,,,,,,,,,,,,,,,,,,,
108.15,2.35977,2.29834,3.5,,,,,,,,,,,,,,,,,,,,,,,,,,,,,,,,,,,,,
108.95,2.22638,1.47822,3.5,,,,,,,,,,,,,,,,,,,,,,,,,,,,,,,,,,,,,
109.508,2.16285,1.02615,4,,,,,,,,,,,,,,,,,,,,,,,,,,,,,,,,,,,,,
110.308,2.30101,2.45652,4,,,,,,,,,,,,,,,,,,,,,,,,,,,,,,,,,,,,,
111.108,2.43434,3.85305,4,,,,,,,,,,,,,,,,,,,,,,,,,,,,,,,,,,,,,
111.908,2.56774,5.18668,4,,,,,,,,,,,,,,,,,,,,,,,,,,,,,,,,,,,,,
112.708,2.70102,6.68721,4,,,,,,,,,,,,,,,,,,,,,,,,,,,,,,,,,,,,,
113.508,2.83424,8.3971,4,,,,,,,,,,,,,,,,,,,,,,,,,,,,,,,,,,,,,
114.308,2.96775,10.32181,4,,,,,,,,,,,,,,,,,,,,,,,,,,,,,,,,,,,,,
115.108,3.10108,12.42997,4,,,,,,,,,,,,,,,,,,,,,,,,,,,,,,,,,,,,,
115.908,3.23431,14.72151,4,,,,,,,,,,,,,,,,,,,,,,,,,,,,,,,,,,,,,
116.708,3.36776,17.21688,4,,,,,,,,,,,,,,,,,,,,,,,,,,,,,,,,,,,,,
117.508,3.50104,19.93159,4,,,,,,,,,,,,,,,,,,,,,,,,,,,,,,,,,,,,,
118.308,3.63437,22.98196,4,,,,,,,,,,,,,,,,,,,,,,,,,,,,,,,,,,,,,
119.108,3.76765,26.18029,4,,,,,,,,,,,,,,,,,,,,,,,,,,,,,,,,,,,,,
119.908,3.90099,30.1454,4,,,,,,,,,,,,,,,,,,,,,,,,,,,,,,,,,,,,,
120.708,4.03438,34.26712,4,,,,,,,,,,,,,,,,,,,,,,,,,,,,,,,,,,,,,
121.508,4.16772,38.60694,4,,,,,,,,,,,,,,,,,,,,,,,,,,,,,,,,,,,,,
122.176,4.14539,36.79266,4.5,,,,,,,,,,,,,,,,,,,,,,,,,,,,,,,,,,,,,
122.976,4.01206,30.87123,4.5,,,,,,,,,,,,,,,,,,,,,,,,,,,,,,,,,,,,,
123.776,3.87878,26.0316,4.5,,,,,,,,,,,,,,,,,,,,,,,,,,,,,,,,,,,,,
124.576,3.74533,21.83098,4.5,,,,,,,,,,,,,,,,,,,,,,,,,,,,,,,,,,,,,
125.376,3.61205,18.21594,4.5,,,,,,,,,,,,,,,,,,,,,,,,,,,,,,,,,,,,,
126.176,3.47871,15.21081,4.5,,,,,,,,,,,,,,,,,,,,,,,,,,,,,,,,,,,,,
126.976,3.3452,12.53532,4.5,,,,,,,,,,,,,,,,,,,,,,,,,,,,,,,,,,,,,
127.776,3.21204,10.279,4.5,,,,,,,,,,,,,,,,,,,,,,,,,,,,,,,,,,,,,
128.576,3.0787,8.44031,4.5,,,,,,,,,,,,,,,,,,,,,,,,,,,,,,,,,,,,,
129.376,2.94531,6.72381,4.5,,,,,,,,,,,,,,,,,,,,,,,,,,,,,,,,,,,,,
130.176,2.81208,5.42369,4.5,,,,,,,,,,,,,,,,,,,,,,,,,,,,,,,,,,,,,
130.976,2.67875,4.25204,4.5,,,,,,,,,,,,,,,,,,,,,,,,,,,,,,,,,,,,,
131.776,2.5453,3.14041,4.5,,,,,,,,,,,,,,,,,,,,,,,,,,,,,,,,,,,,,
132.576,2.41207,2.28447,4.5,,,,,,,,,,,,,,,,,,,,,,,,,,,,,,,,,,,,,
133.376,2.27868,1.42877,4.5,,,,,,,,,,,,,,,,,,,,,,,,,,,,,,,,,,,,,
133.896,2.22139,1.02394,5,,,,,,,,,,,,,,,,,,,,,,,,,,,,,,,,,,,,,
134.696,2.35966,2.43452,5,,,,,,,,,,,,,,,,,,,,,,,,,,,,,,,,,,,,,
135.496,2.49294,3.80675,5,,,,,,,,,,,,,,,,,,,,,,,,,,,,,,,,,,,,,
136.296,2.62644,5.14692,5,,,,,,,,,,,,,,,,,,,,,,,,,,,,,,,,,,,,,
137.096,2.75967,6.70449,5,,,,,,,,,,,,,,,,,,,,,,,,,,,,,,,,,,,,,
137.896,2.89295,8.45537,5,,,,,,,,,,,,,,,,,,,,,,,,,,,,,,,,,,,,,
138.696,3.02645,10.41609,5,,,,,,,,,,,,,,,,,,,,,,,,,,,,,,,,,,,,,
139.496,3.15962,12.54307,5,,,,,,,,,,,,,,,,,,,,,,,,,,,,,,,,,,,,,
140.296,3.29301,14.84039,5,,,,,,,,,,,,,,,,,,,,,,,,,,,,,,,,,,,,,
141.096,3.42646,17.42624,5,,,,,,,,,,,,,,,,,,,,,,,,,,,,,,,,,,,,,
141.896,3.55969,20.17965,5,,,,,,,,,,,,,,,,,,,,,,,,,,,,,,,,,,,,,
142.696,3.69302,23.17098,5,,,,,,,,,,,,,,,,,,,,,,,,,,,,,,,,,,,,,
143.496,3.82636,26.42492,5,,,,,,,,,,,,,,,,,,,,,,,,,,,,,,,,,,,,,
144.296,3.95958,30.44752,5,,,,,,,,,,,,,,,,,,,,,,,,,,,,,,,,,,,,,
145.096,4.09309,34.71566,5,,,,,,,,,,,,,,,,,,,,,,,,,,,,,,,,,,,,,
145.896,4.22637,39.14083,5,,,,,,,,,,,,,,,,,,,,,,,,,,,,,,,,,,,,,
146.552,4.1688,35.91761,5.5,,,,,,,,,,,,,,,,,,,,,,,,,,,,,,,,,,,,,
147.352,4.03546,30.22034,5.5,,,,,,,,,,,,,,,,,,,,,,,,,,,,,,,,,,,,,
148.152,3.90195,25.45336,5.5,,,,,,,,,,,,,,,,,,,,,,,,,,,,,,,,,,,,,
148.952,3.76867,21.31569,5.5,,,,,,,,,,,,,,,,,,,,,,,,,,,,,,,,,,,,,
149.752,3.63539,17.79859,5.5,,,,,,,,,,,,,,,,,,,,,,,,,,,,,,,,,,,,,
150.552,3.50206,14.75118,5.5,,,,,,,,,,,,,,,,,,,,,,,,,,,,,,,,,,,,,
151.352,3.36872,12.23841,5.5,,,,,,,,,,,,,,,,,,,,,,,,,,,,,,,,,,,,,
152.152,3.23533,10.01802,5.5,,,,,,,,,,,,,,,,,,,,,,,,,,,,,,,,,,,,,
152.952,3.10205,8.1125,5.5,,,,,,,,,,,,,,,,,,,,,,,,,,,,,,,,,,,,,
153.752,2.96877,6.54426,5.5,,,,,,,,,,,,,,,,,,,,,,,,,,,,,,,,,,,,,
154.552,2.83532,5.20284,5.5,,,,,,,,,,,,,,,,,,,,,,,,,,,,,,,,,,,,,
155.352,2.70204,4.01014,5.5,,,,,,,,,,,,,,,,,,,,,,,,,,,,,,,,,,,,,
156.152,2.56876,3.03275,5.5,,,,,,,,,,,,,,,,,,,,,,,,,,,,,,,,,,,,,
156.952,2.43525,2.03981,5.5,,,,,,,,,,,,,,,,,,,,,,,,,,,,,,,,,,,,,
157.752,2.30208,1.30335,5.5,,,,,,,,,,,,,,,,,,,,,,,,,,,,,,,,,,,,,
158.266,2.31721,1.52182,6,,,,,,,,,,,,,,,,,,,,,,,,,,,,,,,,,,,,,
159.066,2.45072,2.89304,6,,,,,,,,,,,,,,,,,,,,,,,,,,,,,,,,,,,,,
159.866,2.58406,4.2414,6,,,,,,,,,,,,,,,,,,,,,,,,,,,,,,,,,,,,,
160.666,2.71722,5.66045,6,,,,,,,,,,,,,,,,,,,,,,,,,,,,,,,,,,,,,
161.466,2.85079,7.26781,6,,,,,,,,,,,,,,,,,,,,,,,,,,,,,,,,,,,,,
162.266,2.98407,9.16601,6,,,,,,,,,,,,,,,,,,,,,,,,,,,,,,,,,,,,,
163.066,3.11729,11.24468,6,,,,,,,,,,,,,,,,,,,,,,,,,,,,,,,,,,,,,
163.866,3.25074,13.38826,6,,,,,,,,,,,,,,,,,,,,,,,,,,,,,,,,,,,,,
164.666,3.38408,15.78707,6,,,,,,,,,,,,,,,,,,,,,,,,,,,,,,,,,,,,,
165.466,3.51724,18.27885,6,,,,,,,,,,,,,,,,,,,,,,,,,,,,,,,,,,,,,
166.266,3.65081,21.05658,6,,,,,,,,,,,,,,,,,,,,,,,,,,,,,,,,,,,,,
167.066,3.78397,24.66042,6,,,,,,,,,,,,,,,,,,,,,,,,,,,,,,,,,,,,,
167.866,3.91731,27.96844,6,,,,,,,,,,,,,,,,,,,,,,,,,,,,,,,,,,,,,
168.666,4.05076,32.07133,6,,,,,,,,,,,,,,,,,,,,,,,,,,,,,,,,,,,,,
169.466,4.18398,36.46128,6,,,,,,,,,,,,,,,,,,,,,,,,,,,,,,,,,,,,,
170.102,4.29006,40.01027,6.5,,,,,,,,,,,,,,,,,,,,,,,,,,,,,,,,,,,,,
170.902,4.15639,33.71141,6.5,,,,,,,,,,,,,,,,,,,,,,,,,,,,,,,,,,,,,
171.702,4.02294,28.34155,6.5,,,,,,,,,,,,,,,,,,,,,,,,,,,,,,,,,,,,,
172.502,3.88971,23.82214,6.5,,,,,,,,,,,,,,,,,,,,,,,,,,,,,,,,,,,,,
173.302,3.75643,19.95112,6.5,,,,,,,,,,,,,,,,,,,,,,,,,,,,,,,,,,,,,
174.102,3.62298,16.62253,6.5,,,,,,,,,,,,,,,,,,,,,,,,,,,,,,,,,,,,,
174.902,3.48976,13.75754,6.5,,,,,,,,,,,,,,,,,,,,,,,,,,,,,,,,,,,,,
175.702,3.35642,11.28283,6.5,,,,,,,,,,,,,,,,,,,,,,,,,,,,,,,,,,,,,
176.502,3.22297,9.22212,6.5,,,,,,,,,,,,,,,,,,,,,,,,,,,,,,,,,,,,,
177.302,3.08975,7.52316,6.5,,,,,,,,,,,,,,,,,,,,,,,,,,,,,,,,,,,,,
178.102,2.95636,5.91068,6.5,,,,,,,,,,,,,,,,,,,,,,,,,,,,,,,,,,,,,
178.902,2.82302,4.62977,6.5,,,,,,,,,,,,,,,,,,,,,,,,,,,,,,,,,,,,,
179.702,2.68974,3.73026,6.5,,,,,,,,,,,,,,,,,,,,,,,,,,,,,,,,,,,,,
180.502,2.55629,2.72742,6.5,,,,,,,,,,,,,,,,,,,,,,,,,,,,,,,,,,,,,
181.302,2.42301,1.75727,6.5,,,,,,,,,,,,,,,,,,,,,,,,,,,,,,,,,,,,,
182.068,2.2954,0.99727,7,,,,,,,,,,,,,,,,,,,,,,,,,,,,,,,,,,,,,
182.672,2.3957,1.94768,7,,,,,,,,,,,,,,,,,,,,,,,,,,,,,,,,,,,,,
183.472,2.52903,3.25436,7,,,,,,,,,,,,,,,,,,,,,,,,,,,,,,,,,,,,,
184.272,2.66226,4.61836,7,,,,,,,,,,,,,,,,,,,,,,,,,,,,,,,,,,,,,
185.072,2.79576,6.15431,7,,,,,,,,,,,,,,,,,,,,,,,,,,,,,,,,,,,,,
185.872,2.92904,7.74628,7,,,,,,,,,,,,,,,,,,,,,,,,,,,,,,,,,,,,,
186.672,3.06227,9.70353,7,,,,,,,,,,,,,,,,,,,,,,,,,,,,,,,,,,,,,
187.472,3.19572,11.80835,7,,,,,,,,,,,,,,,,,,,,,,,,,,,,,,,,,,,,,
188.272,3.329,14.07264,7,,,,,,,,,,,,,,,,,,,,,,,,,,,,,,,,,,,,,
189.072,3.46228,16.53097,7,,,,,,,,,,,,,,,,,,,,,,,,,,,,,,,,,,,,,
189.872,3.59573,19.26909,7,,,,,,,,,,,,,,,,,,,,,,,,,,,,,,,,,,,,,
190.672,3.72901,22.09765,7,,,,,,,,,,,,,,,,,,,,,,,,,,,,,,,,,,,,,
191.472,3.86234,25.55427,7,,,,,,,,,,,,,,,,,,,,,,,,,,,,,,,,,,,,,
192.272,3.99574,29.30036,7,,,,,,,,,,,,,,,,,,,,,,,,,,,,,,,,,,,,,
193.072,4.12896,33.50403,7,,,,,,,,,,,,,,,,,,,,,,,,,,,,,,,,,,,,,
193.872,4.26241,38.0145,7,,,,,,,,,,,,,,,,,,,,,,,,,,,,,,,,,,,,,
194.534,4.2725,37.66798,7.5,,,,,,,,,,,,,,,,,,,,,,,,,,,,,,,,,,,,,
195.334,4.13899,31.64864,7.5,,,,,,,,,,,,,,,,,,,,,,,,,,,,,,,,,,,,,
196.134,4.00571,26.62554,7.5,,,,,,,,,,,,,,,,,,,,,,,,,,,,,,,,,,,,,
196.934,3.87249,22.32907,7.5,,,,,,,,,,,,,,,,,,,,,,,,,,,,,,,,,,,,,
197.734,3.73898,18.70911,7.5,,,,,,,,,,,,,,,,,,,,,,,,,,,,,,,,,,,,,
198.534,3.6057,15.46245,7.5,,,,,,,,,,,,,,,,,,,,,,,,,,,,,,,,,,,,,
199.334,3.47242,12.82346,7.5,,,,,,,,,,,,,,,,,,,,,,,,,,,,,,,,,,,,,
200.134,3.33891,10.54178,7.5,,,,,,,,,,,,,,,,,,,,,,,,,,,,,,,,,,,,,
200.934,3.20575,8.59971,7.5,,,,,,,,,,,,,,,,,,,,,,,,,,,,,,,,,,,,,
201.734,3.07247,6.90428,7.5,,,,,,,,,,,,,,,,,,,,,,,,,,,,,,,,,,,,,
202.534,2.93896,5.52877,7.5,,,,,,,,,,,,,,,,,,,,,,,,,,,,,,,,,,,,,
203.334,2.80574,4.33281,7.5,,,,,,,,,,,,,,,,,,,,,,,,,,,,,,,,,,,,,
204.134,2.6724,3.41309,7.5,,,,,,,,,,,,,,,,,,,,,,,,,,,,,,,,,,,,,
204.934,2.53901,2.31421,7.5,,,,,,,,,,,,,,,,,,,,,,,,,,,,,,,,,,,,,
205.734,2.40578,1.49355,7.5,,,,,,,,,,,,,,,,,,,,,,,,,,,,,,,,,,,,,
206.274,2.34481,0.99431,8,,,,,,,,,,,,,,,,,,,,,,,,,,,,,,,,,,,,,
207.074,2.4833,2.46484,8,,,,,,,,,,,,,,,,,,,,,,,,,,,,,,,,,,,,,
207.874,2.61675,3.87043,8,,,,,,,,,,,,,,,,,,,,,,,,,,,,,,,,,,,,,
208.674,2.74998,5.19706,8,,,,,,,,,,,,,,,,,,,,,,,,,,,,,,,,,,,,,
209.474,2.88331,6.74556,8,,,,,,,,,,,,,,,,,,,,,,,,,,,,,,,,,,,,,
210.274,3.01676,8.52362,8,,,,,,,,,,,,,,,,,,,,,,,,,,,,,,,,,,,,,
211.074,3.14999,10.52571,8,,,,,,,,,,,,,,,,,,,,,,,,,,,,,,,,,,,,,
211.874,3.28327,12.74514,8,,,,,,,,,,,,,,,,,,,,,,,,,,,,,,,,,,,,,
212.674,3.41683,15.04388,8,,,,,,,,,,,,,,,,,,,,,,,,,,,,,,,,,,,,,
213.474,3.55,17.63523,8,,,,,,,,,,,,,,,,,,,,,,,,,,,,,,,,,,,,,
214.274,3.68333,20.58333,8,,,,,,,,,,,,,,,,,,,,,,,,,,,,,,,,,,,,,
215.074,3.81678,23.55152,8,,,,,,,,,,,,,,,,,,,,,,,,,,,,,,,,,,,,,
215.874,3.94995,26.85429,8,,,,,,,,,,,,,,,,,,,,,,,,,,,,,,,,,,,,,
216.674,4.08329,31.04056,8,,,,,,,,,,,,,,,,,,,,,,,,,,,,,,,,,,,,,
217.474,4.21674,35.41017,8,,,,,,,,,,,,,,,,,,,,,,,,,,,,,,,,,,,,,
218.27,4.34928,40.00636,8.5,,,,,,,,,,,,,,,,,,,,,,,,,,,,,,,,,,,,,
218.972,4.23277,34.43208,8.5,,,,,,,,,,,,,,,,,,,,,,,,,,,,,,,,,,,,,
219.772,4.09949,28.95245,8.5,,,,,,,,,,,,,,,,,,,,,,,,,,,,,,,,,,,,,
220.572,3.96593,24.3577,8.5,,,,,,,,,,,,,,,,,,,,,,,,,,,,,,,,,,,,,
221.372,3.83271,20.41418,8.5,,,,,,,,,,,,,,,,,,,,,,,,,,,,,,,,,,,,,
222.172,3.69943,16.97752,8.5,,,,,,,,,,,,,,,,,,,,,,,,,,,,,,,,,,,,,
222.972,3.56592,14.08999,8.5,,,,,,,,,,,,,,,,,,,,,,,,,,,,,,,,,,,,,
223.772,3.43275,11.54199,8.5,,,,,,,,,,,,,,,,,,,,,,,,,,,,,,,,,,,,,
224.572,3.29942,9.49542,8.5,,,,,,,,,,,,,,,,,,,,,,,,,,,,,,,,,,,,,
225.372,3.16591,7.68197,8.5,,,,,,,,,,,,,,,,,,,,,,,,,,,,,,,,,,,,,
226.172,3.03274,6.04133,8.5,,,,,,,,,,,,,,,,,,,,,,,,,,,,,,,,,,,,,
226.972,2.89935,4.81149,8.5,,,,,,,,,,,,,,,,,,,,,,,,,,,,,,,,,,,,,
227.772,2.76601,3.62685,8.5,,,,,,,,,,,,,,,,,,,,,,,,,,,,,,,,,,,,,
228.572,2.63273,2.76608,8.5,,,,,,,,,,,,,,,,,,,,,,,,,,,,,,,,,,,,,
229.372,2.49928,1.80739,8.5,,,,,,,,,,,,,,,,,,,,,,,,,,,,,,,,,,,,,
230.144,2.37071,0.99904,9,,,,,,,,,,,,,,,,,,,,,,,,,,,,,,,,,,,,,
230.748,2.47095,2.01299,9,,,,,,,,,,,,,,,,,,,,,,,,,,,,,,,,,,,,,
231.548,2.60434,3.36536,9,,,,,,,,,,,,,,,,,,,,,,,,,,,,,,,,,,,,,
232.348,2.73779,4.79276,9,,,,,,,,,,,,,,,,,,,,,,,,,,,,,,,,,,,,,
233.148,2.87096,6.2865,9,,,,,,,,,,,,,,,,,,,,,,,,,,,,,,,,,,,,,
233.948,3.0043,7.92085,9,,,,,,,,,,,,,,,,,,,,,,,,,,,,,,,,,,,,,
234.748,3.13775,9.88929,9,,,,,,,,,,,,,,,,,,,,,,,,,,,,,,,,,,,,,
235.548,3.27091,12.02826,9,,,,,,,,,,,,,,,,,,,,,,,,,,,,,,,,,,,,,
236.348,3.40436,14.2636,9,,,,,,,,,,,,,,,,,,,,,,,,,,,,,,,,,,,,,
237.148,3.5377,16.8566,9,,,,,,,,,,,,,,,,,,,,,,,,,,,,,,,,,,,,,
237.948,3.67098,19.5961,9,,,,,,,,,,,,,,,,,,,,,,,,,,,,,,,,,,,,,
238.748,3.80437,22.47619,9,,,,,,,,,,,,,,,,,,,,,,,,,,,,,,,,,,,,,
239.548,3.93765,26.24226,9,,,,,,,,,,,,,,,,,,,,,,,,,,,,,,,,,,,,,
240.348,4.07099,29.7934,9,,,,,,,,,,,,,,,,,,,,,,,,,,,,,,,,,,,,,
241.148,4.20444,34.02835,9,,,,,,,,,,,,,,,,,,,,,,,,,,,,,,,,,,,,,
241.948,4.33761,38.73573,9,,,,,,,,,,,,,,,,,,,,,,,,,,,,,,,,,,,,,
242.578,4.30899,36.84719,9.5,,,,,,,,,,,,,,,,,,,,,,,,,,,,,,,,,,,,,
243.378,4.17582,30.98157,9.5,,,,,,,,,,,,,,,,,,,,,,,,,,,,,,,,,,,,,
244.178,4.04243,26.05706,9.5,,,,,,,,,,,,,,,,,,,,,,,,,,,,,,,,,,,,,
244.978,3.90887,21.83489,9.5,,,,,,,,,,,,,,,,,,,,,,,,,,,,,,,,,,,,,
245.778,3.77576,18.2282,9.5,,,,,,,,,,,,,,,,,,,,,,,,,,,,,,,,,,,,,
246.578,3.64242,15.17085,9.5,,,,,,,,,,,,,,,,,,,,,,,,,,,,,,,,,,,,,
247.378,3.50891,12.51762,9.5,,,,,,,,,,,,,,,,,,,,,,,,,,,,,,,,,,,,,
248.178,3.3758,10.18624,9.5,,,,,,,,,,,,,,,,,,,,,,,,,,,,,,,,,,,,,
248.978,3.24235,8.32611,9.5,,,,,,,,,,,,,,,,,,,,,,,,,,,,,,,,,,,,,
249.778,3.10902,6.56465,9.5,,,,,,,,,,,,,,,,,,,,,,,,,,,,,,,,,,,,,
250.578,2.97574,5.38329,9.5,,,,,,,,,,,,,,,,,,,,,,,,,,,,,,,,,,,,,
251.378,2.84234,4.03658,9.5,,,,,,,,,,,,,,,,,,,,,,,,,,,,,,,,,,,,,
252.178,2.70901,3.2233,9.5,,,,,,,,,,,,,,,,,,,,,,,,,,,,,,,,,,,,,
252.978,2.57573,2.12935,9.5,,,,,,,,,,,,,,,,,,,,,,,,,,,,,,,,,,,,,
253.778,2.44222,1.30357,9.5,,,,,,,,,,,,,,,,,,,,,,,,,,,,,,,,,,,,,
254.464,2.34005,0.60234,10,,,,,,,,,,,,,,,,,,,,,,,,,,,,,,,,,,,,,
255.264,2.32883,0.65176,10,,,,,,,,,,,,,,,,,,,,,,,,,,,,,,,,,,,,,
256.064,2.32996,0.74764,10,,,,,,,,,,,,,,,,,,,,,,,,,,,,,,,,,,,,,
256.864,2.33869,0.86724,10,,,,,,,,,,,,,,,,,,,,,,,,,,,,,,,,,,,,,
257.664,2.3643,1.15868,10,,,,,,,,,,,,,,,,,,,,,,,,,,,,,,,,,,,,,
258.464,2.36442,1.13487,10,,,,,,,,,,,,,,,,,,,,,,,,,,,,,,,,,,,,,
259.264,2.36396,1.13496,10,,,,,,,,,,,,,,,,,,,,,,,,,,,,,,,,,,,,,
260.064,2.35801,1.13299,10,,,,,,,,,,,,,,,,,,,,,,,,,,,,,,,,,,,,,
260.864,2.33863,0.94489,10,,,,,,,,,,,,,,,,,,,,,,,,,,,,,,,,,,,,,
261.664,2.33501,0.95965,10,,,,,,,,,,,,,,,,,,,,,,,,,,,,,,,,,,,,,
262.464,2.33427,1.00462,10,,,,,,,,,,,,,,,,,,,,,,,,,,,,,,,,,,,,,
263.264,2.33376,0.99507,10,,,,,,,,,,,,,,,,,,,,,,,,,,,,,,,,,,,,,
264.064,2.33246,0.96647,10,,,,,,,,,,,,,,,,,,,,,,,,,,,,,,,,,,,,,
264.864,2.33064,0.99639,10,,,,,,,,,,,,,,,,,,,,,,,,,,,,,,,,,,,,,
265.664,2.32826,0.93873,10,,,,,,,,,,,,,,,,,,,,,,,,,,,,,,,,,,,,,
266.464,2.32577,0.94637,10,,,,,,,,,,,,,,,,,,,,,,,,,,,,,,,,,,,,,
267.264,2.32362,0.97995,10,,,,,,,,,,,,,,,,,,,,,,,,,,,,,,,,,,,,,
268.064,2.32214,1.02395,10,,,,,,,,,,,,,,,,,,,,,,,,,,,,,,,,,,,,,
268.864,2.32112,0.99559,10,,,,,,,,,,,,,,,,,,,,,,,,,,,,,,,,,,,,,
269.664,2.3201,1.02572,10,,,,,,,,,,,,,,,,,,,,,,,,,,,,,,,,,,,,,
270.464,2.31914,1.00117,10,,,,,,,,,,,,,,,,,,,,,,,,,,,,,,,,,,,,,
271.264,2.31857,0.98491,10,,,,,,,,,,,,,,,,,,,,,,,,,,,,,,,,,,,,,
272.064,2.31806,0.96494,10,,,,,,,,,,,,,,,,,,,,,,,,,,,,,,,,,,,,,
272.864,2.3171,0.93505,10,,,,,,,,,,,,,,,,,,,,,,,,,,,,,,,,,,,,,
273.664,2.31574,0.96985,10,,,,,,,,,,,,,,,,,,,,,,,,,,,,,,,,,,,,,
274.464,2.31438,1.00381,10,,,,,,,,,,,,,,,,,,,,,,,,,,,,,,,,,,,,,
275.264,2.31296,0.95385,10,,,,,,,,,,,,,,,,,,,,,,,,,,,,,,,,,,,,,
276.064,2.31166,0.92286,10,,,,,,,,,,,,,,,,,,,,,,,,,,,,,,,,,,,,,
276.864,2.31053,0.98228,10,,,,,,,,,,,,,,,,,,,,,,,,,,,,,,,,,,,,,
277.664,2.30979,0.96339,10,,,,,,,,,,,,,,,,,,,,,,,,,,,,,,,,,,,,,
278.464,2.30888,1.0463,10,,,,,,,,,,,,,,,,,,,,,,,,,,,,,,,,,,,,,
279.264,2.30798,0.98963,10,,,,,,,,,,,,,,,,,,,,,,,,,,,,,,,,,,,,,
280.064,2.30645,0.93393,10,,,,,,,,,,,,,,,,,,,,,,,,,,,,,,,,,,,,,
280.864,2.30475,0.94152,10,,,,,,,,,,,,,,,,,,,,,,,,,,,,,,,,,,,,,
281.664,2.3039,0.93848,10,,,,,,,,,,,,,,,,,,,,,,,,,,,,,,,,,,,,,
282.464,2.30344,0.99931,10,,,,,,,,,,,,,,,,,,,,,,,,,,,,,,,,,,,,,
283.264,2.30316,0.93553,10,,,,,,,,,,,,,,,,,,,,,,,,,,,,,,,,,,,,,
284.064,2.30299,0.9989,10,,,,,,,,,,,,,,,,,,,,,,,,,,,,,,,,,,,,,
284.864,2.30276,0.9986,10,,,,,,,,,,,,,,,,,,,,,,,,,,,,,,,,,,,,,
285.664,2.30248,0.94521,10,,,,,,,,,,,,,,,,,,,,,,,,,,,,,,,,,,,,,
286.464,2.30214,1.04731,10,,,,,,,,,,,,,,,,,,,,,,,,,,,,,,,,,,,,,
287.264,2.30169,0.97484,10,,,,,,,,,,,,,,,,,,,,,,,,,,,,,,,,,,,,,
288.064,2.30061,0.99651,10,,,,,,,,,,,,,,,,,,,,,,,,,,,,,,,,,,,,,
288.864,2.29942,0.97369,10,,,,,,,,,,,,,,,,,,,,,,,,,,,,,,,,,,,,,
289.664,2.29778,0.92618,10,,,,,,,,,,,,,,,,,,,,,,,,,,,,,,,,,,,,,
290.464,2.29653,0.91551,10,,,,,,,,,,,,,,,,,,,,,,,,,,,,,,,,,,,,,
291.264,2.29579,1.00618,10,,,,,,,,,,,,,,,,,,,,,,,,,,,,,,,,,,,,,
292.064,2.29557,0.95777,10,,,,,,,,,,,,,,,,,,,,,,,,,,,,,,,,,,,,,
292.864,2.29545,0.93037,10,,,,,,,,,,,,,,,,,,,,,,,,,,,,,,,,,,,,,
293.664,2.2954,0.94029,10,,,,,,,,,,,,,,,,,,,,,,,,,,,,,,,,,,,,,
294.464,2.29551,0.94237,10,,,,,,,,,,,,,,,,,,,,,,,,,,,,,,,,,,,,,
295.264,2.29557,0.92831,10,,,,,,,,,,,,,,,,,,,,,,,,,,,,,,,,,,,,,
296.064,2.29557,0.96275,10,,,,,,,,,,,,,,,,,,,,,,,,,,,,,,,,,,,,,
296.864,2.29557,0.96118,10,,,,,,,,,,,,,,,,,,,,,,,,,,,,,,,,,,,,,
297.664,2.29557,0.98744,10,,,,,,,,,,,,,,,,,,,,,,,,,,,,,,,,,,,,,
298.464,2.29551,0.95905,10,,,,,,,,,,,,,,,,,,,,,,,,,,,,,,,,,,,,,
299.264,2.29551,0.93319,10,,,,,,,,,,,,,,,,,,,,,,,,,,,,,,,,,,,,,
300.064,2.29545,1.00373,10,,,,,,,,,,,,,,,,,,,,,,,,,,,,,,,,,,,,,
300.864,2.29545,1.05398,10,,,,,,,,,,,,,,,,,,,,,,,,,,,,,,,,,,,,,
301.664,2.2954,0.97377,10,,,,,,,,,,,,,,,,,,,,,,,,,,,,,,,,,,,,,
302.464,2.2954,0.95396,10,,,,,,,,,,,,,,,,,,,,,,,,,,,,,,,,,,,,,
303.264,2.29523,1.03637,10,,,,,,,,,,,,,,,,,,,,,,,,,,,,,,,,,,,,,
304.064,2.29421,1.01812,10,,,,,,,,,,,,,,,,,,,,,,,,,,,,,,,,,,,,,
304.864,2.2903,0.9693,10,,,,,,,,,,,,,,,,,,,,,,,,,,,,,,,,,,,,,
305.664,2.28582,0.96527,10,,,,,,,,,,,,,,,,,,,,,,,,,,,,,,,,,,,,,
306.464,2.2831,0.90838,10,,,,,,,,,,,,,,,,,,,,,,,,,,,,,,,,,,,,,
307.264,2.28248,0.93319,10,,,,,,,,,,,,,,,,,,,,,,,,,,,,,,,,,,,,,
308.064,2.28253,0.87872,10,,,,,,,,,,,,,,,,,,,,,,,,,,,,,,,,,,,,,
308.864,2.28265,0.93359,10,,,,,,,,,,,,,,,,,,,,,,,,,,,,,,,,,,,,,
309.664,2.28276,0.9343,10,,,,,,,,,,,,,,,,,,,,,,,,,,,,,,,,,,,,,
310.464,2.28293,0.91686,10,,,,,,,,,,,,,,,,,,,,,,,,,,,,,,,,,,,,,
311.264,2.28304,0.94506,10,,,,,,,,,,,,,,,,,,,,,,,,,,,,,,,,,,,,,
312.064,2.2831,0.97362,10,,,,,,,,,,,,,,,,,,,,,,,,,,,,,,,,,,,,,
312.864,2.2831,1.00835,10,,,,,,,,,,,,,,,,,,,,,,,,,,,,,,,,,,,,,
313.664,2.28321,0.94067,10,,,,,,,,,,,,,,,,,,,,,,,,,,,,,,,,,,,,,
314.464,2.28327,0.94984,10,,,,,,,,,,,,,,,,,,,,,,,,,,,,,,,,,,,,,
315.264,2.28338,0.99046,10,,,,,,,,,,,,,,,,,,,,,,,,,,,,,,,,,,,,,
316.064,2.28344,0.98297,10,,,,,,,,,,,,,,,,,,,,,,,,,,,,,,,,,,,,,
316.864,2.28344,0.98325,10,,,,,,,,,,,,,,,,,,,,,,,,,,,,,,,,,,,,,
317.664,2.28344,1.01884,10,,,,,,,,,,,,,,,,,,,,,,,,,,,,,,,,,,,,,
318.464,2.28344,0.95387,10,,,,,,,,,,,,,,,,,,,,,,,,,,,,,,,,,,,,,
319.264,2.28333,0.97898,10,,,,,,,,,,,,,,,,,,,,,,,,,,,,,,,,,,,,,
320.064,2.28333,1.00624,10,,,,,,,,,,,,,,,,,,,,,,,,,,,,,,,,,,,,,
320.864,2.28344,0.95903,10,,,,,,,,,,,,,,,,,,,,,,,,,,,,,,,,,,,,,
321.664,2.28333,0.95939,10,,,,,,,,,,,,,,,,,,,,,,,,,,,,,,,,,,,,,
322.464,2.28333,0.96809,10,,,,,,,,,,,,,,,,,,,,,,,,,,,,,,,,,,,,,
323.264,2.28333,0.99939,10,,,,,,,,,,,,,,,,,,,,,,,,,,,,,,,,,,,,,
324.064,2.28333,0.94942,10,,,,,,,,,,,,,,,,,,,,,,,,,,,,,,,,,,,,,
324.864,2.28338,1.0176,10,,,,,,,,,,,,,,,,,,,,,,,,,,,,,,,,,,,,,
325.664,2.28338,0.94424,10,,,,,,,,,,,,,,,,,,,,,,,,,,,,,,,,,,,,,
326.464,2.28338,0.97048,10,,,,,,,,,,,,,,,,,,,,,,,,,,,,,,,,,,,,,
327.264,2.28338,0.90757,10,,,,,,,,,,,,,,,,,,,,,,,,,,,,,,,,,,,,,
328.064,2.28338,0.97122,10,,,,,,,,,,,,,,,,,,,,,,,,,,,,,,,,,,,,,
328.864,2.28327,0.97318,10,,,,,,,,,,,,,,,,,,,,,,,,,,,,,,,,,,,,,
329.664,2.28333,0.97572,10,,,,,,,,,,,,,,,,,,,,,,,,,,,,,,,,,,,,,
330.464,2.28333,0.96977,10,,,,,,,,,,,,,,,,,,,,,,,,,,,,,,,,,,,,,
331.264,2.28333,0.96072,10,,,,,,,,,,,,,,,,,,,,,,,,,,,,,,,,,,,,,
332.064,2.28321,0.96311,10,,,,,,,,,,,,,,,,,,,,,,,,,,,,,,,,,,,,,
332.864,2.28316,0.99429,10,,,,,,,,,,,,,,,,,,,,,,,,,,,,,,,,,,,,,
333.664,2.2831,0.98007,10,,,,,,,,,,,,,,,,,,,,,,,,,,,,,,,,,,,,,
334.464,2.28304,1.01802,10,,,,,,,,,,,,,,,,,,,,,,,,,,,,,,,,,,,,,
335.264,2.28282,0.98921,10,,,,,,,,,,,,,,,,,,,,,,,,,,,,,,,,,,,,,
336.064,2.28259,1.0401,10,,,,,,,,,,,,,,,,,,,,,,,,,,,,,,,,,,,,,
336.864,2.28219,0.99639,10,,,,,,,,,,,,,,,,,,,,,,,,,,,,,,,,,,,,,
337.664,2.281,1.00643,10,,,,,,,,,,,,,,,,,,,,,,,,,,,,,,,,,,,,,
338.464,2.27687,1.02027,10,,,,,,,,,,,,,,,,,,,,,,,,,,,,,,,,,,,,,
339.264,2.27216,0.92474,10,,,,,,,,,,,,,,,,,,,,,,,,,,,,,,,,,,,,,
340.064,2.2716,0.92845,10,,,,,,,,,,,,,,,,,,,,,,,,,,,,,,,,,,,,,
340.864,2.27148,0.91699,10,,,,,,,,,,,,,,,,,,,,,,,,,,,,,,,,,,,,,
341.664,2.27165,0.88336,10,,,,,,,,,,,,,,,,,,,,,,,,,,,,,,,,,,,,,
342.464,2.27171,0.89809,10,,,,,,,,,,,,,,,,,,,,,,,,,,,,,,,,,,,,,
343.264,2.27182,0.97695,10,,,,,,,,,,,,,,,,,,,,,,,,,,,,,,,,,,,,,
344.064,2.27194,0.93528,10,,,,,,,,,,,,,,,,,,,,,,,,,,,,,,,,,,,,,
344.864,2.27205,0.92561,10,,,,,,,,,,,,,,,,,,,,,,,,,,,,,,,,,,,,,
345.664,2.27211,0.95698,10,,,,,,,,,,,,,,,,,,,,,,,,,,,,,,,,,,,,,
346.464,2.27216,0.97384,10,,,,,,,,,,,,,,,,,,,,,,,,,,,,,,,,,,,,,
347.264,2.27216,0.93924,10,,,,,,,,,,,,,,,,,,,,,,,,,,,,,,,,,,,,,
348.064,2.27222,0.95866,10,,,,,,,,,,,,,,,,,,,,,,,,,,,,,,,,,,,,,
348.864,2.27228,0.98628,10,,,,,,,,,,,,,,,,,,,,,,,,,,,,,,,,,,,,,
349.664,2.27228,1.05857,10,,,,,,,,,,,,,,,,,,,,,,,,,,,,,,,,,,,,,
350.464,2.27228,0.98575,10,,,,,,,,,,,,,,,,,,,,,,,,,,,,,,,,,,,,,
351.264,2.27228,0.95068,10,,,,,,,,,,,,,,,,,,,,,,,,,,,,,,,,,,,,,
352.064,2.27228,0.92886,10,,,,,,,,,,,,,,,,,,,,,,,,,,,,,,,,,,,,,
352.864,2.27228,0.98996,10,,,,,,,,,,,,,,,,,,,,,,,,,,,,,,,,,,,,,
353.664,2.27228,0.99424,10,,,,,,,,,,,,,,,,,,,,,,,,,,,,,,,,,,,,,
354.464,2.27228,0.95888,10,,,,,,,,,,,,,,,,,,,,,,,,,,,,,,,,,,,,,
355.264,2.27228,0.97076,10,,,,,,,,,,,,,,,,,,,,,,,,,,,,,,,,,,,,,
356.064,2.27228,0.97453,10,,,,,,,,,,,,,,,,,,,,,,,,,,,,,,,,,,,,,
356.864,2.27216,0.95841,10,,,,,,,,,,,,,,,,,,,,,,,,,,,,,,,,,,,,,
357.664,2.27216,0.9866,10,,,,,,,,,,,,,,,,,,,,,,,,,,,,,,,,,,,,,
358.464,2.27211,0.99737,10,,,,,,,,,,,,,,,,,,,,,,,,,,,,,,,,,,,,,
359.264,2.27216,0.91708,10,,,,,,,,,,,,,,,,,,,,,,,,,,,,,,,,,,,,,
360.064,2.27216,0.93969,10,,,,,,,,,,,,,,,,,,,,,,,,,,,,,,,,,,,,,
360.864,2.27205,0.96034,10,,,,,,,,,,,,,,,,,,,,,,,,,,,,,,,,,,,,,
361.664,2.27199,0.96175,10,,,,,,,,,,,,,,,,,,,,,,,,,,,,,,,,,,,,,
362.464,2.27205,0.98896,10,,,,,,,,,,,,,,,,,,,,,,,,,,,,,,,,,,,,,
363.264,2.27188,0.96431,10,,,,,,,,,,,,,,,,,,,,,,,,,,,,,,,,,,,,,
364.064,2.27177,0.96966,10,,,,,,,,,,,,,,,,,,,,,,,,,,,,,,,,,,,,,
364.864,2.27165,1.04235,10,,,,,,,,,,,,,,,,,,,,,,,,,,,,,,,,,,,,,
365.664,2.27154,1.01949,10,,,,,,,,,,,,,,,,,,,,,,,,,,,,,,,,,,,,,
366.464,2.27137,1.00458,10,,,,,,,,,,,,,,,,,,,,,,,,,,,,,,,,,,,,,
367.264,2.27092,1.01869,10,,,,,,,,,,,,,,,,,,,,,,,,,,,,,,,,,,,,,
368.064,2.26973,0.98055,10,,,,,,,,,,,,,,,,,,,,,,,,,,,,,,,,,,,,,
368.864,2.26757,0.9617,10,,,,,,,,,,,,,,,,,,,,,,,,,,,,,,,,,,,,,
369.664,2.26519,0.96067,10,,,,,,,,,,,,,,,,,,,,,,,,,,,,,,,,,,,,,
370.464,2.26417,0.96917,10,,,,,,,,,,,,,,,,,,,,,,,,,,,,,,,,,,,,,
371.264,2.26338,0.931,10,,,,,,,,,,,,,,,,,,,,,,,,,,,,,,,,,,,,,
372.064,2.26298,0.98694,10,,,,,,,,,,,,,,,,,,,,,,,,,,,,,,,,,,,,,
372.864,2.26281,0.99903,10,,,,,,,,,,,,,,,,,,,,,,,,,,,,,,,,,,,,,
373.664,2.26287,0.98542,10,,,,,,,,,,,,,,,,,,,,,,,,,,,,,,,,,,,,,
374.464,2.26293,0.87751,10,,,,,,,,,,,,,,,,,,,,,,,,,,,,,,,,,,,,,
375.264,2.26298,0.92544,10,,,,,,,,,,,,,,,,,,,,,,,,,,,,,,,,,,,,,
376.064,2.26304,0.94479,10,,,,,,,,,,,,,,,,,,,,,,,,,,,,,,,,,,,,,
376.864,2.26304,0.94835,10,,,,,,,,,,,,,,,,,,,,,,,,,,,,,,,,,,,,,
377.664,2.26315,1.0272,10,,,,,,,,,,,,,,,,,,,,,,,,,,,,,,,,,,,,,
378.464,2.26321,0.9086,10,,,,,,,,,,,,,,,,,,,,,,,,,,,,,,,,,,,,,
379.264,2.26338,0.95765,10,,,,,,,,,,,,,,,,,,,,,,,,,,,,,,,,,,,,,
380.064,2.26344,0.97655,10,,,,,,,,,,,,,,,,,,,,,,,,,,,,,,,,,,,,,
380.864,2.26349,0.9808,10,,,,,,,,,,,,,,,,,,,,,,,,,,,,,,,,,,,,,
381.664,2.26361,1.06014,10,,,,,,,,,,,,,,,,,,,,,,,,,,,,,,,,,,,,,
382.464,2.26366,1.00867,10,,,,,,,,,,,,,,,,,,,,,,,,,,,,,,,,,,,,,
383.264,2.26372,0.98998,10,,,,,,,,,,,,,,,,,,,,,,,,,,,,,,,,,,,,,
384.064,2.26372,0.94642,10,,,,,,,,,,,,,,,,,,,,,,,,,,,,,,,,,,,,,
384.864,2.26378,1.00155,10,,,,,,,,,,,,,,,,,,,,,,,,,,,,,,,,,,,,,
385.664,2.26378,1.05609,10,,,,,,,,,,,,,,,,,,,,,,,,,,,,,,,,,,,,,
386.464,2.26378,0.9908,10,,,,,,,,,,,,,,,,,,,,,,,,,,,,,,,,,,,,,
387.264,2.26378,0.99827,10,,,,,,,,,,,,,,,,,,,,,,,,,,,,,,,,,,,,,
388.064,2.26378,0.96784,10,,,,,,,,,,,,,,,,,,,,,,,,,,,,,,,,,,,,,
388.864,2.26378,0.9488,10,,,,,,,,,,,,,,,,,,,,,,,,,,,,,,,,,,,,,
389.664,2.26378,1.01985,10,,,,,,,,,,,,,,,,,,,,,,,,,,,,,,,,,,,,,
390.464,2.26378,1.02355,10,,,,,,,,,,,,,,,,,,,,,,,,,,,,,,,,,,,,,
391.264,2.26378,0.98511,10,,,,,,,,,,,,,,,,,,,,,,,,,,,,,,,,,,,,,
392.064,2.26378,0.98665,10,,,,,,,,,,,,,,,,,,,,,,,,,,,,,,,,,,,,,
392.864,2.26378,0.95124,10,,,,,,,,,,,,,,,,,,,,,,,,,,,,,,,,,,,,,
393.664,2.26378,0.96297,10,,,,,,,,,,,,,,,,,,,,,,,,,,,,,,,,,,,,,
394.464,2.26366,0.99539,10,,,,,,,,,,,,,,,,,,,,,,,,,,,,,,,,,,,,,
395.264,2.26366,0.94534,10,,,,,,,,,,,,,,,,,,,,,,,,,,,,,,,,,,,,,
396.064,2.26366,0.96937,10,,,,,,,,,,,,,,,,,,,,,,,,,,,,,,,,,,,,,
396.864,2.26372,1.02601,10,,,,,,,,,,,,,,,,,,,,,,,,,,,,,,,,,,,,,
397.664,2.26372,0.96562,10,,,,,,,,,,,,,,,,,,,,,,,,,,,,,,,,,,,,,
398.464,2.26372,0.94109,10,,,,,,,,,,,,,,,,,,,,,,,,,,,,,,,,,,,,,
399.264,2.26372,0.96921,10,,,,,,,,,,,,,,,,,,,,,,,,,,,,,,,,,,,,,
400.064,2.26372,0.95886,10,,,,,,,,,,,,,,,,,,,,,,,,,,,,,,,,,,,,,
400.864,2.26372,0.95044,10,,,,,,,,,,,,,,,,,,,,,,,,,,,,,,,,,,,,,
401.664,2.26372,1.00545,10,,,,,,,,,,,,,,,,,,,,,,,,,,,,,,,,,,,,,
402.464,2.26372,1.01198,10,,,,,,,,,,,,,,,,,,,,,,,,,,,,,,,,,,,,,
403.264,2.26372,1.00197,10,,,,,,,,,,,,,,,,,,,,,,,,,,,,,,,,,,,,,
404.064,2.26372,0.93104,10,,,,,,,,,,,,,,,,,,,,,,,,,,,,,,,,,,,,,
404.864,2.26372,0.94433,10,,,,,,,,,,,,,,,,,,,,,,,,,,,,,,,,,,,,,
405.664,2.26372,0.97122,10,,,,,,,,,,,,,,,,,,,,,,,,,,,,,,,,,,,,,
406.464,2.26372,0.99325,10,,,,,,,,,,,,,,,,,,,,,,,,,,,,,,,,,,,,,
407.264,2.26372,0.925,10,,,,,,,,,,,,,,,,,,,,,,,,,,,,,,,,,,,,,
408.064,2.26372,0.95806,10,,,,,,,,,,,,,,,,,,,,,,,,,,,,,,,,,,,,,
408.864,2.26366,1.04512,10,,,,,,,,,,,,,,,,,,,,,,,,,,,,,,,,,,,,,
409.664,2.26372,0.97624,10,,,,,,,,,,,,,,,,,,,,,,,,,,,,,,,,,,,,,
410.464,2.26372,0.92988,10,,,,,,,,,,,,,,,,,,,,,,,,,,,,,,,,,,,,,
411.264,2.26372,0.96895,10,,,,,,,,,,,,,,,,,,,,,,,,,,,,,,,,,,,,,
412.064,2.26361,0.94196,10,,,,,,,,,,,,,,,,,,,,,,,,,,,,,,,,,,,,,
412.864,2.26372,0.94632,10,,,,,,,,,,,,,,,,,,,,,,,,,,,,,,,,,,,,,
413.664,2.26372,0.97632,10,,,,,,,,,,,,,,,,,,,,,,,,,,,,,,,,,,,,,
414.464,2.26372,0.96233,10,,,,,,,,,,,,,,,,,,,,,,,,,,,,,,,,,,,,,
415.264,2.26372,0.95572,10,,,,,,,,,,,,,,,,,,,,,,,,,,,,,,,,,,,,,
416.064,2.26372,0.98961,10,,,,,,,,,,,,,,,,,,,,,,,,,,,,,,,,,,,,,
416.864,2.26372,0.98364,10,,,,,,,,,,,,,,,,,,,,,,,,,,,,,,,,,,,,,
417.664,2.26372,0.98073,10,,,,,,,,,,,,,,,,,,,,,,,,,,,,,,,,,,,,,
418.464,2.26372,0.9928,10,,,,,,,,,,,,,,,,,,,,,,,,,,,,,,,,,,,,,
419.264,2.26372,0.96045,10,,,,,,,,,,,,,,,,,,,,,,,,,,,,,,,,,,,,,
420.064,2.26372,0.95511,10,,,,,,,,,,,,,,,,,,,,,,,,,,,,,,,,,,,,,
420.864,2.26372,1.03833,10,,,,,,,,,,,,,,,,,,,,,,,,,,,,,,,,,,,,,
421.664,2.26372,0.94164,10,,,,,,,,,,,,,,,,,,,,,,,,,,,,,,,,,,,,,
422.464,2.26366,0.97267,10,,,,,,,,,,,,,,,,,,,,,,,,,,,,,,,,,,,,,
423.264,2.26366,0.95974,10,,,,,,,,,,,,,,,,,,,,,,,,,,,,,,,,,,,,,
424.064,2.26366,0.94663,10,,,,,,,,,,,,,,,,,,,,,,,,,,,,,,,,,,,,,
424.864,2.26355,1.01023,10,,,,,,,,,,,,,,,,,,,,,,,,,,,,,,,,,,,,,
425.664,2.26355,0.99288,10,,,,,,,,,,,,,,,,,,,,,,,,,,,,,,,,,,,,,
426.464,2.26355,0.90003,10,,,,,,,,,,,,,,,,,,,,,,,,,,,,,,,,,,,,,
427.264,2.26361,1.00873,10,,,,,,,,,,,,,,,,,,,,,,,,,,,,,,,,,,,,,
428.064,2.26349,0.99862,10,,,,,,,,,,,,,,,,,,,,,,,,,,,,,,,,,,,,,
428.864,2.26361,0.95085,10,,,,,,,,,,,,,,,,,,,,,,,,,,,,,,,,,,,,,
429.664,2.26361,0.94522,10,,,,,,,,,,,,,,,,,,,,,,,,,,,,,,,,,,,,,
430.464,2.26361,0.95898,10,,,,,,,,,,,,,,,,,,,,,,,,,,,,,,,,,,,,,
431.264,2.26355,1.07057,10,,,,,,,,,,,,,,,,,,,,,,,,,,,,,,,,,,,,,
432.064,2.26349,0.95831,10,,,,,,,,,,,,,,,,,,,,,,,,,,,,,,,,,,,,,
432.864,2.26349,0.96757,10,,,,,,,,,,,,,,,,,,,,,,,,,,,,,,,,,,,,,
433.664,2.26361,0.92488,10,,,,,,,,,,,,,,,,,,,,,,,,,,,,,,,,,,,,,
434.464,2.26355,0.96127,10,,,,,,,,,,,,,,,,,,,,,,,,,,,,,,,,,,,,,
435.264,2.26355,0.98163,10,,,,,,,,,,,,,,,,,,,,,,,,,,,,,,,,,,,,,
436.064,2.26355,0.98112,10,,,,,,,,,,,,,,,,,,,,,,,,,,,,,,,,,,,,,
436.864,2.26349,0.96745,10,,,,,,,,,,,,,,,,,,,,,,,,,,,,,,,,,,,,,
437.664,2.26349,0.99303,10,,,,,,,,,,,,,,,,,,,,,,,,,,,,,,,,,,,,,
438.464,2.26349,0.93137,10,,,,,,,,,,,,,,,,,,,,,,,,,,,,,,,,,,,,,
439.264,2.26338,0.99298,10,,,,,,,,,,,,,,,,,,,,,,,,,,,,,,,,,,,,,
440.064,2.26332,1.00853,10,,,,,,,,,,,,,,,,,,,,,,,,,,,,,,,,,,,,,
440.864,2.26327,0.95273,10,,,,,,,,,,,,,,,,,,,,,,,,,,,,,,,,,,,,,
441.664,2.26321,0.94013,10,,,,,,,,,,,,,,,,,,,,,,,,,,,,,,,,,,,,,
442.464,2.26315,0.97824,10,,,,,,,,,,,,,,,,,,,,,,,,,,,,,,,,,,,,,
443.264,2.26304,1.00635,10,,,,,,,,,,,,,,,,,,,,,,,,,,,,,,,,,,,,,
444.064,2.26281,0.97946,10,,,,,,,,,,,,,,,,,,,,,,,,,,,,,,,,,,,,,
444.864,2.26253,1.02418,10,,,,,,,,,,,,,,,,,,,,,,,,,,,,,,,,,,,,,
445.664,2.26191,0.98073,10,,,,,,,,,,,,,,,,,,,,,,,,,,,,,,,,,,,,,
446.464,2.26026,0.96603,10,,,,,,,,,,,,,,,,,,,,,,,,,,,,,,,,,,,,,
447.264,2.25839,0.95784,10,,,,,,,,,,,,,,,,,,,,,,,,,,,,,,,,,,,,,
448.064,2.25743,0.93685,10,,,,,,,,,,,,,,,,,,,,,,,,,,,,,,,,,,,,,
448.864,2.2572,0.89622,10,,,,,,,,,,,,,,,,,,,,,,,,,,,,,,,,,,,,,
449.664,2.25726,0.96891,10,,,,,,,,,,,,,,,,,,,,,,,,,,,,,,,,,,,,,
450.464,2.25732,0.90847,10,,,,,,,,,,,,,,,,,,,,,,,,,,,,,,,,,,,,,
451.264,2.25737,0.9775,10,,,,,,,,,,,,,,,,,,,,,,,,,,,,,,,,,,,,,
452.064,2.25749,0.91684,10,,,,,,,,,,,,,,,,,,,,,,,,,,,,,,,,,,,,,
452.864,2.2576,0.88219,10,,,,,,,,,,,,,,,,,,,,,,,,,,,,,,,,,,,,,
453.664,2.25771,0.91205,10,,,,,,,,,,,,,,,,,,,,,,,,,,,,,,,,,,,,,
454.464,2.25777,0.98063,10,,,,,,,,,,,,,,,,,,,,,,,,,,,,,,,,,,,,,
455.264,2.25788,0.92975,10,,,,,,,,,,,,,,,,,,,,,,,,,,,,,,,,,,,,,
456.064,2.25794,0.97757,10,,,,,,,,,,,,,,,,,,,,,,,,,,,,,,,,,,,,,
456.864,2.258,0.96221,10,,,,,,,,,,,,,,,,,,,,,,,,,,,,,,,,,,,,,
457.664,2.25811,0.91641,10,,,,,,,,,,,,,,,,,,,,,,,,,,,,,,,,,,,,,
458.464,2.25817,0.97001,10,,,,,,,,,,,,,,,,,,,,,,,,,,,,,,,,,,,,,
459.264,2.25822,0.99823,10,,,,,,,,,,,,,,,,,,,,,,,,,,,,,,,,,,,,,
460.064,2.25822,0.97647,10,,,,,,,,,,,,,,,,,,,,,,,,,,,,,,,,,,,,,
460.864,2.25822,0.94729,10,,,,,,,,,,,,,,,,,,,,,,,,,,,,,,,,,,,,,
461.664,2.25828,1.00151,10,,,,,,,,,,,,,,,,,,,,,,,,,,,,,,,,,,,,,
462.464,2.25828,0.94184,10,,,,,,,,,,,,,,,,,,,,,,,,,,,,,,,,,,,,,
463.264,2.25834,0.98572,10,,,,,,,,,,,,,,,,,,,,,,,,,,,,,,,,,,,,,
464.064,2.25834,0.95904,10,,,,,,,,,,,,,,,,,,,,,,,,,,,,,,,,,,,,,
464.864,2.25839,0.95125,10,,,,,,,,,,,,,,,,,,,,,,,,,,,,,,,,,,,,,
465.664,2.25839,0.95782,10,,,,,,,,,,,,,,,,,,,,,,,,,,,,,,,,,,,,,
466.464,2.25839,0.98774,10,,,,,,,,,,,,,,,,,,,,,,,,,,,,,,,,,,,,,
467.264,2.25839,0.96436,10,,,,,,,,,,,,,,,,,,,,,,,,,,,,,,,,,,,,,
468.064,2.25839,0.96372,10,,,,,,,,,,,,,,,,,,,,,,,,,,,,,,,,,,,,,
468.864,2.25839,1.01801,10,,,,,,,,,,,,,,,,,,,,,,,,,,,,,,,,,,,,,
469.664,2.25839,0.98975,10,,,,,,,,,,,,,,,,,,,,,,,,,,,,,,,,,,,,,
470.464,2.25839,0.9572,10,,,,,,,,,,,,,,,,,,,,,,,,,,,,,,,,,,,,,
471.264,2.25839,1.00888,10,,,,,,,,,,,,,,,,,,,,,,,,,,,,,,,,,,,,,
472.064,2.25834,0.90646,10,,,,,,,,,,,,,,,,,,,,,,,,,,,,,,,,,,,,,
472.864,2.25834,1.05446,10,,,,,,,,,,,,,,,,,,,,,,,,,,,,,,,,,,,,,
473.664,2.25834,0.99735,10,,,,,,,,,,,,,,,,,,,,,,,,,,,,,,,,,,,,,
474.464,2.25834,0.95771,10,,,,,,,,,,,,,,,,,,,,,,,,,,,,,,,,,,,,,
475.264,2.25845,0.95197,10,,,,,,,,,,,,,,,,,,,,,,,,,,,,,,,,,,,,,
476.064,2.25845,0.98251,10,,,,,,,,,,,,,,,,,,,,,,,,,,,,,,,,,,,,,
476.864,2.25845,1.07834,10,,,,,,,,,,,,,,,,,,,,,,,,,,,,,,,,,,,,,
477.664,2.25845,0.96731,10,,,,,,,,,,,,,,,,,,,,,,,,,,,,,,,,,,,,,
478.464,2.25839,1.00485,10,,,,,,,,,,,,,,,,,,,,,,,,,,,,,,,,,,,,,
479.264,2.25845,0.95888,10,,,,,,,,,,,,,,,,,,,,,,,,,,,,,,,,,,,,,
480.064,2.25845,0.94784,10,,,,,,,,,,,,,,,,,,,,,,,,,,,,,,,,,,,,,
480.864,2.25845,1.07756,10,,,,,,,,,,,,,,,,,,,,,,,,,,,,,,,,,,,,,
481.664,2.25834,0.97712,10,,,,,,,,,,,,,,,,,,,,,,,,,,,,,,,,,,,,,
482.464,2.25834,0.95515,10,,,,,,,,,,,,,,,,,,,,,,,,,,,,,,,,,,,,,
483.264,2.25834,0.96799,10,,,,,,,,,,,,,,,,,,,,,,,,,,,,,,,,,,,,,
484.064,2.25834,0.95447,10,,,,,,,,,,,,,,,,,,,,,,,,,,,,,,,,,,,,,
484.864,2.25828,0.97417,10,,,,,,,,,,,,,,,,,,,,,,,,,,,,,,,,,,,,,
485.664,2.25828,0.99025,10,,,,,,,,,,,,,,,,,,,,,,,,,,,,,,,,,,,,,
486.464,2.25839,0.97383,10,,,,,,,,,,,,,,,,,,,,,,,,,,,,,,,,,,,,,
487.264,2.25834,1.00975,10,,,,,,,,,,,,,,,,,,,,,,,,,,,,,,,,,,,,,
488.064,2.25828,0.98912,10,,,,,,,,,,,,,,,,,,,,,,,,,,,,,,,,,,,,,
488.864,2.25828,0.98758,10,,,,,,,,,,,,,,,,,,,,,,,,,,,,,,,,,,,,,
489.664,2.25834,0.96844,10,,,,,,,,,,,,,,,,,,,,,,,,,,,,,,,,,,,,,
490.464,2.25834,0.96409,10,,,,,,,,,,,,,,,,,,,,,,,,,,,,,,,,,,,,,
491.264,2.25834,0.99224,10,,,,,,,,,,,,,,,,,,,,,,,,,,,,,,,,,,,,,
492.064,2.25834,0.96222,10,,,,,,,,,,,,,,,,,,,,,,,,,,,,,,,,,,,,,
492.864,2.25834,0.98363,10,,,,,,,,,,,,,,,,,,,,,,,,,,,,,,,,,,,,,
493.664,2.25834,0.9374,10,,,,,,,,,,,,,,,,,,,,,,,,,,,,,,,,,,,,,
494.464,2.25834,0.95643,10,,,,,,,,,,,,,,,,,,,,,,,,,,,,,,,,,,,,,
495.264,2.25834,1.01316,10,,,,,,,,,,,,,,,,,,,,,,,,,,,,,,,,,,,,,
496.064,2.25834,0.99573,10,,,,,,,,,,,,,,,,,,,,,,,,,,,,,,,,,,,,,
496.864,2.25834,0.9769,10,,,,,,,,,,,,,,,,,,,,,,,,,,,,,,,,,,,,,
497.664,2.25834,0.97217,10,,,,,,,,,,,,,,,,,,,,,,,,,,,,,,,,,,,,,
498.464,2.25834,0.94013,10,,,,,,,,,,,,,,,,,,,,,,,,,,,,,,,,,,,,,
499.264,2.25834,1.00095,10,,,,,,,,,,,,,,,,,,,,,,,,,,,,,,,,,,,,,
500.064,2.25834,0.95269,10,,,,,,,,,,,,,,,,,,,,,,,,,,,,,,,,,,,,,
500.864,2.25834,0.95648,10,,,,,,,,,,,,,,,,,,,,,,,,,,,,,,,,,,,,,
501.664,2.25834,0.97436,10,,,,,,,,,,,,,,,,,,,,,,,,,,,,,,,,,,,,,
502.464,2.25834,0.95503,10,,,,,,,,,,,,,,,,,,,,,,,,,,,,,,,,,,,,,
503.264,2.25834,0.98021,10,,,,,,,,,,,,,,,,,,,,,,,,,,,,,,,,,,,,,
504.064,2.25834,0.99459,10,,,,,,,,,,,,,,,,,,,,,,,,,,,,,,,,,,,,,
504.864,2.25834,0.98602,10,,,,,,,,,,,,,,,,,,,,,,,,,,,,,,,,,,,,,
505.664,2.25834,0.94078,10,,,,,,,,,,,,,,,,,,,,,,,,,,,,,,,,,,,,,
506.464,2.25834,0.97232,10,,,,,,,,,,,,,,,,,,,,,,,,,,,,,,,,,,,,,
507.264,2.25834,0.99061,10,,,,,,,,,,,,,,,,,,,,,,,,,,,,,,,,,,,,,
508.064,2.25834,0.97438,10,,,,,,,,,,,,,,,,,,,,,,,,,,,,,,,,,,,,,
508.864,2.25834,0.95928,10,,,,,,,,,,,,,,,,,,,,,,,,,,,,,,,,,,,,,
509.664,2.25834,0.97193,10,,,,,,,,,,,,,,,,,,,,,,,,,,,,,,,,,,,,,
510.464,2.25834,0.94702,10,,,,,,,,,,,,,,,,,,,,,,,,,,,,,,,,,,,,,
511.264,2.25834,0.98851,10,,,,,,,,,,,,,,,,,,,,,,,,,,,,,,,,,,,,,
512.064,2.25822,1.01662,10,,,,,,,,,,,,,,,,,,,,,,,,,,,,,,,,,,,,,
512.864,2.25834,0.97472,10,,,,,,,,,,,,,,,,,,,,,,,,,,,,,,,,,,,,,
513.664,2.25834,0.91886,10,,,,,,,,,,,,,,,,,,,,,,,,,,,,,,,,,,,,,
514.464,2.25834,0.95778,10,,,,,,,,,,,,,,,,,,,,,,,,,,,,,,,,,,,,,
515.264,2.25834,0.93668,10,,,,,,,,,,,,,,,,,,,,,,,,,,,,,,,,,,,,,
516.064,2.25834,0.96059,10,,,,,,,,,,,,,,,,,,,,,,,,,,,,,,,,,,,,,
516.864,2.25834,1.00231,10,,,,,,,,,,,,,,,,,,,,,,,,,,,,,,,,,,,,,
517.664,2.25834,0.97461,10,,,,,,,,,,,,,,,,,,,,,,,,,,,,,,,,,,,,,
518.464,2.25834,0.94558,10,,,,,,,,,,,,,,,,,,,,,,,,,,,,,,,,,,,,,
519.264,2.25834,0.99571,10,,,,,,,,,,,,,,,,,,,,,,,,,,,,,,,,,,,,,
520.064,2.25834,0.97131,10,,,,,,,,,,,,,,,,,,,,,,,,,,,,,,,,,,,,,
520.864,2.25834,0.93677,10,,,,,,,,,,,,,,,,,,,,,,,,,,,,,,,,,,,,,
521.664,2.25834,0.96492,10,,,,,,,,,,,,,,,,,,,,,,,,,,,,,,,,,,,,,
522.464,2.25834,0.94756,10,,,,,,,,,,,,,,,,,,,,,,,,,,,,,,,,,,,,,
523.264,2.25834,0.93332,10,,,,,,,,,,,,,,,,,,,,,,,,,,,,,,,,,,,,,
524.064,2.25834,1.01947,10,,,,,,,,,,,,,,,,,,,,,,,,,,,,,,,,,,,,,
524.864,2.25834,0.96003,10,,,,,,,,,,,,,,,,,,,,,,,,,,,,,,,,,,,,,
525.664,2.25834,0.9816,10,,,,,,,,,,,,,,,,,,,,,,,,,,,,,,,,,,,,,
526.464,2.25834,0.95851,10,,,,,,,,,,,,,,,,,,,,,,,,,,,,,,,,,,,,,
527.264,2.25834,0.96778,10,,,,,,,,,,,,,,,,,,,,,,,,,,,,,,,,,,,,,
528.064,2.25834,0.96554,10,,,,,,,,,,,,,,,,,,,,,,,,,,,,,,,,,,,,,
528.864,2.25834,0.96933,10,,,,,,,,,,,,,,,,,,,,,,,,,,,,,,,,,,,,,
529.664,2.25834,0.95131,10,,,,,,,,,,,,,,,,,,,,,,,,,,,,,,,,,,,,,
530.464,2.25834,0.95113,10,,,,,,,,,,,,,,,,,,,,,,,,,,,,,,,,,,,,,
531.264,2.25834,0.9599,10,,,,,,,,,,,,,,,,,,,,,,,,,,,,,,,,,,,,,
532.064,2.25828,0.99177,10,,,,,,,,,,,,,,,,,,,,,,,,,,,,,,,,,,,,,
532.864,2.25822,0.9389,10,,,,,,,,,,,,,,,,,,,,,,,,,,,,,,,,,,,,,
533.664,2.25828,0.99971,10,,,,,,,,,,,,,,,,,,,,,,,,,,,,,,,,,,,,,
534.464,2.25828,0.93593,10,,,,,,,,,,,,,,,,,,,,,,,,,,,,,,,,,,,,,
535.264,2.25828,1.00321,10,,,,,,,,,,,,,,,,,,,,,,,,,,,,,,,,,,,,,
536.064,2.25828,0.97877,10,,,,,,,,,,,,,,,,,,,,,,,,,,,,,,,,,,,,,
536.864,2.25828,0.97366,10,,,,,,,,,,,,,,,,,,,,,,,,,,,,,,,,,,,,,
537.664,2.25822,0.99593,10,,,,,,,,,,,,,,,,,,,,,,,,,,,,,,,,,,,,,
538.464,2.25822,0.96452,10,,,,,,,,,,,,,,,,,,,,,,,,,,,,,,,,,,,,,
539.264,2.25817,0.97633,10,,,,,,,,,,,,,,,,,,,,,,,,,,,,,,,,,,,,,
540.064,2.25817,1.00678,10,,,,,,,,,,,,,,,,,,,,,,,,,,,,,,,,,,,,,
540.864,2.25811,1.03966,10,,,,,,,,,,,,,,,,,,,,,,,,,,,,,,,,,,,,,
541.664,2.258,0.95945,10,,,,,,,,,,,,,,,,,,,,,,,,,,,,,,,,,,,,,
542.464,2.25788,0.96124,10,,,,,,,,,,,,,,,,,,,,,,,,,,,,,,,,,,,,,
543.264,2.25777,1.04838,10,,,,,,,,,,,,,,,,,,,,,,,,,,,,,,,,,,,,,
544.064,2.2576,1.01312,10,,,,,,,,,,,,,,,,,,,,,,,,,,,,,,,,,,,,,
544.864,2.25737,0.99688,10,,,,,,,,,,,,,,,,,,,,,,,,,,,,,,,,,,,,,
545.664,2.2572,1.04412,10,,,,,,,,,,,,,,,,,,,,,,,,,,,,,,,,,,,,,
546.464,2.25686,0.99744,10,,,,,,,,,,,,,,,,,,,,,,,,,,,,,,,,,,,,,
547.264,2.25573,0.99242,10,,,,,,,,,,,,,,,,,,,,,,,,,,,,,,,,,,,,,
548.064,2.25358,0.96549,10,,,,,,,,,,,,,,,,,,,,,,,,,,,,,,,,,,,,,
548.864,2.25227,0.93096,10,,,,,,,,,,,,,,,,,,,,,,,,,,,,,,,,,,,,,
549.664,2.25171,0.96644,10,,,,,,,,,,,,,,,,,,,,,,,,,,,,,,,,,,,,,
550.464,2.25159,0.91173,10,,,,,,,,,,,,,,,,,,,,,,,,,,,,,,,,,,,,,
551.264,2.25171,0.90564,10,,,,,,,,,,,,,,,,,,,,,,,,,,,,,,,,,,,,,
552.064,2.25182,0.93409,10,,,,,,,,,,,,,,,,,,,,,,,,,,,,,,,,,,,,,
552.864,2.25188,0.94295,10,,,,,,,,,,,,,,,,,,,,,,,,,,,,,,,,,,,,,
553.664,2.25199,0.93626,10,,,,,,,,,,,,,,,,,,,,,,,,,,,,,,,,,,,,,
554.366,4.51798,42.06881,10,,,,,,,,,,,,,,,,,,,,,,,,,,,,,,,,,,,,,
555.166,11.18526,336.08865,10,,,,,,,,,,,,,,,,,,,,,,,,,,,,,,,,,,,,,
555.966,17.85204,88.8772,10,,,,,,,,,,,,,,,,,,,,,,,,,,,,,,,,,,,,,
556.766,24.5187,40.32943,10,,,,,,,,,,,,,,,,,,,,,,,,,,,,,,,,,,,,,
557.566,31.18536,27.30023,10,,,,,,,,,,,,,,,,,,,,,,,,,,,,,,,,,,,,,
558.366,37.85208,9.52138,10,,,,,,,,,,,,,,,,,,,,,,,,,,,,,,,,,,,,,
559.166,44.51875,8.26167,10,,,,,,,,,,,,,,,,,,,,,,,,,,,,,,,,,,,,,
559.966,51.18536,8.72725,10,,,,,,,,,,,,,,,,,,,,,,,,,,,,,,,,,,,,,
560.766,57.85207,9.09266,10,,,,,,,,,,,,,,,,,,,,,,,,,,,,,,,,,,,,,
561.566,64.51868,1.62317,10,,,,,,,,,,,,,,,,,,,,,,,,,,,,,,,,,,,,,
562.366,71.18539,0.6134,10,,,,,,,,,,,,,,,,,,,,,,,,,,,,,,,,,,,,,
563.166,77.85207,0.08995,10,,,,,,,,,,,,,,,,,,,,,,,,,,,,,,,,,,,,,
563.966,84.51867,-0.75781,10,,,,,,,,,,,,,,,,,,,,,,,,,,,,,,,,,,,,,
564.766,91.18533,-3.03531,10,,,,,,,,,,,,,,,,,,,,,,,,,,,,,,,,,,,,,
565.566,97.85205,-3.23447,10,,,,,,,,,,,,,,,,,,,,,,,,,,,,,,,,,,,,,
566.366,104.51872,-3.21345,10,,,,,,,,,,,,,,,,,,,,,,,,,,,,,,,,,,,,,
567.166,111.18526,-3.26056,10,,,,,,,,,,,,,,,,,,,,,,,,,,,,,,,,,,,,,
567.58,114.63541,-3.25895,10,,,,,,,,,,,,,,,,,,,,,,,,,,,,,,,,,,,,,