File: combined_ligament_solver/data/processed/Data Sheet 3_S151624_LCL.csv
Specimen properties : Length,62,mm,Unnamed: 3,Unnamed: 4,This ,Unnamed: 6,Unnamed: 7,Unnamed: 8,Unnamed: 9,Unnamed: 10,Unnamed: 11,Stress-Strain,Unnamed: 13,Unnamed: 14,Unnamed: 15,Unnamed: 16,Unnamed: 17,Unnamed: 18,Unnamed: 19,Unnamed: 20,Unnamed: 21,Unnamed: 22,Unnamed: 23,Unnamed: 24,Unnamed: 25,Unnamed: 26,Unnamed: 27,Linear,Unnamed: 29,Unnamed: 30,Unnamed: 31,Unnamed: 32,Unnamed: 33,Modulus,Unnamed: 35,Failure,Unnamed: 37,Unnamed: 38,Unnamed: 39,Unnamed: 40
Cross Section Average,17.103,mm2,,,,,,,,,,Polynomial Coefficients,,,,,,,,,,,,,,,,Force,,Stress,Extension,Strain,,Secant,Tangent,Load,Stress,Extension,Strain,Stiffness
Time,Extension,Load,Total cycle count,,,Extension,Load,Strain,Stress,E-tan,,X6,-14767309.563537348,,,,,,,,,Strain,Stress,E-tan,,,,(N),,(MPa),(mm),(%),,(MPa),(MPa),(N),(MPa),(mm),(%),(N/mm)
(s),(mm),(N),,,,(mm),(N),(mm/mm),(MPa),(MPa),,X5,7398177.535741801,,,,,,,,,(mm/mm),(MPa),(MPa),,,,320.33044837376866,,18.729488883457208,5.58,9,,208.10543203841343,375.54682008452255,545.89709,31.918206747354265,7.999910000000001,12.90308064516129,57.406890389564275
0.7,2.09151,1.21001,0,,,9.31084,311.95798,0.08870790322580646,18.239956732736946,372.19953554351514,,,,,,,,,,,,0.007,0.15737878653010892,18.39301040653804,,,,,,,,,,,,,,,,
1.5,2.22473,1.27513,0,,,15.97762,79.07514,,,,,,,,,,,,,,,0.015,0.3571133393866107,34.40581444587756,,,,,,,,,,,,,,,,
2.3,2.35807,1.41798,0,,,,,,,,,,,,,,,,,,,0.023,0.7977195109543179,73.66466969535993,,,,,,,,,,,,,,,,
3.1,2.49152,1.58604,0,,,,,,,,,,,,,,,,,,,0.031,1.6138135011189205,125.17077954078404,,,,,,,,,,,,,,,,
3.9,2.62474,1.83751,0,,,,,,,,,,,,,,,,,,,0.039,2.864203867327063,180.58181181076299,,,,,,,,,,,,,,,,
4.7,2.75802,2.14696,0,,,,,,,,,,,,,,,,,,,0.047,4.5515754196816,233.86349423289298,,,,,,,,,,,,,,,,
5.5,2.89147,2.62057,0,,,,,,,,,,,,,,,,,,,0.055,6.639385879686138,280.94120988989397,,,,,,,,,,,,,,,,
6.3,3.02475,3.0642,0,,,,,,,,,,,,,,,,,,,0.063,9.065975302638849,319.3515926758043,,,,,,,,,,,,,,,,
7.1,3.15809,3.53915,0,,,,,,,,,,,,,,,,,,,0.071,11.755888263675558,347.89412275209054,,,,,,,,,,,,,,,,
7.9,3.29143,4.22763,0,,,,,,,,,,,,,,,,,,,0.079,14.628408807462145,366.2827220038785,,,,,,,,,,,,,,,,
8.7,3.42476,4.94455,0,,,,,,,,,,,,,,,,,,,0.087,17.60330816153614,374.79734949602386,,,,,,,,,,,,,,,,
9.5,3.5581,5.5795,0,,,,,,,,,,,,,,,,,,,0.095,20.603805213297758,373.9355969293743,,,,,,,,,,,,,,,,
10.3,3.69144,6.53967,0,,,,,,,,,,,,,,,,,,,0.103,23.55673975064988,364.0642840967413,,,,,,,,,,,,,,,,
11.1,3.82477,7.62837,0,,,,,,,,,,,,,,,,,,,0.111,26.38995846628791,345.0710543393992,,,,,,,,,,,,,,,,
11.9,3.95811,8.75476,0,,,,,,,,,,,,,,,,,,,0.119,29.02691372563826,316.0159700028867,,,,,,,,,,,,,,,,
12.7,4.09145,9.92097,0,,,,,,,,,,,,,,,,,,,0.127,31.378475098446327,274.7831078933342,,,,,,,,,,,,,,,,
13.5,4.22473,11.08313,0,,,,,,,,,,,,,,,,,,,0.135,33.33195365401418,217.7321547336957,,,,,,,,,,,,,,,,
14.3,4.35818,12.48807,0,,,,,,,,,,,,,,,,,,,0.143,34.737339020086814,139.35000261965044,,,,,,,,,,,,,,,,
15.1,4.4914,13.96824,0,,,,,,,,,,,,,,,,,,,0.151,35.390749205388154,31.90234447607306,,,,,,,,,,,,,,,,
15.9,4.62474,15.78315,0,,,,,,,,,,,,,,,,,,,0.159,35.01509318580644,-114.91473048673828,,,,,,,,,,,,,,,,
16.7,4.75813,17.86362,0,,,,,,,,,,,,,,,,,,,0.167,33.237946254227964,-314.32314131780686,,,,,,,,,,,,,,,,
17.5,4.89141,20.39318,0,,,,,,,,,,,,,,,,,,,0.175,29.56663813402192,-582.8112198677603,,,,,,,,,,,,,,,,
18.3,5.02469,23.08996,0,,,,,,,,,,,,,,,,,,,0.183,23.360553856171894,-940.4821153340732,,,,,,,,,,,,,,,,
19.1,5.1582,25.77682,0,,,,,,,,,,,,,,,,,,,0.191,13.800647400060598,-1411.402198804565,,,,,,,,,,,,,,,,
19.9,5.29148,28.75913,0,,,,,,,,,,,,,,,,,,,0.199,-0.14383190210198027,-2023.94946779955,,,,,,,,,,,,,,,,
20.7,5.4247,32.11921,0,,,,,,,,,,,,,,,,,,,,,,,,,,,,,,,,,,,,,
21.5,5.55815,35.97955,0,,,,,,,,,,,,,,,,,,,,,,,,,,,,,,,,,,,,,
22.226,5.67908,40.00642,0.5,,,,,,,,,,,,,,,,,,,,,,,,,,,,,,,,,,,,,
22.928,5.56246,33.33528,0.5,,,,,,,,,,,,,,,,,,,,,,,,,,,,,,,,,,,,,
23.728,5.42912,27.29241,0.5,,,,,,,,,,,,,,,,,,,,,,,,,,,,,,,,,,,,,
24.528,5.29584,22.4411,0.5,,,,,,,,,,,,,,,,,,,,,,,,,,,,,,,,,,,,,
25.328,5.16245,18.25035,0.5,,,,,,,,,,,,,,,,,,,,,,,,,,,,,,,,,,,,,
26.128,5.02905,14.86989,0.5,,,,,,,,,,,,,,,,,,,,,,,,,,,,,,,,,,,,,
26.928,4.89583,12.11048,0.5,,,,,,,,,,,,,,,,,,,,,,,,,,,,,,,,,,,,,
27.728,4.76244,9.82091,0.5,,,,,,,,,,,,,,,,,,,,,,,,,,,,,,,,,,,,,
28.528,4.62899,7.96431,0.5,,,,,,,,,,,,,,,,,,,,,,,,,,,,,,,,,,,,,
29.328,4.49582,6.39467,0.5,,,,,,,,,,,,,,,,,,,,,,,,,,,,,,,,,,,,,
30.128,4.36248,5.10212,0.5,,,,,,,,,,,,,,,,,,,,,,,,,,,,,,,,,,,,,
30.928,4.22903,4.1411,0.5,,,,,,,,,,,,,,,,,,,,,,,,,,,,,,,,,,,,,
31.728,4.09581,3.26578,0.5,,,,,,,,,,,,,,,,,,,,,,,,,,,,,,,,,,,,,
32.528,3.96253,2.45766,0.5,,,,,,,,,,,,,,,,,,,,,,,,,,,,,,,,,,,,,
33.328,3.82902,1.98044,0.5,,,,,,,,,,,,,,,,,,,,,,,,,,,,,,,,,,,,,
34.128,3.6958,1.56856,0.5,,,,,,,,,,,,,,,,,,,,,,,,,,,,,,,,,,,,,
34.928,3.56246,1.28407,0.5,,,,,,,,,,,,,,,,,,,,,,,,,,,,,,,,,,,,,
35.632,3.44505,0.99872,1,,,,,,,,,,,,,,,,,,,,,,,,,,,,,,,,,,,,,
36.236,3.54541,1.41246,1,,,,,,,,,,,,,,,,,,,,,,,,,,,,,,,,,,,,,
37.036,3.6788,1.79064,1,,,,,,,,,,,,,,,,,,,,,,,,,,,,,,,,,,,,,
37.836,3.81202,2.39046,1,,,,,,,,,,,,,,,,,,,,,,,,,,,,,,,,,,,,,
38.636,3.94536,3.38763,1,,,,,,,,,,,,,,,,,,,,,,,,,,,,,,,,,,,,,
39.436,4.07881,4.33406,1,,,,,,,,,,,,,,,,,,,,,,,,,,,,,,,,,,,,,
40.236,4.21215,5.66884,1,,,,,,,,,,,,,,,,,,,,,,,,,,,,,,,,,,,,,
41.036,4.34537,7.23585,1,,,,,,,,,,,,,,,,,,,,,,,,,,,,,,,,,,,,,
41.836,4.47882,8.95134,1,,,,,,,,,,,,,,,,,,,,,,,,,,,,,,,,,,,,,
42.636,4.61204,10.61944,1,,,,,,,,,,,,,,,,,,,,,,,,,,,,,,,,,,,,,
43.436,4.74544,12.47018,1,,,,,,,,,,,,,,,,,,,,,,,,,,,,,,,,,,,,,
44.236,4.87877,14.684,1,,,,,,,,,,,,,,,,,,,,,,,,,,,,,,,,,,,,,
45.036,5.01211,17.56122,1,,,,,,,,,,,,,,,,,,,,,,,,,,,,,,,,,,,,,
45.836,5.14545,20.86407,1,,,,,,,,,,,,,,,,,,,,,,,,,,,,,,,,,,,,,
46.636,5.27878,24.13173,1,,,,,,,,,,,,,,,,,,,,,,,,,,,,,,,,,,,,,
47.436,5.41206,27.78665,1,,,,,,,,,,,,,,,,,,,,,,,,,,,,,,,,,,,,,
48.236,5.54546,31.95601,1,,,,,,,,,,,,,,,,,,,,,,,,,,,,,,,,,,,,,
49.036,5.67874,36.77359,1,,,,,,,,,,,,,,,,,,,,,,,,,,,,,,,,,,,,,
49.73,5.72804,38.22839,1.5,,,,,,,,,,,,,,,,,,,,,,,,,,,,,,,,,,,,,
50.53,5.59408,30.98798,1.5,,,,,,,,,,,,,,,,,,,,,,,,,,,,,,,,,,,,,
51.33,5.46085,25.45812,1.5,,,,,,,,,,,,,,,,,,,,,,,,,,,,,,,,,,,,,
52.13,5.32752,20.86397,1.5,,,,,,,,,,,,,,,,,,,,,,,,,,,,,,,,,,,,,
52.93,5.19395,17.06186,1.5,,,,,,,,,,,,,,,,,,,,,,,,,,,,,,,,,,,,,
53.73,5.06084,13.91973,1.5,,,,,,,,,,,,,,,,,,,,,,,,,,,,,,,,,,,,,
54.53,4.92745,11.26825,1.5,,,,,,,,,,,,,,,,,,,,,,,,,,,,,,,,,,,,,
55.33,4.794,9.01286,1.5,,,,,,,,,,,,,,,,,,,,,,,,,,,,,,,,,,,,,
56.13,4.66083,7.23642,1.5,,,,,,,,,,,,,,,,,,,,,,,,,,,,,,,,,,,,,
56.93,4.5275,5.76362,1.5,,,,,,,,,,,,,,,,,,,,,,,,,,,,,,,,,,,,,
57.73,4.39405,4.51097,1.5,,,,,,,,,,,,,,,,,,,,,,,,,,,,,,,,,,,,,
58.53,4.26082,3.6792,1.5,,,,,,,,,,,,,,,,,,,,,,,,,,,,,,,,,,,,,
59.33,4.12737,2.7619,1.5,,,,,,,,,,,,,,,,,,,,,,,,,,,,,,,,,,,,,
60.13,3.99409,2.06215,1.5,,,,,,,,,,,,,,,,,,,,,,,,,,,,,,,,,,,,,
60.93,3.86087,1.7013,1.5,,,,,,,,,,,,,,,,,,,,,,,,,,,,,,,,,,,,,
61.73,3.72731,1.43523,1.5,,,,,,,,,,,,,,,,,,,,,,,,,,,,,,,,,,,,,
62.53,3.59414,1.0281,1.5,,,,,,,,,,,,,,,,,,,,,,,,,,,,,,,,,,,,,
63.108,3.63216,1.20016,2,,,,,,,,,,,,,,,,,,,,,,,,,,,,,,,,,,,,,
63.908,3.76539,1.58833,2,,,,,,,,,,,,,,,,,,,,,,,,,,,,,,,,,,,,,
64.708,3.89878,2.19853,2,,,,,,,,,,,,,,,,,,,,,,,,,,,,,,,,,,,,,
65.508,4.03223,3.10925,2,,,,,,,,,,,,,,,,,,,,,,,,,,,,,,,,,,,,,
66.308,4.16534,4.12338,2,,,,,,,,,,,,,,,,,,,,,,,,,,,,,,,,,,,,,
67.108,4.29879,5.46956,2,,,,,,,,,,,,,,,,,,,,,,,,,,,,,,,,,,,,,
67.908,4.43207,7.01779,2,,,,,,,,,,,,,,,,,,,,,,,,,,,,,,,,,,,,,
68.708,4.56535,8.74739,2,,,,,,,,,,,,,,,,,,,,,,,,,,,,,,,,,,,,,
69.508,4.69886,10.41157,2,,,,,,,,,,,,,,,,,,,,,,,,,,,,,,,,,,,,,
70.308,4.83208,12.32334,2,,,,,,,,,,,,,,,,,,,,,,,,,,,,,,,,,,,,,
71.108,4.9653,14.8627,2,,,,,,,,,,,,,,,,,,,,,,,,,,,,,,,,,,,,,
71.908,5.09892,17.944,2,,,,,,,,,,,,,,,,,,,,,,,,,,,,,,,,,,,,,
72.708,5.23203,21.29948,2,,,,,,,,,,,,,,,,,,,,,,,,,,,,,,,,,,,,,
73.508,5.36531,24.53632,2,,,,,,,,,,,,,,,,,,,,,,,,,,,,,,,,,,,,,
74.308,5.49888,28.45279,2,,,,,,,,,,,,,,,,,,,,,,,,,,,,,,,,,,,,,
75.108,5.63204,32.97465,2,,,,,,,,,,,,,,,,,,,,,,,,,,,,,,,,,,,,,
75.908,5.76544,38.31531,2,,,,,,,,,,,,,,,,,,,,,,,,,,,,,,,,,,,,,
76.566,5.74158,36.17912,2.5,,,,,,,,,,,,,,,,,,,,,,,,,,,,,,,,,,,,,
77.366,5.60819,29.50609,2.5,,,,,,,,,,,,,,,,,,,,,,,,,,,,,,,,,,,,,
78.166,5.47462,24.2492,2.5,,,,,,,,,,,,,,,,,,,,,,,,,,,,,,,,,,,,,
78.966,5.34157,19.87087,2.5,,,,,,,,,,,,,,,,,,,,,,,,,,,,,,,,,,,,,
79.766,5.20812,16.33321,2.5,,,,,,,,,,,,,,,,,,,,,,,,,,,,,,,,,,,,,
80.566,5.07467,13.23105,2.5,,,,,,,,,,,,,,,,,,,,,,,,,,,,,,,,,,,,,
81.366,4.9415,10.66313,2.5,,,,,,,,,,,,,,,,,,,,,,,,,,,,,,,,,,,,,
82.166,4.80805,8.50365,2.5,,,,,,,,,,,,,,,,,,,,,,,,,,,,,,,,,,,,,
82.966,4.67477,6.72119,2.5,,,,,,,,,,,,,,,,,,,,,,,,,,,,,,,,,,,,,
83.766,4.54155,5.30084,2.5,,,,,,,,,,,,,,,,,,,,,,,,,,,,,,,,,,,,,
84.566,4.40799,4.16142,2.5,,,,,,,,,,,,,,,,,,,,,,,,,,,,,,,,,,,,,
85.366,4.27482,3.31586,2.5,,,,,,,,,,,,,,,,,,,,,,,,,,,,,,,,,,,,,
86.166,4.14148,2.49134,2.5,,,,,,,,,,,,,,,,,,,,,,,,,,,,,,,,,,,,,
86.966,4.00798,1.97218,2.5,,,,,,,,,,,,,,,,,,,,,,,,,,,,,,,,,,,,,
87.766,3.87481,1.60651,2.5,,,,,,,,,,,,,,,,,,,,,,,,,,,,,,,,,,,,,
88.566,3.74153,1.18474,2.5,,,,,,,,,,,,,,,,,,,,,,,,,,,,,,,,,,,,,
89.142,3.71257,1.20132,3,,,,,,,,,,,,,,,,,,,,,,,,,,,,,,,,,,,,,
89.942,3.84653,1.57229,3,,,,,,,,,,,,,,,,,,,,,,,,,,,,,,,,,,,,,
90.742,3.97976,2.10139,3,,,,,,,,,,,,,,,,,,,,,,,,,,,,,,,,,,,,,
91.542,4.11298,3.16284,3,,,,,,,,,,,,,,,,,,,,,,,,,,,,,,,,,,,,,
92.342,4.24654,4.20096,3,,,,,,,,,,,,,,,,,,,,,,,,,,,,,,,,,,,,,
93.142,4.37971,5.49818,3,,,,,,,,,,,,,,,,,,,,,,,,,,,,,,,,,,,,,
93.942,4.51299,7.18656,3,,,,,,,,,,,,,,,,,,,,,,,,,,,,,,,,,,,,,
94.742,4.64661,8.93183,3,,,,,,,,,,,,,,,,,,,,,,,,,,,,,,,,,,,,,
95.542,4.77972,10.59333,3,,,,,,,,,,,,,,,,,,,,,,,,,,,,,,,,,,,,,
96.342,4.91306,12.81153,3,,,,,,,,,,,,,,,,,,,,,,,,,,,,,,,,,,,,,
97.142,5.04656,15.56031,3,,,,,,,,,,,,,,,,,,,,,,,,,,,,,,,,,,,,,
97.942,5.17967,18.70592,3,,,,,,,,,,,,,,,,,,,,,,,,,,,,,,,,,,,,,
98.742,5.31301,22.15284,3,,,,,,,,,,,,,,,,,,,,,,,,,,,,,,,,,,,,,
99.542,5.44652,25.63803,3,,,,,,,,,,,,,,,,,,,,,,,,,,,,,,,,,,,,,
100.342,5.57974,29.71234,3,,,,,,,,,,,,,,,,,,,,,,,,,,,,,,,,,,,,,
101.142,5.71313,34.58725,3,,,,,,,,,,,,,,,,,,,,,,,,,,,,,,,,,,,,,
101.916,5.84222,40.00037,3.5,,,,,,,,,,,,,,,,,,,,,,,,,,,,,,,,,,,,,
102.618,5.72554,33.44817,3.5,,,,,,,,,,,,,,,,,,,,,,,,,,,,,,,,,,,,,
103.418,5.59204,27.3603,3.5,,,,,,,,,,,,,,,,,,,,,,,,,,,,,,,,,,,,,
104.218,5.45887,22.3948,3.5,,,,,,,,,,,,,,,,,,,,,,,,,,,,,,,,,,,,,
105.018,5.32548,18.38405,3.5,,,,,,,,,,,,,,,,,,,,,,,,,,,,,,,,,,,,,
105.818,5.19197,15.09146,3.5,,,,,,,,,,,,,,,,,,,,,,,,,,,,,,,,,,,,,
106.618,5.05886,12.15638,3.5,,,,,,,,,,,,,,,,,,,,,,,,,,,,,,,,,,,,,
107.418,4.92541,9.68193,3.5,,,,,,,,,,,,,,,,,,,,,,,,,,,,,,,,,,,,,
108.218,4.79207,7.63484,3.5,,,,,,,,,,,,,,,,,,,,,,,,,,,,,,,,,,,,,
109.018,4.65885,6.02673,3.5,,,,,,,,,,,,,,,,,,,,,,,,,,,,,,,,,,,,,
109.818,4.52546,4.65015,3.5,,,,,,,,,,,,,,,,,,,,,,,,,,,,,,,,,,,,,
110.618,4.39206,3.76738,3.5,,,,,,,,,,,,,,,,,,,,,,,,,,,,,,,,,,,,,
111.418,4.25884,2.84389,3.5,,,,,,,,,,,,,,,,,,,,,,,,,,,,,,,,,,,,,
112.218,4.12545,2.07555,3.5,,,,,,,,,,,,,,,,,,,,,,,,,,,,,,,,,,,,,
113.018,3.99217,1.73628,3.5,,,,,,,,,,,,,,,,,,,,,,,,,,,,,,,,,,,,,
113.818,3.85883,1.43174,3.5,,,,,,,,,,,,,,,,,,,,,,,,,,,,,,,,,,,,,
114.618,3.72532,1.00026,3.5,,,,,,,,,,,,,,,,,,,,,,,,,,,,,,,,,,,,,
115.124,3.80868,1.31408,4,,,,,,,,,,,,,,,,,,,,,,,,,,,,,,,,,,,,,
115.924,3.94202,1.78165,4,,,,,,,,,,,,,,,,,,,,,,,,,,,,,,,,,,,,,
116.724,4.07552,2.47133,4,,,,,,,,,,,,,,,,,,,,,,,,,,,,,,,,,,,,,
117.524,4.20875,3.51901,4,,,,,,,,,,,,,,,,,,,,,,,,,,,,,,,,,,,,,
118.324,4.34203,4.56312,4,,,,,,,,,,,,,,,,,,,,,,,,,,,,,,,,,,,,,
119.124,4.47553,6.10898,4,,,,,,,,,,,,,,,,,,,,,,,,,,,,,,,,,,,,,
119.924,4.6087,7.77132,4,,,,,,,,,,,,,,,,,,,,,,,,,,,,,,,,,,,,,
120.724,4.74209,9.50219,4,,,,,,,,,,,,,,,,,,,,,,,,,,,,,,,,,,,,,
121.524,4.87554,11.3312,4,,,,,,,,,,,,,,,,,,,,,,,,,,,,,,,,,,,,,
122.324,5.00865,13.90401,4,,,,,,,,,,,,,,,,,,,,,,,,,,,,,,,,,,,,,
123.124,5.1421,16.85989,4,,,,,,,,,,,,,,,,,,,,,,,,,,,,,,,,,,,,,
123.924,5.2755,20.21941,4,,,,,,,,,,,,,,,,,,,,,,,,,,,,,,,,,,,,,
124.724,5.40872,23.58786,4,,,,,,,,,,,,,,,,,,,,,,,,,,,,,,,,,,,,,
125.524,5.54211,27.35575,4,,,,,,,,,,,,,,,,,,,,,,,,,,,,,,,,,,,,,
126.324,5.67545,32.05609,4,,,,,,,,,,,,,,,,,,,,,,,,,,,,,,,,,,,,,
127.124,5.80873,37.34523,4,,,,,,,,,,,,,,,,,,,,,,,,,,,,,,,,,,,,,
127.788,5.8191,37.17297,4.5,,,,,,,,,,,,,,,,,,,,,,,,,,,,,,,,,,,,,
128.588,5.68588,30.28339,4.5,,,,,,,,,,,,,,,,,,,,,,,,,,,,,,,,,,,,,
129.388,5.55248,24.72896,4.5,,,,,,,,,,,,,,,,,,,,,,,,,,,,,,,,,,,,,
130.188,5.41903,20.26489,4.5,,,,,,,,,,,,,,,,,,,,,,,,,,,,,,,,,,,,,
130.988,5.28592,16.64941,4.5,,,,,,,,,,,,,,,,,,,,,,,,,,,,,,,,,,,,,
131.788,5.15247,13.51437,4.5,,,,,,,,,,,,,,,,,,,,,,,,,,,,,,,,,,,,,
132.588,5.01902,10.83279,4.5,,,,,,,,,,,,,,,,,,,,,,,,,,,,,,,,,,,,,
133.388,4.8858,8.55369,4.5,,,,,,,,,,,,,,,,,,,,,,,,,,,,,,,,,,,,,
134.188,4.75241,6.71995,4.5,,,,,,,,,,,,,,,,,,,,,,,,,,,,,,,,,,,,,
134.988,4.61907,5.27182,4.5,,,,,,,,,,,,,,,,,,,,,,,,,,,,,,,,,,,,,
135.788,4.48579,4.0844,4.5,,,,,,,,,,,,,,,,,,,,,,,,,,,,,,,,,,,,,
136.588,4.3524,3.1731,4.5,,,,,,,,,,,,,,,,,,,,,,,,,,,,,,,,,,,,,
137.388,4.21912,2.34152,4.5,,,,,,,,,,,,,,,,,,,,,,,,,,,,,,,,,,,,,
138.188,4.08589,1.95536,4.5,,,,,,,,,,,,,,,,,,,,,,,,,,,,,,,,,,,,,
138.988,3.95233,1.61002,4.5,,,,,,,,,,,,,,,,,,,,,,,,,,,,,,,,,,,,,
139.788,3.81916,1.11446,4.5,,,,,,,,,,,,,,,,,,,,,,,,,,,,,,,,,,,,,
140.342,3.82772,1.18575,5,,,,,,,,,,,,,,,,,,,,,,,,,,,,,,,,,,,,,
141.142,3.96111,1.57984,5,,,,,,,,,,,,,,,,,,,,,,,,,,,,,,,,,,,,,
141.942,4.09445,2.21366,5,,,,,,,,,,,,,,,,,,,,,,,,,,,,,,,,,,,,,
142.742,4.22767,3.30729,5,,,,,,,,,,,,,,,,,,,,,,,,,,,,,,,,,,,,,
143.542,4.36112,4.32854,5,,,,,,,,,,,,,,,,,,,,,,,,,,,,,,,,,,,,,
144.342,4.4944,5.88549,5,,,,,,,,,,,,,,,,,,,,,,,,,,,,,,,,,,,,,
145.142,4.62768,7.59977,5,,,,,,,,,,,,,,,,,,,,,,,,,,,,,,,,,,,,,
145.942,4.76113,9.32263,5,,,,,,,,,,,,,,,,,,,,,,,,,,,,,,,,,,,,,
146.742,4.89447,10.99996,5,,,,,,,,,,,,,,,,,,,,,,,,,,,,,,,,,,,,,
147.542,5.02764,13.62591,5,,,,,,,,,,,,,,,,,,,,,,,,,,,,,,,,,,,,,
148.342,5.16114,16.67684,5,,,,,,,,,,,,,,,,,,,,,,,,,,,,,,,,,,,,,
149.142,5.29442,20.01536,5,,,,,,,,,,,,,,,,,,,,,,,,,,,,,,,,,,,,,
149.942,5.4277,23.40784,5,,,,,,,,,,,,,,,,,,,,,,,,,,,,,,,,,,,,,
150.742,5.56115,27.13016,5,,,,,,,,,,,,,,,,,,,,,,,,,,,,,,,,,,,,,
151.542,5.69443,31.8482,5,,,,,,,,,,,,,,,,,,,,,,,,,,,,,,,,,,,,,
152.342,5.82771,37.26049,5,,,,,,,,,,,,,,,,,,,,,,,,,,,,,,,,,,,,,
153.022,5.84097,37.207,5.5,,,,,,,,,,,,,,,,,,,,,,,,,,,,,,,,,,,,,
153.822,5.70741,30.25629,5.5,,,,,,,,,,,,,,,,,,,,,,,,,,,,,,,,,,,,,
154.622,5.57413,24.73115,5.5,,,,,,,,,,,,,,,,,,,,,,,,,,,,,,,,,,,,,
155.422,5.44079,20.19639,5.5,,,,,,,,,,,,,,,,,,,,,,,,,,,,,,,,,,,,,
156.222,5.30729,16.58838,5.5,,,,,,,,,,,,,,,,,,,,,,,,,,,,,,,,,,,,,
157.022,5.17412,13.57649,5.5,,,,,,,,,,,,,,,,,,,,,,,,,,,,,,,,,,,,,
157.822,5.04084,10.76094,5.5,,,,,,,,,,,,,,,,,,,,,,,,,,,,,,,,,,,,,
158.622,4.90733,8.49167,5.5,,,,,,,,,,,,,,,,,,,,,,,,,,,,,,,,,,,,,
159.422,4.77417,6.66336,5.5,,,,,,,,,,,,,,,,,,,,,,,,,,,,,,,,,,,,,
160.222,4.64083,5.12821,5.5,,,,,,,,,,,,,,,,,,,,,,,,,,,,,,,,,,,,,
161.022,4.50744,4.14333,5.5,,,,,,,,,,,,,,,,,,,,,,,,,,,,,,,,,,,,,
161.822,4.3741,3.1448,5.5,,,,,,,,,,,,,,,,,,,,,,,,,,,,,,,,,,,,,
162.622,4.24082,2.35497,5.5,,,,,,,,,,,,,,,,,,,,,,,,,,,,,,,,,,,,,
163.422,4.10748,1.90827,5.5,,,,,,,,,,,,,,,,,,,,,,,,,,,,,,,,,,,,,
164.222,3.97409,1.51318,5.5,,,,,,,,,,,,,,,,,,,,,,,,,,,,,,,,,,,,,
165.022,3.84081,1.09273,5.5,,,,,,,,,,,,,,,,,,,,,,,,,,,,,,,,,,,,,
165.604,3.87798,1.2677,6,,,,,,,,,,,,,,,,,,,,,,,,,,,,,,,,,,,,,
166.404,4.01143,1.70032,6,,,,,,,,,,,,,,,,,,,,,,,,,,,,,,,,,,,,,
167.204,4.14471,2.37216,6,,,,,,,,,,,,,,,,,,,,,,,,,,,,,,,,,,,,,
168.004,4.27811,3.49805,6,,,,,,,,,,,,,,,,,,,,,,,,,,,,,,,,,,,,,
168.804,4.41144,4.51558,6,,,,,,,,,,,,,,,,,,,,,,,,,,,,,,,,,,,,,
169.604,4.54472,6.15266,6,,,,,,,,,,,,,,,,,,,,,,,,,,,,,,,,,,,,,
170.404,4.67806,7.89254,6,,,,,,,,,,,,,,,,,,,,,,,,,,,,,,,,,,,,,
171.204,4.81151,9.58408,6,,,,,,,,,,,,,,,,,,,,,,,,,,,,,,,,,,,,,
172.004,4.94473,11.46928,6,,,,,,,,,,,,,,,,,,,,,,,,,,,,,,,,,,,,,
172.804,5.07807,14.23641,6,,,,,,,,,,,,,,,,,,,,,,,,,,,,,,,,,,,,,
173.604,5.21152,17.25024,6,,,,,,,,,,,,,,,,,,,,,,,,,,,,,,,,,,,,,
174.404,5.3448,20.75058,6,,,,,,,,,,,,,,,,,,,,,,,,,,,,,,,,,,,,,
175.204,5.47808,24.18545,6,,,,,,,,,,,,,,,,,,,,,,,,,,,,,,,,,,,,,
176.004,5.61147,28.14575,6,,,,,,,,,,,,,,,,,,,,,,,,,,,,,,,,,,,,,
176.804,5.7447,33.03836,6,,,,,,,,,,,,,,,,,,,,,,,,,,,,,,,,,,,,,
177.604,5.87803,38.61873,6,,,,,,,,,,,,,,,,,,,,,,,,,,,,,,,,,,,,,
178.296,5.82647,35.40549,6.5,,,,,,,,,,,,,,,,,,,,,,,,,,,,,,,,,,,,,
179.096,5.69313,28.82393,6.5,,,,,,,,,,,,,,,,,,,,,,,,,,,,,,,,,,,,,
179.896,5.55979,23.53343,6.5,,,,,,,,,,,,,,,,,,,,,,,,,,,,,,,,,,,,,
180.696,5.4264,19.28895,6.5,,,,,,,,,,,,,,,,,,,,,,,,,,,,,,,,,,,,,
181.496,5.29318,15.76544,6.5,,,,,,,,,,,,,,,,,,,,,,,,,,,,,,,,,,,,,
182.296,5.15984,12.72707,6.5,,,,,,,,,,,,,,,,,,,,,,,,,,,,,,,,,,,,,
183.096,5.02639,10.18005,6.5,,,,,,,,,,,,,,,,,,,,,,,,,,,,,,,,,,,,,
183.896,4.89311,7.94884,6.5,,,,,,,,,,,,,,,,,,,,,,,,,,,,,,,,,,,,,
184.696,4.75983,6.19912,6.5,,,,,,,,,,,,,,,,,,,,,,,,,,,,,,,,,,,,,
185.496,4.62627,4.83724,6.5,,,,,,,,,,,,,,,,,,,,,,,,,,,,,,,,,,,,,
186.296,4.4931,3.89864,6.5,,,,,,,,,,,,,,,,,,,,,,,,,,,,,,,,,,,,,
187.096,4.35988,2.97798,6.5,,,,,,,,,,,,,,,,,,,,,,,,,,,,,,,,,,,,,
187.896,4.22637,2.1653,6.5,,,,,,,,,,,,,,,,,,,,,,,,,,,,,,,,,,,,,
188.696,4.09326,1.70384,6.5,,,,,,,,,,,,,,,,,,,,,,,,,,,,,,,,,,,,,
189.496,3.95981,1.32594,6.5,,,,,,,,,,,,,,,,,,,,,,,,,,,,,,,,,,,,,
190.202,3.84206,0.99503,7,,,,,,,,,,,,,,,,,,,,,,,,,,,,,,,,,,,,,
190.806,3.94236,1.4337,7,,,,,,,,,,,,,,,,,,,,,,,,,,,,,,,,,,,,,
191.606,4.07586,1.92389,7,,,,,,,,,,,,,,,,,,,,,,,,,,,,,,,,,,,,,
192.406,4.20903,2.59518,7,,,,,,,,,,,,,,,,,,,,,,,,,,,,,,,,,,,,,
193.206,4.34237,3.84332,7,,,,,,,,,,,,,,,,,,,,,,,,,,,,,,,,,,,,,
194.006,4.47587,5.00577,7,,,,,,,,,,,,,,,,,,,,,,,,,,,,,,,,,,,,,
194.806,4.60898,6.58633,7,,,,,,,,,,,,,,,,,,,,,,,,,,,,,,,,,,,,,
195.606,4.74243,8.47969,7,,,,,,,,,,,,,,,,,,,,,,,,,,,,,,,,,,,,,
196.406,4.87583,10.11841,7,,,,,,,,,,,,,,,,,,,,,,,,,,,,,,,,,,,,,
197.206,5.00899,12.27356,7,,,,,,,,,,,,,,,,,,,,,,,,,,,,,,,,,,,,,
198.006,5.14244,15.1323,7,,,,,,,,,,,,,,,,,,,,,,,,,,,,,,,,,,,,,
198.806,5.27578,18.3782,7,,,,,,,,,,,,,,,,,,,,,,,,,,,,,,,,,,,,,
199.606,5.409,21.87699,7,,,,,,,,,,,,,,,,,,,,,,,,,,,,,,,,,,,,,
200.406,5.54245,25.48691,7,,,,,,,,,,,,,,,,,,,,,,,,,,,,,,,,,,,,,
201.206,5.67573,29.75202,7,,,,,,,,,,,,,,,,,,,,,,,,,,,,,,,,,,,,,
202.006,5.80907,34.95419,7,,,,,,,,,,,,,,,,,,,,,,,,,,,,,,,,,,,,,
202.702,5.92495,40.01729,7.5,,,,,,,,,,,,,,,,,,,,,,,,,,,,,,,,,,,,,
203.502,5.7915,32.73045,7.5,,,,,,,,,,,,,,,,,,,,,,,,,,,,,,,,,,,,,
204.302,5.65811,26.65017,7.5,,,,,,,,,,,,,,,,,,,,,,,,,,,,,,,,,,,,,
205.102,5.52477,21.73978,7.5,,,,,,,,,,,,,,,,,,,,,,,,,,,,,,,,,,,,,
205.902,5.39149,17.79731,7.5,,,,,,,,,,,,,,,,,,,,,,,,,,,,,,,,,,,,,
206.702,5.25804,14.52243,7.5,,,,,,,,,,,,,,,,,,,,,,,,,,,,,,,,,,,,,
207.502,5.12482,11.63799,7.5,,,,,,,,,,,,,,,,,,,,,,,,,,,,,,,,,,,,,
208.302,4.99154,9.18189,7.5,,,,,,,,,,,,,,,,,,,,,,,,,,,,,,,,,,,,,
209.102,4.85798,7.21972,7.5,,,,,,,,,,,,,,,,,,,,,,,,,,,,,,,,,,,,,
209.902,4.72487,5.51667,7.5,,,,,,,,,,,,,,,,,,,,,,,,,,,,,,,,,,,,,
210.702,4.59142,4.26417,7.5,,,,,,,,,,,,,,,,,,,,,,,,,,,,,,,,,,,,,
211.502,4.45791,3.36721,7.5,,,,,,,,,,,,,,,,,,,,,,,,,,,,,,,,,,,,,
212.302,4.32486,2.41008,7.5,,,,,,,,,,,,,,,,,,,,,,,,,,,,,,,,,,,,,
213.102,4.19146,2.03046,7.5,,,,,,,,,,,,,,,,,,,,,,,,,,,,,,,,,,,,,
213.902,4.05796,1.56805,7.5,,,,,,,,,,,,,,,,,,,,,,,,,,,,,,,,,,,,,
214.702,3.92485,1.12532,7.5,,,,,,,,,,,,,,,,,,,,,,,,,,,,,,,,,,,,,
215.216,3.86761,1.02889,8,,,,,,,,,,,,,,,,,,,,,,,,,,,,,,,,,,,,,
216.016,4.00673,1.51904,8,,,,,,,,,,,,,,,,,,,,,,,,,,,,,,,,,,,,,
216.816,4.14024,2.07526,8,,,,,,,,,,,,,,,,,,,,,,,,,,,,,,,,,,,,,
217.616,4.2734,2.96407,8,,,,,,,,,,,,,,,,,,,,,,,,,,,,,,,,,,,,,
218.416,4.4068,4.0471,8,,,,,,,,,,,,,,,,,,,,,,,,,,,,,,,,,,,,,
219.216,4.54013,5.41309,8,,,,,,,,,,,,,,,,,,,,,,,,,,,,,,,,,,,,,
220.016,4.6733,7.16933,8,,,,,,,,,,,,,,,,,,,,,,,,,,,,,,,,,,,,,
220.816,4.80675,8.94125,8,,,,,,,,,,,,,,,,,,,,,,,,,,,,,,,,,,,,,
221.616,4.94009,10.68288,8,,,,,,,,,,,,,,,,,,,,,,,,,,,,,,,,,,,,,
222.416,5.07331,13.1211,8,,,,,,,,,,,,,,,,,,,,,,,,,,,,,,,,,,,,,
223.216,5.20687,16.1162,8,,,,,,,,,,,,,,,,,,,,,,,,,,,,,,,,,,,,,
224.016,5.3401,19.58702,8,,,,,,,,,,,,,,,,,,,,,,,,,,,,,,,,,,,,,
224.816,5.47332,23.03022,8,,,,,,,,,,,,,,,,,,,,,,,,,,,,,,,,,,,,,
225.616,5.60688,26.82942,8,,,,,,,,,,,,,,,,,,,,,,,,,,,,,,,,,,,,,
226.416,5.73999,31.55373,8,,,,,,,,,,,,,,,,,,,,,,,,,,,,,,,,,,,,,
227.216,5.87333,37.07069,8,,,,,,,,,,,,,,,,,,,,,,,,,,,,,,,,,,,,,
227.82,5.90773,38.387,8.5,,,,,,,,,,,,,,,,,,,,,,,,,,,,,,,,,,,,,
228.62,5.77394,31.03959,8.5,,,,,,,,,,,,,,,,,,,,,,,,,,,,,,,,,,,,,
229.42,5.64037,25.35929,8.5,,,,,,,,,,,,,,,,,,,,,,,,,,,,,,,,,,,,,
230.22,5.50709,20.71005,8.5,,,,,,,,,,,,,,,,,,,,,,,,,,,,,,,,,,,,,
231.02,5.37376,16.92831,8.5,,,,,,,,,,,,,,,,,,,,,,,,,,,,,,,,,,,,,
231.82,5.24036,13.72729,8.5,,,,,,,,,,,,,,,,,,,,,,,,,,,,,,,,,,,,,
232.62,5.10708,10.9395,8.5,,,,,,,,,,,,,,,,,,,,,,,,,,,,,,,,,,,,,
233.42,4.9738,8.63255,8.5,,,,,,,,,,,,,,,,,,,,,,,,,,,,,,,,,,,,,
234.22,4.84041,6.73872,8.5,,,,,,,,,,,,,,,,,,,,,,,,,,,,,,,,,,,,,
235.02,4.70713,5.15287,8.5,,,,,,,,,,,,,,,,,,,,,,,,,,,,,,,,,,,,,
235.82,4.57374,4.04446,8.5,,,,,,,,,,,,,,,,,,,,,,,,,,,,,,,,,,,,,
236.62,4.4404,3.0751,8.5,,,,,,,,,,,,,,,,,,,,,,,,,,,,,,,,,,,,,
237.42,4.30718,2.30912,8.5,,,,,,,,,,,,,,,,,,,,,,,,,,,,,,,,,,,,,
238.22,4.17367,1.82397,8.5,,,,,,,,,,,,,,,,,,,,,,,,,,,,,,,,,,,,,
239.02,4.04039,1.51298,8.5,,,,,,,,,,,,,,,,,,,,,,,,,,,,,,,,,,,,,
239.82,3.90717,1.06075,8.5,,,,,,,,,,,,,,,,,,,,,,,,,,,,,,,,,,,,,
240.328,3.95675,1.28595,9,,,,,,,,,,,,,,,,,,,,,,,,,,,,,,,,,,,,,
241.128,4.09009,1.76563,9,,,,,,,,,,,,,,,,,,,,,,,,,,,,,,,,,,,,,
241.928,4.22342,2.29658,9,,,,,,,,,,,,,,,,,,,,,,,,,,,,,,,,,,,,,
242.728,4.35682,3.4731,9,,,,,,,,,,,,,,,,,,,,,,,,,,,,,,,,,,,,,
243.528,4.49004,4.57804,9,,,,,,,,,,,,,,,,,,,,,,,,,,,,,,,,,,,,,
244.328,4.62338,6.24345,9,,,,,,,,,,,,,,,,,,,,,,,,,,,,,,,,,,,,,
245.128,4.75688,8.02225,9,,,,,,,,,,,,,,,,,,,,,,,,,,,,,,,,,,,,,
245.928,4.89005,9.77574,9,,,,,,,,,,,,,,,,,,,,,,,,,,,,,,,,,,,,,
246.728,5.02339,11.77689,9,,,,,,,,,,,,,,,,,,,,,,,,,,,,,,,,,,,,,
247.528,5.15684,14.60664,9,,,,,,,,,,,,,,,,,,,,,,,,,,,,,,,,,,,,,
248.328,5.29006,17.80596,9,,,,,,,,,,,,,,,,,,,,,,,,,,,,,,,,,,,,,
249.128,5.4234,21.38588,9,,,,,,,,,,,,,,,,,,,,,,,,,,,,,,,,,,,,,
249.928,5.55685,24.98355,9,,,,,,,,,,,,,,,,,,,,,,,,,,,,,,,,,,,,,
250.728,5.69007,29.18132,9,,,,,,,,,,,,,,,,,,,,,,,,,,,,,,,,,,,,,
251.528,5.82341,34.33218,9,,,,,,,,,,,,,,,,,,,,,,,,,,,,,,,,,,,,,
252.294,5.95125,40.01038,9.5,,,,,,,,,,,,,,,,,,,,,,,,,,,,,,,,,,,,,
252.996,5.83457,33.51263,9.5,,,,,,,,,,,,,,,,,,,,,,,,,,,,,,,,,,,,,
253.796,5.70101,27.32881,9.5,,,,,,,,,,,,,,,,,,,,,,,,,,,,,,,,,,,,,
254.596,5.56784,22.2611,9.5,,,,,,,,,,,,,,,,,,,,,,,,,,,,,,,,,,,,,
255.396,5.43445,18.26938,9.5,,,,,,,,,,,,,,,,,,,,,,,,,,,,,,,,,,,,,
256.196,5.30105,14.85083,9.5,,,,,,,,,,,,,,,,,,,,,,,,,,,,,,,,,,,,,
256.996,5.16783,11.84692,9.5,,,,,,,,,,,,,,,,,,,,,,,,,,,,,,,,,,,,,
257.796,5.03449,9.35064,9.5,,,,,,,,,,,,,,,,,,,,,,,,,,,,,,,,,,,,,
258.596,4.90104,7.29308,9.5,,,,,,,,,,,,,,,,,,,,,,,,,,,,,,,,,,,,,
259.396,4.76788,5.59367,9.5,,,,,,,,,,,,,,,,,,,,,,,,,,,,,,,,,,,,,
260.196,4.63426,4.26857,9.5,,,,,,,,,,,,,,,,,,,,,,,,,,,,,,,,,,,,,
260.996,4.5012,3.42464,9.5,,,,,,,,,,,,,,,,,,,,,,,,,,,,,,,,,,,,,
261.796,4.36781,2.46676,9.5,,,,,,,,,,,,,,,,,,,,,,,,,,,,,,,,,,,,,
262.596,4.2343,2.0645,9.5,,,,,,,,,,,,,,,,,,,,,,,,,,,,,,,,,,,,,
263.396,4.10125,1.58558,9.5,,,,,,,,,,,,,,,,,,,,,,,,,,,,,,,,,,,,,
264.196,3.96786,1.14705,9.5,,,,,,,,,,,,,,,,,,,,,,,,,,,,,,,,,,,,,
264.854,3.86501,0.9247,10,,,,,,,,,,,,,,,,,,,,,,,,,,,,,,,,,,,,,
265.654,3.82715,0.91501,10,,,,,,,,,,,,,,,,,,,,,,,,,,,,,,,,,,,,,
266.454,3.82766,0.90625,10,,,,,,,,,,,,,,,,,,,,,,,,,,,,,,,,,,,,,
267.254,3.82936,0.89907,10,,,,,,,,,,,,,,,,,,,,,,,,,,,,,,,,,,,,,
268.054,3.85379,0.9592,10,,,,,,,,,,,,,,,,,,,,,,,,,,,,,,,,,,,,,
268.854,3.93856,1.32804,10,,,,,,,,,,,,,,,,,,,,,,,,,,,,,,,,,,,,,
269.654,3.95579,1.30373,10,,,,,,,,,,,,,,,,,,,,,,,,,,,,,,,,,,,,,
270.454,3.95494,1.42142,10,,,,,,,,,,,,,,,,,,,,,,,,,,,,,,,,,,,,,
271.254,3.93363,1.34036,10,,,,,,,,,,,,,,,,,,,,,,,,,,,,,,,,,,,,,
272.054,3.87589,1.0115,10,,,,,,,,,,,,,,,,,,,,,,,,,,,,,,,,,,,,,
272.854,3.86563,1.05413,10,,,,,,,,,,,,,,,,,,,,,,,,,,,,,,,,,,,,,
273.654,3.8658,0.98956,10,,,,,,,,,,,,,,,,,,,,,,,,,,,,,,,,,,,,,
274.454,3.86603,1.02728,10,,,,,,,,,,,,,,,,,,,,,,,,,,,,,,,,,,,,,
275.254,3.86654,1.08495,10,,,,,,,,,,,,,,,,,,,,,,,,,,,,,,,,,,,,,
276.054,3.86824,1.02584,10,,,,,,,,,,,,,,,,,,,,,,,,,,,,,,,,,,,,,
276.854,3.87747,1.01595,10,,,,,,,,,,,,,,,,,,,,,,,,,,,,,,,,,,,,,
277.654,3.90739,1.22978,10,,,,,,,,,,,,,,,,,,,,,,,,,,,,,,,,,,,,,
278.454,3.91261,1.2671,10,,,,,,,,,,,,,,,,,,,,,,,,,,,,,,,,,,,,,
279.254,3.91232,1.23326,10,,,,,,,,,,,,,,,,,,,,,,,,,,,,,,,,,,,,,
280.054,3.9117,1.29047,10,,,,,,,,,,,,,,,,,,,,,,,,,,,,,,,,,,,,,
280.854,3.90586,1.22385,10,,,,,,,,,,,,,,,,,,,,,,,,,,,,,,,,,,,,,
281.654,3.88087,1.09577,10,,,,,,,,,,,,,,,,,,,,,,,,,,,,,,,,,,,,,
282.454,3.86886,1.08547,10,,,,,,,,,,,,,,,,,,,,,,,,,,,,,,,,,,,,,
283.254,3.86829,1.09078,10,,,,,,,,,,,,,,,,,,,,,,,,,,,,,,,,,,,,,
284.054,3.86841,1.02469,10,,,,,,,,,,,,,,,,,,,,,,,,,,,,,,,,,,,,,
284.854,3.86846,1.14669,10,,,,,,,,,,,,,,,,,,,,,,,,,,,,,,,,,,,,,
285.654,3.86852,1.11282,10,,,,,,,,,,,,,,,,,,,,,,,,,,,,,,,,,,,,,
286.454,3.86858,1.08036,10,,,,,,,,,,,,,,,,,,,,,,,,,,,,,,,,,,,,,
287.254,3.86869,1.07602,10,,,,,,,,,,,,,,,,,,,,,,,,,,,,,,,,,,,,,
288.054,3.8688,1.13539,10,,,,,,,,,,,,,,,,,,,,,,,,,,,,,,,,,,,,,
288.854,3.86903,1.04714,10,,,,,,,,,,,,,,,,,,,,,,,,,,,,,,,,,,,,,
289.654,3.86937,1.09643,10,,,,,,,,,,,,,,,,,,,,,,,,,,,,,,,,,,,,,
290.454,3.86982,1.12601,10,,,,,,,,,,,,,,,,,,,,,,,,,,,,,,,,,,,,,
291.254,3.87022,1.08423,10,,,,,,,,,,,,,,,,,,,,,,,,,,,,,,,,,,,,,
292.054,3.87067,1.10291,10,,,,,,,,,,,,,,,,,,,,,,,,,,,,,,,,,,,,,
292.854,3.87158,1.12881,10,,,,,,,,,,,,,,,,,,,,,,,,,,,,,,,,,,,,,
293.654,3.87249,1.05978,10,,,,,,,,,,,,,,,,,,,,,,,,,,,,,,,,,,,,,
294.454,3.87317,1.09199,10,,,,,,,,,,,,,,,,,,,,,,,,,,,,,,,,,,,,,
295.254,3.87413,1.12098,10,,,,,,,,,,,,,,,,,,,,,,,,,,,,,,,,,,,,,
296.054,3.87458,1.09034,10,,,,,,,,,,,,,,,,,,,,,,,,,,,,,,,,,,,,,
296.854,3.87481,1.16201,10,,,,,,,,,,,,,,,,,,,,,,,,,,,,,,,,,,,,,
297.654,3.87492,1.12407,10,,,,,,,,,,,,,,,,,,,,,,,,,,,,,,,,,,,,,
298.454,3.87492,1.062,10,,,,,,,,,,,,,,,,,,,,,,,,,,,,,,,,,,,,,
299.254,3.87487,1.16698,10,,,,,,,,,,,,,,,,,,,,,,,,,,,,,,,,,,,,,
300.054,3.87487,1.14286,10,,,,,,,,,,,,,,,,,,,,,,,,,,,,,,,,,,,,,
300.854,3.87481,1.07305,10,,,,,,,,,,,,,,,,,,,,,,,,,,,,,,,,,,,,,
301.654,3.87464,1.19643,10,,,,,,,,,,,,,,,,,,,,,,,,,,,,,,,,,,,,,
302.454,3.87447,1.1692,10,,,,,,,,,,,,,,,,,,,,,,,,,,,,,,,,,,,,,
303.254,3.87424,1.20311,10,,,,,,,,,,,,,,,,,,,,,,,,,,,,,,,,,,,,,
304.054,3.87362,1.18545,10,,,,,,,,,,,,,,,,,,,,,,,,,,,,,,,,,,,,,
304.854,3.87181,1.23696,10,,,,,,,,,,,,,,,,,,,,,,,,,,,,,,,,,,,,,
305.654,3.86903,1.17193,10,,,,,,,,,,,,,,,,,,,,,,,,,,,,,,,,,,,,,
306.454,3.86546,1.16445,10,,,,,,,,,,,,,,,,,,,,,,,,,,,,,,,,,,,,,
307.254,3.85764,1.14072,10,,,,,,,,,,,,,,,,,,,,,,,,,,,,,,,,,,,,,
308.054,3.85277,1.05809,10,,,,,,,,,,,,,,,,,,,,,,,,,,,,,,,,,,,,,
308.854,3.85044,1.11963,10,,,,,,,,,,,,,,,,,,,,,,,,,,,,,,,,,,,,,
309.654,3.84971,1.11123,10,,,,,,,,,,,,,,,,,,,,,,,,,,,,,,,,,,,,,
310.454,3.84959,1.0958,10,,,,,,,,,,,,,,,,,,,,,,,,,,,,,,,,,,,,,
311.254,3.84959,1.15081,10,,,,,,,,,,,,,,,,,,,,,,,,,,,,,,,,,,,,,
312.054,3.84965,1.08484,10,,,,,,,,,,,,,,,,,,,,,,,,,,,,,,,,,,,,,
312.854,3.84971,1.06553,10,,,,,,,,,,,,,,,,,,,,,,,,,,,,,,,,,,,,,
313.654,3.84971,1.13642,10,,,,,,,,,,,,,,,,,,,,,,,,,,,,,,,,,,,,,
314.454,3.84976,1.10644,10,,,,,,,,,,,,,,,,,,,,,,,,,,,,,,,,,,,,,
315.254,3.84976,1.11533,10,,,,,,,,,,,,,,,,,,,,,,,,,,,,,,,,,,,,,
316.054,3.84976,1.12162,10,,,,,,,,,,,,,,,,,,,,,,,,,,,,,,,,,,,,,
316.854,3.84988,1.13535,10,,,,,,,,,,,,,,,,,,,,,,,,,,,,,,,,,,,,,
317.654,3.84982,1.09115,10,,,,,,,,,,,,,,,,,,,,,,,,,,,,,,,,,,,,,
318.454,3.84993,1.14093,10,,,,,,,,,,,,,,,,,,,,,,,,,,,,,,,,,,,,,
319.254,3.84993,1.11918,10,,,,,,,,,,,,,,,,,,,,,,,,,,,,,,,,,,,,,
320.054,3.84999,1.09093,10,,,,,,,,,,,,,,,,,,,,,,,,,,,,,,,,,,,,,
320.854,3.84988,1.1357,10,,,,,,,,,,,,,,,,,,,,,,,,,,,,,,,,,,,,,
321.654,3.84999,1.14437,10,,,,,,,,,,,,,,,,,,,,,,,,,,,,,,,,,,,,,
322.454,3.84999,1.12289,10,,,,,,,,,,,,,,,,,,,,,,,,,,,,,,,,,,,,,
323.254,3.84999,1.13177,10,,,,,,,,,,,,,,,,,,,,,,,,,,,,,,,,,,,,,
324.054,3.84999,1.16073,10,,,,,,,,,,,,,,,,,,,,,,,,,,,,,,,,,,,,,
324.854,3.84999,1.09404,10,,,,,,,,,,,,,,,,,,,,,,,,,,,,,,,,,,,,,
325.654,3.84999,1.12104,10,,,,,,,,,,,,,,,,,,,,,,,,,,,,,,,,,,,,,
326.454,3.84999,1.1359,10,,,,,,,,,,,,,,,,,,,,,,,,,,,,,,,,,,,,,
327.254,3.84999,1.11282,10,,,,,,,,,,,,,,,,,,,,,,,,,,,,,,,,,,,,,
328.054,3.84999,1.11807,10,,,,,,,,,,,,,,,,,,,,,,,,,,,,,,,,,,,,,
328.854,3.84999,1.11587,10,,,,,,,,,,,,,,,,,,,,,,,,,,,,,,,,,,,,,
329.654,3.84999,1.12062,10,,,,,,,,,,,,,,,,,,,,,,,,,,,,,,,,,,,,,
330.454,3.84999,1.16271,10,,,,,,,,,,,,,,,,,,,,,,,,,,,,,,,,,,,,,
331.254,3.84999,1.15637,10,,,,,,,,,,,,,,,,,,,,,,,,,,,,,,,,,,,,,
332.054,3.84999,1.09803,10,,,,,,,,,,,,,,,,,,,,,,,,,,,,,,,,,,,,,
332.854,3.84999,1.11871,10,,,,,,,,,,,,,,,,,,,,,,,,,,,,,,,,,,,,,
333.654,3.84988,1.12956,10,,,,,,,,,,,,,,,,,,,,,,,,,,,,,,,,,,,,,
334.454,3.84988,1.13975,10,,,,,,,,,,,,,,,,,,,,,,,,,,,,,,,,,,,,,
335.254,3.84982,1.15021,10,,,,,,,,,,,,,,,,,,,,,,,,,,,,,,,,,,,,,
336.054,3.84976,1.13564,10,,,,,,,,,,,,,,,,,,,,,,,,,,,,,,,,,,,,,
336.854,3.84976,1.12415,10,,,,,,,,,,,,,,,,,,,,,,,,,,,,,,,,,,,,,
337.654,3.84971,1.18405,10,,,,,,,,,,,,,,,,,,,,,,,,,,,,,,,,,,,,,
338.454,3.84959,1.19804,10,,,,,,,,,,,,,,,,,,,,,,,,,,,,,,,,,,,,,
339.254,3.84937,1.21394,10,,,,,,,,,,,,,,,,,,,,,,,,,,,,,,,,,,,,,
340.054,3.84823,1.18234,10,,,,,,,,,,,,,,,,,,,,,,,,,,,,,,,,,,,,,
340.854,3.84143,1.12801,10,,,,,,,,,,,,,,,,,,,,,,,,,,,,,,,,,,,,,
341.654,3.83367,1.0716,10,,,,,,,,,,,,,,,,,,,,,,,,,,,,,,,,,,,,,
342.454,3.83225,1.13988,10,,,,,,,,,,,,,,,,,,,,,,,,,,,,,,,,,,,,,
343.254,3.83203,1.13221,10,,,,,,,,,,,,,,,,,,,,,,,,,,,,,,,,,,,,,
344.054,3.83197,1.07073,10,,,,,,,,,,,,,,,,,,,,,,,,,,,,,,,,,,,,,
344.854,3.83214,1.06845,10,,,,,,,,,,,,,,,,,,,,,,,,,,,,,,,,,,,,,
345.654,3.83214,1.11738,10,,,,,,,,,,,,,,,,,,,,,,,,,,,,,,,,,,,,,
346.454,3.8322,1.09114,10,,,,,,,,,,,,,,,,,,,,,,,,,,,,,,,,,,,,,
347.254,3.83231,1.06107,10,,,,,,,,,,,,,,,,,,,,,,,,,,,,,,,,,,,,,
348.054,3.83237,1.10163,10,,,,,,,,,,,,,,,,,,,,,,,,,,,,,,,,,,,,,
348.854,3.83242,1.08961,10,,,,,,,,,,,,,,,,,,,,,,,,,,,,,,,,,,,,,
349.654,3.83254,1.08139,10,,,,,,,,,,,,,,,,,,,,,,,,,,,,,,,,,,,,,
350.454,3.83293,1.08402,10,,,,,,,,,,,,,,,,,,,,,,,,,,,,,,,,,,,,,
351.254,3.83333,1.11282,10,,,,,,,,,,,,,,,,,,,,,,,,,,,,,,,,,,,,,
352.054,3.83361,1.0932,10,,,,,,,,,,,,,,,,,,,,,,,,,,,,,,,,,,,,,
352.854,3.83435,1.08078,10,,,,,,,,,,,,,,,,,,,,,,,,,,,,,,,,,,,,,
353.654,3.83588,1.08834,10,,,,,,,,,,,,,,,,,,,,,,,,,,,,,,,,,,,,,
354.454,3.83871,1.11217,10,,,,,,,,,,,,,,,,,,,,,,,,,,,,,,,,,,,,,
355.254,3.8467,1.18965,10,,,,,,,,,,,,,,,,,,,,,,,,,,,,,,,,,,,,,
356.054,3.85968,1.15124,10,,,,,,,,,,,,,,,,,,,,,,,,,,,,,,,,,,,,,
356.854,3.86047,1.26114,10,,,,,,,,,,,,,,,,,,,,,,,,,,,,,,,,,,,,,
357.654,3.86036,1.23503,10,,,,,,,,,,,,,,,,,,,,,,,,,,,,,,,,,,,,,
358.454,3.86002,1.23209,10,,,,,,,,,,,,,,,,,,,,,,,,,,,,,,,,,,,,,
359.254,3.85787,1.21946,10,,,,,,,,,,,,,,,,,,,,,,,,,,,,,,,,,,,,,
360.054,3.84631,1.20335,10,,,,,,,,,,,,,,,,,,,,,,,,,,,,,,,,,,,,,
360.854,3.83044,1.07768,10,,,,,,,,,,,,,,,,,,,,,,,,,,,,,,,,,,,,,
361.654,3.82727,1.12518,10,,,,,,,,,,,,,,,,,,,,,,,,,,,,,,,,,,,,,
362.454,3.82676,1.14271,10,,,,,,,,,,,,,,,,,,,,,,,,,,,,,,,,,,,,,
363.254,3.82681,1.07343,10,,,,,,,,,,,,,,,,,,,,,,,,,,,,,,,,,,,,,
364.054,3.82687,1.14145,10,,,,,,,,,,,,,,,,,,,,,,,,,,,,,,,,,,,,,
364.854,3.82693,1.1024,10,,,,,,,,,,,,,,,,,,,,,,,,,,,,,,,,,,,,,
365.654,3.82704,1.08047,10,,,,,,,,,,,,,,,,,,,,,,,,,,,,,,,,,,,,,
366.454,3.8271,1.13608,10,,,,,,,,,,,,,,,,,,,,,,,,,,,,,,,,,,,,,
367.254,3.82715,1.10693,10,,,,,,,,,,,,,,,,,,,,,,,,,,,,,,,,,,,,,
368.054,3.82738,1.06471,10,,,,,,,,,,,,,,,,,,,,,,,,,,,,,,,,,,,,,
368.854,3.82772,1.06217,10,,,,,,,,,,,,,,,,,,,,,,,,,,,,,,,,,,,,,
369.654,3.82834,1.09332,10,,,,,,,,,,,,,,,,,,,,,,,,,,,,,,,,,,,,,
370.454,3.82965,1.15767,10,,,,,,,,,,,,,,,,,,,,,,,,,,,,,,,,,,,,,
371.254,3.83407,1.10291,10,,,,,,,,,,,,,,,,,,,,,,,,,,,,,,,,,,,,,
372.054,3.84347,1.14819,10,,,,,,,,,,,,,,,,,,,,,,,,,,,,,,,,,,,,,
372.854,3.85883,1.20522,10,,,,,,,,,,,,,,,,,,,,,,,,,,,,,,,,,,,,,
373.654,3.85917,1.26806,10,,,,,,,,,,,,,,,,,,,,,,,,,,,,,,,,,,,,,
374.454,3.85889,1.27747,10,,,,,,,,,,,,,,,,,,,,,,,,,,,,,,,,,,,,,
375.254,3.85849,1.23209,10,,,,,,,,,,,,,,,,,,,,,,,,,,,,,,,,,,,,,
376.054,3.85515,1.24307,10,,,,,,,,,,,,,,,,,,,,,,,,,,,,,,,,,,,,,
376.854,3.8356,1.15358,10,,,,,,,,,,,,,,,,,,,,,,,,,,,,,,,,,,,,,
377.654,3.828,1.09049,10,,,,,,,,,,,,,,,,,,,,,,,,,,,,,,,,,,,,,
378.454,3.82715,1.16751,10,,,,,,,,,,,,,,,,,,,,,,,,,,,,,,,,,,,,,
379.254,3.82693,1.14857,10,,,,,,,,,,,,,,,,,,,,,,,,,,,,,,,,,,,,,
380.054,3.82681,1.06916,10,,,,,,,,,,,,,,,,,,,,,,,,,,,,,,,,,,,,,
380.854,3.82687,1.12623,10,,,,,,,,,,,,,,,,,,,,,,,,,,,,,,,,,,,,,
381.654,3.82698,1.12494,10,,,,,,,,,,,,,,,,,,,,,,,,,,,,,,,,,,,,,
382.454,3.82704,1.11856,10,,,,,,,,,,,,,,,,,,,,,,,,,,,,,,,,,,,,,
383.254,3.8271,1.1409,10,,,,,,,,,,,,,,,,,,,,,,,,,,,,,,,,,,,,,
384.054,3.82715,1.10082,10,,,,,,,,,,,,,,,,,,,,,,,,,,,,,,,,,,,,,
384.854,3.82721,1.08118,10,,,,,,,,,,,,,,,,,,,,,,,,,,,,,,,,,,,,,
385.654,3.82727,1.09874,10,,,,,,,,,,,,,,,,,,,,,,,,,,,,,,,,,,,,,
386.454,3.82749,1.09384,10,,,,,,,,,,,,,,,,,,,,,,,,,,,,,,,,,,,,,
387.254,3.82783,1.0308,10,,,,,,,,,,,,,,,,,,,,,,,,,,,,,,,,,,,,,
388.054,3.82834,1.07446,10,,,,,,,,,,,,,,,,,,,,,,,,,,,,,,,,,,,,,
388.854,3.82965,1.11664,10,,,,,,,,,,,,,,,,,,,,,,,,,,,,,,,,,,,,,
389.654,3.83288,1.04077,10,,,,,,,,,,,,,,,,,,,,,,,,,,,,,,,,,,,,,
390.454,3.83803,1.1012,10,,,,,,,,,,,,,,,,,,,,,,,,,,,,,,,,,,,,,
391.254,3.84557,1.13418,10,,,,,,,,,,,,,,,,,,,,,,,,,,,,,,,,,,,,,
392.054,3.85832,1.22645,10,,,,,,,,,,,,,,,,,,,,,,,,,,,,,,,,,,,,,
392.854,3.85826,1.29933,10,,,,,,,,,,,,,,,,,,,,,,,,,,,,,,,,,,,,,
393.654,3.85804,1.25803,10,,,,,,,,,,,,,,,,,,,,,,,,,,,,,,,,,,,,,
394.454,3.85668,1.27217,10,,,,,,,,,,,,,,,,,,,,,,,,,,,,,,,,,,,,,
395.254,3.84625,1.22144,10,,,,,,,,,,,,,,,,,,,,,,,,,,,,,,,,,,,,,
396.054,3.82693,1.11539,10,,,,,,,,,,,,,,,,,,,,,,,,,,,,,,,,,,,,,
396.854,3.82585,1.10182,10,,,,,,,,,,,,,,,,,,,,,,,,,,,,,,,,,,,,,
397.654,3.82545,1.13123,10,,,,,,,,,,,,,,,,,,,,,,,,,,,,,,,,,,,,,
398.454,3.82534,1.10157,10,,,,,,,,,,,,,,,,,,,,,,,,,,,,,,,,,,,,,
399.254,3.82534,1.12986,10,,,,,,,,,,,,,,,,,,,,,,,,,,,,,,,,,,,,,
400.054,3.82545,1.0636,10,,,,,,,,,,,,,,,,,,,,,,,,,,,,,,,,,,,,,
400.854,3.82551,1.16787,10,,,,,,,,,,,,,,,,,,,,,,,,,,,,,,,,,,,,,
401.654,3.82551,1.11467,10,,,,,,,,,,,,,,,,,,,,,,,,,,,,,,,,,,,,,
402.454,3.82557,1.1283,10,,,,,,,,,,,,,,,,,,,,,,,,,,,,,,,,,,,,,
403.254,3.82562,1.07525,10,,,,,,,,,,,,,,,,,,,,,,,,,,,,,,,,,,,,,
404.054,3.82562,1.10997,10,,,,,,,,,,,,,,,,,,,,,,,,,,,,,,,,,,,,,
404.854,3.82568,1.15179,10,,,,,,,,,,,,,,,,,,,,,,,,,,,,,,,,,,,,,
405.654,3.82568,1.1409,10,,,,,,,,,,,,,,,,,,,,,,,,,,,,,,,,,,,,,
406.454,3.82574,1.10133,10,,,,,,,,,,,,,,,,,,,,,,,,,,,,,,,,,,,,,
407.254,3.82574,1.10093,10,,,,,,,,,,,,,,,,,,,,,,,,,,,,,,,,,,,,,
408.054,3.82574,1.05649,10,,,,,,,,,,,,,,,,,,,,,,,,,,,,,,,,,,,,,
408.854,3.82585,1.07597,10,,,,,,,,,,,,,,,,,,,,,,,,,,,,,,,,,,,,,
409.654,3.82602,1.09852,10,,,,,,,,,,,,,,,,,,,,,,,,,,,,,,,,,,,,,
410.454,3.82619,1.14439,10,,,,,,,,,,,,,,,,,,,,,,,,,,,,,,,,,,,,,
411.254,3.8263,1.07851,10,,,,,,,,,,,,,,,,,,,,,,,,,,,,,,,,,,,,,
412.054,3.82653,1.09116,10,,,,,,,,,,,,,,,,,,,,,,,,,,,,,,,,,,,,,
412.854,3.82681,1.09625,10,,,,,,,,,,,,,,,,,,,,,,,,,,,,,,,,,,,,,
413.654,3.82727,1.06348,10,,,,,,,,,,,,,,,,,,,,,,,,,,,,,,,,,,,,,
414.454,3.82789,1.10161,10,,,,,,,,,,,,,,,,,,,,,,,,,,,,,,,,,,,,,
415.254,3.82902,1.14876,10,,,,,,,,,,,,,,,,,,,,,,,,,,,,,,,,,,,,,
416.054,3.82993,1.10588,10,,,,,,,,,,,,,,,,,,,,,,,,,,,,,,,,,,,,,
416.854,3.83078,1.13422,10,,,,,,,,,,,,,,,,,,,,,,,,,,,,,,,,,,,,,
417.654,3.83123,1.14216,10,,,,,,,,,,,,,,,,,,,,,,,,,,,,,,,,,,,,,
418.454,3.83146,1.10049,10,,,,,,,,,,,,,,,,,,,,,,,,,,,,,,,,,,,,,
419.254,3.83152,1.20374,10,,,,,,,,,,,,,,,,,,,,,,,,,,,,,,,,,,,,,
420.054,3.8314,1.16553,10,,,,,,,,,,,,,,,,,,,,,,,,,,,,,,,,,,,,,
420.854,3.83135,1.13,10,,,,,,,,,,,,,,,,,,,,,,,,,,,,,,,,,,,,,
421.654,3.83123,1.22795,10,,,,,,,,,,,,,,,,,,,,,,,,,,,,,,,,,,,,,
422.454,3.83118,1.15557,10,,,,,,,,,,,,,,,,,,,,,,,,,,,,,,,,,,,,,
423.254,3.83112,1.12711,10,,,,,,,,,,,,,,,,,,,,,,,,,,,,,,,,,,,,,
424.054,3.83106,1.12306,10,,,,,,,,,,,,,,,,,,,,,,,,,,,,,,,,,,,,,
424.854,3.83095,1.22306,10,,,,,,,,,,,,,,,,,,,,,,,,,,,,,,,,,,,,,
425.654,3.83072,1.15175,10,,,,,,,,,,,,,,,,,,,,,,,,,,,,,,,,,,,,,
426.454,3.83038,1.16838,10,,,,,,,,,,,,,,,,,,,,,,,,,,,,,,,,,,,,,
427.254,3.82976,1.12474,10,,,,,,,,,,,,,,,,,,,,,,,,,,,,,,,,,,,,,
428.054,3.82897,1.16957,10,,,,,,,,,,,,,,,,,,,,,,,,,,,,,,,,,,,,,
428.854,3.82732,1.21325,10,,,,,,,,,,,,,,,,,,,,,,,,,,,,,,,,,,,,,
429.654,3.82483,1.16845,10,,,,,,,,,,,,,,,,,,,,,,,,,,,,,,,,,,,,,
430.454,3.82268,1.12009,10,,,,,,,,,,,,,,,,,,,,,,,,,,,,,,,,,,,,,
431.254,3.81967,1.16066,10,,,,,,,,,,,,,,,,,,,,,,,,,,,,,,,,,,,,,
432.054,3.81656,1.09212,10,,,,,,,,,,,,,,,,,,,,,,,,,,,,,,,,,,,,,
432.854,3.81491,1.07012,10,,,,,,,,,,,,,,,,,,,,,,,,,,,,,,,,,,,,,
433.654,3.81378,1.09255,10,,,,,,,,,,,,,,,,,,,,,,,,,,,,,,,,,,,,,
434.454,3.81361,1.12453,10,,,,,,,,,,,,,,,,,,,,,,,,,,,,,,,,,,,,,
435.254,3.81355,1.06895,10,,,,,,,,,,,,,,,,,,,,,,,,,,,,,,,,,,,,,
436.054,3.81372,1.07874,10,,,,,,,,,,,,,,,,,,,,,,,,,,,,,,,,,,,,,
436.854,3.81378,1.09261,10,,,,,,,,,,,,,,,,,,,,,,,,,,,,,,,,,,,,,
437.654,3.81384,1.0943,10,,,,,,,,,,,,,,,,,,,,,,,,,,,,,,,,,,,,,
438.454,3.81395,1.09688,10,,,,,,,,,,,,,,,,,,,,,,,,,,,,,,,,,,,,,
439.254,3.81406,1.10807,10,,,,,,,,,,,,,,,,,,,,,,,,,,,,,,,,,,,,,
440.054,3.81412,1.08147,10,,,,,,,,,,,,,,,,,,,,,,,,,,,,,,,,,,,,,
440.854,3.8144,1.11844,10,,,,,,,,,,,,,,,,,,,,,,,,,,,,,,,,,,,,,
441.654,3.81457,1.13341,10,,,,,,,,,,,,,,,,,,,,,,,,,,,,,,,,,,,,,
442.454,3.81474,1.06392,10,,,,,,,,,,,,,,,,,,,,,,,,,,,,,,,,,,,,,
443.254,3.81503,1.09608,10,,,,,,,,,,,,,,,,,,,,,,,,,,,,,,,,,,,,,
444.054,3.81548,1.08143,10,,,,,,,,,,,,,,,,,,,,,,,,,,,,,,,,,,,,,
444.854,3.81616,1.1084,10,,,,,,,,,,,,,,,,,,,,,,,,,,,,,,,,,,,,,
445.654,3.8182,1.12908,10,,,,,,,,,,,,,,,,,,,,,,,,,,,,,,,,,,,,,
446.454,3.82126,1.09493,10,,,,,,,,,,,,,,,,,,,,,,,,,,,,,,,,,,,,,
447.254,3.82744,1.1104,10,,,,,,,,,,,,,,,,,,,,,,,,,,,,,,,,,,,,,
448.054,3.83004,1.15836,10,,,,,,,,,,,,,,,,,,,,,,,,,,,,,,,,,,,,,
448.854,3.83033,1.16093,10,,,,,,,,,,,,,,,,,,,,,,,,,,,,,,,,,,,,,
449.654,3.83016,1.15009,10,,,,,,,,,,,,,,,,,,,,,,,,,,,,,,,,,,,,,
450.454,3.8301,1.16975,10,,,,,,,,,,,,,,,,,,,,,,,,,,,,,,,,,,,,,
451.254,3.82993,1.20174,10,,,,,,,,,,,,,,,,,,,,,,,,,,,,,,,,,,,,,
452.054,3.82976,1.1818,10,,,,,,,,,,,,,,,,,,,,,,,,,,,,,,,,,,,,,
452.854,3.82885,1.23125,10,,,,,,,,,,,,,,,,,,,,,,,,,,,,,,,,,,,,,
453.654,3.82721,1.18602,10,,,,,,,,,,,,,,,,,,,,,,,,,,,,,,,,,,,,,
454.454,3.82426,1.15886,10,,,,,,,,,,,,,,,,,,,,,,,,,,,,,,,,,,,,,
455.254,3.81939,1.16667,10,,,,,,,,,,,,,,,,,,,,,,,,,,,,,,,,,,,,,
456.054,3.81622,1.14973,10,,,,,,,,,,,,,,,,,,,,,,,,,,,,,,,,,,,,,
456.854,3.81423,1.11798,10,,,,,,,,,,,,,,,,,,,,,,,,,,,,,,,,,,,,,
457.654,3.8131,1.17916,10,,,,,,,,,,,,,,,,,,,,,,,,,,,,,,,,,,,,,
458.454,3.81197,1.11518,10,,,,,,,,,,,,,,,,,,,,,,,,,,,,,,,,,,,,,
459.254,3.81134,1.10634,10,,,,,,,,,,,,,,,,,,,,,,,,,,,,,,,,,,,,,
460.054,3.81066,1.13744,10,,,,,,,,,,,,,,,,,,,,,,,,,,,,,,,,,,,,,
460.854,3.81021,1.10335,10,,,,,,,,,,,,,,,,,,,,,,,,,,,,,,,,,,,,,
461.654,3.80987,1.15333,10,,,,,,,,,,,,,,,,,,,,,,,,,,,,,,,,,,,,,
462.454,3.8097,1.1155,10,,,,,,,,,,,,,,,,,,,,,,,,,,,,,,,,,,,,,
463.254,3.80959,1.07098,10,,,,,,,,,,,,,,,,,,,,,,,,,,,,,,,,,,,,,
464.054,3.80976,1.07972,10,,,,,,,,,,,,,,,,,,,,,,,,,,,,,,,,,,,,,
464.854,3.80981,1.13329,10,,,,,,,,,,,,,,,,,,,,,,,,,,,,,,,,,,,,,
465.654,3.80987,1.08567,10,,,,,,,,,,,,,,,,,,,,,,,,,,,,,,,,,,,,,
466.454,3.80987,1.10977,10,,,,,,,,,,,,,,,,,,,,,,,,,,,,,,,,,,,,,
467.254,3.80998,1.09146,10,,,,,,,,,,,,,,,,,,,,,,,,,,,,,,,,,,,,,
468.054,3.80998,1.14523,10,,,,,,,,,,,,,,,,,,,,,,,,,,,,,,,,,,,,,
468.854,3.81004,1.0666,10,,,,,,,,,,,,,,,,,,,,,,,,,,,,,,,,,,,,,
469.654,3.81004,1.14598,10,,,,,,,,,,,,,,,,,,,,,,,,,,,,,,,,,,,,,
470.454,3.81004,1.14389,10,,,,,,,,,,,,,,,,,,,,,,,,,,,,,,,,,,,,,
471.254,3.8101,1.06402,10,,,,,,,,,,,,,,,,,,,,,,,,,,,,,,,,,,,,,
472.054,3.8101,1.14181,10,,,,,,,,,,,,,,,,,,,,,,,,,,,,,,,,,,,,,
472.854,3.81015,1.07432,10,,,,,,,,,,,,,,,,,,,,,,,,,,,,,,,,,,,,,
473.654,3.81038,1.13512,10,,,,,,,,,,,,,,,,,,,,,,,,,,,,,,,,,,,,,
474.454,3.81055,1.12573,10,,,,,,,,,,,,,,,,,,,,,,,,,,,,,,,,,,,,,
475.254,3.81078,1.11258,10,,,,,,,,,,,,,,,,,,,,,,,,,,,,,,,,,,,,,
476.054,3.81117,1.10048,10,,,,,,,,,,,,,,,,,,,,,,,,,,,,,,,,,,,,,
476.854,3.81151,1.16779,10,,,,,,,,,,,,,,,,,,,,,,,,,,,,,,,,,,,,,
477.654,3.81225,1.12643,10,,,,,,,,,,,,,,,,,,,,,,,,,,,,,,,,,,,,,
478.454,3.81338,1.03575,10,,,,,,,,,,,,,,,,,,,,,,,,,,,,,,,,,,,,,
479.254,3.81508,1.11426,10,,,,,,,,,,,,,,,,,,,,,,,,,,,,,,,,,,,,,
480.054,3.8186,1.12505,10,,,,,,,,,,,,,,,,,,,,,,,,,,,,,,,,,,,,,
480.854,3.82574,1.12546,10,,,,,,,,,,,,,,,,,,,,,,,,,,,,,,,,,,,,,
481.654,3.82936,1.20079,10,,,,,,,,,,,,,,,,,,,,,,,,,,,,,,,,,,,,,
482.454,3.8297,1.17336,10,,,,,,,,,,,,,,,,,,,,,,,,,,,,,,,,,,,,,
483.254,3.82965,1.14137,10,,,,,,,,,,,,,,,,,,,,,,,,,,,,,,,,,,,,,
484.054,3.82959,1.1899,10,,,,,,,,,,,,,,,,,,,,,,,,,,,,,,,,,,,,,
484.854,3.82948,1.14861,10,,,,,,,,,,,,,,,,,,,,,,,,,,,,,,,,,,,,,
485.654,3.82936,1.13016,10,,,,,,,,,,,,,,,,,,,,,,,,,,,,,,,,,,,,,
486.454,3.82914,1.19764,10,,,,,,,,,,,,,,,,,,,,,,,,,,,,,,,,,,,,,
487.254,3.8284,1.20121,10,,,,,,,,,,,,,,,,,,,,,,,,,,,,,,,,,,,,,
488.054,3.8263,1.19235,10,,,,,,,,,,,,,,,,,,,,,,,,,,,,,,,,,,,,,
488.854,3.82245,1.19055,10,,,,,,,,,,,,,,,,,,,,,,,,,,,,,,,,,,,,,
489.654,3.81758,1.15443,10,,,,,,,,,,,,,,,,,,,,,,,,,,,,,,,,,,,,,
490.454,3.81508,1.08775,10,,,,,,,,,,,,,,,,,,,,,,,,,,,,,,,,,,,,,
491.254,3.81389,1.14817,10,,,,,,,,,,,,,,,,,,,,,,,,,,,,,,,,,,,,,
492.054,3.8135,1.15718,10,,,,,,,,,,,,,,,,,,,,,,,,,,,,,,,,,,,,,
492.854,3.81327,1.09511,10,,,,,,,,,,,,,,,,,,,,,,,,,,,,,,,,,,,,,
493.654,3.81321,1.13506,10,,,,,,,,,,,,,,,,,,,,,,,,,,,,,,,,,,,,,
494.454,3.81316,1.06191,10,,,,,,,,,,,,,,,,,,,,,,,,,,,,,,,,,,,,,
495.254,3.81327,1.09576,10,,,,,,,,,,,,,,,,,,,,,,,,,,,,,,,,,,,,,
496.054,3.81327,1.13821,10,,,,,,,,,,,,,,,,,,,,,,,,,,,,,,,,,,,,,
496.854,3.81333,1.09732,10,,,,,,,,,,,,,,,,,,,,,,,,,,,,,,,,,,,,,
497.654,3.81333,1.08151,10,,,,,,,,,,,,,,,,,,,,,,,,,,,,,,,,,,,,,
498.454,3.81333,1.14555,10,,,,,,,,,,,,,,,,,,,,,,,,,,,,,,,,,,,,,
499.254,3.81338,1.10656,10,,,,,,,,,,,,,,,,,,,,,,,,,,,,,,,,,,,,,
500.054,3.81338,1.11678,10,,,,,,,,,,,,,,,,,,,,,,,,,,,,,,,,,,,,,
500.854,3.8135,1.10647,10,,,,,,,,,,,,,,,,,,,,,,,,,,,,,,,,,,,,,
501.654,3.8135,1.10115,10,,,,,,,,,,,,,,,,,,,,,,,,,,,,,,,,,,,,,
502.454,3.81344,1.09491,10,,,,,,,,,,,,,,,,,,,,,,,,,,,,,,,,,,,,,
503.254,3.81355,1.15274,10,,,,,,,,,,,,,,,,,,,,,,,,,,,,,,,,,,,,,
504.054,3.81361,1.09673,10,,,,,,,,,,,,,,,,,,,,,,,,,,,,,,,,,,,,,
504.854,3.81372,1.07211,10,,,,,,,,,,,,,,,,,,,,,,,,,,,,,,,,,,,,,
505.654,3.81384,1.08149,10,,,,,,,,,,,,,,,,,,,,,,,,,,,,,,,,,,,,,
506.454,3.81395,1.14346,10,,,,,,,,,,,,,,,,,,,,,,,,,,,,,,,,,,,,,
507.254,3.81406,1.09598,10,,,,,,,,,,,,,,,,,,,,,,,,,,,,,,,,,,,,,
508.054,3.81412,1.11131,10,,,,,,,,,,,,,,,,,,,,,,,,,,,,,,,,,,,,,
508.854,3.81429,1.10646,10,,,,,,,,,,,,,,,,,,,,,,,,,,,,,,,,,,,,,
509.654,3.81463,1.10753,10,,,,,,,,,,,,,,,,,,,,,,,,,,,,,,,,,,,,,
510.454,3.81486,1.08577,10,,,,,,,,,,,,,,,,,,,,,,,,,,,,,,,,,,,,,
511.254,3.81571,1.08825,10,,,,,,,,,,,,,,,,,,,,,,,,,,,,,,,,,,,,,
512.054,3.81786,1.06991,10,,,,,,,,,,,,,,,,,,,,,,,,,,,,,,,,,,,,,
512.854,3.82137,1.10739,10,,,,,,,,,,,,,,,,,,,,,,,,,,,,,,,,,,,,,
513.654,3.82817,1.18499,10,,,,,,,,,,,,,,,,,,,,,,,,,,,,,,,,,,,,,
514.454,3.83033,1.17117,10,,,,,,,,,,,,,,,,,,,,,,,,,,,,,,,,,,,,,
515.254,3.83055,1.20003,10,,,,,,,,,,,,,,,,,,,,,,,,,,,,,,,,,,,,,
516.054,3.83038,1.21086,10,,,,,,,,,,,,,,,,,,,,,,,,,,,,,,,,,,,,,
516.854,3.83033,1.15938,10,,,,,,,,,,,,,,,,,,,,,,,,,,,,,,,,,,,,,
517.654,3.83027,1.1651,10,,,,,,,,,,,,,,,,,,,,,,,,,,,,,,,,,,,,,
518.454,3.83021,1.1522,10,,,,,,,,,,,,,,,,,,,,,,,,,,,,,,,,,,,,,
519.254,3.8301,1.12384,10,,,,,,,,,,,,,,,,,,,,,,,,,,,,,,,,,,,,,
520.054,3.8297,1.20777,10,,,,,,,,,,,,,,,,,,,,,,,,,,,,,,,,,,,,,
520.854,3.828,1.23005,10,,,,,,,,,,,,,,,,,,,,,,,,,,,,,,,,,,,,,
521.654,3.82511,1.14668,10,,,,,,,,,,,,,,,,,,,,,,,,,,,,,,,,,,,,,
522.454,3.82047,1.1371,10,,,,,,,,,,,,,,,,,,,,,,,,,,,,,,,,,,,,,
523.254,3.81712,1.13025,10,,,,,,,,,,,,,,,,,,,,,,,,,,,,,,,,,,,,,
524.054,3.81588,1.14232,10,,,,,,,,,,,,,,,,,,,,,,,,,,,,,,,,,,,,,
524.854,3.81491,1.15329,10,,,,,,,,,,,,,,,,,,,,,,,,,,,,,,,,,,,,,
525.654,3.81429,1.12139,10,,,,,,,,,,,,,,,,,,,,,,,,,,,,,,,,,,,,,
526.454,3.81384,1.12035,10,,,,,,,,,,,,,,,,,,,,,,,,,,,,,,,,,,,,,
527.254,3.81361,1.11542,10,,,,,,,,,,,,,,,,,,,,,,,,,,,,,,,,,,,,,
528.054,3.81344,1.11899,10,,,,,,,,,,,,,,,,,,,,,,,,,,,,,,,,,,,,,
528.854,3.8135,1.03602,10,,,,,,,,,,,,,,,,,,,,,,,,,,,,,,,,,,,,,
529.654,3.8135,1.13086,10,,,,,,,,,,,,,,,,,,,,,,,,,,,,,,,,,,,,,
530.454,3.8135,1.10423,10,,,,,,,,,,,,,,,,,,,,,,,,,,,,,,,,,,,,,
531.254,3.81344,1.09474,10,,,,,,,,,,,,,,,,,,,,,,,,,,,,,,,,,,,,,
532.054,3.81355,1.1086,10,,,,,,,,,,,,,,,,,,,,,,,,,,,,,,,,,,,,,
532.854,3.81361,1.09862,10,,,,,,,,,,,,,,,,,,,,,,,,,,,,,,,,,,,,,
533.654,3.81367,1.09966,10,,,,,,,,,,,,,,,,,,,,,,,,,,,,,,,,,,,,,
534.454,3.81372,1.11012,10,,,,,,,,,,,,,,,,,,,,,,,,,,,,,,,,,,,,,
535.254,3.81372,1.14254,10,,,,,,,,,,,,,,,,,,,,,,,,,,,,,,,,,,,,,
536.054,3.81384,1.0674,10,,,,,,,,,,,,,,,,,,,,,,,,,,,,,,,,,,,,,
536.854,3.81389,1.13907,10,,,,,,,,,,,,,,,,,,,,,,,,,,,,,,,,,,,,,
537.654,3.81395,1.11088,10,,,,,,,,,,,,,,,,,,,,,,,,,,,,,,,,,,,,,
538.454,3.81401,1.08095,10,,,,,,,,,,,,,,,,,,,,,,,,,,,,,,,,,,,,,
539.254,3.81412,1.13417,10,,,,,,,,,,,,,,,,,,,,,,,,,,,,,,,,,,,,,
540.054,3.81423,1.07585,10,,,,,,,,,,,,,,,,,,,,,,,,,,,,,,,,,,,,,
540.854,3.81446,1.06002,10,,,,,,,,,,,,,,,,,,,,,,,,,,,,,,,,,,,,,
541.654,3.81469,1.14977,10,,,,,,,,,,,,,,,,,,,,,,,,,,,,,,,,,,,,,
542.454,3.81497,1.0962,10,,,,,,,,,,,,,,,,,,,,,,,,,,,,,,,,,,,,,
543.254,3.81565,1.04796,10,,,,,,,,,,,,,,,,,,,,,,,,,,,,,,,,,,,,,
544.054,3.81707,1.11928,10,,,,,,,,,,,,,,,,,,,,,,,,,,,,,,,,,,,,,
544.854,3.81962,1.12817,10,,,,,,,,,,,,,,,,,,,,,,,,,,,,,,,,,,,,,
545.654,3.82211,1.12376,10,,,,,,,,,,,,,,,,,,,,,,,,,,,,,,,,,,,,,
546.454,3.82585,1.1582,10,,,,,,,,,,,,,,,,,,,,,,,,,,,,,,,,,,,,,
547.254,3.82749,1.15866,10,,,,,,,,,,,,,,,,,,,,,,,,,,,,,,,,,,,,,
548.054,3.82789,1.1052,10,,,,,,,,,,,,,,,,,,,,,,,,,,,,,,,,,,,,,
548.854,3.828,1.19228,10,,,,,,,,,,,,,,,,,,,,,,,,,,,,,,,,,,,,,
549.654,3.82789,1.18055,10,,,,,,,,,,,,,,,,,,,,,,,,,,,,,,,,,,,,,
550.454,3.82778,1.20591,10,,,,,,,,,,,,,,,,,,,,,,,,,,,,,,,,,,,,,
551.254,3.82766,1.20387,10,,,,,,,,,,,,,,,,,,,,,,,,,,,,,,,,,,,,,
552.054,3.82755,1.15892,10,,,,,,,,,,,,,,,,,,,,,,,,,,,,,,,,,,,,,
552.854,3.82732,1.18616,10,,,,,,,,,,,,,,,,,,,,,,,,,,,,,,,,,,,,,
553.654,3.82619,1.16586,10,,,,,,,,,,,,,,,,,,,,,,,,,,,,,,,,,,,,,
554.454,3.82404,1.19525,10,,,,,,,,,,,,,,,,,,,,,,,,,,,,,,,,,,,,,
555.254,3.8199,1.12188,10,,,,,,,,,,,,,,,,,,,,,,,,,,,,,,,,,,,,,
556.054,3.81684,1.16105,10,,,,,,,,,,,,,,,,,,,,,,,,,,,,,,,,,,,,,
556.854,3.81463,1.14718,10,,,,,,,,,,,,,,,,,,,,,,,,,,,,,,,,,,,,,
557.654,3.81316,1.07761,10,,,,,,,,,,,,,,,,,,,,,,,,,,,,,,,,,,,,,
558.454,3.81231,1.16407,10,,,,,,,,,,,,,,,,,,,,,,,,,,,,,,,,,,,,,
559.254,3.8118,1.14863,10,,,,,,,,,,,,,,,,,,,,,,,,,,,,,,,,,,,,,
560.054,3.81123,1.12662,10,,,,,,,,,,,,,,,,,,,,,,,,,,,,,,,,,,,,,
560.854,3.81083,1.17542,10,,,,,,,,,,,,,,,,,,,,,,,,,,,,,,,,,,,,,
561.654,3.81072,1.07158,10,,,,,,,,,,,,,,,,,,,,,,,,,,,,,,,,,,,,,
562.454,3.81089,1.0534,10,,,,,,,,,,,,,,,,,,,,,,,,,,,,,,,,,,,,,
563.254,3.81089,1.08253,10,,,,,,,,,,,,,,,,,,,,,,,,,,,,,,,,,,,,,
564.054,3.81089,1.10901,10,,,,,,,,,,,,,,,,,,,,,,,,,,,,,,,,,,,,,
564.756,5.13474,12.16686,10,,,,,,,,,,,,,,,,,,,,,,,,,,,,,,,,,,,,,
565.556,11.81086,545.89709,10,,,,,,,,,,,,,,,,,,,,,,,,,,,,,,,,,,,,,
566.356,18.47758,80.05363,10,,,,,,,,,,,,,,,,,,,,,,,,,,,,,,,,,,,,,
567.156,25.14436,45.71188,10,,,,,,,,,,,,,,,,,,,,,,,,,,,,,,,,,,,,,
567.956,31.81091,16.55732,10,,,,,,,,,,,,,,,,,,,,,,,,,,,,,,,,,,,,,
568.756,38.47757,3.39404,10,,,,,,,,,,,,,,,,,,,,,,,,,,,,,,,,,,,,,
569.556,45.14429,0.50426,10,,,,,,,,,,,,,,,,,,,,,,,,,,,,,,,,,,,,,
570.356,51.81095,0.38922,10,,,,,,,,,,,,,,,,,,,,,,,,,,,,,,,,,,,,,
571.156,58.47756,0.40594,10,,,,,,,,,,,,,,,,,,,,,,,,,,,,,,,,,,,,,
571.902,64.69428,0.39563,10,,,,,,,,,,,,,,,,,,,,,,,,,,,,,,,,,,,,,