File: combined_ligament_solver/data/processed/Data Sheet 3_S160798_ACL.csv
Specimen properties : Length,41,mm,Unnamed: 3,Unnamed: 4,Unnamed: 5,Unnamed: 6,Unnamed: 7,Unnamed: 8,Unnamed: 9,Unnamed: 10,Unnamed: 11,Stress-Strain,Unnamed: 13,Unnamed: 14,Unnamed: 15,Unnamed: 16,Unnamed: 17,Unnamed: 18,Unnamed: 19,Unnamed: 20,Unnamed: 21,Unnamed: 22,Unnamed: 23,Unnamed: 24,Unnamed: 25,Unnamed: 26,Unnamed: 27,Linear,Unnamed: 29,Unnamed: 30,Unnamed: 31,Unnamed: 32,Unnamed: 33,Modulus,Unnamed: 35,Failure,Unnamed: 37,Unnamed: 38,Unnamed: 39,Unnamed: 40
Cross Section Average,95.79249999999999,mm2,,,,,,,,,,Polynomial Coefficients,,,,,,,,,,,,,,,,Force,,Stress,Extension,Strain,,Secant,Tangent,Load,Stress,Extension,Strain,Stiffness
Time,Extension,Load,Total cycle count,,,Extension,Load,Strain,Stress,E-tan,,X6,63212.49394816189,,,,,,,,,Strain,Stress,E-tan,,,,(N),,(MPa),(mm),(%),,(MPa),(MPa),(N),(MPa),(mm),(%),(N/mm)
(s),(mm),(N),,,,(mm),(N),(mm/mm),(MPa),(MPa),,X5,101309.14030995575,,,,,,,,,(mm/mm),(MPa),(MPa),,,,112.84188199228797,,1.1779824306943443,3.772,9.2,,12.804156855373309,25.096752878732005,205.60124,2.1371250358848557,5.61658,13.698975609756097,29.915663306545063
0.7,1.58225,1.16857,0,,,7.80272,205.60124,0.13698975609756098,2.1371250358848557,,,,,,,,,,,,,0.007,0.011252474566167004,1.1259889248162456,,,,,,,,,,,,,,,,
1.5,1.71581,1.38333,0,,,14.46949,664.31085,,,,,,,,,,,,,,,0.015,0.020241293094872666,1.3844504847941073,,,,,,,,,,,,,,,,
2.3,1.84903,1.6676,0,,,21.13621,134.50043,,,,,,,,,,,,,,,0.023,0.03855457315312649,3.17922732378961,,,,,,,,,,,,,,,,
3.1,1.9822,2.01892,0,,,,,,,,,,,,,,,,,,,0.031,0.0762128473344272,6.013642088003488,,,,,,,,,,,,,,,,
3.9,2.11576,2.45083,0,,,,,,,,,,,,,,,,,,,0.039,0.1395052054488768,9.445007369960004,,,,,,,,,,,,,,,,
4.7,2.24893,2.99889,0,,,,,,,,,,,,,,,,,,,0.047,0.23142792525805495,13.086117078348213,,,,,,,,,,,,,,,,
5.5,2.38227,3.83449,0,,,,,,,,,,,,,,,,,,,0.055,0.35213503416862235,16.606737807863077,,,,,,,,,,,,,,,,
6.3,2.51577,4.74388,0,,,,,,,,,,,,,,,,,,,0.063,0.4994008018846555,19.73510020904721,,,,,,,,,,,,,,,,
7.1,2.64894,5.8844,0,,,,,,,,,,,,,,,,,,,0.071,0.6690941640187082,22.259390358131142,,,,,,,,,,,,,,,,
7.9,2.78233,7.10275,0,,,,,,,,,,,,,,,,,,,0.079,0.8556650766616071,24.029241126875966,,,,,,,,,,,,,,,,
8.7,2.91573,8.59676,0,,,,,,,,,,,,,,,,,,,0.087,1.0526428019109701,24.9572235524109,,,,,,,,,,,,,,,,
9.5,3.04889,10.34369,0,,,,,,,,,,,,,,,,,,,0.095,1.2531461243584683,25.0203382070828,,,,,,,,,,,,,,,,
10.3,3.1824,12.1581,0,,,,,,,,,,,,,,,,,,,0.103,1.4504054985357948,24.261506568285604,,,,,,,,,,,,,,,,
11.1,3.31574,13.91595,0,,,,,,,,,,,,,,,,,,,0.111,1.6382971273193911,22.791062388314277,,,,,,,,,,,,,,,,
11.9,3.4489,16.43169,0,,,,,,,,,,,,,,,,,,,0.119,1.8118889712938755,20.788243064191672,,,,,,,,,,,,,,,,
12.7,3.58252,18.85012,0,,,,,,,,,,,,,,,,,,,0.127,1.967998689074226,18.502681007521485,,,,,,,,,,,,,,,,
13.5,3.71569,21.61044,0,,,,,,,,,,,,,,,,,,,0.135,2.10576350858668,16.255895014335202,,,,,,,,,,,,,,,,
14.3,3.84886,25.10135,0,,,,,,,,,,,,,,,,,,,0.143,2.2272220293083502,14.442781634897525,,,,,,,,,,,,,,,,
15.1,3.98248,28.78457,0,,,,,,,,,,,,,,,,,,,0.151,,,,,,,,,,,,,,,,,,
15.9,4.11564,32.67572,0,,,,,,,,,,,,,,,,,,,0.159,,,,,,,,,,,,,,,,,,
16.7,4.24892,37.00196,0,,,,,,,,,,,,,,,,,,,0.167,,,,,,,,,,,,,,,,,,
17.39,4.29743,38.15473,0.5,,,,,,,,,,,,,,,,,,,0.175,,,,,,,,,,,,,,,,,,
18.19,4.16381,31.32557,0.5,,,,,,,,,,,,,,,,,,,0.183,,,,,,,,,,,,,,,,,,
18.99,4.03042,25.96683,0.5,,,,,,,,,,,,,,,,,,,0.191,,,,,,,,,,,,,,,,,,
19.79,3.89697,21.42695,0.5,,,,,,,,,,,,,,,,,,,0.199,,,,,,,,,,,,,,,,,,
20.59,3.76369,17.62888,0.5,,,,,,,,,,,,,,,,,,,,,,,,,,,,,,,,,,,,,
21.39,3.63035,14.47037,0.5,,,,,,,,,,,,,,,,,,,,,,,,,,,,,,,,,,,,,
22.19,3.49701,11.87652,0.5,,,,,,,,,,,,,,,,,,,,,,,,,,,,,,,,,,,,,
22.99,3.36368,9.55241,0.5,,,,,,,,,,,,,,,,,,,,,,,,,,,,,,,,,,,,,
23.79,3.23028,7.57601,0.5,,,,,,,,,,,,,,,,,,,,,,,,,,,,,,,,,,,,,
24.59,3.097,5.98293,0.5,,,,,,,,,,,,,,,,,,,,,,,,,,,,,,,,,,,,,
25.39,2.96378,4.63417,0.5,,,,,,,,,,,,,,,,,,,,,,,,,,,,,,,,,,,,,
26.19,2.83022,3.66877,0.5,,,,,,,,,,,,,,,,,,,,,,,,,,,,,,,,,,,,,
26.99,2.69699,2.71917,0.5,,,,,,,,,,,,,,,,,,,,,,,,,,,,,,,,,,,,,
27.79,2.56377,2.10072,0.5,,,,,,,,,,,,,,,,,,,,,,,,,,,,,,,,,,,,,
28.59,2.43021,1.73314,0.5,,,,,,,,,,,,,,,,,,,,,,,,,,,,,,,,,,,,,
29.39,2.2971,1.37025,0.5,,,,,,,,,,,,,,,,,,,,,,,,,,,,,,,,,,,,,
30.19,2.16376,1.09669,0.5,,,,,,,,,,,,,,,,,,,,,,,,,,,,,,,,,,,,,
30.774,2.20059,1.22466,1,,,,,,,,,,,,,,,,,,,,,,,,,,,,,,,,,,,,,
31.574,2.3341,1.63659,1,,,,,,,,,,,,,,,,,,,,,,,,,,,,,,,,,,,,,
32.374,2.46727,2.17224,1,,,,,,,,,,,,,,,,,,,,,,,,,,,,,,,,,,,,,
33.174,2.6006,2.92477,1,,,,,,,,,,,,,,,,,,,,,,,,,,,,,,,,,,,,,
33.974,2.73411,3.77955,1,,,,,,,,,,,,,,,,,,,,,,,,,,,,,,,,,,,,,
34.774,2.86722,4.91414,1,,,,,,,,,,,,,,,,,,,,,,,,,,,,,,,,,,,,,
35.574,3.00067,6.26292,1,,,,,,,,,,,,,,,,,,,,,,,,,,,,,,,,,,,,,
36.374,3.13412,7.81215,1,,,,,,,,,,,,,,,,,,,,,,,,,,,,,,,,,,,,,
37.174,3.26729,9.73625,1,,,,,,,,,,,,,,,,,,,,,,,,,,,,,,,,,,,,,
37.974,3.40068,12.03466,1,,,,,,,,,,,,,,,,,,,,,,,,,,,,,,,,,,,,,
38.774,3.53402,14.54609,1,,,,,,,,,,,,,,,,,,,,,,,,,,,,,,,,,,,,,
39.574,3.6673,17.42839,1,,,,,,,,,,,,,,,,,,,,,,,,,,,,,,,,,,,,,
40.374,3.80069,20.89336,1,,,,,,,,,,,,,,,,,,,,,,,,,,,,,,,,,,,,,
41.174,3.93397,24.55459,1,,,,,,,,,,,,,,,,,,,,,,,,,,,,,,,,,,,,,
41.974,4.06731,28.33524,1,,,,,,,,,,,,,,,,,,,,,,,,,,,,,,,,,,,,,
42.774,4.20076,32.93436,1,,,,,,,,,,,,,,,,,,,,,,,,,,,,,,,,,,,,,
43.574,4.33398,38.02966,1,,,,,,,,,,,,,,,,,,,,,,,,,,,,,,,,,,,,,
44.258,4.31437,36.28863,1.5,,,,,,,,,,,,,,,,,,,,,,,,,,,,,,,,,,,,,
45.058,4.18104,29.97729,1.5,,,,,,,,,,,,,,,,,,,,,,,,,,,,,,,,,,,,,
45.858,4.0477,24.74556,1.5,,,,,,,,,,,,,,,,,,,,,,,,,,,,,,,,,,,,,
46.658,3.91431,20.46626,1.5,,,,,,,,,,,,,,,,,,,,,,,,,,,,,,,,,,,,,
47.458,3.78103,16.84724,1.5,,,,,,,,,,,,,,,,,,,,,,,,,,,,,,,,,,,,,
48.258,3.64769,13.93337,1.5,,,,,,,,,,,,,,,,,,,,,,,,,,,,,,,,,,,,,
49.058,3.5143,11.28767,1.5,,,,,,,,,,,,,,,,,,,,,,,,,,,,,,,,,,,,,
49.858,3.38102,9.13803,1.5,,,,,,,,,,,,,,,,,,,,,,,,,,,,,,,,,,,,,
50.658,3.24774,7.25466,1.5,,,,,,,,,,,,,,,,,,,,,,,,,,,,,,,,,,,,,
51.458,3.11423,5.66251,1.5,,,,,,,,,,,,,,,,,,,,,,,,,,,,,,,,,,,,,
52.258,2.98106,4.44478,1.5,,,,,,,,,,,,,,,,,,,,,,,,,,,,,,,,,,,,,
53.058,2.84773,3.35642,1.5,,,,,,,,,,,,,,,,,,,,,,,,,,,,,,,,,,,,,
53.858,2.71428,2.50714,1.5,,,,,,,,,,,,,,,,,,,,,,,,,,,,,,,,,,,,,
54.658,2.58105,2.06984,1.5,,,,,,,,,,,,,,,,,,,,,,,,,,,,,,,,,,,,,
55.458,2.44772,1.60766,1.5,,,,,,,,,,,,,,,,,,,,,,,,,,,,,,,,,,,,,
56.258,2.31427,1.34296,1.5,,,,,,,,,,,,,,,,,,,,,,,,,,,,,,,,,,,,,
56.978,2.19436,0.99571,2,,,,,,,,,,,,,,,,,,,,,,,,,,,,,,,,,,,,,
57.582,2.2946,1.32843,2,,,,,,,,,,,,,,,,,,,,,,,,,,,,,,,,,,,,,
58.382,2.428,1.83204,2,,,,,,,,,,,,,,,,,,,,,,,,,,,,,,,,,,,,,
59.182,2.56139,2.43148,2,,,,,,,,,,,,,,,,,,,,,,,,,,,,,,,,,,,,,
59.982,2.69461,3.09543,2,,,,,,,,,,,,,,,,,,,,,,,,,,,,,,,,,,,,,
60.782,2.82795,4.14538,2,,,,,,,,,,,,,,,,,,,,,,,,,,,,,,,,,,,,,
61.582,2.96146,5.25417,2,,,,,,,,,,,,,,,,,,,,,,,,,,,,,,,,,,,,,
62.382,3.09462,6.66918,2,,,,,,,,,,,,,,,,,,,,,,,,,,,,,,,,,,,,,
63.182,3.22796,8.4471,2,,,,,,,,,,,,,,,,,,,,,,,,,,,,,,,,,,,,,
63.982,3.36141,10.55801,2,,,,,,,,,,,,,,,,,,,,,,,,,,,,,,,,,,,,,
64.782,3.49463,12.93919,2,,,,,,,,,,,,,,,,,,,,,,,,,,,,,,,,,,,,,
65.582,3.62797,15.55993,2,,,,,,,,,,,,,,,,,,,,,,,,,,,,,,,,,,,,,
66.382,3.76136,18.70148,2,,,,,,,,,,,,,,,,,,,,,,,,,,,,,,,,,,,,,
67.182,3.89464,22.24775,2,,,,,,,,,,,,,,,,,,,,,,,,,,,,,,,,,,,,,
67.982,4.02804,26.22984,2,,,,,,,,,,,,,,,,,,,,,,,,,,,,,,,,,,,,,
68.782,4.16132,30.28143,2,,,,,,,,,,,,,,,,,,,,,,,,,,,,,,,,,,,,,
69.582,4.29465,35.06367,2,,,,,,,,,,,,,,,,,,,,,,,,,,,,,,,,,,,,,
70.312,4.41626,40.01378,2.5,,,,,,,,,,,,,,,,,,,,,,,,,,,,,,,,,,,,,
71.014,4.29964,33.83078,2.5,,,,,,,,,,,,,,,,,,,,,,,,,,,,,,,,,,,,,
71.814,4.16647,27.92712,2.5,,,,,,,,,,,,,,,,,,,,,,,,,,,,,,,,,,,,,
72.614,4.03308,23.10155,2.5,,,,,,,,,,,,,,,,,,,,,,,,,,,,,,,,,,,,,
73.414,3.89963,19.0615,2.5,,,,,,,,,,,,,,,,,,,,,,,,,,,,,,,,,,,,,
74.214,3.76635,15.77151,2.5,,,,,,,,,,,,,,,,,,,,,,,,,,,,,,,,,,,,,
75.014,3.63301,13.02268,2.5,,,,,,,,,,,,,,,,,,,,,,,,,,,,,,,,,,,,,
75.814,3.49962,10.45335,2.5,,,,,,,,,,,,,,,,,,,,,,,,,,,,,,,,,,,,,
76.614,3.36634,8.38265,2.5,,,,,,,,,,,,,,,,,,,,,,,,,,,,,,,,,,,,,
77.414,3.233,6.61658,2.5,,,,,,,,,,,,,,,,,,,,,,,,,,,,,,,,,,,,,
78.214,3.09967,5.13662,2.5,,,,,,,,,,,,,,,,,,,,,,,,,,,,,,,,,,,,,
79.014,2.96639,3.9102,2.5,,,,,,,,,,,,,,,,,,,,,,,,,,,,,,,,,,,,,
79.814,2.83299,3.0258,2.5,,,,,,,,,,,,,,,,,,,,,,,,,,,,,,,,,,,,,
80.614,2.69966,2.29946,2.5,,,,,,,,,,,,,,,,,,,,,,,,,,,,,,,,,,,,,
81.414,2.56638,1.85154,2.5,,,,,,,,,,,,,,,,,,,,,,,,,,,,,,,,,,,,,
82.214,2.43293,1.49149,2.5,,,,,,,,,,,,,,,,,,,,,,,,,,,,,,,,,,,,,
83.014,2.29976,1.1817,2.5,,,,,,,,,,,,,,,,,,,,,,,,,,,,,,,,,,,,,
83.55,2.27772,1.16816,3,,,,,,,,,,,,,,,,,,,,,,,,,,,,,,,,,,,,,
84.35,2.41128,1.62066,3,,,,,,,,,,,,,,,,,,,,,,,,,,,,,,,,,,,,,
85.15,2.54456,2.07679,3,,,,,,,,,,,,,,,,,,,,,,,,,,,,,,,,,,,,,
85.95,2.67812,2.81095,3,,,,,,,,,,,,,,,,,,,,,,,,,,,,,,,,,,,,,
86.75,2.81123,3.73125,3,,,,,,,,,,,,,,,,,,,,,,,,,,,,,,,,,,,,,
87.55,2.94468,4.80387,3,,,,,,,,,,,,,,,,,,,,,,,,,,,,,,,,,,,,,
88.35,3.07808,6.29687,3,,,,,,,,,,,,,,,,,,,,,,,,,,,,,,,,,,,,,
89.15,3.21136,7.9115,3,,,,,,,,,,,,,,,,,,,,,,,,,,,,,,,,,,,,,
89.95,3.34469,9.74472,3,,,,,,,,,,,,,,,,,,,,,,,,,,,,,,,,,,,,,
90.75,3.47809,12.10562,3,,,,,,,,,,,,,,,,,,,,,,,,,,,,,,,,,,,,,
91.55,3.61131,14.61024,3,,,,,,,,,,,,,,,,,,,,,,,,,,,,,,,,,,,,,
92.35,3.74465,17.66456,3,,,,,,,,,,,,,,,,,,,,,,,,,,,,,,,,,,,,,
93.15,3.87804,21.17192,3,,,,,,,,,,,,,,,,,,,,,,,,,,,,,,,,,,,,,
93.95,4.01126,24.99699,3,,,,,,,,,,,,,,,,,,,,,,,,,,,,,,,,,,,,,
94.75,4.14483,28.95457,3,,,,,,,,,,,,,,,,,,,,,,,,,,,,,,,,,,,,,
95.55,4.27799,33.78854,3,,,,,,,,,,,,,,,,,,,,,,,,,,,,,,,,,,,,,
96.35,4.41122,38.98408,3,,,,,,,,,,,,,,,,,,,,,,,,,,,,,,,,,,,,,
96.996,4.35206,35.5052,3.5,,,,,,,,,,,,,,,,,,,,,,,,,,,,,,,,,,,,,
97.796,4.21872,29.30934,3.5,,,,,,,,,,,,,,,,,,,,,,,,,,,,,,,,,,,,,
98.596,4.08538,24.30873,3.5,,,,,,,,,,,,,,,,,,,,,,,,,,,,,,,,,,,,,
99.396,3.95199,19.97944,3.5,,,,,,,,,,,,,,,,,,,,,,,,,,,,,,,,,,,,,
100.196,3.81865,16.4838,3.5,,,,,,,,,,,,,,,,,,,,,,,,,,,,,,,,,,,,,
100.996,3.68526,13.58135,3.5,,,,,,,,,,,,,,,,,,,,,,,,,,,,,,,,,,,,,
101.796,3.55204,11.09837,3.5,,,,,,,,,,,,,,,,,,,,,,,,,,,,,,,,,,,,,
102.596,3.41876,8.82266,3.5,,,,,,,,,,,,,,,,,,,,,,,,,,,,,,,,,,,,,
103.396,3.28531,7.00437,3.5,,,,,,,,,,,,,,,,,,,,,,,,,,,,,,,,,,,,,
104.196,3.15203,5.44626,3.5,,,,,,,,,,,,,,,,,,,,,,,,,,,,,,,,,,,,,
104.996,3.01869,4.23125,3.5,,,,,,,,,,,,,,,,,,,,,,,,,,,,,,,,,,,,,
105.796,2.88524,3.23815,3.5,,,,,,,,,,,,,,,,,,,,,,,,,,,,,,,,,,,,,
106.596,2.75207,2.48252,3.5,,,,,,,,,,,,,,,,,,,,,,,,,,,,,,,,,,,,,
107.396,2.61874,1.9918,3.5,,,,,,,,,,,,,,,,,,,,,,,,,,,,,,,,,,,,,
108.196,2.48523,1.47808,3.5,,,,,,,,,,,,,,,,,,,,,,,,,,,,,,,,,,,,,
108.996,2.35206,1.1982,3.5,,,,,,,,,,,,,,,,,,,,,,,,,,,,,,,,,,,,,
109.576,2.28446,1.05789,4,,,,,,,,,,,,,,,,,,,,,,,,,,,,,,,,,,,,,
110.376,2.4229,1.54146,4,,,,,,,,,,,,,,,,,,,,,,,,,,,,,,,,,,,,,
111.176,2.55635,2.08036,4,,,,,,,,,,,,,,,,,,,,,,,,,,,,,,,,,,,,,
111.976,2.68968,2.67439,4,,,,,,,,,,,,,,,,,,,,,,,,,,,,,,,,,,,,,
112.776,2.82285,3.61584,4,,,,,,,,,,,,,,,,,,,,,,,,,,,,,,,,,,,,,
113.576,2.95653,4.76057,4,,,,,,,,,,,,,,,,,,,,,,,,,,,,,,,,,,,,,
114.376,3.08969,6.17533,4,,,,,,,,,,,,,,,,,,,,,,,,,,,,,,,,,,,,,
115.176,3.22292,7.74242,4,,,,,,,,,,,,,,,,,,,,,,,,,,,,,,,,,,,,,
115.976,3.35648,9.68587,4,,,,,,,,,,,,,,,,,,,,,,,,,,,,,,,,,,,,,
116.776,3.48959,11.94308,4,,,,,,,,,,,,,,,,,,,,,,,,,,,,,,,,,,,,,
117.576,3.62287,14.41584,4,,,,,,,,,,,,,,,,,,,,,,,,,,,,,,,,,,,,,
118.376,3.75643,17.49625,4,,,,,,,,,,,,,,,,,,,,,,,,,,,,,,,,,,,,,
119.176,3.88966,20.92872,4,,,,,,,,,,,,,,,,,,,,,,,,,,,,,,,,,,,,,
119.976,4.02299,24.80233,4,,,,,,,,,,,,,,,,,,,,,,,,,,,,,,,,,,,,,
120.776,4.15644,28.79224,4,,,,,,,,,,,,,,,,,,,,,,,,,,,,,,,,,,,,,
121.576,4.28961,33.5508,4,,,,,,,,,,,,,,,,,,,,,,,,,,,,,,,,,,,,,
122.376,4.42295,38.82674,4,,,,,,,,,,,,,,,,,,,,,,,,,,,,,,,,,,,,,
123.04,4.36668,35.48838,4.5,,,,,,,,,,,,,,,,,,,,,,,,,,,,,,,,,,,,,
123.84,4.23334,29.21645,4.5,,,,,,,,,,,,,,,,,,,,,,,,,,,,,,,,,,,,,
124.64,4.10006,24.1916,4.5,,,,,,,,,,,,,,,,,,,,,,,,,,,,,,,,,,,,,
125.44,3.96661,20.02789,4.5,,,,,,,,,,,,,,,,,,,,,,,,,,,,,,,,,,,,,
126.24,3.83333,16.45271,4.5,,,,,,,,,,,,,,,,,,,,,,,,,,,,,,,,,,,,,
127.04,3.70005,13.59846,4.5,,,,,,,,,,,,,,,,,,,,,,,,,,,,,,,,,,,,,
127.84,3.5666,10.99494,4.5,,,,,,,,,,,,,,,,,,,,,,,,,,,,,,,,,,,,,
128.64,3.43338,8.7521,4.5,,,,,,,,,,,,,,,,,,,,,,,,,,,,,,,,,,,,,
129.44,3.30004,6.98616,4.5,,,,,,,,,,,,,,,,,,,,,,,,,,,,,,,,,,,,,
130.24,3.1667,5.48751,4.5,,,,,,,,,,,,,,,,,,,,,,,,,,,,,,,,,,,,,
131.04,3.03342,4.26046,4.5,,,,,,,,,,,,,,,,,,,,,,,,,,,,,,,,,,,,,
131.84,2.90009,3.25661,4.5,,,,,,,,,,,,,,,,,,,,,,,,,,,,,,,,,,,,,
132.64,2.76664,2.53113,4.5,,,,,,,,,,,,,,,,,,,,,,,,,,,,,,,,,,,,,
133.44,2.6333,1.92925,4.5,,,,,,,,,,,,,,,,,,,,,,,,,,,,,,,,,,,,,
134.24,2.50008,1.53166,4.5,,,,,,,,,,,,,,,,,,,,,,,,,,,,,,,,,,,,,
135.04,2.36668,1.21911,4.5,,,,,,,,,,,,,,,,,,,,,,,,,,,,,,,,,,,,,
135.612,2.30038,1.0585,5,,,,,,,,,,,,,,,,,,,,,,,,,,,,,,,,,,,,,
136.412,2.43899,1.53413,5,,,,,,,,,,,,,,,,,,,,,,,,,,,,,,,,,,,,,
137.212,2.57238,2.03478,5,,,,,,,,,,,,,,,,,,,,,,,,,,,,,,,,,,,,,
138.012,2.70561,2.69703,5,,,,,,,,,,,,,,,,,,,,,,,,,,,,,,,,,,,,,
138.812,2.83906,3.62599,5,,,,,,,,,,,,,,,,,,,,,,,,,,,,,,,,,,,,,
139.612,2.97234,4.79677,5,,,,,,,,,,,,,,,,,,,,,,,,,,,,,,,,,,,,,
140.412,3.10562,6.10985,5,,,,,,,,,,,,,,,,,,,,,,,,,,,,,,,,,,,,,
141.212,3.23907,7.74397,5,,,,,,,,,,,,,,,,,,,,,,,,,,,,,,,,,,,,,
142.012,3.37235,9.69883,5,,,,,,,,,,,,,,,,,,,,,,,,,,,,,,,,,,,,,
142.812,3.50557,11.96076,5,,,,,,,,,,,,,,,,,,,,,,,,,,,,,,,,,,,,,
143.612,3.63913,14.47747,5,,,,,,,,,,,,,,,,,,,,,,,,,,,,,,,,,,,,,
144.412,3.7723,17.54415,5,,,,,,,,,,,,,,,,,,,,,,,,,,,,,,,,,,,,,
145.212,3.90564,20.99373,5,,,,,,,,,,,,,,,,,,,,,,,,,,,,,,,,,,,,,
146.012,4.03909,24.90934,5,,,,,,,,,,,,,,,,,,,,,,,,,,,,,,,,,,,,,
146.812,4.17225,28.9324,5,,,,,,,,,,,,,,,,,,,,,,,,,,,,,,,,,,,,,
147.612,4.30559,33.68527,5,,,,,,,,,,,,,,,,,,,,,,,,,,,,,,,,,,,,,
148.412,4.4391,39.01698,5,,,,,,,,,,,,,,,,,,,,,,,,,,,,,,,,,,,,,
149.052,4.37875,35.47275,5.5,,,,,,,,,,,,,,,,,,,,,,,,,,,,,,,,,,,,,
149.852,4.24524,29.24792,5.5,,,,,,,,,,,,,,,,,,,,,,,,,,,,,,,,,,,,,
150.652,4.11207,24.26023,5.5,,,,,,,,,,,,,,,,,,,,,,,,,,,,,,,,,,,,,
151.452,3.97874,19.98105,5.5,,,,,,,,,,,,,,,,,,,,,,,,,,,,,,,,,,,,,
152.252,3.84529,16.51564,5.5,,,,,,,,,,,,,,,,,,,,,,,,,,,,,,,,,,,,,
153.052,3.71206,13.61048,5.5,,,,,,,,,,,,,,,,,,,,,,,,,,,,,,,,,,,,,
153.852,3.57873,10.98202,5.5,,,,,,,,,,,,,,,,,,,,,,,,,,,,,,,,,,,,,
154.652,3.44528,8.84311,5.5,,,,,,,,,,,,,,,,,,,,,,,,,,,,,,,,,,,,,
155.452,3.312,6.98645,5.5,,,,,,,,,,,,,,,,,,,,,,,,,,,,,,,,,,,,,
156.252,3.17872,5.35466,5.5,,,,,,,,,,,,,,,,,,,,,,,,,,,,,,,,,,,,,
157.052,3.04532,4.25042,5.5,,,,,,,,,,,,,,,,,,,,,,,,,,,,,,,,,,,,,
157.852,2.91204,3.31369,5.5,,,,,,,,,,,,,,,,,,,,,,,,,,,,,,,,,,,,,
158.652,2.77871,2.4708,5.5,,,,,,,,,,,,,,,,,,,,,,,,,,,,,,,,,,,,,
159.452,2.64531,1.92564,5.5,,,,,,,,,,,,,,,,,,,,,,,,,,,,,,,,,,,,,
160.252,2.51203,1.54488,5.5,,,,,,,,,,,,,,,,,,,,,,,,,,,,,,,,,,,,,
161.052,2.37858,1.16462,5.5,,,,,,,,,,,,,,,,,,,,,,,,,,,,,,,,,,,,,
161.566,2.29313,0.99765,6,,,,,,,,,,,,,,,,,,,,,,,,,,,,,,,,,,,,,
162.366,2.42726,1.45222,6,,,,,,,,,,,,,,,,,,,,,,,,,,,,,,,,,,,,,
163.166,2.56071,1.91683,6,,,,,,,,,,,,,,,,,,,,,,,,,,,,,,,,,,,,,
163.966,2.69393,2.55878,6,,,,,,,,,,,,,,,,,,,,,,,,,,,,,,,,,,,,,
164.766,2.82721,3.51353,6,,,,,,,,,,,,,,,,,,,,,,,,,,,,,,,,,,,,,
165.566,2.96083,4.5276,6,,,,,,,,,,,,,,,,,,,,,,,,,,,,,,,,,,,,,
166.366,3.09389,5.84277,6,,,,,,,,,,,,,,,,,,,,,,,,,,,,,,,,,,,,,
167.166,3.22728,7.49734,6,,,,,,,,,,,,,,,,,,,,,,,,,,,,,,,,,,,,,
167.966,3.36073,9.42119,6,,,,,,,,,,,,,,,,,,,,,,,,,,,,,,,,,,,,,
168.766,3.4939,11.54796,6,,,,,,,,,,,,,,,,,,,,,,,,,,,,,,,,,,,,,
169.566,3.62735,14.09944,6,,,,,,,,,,,,,,,,,,,,,,,,,,,,,,,,,,,,,
170.366,3.76068,16.93206,6,,,,,,,,,,,,,,,,,,,,,,,,,,,,,,,,,,,,,
171.166,3.89396,20.38407,6,,,,,,,,,,,,,,,,,,,,,,,,,,,,,,,,,,,,,
171.966,4.02736,24.2924,6,,,,,,,,,,,,,,,,,,,,,,,,,,,,,,,,,,,,,
172.766,4.16064,28.30442,6,,,,,,,,,,,,,,,,,,,,,,,,,,,,,,,,,,,,,
173.566,4.29397,32.9605,6,,,,,,,,,,,,,,,,,,,,,,,,,,,,,,,,,,,,,
174.366,4.42737,38.50798,6,,,,,,,,,,,,,,,,,,,,,,,,,,,,,,,,,,,,,
174.988,4.3975,36.42321,6.5,,,,,,,,,,,,,,,,,,,,,,,,,,,,,,,,,,,,,
175.788,4.26411,29.96944,6.5,,,,,,,,,,,,,,,,,,,,,,,,,,,,,,,,,,,,,
176.588,4.13055,24.79419,6.5,,,,,,,,,,,,,,,,,,,,,,,,,,,,,,,,,,,,,
177.388,3.99744,20.45987,6.5,,,,,,,,,,,,,,,,,,,,,,,,,,,,,,,,,,,,,
178.188,3.86404,16.76427,6.5,,,,,,,,,,,,,,,,,,,,,,,,,,,,,,,,,,,,,
178.988,3.73065,13.79875,6.5,,,,,,,,,,,,,,,,,,,,,,,,,,,,,,,,,,,,,
179.788,3.59743,11.13145,6.5,,,,,,,,,,,,,,,,,,,,,,,,,,,,,,,,,,,,,
180.588,3.46403,8.90443,6.5,,,,,,,,,,,,,,,,,,,,,,,,,,,,,,,,,,,,,
181.388,3.3307,7.07128,6.5,,,,,,,,,,,,,,,,,,,,,,,,,,,,,,,,,,,,,
182.188,3.19736,5.54065,6.5,,,,,,,,,,,,,,,,,,,,,,,,,,,,,,,,,,,,,
182.988,3.06402,4.2868,6.5,,,,,,,,,,,,,,,,,,,,,,,,,,,,,,,,,,,,,
183.788,2.93069,3.25844,6.5,,,,,,,,,,,,,,,,,,,,,,,,,,,,,,,,,,,,,
184.588,2.79741,2.48291,6.5,,,,,,,,,,,,,,,,,,,,,,,,,,,,,,,,,,,,,
185.388,2.66384,1.93246,6.5,,,,,,,,,,,,,,,,,,,,,,,,,,,,,,,,,,,,,
186.188,2.53079,1.51255,6.5,,,,,,,,,,,,,,,,,,,,,,,,,,,,,,,,,,,,,
186.988,2.3974,1.20455,6.5,,,,,,,,,,,,,,,,,,,,,,,,,,,,,,,,,,,,,
187.568,2.30072,0.99054,7,,,,,,,,,,,,,,,,,,,,,,,,,,,,,,,,,,,,,
188.368,2.43491,1.43537,7,,,,,,,,,,,,,,,,,,,,,,,,,,,,,,,,,,,,,
189.168,2.56847,1.91663,7,,,,,,,,,,,,,,,,,,,,,,,,,,,,,,,,,,,,,
189.968,2.70164,2.60904,7,,,,,,,,,,,,,,,,,,,,,,,,,,,,,,,,,,,,,
190.768,2.83492,3.40201,7,,,,,,,,,,,,,,,,,,,,,,,,,,,,,,,,,,,,,
191.568,2.96843,4.51539,7,,,,,,,,,,,,,,,,,,,,,,,,,,,,,,,,,,,,,
192.368,3.10159,5.83796,7,,,,,,,,,,,,,,,,,,,,,,,,,,,,,,,,,,,,,
193.168,3.23493,7.38132,7,,,,,,,,,,,,,,,,,,,,,,,,,,,,,,,,,,,,,
193.968,3.36844,9.27538,7,,,,,,,,,,,,,,,,,,,,,,,,,,,,,,,,,,,,,
194.768,3.5016,11.50758,7,,,,,,,,,,,,,,,,,,,,,,,,,,,,,,,,,,,,,
195.568,3.63505,14.10741,7,,,,,,,,,,,,,,,,,,,,,,,,,,,,,,,,,,,,,
196.368,3.76839,16.93858,7,,,,,,,,,,,,,,,,,,,,,,,,,,,,,,,,,,,,,
197.168,3.90161,20.38304,7,,,,,,,,,,,,,,,,,,,,,,,,,,,,,,,,,,,,,
197.968,4.03512,24.16824,7,,,,,,,,,,,,,,,,,,,,,,,,,,,,,,,,,,,,,
198.768,4.16834,28.2943,7,,,,,,,,,,,,,,,,,,,,,,,,,,,,,,,,,,,,,
199.568,4.30151,32.94926,7,,,,,,,,,,,,,,,,,,,,,,,,,,,,,,,,,,,,,
200.368,4.43513,38.41846,7,,,,,,,,,,,,,,,,,,,,,,,,,,,,,,,,,,,,,
200.988,4.40476,36.33759,7.5,,,,,,,,,,,,,,,,,,,,,,,,,,,,,,,,,,,,,
201.788,4.27136,29.94485,7.5,,,,,,,,,,,,,,,,,,,,,,,,,,,,,,,,,,,,,
202.588,4.13797,24.80733,7.5,,,,,,,,,,,,,,,,,,,,,,,,,,,,,,,,,,,,,
203.388,4.00469,20.43208,7.5,,,,,,,,,,,,,,,,,,,,,,,,,,,,,,,,,,,,,
204.188,3.87141,16.79531,7.5,,,,,,,,,,,,,,,,,,,,,,,,,,,,,,,,,,,,,
204.988,3.7379,13.76721,7.5,,,,,,,,,,,,,,,,,,,,,,,,,,,,,,,,,,,,,
205.788,3.60468,11.13286,7.5,,,,,,,,,,,,,,,,,,,,,,,,,,,,,,,,,,,,,
206.588,3.4714,8.91522,7.5,,,,,,,,,,,,,,,,,,,,,,,,,,,,,,,,,,,,,
207.388,3.33789,7.04986,7.5,,,,,,,,,,,,,,,,,,,,,,,,,,,,,,,,,,,,,
208.188,3.20473,5.4673,7.5,,,,,,,,,,,,,,,,,,,,,,,,,,,,,,,,,,,,,
208.988,3.07139,4.22257,7.5,,,,,,,,,,,,,,,,,,,,,,,,,,,,,,,,,,,,,
209.788,2.93788,3.2813,7.5,,,,,,,,,,,,,,,,,,,,,,,,,,,,,,,,,,,,,
210.588,2.80472,2.47425,7.5,,,,,,,,,,,,,,,,,,,,,,,,,,,,,,,,,,,,,
211.388,2.67144,1.9473,7.5,,,,,,,,,,,,,,,,,,,,,,,,,,,,,,,,,,,,,
212.188,2.53804,1.50355,7.5,,,,,,,,,,,,,,,,,,,,,,,,,,,,,,,,,,,,,
212.988,2.40471,1.19783,7.5,,,,,,,,,,,,,,,,,,,,,,,,,,,,,,,,,,,,,
213.568,2.3371,1.02677,8,,,,,,,,,,,,,,,,,,,,,,,,,,,,,,,,,,,,,
214.368,2.4756,1.50628,8,,,,,,,,,,,,,,,,,,,,,,,,,,,,,,,,,,,,,
215.168,2.60893,2.06001,8,,,,,,,,,,,,,,,,,,,,,,,,,,,,,,,,,,,,,
215.968,2.74238,2.71926,8,,,,,,,,,,,,,,,,,,,,,,,,,,,,,,,,,,,,,
216.768,2.87561,3.63336,8,,,,,,,,,,,,,,,,,,,,,,,,,,,,,,,,,,,,,
217.568,3.00906,4.9217,8,,,,,,,,,,,,,,,,,,,,,,,,,,,,,,,,,,,,,
218.368,3.14239,6.18773,8,,,,,,,,,,,,,,,,,,,,,,,,,,,,,,,,,,,,,
219.168,3.27556,7.81922,8,,,,,,,,,,,,,,,,,,,,,,,,,,,,,,,,,,,,,
219.968,3.40912,9.80848,8,,,,,,,,,,,,,,,,,,,,,,,,,,,,,,,,,,,,,
220.768,3.54229,12.08416,8,,,,,,,,,,,,,,,,,,,,,,,,,,,,,,,,,,,,,
221.568,3.67557,14.66893,8,,,,,,,,,,,,,,,,,,,,,,,,,,,,,,,,,,,,,
222.368,3.80908,17.71813,8,,,,,,,,,,,,,,,,,,,,,,,,,,,,,,,,,,,,,
223.168,3.9423,21.24685,8,,,,,,,,,,,,,,,,,,,,,,,,,,,,,,,,,,,,,
223.968,4.07552,25.17421,8,,,,,,,,,,,,,,,,,,,,,,,,,,,,,,,,,,,,,
224.768,4.20914,29.41249,8,,,,,,,,,,,,,,,,,,,,,,,,,,,,,,,,,,,,,
225.568,4.34231,34.24691,8,,,,,,,,,,,,,,,,,,,,,,,,,,,,,,,,,,,,,
226.368,4.47559,39.90367,8,,,,,,,,,,,,,,,,,,,,,,,,,,,,,,,,,,,,,
226.98,4.37744,34.64915,8.5,,,,,,,,,,,,,,,,,,,,,,,,,,,,,,,,,,,,,
227.78,4.24388,28.54294,8.5,,,,,,,,,,,,,,,,,,,,,,,,,,,,,,,,,,,,,
228.58,4.11077,23.56577,8.5,,,,,,,,,,,,,,,,,,,,,,,,,,,,,,,,,,,,,
229.38,3.97743,19.43797,8.5,,,,,,,,,,,,,,,,,,,,,,,,,,,,,,,,,,,,,
230.18,3.84393,16.02525,8.5,,,,,,,,,,,,,,,,,,,,,,,,,,,,,,,,,,,,,
230.98,3.7107,13.03234,8.5,,,,,,,,,,,,,,,,,,,,,,,,,,,,,,,,,,,,,
231.78,3.57737,10.56172,8.5,,,,,,,,,,,,,,,,,,,,,,,,,,,,,,,,,,,,,
232.58,3.44397,8.39005,8.5,,,,,,,,,,,,,,,,,,,,,,,,,,,,,,,,,,,,,
233.38,3.31069,6.59151,8.5,,,,,,,,,,,,,,,,,,,,,,,,,,,,,,,,,,,,,
234.18,3.1773,5.14252,8.5,,,,,,,,,,,,,,,,,,,,,,,,,,,,,,,,,,,,,
234.98,3.04402,3.90779,8.5,,,,,,,,,,,,,,,,,,,,,,,,,,,,,,,,,,,,,
235.78,2.91074,2.98297,8.5,,,,,,,,,,,,,,,,,,,,,,,,,,,,,,,,,,,,,
236.58,2.77735,2.42737,8.5,,,,,,,,,,,,,,,,,,,,,,,,,,,,,,,,,,,,,
237.38,2.64395,1.8648,8.5,,,,,,,,,,,,,,,,,,,,,,,,,,,,,,,,,,,,,
238.18,2.51073,1.42574,8.5,,,,,,,,,,,,,,,,,,,,,,,,,,,,,,,,,,,,,
238.98,2.37728,1.14689,8.5,,,,,,,,,,,,,,,,,,,,,,,,,,,,,,,,,,,,,
239.57,2.37983,1.19363,9,,,,,,,,,,,,,,,,,,,,,,,,,,,,,,,,,,,,,
240.37,2.51339,1.63386,9,,,,,,,,,,,,,,,,,,,,,,,,,,,,,,,,,,,,,
241.17,2.64667,2.19404,9,,,,,,,,,,,,,,,,,,,,,,,,,,,,,,,,,,,,,
241.97,2.77995,2.91163,9,,,,,,,,,,,,,,,,,,,,,,,,,,,,,,,,,,,,,
242.77,2.91335,3.88225,9,,,,,,,,,,,,,,,,,,,,,,,,,,,,,,,,,,,,,
243.57,3.04657,5.0607,9,,,,,,,,,,,,,,,,,,,,,,,,,,,,,,,,,,,,,
244.37,3.17996,6.47735,9,,,,,,,,,,,,,,,,,,,,,,,,,,,,,,,,,,,,,
245.17,3.31336,8.25393,9,,,,,,,,,,,,,,,,,,,,,,,,,,,,,,,,,,,,,
245.97,3.44664,10.21221,9,,,,,,,,,,,,,,,,,,,,,,,,,,,,,,,,,,,,,
246.77,3.58014,12.68683,9,,,,,,,,,,,,,,,,,,,,,,,,,,,,,,,,,,,,,
247.57,3.71337,15.26707,9,,,,,,,,,,,,,,,,,,,,,,,,,,,,,,,,,,,,,
248.37,3.84665,18.45674,9,,,,,,,,,,,,,,,,,,,,,,,,,,,,,,,,,,,,,
249.17,3.98004,22.10839,9,,,,,,,,,,,,,,,,,,,,,,,,,,,,,,,,,,,,,
249.97,4.11332,26.14624,9,,,,,,,,,,,,,,,,,,,,,,,,,,,,,,,,,,,,,
250.77,4.24654,30.34699,9,,,,,,,,,,,,,,,,,,,,,,,,,,,,,,,,,,,,,
251.57,4.38011,35.60098,9,,,,,,,,,,,,,,,,,,,,,,,,,,,,,,,,,,,,,
252.182,4.48199,40.0318,9.5,,,,,,,,,,,,,,,,,,,,,,,,,,,,,,,,,,,,,
252.982,4.34843,33.02917,9.5,,,,,,,,,,,,,,,,,,,,,,,,,,,,,,,,,,,,,
253.782,4.21509,27.2652,9.5,,,,,,,,,,,,,,,,,,,,,,,,,,,,,,,,,,,,,
254.582,4.08164,22.52247,9.5,,,,,,,,,,,,,,,,,,,,,,,,,,,,,,,,,,,,,
255.382,3.94831,18.49759,9.5,,,,,,,,,,,,,,,,,,,,,,,,,,,,,,,,,,,,,
256.182,3.81508,15.17864,9.5,,,,,,,,,,,,,,,,,,,,,,,,,,,,,,,,,,,,,
256.982,3.68152,12.3764,9.5,,,,,,,,,,,,,,,,,,,,,,,,,,,,,,,,,,,,,
257.782,3.54835,9.94809,9.5,,,,,,,,,,,,,,,,,,,,,,,,,,,,,,,,,,,,,
258.582,3.41513,7.91088,9.5,,,,,,,,,,,,,,,,,,,,,,,,,,,,,,,,,,,,,
259.382,3.28157,6.22038,9.5,,,,,,,,,,,,,,,,,,,,,,,,,,,,,,,,,,,,,
260.182,3.14834,4.8246,9.5,,,,,,,,,,,,,,,,,,,,,,,,,,,,,,,,,,,,,
260.982,3.01506,3.6543,9.5,,,,,,,,,,,,,,,,,,,,,,,,,,,,,,,,,,,,,
261.782,2.88156,2.86001,9.5,,,,,,,,,,,,,,,,,,,,,,,,,,,,,,,,,,,,,
262.582,2.74839,2.26299,9.5,,,,,,,,,,,,,,,,,,,,,,,,,,,,,,,,,,,,,
263.382,2.61505,1.70271,9.5,,,,,,,,,,,,,,,,,,,,,,,,,,,,,,,,,,,,,
264.182,2.4816,1.36141,9.5,,,,,,,,,,,,,,,,,,,,,,,,,,,,,,,,,,,,,
264.982,2.34844,1.06199,9.5,,,,,,,,,,,,,,,,,,,,,,,,,,,,,,,,,,,,,
265.608,2.24627,0.81221,10,,,,,,,,,,,,,,,,,,,,,,,,,,,,,,,,,,,,,
266.408,2.1879,0.72529,10,,,,,,,,,,,,,,,,,,,,,,,,,,,,,,,,,,,,,
267.208,2.18796,0.76336,10,,,,,,,,,,,,,,,,,,,,,,,,,,,,,,,,,,,,,
268.008,2.18892,0.72273,10,,,,,,,,,,,,,,,,,,,,,,,,,,,,,,,,,,,,,
268.808,2.19425,0.75782,10,,,,,,,,,,,,,,,,,,,,,,,,,,,,,,,,,,,,,
269.608,2.26208,0.96981,10,,,,,,,,,,,,,,,,,,,,,,,,,,,,,,,,,,,,,
270.408,2.326,1.1234,10,,,,,,,,,,,,,,,,,,,,,,,,,,,,,,,,,,,,,
271.208,2.33149,1.10684,10,,,,,,,,,,,,,,,,,,,,,,,,,,,,,,,,,,,,,
272.008,2.33098,1.15875,10,,,,,,,,,,,,,,,,,,,,,,,,,,,,,,,,,,,,,
272.808,2.32311,1.16863,10,,,,,,,,,,,,,,,,,,,,,,,,,,,,,,,,,,,,,
273.608,2.27029,1.019,10,,,,,,,,,,,,,,,,,,,,,,,,,,,,,,,,,,,,,
274.408,2.22462,0.87402,10,,,,,,,,,,,,,,,,,,,,,,,,,,,,,,,,,,,,,
275.208,2.21963,0.87574,10,,,,,,,,,,,,,,,,,,,,,,,,,,,,,,,,,,,,,
276.008,2.21969,0.89783,10,,,,,,,,,,,,,,,,,,,,,,,,,,,,,,,,,,,,,
276.808,2.2198,0.88609,10,,,,,,,,,,,,,,,,,,,,,,,,,,,,,,,,,,,,,
277.608,2.22009,0.86518,10,,,,,,,,,,,,,,,,,,,,,,,,,,,,,,,,,,,,,
278.408,2.22071,0.85168,10,,,,,,,,,,,,,,,,,,,,,,,,,,,,,,,,,,,,,
279.208,2.22247,0.89765,10,,,,,,,,,,,,,,,,,,,,,,,,,,,,,,,,,,,,,
280.008,2.2304,0.90149,10,,,,,,,,,,,,,,,,,,,,,,,,,,,,,,,,,,,,,
280.808,2.26729,0.95394,10,,,,,,,,,,,,,,,,,,,,,,,,,,,,,,,,,,,,,
281.608,2.2882,1.07251,10,,,,,,,,,,,,,,,,,,,,,,,,,,,,,,,,,,,,,
282.408,2.28843,1.08837,10,,,,,,,,,,,,,,,,,,,,,,,,,,,,,,,,,,,,,
283.208,2.28814,1.15839,10,,,,,,,,,,,,,,,,,,,,,,,,,,,,,,,,,,,,,
284.008,2.28622,1.13461,10,,,,,,,,,,,,,,,,,,,,,,,,,,,,,,,,,,,,,
284.808,2.27194,1.07657,10,,,,,,,,,,,,,,,,,,,,,,,,,,,,,,,,,,,,,
285.608,2.23199,0.96182,10,,,,,,,,,,,,,,,,,,,,,,,,,,,,,,,,,,,,,
286.408,2.21697,0.93838,10,,,,,,,,,,,,,,,,,,,,,,,,,,,,,,,,,,,,,
287.208,2.21555,0.85044,10,,,,,,,,,,,,,,,,,,,,,,,,,,,,,,,,,,,,,
288.008,2.21572,0.93182,10,,,,,,,,,,,,,,,,,,,,,,,,,,,,,,,,,,,,,
288.808,2.21589,0.92605,10,,,,,,,,,,,,,,,,,,,,,,,,,,,,,,,,,,,,,
289.608,2.21606,0.89483,10,,,,,,,,,,,,,,,,,,,,,,,,,,,,,,,,,,,,,
290.408,2.21663,0.87021,10,,,,,,,,,,,,,,,,,,,,,,,,,,,,,,,,,,,,,
291.208,2.21759,0.87132,10,,,,,,,,,,,,,,,,,,,,,,,,,,,,,,,,,,,,,
292.008,2.22269,0.90441,10,,,,,,,,,,,,,,,,,,,,,,,,,,,,,,,,,,,,,
292.808,2.23539,0.94894,10,,,,,,,,,,,,,,,,,,,,,,,,,,,,,,,,,,,,,
293.608,2.26026,1.01317,10,,,,,,,,,,,,,,,,,,,,,,,,,,,,,,,,,,,,,
294.408,2.2661,1.05737,10,,,,,,,,,,,,,,,,,,,,,,,,,,,,,,,,,,,,,
295.208,2.2661,1.04749,10,,,,,,,,,,,,,,,,,,,,,,,,,,,,,,,,,,,,,
296.008,2.26593,1.06359,10,,,,,,,,,,,,,,,,,,,,,,,,,,,,,,,,,,,,,
296.808,2.26565,1.04695,10,,,,,,,,,,,,,,,,,,,,,,,,,,,,,,,,,,,,,
297.608,2.26406,1.05967,10,,,,,,,,,,,,,,,,,,,,,,,,,,,,,,,,,,,,,
298.408,2.25618,1.04085,10,,,,,,,,,,,,,,,,,,,,,,,,,,,,,,,,,,,,,
299.208,2.23465,1.00691,10,,,,,,,,,,,,,,,,,,,,,,,,,,,,,,,,,,,,,
300.008,2.22009,0.93959,10,,,,,,,,,,,,,,,,,,,,,,,,,,,,,,,,,,,,,
300.808,2.21856,0.94548,10,,,,,,,,,,,,,,,,,,,,,,,,,,,,,,,,,,,,,
301.608,2.21833,0.93875,10,,,,,,,,,,,,,,,,,,,,,,,,,,,,,,,,,,,,,
302.408,2.21844,0.92883,10,,,,,,,,,,,,,,,,,,,,,,,,,,,,,,,,,,,,,
303.208,2.2185,0.92787,10,,,,,,,,,,,,,,,,,,,,,,,,,,,,,,,,,,,,,
304.008,2.21856,0.91085,10,,,,,,,,,,,,,,,,,,,,,,,,,,,,,,,,,,,,,
304.808,2.21873,0.96554,10,,,,,,,,,,,,,,,,,,,,,,,,,,,,,,,,,,,,,
305.608,2.2189,0.92661,10,,,,,,,,,,,,,,,,,,,,,,,,,,,,,,,,,,,,,
306.408,2.21924,0.91062,10,,,,,,,,,,,,,,,,,,,,,,,,,,,,,,,,,,,,,
307.208,2.21963,0.93158,10,,,,,,,,,,,,,,,,,,,,,,,,,,,,,,,,,,,,,
308.008,2.22037,0.91807,10,,,,,,,,,,,,,,,,,,,,,,,,,,,,,,,,,,,,,
308.808,2.22201,0.94526,10,,,,,,,,,,,,,,,,,,,,,,,,,,,,,,,,,,,,,
309.608,2.22445,0.92967,10,,,,,,,,,,,,,,,,,,,,,,,,,,,,,,,,,,,,,
310.408,2.22813,0.9588,10,,,,,,,,,,,,,,,,,,,,,,,,,,,,,,,,,,,,,
311.208,2.25006,1.00837,10,,,,,,,,,,,,,,,,,,,,,,,,,,,,,,,,,,,,,
312.008,2.25811,1.01759,10,,,,,,,,,,,,,,,,,,,,,,,,,,,,,,,,,,,,,
312.808,2.25817,1.09094,10,,,,,,,,,,,,,,,,,,,,,,,,,,,,,,,,,,,,,
313.608,2.258,1.06476,10,,,,,,,,,,,,,,,,,,,,,,,,,,,,,,,,,,,,,
314.408,2.25766,1.09744,10,,,,,,,,,,,,,,,,,,,,,,,,,,,,,,,,,,,,,
315.208,2.25573,1.03358,10,,,,,,,,,,,,,,,,,,,,,,,,,,,,,,,,,,,,,
316.008,2.24933,1.05166,10,,,,,,,,,,,,,,,,,,,,,,,,,,,,,,,,,,,,,
316.808,2.22672,1.01482,10,,,,,,,,,,,,,,,,,,,,,,,,,,,,,,,,,,,,,
317.608,2.21306,0.93647,10,,,,,,,,,,,,,,,,,,,,,,,,,,,,,,,,,,,,,
318.408,2.20762,0.95039,10,,,,,,,,,,,,,,,,,,,,,,,,,,,,,,,,,,,,,
319.208,2.20479,0.97782,10,,,,,,,,,,,,,,,,,,,,,,,,,,,,,,,,,,,,,
320.008,2.20388,0.97949,10,,,,,,,,,,,,,,,,,,,,,,,,,,,,,,,,,,,,,
320.808,2.20348,0.99942,10,,,,,,,,,,,,,,,,,,,,,,,,,,,,,,,,,,,,,
321.608,2.20331,0.97958,10,,,,,,,,,,,,,,,,,,,,,,,,,,,,,,,,,,,,,
322.408,2.20326,0.9586,10,,,,,,,,,,,,,,,,,,,,,,,,,,,,,,,,,,,,,
323.208,2.20331,0.91318,10,,,,,,,,,,,,,,,,,,,,,,,,,,,,,,,,,,,,,
324.008,2.20343,0.93052,10,,,,,,,,,,,,,,,,,,,,,,,,,,,,,,,,,,,,,
324.808,2.20348,0.93371,10,,,,,,,,,,,,,,,,,,,,,,,,,,,,,,,,,,,,,
325.608,2.20348,0.95282,10,,,,,,,,,,,,,,,,,,,,,,,,,,,,,,,,,,,,,
326.408,2.2036,0.90267,10,,,,,,,,,,,,,,,,,,,,,,,,,,,,,,,,,,,,,
327.208,2.2036,0.97729,10,,,,,,,,,,,,,,,,,,,,,,,,,,,,,,,,,,,,,
328.008,2.20365,0.94481,10,,,,,,,,,,,,,,,,,,,,,,,,,,,,,,,,,,,,,
328.808,2.20371,0.96033,10,,,,,,,,,,,,,,,,,,,,,,,,,,,,,,,,,,,,,
329.608,2.20371,0.88763,10,,,,,,,,,,,,,,,,,,,,,,,,,,,,,,,,,,,,,
330.408,2.20388,0.88963,10,,,,,,,,,,,,,,,,,,,,,,,,,,,,,,,,,,,,,
331.208,2.20399,0.99902,10,,,,,,,,,,,,,,,,,,,,,,,,,,,,,,,,,,,,,
332.008,2.20405,0.97712,10,,,,,,,,,,,,,,,,,,,,,,,,,,,,,,,,,,,,,
332.808,2.20422,1.04188,10,,,,,,,,,,,,,,,,,,,,,,,,,,,,,,,,,,,,,
333.608,2.20433,0.92025,10,,,,,,,,,,,,,,,,,,,,,,,,,,,,,,,,,,,,,
334.408,2.20445,0.91447,10,,,,,,,,,,,,,,,,,,,,,,,,,,,,,,,,,,,,,
335.208,2.20462,0.95839,10,,,,,,,,,,,,,,,,,,,,,,,,,,,,,,,,,,,,,
336.008,2.20467,1.00033,10,,,,,,,,,,,,,,,,,,,,,,,,,,,,,,,,,,,,,
336.808,2.20473,0.99645,10,,,,,,,,,,,,,,,,,,,,,,,,,,,,,,,,,,,,,
337.608,2.20473,0.97922,10,,,,,,,,,,,,,,,,,,,,,,,,,,,,,,,,,,,,,
338.408,2.20462,1.0096,10,,,,,,,,,,,,,,,,,,,,,,,,,,,,,,,,,,,,,
339.208,2.20467,0.98699,10,,,,,,,,,,,,,,,,,,,,,,,,,,,,,,,,,,,,,
340.008,2.20456,1.07667,10,,,,,,,,,,,,,,,,,,,,,,,,,,,,,,,,,,,,,
340.808,2.20456,1.0278,10,,,,,,,,,,,,,,,,,,,,,,,,,,,,,,,,,,,,,
341.608,2.20456,0.94044,10,,,,,,,,,,,,,,,,,,,,,,,,,,,,,,,,,,,,,
342.408,2.20462,0.96662,10,,,,,,,,,,,,,,,,,,,,,,,,,,,,,,,,,,,,,
343.208,2.20462,0.97913,10,,,,,,,,,,,,,,,,,,,,,,,,,,,,,,,,,,,,,
344.008,2.2045,0.95378,10,,,,,,,,,,,,,,,,,,,,,,,,,,,,,,,,,,,,,
344.808,2.20445,1.01837,10,,,,,,,,,,,,,,,,,,,,,,,,,,,,,,,,,,,,,
345.608,2.20456,1.01889,10,,,,,,,,,,,,,,,,,,,,,,,,,,,,,,,,,,,,,
346.408,2.20445,1.00628,10,,,,,,,,,,,,,,,,,,,,,,,,,,,,,,,,,,,,,
347.208,2.2045,0.95925,10,,,,,,,,,,,,,,,,,,,,,,,,,,,,,,,,,,,,,
348.008,2.2045,1.00245,10,,,,,,,,,,,,,,,,,,,,,,,,,,,,,,,,,,,,,
348.808,2.2045,0.96359,10,,,,,,,,,,,,,,,,,,,,,,,,,,,,,,,,,,,,,
349.608,2.2045,0.98556,10,,,,,,,,,,,,,,,,,,,,,,,,,,,,,,,,,,,,,
350.408,2.2045,1.00261,10,,,,,,,,,,,,,,,,,,,,,,,,,,,,,,,,,,,,,
351.208,2.20439,0.98243,10,,,,,,,,,,,,,,,,,,,,,,,,,,,,,,,,,,,,,
352.008,2.20428,0.92626,10,,,,,,,,,,,,,,,,,,,,,,,,,,,,,,,,,,,,,
352.808,2.20433,0.94945,10,,,,,,,,,,,,,,,,,,,,,,,,,,,,,,,,,,,,,
353.608,2.20428,0.97588,10,,,,,,,,,,,,,,,,,,,,,,,,,,,,,,,,,,,,,
354.408,2.20428,0.9704,10,,,,,,,,,,,,,,,,,,,,,,,,,,,,,,,,,,,,,
355.208,2.20428,0.95355,10,,,,,,,,,,,,,,,,,,,,,,,,,,,,,,,,,,,,,
356.008,2.20422,0.93979,10,,,,,,,,,,,,,,,,,,,,,,,,,,,,,,,,,,,,,
356.808,2.20433,0.95611,10,,,,,,,,,,,,,,,,,,,,,,,,,,,,,,,,,,,,,
357.608,2.20433,0.95089,10,,,,,,,,,,,,,,,,,,,,,,,,,,,,,,,,,,,,,
358.408,2.20433,0.9223,10,,,,,,,,,,,,,,,,,,,,,,,,,,,,,,,,,,,,,
359.208,2.20433,0.92741,10,,,,,,,,,,,,,,,,,,,,,,,,,,,,,,,,,,,,,
360.008,2.20433,0.91902,10,,,,,,,,,,,,,,,,,,,,,,,,,,,,,,,,,,,,,
360.808,2.20433,0.95409,10,,,,,,,,,,,,,,,,,,,,,,,,,,,,,,,,,,,,,
361.608,2.20433,0.94459,10,,,,,,,,,,,,,,,,,,,,,,,,,,,,,,,,,,,,,
362.408,2.20433,0.91948,10,,,,,,,,,,,,,,,,,,,,,,,,,,,,,,,,,,,,,
363.208,2.20433,0.93961,10,,,,,,,,,,,,,,,,,,,,,,,,,,,,,,,,,,,,,
364.008,2.20433,0.97112,10,,,,,,,,,,,,,,,,,,,,,,,,,,,,,,,,,,,,,
364.808,2.20433,0.9986,10,,,,,,,,,,,,,,,,,,,,,,,,,,,,,,,,,,,,,
365.608,2.20433,0.96755,10,,,,,,,,,,,,,,,,,,,,,,,,,,,,,,,,,,,,,
366.408,2.20433,0.93645,10,,,,,,,,,,,,,,,,,,,,,,,,,,,,,,,,,,,,,
367.208,2.20433,0.96422,10,,,,,,,,,,,,,,,,,,,,,,,,,,,,,,,,,,,,,
368.008,2.20422,0.98631,10,,,,,,,,,,,,,,,,,,,,,,,,,,,,,,,,,,,,,
368.808,2.20422,0.91025,10,,,,,,,,,,,,,,,,,,,,,,,,,,,,,,,,,,,,,
369.608,2.20433,0.94462,10,,,,,,,,,,,,,,,,,,,,,,,,,,,,,,,,,,,,,
370.408,2.20433,0.95475,10,,,,,,,,,,,,,,,,,,,,,,,,,,,,,,,,,,,,,
371.208,2.20433,0.94425,10,,,,,,,,,,,,,,,,,,,,,,,,,,,,,,,,,,,,,
372.008,2.20428,0.95475,10,,,,,,,,,,,,,,,,,,,,,,,,,,,,,,,,,,,,,
372.808,2.20433,0.94974,10,,,,,,,,,,,,,,,,,,,,,,,,,,,,,,,,,,,,,
373.608,2.20422,0.94146,10,,,,,,,,,,,,,,,,,,,,,,,,,,,,,,,,,,,,,
374.408,2.20422,0.97501,10,,,,,,,,,,,,,,,,,,,,,,,,,,,,,,,,,,,,,
375.208,2.20433,0.94021,10,,,,,,,,,,,,,,,,,,,,,,,,,,,,,,,,,,,,,
376.008,2.20422,0.98586,10,,,,,,,,,,,,,,,,,,,,,,,,,,,,,,,,,,,,,
376.808,2.20433,1.00198,10,,,,,,,,,,,,,,,,,,,,,,,,,,,,,,,,,,,,,
377.608,2.20433,0.94042,10,,,,,,,,,,,,,,,,,,,,,,,,,,,,,,,,,,,,,
378.408,2.20433,0.98626,10,,,,,,,,,,,,,,,,,,,,,,,,,,,,,,,,,,,,,
379.208,2.20433,0.9814,10,,,,,,,,,,,,,,,,,,,,,,,,,,,,,,,,,,,,,
380.008,2.20433,0.93991,10,,,,,,,,,,,,,,,,,,,,,,,,,,,,,,,,,,,,,
380.808,2.20433,0.96726,10,,,,,,,,,,,,,,,,,,,,,,,,,,,,,,,,,,,,,
381.608,2.20433,0.97439,10,,,,,,,,,,,,,,,,,,,,,,,,,,,,,,,,,,,,,
382.408,2.20422,0.96709,10,,,,,,,,,,,,,,,,,,,,,,,,,,,,,,,,,,,,,
383.208,2.20422,0.98113,10,,,,,,,,,,,,,,,,,,,,,,,,,,,,,,,,,,,,,
384.008,2.20422,1.01522,10,,,,,,,,,,,,,,,,,,,,,,,,,,,,,,,,,,,,,
384.808,2.20422,0.9316,10,,,,,,,,,,,,,,,,,,,,,,,,,,,,,,,,,,,,,
385.608,2.20422,0.9295,10,,,,,,,,,,,,,,,,,,,,,,,,,,,,,,,,,,,,,
386.408,2.20422,0.95551,10,,,,,,,,,,,,,,,,,,,,,,,,,,,,,,,,,,,,,
387.208,2.20422,0.95482,10,,,,,,,,,,,,,,,,,,,,,,,,,,,,,,,,,,,,,
388.008,2.20422,0.95934,10,,,,,,,,,,,,,,,,,,,,,,,,,,,,,,,,,,,,,
388.808,2.20422,0.98101,10,,,,,,,,,,,,,,,,,,,,,,,,,,,,,,,,,,,,,
389.608,2.20433,0.90851,10,,,,,,,,,,,,,,,,,,,,,,,,,,,,,,,,,,,,,
390.408,2.20433,0.96173,10,,,,,,,,,,,,,,,,,,,,,,,,,,,,,,,,,,,,,
391.208,2.20433,0.99579,10,,,,,,,,,,,,,,,,,,,,,,,,,,,,,,,,,,,,,
392.008,2.20433,1.01041,10,,,,,,,,,,,,,,,,,,,,,,,,,,,,,,,,,,,,,
392.808,2.20422,0.94492,10,,,,,,,,,,,,,,,,,,,,,,,,,,,,,,,,,,,,,
393.608,2.20422,0.97469,10,,,,,,,,,,,,,,,,,,,,,,,,,,,,,,,,,,,,,
394.408,2.20422,1.00089,10,,,,,,,,,,,,,,,,,,,,,,,,,,,,,,,,,,,,,
395.208,2.20433,0.92397,10,,,,,,,,,,,,,,,,,,,,,,,,,,,,,,,,,,,,,
396.008,2.20433,0.93422,10,,,,,,,,,,,,,,,,,,,,,,,,,,,,,,,,,,,,,
396.808,2.20433,0.95387,10,,,,,,,,,,,,,,,,,,,,,,,,,,,,,,,,,,,,,
397.608,2.20433,0.98366,10,,,,,,,,,,,,,,,,,,,,,,,,,,,,,,,,,,,,,
398.408,2.20422,0.98655,10,,,,,,,,,,,,,,,,,,,,,,,,,,,,,,,,,,,,,
399.208,2.20422,0.95996,10,,,,,,,,,,,,,,,,,,,,,,,,,,,,,,,,,,,,,
400.008,2.20422,0.98342,10,,,,,,,,,,,,,,,,,,,,,,,,,,,,,,,,,,,,,
400.808,2.20422,0.97991,10,,,,,,,,,,,,,,,,,,,,,,,,,,,,,,,,,,,,,
401.608,2.20422,0.95643,10,,,,,,,,,,,,,,,,,,,,,,,,,,,,,,,,,,,,,
402.408,2.20422,0.96937,10,,,,,,,,,,,,,,,,,,,,,,,,,,,,,,,,,,,,,
403.208,2.20422,0.917,10,,,,,,,,,,,,,,,,,,,,,,,,,,,,,,,,,,,,,
404.008,2.20422,0.96841,10,,,,,,,,,,,,,,,,,,,,,,,,,,,,,,,,,,,,,
404.808,2.20422,0.93531,10,,,,,,,,,,,,,,,,,,,,,,,,,,,,,,,,,,,,,
405.608,2.20422,0.97452,10,,,,,,,,,,,,,,,,,,,,,,,,,,,,,,,,,,,,,
406.408,2.20422,0.96149,10,,,,,,,,,,,,,,,,,,,,,,,,,,,,,,,,,,,,,
407.208,2.20422,0.94465,10,,,,,,,,,,,,,,,,,,,,,,,,,,,,,,,,,,,,,
408.008,2.20422,0.90867,10,,,,,,,,,,,,,,,,,,,,,,,,,,,,,,,,,,,,,
408.808,2.20422,0.94767,10,,,,,,,,,,,,,,,,,,,,,,,,,,,,,,,,,,,,,
409.608,2.20422,0.97518,10,,,,,,,,,,,,,,,,,,,,,,,,,,,,,,,,,,,,,
410.408,2.20422,0.96603,10,,,,,,,,,,,,,,,,,,,,,,,,,,,,,,,,,,,,,
411.208,2.20433,0.96329,10,,,,,,,,,,,,,,,,,,,,,,,,,,,,,,,,,,,,,
412.008,2.20422,1.00795,10,,,,,,,,,,,,,,,,,,,,,,,,,,,,,,,,,,,,,
412.808,2.20422,0.9741,10,,,,,,,,,,,,,,,,,,,,,,,,,,,,,,,,,,,,,
413.608,2.20422,0.98819,10,,,,,,,,,,,,,,,,,,,,,,,,,,,,,,,,,,,,,
414.408,2.20422,0.95588,10,,,,,,,,,,,,,,,,,,,,,,,,,,,,,,,,,,,,,
415.208,2.20422,1.0264,10,,,,,,,,,,,,,,,,,,,,,,,,,,,,,,,,,,,,,
416.008,2.20422,0.99795,10,,,,,,,,,,,,,,,,,,,,,,,,,,,,,,,,,,,,,
416.808,2.20416,0.95786,10,,,,,,,,,,,,,,,,,,,,,,,,,,,,,,,,,,,,,
417.608,2.20411,0.91085,10,,,,,,,,,,,,,,,,,,,,,,,,,,,,,,,,,,,,,
418.408,2.20411,0.91453,10,,,,,,,,,,,,,,,,,,,,,,,,,,,,,,,,,,,,,
419.208,2.20411,0.98278,10,,,,,,,,,,,,,,,,,,,,,,,,,,,,,,,,,,,,,
420.008,2.20405,0.96253,10,,,,,,,,,,,,,,,,,,,,,,,,,,,,,,,,,,,,,
420.808,2.20416,0.93508,10,,,,,,,,,,,,,,,,,,,,,,,,,,,,,,,,,,,,,
421.608,2.20416,0.98495,10,,,,,,,,,,,,,,,,,,,,,,,,,,,,,,,,,,,,,
422.408,2.20405,0.94452,10,,,,,,,,,,,,,,,,,,,,,,,,,,,,,,,,,,,,,
423.208,2.20416,0.94743,10,,,,,,,,,,,,,,,,,,,,,,,,,,,,,,,,,,,,,
424.008,2.20405,1.0032,10,,,,,,,,,,,,,,,,,,,,,,,,,,,,,,,,,,,,,
424.808,2.20405,0.94086,10,,,,,,,,,,,,,,,,,,,,,,,,,,,,,,,,,,,,,
425.608,2.20405,0.96289,10,,,,,,,,,,,,,,,,,,,,,,,,,,,,,,,,,,,,,
426.408,2.20416,0.97803,10,,,,,,,,,,,,,,,,,,,,,,,,,,,,,,,,,,,,,
427.208,2.20416,0.956,10,,,,,,,,,,,,,,,,,,,,,,,,,,,,,,,,,,,,,
428.008,2.20405,1.07584,10,,,,,,,,,,,,,,,,,,,,,,,,,,,,,,,,,,,,,
428.808,2.20416,0.95908,10,,,,,,,,,,,,,,,,,,,,,,,,,,,,,,,,,,,,,
429.608,2.20405,0.9841,10,,,,,,,,,,,,,,,,,,,,,,,,,,,,,,,,,,,,,
430.408,2.20405,0.95491,10,,,,,,,,,,,,,,,,,,,,,,,,,,,,,,,,,,,,,
431.208,2.20405,0.96265,10,,,,,,,,,,,,,,,,,,,,,,,,,,,,,,,,,,,,,
432.008,2.20405,1.05446,10,,,,,,,,,,,,,,,,,,,,,,,,,,,,,,,,,,,,,
432.808,2.20416,0.91946,10,,,,,,,,,,,,,,,,,,,,,,,,,,,,,,,,,,,,,
433.608,2.20405,0.9524,10,,,,,,,,,,,,,,,,,,,,,,,,,,,,,,,,,,,,,
434.408,2.20405,0.99179,10,,,,,,,,,,,,,,,,,,,,,,,,,,,,,,,,,,,,,
435.208,2.20405,0.93574,10,,,,,,,,,,,,,,,,,,,,,,,,,,,,,,,,,,,,,
436.008,2.20405,0.98802,10,,,,,,,,,,,,,,,,,,,,,,,,,,,,,,,,,,,,,
436.808,2.20405,0.90477,10,,,,,,,,,,,,,,,,,,,,,,,,,,,,,,,,,,,,,
437.608,2.20405,0.92937,10,,,,,,,,,,,,,,,,,,,,,,,,,,,,,,,,,,,,,
438.408,2.20411,0.97791,10,,,,,,,,,,,,,,,,,,,,,,,,,,,,,,,,,,,,,
439.208,2.20411,0.99649,10,,,,,,,,,,,,,,,,,,,,,,,,,,,,,,,,,,,,,
440.008,2.20411,0.97226,10,,,,,,,,,,,,,,,,,,,,,,,,,,,,,,,,,,,,,
440.808,2.20411,0.97126,10,,,,,,,,,,,,,,,,,,,,,,,,,,,,,,,,,,,,,
441.608,2.20405,0.94389,10,,,,,,,,,,,,,,,,,,,,,,,,,,,,,,,,,,,,,
442.408,2.20411,0.96369,10,,,,,,,,,,,,,,,,,,,,,,,,,,,,,,,,,,,,,
443.208,2.20411,0.97889,10,,,,,,,,,,,,,,,,,,,,,,,,,,,,,,,,,,,,,
444.008,2.20411,0.99971,10,,,,,,,,,,,,,,,,,,,,,,,,,,,,,,,,,,,,,
444.808,2.20411,0.95669,10,,,,,,,,,,,,,,,,,,,,,,,,,,,,,,,,,,,,,
445.608,2.20411,0.94118,10,,,,,,,,,,,,,,,,,,,,,,,,,,,,,,,,,,,,,
446.408,2.20411,0.9457,10,,,,,,,,,,,,,,,,,,,,,,,,,,,,,,,,,,,,,
447.208,2.20405,0.97935,10,,,,,,,,,,,,,,,,,,,,,,,,,,,,,,,,,,,,,
448.008,2.20411,1.00336,10,,,,,,,,,,,,,,,,,,,,,,,,,,,,,,,,,,,,,
448.808,2.20411,0.99871,10,,,,,,,,,,,,,,,,,,,,,,,,,,,,,,,,,,,,,
449.608,2.20411,0.96368,10,,,,,,,,,,,,,,,,,,,,,,,,,,,,,,,,,,,,,
450.408,2.20399,1.06998,10,,,,,,,,,,,,,,,,,,,,,,,,,,,,,,,,,,,,,
451.208,2.20394,0.99914,10,,,,,,,,,,,,,,,,,,,,,,,,,,,,,,,,,,,,,
452.008,2.20382,0.99535,10,,,,,,,,,,,,,,,,,,,,,,,,,,,,,,,,,,,,,
452.808,2.20371,0.945,10,,,,,,,,,,,,,,,,,,,,,,,,,,,,,,,,,,,,,
453.608,2.2036,0.95554,10,,,,,,,,,,,,,,,,,,,,,,,,,,,,,,,,,,,,,
454.408,2.20365,0.97454,10,,,,,,,,,,,,,,,,,,,,,,,,,,,,,,,,,,,,,
455.208,2.20354,0.91509,10,,,,,,,,,,,,,,,,,,,,,,,,,,,,,,,,,,,,,
456.008,2.20354,0.92752,10,,,,,,,,,,,,,,,,,,,,,,,,,,,,,,,,,,,,,
456.808,2.20354,0.96255,10,,,,,,,,,,,,,,,,,,,,,,,,,,,,,,,,,,,,,
457.608,2.20365,0.89932,10,,,,,,,,,,,,,,,,,,,,,,,,,,,,,,,,,,,,,
458.408,2.20365,0.9484,10,,,,,,,,,,,,,,,,,,,,,,,,,,,,,,,,,,,,,
459.208,2.20365,0.97491,10,,,,,,,,,,,,,,,,,,,,,,,,,,,,,,,,,,,,,
460.008,2.20365,0.98372,10,,,,,,,,,,,,,,,,,,,,,,,,,,,,,,,,,,,,,
460.808,2.20365,0.99432,10,,,,,,,,,,,,,,,,,,,,,,,,,,,,,,,,,,,,,
461.608,2.20365,0.96278,10,,,,,,,,,,,,,,,,,,,,,,,,,,,,,,,,,,,,,
462.408,2.20365,0.96253,10,,,,,,,,,,,,,,,,,,,,,,,,,,,,,,,,,,,,,
463.208,2.20365,0.94068,10,,,,,,,,,,,,,,,,,,,,,,,,,,,,,,,,,,,,,
464.008,2.20365,0.95493,10,,,,,,,,,,,,,,,,,,,,,,,,,,,,,,,,,,,,,
464.808,2.20365,0.94532,10,,,,,,,,,,,,,,,,,,,,,,,,,,,,,,,,,,,,,
465.608,2.20365,0.957,10,,,,,,,,,,,,,,,,,,,,,,,,,,,,,,,,,,,,,
466.408,2.20365,0.96686,10,,,,,,,,,,,,,,,,,,,,,,,,,,,,,,,,,,,,,
467.208,2.20365,0.97025,10,,,,,,,,,,,,,,,,,,,,,,,,,,,,,,,,,,,,,
468.008,2.20365,0.9887,10,,,,,,,,,,,,,,,,,,,,,,,,,,,,,,,,,,,,,
468.808,2.20365,0.94625,10,,,,,,,,,,,,,,,,,,,,,,,,,,,,,,,,,,,,,
469.608,2.20365,0.96323,10,,,,,,,,,,,,,,,,,,,,,,,,,,,,,,,,,,,,,
470.408,2.20365,0.95899,10,,,,,,,,,,,,,,,,,,,,,,,,,,,,,,,,,,,,,
471.208,2.20365,0.97508,10,,,,,,,,,,,,,,,,,,,,,,,,,,,,,,,,,,,,,
472.008,2.20365,0.96945,10,,,,,,,,,,,,,,,,,,,,,,,,,,,,,,,,,,,,,
472.808,2.20365,0.99261,10,,,,,,,,,,,,,,,,,,,,,,,,,,,,,,,,,,,,,
473.608,2.2036,0.92927,10,,,,,,,,,,,,,,,,,,,,,,,,,,,,,,,,,,,,,
474.408,2.20365,1.01412,10,,,,,,,,,,,,,,,,,,,,,,,,,,,,,,,,,,,,,
475.208,2.20365,0.95022,10,,,,,,,,,,,,,,,,,,,,,,,,,,,,,,,,,,,,,
476.008,2.20365,1.00845,10,,,,,,,,,,,,,,,,,,,,,,,,,,,,,,,,,,,,,
476.808,2.2036,0.97478,10,,,,,,,,,,,,,,,,,,,,,,,,,,,,,,,,,,,,,
477.608,2.20371,0.985,10,,,,,,,,,,,,,,,,,,,,,,,,,,,,,,,,,,,,,
478.408,2.20371,0.95384,10,,,,,,,,,,,,,,,,,,,,,,,,,,,,,,,,,,,,,
479.208,2.20371,0.94906,10,,,,,,,,,,,,,,,,,,,,,,,,,,,,,,,,,,,,,
480.008,2.20371,0.99166,10,,,,,,,,,,,,,,,,,,,,,,,,,,,,,,,,,,,,,
480.808,2.20371,0.97465,10,,,,,,,,,,,,,,,,,,,,,,,,,,,,,,,,,,,,,
481.608,2.20371,0.95163,10,,,,,,,,,,,,,,,,,,,,,,,,,,,,,,,,,,,,,
482.408,2.2036,0.93648,10,,,,,,,,,,,,,,,,,,,,,,,,,,,,,,,,,,,,,
483.208,2.2036,0.96816,10,,,,,,,,,,,,,,,,,,,,,,,,,,,,,,,,,,,,,
484.008,2.2036,0.94013,10,,,,,,,,,,,,,,,,,,,,,,,,,,,,,,,,,,,,,
484.808,2.2036,0.93814,10,,,,,,,,,,,,,,,,,,,,,,,,,,,,,,,,,,,,,
485.608,2.20371,1.00576,10,,,,,,,,,,,,,,,,,,,,,,,,,,,,,,,,,,,,,
486.408,2.20371,0.9466,10,,,,,,,,,,,,,,,,,,,,,,,,,,,,,,,,,,,,,
487.208,2.20371,1.02013,10,,,,,,,,,,,,,,,,,,,,,,,,,,,,,,,,,,,,,
488.008,2.20371,0.9663,10,,,,,,,,,,,,,,,,,,,,,,,,,,,,,,,,,,,,,
488.808,2.2036,0.92417,10,,,,,,,,,,,,,,,,,,,,,,,,,,,,,,,,,,,,,
489.608,2.20371,0.97325,10,,,,,,,,,,,,,,,,,,,,,,,,,,,,,,,,,,,,,
490.408,2.20365,0.93453,10,,,,,,,,,,,,,,,,,,,,,,,,,,,,,,,,,,,,,
491.208,2.20377,0.97192,10,,,,,,,,,,,,,,,,,,,,,,,,,,,,,,,,,,,,,
492.008,2.20377,0.94721,10,,,,,,,,,,,,,,,,,,,,,,,,,,,,,,,,,,,,,
492.808,2.20377,0.94282,10,,,,,,,,,,,,,,,,,,,,,,,,,,,,,,,,,,,,,
493.608,2.20377,0.97529,10,,,,,,,,,,,,,,,,,,,,,,,,,,,,,,,,,,,,,
494.408,2.20377,0.95392,10,,,,,,,,,,,,,,,,,,,,,,,,,,,,,,,,,,,,,
495.208,2.20377,0.94686,10,,,,,,,,,,,,,,,,,,,,,,,,,,,,,,,,,,,,,
496.008,2.20377,0.97247,10,,,,,,,,,,,,,,,,,,,,,,,,,,,,,,,,,,,,,
496.808,2.20377,0.99646,10,,,,,,,,,,,,,,,,,,,,,,,,,,,,,,,,,,,,,
497.608,2.20377,0.94864,10,,,,,,,,,,,,,,,,,,,,,,,,,,,,,,,,,,,,,
498.408,2.20365,0.9186,10,,,,,,,,,,,,,,,,,,,,,,,,,,,,,,,,,,,,,
499.208,2.20365,1.05007,10,,,,,,,,,,,,,,,,,,,,,,,,,,,,,,,,,,,,,
500.008,2.20365,1.0043,10,,,,,,,,,,,,,,,,,,,,,,,,,,,,,,,,,,,,,
500.808,2.20365,0.95009,10,,,,,,,,,,,,,,,,,,,,,,,,,,,,,,,,,,,,,
501.608,2.20377,1.0099,10,,,,,,,,,,,,,,,,,,,,,,,,,,,,,,,,,,,,,
502.408,2.20377,0.96318,10,,,,,,,,,,,,,,,,,,,,,,,,,,,,,,,,,,,,,
503.208,2.20377,0.95737,10,,,,,,,,,,,,,,,,,,,,,,,,,,,,,,,,,,,,,
504.008,2.20377,0.96378,10,,,,,,,,,,,,,,,,,,,,,,,,,,,,,,,,,,,,,
504.808,2.20371,0.96288,10,,,,,,,,,,,,,,,,,,,,,,,,,,,,,,,,,,,,,
505.608,2.20365,1.00345,10,,,,,,,,,,,,,,,,,,,,,,,,,,,,,,,,,,,,,
506.408,2.20377,0.9989,10,,,,,,,,,,,,,,,,,,,,,,,,,,,,,,,,,,,,,
507.208,2.20377,0.95953,10,,,,,,,,,,,,,,,,,,,,,,,,,,,,,,,,,,,,,
508.008,2.20377,0.94719,10,,,,,,,,,,,,,,,,,,,,,,,,,,,,,,,,,,,,,
508.808,2.20377,0.89521,10,,,,,,,,,,,,,,,,,,,,,,,,,,,,,,,,,,,,,
509.608,2.20371,0.99406,10,,,,,,,,,,,,,,,,,,,,,,,,,,,,,,,,,,,,,
510.408,2.20365,0.96004,10,,,,,,,,,,,,,,,,,,,,,,,,,,,,,,,,,,,,,
511.208,2.20377,0.95026,10,,,,,,,,,,,,,,,,,,,,,,,,,,,,,,,,,,,,,
512.008,2.20365,0.96174,10,,,,,,,,,,,,,,,,,,,,,,,,,,,,,,,,,,,,,
512.808,2.20365,0.99944,10,,,,,,,,,,,,,,,,,,,,,,,,,,,,,,,,,,,,,
513.608,2.20377,0.94789,10,,,,,,,,,,,,,,,,,,,,,,,,,,,,,,,,,,,,,
514.408,2.20377,0.94989,10,,,,,,,,,,,,,,,,,,,,,,,,,,,,,,,,,,,,,
515.208,2.20377,0.9379,10,,,,,,,,,,,,,,,,,,,,,,,,,,,,,,,,,,,,,
516.008,2.20377,0.9748,10,,,,,,,,,,,,,,,,,,,,,,,,,,,,,,,,,,,,,
516.808,2.20377,0.94607,10,,,,,,,,,,,,,,,,,,,,,,,,,,,,,,,,,,,,,
517.608,2.20377,0.99758,10,,,,,,,,,,,,,,,,,,,,,,,,,,,,,,,,,,,,,
518.408,2.20377,1.01739,10,,,,,,,,,,,,,,,,,,,,,,,,,,,,,,,,,,,,,
519.208,2.20365,0.99035,10,,,,,,,,,,,,,,,,,,,,,,,,,,,,,,,,,,,,,
520.008,2.20365,0.95701,10,,,,,,,,,,,,,,,,,,,,,,,,,,,,,,,,,,,,,
520.808,2.20365,1.01677,10,,,,,,,,,,,,,,,,,,,,,,,,,,,,,,,,,,,,,
521.608,2.20365,0.98999,10,,,,,,,,,,,,,,,,,,,,,,,,,,,,,,,,,,,,,
522.408,2.20365,0.98586,10,,,,,,,,,,,,,,,,,,,,,,,,,,,,,,,,,,,,,
523.208,2.20365,0.99822,10,,,,,,,,,,,,,,,,,,,,,,,,,,,,,,,,,,,,,
524.008,2.20365,0.96406,10,,,,,,,,,,,,,,,,,,,,,,,,,,,,,,,,,,,,,
524.808,2.20377,0.96947,10,,,,,,,,,,,,,,,,,,,,,,,,,,,,,,,,,,,,,
525.608,2.20365,0.98553,10,,,,,,,,,,,,,,,,,,,,,,,,,,,,,,,,,,,,,
526.408,2.20365,0.98072,10,,,,,,,,,,,,,,,,,,,,,,,,,,,,,,,,,,,,,
527.208,2.20365,0.91668,10,,,,,,,,,,,,,,,,,,,,,,,,,,,,,,,,,,,,,
528.008,2.20365,1.02633,10,,,,,,,,,,,,,,,,,,,,,,,,,,,,,,,,,,,,,
528.808,2.20371,0.99124,10,,,,,,,,,,,,,,,,,,,,,,,,,,,,,,,,,,,,,
529.608,2.20365,0.95358,10,,,,,,,,,,,,,,,,,,,,,,,,,,,,,,,,,,,,,
530.408,2.20371,0.93289,10,,,,,,,,,,,,,,,,,,,,,,,,,,,,,,,,,,,,,
531.208,2.2036,1.09938,10,,,,,,,,,,,,,,,,,,,,,,,,,,,,,,,,,,,,,
532.008,2.2036,1.02677,10,,,,,,,,,,,,,,,,,,,,,,,,,,,,,,,,,,,,,
532.808,2.2036,0.95013,10,,,,,,,,,,,,,,,,,,,,,,,,,,,,,,,,,,,,,
533.608,2.2036,0.94855,10,,,,,,,,,,,,,,,,,,,,,,,,,,,,,,,,,,,,,
534.408,2.2036,0.96013,10,,,,,,,,,,,,,,,,,,,,,,,,,,,,,,,,,,,,,
535.208,2.20354,1.05602,10,,,,,,,,,,,,,,,,,,,,,,,,,,,,,,,,,,,,,
536.008,2.20365,0.98064,10,,,,,,,,,,,,,,,,,,,,,,,,,,,,,,,,,,,,,
536.808,2.20354,0.92185,10,,,,,,,,,,,,,,,,,,,,,,,,,,,,,,,,,,,,,
537.608,2.20354,0.94187,10,,,,,,,,,,,,,,,,,,,,,,,,,,,,,,,,,,,,,
538.408,2.20354,0.91963,10,,,,,,,,,,,,,,,,,,,,,,,,,,,,,,,,,,,,,
539.208,2.20365,0.98447,10,,,,,,,,,,,,,,,,,,,,,,,,,,,,,,,,,,,,,
540.008,2.20365,0.96245,10,,,,,,,,,,,,,,,,,,,,,,,,,,,,,,,,,,,,,
540.808,2.20365,0.89093,10,,,,,,,,,,,,,,,,,,,,,,,,,,,,,,,,,,,,,
541.608,2.20365,0.96331,10,,,,,,,,,,,,,,,,,,,,,,,,,,,,,,,,,,,,,
542.408,2.20365,0.98465,10,,,,,,,,,,,,,,,,,,,,,,,,,,,,,,,,,,,,,
543.208,2.20365,0.98266,10,,,,,,,,,,,,,,,,,,,,,,,,,,,,,,,,,,,,,
544.008,2.20365,0.94391,10,,,,,,,,,,,,,,,,,,,,,,,,,,,,,,,,,,,,,
544.808,2.20365,1.007,10,,,,,,,,,,,,,,,,,,,,,,,,,,,,,,,,,,,,,
545.608,2.2036,0.95691,10,,,,,,,,,,,,,,,,,,,,,,,,,,,,,,,,,,,,,
546.408,2.20354,0.94147,10,,,,,,,,,,,,,,,,,,,,,,,,,,,,,,,,,,,,,
547.208,2.20354,1.01362,10,,,,,,,,,,,,,,,,,,,,,,,,,,,,,,,,,,,,,
548.008,2.20343,1.00074,10,,,,,,,,,,,,,,,,,,,,,,,,,,,,,,,,,,,,,
548.808,2.20326,0.97935,10,,,,,,,,,,,,,,,,,,,,,,,,,,,,,,,,,,,,,
549.608,2.20286,1.01325,10,,,,,,,,,,,,,,,,,,,,,,,,,,,,,,,,,,,,,
550.408,2.20195,1.02581,10,,,,,,,,,,,,,,,,,,,,,,,,,,,,,,,,,,,,,
551.208,2.19963,1.00957,10,,,,,,,,,,,,,,,,,,,,,,,,,,,,,,,,,,,,,
552.008,2.19538,0.9638,10,,,,,,,,,,,,,,,,,,,,,,,,,,,,,,,,,,,,,
552.808,2.19062,0.98292,10,,,,,,,,,,,,,,,,,,,,,,,,,,,,,,,,,,,,,
553.608,2.18796,0.95916,10,,,,,,,,,,,,,,,,,,,,,,,,,,,,,,,,,,,,,
554.408,2.18614,0.95324,10,,,,,,,,,,,,,,,,,,,,,,,,,,,,,,,,,,,,,
555.208,2.18541,0.99432,10,,,,,,,,,,,,,,,,,,,,,,,,,,,,,,,,,,,,,
556.008,2.18495,0.96775,10,,,,,,,,,,,,,,,,,,,,,,,,,,,,,,,,,,,,,
556.808,2.18484,0.91776,10,,,,,,,,,,,,,,,,,,,,,,,,,,,,,,,,,,,,,
557.608,2.18495,0.91009,10,,,,,,,,,,,,,,,,,,,,,,,,,,,,,,,,,,,,,
558.408,2.18501,0.94206,10,,,,,,,,,,,,,,,,,,,,,,,,,,,,,,,,,,,,,
559.208,2.18501,1.01586,10,,,,,,,,,,,,,,,,,,,,,,,,,,,,,,,,,,,,,
560.008,2.18507,0.95328,10,,,,,,,,,,,,,,,,,,,,,,,,,,,,,,,,,,,,,
560.808,2.18512,0.95927,10,,,,,,,,,,,,,,,,,,,,,,,,,,,,,,,,,,,,,
561.608,2.18524,0.93531,10,,,,,,,,,,,,,,,,,,,,,,,,,,,,,,,,,,,,,
562.408,2.18529,0.92614,10,,,,,,,,,,,,,,,,,,,,,,,,,,,,,,,,,,,,,
563.208,2.18535,0.89016,10,,,,,,,,,,,,,,,,,,,,,,,,,,,,,,,,,,,,,
564.008,2.18563,0.89711,10,,,,,,,,,,,,,,,,,,,,,,,,,,,,,,,,,,,,,
564.808,2.18592,0.91279,10,,,,,,,,,,,,,,,,,,,,,,,,,,,,,,,,,,,,,
565.51,5.3027,76.77003,10,,,,,,,,,,,,,,,,,,,,,,,,,,,,,,,,,,,,,
566.31,11.96936,540.32593,10,,,,,,,,,,,,,,,,,,,,,,,,,,,,,,,,,,,,,
567.11,18.63619,280.84009,10,,,,,,,,,,,,,,,,,,,,,,,,,,,,,,,,,,,,,
567.91,25.3028,62.436,10,,,,,,,,,,,,,,,,,,,,,,,,,,,,,,,,,,,,,
568.71,31.96946,20.03034,10,,,,,,,,,,,,,,,,,,,,,,,,,,,,,,,,,,,,,
569.51,38.63613,13.36333,10,,,,,,,,,,,,,,,,,,,,,,,,,,,,,,,,,,,,,
570.31,45.30279,11.16975,10,,,,,,,,,,,,,,,,,,,,,,,,,,,,,,,,,,,,,
571.11,51.96945,10.773,10,,,,,,,,,,,,,,,,,,,,,,,,,,,,,,,,,,,,,
571.91,58.63617,7.7905,10,,,,,,,,,,,,,,,,,,,,,,,,,,,,,,,,,,,,,
572.71,65.30289,4.58291,10,,,,,,,,,,,,,,,,,,,,,,,,,,,,,,,,,,,,,
573.51,71.9695,0.65761,10,,,,,,,,,,,,,,,,,,,,,,,,,,,,,,,,,,,,,
574.31,78.6361,0.64897,10,,,,,,,,,,,,,,,,,,,,,,,,,,,,,,,,,,,,,
575.11,85.30283,0.63661,10,,,,,,,,,,,,,,,,,,,,,,,,,,,,,,,,,,,,,
575.262,86.56955,0.68007,10,,,,,,,,,,,,,,,,,,,,,,,,,,,,,,,,,,,,,