File: combined_ligament_solver/data/processed/Data Sheet 3_S160302_LCL.csv
Specimen properties : Length,47,mm,Unnamed: 3,Unnamed: 4,Unnamed: 5,Unnamed: 6,Unnamed: 7,Unnamed: 8,Unnamed: 9,Unnamed: 10,Unnamed: 11,Stress-Strain,Unnamed: 13,Unnamed: 14,Unnamed: 15,Unnamed: 16,Unnamed: 17,Unnamed: 18,Unnamed: 19,Unnamed: 20,Unnamed: 21,Unnamed: 22,Unnamed: 23,Unnamed: 24,Unnamed: 25,Unnamed: 26,Unnamed: 27,Linear,Unnamed: 29,Unnamed: 30,Unnamed: 31,Unnamed: 32,Unnamed: 33,Modulus,Unnamed: 35,Failure,Unnamed: 37,Unnamed: 38,Unnamed: 39,Unnamed: 40
Cross Section Average,45.1475,mm2,,,,,,,,,,Polynomial Coefficients,,,,,,,,,,,,,,,,Force,,Stress,Extension,Strain,,Secant,Tangent,Load,Stress,Extension,Strain,Stiffness
Time,Extension,Load,Total cycle count,,,Extension,Load,Strain,Stress,E-tan,,X6,-10621056.335733714,,,,,,,,,Strain,Stress,E-tan,,,,(N),,(MPa),(mm),(%),,(MPa),(MPa),(N),(MPa),(mm),(%),(N/mm)
(s),(mm),(N),,,,(mm),(N),(mm/mm),(MPa),(MPa),,X5,4238780.632532292,,,,,,,,,(mm/mm),(MPa),(MPa),,,,274.3878188263688,,6.077586108341963,5.593,11.899999999999999,,51.072152170940875,88.91947958247562,341.77228,7.547325765546266,6.43325,13.68776595744681,49.059148726330925
0.6,0.17731,2.13151,0,,,5.36843,208.96614,0.1014163829787234,4.60572013954261,77.76316694073695,,,,,,,,,,,,0.006,0.06651330658436258,9.222281668407293,,,,,,,,,,,,,,,,
1.3,0.2941,3.46098,0,,,11.20192,267.25934,,,,,,,,,,,,,,,0.013,0.13127827535284303,10.243377335093152,,,,,,,,,,,,,,,,
2,0.41078,4.72073,0,,,17.0353,98.00486,,,,,,,,,,,,,,,0.02,0.22540838575353206,16.35413047324967,,,,,,,,,,,,,,,,
2.7,0.52745,6.09499,0,,,22.86851,24.48955,,,,,,,,,,,,,,,0.027,0.3728784501557167,24.773844193797167,,,,,,,,,,,,,,,,
3.4,0.64413,7.44942,0,,,,,,,,,,,,,,,,,,,0.034,0.5817248110028638,33.58506284958181,,,,,,,,,,,,,,,,
4.1,0.76086,8.97405,0,,,,,,,,,,,,,,,,,,,0.041,0.8495739261958525,41.60504620781298,,,,,,,,,,,,,,,,
4.8,0.87754,10.57274,0,,,,,,,,,,,,,,,,,,,0.048,1.1682712736832825,48.257243622505676,,,,,,,,,,,,,,,,
5.5,0.99416,12.28369,0,,,,,,,,,,,,,,,,,,,0.055,1.5276105752588527,53.442768206914465,,,,,,,,,,,,,,,,
6.2,1.11072,14.04446,0,,,,,,,,,,,,,,,,,,,0.062,1.9181633395658184,57.411871005979826,,,,,,,,,,,,,,,,
6.9,1.22734,16.03649,0,,,,,,,,,,,,,,,,,,,0.069,2.3332087243085113,60.63541516875353,,,,,,,,,,,,,,,,
7.6,1.34396,18.14748,0,,,,,,,,,,,,,,,,,,,0.076,2.7697637176709393,63.67635012085898,,,,,,,,,,,,,,,,
8.3,1.4607,20.00138,0,,,,,,,,,,,,,,,,,,,0.083,3.22871363894248,67.06118573691005,,,,,,,,,,,,,,,,
9,1.57737,22.3548,0,,,,,,,,,,,,,,,,,,,0.09,3.714042958350593,71.15146651297215,,,,,,,,,,,,,,,,
9.7,1.69405,24.93686,0,,,,,,,,,,,,,,,,,,,0.097,4.231166436100662,76.01524573894817,,,,,,,,,,,,,,,,
10.4,1.81061,27.76736,0,,,,,,,,,,,,,,,,,,,0.104,4.784360580622877,81.29855967111236,,,,,,,,,,,,,,,,
11.1,1.92735,30.68855,0,,,,,,,,,,,,,,,,,,,0.111,5.373295426026213,86.09690170444121,,,,,,,,,,,,,,,,
11.8,2.04402,33.90388,0,,,,,,,,,,,,,,,,,,,0.118,5.988666628759487,88.82669654515435,,,,,,,,,,,,,,,,
12.5,2.1607,37.34521,0,,,,,,,,,,,,,,,,,,,0.125,6.606927883479399,87.09677438306943,,,,,,,,,,,,,,,,
13.026,2.24842,40.00941,0.5,,,,,,,,,,,,,,,,,,,0.132,7.184123658125756,77.57984506408448,,,,,,,,,,,,,,,,
13.726,2.13152,34.5277,0.5,,,,,,,,,,,,,,,,,,,0.139,7.648822248203829,55.883972262583846,,,,,,,,,,,,,,,,
14.426,2.01484,29.78845,0.5,,,,,,,,,,,,,,,,,,,0.146,7.894149150273519,16.424047654082216,,,,,,,,,,,,,,,,
15.126,1.89816,25.60936,0.5,,,,,,,,,,,,,,,,,,,0.153,,,,,,,,,,,,,,,,,,
15.826,1.78143,22.04995,0.5,,,,,,,,,,,,,,,,,,,0.16,,,,,,,,,,,,,,,,,,
16.526,1.66481,18.79113,0.5,,,,,,,,,,,,,,,,,,,0.167,,,,,,,,,,,,,,,,,,
17.226,1.54808,15.91832,0.5,,,,,,,,,,,,,,,,,,,0.174,,,,,,,,,,,,,,,,,,
17.926,1.43146,13.46931,0.5,,,,,,,,,,,,,,,,,,,0.181,,,,,,,,,,,,,,,,,,
18.626,1.31467,11.11501,0.5,,,,,,,,,,,,,,,,,,,0.188,,,,,,,,,,,,,,,,,,
19.326,1.19799,9.11729,0.5,,,,,,,,,,,,,,,,,,,0.195,,,,,,,,,,,,,,,,,,
20.026,1.08131,7.46279,0.5,,,,,,,,,,,,,,,,,,,,,,,,,,,,,,,,,,,,,
20.726,0.96464,5.79565,0.5,,,,,,,,,,,,,,,,,,,,,,,,,,,,,,,,,,,,,
21.426,0.84807,4.28444,0.5,,,,,,,,,,,,,,,,,,,,,,,,,,,,,,,,,,,,,
22.126,0.7314,2.9755,0.5,,,,,,,,,,,,,,,,,,,,,,,,,,,,,,,,,,,,,
22.826,0.61472,1.87671,0.5,,,,,,,,,,,,,,,,,,,,,,,,,,,,,,,,,,,,,
23.502,0.50212,0.99887,1,,,,,,,,,,,,,,,,,,,,,,,,,,,,,,,,,,,,,
24.006,0.58576,2.20734,1,,,,,,,,,,,,,,,,,,,,,,,,,,,,,,,,,,,,,
24.706,0.7025,3.79371,1,,,,,,,,,,,,,,,,,,,,,,,,,,,,,,,,,,,,,
25.406,0.81912,5.19927,1,,,,,,,,,,,,,,,,,,,,,,,,,,,,,,,,,,,,,
26.106,0.93579,6.86783,1,,,,,,,,,,,,,,,,,,,,,,,,,,,,,,,,,,,,,
26.806,1.05247,8.61907,1,,,,,,,,,,,,,,,,,,,,,,,,,,,,,,,,,,,,,
27.506,1.16909,10.3712,1,,,,,,,,,,,,,,,,,,,,,,,,,,,,,,,,,,,,,
28.206,1.28571,12.35353,1,,,,,,,,,,,,,,,,,,,,,,,,,,,,,,,,,,,,,
28.906,1.40233,14.71668,1,,,,,,,,,,,,,,,,,,,,,,,,,,,,,,,,,,,,,
29.606,1.51895,17.17337,1,,,,,,,,,,,,,,,,,,,,,,,,,,,,,,,,,,,,,
30.306,1.63568,19.94344,1,,,,,,,,,,,,,,,,,,,,,,,,,,,,,,,,,,,,,
31.006,1.75236,22.95119,1,,,,,,,,,,,,,,,,,,,,,,,,,,,,,,,,,,,,,
31.706,1.86904,26.14018,1,,,,,,,,,,,,,,,,,,,,,,,,,,,,,,,,,,,,,
32.406,1.98571,29.67658,1,,,,,,,,,,,,,,,,,,,,,,,,,,,,,,,,,,,,,
33.106,2.10228,33.40717,1,,,,,,,,,,,,,,,,,,,,,,,,,,,,,,,,,,,,,
33.806,2.21901,37.38034,1,,,,,,,,,,,,,,,,,,,,,,,,,,,,,,,,,,,,,
34.36,2.28242,39.81511,1.5,,,,,,,,,,,,,,,,,,,,,,,,,,,,,,,,,,,,,
35.06,2.16098,33.88034,1.5,,,,,,,,,,,,,,,,,,,,,,,,,,,,,,,,,,,,,
35.76,2.04431,29.26253,1.5,,,,,,,,,,,,,,,,,,,,,,,,,,,,,,,,,,,,,
36.46,1.92769,25.2171,1.5,,,,,,,,,,,,,,,,,,,,,,,,,,,,,,,,,,,,,
37.16,1.81107,21.65926,1.5,,,,,,,,,,,,,,,,,,,,,,,,,,,,,,,,,,,,,
37.86,1.69439,18.42283,1.5,,,,,,,,,,,,,,,,,,,,,,,,,,,,,,,,,,,,,
38.56,1.57777,15.6436,1.5,,,,,,,,,,,,,,,,,,,,,,,,,,,,,,,,,,,,,
39.26,1.46109,13.00398,1.5,,,,,,,,,,,,,,,,,,,,,,,,,,,,,,,,,,,,,
39.96,1.34447,10.93155,1.5,,,,,,,,,,,,,,,,,,,,,,,,,,,,,,,,,,,,,
40.66,1.2278,8.93138,1.5,,,,,,,,,,,,,,,,,,,,,,,,,,,,,,,,,,,,,
41.36,1.11106,7.21742,1.5,,,,,,,,,,,,,,,,,,,,,,,,,,,,,,,,,,,,,
42.06,0.99444,5.62702,1.5,,,,,,,,,,,,,,,,,,,,,,,,,,,,,,,,,,,,,
42.76,0.87782,4.12398,1.5,,,,,,,,,,,,,,,,,,,,,,,,,,,,,,,,,,,,,
43.46,0.76115,2.75493,1.5,,,,,,,,,,,,,,,,,,,,,,,,,,,,,,,,,,,,,
44.16,0.64447,1.76079,1.5,,,,,,,,,,,,,,,,,,,,,,,,,,,,,,,,,,,,,
44.696,0.55511,0.9932,2,,,,,,,,,,,,,,,,,,,,,,,,,,,,,,,,,,,,,
45.298,0.65569,2.44374,2,,,,,,,,,,,,,,,,,,,,,,,,,,,,,,,,,,,,,
45.998,0.77231,3.97607,2,,,,,,,,,,,,,,,,,,,,,,,,,,,,,,,,,,,,,
46.698,0.88904,5.49601,2,,,,,,,,,,,,,,,,,,,,,,,,,,,,,,,,,,,,,
47.398,1.00578,7.17462,2,,,,,,,,,,,,,,,,,,,,,,,,,,,,,,,,,,,,,
48.098,1.1224,8.94796,2,,,,,,,,,,,,,,,,,,,,,,,,,,,,,,,,,,,,,
48.798,1.23902,10.70928,2,,,,,,,,,,,,,,,,,,,,,,,,,,,,,,,,,,,,,
49.498,1.35569,12.80562,2,,,,,,,,,,,,,,,,,,,,,,,,,,,,,,,,,,,,,
50.198,1.47237,15.24026,2,,,,,,,,,,,,,,,,,,,,,,,,,,,,,,,,,,,,,
50.898,1.58899,17.74803,2,,,,,,,,,,,,,,,,,,,,,,,,,,,,,,,,,,,,,
51.598,1.70561,20.68303,2,,,,,,,,,,,,,,,,,,,,,,,,,,,,,,,,,,,,,
52.298,1.82234,23.80699,2,,,,,,,,,,,,,,,,,,,,,,,,,,,,,,,,,,,,,
52.998,1.93902,27.21853,2,,,,,,,,,,,,,,,,,,,,,,,,,,,,,,,,,,,,,
53.698,2.05575,30.79178,2,,,,,,,,,,,,,,,,,,,,,,,,,,,,,,,,,,,,,
54.398,2.17254,34.78137,2,,,,,,,,,,,,,,,,,,,,,,,,,,,,,,,,,,,,,
55.098,2.28922,38.84903,2,,,,,,,,,,,,,,,,,,,,,,,,,,,,,,,,,,,,,
55.684,2.25324,36.92098,2.5,,,,,,,,,,,,,,,,,,,,,,,,,,,,,,,,,,,,,
56.384,2.1365,31.8627,2.5,,,,,,,,,,,,,,,,,,,,,,,,,,,,,,,,,,,,,
57.084,2.01977,27.44726,2.5,,,,,,,,,,,,,,,,,,,,,,,,,,,,,,,,,,,,,
57.784,1.90315,23.61854,2.5,,,,,,,,,,,,,,,,,,,,,,,,,,,,,,,,,,,,,
58.484,1.78647,20.19579,2.5,,,,,,,,,,,,,,,,,,,,,,,,,,,,,,,,,,,,,
59.184,1.6698,17.1032,2.5,,,,,,,,,,,,,,,,,,,,,,,,,,,,,,,,,,,,,
59.884,1.55312,14.42048,2.5,,,,,,,,,,,,,,,,,,,,,,,,,,,,,,,,,,,,,
60.584,1.43644,12.09968,2.5,,,,,,,,,,,,,,,,,,,,,,,,,,,,,,,,,,,,,
61.284,1.31977,9.88918,2.5,,,,,,,,,,,,,,,,,,,,,,,,,,,,,,,,,,,,,
61.984,1.20303,8.10446,2.5,,,,,,,,,,,,,,,,,,,,,,,,,,,,,,,,,,,,,
62.684,1.08636,6.41384,2.5,,,,,,,,,,,,,,,,,,,,,,,,,,,,,,,,,,,,,
63.384,0.96962,4.89832,2.5,,,,,,,,,,,,,,,,,,,,,,,,,,,,,,,,,,,,,
64.084,0.85295,3.45373,2.5,,,,,,,,,,,,,,,,,,,,,,,,,,,,,,,,,,,,,
64.784,0.73627,2.27154,2.5,,,,,,,,,,,,,,,,,,,,,,,,,,,,,,,,,,,,,
65.484,0.61971,1.24821,2.5,,,,,,,,,,,,,,,,,,,,,,,,,,,,,,,,,,,,,
65.896,0.61829,1.44044,3,,,,,,,,,,,,,,,,,,,,,,,,,,,,,,,,,,,,,
66.596,0.73536,3.11267,3,,,,,,,,,,,,,,,,,,,,,,,,,,,,,,,,,,,,,
67.296,0.85193,4.63335,3,,,,,,,,,,,,,,,,,,,,,,,,,,,,,,,,,,,,,
67.996,0.9686,6.25764,3,,,,,,,,,,,,,,,,,,,,,,,,,,,,,,,,,,,,,
68.696,1.08528,7.90998,3,,,,,,,,,,,,,,,,,,,,,,,,,,,,,,,,,,,,,
69.396,1.20207,9.67079,3,,,,,,,,,,,,,,,,,,,,,,,,,,,,,,,,,,,,,
70.096,1.31875,11.6369,3,,,,,,,,,,,,,,,,,,,,,,,,,,,,,,,,,,,,,
70.796,1.43548,13.86147,3,,,,,,,,,,,,,,,,,,,,,,,,,,,,,,,,,,,,,
71.496,1.55216,16.38506,3,,,,,,,,,,,,,,,,,,,,,,,,,,,,,,,,,,,,,
72.196,1.66883,19.13655,3,,,,,,,,,,,,,,,,,,,,,,,,,,,,,,,,,,,,,
72.896,1.78545,22.12877,3,,,,,,,,,,,,,,,,,,,,,,,,,,,,,,,,,,,,,
73.596,1.90213,25.43637,3,,,,,,,,,,,,,,,,,,,,,,,,,,,,,,,,,,,,,
74.296,2.01869,28.95001,3,,,,,,,,,,,,,,,,,,,,,,,,,,,,,,,,,,,,,
74.996,2.13537,32.86404,3,,,,,,,,,,,,,,,,,,,,,,,,,,,,,,,,,,,,,
75.696,2.25205,36.96053,3,,,,,,,,,,,,,,,,,,,,,,,,,,,,,,,,,,,,,
76.208,2.33739,40.03392,3.5,,,,,,,,,,,,,,,,,,,,,,,,,,,,,,,,,,,,,
76.908,2.22043,34.66941,3.5,,,,,,,,,,,,,,,,,,,,,,,,,,,,,,,,,,,,,
77.608,2.10369,29.9138,3.5,,,,,,,,,,,,,,,,,,,,,,,,,,,,,,,,,,,,,
78.308,1.9869,25.75815,3.5,,,,,,,,,,,,,,,,,,,,,,,,,,,,,,,,,,,,,
79.008,1.87034,22.09143,3.5,,,,,,,,,,,,,,,,,,,,,,,,,,,,,,,,,,,,,
79.708,1.75372,18.82015,3.5,,,,,,,,,,,,,,,,,,,,,,,,,,,,,,,,,,,,,
80.408,1.6371,15.9477,3.5,,,,,,,,,,,,,,,,,,,,,,,,,,,,,,,,,,,,,
81.108,1.52042,13.38029,3.5,,,,,,,,,,,,,,,,,,,,,,,,,,,,,,,,,,,,,
81.808,1.40375,11.07959,3.5,,,,,,,,,,,,,,,,,,,,,,,,,,,,,,,,,,,,,
82.508,1.28713,9.05629,3.5,,,,,,,,,,,,,,,,,,,,,,,,,,,,,,,,,,,,,
83.208,1.17045,7.3738,3.5,,,,,,,,,,,,,,,,,,,,,,,,,,,,,,,,,,,,,
83.908,1.05377,5.64656,3.5,,,,,,,,,,,,,,,,,,,,,,,,,,,,,,,,,,,,,
84.608,0.9371,4.16592,3.5,,,,,,,,,,,,,,,,,,,,,,,,,,,,,,,,,,,,,
85.308,0.82048,2.8899,3.5,,,,,,,,,,,,,,,,,,,,,,,,,,,,,,,,,,,,,
86.008,0.7038,1.75989,3.5,,,,,,,,,,,,,,,,,,,,,,,,,,,,,,,,,,,,,
86.59,0.60679,0.99461,4,,,,,,,,,,,,,,,,,,,,,,,,,,,,,,,,,,,,,
87.192,0.70743,2.41482,4,,,,,,,,,,,,,,,,,,,,,,,,,,,,,,,,,,,,,
87.892,0.82416,4.03223,4,,,,,,,,,,,,,,,,,,,,,,,,,,,,,,,,,,,,,
88.592,0.94078,5.55914,4,,,,,,,,,,,,,,,,,,,,,,,,,,,,,,,,,,,,,
89.292,1.05746,7.19744,4,,,,,,,,,,,,,,,,,,,,,,,,,,,,,,,,,,,,,
89.992,1.17402,8.91086,4,,,,,,,,,,,,,,,,,,,,,,,,,,,,,,,,,,,,,
90.692,1.29064,10.77447,4,,,,,,,,,,,,,,,,,,,,,,,,,,,,,,,,,,,,,
91.392,1.40737,12.92846,4,,,,,,,,,,,,,,,,,,,,,,,,,,,,,,,,,,,,,
92.092,1.52405,15.38798,4,,,,,,,,,,,,,,,,,,,,,,,,,,,,,,,,,,,,,
92.792,1.64073,18.01063,4,,,,,,,,,,,,,,,,,,,,,,,,,,,,,,,,,,,,,
93.492,1.75729,20.93309,4,,,,,,,,,,,,,,,,,,,,,,,,,,,,,,,,,,,,,
94.192,1.87397,24.09105,4,,,,,,,,,,,,,,,,,,,,,,,,,,,,,,,,,,,,,
94.892,1.9907,27.56051,4,,,,,,,,,,,,,,,,,,,,,,,,,,,,,,,,,,,,,
95.592,2.10743,31.3655,4,,,,,,,,,,,,,,,,,,,,,,,,,,,,,,,,,,,,,
96.292,2.22405,35.39654,4,,,,,,,,,,,,,,,,,,,,,,,,,,,,,,,,,,,,,
96.992,2.34079,39.6708,4,,,,,,,,,,,,,,,,,,,,,,,,,,,,,,,,,,,,,
97.546,2.26604,36.13175,4.5,,,,,,,,,,,,,,,,,,,,,,,,,,,,,,,,,,,,,
98.246,2.14937,31.13207,4.5,,,,,,,,,,,,,,,,,,,,,,,,,,,,,,,,,,,,,
98.946,2.03275,26.83036,4.5,,,,,,,,,,,,,,,,,,,,,,,,,,,,,,,,,,,,,
99.646,1.91613,23.08216,4.5,,,,,,,,,,,,,,,,,,,,,,,,,,,,,,,,,,,,,
100.346,1.79945,19.64593,4.5,,,,,,,,,,,,,,,,,,,,,,,,,,,,,,,,,,,,,
101.046,1.68277,16.72835,4.5,,,,,,,,,,,,,,,,,,,,,,,,,,,,,,,,,,,,,
101.746,1.5661,13.99073,4.5,,,,,,,,,,,,,,,,,,,,,,,,,,,,,,,,,,,,,
102.446,1.44948,11.67686,4.5,,,,,,,,,,,,,,,,,,,,,,,,,,,,,,,,,,,,,
103.146,1.3328,9.61636,4.5,,,,,,,,,,,,,,,,,,,,,,,,,,,,,,,,,,,,,
103.846,1.21612,7.74822,4.5,,,,,,,,,,,,,,,,,,,,,,,,,,,,,,,,,,,,,
104.546,1.09945,6.06324,4.5,,,,,,,,,,,,,,,,,,,,,,,,,,,,,,,,,,,,,
105.246,0.98277,4.54518,4.5,,,,,,,,,,,,,,,,,,,,,,,,,,,,,,,,,,,,,
105.946,0.86604,3.16684,4.5,,,,,,,,,,,,,,,,,,,,,,,,,,,,,,,,,,,,,
106.646,0.74936,2.02855,4.5,,,,,,,,,,,,,,,,,,,,,,,,,,,,,,,,,,,,,
107.346,0.63268,1.05934,4.5,,,,,,,,,,,,,,,,,,,,,,,,,,,,,,,,,,,,,
107.798,0.69167,1.96707,5,,,,,,,,,,,,,,,,,,,,,,,,,,,,,,,,,,,,,
108.498,0.80835,3.61772,5,,,,,,,,,,,,,,,,,,,,,,,,,,,,,,,,,,,,,
109.198,0.92508,5.08841,5,,,,,,,,,,,,,,,,,,,,,,,,,,,,,,,,,,,,,
109.898,1.04176,6.76769,5,,,,,,,,,,,,,,,,,,,,,,,,,,,,,,,,,,,,,
110.598,1.15849,8.4592,5,,,,,,,,,,,,,,,,,,,,,,,,,,,,,,,,,,,,,
111.298,1.27517,10.28116,5,,,,,,,,,,,,,,,,,,,,,,,,,,,,,,,,,,,,,
111.998,1.39179,12.40827,5,,,,,,,,,,,,,,,,,,,,,,,,,,,,,,,,,,,,,
112.698,1.50835,14.75027,5,,,,,,,,,,,,,,,,,,,,,,,,,,,,,,,,,,,,,
113.398,1.62503,17.33505,5,,,,,,,,,,,,,,,,,,,,,,,,,,,,,,,,,,,,,
114.098,1.74171,20.21791,5,,,,,,,,,,,,,,,,,,,,,,,,,,,,,,,,,,,,,
114.798,1.85844,23.29794,5,,,,,,,,,,,,,,,,,,,,,,,,,,,,,,,,,,,,,
115.498,1.97506,26.72221,5,,,,,,,,,,,,,,,,,,,,,,,,,,,,,,,,,,,,,
116.198,2.09168,30.44898,5,,,,,,,,,,,,,,,,,,,,,,,,,,,,,,,,,,,,,
116.898,2.2083,34.43701,5,,,,,,,,,,,,,,,,,,,,,,,,,,,,,,,,,,,,,
117.598,2.32498,38.73504,5,,,,,,,,,,,,,,,,,,,,,,,,,,,,,,,,,,,,,
118.112,2.31053,37.80014,5.5,,,,,,,,,,,,,,,,,,,,,,,,,,,,,,,,,,,,,
118.812,2.19385,32.51576,5.5,,,,,,,,,,,,,,,,,,,,,,,,,,,,,,,,,,,,,
119.512,2.07717,28.01959,5.5,,,,,,,,,,,,,,,,,,,,,,,,,,,,,,,,,,,,,
120.212,1.9605,24.1306,5.5,,,,,,,,,,,,,,,,,,,,,,,,,,,,,,,,,,,,,
120.912,1.84371,20.58189,5.5,,,,,,,,,,,,,,,,,,,,,,,,,,,,,,,,,,,,,
121.612,1.72709,17.49906,5.5,,,,,,,,,,,,,,,,,,,,,,,,,,,,,,,,,,,,,
122.312,1.61047,14.76301,5.5,,,,,,,,,,,,,,,,,,,,,,,,,,,,,,,,,,,,,
123.012,1.49379,12.24717,5.5,,,,,,,,,,,,,,,,,,,,,,,,,,,,,,,,,,,,,
123.712,1.37717,10.10679,5.5,,,,,,,,,,,,,,,,,,,,,,,,,,,,,,,,,,,,,
124.412,1.26038,8.17391,5.5,,,,,,,,,,,,,,,,,,,,,,,,,,,,,,,,,,,,,
125.112,1.14359,6.47797,5.5,,,,,,,,,,,,,,,,,,,,,,,,,,,,,,,,,,,,,
125.812,1.02697,4.95116,5.5,,,,,,,,,,,,,,,,,,,,,,,,,,,,,,,,,,,,,
126.512,0.91029,3.56692,5.5,,,,,,,,,,,,,,,,,,,,,,,,,,,,,,,,,,,,,
127.212,0.79373,2.29668,5.5,,,,,,,,,,,,,,,,,,,,,,,,,,,,,,,,,,,,,
127.912,0.677,1.37488,5.5,,,,,,,,,,,,,,,,,,,,,,,,,,,,,,,,,,,,,
128.404,0.69604,1.80384,6,,,,,,,,,,,,,,,,,,,,,,,,,,,,,,,,,,,,,
129.104,0.81277,3.49494,6,,,,,,,,,,,,,,,,,,,,,,,,,,,,,,,,,,,,,
129.804,0.92956,4.96065,6,,,,,,,,,,,,,,,,,,,,,,,,,,,,,,,,,,,,,
130.504,1.04618,6.62074,6,,,,,,,,,,,,,,,,,,,,,,,,,,,,,,,,,,,,,
131.204,1.16274,8.30646,6,,,,,,,,,,,,,,,,,,,,,,,,,,,,,,,,,,,,,
131.904,1.27942,10.19191,6,,,,,,,,,,,,,,,,,,,,,,,,,,,,,,,,,,,,,
132.604,1.3961,12.19366,6,,,,,,,,,,,,,,,,,,,,,,,,,,,,,,,,,,,,,
133.304,1.51272,14.57472,6,,,,,,,,,,,,,,,,,,,,,,,,,,,,,,,,,,,,,
134.004,1.62939,17.11389,6,,,,,,,,,,,,,,,,,,,,,,,,,,,,,,,,,,,,,
134.704,1.74601,20.00974,6,,,,,,,,,,,,,,,,,,,,,,,,,,,,,,,,,,,,,
135.404,1.86269,23.13423,6,,,,,,,,,,,,,,,,,,,,,,,,,,,,,,,,,,,,,
136.104,1.97937,26.48749,6,,,,,,,,,,,,,,,,,,,,,,,,,,,,,,,,,,,,,
136.804,2.09604,30.22463,6,,,,,,,,,,,,,,,,,,,,,,,,,,,,,,,,,,,,,
137.504,2.21261,34.30701,6,,,,,,,,,,,,,,,,,,,,,,,,,,,,,,,,,,,,,
138.204,2.32928,38.53965,6,,,,,,,,,,,,,,,,,,,,,,,,,,,,,,,,,,,,,
138.742,2.31886,37.72335,6.5,,,,,,,,,,,,,,,,,,,,,,,,,,,,,,,,,,,,,
139.442,2.20212,32.48177,6.5,,,,,,,,,,,,,,,,,,,,,,,,,,,,,,,,,,,,,
140.142,2.08545,28.06669,6.5,,,,,,,,,,,,,,,,,,,,,,,,,,,,,,,,,,,,,
140.842,1.96883,24.0704,6.5,,,,,,,,,,,,,,,,,,,,,,,,,,,,,,,,,,,,,
141.542,1.85215,20.59426,6.5,,,,,,,,,,,,,,,,,,,,,,,,,,,,,,,,,,,,,
142.242,1.73547,17.48595,6.5,,,,,,,,,,,,,,,,,,,,,,,,,,,,,,,,,,,,,
142.942,1.61874,14.70303,6.5,,,,,,,,,,,,,,,,,,,,,,,,,,,,,,,,,,,,,
143.642,1.50212,12.26594,6.5,,,,,,,,,,,,,,,,,,,,,,,,,,,,,,,,,,,,,
144.342,1.3855,10.07862,6.5,,,,,,,,,,,,,,,,,,,,,,,,,,,,,,,,,,,,,
145.042,1.26877,8.1614,6.5,,,,,,,,,,,,,,,,,,,,,,,,,,,,,,,,,,,,,
145.742,1.15215,6.4538,6.5,,,,,,,,,,,,,,,,,,,,,,,,,,,,,,,,,,,,,
146.442,1.03536,4.87068,6.5,,,,,,,,,,,,,,,,,,,,,,,,,,,,,,,,,,,,,
147.142,0.91862,3.48836,6.5,,,,,,,,,,,,,,,,,,,,,,,,,,,,,,,,,,,,,
147.842,0.80195,2.27648,6.5,,,,,,,,,,,,,,,,,,,,,,,,,,,,,,,,,,,,,
148.542,0.68533,1.28926,6.5,,,,,,,,,,,,,,,,,,,,,,,,,,,,,,,,,,,,,
149.04,0.7034,1.72636,7,,,,,,,,,,,,,,,,,,,,,,,,,,,,,,,,,,,,,
149.74,0.82014,3.4577,7,,,,,,,,,,,,,,,,,,,,,,,,,,,,,,,,,,,,,
150.44,0.93676,4.90482,7,,,,,,,,,,,,,,,,,,,,,,,,,,,,,,,,,,,,,
151.14,1.05343,6.59025,7,,,,,,,,,,,,,,,,,,,,,,,,,,,,,,,,,,,,,
151.84,1.17011,8.30449,7,,,,,,,,,,,,,,,,,,,,,,,,,,,,,,,,,,,,,
152.54,1.28679,10.05941,7,,,,,,,,,,,,,,,,,,,,,,,,,,,,,,,,,,,,,
153.24,1.40341,12.15917,7,,,,,,,,,,,,,,,,,,,,,,,,,,,,,,,,,,,,,
153.94,1.51997,14.50816,7,,,,,,,,,,,,,,,,,,,,,,,,,,,,,,,,,,,,,
154.64,1.63665,17.07069,7,,,,,,,,,,,,,,,,,,,,,,,,,,,,,,,,,,,,,
155.34,1.75332,19.95633,7,,,,,,,,,,,,,,,,,,,,,,,,,,,,,,,,,,,,,
156.04,1.87006,23.08439,7,,,,,,,,,,,,,,,,,,,,,,,,,,,,,,,,,,,,,
156.74,1.98673,26.50466,7,,,,,,,,,,,,,,,,,,,,,,,,,,,,,,,,,,,,,
157.44,2.10335,30.22181,7,,,,,,,,,,,,,,,,,,,,,,,,,,,,,,,,,,,,,
158.14,2.21997,34.21445,7,,,,,,,,,,,,,,,,,,,,,,,,,,,,,,,,,,,,,
158.84,2.33671,38.43778,7,,,,,,,,,,,,,,,,,,,,,,,,,,,,,,,,,,,,,
159.384,2.32713,37.74334,7.5,,,,,,,,,,,,,,,,,,,,,,,,,,,,,,,,,,,,,
160.084,2.2104,32.5428,7.5,,,,,,,,,,,,,,,,,,,,,,,,,,,,,,,,,,,,,
160.784,2.09366,27.97703,7.5,,,,,,,,,,,,,,,,,,,,,,,,,,,,,,,,,,,,,
161.484,1.9771,24.10162,7.5,,,,,,,,,,,,,,,,,,,,,,,,,,,,,,,,,,,,,
162.184,1.86042,20.58787,7.5,,,,,,,,,,,,,,,,,,,,,,,,,,,,,,,,,,,,,
162.884,1.7438,17.4565,7.5,,,,,,,,,,,,,,,,,,,,,,,,,,,,,,,,,,,,,
163.584,1.62718,14.66186,7.5,,,,,,,,,,,,,,,,,,,,,,,,,,,,,,,,,,,,,
164.284,1.51045,12.23329,7.5,,,,,,,,,,,,,,,,,,,,,,,,,,,,,,,,,,,,,
164.984,1.39377,10.07359,7.5,,,,,,,,,,,,,,,,,,,,,,,,,,,,,,,,,,,,,
165.684,1.27715,8.12827,7.5,,,,,,,,,,,,,,,,,,,,,,,,,,,,,,,,,,,,,
166.384,1.16048,6.47497,7.5,,,,,,,,,,,,,,,,,,,,,,,,,,,,,,,,,,,,,
167.084,1.04374,4.89289,7.5,,,,,,,,,,,,,,,,,,,,,,,,,,,,,,,,,,,,,
167.784,0.92707,3.49297,7.5,,,,,,,,,,,,,,,,,,,,,,,,,,,,,,,,,,,,,
168.484,0.81039,2.2405,7.5,,,,,,,,,,,,,,,,,,,,,,,,,,,,,,,,,,,,,
169.184,0.69371,1.31542,7.5,,,,,,,,,,,,,,,,,,,,,,,,,,,,,,,,,,,,,
169.654,0.71627,1.72681,8,,,,,,,,,,,,,,,,,,,,,,,,,,,,,,,,,,,,,
170.354,0.833,3.4299,8,,,,,,,,,,,,,,,,,,,,,,,,,,,,,,,,,,,,,
171.054,0.94979,4.9256,8,,,,,,,,,,,,,,,,,,,,,,,,,,,,,,,,,,,,,
171.754,1.06635,6.62231,8,,,,,,,,,,,,,,,,,,,,,,,,,,,,,,,,,,,,,
172.454,1.18303,8.29049,8,,,,,,,,,,,,,,,,,,,,,,,,,,,,,,,,,,,,,
173.154,1.29971,10.12752,8,,,,,,,,,,,,,,,,,,,,,,,,,,,,,,,,,,,,,
173.854,1.41638,12.17062,8,,,,,,,,,,,,,,,,,,,,,,,,,,,,,,,,,,,,,
174.554,1.533,14.65861,8,,,,,,,,,,,,,,,,,,,,,,,,,,,,,,,,,,,,,
175.254,1.64957,17.19452,8,,,,,,,,,,,,,,,,,,,,,,,,,,,,,,,,,,,,,
175.954,1.7663,20.05756,8,,,,,,,,,,,,,,,,,,,,,,,,,,,,,,,,,,,,,
176.654,1.88303,23.15372,8,,,,,,,,,,,,,,,,,,,,,,,,,,,,,,,,,,,,,
177.354,1.99982,26.56932,8,,,,,,,,,,,,,,,,,,,,,,,,,,,,,,,,,,,,,
178.054,2.11656,30.3492,8,,,,,,,,,,,,,,,,,,,,,,,,,,,,,,,,,,,,,
178.754,2.23318,34.36384,8,,,,,,,,,,,,,,,,,,,,,,,,,,,,,,,,,,,,,
179.454,2.3498,38.68763,8,,,,,,,,,,,,,,,,,,,,,,,,,,,,,,,,,,,,,
179.958,2.33342,37.68763,8.5,,,,,,,,,,,,,,,,,,,,,,,,,,,,,,,,,,,,,
180.658,2.21674,32.44334,8.5,,,,,,,,,,,,,,,,,,,,,,,,,,,,,,,,,,,,,
181.358,2.10001,27.9693,8.5,,,,,,,,,,,,,,,,,,,,,,,,,,,,,,,,,,,,,
182.058,1.98333,24.06865,8.5,,,,,,,,,,,,,,,,,,,,,,,,,,,,,,,,,,,,,
182.758,1.86666,20.49823,8.5,,,,,,,,,,,,,,,,,,,,,,,,,,,,,,,,,,,,,
183.458,1.75009,17.44463,8.5,,,,,,,,,,,,,,,,,,,,,,,,,,,,,,,,,,,,,
184.158,1.63347,14.61052,8.5,,,,,,,,,,,,,,,,,,,,,,,,,,,,,,,,,,,,,
184.858,1.5168,12.17574,8.5,,,,,,,,,,,,,,,,,,,,,,,,,,,,,,,,,,,,,
185.558,1.40018,10.03303,8.5,,,,,,,,,,,,,,,,,,,,,,,,,,,,,,,,,,,,,
186.258,1.28344,8.12406,8.5,,,,,,,,,,,,,,,,,,,,,,,,,,,,,,,,,,,,,
186.958,1.16677,6.38324,8.5,,,,,,,,,,,,,,,,,,,,,,,,,,,,,,,,,,,,,
187.658,1.05015,4.85832,8.5,,,,,,,,,,,,,,,,,,,,,,,,,,,,,,,,,,,,,
188.358,0.93347,3.41268,8.5,,,,,,,,,,,,,,,,,,,,,,,,,,,,,,,,,,,,,
189.058,0.81679,2.24898,8.5,,,,,,,,,,,,,,,,,,,,,,,,,,,,,,,,,,,,,
189.758,0.70012,1.30261,8.5,,,,,,,,,,,,,,,,,,,,,,,,,,,,,,,,,,,,,
190.218,0.72431,1.71989,9,,,,,,,,,,,,,,,,,,,,,,,,,,,,,,,,,,,,,
190.918,0.84105,3.45847,9,,,,,,,,,,,,,,,,,,,,,,,,,,,,,,,,,,,,,
191.618,0.95761,5.0027,9,,,,,,,,,,,,,,,,,,,,,,,,,,,,,,,,,,,,,
192.318,1.07434,6.60963,9,,,,,,,,,,,,,,,,,,,,,,,,,,,,,,,,,,,,,
193.018,1.19102,8.34408,9,,,,,,,,,,,,,,,,,,,,,,,,,,,,,,,,,,,,,
193.718,1.3077,10.1496,9,,,,,,,,,,,,,,,,,,,,,,,,,,,,,,,,,,,,,
194.418,1.42432,12.21269,9,,,,,,,,,,,,,,,,,,,,,,,,,,,,,,,,,,,,,
195.118,1.54099,14.60206,9,,,,,,,,,,,,,,,,,,,,,,,,,,,,,,,,,,,,,
195.818,1.65773,17.21474,9,,,,,,,,,,,,,,,,,,,,,,,,,,,,,,,,,,,,,
196.518,1.77446,20.04189,9,,,,,,,,,,,,,,,,,,,,,,,,,,,,,,,,,,,,,
197.218,1.89114,23.23135,9,,,,,,,,,,,,,,,,,,,,,,,,,,,,,,,,,,,,,
197.918,2.00781,26.69915,9,,,,,,,,,,,,,,,,,,,,,,,,,,,,,,,,,,,,,
198.618,2.12443,30.36642,9,,,,,,,,,,,,,,,,,,,,,,,,,,,,,,,,,,,,,
199.318,2.24111,34.46006,9,,,,,,,,,,,,,,,,,,,,,,,,,,,,,,,,,,,,,
200.018,2.35779,38.82746,9,,,,,,,,,,,,,,,,,,,,,,,,,,,,,,,,,,,,,
200.618,2.32407,36.98929,9.5,,,,,,,,,,,,,,,,,,,,,,,,,,,,,,,,,,,,,
201.318,2.20745,31.83511,9.5,,,,,,,,,,,,,,,,,,,,,,,,,,,,,,,,,,,,,
202.018,2.09072,27.46129,9.5,,,,,,,,,,,,,,,,,,,,,,,,,,,,,,,,,,,,,
202.718,1.97404,23.59039,9.5,,,,,,,,,,,,,,,,,,,,,,,,,,,,,,,,,,,,,
203.418,1.85742,20.12679,9.5,,,,,,,,,,,,,,,,,,,,,,,,,,,,,,,,,,,,,
204.118,1.74086,17.08511,9.5,,,,,,,,,,,,,,,,,,,,,,,,,,,,,,,,,,,,,
204.818,1.62418,14.35619,9.5,,,,,,,,,,,,,,,,,,,,,,,,,,,,,,,,,,,,,
205.518,1.50745,11.90881,9.5,,,,,,,,,,,,,,,,,,,,,,,,,,,,,,,,,,,,,
206.218,1.39077,9.78605,9.5,,,,,,,,,,,,,,,,,,,,,,,,,,,,,,,,,,,,,
206.918,1.27409,7.9131,9.5,,,,,,,,,,,,,,,,,,,,,,,,,,,,,,,,,,,,,
207.618,1.15747,6.1815,9.5,,,,,,,,,,,,,,,,,,,,,,,,,,,,,,,,,,,,,
208.318,1.04074,4.71306,9.5,,,,,,,,,,,,,,,,,,,,,,,,,,,,,,,,,,,,,
209.018,0.92412,3.27644,9.5,,,,,,,,,,,,,,,,,,,,,,,,,,,,,,,,,,,,,
209.718,0.80739,2.04369,9.5,,,,,,,,,,,,,,,,,,,,,,,,,,,,,,,,,,,,,
210.418,0.69065,1.08133,9.5,,,,,,,,,,,,,,,,,,,,,,,,,,,,,,,,,,,,,
211.008,0.63121,0.60951,10,,,,,,,,,,,,,,,,,,,,,,,,,,,,,,,,,,,,,
211.708,0.6307,0.64882,10,,,,,,,,,,,,,,,,,,,,,,,,,,,,,,,,,,,,,
212.408,0.63206,0.77538,10,,,,,,,,,,,,,,,,,,,,,,,,,,,,,,,,,,,,,
213.108,0.64328,1.01239,10,,,,,,,,,,,,,,,,,,,,,,,,,,,,,,,,,,,,,
213.808,0.65631,1.16597,10,,,,,,,,,,,,,,,,,,,,,,,,,,,,,,,,,,,,,
214.508,0.65614,1.15172,10,,,,,,,,,,,,,,,,,,,,,,,,,,,,,,,,,,,,,
215.208,0.65575,1.21249,10,,,,,,,,,,,,,,,,,,,,,,,,,,,,,,,,,,,,,
215.908,0.6528,1.14279,10,,,,,,,,,,,,,,,,,,,,,,,,,,,,,,,,,,,,,
216.608,0.64515,1.01398,10,,,,,,,,,,,,,,,,,,,,,,,,,,,,,,,,,,,,,
217.308,0.64096,1.07537,10,,,,,,,,,,,,,,,,,,,,,,,,,,,,,,,,,,,,,
218.008,0.6405,0.99862,10,,,,,,,,,,,,,,,,,,,,,,,,,,,,,,,,,,,,,
218.708,0.64022,0.99385,10,,,,,,,,,,,,,,,,,,,,,,,,,,,,,,,,,,,,,
219.408,0.64005,1.03963,10,,,,,,,,,,,,,,,,,,,,,,,,,,,,,,,,,,,,,
220.108,0.63971,1.03712,10,,,,,,,,,,,,,,,,,,,,,,,,,,,,,,,,,,,,,
220.808,0.63909,1.01111,10,,,,,,,,,,,,,,,,,,,,,,,,,,,,,,,,,,,,,
221.508,0.6379,1.05527,10,,,,,,,,,,,,,,,,,,,,,,,,,,,,,,,,,,,,,
222.208,0.63699,0.99068,10,,,,,,,,,,,,,,,,,,,,,,,,,,,,,,,,,,,,,
222.908,0.63603,0.9742,10,,,,,,,,,,,,,,,,,,,,,,,,,,,,,,,,,,,,,
223.608,0.63546,0.98146,10,,,,,,,,,,,,,,,,,,,,,,,,,,,,,,,,,,,,,
224.308,0.63518,1.01213,10,,,,,,,,,,,,,,,,,,,,,,,,,,,,,,,,,,,,,
225.008,0.63484,0.99478,10,,,,,,,,,,,,,,,,,,,,,,,,,,,,,,,,,,,,,
225.708,0.63444,1.05538,10,,,,,,,,,,,,,,,,,,,,,,,,,,,,,,,,,,,,,
226.408,0.63387,0.94819,10,,,,,,,,,,,,,,,,,,,,,,,,,,,,,,,,,,,,,
227.108,0.63308,0.99865,10,,,,,,,,,,,,,,,,,,,,,,,,,,,,,,,,,,,,,
227.808,0.63234,1.02311,10,,,,,,,,,,,,,,,,,,,,,,,,,,,,,,,,,,,,,
228.508,0.63178,1.01922,10,,,,,,,,,,,,,,,,,,,,,,,,,,,,,,,,,,,,,
229.208,0.63115,0.96644,10,,,,,,,,,,,,,,,,,,,,,,,,,,,,,,,,,,,,,
229.908,0.63076,1.06176,10,,,,,,,,,,,,,,,,,,,,,,,,,,,,,,,,,,,,,
230.608,0.63053,0.99339,10,,,,,,,,,,,,,,,,,,,,,,,,,,,,,,,,,,,,,
231.308,0.63036,1.0208,10,,,,,,,,,,,,,,,,,,,,,,,,,,,,,,,,,,,,,
232.008,0.63025,1.01696,10,,,,,,,,,,,,,,,,,,,,,,,,,,,,,,,,,,,,,
232.708,0.63008,1.11128,10,,,,,,,,,,,,,,,,,,,,,,,,,,,,,,,,,,,,,
233.408,0.62985,1.0188,10,,,,,,,,,,,,,,,,,,,,,,,,,,,,,,,,,,,,,
234.108,0.62957,1.05601,10,,,,,,,,,,,,,,,,,,,,,,,,,,,,,,,,,,,,,
234.808,0.62934,1.02129,10,,,,,,,,,,,,,,,,,,,,,,,,,,,,,,,,,,,,,
235.508,0.62872,1.00388,10,,,,,,,,,,,,,,,,,,,,,,,,,,,,,,,,,,,,,
236.208,0.62798,1.0015,10,,,,,,,,,,,,,,,,,,,,,,,,,,,,,,,,,,,,,
236.908,0.62758,1.0096,10,,,,,,,,,,,,,,,,,,,,,,,,,,,,,,,,,,,,,
237.608,0.62724,0.98169,10,,,,,,,,,,,,,,,,,,,,,,,,,,,,,,,,,,,,,
238.308,0.62685,1.01741,10,,,,,,,,,,,,,,,,,,,,,,,,,,,,,,,,,,,,,
239.008,0.62662,1.05185,10,,,,,,,,,,,,,,,,,,,,,,,,,,,,,,,,,,,,,
239.708,0.62651,0.99189,10,,,,,,,,,,,,,,,,,,,,,,,,,,,,,,,,,,,,,
240.408,0.62639,1.02698,10,,,,,,,,,,,,,,,,,,,,,,,,,,,,,,,,,,,,,
241.108,0.62634,1.00192,10,,,,,,,,,,,,,,,,,,,,,,,,,,,,,,,,,,,,,
241.808,0.62628,0.97164,10,,,,,,,,,,,,,,,,,,,,,,,,,,,,,,,,,,,,,
242.508,0.62622,1.02784,10,,,,,,,,,,,,,,,,,,,,,,,,,,,,,,,,,,,,,
243.208,0.62622,0.99277,10,,,,,,,,,,,,,,,,,,,,,,,,,,,,,,,,,,,,,
243.908,0.62605,1.06007,10,,,,,,,,,,,,,,,,,,,,,,,,,,,,,,,,,,,,,
244.608,0.62588,1.02386,10,,,,,,,,,,,,,,,,,,,,,,,,,,,,,,,,,,,,,
245.308,0.62577,1.01711,10,,,,,,,,,,,,,,,,,,,,,,,,,,,,,,,,,,,,,
246.008,0.62549,1.05416,10,,,,,,,,,,,,,,,,,,,,,,,,,,,,,,,,,,,,,
246.708,0.62509,1.05346,10,,,,,,,,,,,,,,,,,,,,,,,,,,,,,,,,,,,,,
247.408,0.62447,1.01152,10,,,,,,,,,,,,,,,,,,,,,,,,,,,,,,,,,,,,,
248.108,0.62367,0.99694,10,,,,,,,,,,,,,,,,,,,,,,,,,,,,,,,,,,,,,
248.808,0.62322,1.01569,10,,,,,,,,,,,,,,,,,,,,,,,,,,,,,,,,,,,,,
249.508,0.62305,1.02086,10,,,,,,,,,,,,,,,,,,,,,,,,,,,,,,,,,,,,,
250.208,0.62288,0.9929,10,,,,,,,,,,,,,,,,,,,,,,,,,,,,,,,,,,,,,
250.908,0.62271,1.05432,10,,,,,,,,,,,,,,,,,,,,,,,,,,,,,,,,,,,,,
251.608,0.6226,1.00328,10,,,,,,,,,,,,,,,,,,,,,,,,,,,,,,,,,,,,,
252.308,0.62254,0.99845,10,,,,,,,,,,,,,,,,,,,,,,,,,,,,,,,,,,,,,
253.008,0.62248,0.93996,10,,,,,,,,,,,,,,,,,,,,,,,,,,,,,,,,,,,,,
253.708,0.62243,1.01697,10,,,,,,,,,,,,,,,,,,,,,,,,,,,,,,,,,,,,,
254.408,0.62237,0.95171,10,,,,,,,,,,,,,,,,,,,,,,,,,,,,,,,,,,,,,
255.108,0.62231,1.00713,10,,,,,,,,,,,,,,,,,,,,,,,,,,,,,,,,,,,,,
255.808,0.62226,1.02286,10,,,,,,,,,,,,,,,,,,,,,,,,,,,,,,,,,,,,,
256.508,0.6222,1.02392,10,,,,,,,,,,,,,,,,,,,,,,,,,,,,,,,,,,,,,
257.208,0.62209,1.02434,10,,,,,,,,,,,,,,,,,,,,,,,,,,,,,,,,,,,,,
257.908,0.62192,1.0323,10,,,,,,,,,,,,,,,,,,,,,,,,,,,,,,,,,,,,,
258.608,0.62169,0.99887,10,,,,,,,,,,,,,,,,,,,,,,,,,,,,,,,,,,,,,
259.308,0.62152,1.04396,10,,,,,,,,,,,,,,,,,,,,,,,,,,,,,,,,,,,,,
260.008,0.62129,0.98195,10,,,,,,,,,,,,,,,,,,,,,,,,,,,,,,,,,,,,,
260.708,0.62118,1.00488,10,,,,,,,,,,,,,,,,,,,,,,,,,,,,,,,,,,,,,
261.408,0.62095,1.0948,10,,,,,,,,,,,,,,,,,,,,,,,,,,,,,,,,,,,,,
262.108,0.62078,1.0205,10,,,,,,,,,,,,,,,,,,,,,,,,,,,,,,,,,,,,,
262.808,0.62056,0.98911,10,,,,,,,,,,,,,,,,,,,,,,,,,,,,,,,,,,,,,
263.508,0.62027,1.02067,10,,,,,,,,,,,,,,,,,,,,,,,,,,,,,,,,,,,,,
264.208,0.62005,0.95591,10,,,,,,,,,,,,,,,,,,,,,,,,,,,,,,,,,,,,,
264.908,0.61976,1.02721,10,,,,,,,,,,,,,,,,,,,,,,,,,,,,,,,,,,,,,
265.608,0.61954,0.99835,10,,,,,,,,,,,,,,,,,,,,,,,,,,,,,,,,,,,,,
266.308,0.61942,0.99803,10,,,,,,,,,,,,,,,,,,,,,,,,,,,,,,,,,,,,,
267.008,0.61931,1.03546,10,,,,,,,,,,,,,,,,,,,,,,,,,,,,,,,,,,,,,
267.708,0.61925,1.05345,10,,,,,,,,,,,,,,,,,,,,,,,,,,,,,,,,,,,,,
268.408,0.6192,1.02158,10,,,,,,,,,,,,,,,,,,,,,,,,,,,,,,,,,,,,,
269.108,0.61914,0.99456,10,,,,,,,,,,,,,,,,,,,,,,,,,,,,,,,,,,,,,
269.808,0.61914,1.04349,10,,,,,,,,,,,,,,,,,,,,,,,,,,,,,,,,,,,,,
270.508,0.61908,1.00744,10,,,,,,,,,,,,,,,,,,,,,,,,,,,,,,,,,,,,,
271.208,0.61903,0.97759,10,,,,,,,,,,,,,,,,,,,,,,,,,,,,,,,,,,,,,
271.908,0.61886,1.02196,10,,,,,,,,,,,,,,,,,,,,,,,,,,,,,,,,,,,,,
272.608,0.61874,0.95467,10,,,,,,,,,,,,,,,,,,,,,,,,,,,,,,,,,,,,,
273.308,0.61863,0.98018,10,,,,,,,,,,,,,,,,,,,,,,,,,,,,,,,,,,,,,
274.008,0.61846,0.99049,10,,,,,,,,,,,,,,,,,,,,,,,,,,,,,,,,,,,,,
274.708,0.6184,1.00138,10,,,,,,,,,,,,,,,,,,,,,,,,,,,,,,,,,,,,,
275.408,0.61835,1.00776,10,,,,,,,,,,,,,,,,,,,,,,,,,,,,,,,,,,,,,
276.108,0.61829,1.048,10,,,,,,,,,,,,,,,,,,,,,,,,,,,,,,,,,,,,,
276.808,0.61818,0.98911,10,,,,,,,,,,,,,,,,,,,,,,,,,,,,,,,,,,,,,
277.508,0.61806,0.99474,10,,,,,,,,,,,,,,,,,,,,,,,,,,,,,,,,,,,,,
278.208,0.61801,1.0039,10,,,,,,,,,,,,,,,,,,,,,,,,,,,,,,,,,,,,,
278.908,0.61789,1.00427,10,,,,,,,,,,,,,,,,,,,,,,,,,,,,,,,,,,,,,
279.608,0.61772,1.01314,10,,,,,,,,,,,,,,,,,,,,,,,,,,,,,,,,,,,,,
280.308,0.61761,1.03323,10,,,,,,,,,,,,,,,,,,,,,,,,,,,,,,,,,,,,,
281.008,0.6175,1.03662,10,,,,,,,,,,,,,,,,,,,,,,,,,,,,,,,,,,,,,
281.708,0.61733,1.00658,10,,,,,,,,,,,,,,,,,,,,,,,,,,,,,,,,,,,,,
282.408,0.61721,0.99569,10,,,,,,,,,,,,,,,,,,,,,,,,,,,,,,,,,,,,,
283.108,0.61704,0.98837,10,,,,,,,,,,,,,,,,,,,,,,,,,,,,,,,,,,,,,
283.808,0.61687,0.98738,10,,,,,,,,,,,,,,,,,,,,,,,,,,,,,,,,,,,,,
284.508,0.6167,1.03385,10,,,,,,,,,,,,,,,,,,,,,,,,,,,,,,,,,,,,,
285.208,0.61665,0.99853,10,,,,,,,,,,,,,,,,,,,,,,,,,,,,,,,,,,,,,
285.908,0.61648,0.97877,10,,,,,,,,,,,,,,,,,,,,,,,,,,,,,,,,,,,,,
286.608,0.61636,0.97664,10,,,,,,,,,,,,,,,,,,,,,,,,,,,,,,,,,,,,,
287.308,0.61631,0.99919,10,,,,,,,,,,,,,,,,,,,,,,,,,,,,,,,,,,,,,
288.008,0.61625,1.02741,10,,,,,,,,,,,,,,,,,,,,,,,,,,,,,,,,,,,,,
288.708,0.61614,1.03936,10,,,,,,,,,,,,,,,,,,,,,,,,,,,,,,,,,,,,,
289.408,0.61608,0.95809,10,,,,,,,,,,,,,,,,,,,,,,,,,,,,,,,,,,,,,
290.108,0.61597,0.99446,10,,,,,,,,,,,,,,,,,,,,,,,,,,,,,,,,,,,,,
290.808,0.61597,1.00684,10,,,,,,,,,,,,,,,,,,,,,,,,,,,,,,,,,,,,,
291.508,0.61591,1.03139,10,,,,,,,,,,,,,,,,,,,,,,,,,,,,,,,,,,,,,
292.208,0.61591,1.01808,10,,,,,,,,,,,,,,,,,,,,,,,,,,,,,,,,,,,,,
292.908,0.6158,1.08832,10,,,,,,,,,,,,,,,,,,,,,,,,,,,,,,,,,,,,,
293.608,0.61574,0.98076,10,,,,,,,,,,,,,,,,,,,,,,,,,,,,,,,,,,,,,
294.308,0.61568,1.06138,10,,,,,,,,,,,,,,,,,,,,,,,,,,,,,,,,,,,,,
295.008,0.61557,1.02431,10,,,,,,,,,,,,,,,,,,,,,,,,,,,,,,,,,,,,,
295.708,0.61546,1.00494,10,,,,,,,,,,,,,,,,,,,,,,,,,,,,,,,,,,,,,
296.408,0.61529,0.9766,10,,,,,,,,,,,,,,,,,,,,,,,,,,,,,,,,,,,,,
297.108,0.61512,1.05939,10,,,,,,,,,,,,,,,,,,,,,,,,,,,,,,,,,,,,,
297.808,0.61489,0.97608,10,,,,,,,,,,,,,,,,,,,,,,,,,,,,,,,,,,,,,
298.508,0.61461,1.04863,10,,,,,,,,,,,,,,,,,,,,,,,,,,,,,,,,,,,,,
299.208,0.61427,1.03967,10,,,,,,,,,,,,,,,,,,,,,,,,,,,,,,,,,,,,,
299.908,0.6141,1.00422,10,,,,,,,,,,,,,,,,,,,,,,,,,,,,,,,,,,,,,
300.608,0.61398,1.00599,10,,,,,,,,,,,,,,,,,,,,,,,,,,,,,,,,,,,,,
301.308,0.61387,1.0283,10,,,,,,,,,,,,,,,,,,,,,,,,,,,,,,,,,,,,,
302.008,0.61381,1.00498,10,,,,,,,,,,,,,,,,,,,,,,,,,,,,,,,,,,,,,
302.708,0.61376,1.03504,10,,,,,,,,,,,,,,,,,,,,,,,,,,,,,,,,,,,,,
303.408,0.6137,1.03905,10,,,,,,,,,,,,,,,,,,,,,,,,,,,,,,,,,,,,,
304.108,0.61359,1.07245,10,,,,,,,,,,,,,,,,,,,,,,,,,,,,,,,,,,,,,
304.808,0.61353,1.00663,10,,,,,,,,,,,,,,,,,,,,,,,,,,,,,,,,,,,,,
305.508,0.61342,1.0916,10,,,,,,,,,,,,,,,,,,,,,,,,,,,,,,,,,,,,,
306.208,0.61342,0.97753,10,,,,,,,,,,,,,,,,,,,,,,,,,,,,,,,,,,,,,
306.908,0.61336,0.98682,10,,,,,,,,,,,,,,,,,,,,,,,,,,,,,,,,,,,,,
307.608,0.6133,1.02877,10,,,,,,,,,,,,,,,,,,,,,,,,,,,,,,,,,,,,,
308.308,0.61319,1.02063,10,,,,,,,,,,,,,,,,,,,,,,,,,,,,,,,,,,,,,
309.008,0.61313,1.00987,10,,,,,,,,,,,,,,,,,,,,,,,,,,,,,,,,,,,,,
309.708,0.61308,1.01247,10,,,,,,,,,,,,,,,,,,,,,,,,,,,,,,,,,,,,,
310.408,0.61302,0.96885,10,,,,,,,,,,,,,,,,,,,,,,,,,,,,,,,,,,,,,
311.108,0.61296,1.00262,10,,,,,,,,,,,,,,,,,,,,,,,,,,,,,,,,,,,,,
311.808,0.61296,1.0198,10,,,,,,,,,,,,,,,,,,,,,,,,,,,,,,,,,,,,,
312.508,0.61291,1.1118,10,,,,,,,,,,,,,,,,,,,,,,,,,,,,,,,,,,,,,
313.208,0.61291,1.00847,10,,,,,,,,,,,,,,,,,,,,,,,,,,,,,,,,,,,,,
313.908,0.61279,1.04706,10,,,,,,,,,,,,,,,,,,,,,,,,,,,,,,,,,,,,,
314.608,0.61274,0.93496,10,,,,,,,,,,,,,,,,,,,,,,,,,,,,,,,,,,,,,
315.308,0.61268,1.0758,10,,,,,,,,,,,,,,,,,,,,,,,,,,,,,,,,,,,,,
316.008,0.61257,0.96582,10,,,,,,,,,,,,,,,,,,,,,,,,,,,,,,,,,,,,,
316.708,0.61245,0.97534,10,,,,,,,,,,,,,,,,,,,,,,,,,,,,,,,,,,,,,
317.408,0.61245,1.0151,10,,,,,,,,,,,,,,,,,,,,,,,,,,,,,,,,,,,,,
318.108,0.6124,1.05867,10,,,,,,,,,,,,,,,,,,,,,,,,,,,,,,,,,,,,,
318.808,0.61228,0.97328,10,,,,,,,,,,,,,,,,,,,,,,,,,,,,,,,,,,,,,
319.508,0.61223,1.02187,10,,,,,,,,,,,,,,,,,,,,,,,,,,,,,,,,,,,,,
320.208,0.61217,1.02277,10,,,,,,,,,,,,,,,,,,,,,,,,,,,,,,,,,,,,,
320.908,0.61206,1.05742,10,,,,,,,,,,,,,,,,,,,,,,,,,,,,,,,,,,,,,
321.608,0.61194,0.98197,10,,,,,,,,,,,,,,,,,,,,,,,,,,,,,,,,,,,,,
322.308,0.61189,1.02939,10,,,,,,,,,,,,,,,,,,,,,,,,,,,,,,,,,,,,,
323.008,0.61177,0.95737,10,,,,,,,,,,,,,,,,,,,,,,,,,,,,,,,,,,,,,
323.708,0.61166,0.99766,10,,,,,,,,,,,,,,,,,,,,,,,,,,,,,,,,,,,,,
324.408,0.61155,0.99504,10,,,,,,,,,,,,,,,,,,,,,,,,,,,,,,,,,,,,,
325.108,0.61143,0.97522,10,,,,,,,,,,,,,,,,,,,,,,,,,,,,,,,,,,,,,
325.808,0.61138,0.99659,10,,,,,,,,,,,,,,,,,,,,,,,,,,,,,,,,,,,,,
326.508,0.61132,1.02305,10,,,,,,,,,,,,,,,,,,,,,,,,,,,,,,,,,,,,,
327.208,0.61126,0.97055,10,,,,,,,,,,,,,,,,,,,,,,,,,,,,,,,,,,,,,
327.908,0.61121,1.00572,10,,,,,,,,,,,,,,,,,,,,,,,,,,,,,,,,,,,,,
328.608,0.61115,1.02013,10,,,,,,,,,,,,,,,,,,,,,,,,,,,,,,,,,,,,,
329.308,0.61115,1.05168,10,,,,,,,,,,,,,,,,,,,,,,,,,,,,,,,,,,,,,
330.008,0.61115,0.98701,10,,,,,,,,,,,,,,,,,,,,,,,,,,,,,,,,,,,,,
330.708,0.61104,1.02489,10,,,,,,,,,,,,,,,,,,,,,,,,,,,,,,,,,,,,,
331.408,0.61104,0.99461,10,,,,,,,,,,,,,,,,,,,,,,,,,,,,,,,,,,,,,
332.108,0.61098,0.9988,10,,,,,,,,,,,,,,,,,,,,,,,,,,,,,,,,,,,,,
332.808,0.61092,1.01847,10,,,,,,,,,,,,,,,,,,,,,,,,,,,,,,,,,,,,,
333.508,0.61087,1.01627,10,,,,,,,,,,,,,,,,,,,,,,,,,,,,,,,,,,,,,
334.208,0.61081,1.02112,10,,,,,,,,,,,,,,,,,,,,,,,,,,,,,,,,,,,,,
334.908,0.6107,1.03858,10,,,,,,,,,,,,,,,,,,,,,,,,,,,,,,,,,,,,,
335.608,0.61064,0.9878,10,,,,,,,,,,,,,,,,,,,,,,,,,,,,,,,,,,,,,
336.308,0.61058,1.03721,10,,,,,,,,,,,,,,,,,,,,,,,,,,,,,,,,,,,,,
337.008,0.61053,1.02788,10,,,,,,,,,,,,,,,,,,,,,,,,,,,,,,,,,,,,,
337.708,0.61047,1.00861,10,,,,,,,,,,,,,,,,,,,,,,,,,,,,,,,,,,,,,
338.408,0.61036,1.03314,10,,,,,,,,,,,,,,,,,,,,,,,,,,,,,,,,,,,,,
339.108,0.61019,1.04167,10,,,,,,,,,,,,,,,,,,,,,,,,,,,,,,,,,,,,,
339.808,0.60979,0.93788,10,,,,,,,,,,,,,,,,,,,,,,,,,,,,,,,,,,,,,
340.508,0.60922,1.00175,10,,,,,,,,,,,,,,,,,,,,,,,,,,,,,,,,,,,,,
341.208,0.60877,0.99231,10,,,,,,,,,,,,,,,,,,,,,,,,,,,,,,,,,,,,,
341.908,0.60849,0.97911,10,,,,,,,,,,,,,,,,,,,,,,,,,,,,,,,,,,,,,
342.608,0.60832,0.99252,10,,,,,,,,,,,,,,,,,,,,,,,,,,,,,,,,,,,,,
343.308,0.60826,0.98435,10,,,,,,,,,,,,,,,,,,,,,,,,,,,,,,,,,,,,,
344.008,0.6082,1.01459,10,,,,,,,,,,,,,,,,,,,,,,,,,,,,,,,,,,,,,
344.708,0.60832,0.99065,10,,,,,,,,,,,,,,,,,,,,,,,,,,,,,,,,,,,,,
345.408,0.60837,0.98876,10,,,,,,,,,,,,,,,,,,,,,,,,,,,,,,,,,,,,,
346.108,0.60837,0.96713,10,,,,,,,,,,,,,,,,,,,,,,,,,,,,,,,,,,,,,
346.808,0.60843,0.96048,10,,,,,,,,,,,,,,,,,,,,,,,,,,,,,,,,,,,,,
347.508,0.60849,1.00469,10,,,,,,,,,,,,,,,,,,,,,,,,,,,,,,,,,,,,,
348.208,0.60849,0.97286,10,,,,,,,,,,,,,,,,,,,,,,,,,,,,,,,,,,,,,
348.908,0.60854,0.94687,10,,,,,,,,,,,,,,,,,,,,,,,,,,,,,,,,,,,,,
349.608,0.6086,1.04097,10,,,,,,,,,,,,,,,,,,,,,,,,,,,,,,,,,,,,,
350.308,0.60866,1.00002,10,,,,,,,,,,,,,,,,,,,,,,,,,,,,,,,,,,,,,
351.008,0.60871,1.05747,10,,,,,,,,,,,,,,,,,,,,,,,,,,,,,,,,,,,,,
351.708,0.60877,0.98899,10,,,,,,,,,,,,,,,,,,,,,,,,,,,,,,,,,,,,,
352.408,0.60883,1.01513,10,,,,,,,,,,,,,,,,,,,,,,,,,,,,,,,,,,,,,
353.108,0.60883,0.97872,10,,,,,,,,,,,,,,,,,,,,,,,,,,,,,,,,,,,,,
353.808,0.60888,1.00831,10,,,,,,,,,,,,,,,,,,,,,,,,,,,,,,,,,,,,,
354.508,0.60888,1.01881,10,,,,,,,,,,,,,,,,,,,,,,,,,,,,,,,,,,,,,
355.208,0.60894,0.97841,10,,,,,,,,,,,,,,,,,,,,,,,,,,,,,,,,,,,,,
355.908,0.60894,1.03133,10,,,,,,,,,,,,,,,,,,,,,,,,,,,,,,,,,,,,,
356.608,0.60888,1.07091,10,,,,,,,,,,,,,,,,,,,,,,,,,,,,,,,,,,,,,
357.308,0.609,1.00599,10,,,,,,,,,,,,,,,,,,,,,,,,,,,,,,,,,,,,,
358.008,0.609,1.02031,10,,,,,,,,,,,,,,,,,,,,,,,,,,,,,,,,,,,,,
358.708,0.609,1.04697,10,,,,,,,,,,,,,,,,,,,,,,,,,,,,,,,,,,,,,
359.408,0.609,0.99361,10,,,,,,,,,,,,,,,,,,,,,,,,,,,,,,,,,,,,,
360.108,0.609,1.02572,10,,,,,,,,,,,,,,,,,,,,,,,,,,,,,,,,,,,,,
360.808,0.609,1.01811,10,,,,,,,,,,,,,,,,,,,,,,,,,,,,,,,,,,,,,
361.508,0.609,0.98806,10,,,,,,,,,,,,,,,,,,,,,,,,,,,,,,,,,,,,,
362.208,0.609,1.00103,10,,,,,,,,,,,,,,,,,,,,,,,,,,,,,,,,,,,,,
362.908,0.609,1.05675,10,,,,,,,,,,,,,,,,,,,,,,,,,,,,,,,,,,,,,
363.608,0.609,1.08265,10,,,,,,,,,,,,,,,,,,,,,,,,,,,,,,,,,,,,,
364.308,0.60888,1.04773,10,,,,,,,,,,,,,,,,,,,,,,,,,,,,,,,,,,,,,
365.008,0.60888,0.99608,10,,,,,,,,,,,,,,,,,,,,,,,,,,,,,,,,,,,,,
365.708,0.60883,1.02914,10,,,,,,,,,,,,,,,,,,,,,,,,,,,,,,,,,,,,,
366.408,0.60888,1.0175,10,,,,,,,,,,,,,,,,,,,,,,,,,,,,,,,,,,,,,
367.108,0.60883,1.09584,10,,,,,,,,,,,,,,,,,,,,,,,,,,,,,,,,,,,,,
367.808,0.60883,1.00496,10,,,,,,,,,,,,,,,,,,,,,,,,,,,,,,,,,,,,,
368.508,0.60871,1.05258,10,,,,,,,,,,,,,,,,,,,,,,,,,,,,,,,,,,,,,
369.208,0.60877,1.01394,10,,,,,,,,,,,,,,,,,,,,,,,,,,,,,,,,,,,,,
369.908,0.6086,1.02123,10,,,,,,,,,,,,,,,,,,,,,,,,,,,,,,,,,,,,,
370.608,0.60854,1.05562,10,,,,,,,,,,,,,,,,,,,,,,,,,,,,,,,,,,,,,
371.308,0.60854,0.99904,10,,,,,,,,,,,,,,,,,,,,,,,,,,,,,,,,,,,,,
372.008,0.60854,0.98244,10,,,,,,,,,,,,,,,,,,,,,,,,,,,,,,,,,,,,,
372.708,0.6086,1.06655,10,,,,,,,,,,,,,,,,,,,,,,,,,,,,,,,,,,,,,
373.408,0.60849,0.98591,10,,,,,,,,,,,,,,,,,,,,,,,,,,,,,,,,,,,,,
374.108,0.60843,1.02322,10,,,,,,,,,,,,,,,,,,,,,,,,,,,,,,,,,,,,,
374.808,0.60849,1.03423,10,,,,,,,,,,,,,,,,,,,,,,,,,,,,,,,,,,,,,
375.508,0.60837,1.0376,10,,,,,,,,,,,,,,,,,,,,,,,,,,,,,,,,,,,,,
376.208,0.60832,0.97176,10,,,,,,,,,,,,,,,,,,,,,,,,,,,,,,,,,,,,,
376.908,0.60826,1.0402,10,,,,,,,,,,,,,,,,,,,,,,,,,,,,,,,,,,,,,
377.608,0.6082,0.99355,10,,,,,,,,,,,,,,,,,,,,,,,,,,,,,,,,,,,,,
378.308,0.60803,0.99654,10,,,,,,,,,,,,,,,,,,,,,,,,,,,,,,,,,,,,,
379.008,0.60786,1.04904,10,,,,,,,,,,,,,,,,,,,,,,,,,,,,,,,,,,,,,
379.708,0.60758,1.05077,10,,,,,,,,,,,,,,,,,,,,,,,,,,,,,,,,,,,,,
380.408,0.60724,1.0313,10,,,,,,,,,,,,,,,,,,,,,,,,,,,,,,,,,,,,,
381.108,0.6069,1.03671,10,,,,,,,,,,,,,,,,,,,,,,,,,,,,,,,,,,,,,
381.808,0.60645,0.98912,10,,,,,,,,,,,,,,,,,,,,,,,,,,,,,,,,,,,,,
382.508,0.60577,1.00548,10,,,,,,,,,,,,,,,,,,,,,,,,,,,,,,,,,,,,,
383.208,0.60526,1.02053,10,,,,,,,,,,,,,,,,,,,,,,,,,,,,,,,,,,,,,
383.908,0.6048,1.00522,10,,,,,,,,,,,,,,,,,,,,,,,,,,,,,,,,,,,,,
384.608,0.60446,0.98168,10,,,,,,,,,,,,,,,,,,,,,,,,,,,,,,,,,,,,,
385.308,0.60418,1.00183,10,,,,,,,,,,,,,,,,,,,,,,,,,,,,,,,,,,,,,
386.008,0.60407,0.95986,10,,,,,,,,,,,,,,,,,,,,,,,,,,,,,,,,,,,,,
386.708,0.60401,0.98311,10,,,,,,,,,,,,,,,,,,,,,,,,,,,,,,,,,,,,,
387.408,0.60401,0.97538,10,,,,,,,,,,,,,,,,,,,,,,,,,,,,,,,,,,,,,
388.108,0.60401,0.98187,10,,,,,,,,,,,,,,,,,,,,,,,,,,,,,,,,,,,,,
388.808,0.60401,0.96853,10,,,,,,,,,,,,,,,,,,,,,,,,,,,,,,,,,,,,,
389.508,0.60412,1.02283,10,,,,,,,,,,,,,,,,,,,,,,,,,,,,,,,,,,,,,
390.208,0.60412,0.96155,10,,,,,,,,,,,,,,,,,,,,,,,,,,,,,,,,,,,,,
390.908,0.60418,0.96087,10,,,,,,,,,,,,,,,,,,,,,,,,,,,,,,,,,,,,,
391.608,0.60418,1.0173,10,,,,,,,,,,,,,,,,,,,,,,,,,,,,,,,,,,,,,
392.308,0.60429,0.96739,10,,,,,,,,,,,,,,,,,,,,,,,,,,,,,,,,,,,,,
393.008,0.60441,0.9538,10,,,,,,,,,,,,,,,,,,,,,,,,,,,,,,,,,,,,,
393.708,0.60446,1.01867,10,,,,,,,,,,,,,,,,,,,,,,,,,,,,,,,,,,,,,
394.408,0.60452,1.00086,10,,,,,,,,,,,,,,,,,,,,,,,,,,,,,,,,,,,,,
395.108,0.60458,1.03461,10,,,,,,,,,,,,,,,,,,,,,,,,,,,,,,,,,,,,,
395.808,0.60463,1.02074,10,,,,,,,,,,,,,,,,,,,,,,,,,,,,,,,,,,,,,
396.508,0.60463,1.02423,10,,,,,,,,,,,,,,,,,,,,,,,,,,,,,,,,,,,,,
397.208,0.60469,0.97725,10,,,,,,,,,,,,,,,,,,,,,,,,,,,,,,,,,,,,,
397.908,0.60469,1.05192,10,,,,,,,,,,,,,,,,,,,,,,,,,,,,,,,,,,,,,
398.608,0.60475,0.99422,10,,,,,,,,,,,,,,,,,,,,,,,,,,,,,,,,,,,,,
399.308,0.60475,0.98402,10,,,,,,,,,,,,,,,,,,,,,,,,,,,,,,,,,,,,,
400.008,0.60475,1.0125,10,,,,,,,,,,,,,,,,,,,,,,,,,,,,,,,,,,,,,
400.708,0.60475,1.06144,10,,,,,,,,,,,,,,,,,,,,,,,,,,,,,,,,,,,,,
401.408,0.60475,0.99308,10,,,,,,,,,,,,,,,,,,,,,,,,,,,,,,,,,,,,,
402.108,0.60475,1.0429,10,,,,,,,,,,,,,,,,,,,,,,,,,,,,,,,,,,,,,
402.808,0.60475,1.02376,10,,,,,,,,,,,,,,,,,,,,,,,,,,,,,,,,,,,,,
403.508,0.60475,0.99186,10,,,,,,,,,,,,,,,,,,,,,,,,,,,,,,,,,,,,,
404.208,0.6048,1.00972,10,,,,,,,,,,,,,,,,,,,,,,,,,,,,,,,,,,,,,
404.908,0.6048,1.08136,10,,,,,,,,,,,,,,,,,,,,,,,,,,,,,,,,,,,,,
405.608,0.6048,1.0003,10,,,,,,,,,,,,,,,,,,,,,,,,,,,,,,,,,,,,,
406.308,0.60475,1.00425,10,,,,,,,,,,,,,,,,,,,,,,,,,,,,,,,,,,,,,
407.008,0.60486,1.00278,10,,,,,,,,,,,,,,,,,,,,,,,,,,,,,,,,,,,,,
407.708,0.60486,1.08839,10,,,,,,,,,,,,,,,,,,,,,,,,,,,,,,,,,,,,,
408.408,0.60486,1.06306,10,,,,,,,,,,,,,,,,,,,,,,,,,,,,,,,,,,,,,
409.108,0.60486,1.0079,10,,,,,,,,,,,,,,,,,,,,,,,,,,,,,,,,,,,,,
409.808,0.60486,0.99445,10,,,,,,,,,,,,,,,,,,,,,,,,,,,,,,,,,,,,,
410.508,0.60486,0.99061,10,,,,,,,,,,,,,,,,,,,,,,,,,,,,,,,,,,,,,
411.208,0.60486,0.98902,10,,,,,,,,,,,,,,,,,,,,,,,,,,,,,,,,,,,,,
411.908,0.60486,0.99019,10,,,,,,,,,,,,,,,,,,,,,,,,,,,,,,,,,,,,,
412.608,0.60486,1.04274,10,,,,,,,,,,,,,,,,,,,,,,,,,,,,,,,,,,,,,
413.308,0.60486,1.02659,10,,,,,,,,,,,,,,,,,,,,,,,,,,,,,,,,,,,,,
414.008,0.60486,0.9781,10,,,,,,,,,,,,,,,,,,,,,,,,,,,,,,,,,,,,,
414.708,0.60486,1.09787,10,,,,,,,,,,,,,,,,,,,,,,,,,,,,,,,,,,,,,
415.408,0.60486,0.97649,10,,,,,,,,,,,,,,,,,,,,,,,,,,,,,,,,,,,,,
416.108,0.60486,0.98751,10,,,,,,,,,,,,,,,,,,,,,,,,,,,,,,,,,,,,,
416.808,0.60486,1.01056,10,,,,,,,,,,,,,,,,,,,,,,,,,,,,,,,,,,,,,
417.508,0.60486,1.0301,10,,,,,,,,,,,,,,,,,,,,,,,,,,,,,,,,,,,,,
418.208,0.60486,1.02805,10,,,,,,,,,,,,,,,,,,,,,,,,,,,,,,,,,,,,,
418.908,0.60486,1.01244,10,,,,,,,,,,,,,,,,,,,,,,,,,,,,,,,,,,,,,
419.608,0.60486,0.97657,10,,,,,,,,,,,,,,,,,,,,,,,,,,,,,,,,,,,,,
420.308,0.60486,0.9698,10,,,,,,,,,,,,,,,,,,,,,,,,,,,,,,,,,,,,,
421.008,0.60486,1.01046,10,,,,,,,,,,,,,,,,,,,,,,,,,,,,,,,,,,,,,
421.708,0.60486,1.02467,10,,,,,,,,,,,,,,,,,,,,,,,,,,,,,,,,,,,,,
422.408,0.60486,0.99718,10,,,,,,,,,,,,,,,,,,,,,,,,,,,,,,,,,,,,,
423.108,0.60486,1.02173,10,,,,,,,,,,,,,,,,,,,,,,,,,,,,,,,,,,,,,
423.808,0.60486,0.95524,10,,,,,,,,,,,,,,,,,,,,,,,,,,,,,,,,,,,,,
424.508,0.60486,0.9841,10,,,,,,,,,,,,,,,,,,,,,,,,,,,,,,,,,,,,,
425.208,0.60486,0.99188,10,,,,,,,,,,,,,,,,,,,,,,,,,,,,,,,,,,,,,
425.908,0.60486,0.99956,10,,,,,,,,,,,,,,,,,,,,,,,,,,,,,,,,,,,,,
426.608,0.60486,0.97763,10,,,,,,,,,,,,,,,,,,,,,,,,,,,,,,,,,,,,,
427.308,0.60486,1.03874,10,,,,,,,,,,,,,,,,,,,,,,,,,,,,,,,,,,,,,
428.008,0.60486,1.00168,10,,,,,,,,,,,,,,,,,,,,,,,,,,,,,,,,,,,,,
428.708,0.60486,1.00666,10,,,,,,,,,,,,,,,,,,,,,,,,,,,,,,,,,,,,,
429.408,0.60486,1.0101,10,,,,,,,,,,,,,,,,,,,,,,,,,,,,,,,,,,,,,
430.108,0.60486,1.02948,10,,,,,,,,,,,,,,,,,,,,,,,,,,,,,,,,,,,,,
430.808,0.60486,0.98728,10,,,,,,,,,,,,,,,,,,,,,,,,,,,,,,,,,,,,,
431.508,0.60486,1.03505,10,,,,,,,,,,,,,,,,,,,,,,,,,,,,,,,,,,,,,
432.208,0.60486,1.00088,10,,,,,,,,,,,,,,,,,,,,,,,,,,,,,,,,,,,,,
432.908,0.60486,0.99294,10,,,,,,,,,,,,,,,,,,,,,,,,,,,,,,,,,,,,,
433.608,0.60486,1.0428,10,,,,,,,,,,,,,,,,,,,,,,,,,,,,,,,,,,,,,
434.308,0.60486,1.01745,10,,,,,,,,,,,,,,,,,,,,,,,,,,,,,,,,,,,,,
435.008,0.60486,1.00311,10,,,,,,,,,,,,,,,,,,,,,,,,,,,,,,,,,,,,,
435.708,0.60475,1.05398,10,,,,,,,,,,,,,,,,,,,,,,,,,,,,,,,,,,,,,
436.408,0.60475,0.9648,10,,,,,,,,,,,,,,,,,,,,,,,,,,,,,,,,,,,,,
437.108,0.60475,1.01552,10,,,,,,,,,,,,,,,,,,,,,,,,,,,,,,,,,,,,,
437.808,0.60486,1.00555,10,,,,,,,,,,,,,,,,,,,,,,,,,,,,,,,,,,,,,
438.508,0.60486,1.01786,10,,,,,,,,,,,,,,,,,,,,,,,,,,,,,,,,,,,,,
439.208,0.60486,1.0287,10,,,,,,,,,,,,,,,,,,,,,,,,,,,,,,,,,,,,,
439.908,0.60486,1.04432,10,,,,,,,,,,,,,,,,,,,,,,,,,,,,,,,,,,,,,
440.608,0.60486,0.98267,10,,,,,,,,,,,,,,,,,,,,,,,,,,,,,,,,,,,,,
441.308,0.60486,1.0206,10,,,,,,,,,,,,,,,,,,,,,,,,,,,,,,,,,,,,,
442.008,0.60486,0.99819,10,,,,,,,,,,,,,,,,,,,,,,,,,,,,,,,,,,,,,
442.708,0.60486,1.00506,10,,,,,,,,,,,,,,,,,,,,,,,,,,,,,,,,,,,,,
443.408,0.60486,1.05442,10,,,,,,,,,,,,,,,,,,,,,,,,,,,,,,,,,,,,,
444.108,0.60486,1.0047,10,,,,,,,,,,,,,,,,,,,,,,,,,,,,,,,,,,,,,
444.808,0.60486,1.01758,10,,,,,,,,,,,,,,,,,,,,,,,,,,,,,,,,,,,,,
445.508,0.60486,0.99204,10,,,,,,,,,,,,,,,,,,,,,,,,,,,,,,,,,,,,,
446.208,0.60486,1.00067,10,,,,,,,,,,,,,,,,,,,,,,,,,,,,,,,,,,,,,
446.908,0.60486,1.07379,10,,,,,,,,,,,,,,,,,,,,,,,,,,,,,,,,,,,,,
447.608,0.60486,0.96289,10,,,,,,,,,,,,,,,,,,,,,,,,,,,,,,,,,,,,,
448.308,0.60486,1.03072,10,,,,,,,,,,,,,,,,,,,,,,,,,,,,,,,,,,,,,
449.008,0.60486,1.01083,10,,,,,,,,,,,,,,,,,,,,,,,,,,,,,,,,,,,,,
449.708,0.60486,0.98137,10,,,,,,,,,,,,,,,,,,,,,,,,,,,,,,,,,,,,,
450.408,0.60486,1.02382,10,,,,,,,,,,,,,,,,,,,,,,,,,,,,,,,,,,,,,
451.108,0.60486,1.01802,10,,,,,,,,,,,,,,,,,,,,,,,,,,,,,,,,,,,,,
451.808,0.60486,1.04055,10,,,,,,,,,,,,,,,,,,,,,,,,,,,,,,,,,,,,,
452.508,0.60486,1.0289,10,,,,,,,,,,,,,,,,,,,,,,,,,,,,,,,,,,,,,
453.208,0.60486,0.99619,10,,,,,,,,,,,,,,,,,,,,,,,,,,,,,,,,,,,,,
453.908,0.60486,1.02818,10,,,,,,,,,,,,,,,,,,,,,,,,,,,,,,,,,,,,,
454.608,0.60486,0.99197,10,,,,,,,,,,,,,,,,,,,,,,,,,,,,,,,,,,,,,
455.308,0.60486,1.03493,10,,,,,,,,,,,,,,,,,,,,,,,,,,,,,,,,,,,,,
456.008,0.60486,0.99106,10,,,,,,,,,,,,,,,,,,,,,,,,,,,,,,,,,,,,,
456.708,0.60486,1.00012,10,,,,,,,,,,,,,,,,,,,,,,,,,,,,,,,,,,,,,
457.408,0.60486,1.03931,10,,,,,,,,,,,,,,,,,,,,,,,,,,,,,,,,,,,,,
458.108,0.60486,1.06376,10,,,,,,,,,,,,,,,,,,,,,,,,,,,,,,,,,,,,,
458.808,0.60486,1.05959,10,,,,,,,,,,,,,,,,,,,,,,,,,,,,,,,,,,,,,
459.508,0.60486,1.04474,10,,,,,,,,,,,,,,,,,,,,,,,,,,,,,,,,,,,,,
460.208,0.60486,0.96618,10,,,,,,,,,,,,,,,,,,,,,,,,,,,,,,,,,,,,,
460.908,0.60486,1.00542,10,,,,,,,,,,,,,,,,,,,,,,,,,,,,,,,,,,,,,
461.608,0.60486,0.99731,10,,,,,,,,,,,,,,,,,,,,,,,,,,,,,,,,,,,,,
462.308,0.60486,1.00041,10,,,,,,,,,,,,,,,,,,,,,,,,,,,,,,,,,,,,,
463.008,0.60486,1.03641,10,,,,,,,,,,,,,,,,,,,,,,,,,,,,,,,,,,,,,
463.708,0.60475,1.04345,10,,,,,,,,,,,,,,,,,,,,,,,,,,,,,,,,,,,,,
464.408,0.6048,1.01176,10,,,,,,,,,,,,,,,,,,,,,,,,,,,,,,,,,,,,,
465.108,0.6048,1.02214,10,,,,,,,,,,,,,,,,,,,,,,,,,,,,,,,,,,,,,
465.808,0.60469,1.11615,10,,,,,,,,,,,,,,,,,,,,,,,,,,,,,,,,,,,,,
466.508,0.60475,1.04794,10,,,,,,,,,,,,,,,,,,,,,,,,,,,,,,,,,,,,,
467.208,0.60463,1.04072,10,,,,,,,,,,,,,,,,,,,,,,,,,,,,,,,,,,,,,
467.908,0.60463,1.04898,10,,,,,,,,,,,,,,,,,,,,,,,,,,,,,,,,,,,,,
468.608,0.60458,1.00826,10,,,,,,,,,,,,,,,,,,,,,,,,,,,,,,,,,,,,,
469.308,0.60452,1.03725,10,,,,,,,,,,,,,,,,,,,,,,,,,,,,,,,,,,,,,
470.008,0.60446,0.97579,10,,,,,,,,,,,,,,,,,,,,,,,,,,,,,,,,,,,,,
470.708,0.60441,1.04949,10,,,,,,,,,,,,,,,,,,,,,,,,,,,,,,,,,,,,,
471.408,0.60441,1.02048,10,,,,,,,,,,,,,,,,,,,,,,,,,,,,,,,,,,,,,
472.108,0.60435,0.98808,10,,,,,,,,,,,,,,,,,,,,,,,,,,,,,,,,,,,,,
472.808,0.60441,1.01165,10,,,,,,,,,,,,,,,,,,,,,,,,,,,,,,,,,,,,,
473.508,0.60429,1.03828,10,,,,,,,,,,,,,,,,,,,,,,,,,,,,,,,,,,,,,
474.208,0.60424,1.02771,10,,,,,,,,,,,,,,,,,,,,,,,,,,,,,,,,,,,,,
474.908,0.60418,1.0331,10,,,,,,,,,,,,,,,,,,,,,,,,,,,,,,,,,,,,,
475.608,0.60418,1.03954,10,,,,,,,,,,,,,,,,,,,,,,,,,,,,,,,,,,,,,
476.308,0.60401,1.01561,10,,,,,,,,,,,,,,,,,,,,,,,,,,,,,,,,,,,,,
477.008,0.60384,1.02146,10,,,,,,,,,,,,,,,,,,,,,,,,,,,,,,,,,,,,,
477.708,0.60356,1.05353,10,,,,,,,,,,,,,,,,,,,,,,,,,,,,,,,,,,,,,
478.408,0.60327,0.98788,10,,,,,,,,,,,,,,,,,,,,,,,,,,,,,,,,,,,,,
479.108,0.60299,1.02499,10,,,,,,,,,,,,,,,,,,,,,,,,,,,,,,,,,,,,,
479.808,0.60276,1.02313,10,,,,,,,,,,,,,,,,,,,,,,,,,,,,,,,,,,,,,
480.508,0.60242,1.01362,10,,,,,,,,,,,,,,,,,,,,,,,,,,,,,,,,,,,,,
481.208,0.60208,1.01115,10,,,,,,,,,,,,,,,,,,,,,,,,,,,,,,,,,,,,,
481.908,0.60157,0.97689,10,,,,,,,,,,,,,,,,,,,,,,,,,,,,,,,,,,,,,
482.608,0.60123,0.93489,10,,,,,,,,,,,,,,,,,,,,,,,,,,,,,,,,,,,,,
483.308,0.60118,0.94937,10,,,,,,,,,,,,,,,,,,,,,,,,,,,,,,,,,,,,,
484.008,0.60118,0.99999,10,,,,,,,,,,,,,,,,,,,,,,,,,,,,,,,,,,,,,
484.708,0.60118,1.04984,10,,,,,,,,,,,,,,,,,,,,,,,,,,,,,,,,,,,,,
485.408,0.60123,1.0015,10,,,,,,,,,,,,,,,,,,,,,,,,,,,,,,,,,,,,,
486.108,0.60135,0.98794,10,,,,,,,,,,,,,,,,,,,,,,,,,,,,,,,,,,,,,
486.808,0.6014,0.97257,10,,,,,,,,,,,,,,,,,,,,,,,,,,,,,,,,,,,,,
487.508,0.60146,1.01264,10,,,,,,,,,,,,,,,,,,,,,,,,,,,,,,,,,,,,,
488.208,0.60146,1.02312,10,,,,,,,,,,,,,,,,,,,,,,,,,,,,,,,,,,,,,
488.908,0.60157,0.98786,10,,,,,,,,,,,,,,,,,,,,,,,,,,,,,,,,,,,,,
489.608,0.60163,0.9739,10,,,,,,,,,,,,,,,,,,,,,,,,,,,,,,,,,,,,,
490.308,0.60169,0.99399,10,,,,,,,,,,,,,,,,,,,,,,,,,,,,,,,,,,,,,
491.008,0.60174,0.97543,10,,,,,,,,,,,,,,,,,,,,,,,,,,,,,,,,,,,,,
491.708,0.6018,0.96028,10,,,,,,,,,,,,,,,,,,,,,,,,,,,,,,,,,,,,,
492.408,0.60186,1.01748,10,,,,,,,,,,,,,,,,,,,,,,,,,,,,,,,,,,,,,
493.108,0.60186,1.01412,10,,,,,,,,,,,,,,,,,,,,,,,,,,,,,,,,,,,,,
493.808,0.60186,1.02609,10,,,,,,,,,,,,,,,,,,,,,,,,,,,,,,,,,,,,,
494.508,0.60186,1.02419,10,,,,,,,,,,,,,,,,,,,,,,,,,,,,,,,,,,,,,
495.208,0.60186,1.00296,10,,,,,,,,,,,,,,,,,,,,,,,,,,,,,,,,,,,,,
495.908,0.60186,1.06694,10,,,,,,,,,,,,,,,,,,,,,,,,,,,,,,,,,,,,,
496.608,0.60186,1.01597,10,,,,,,,,,,,,,,,,,,,,,,,,,,,,,,,,,,,,,
497.308,0.60186,1.01536,10,,,,,,,,,,,,,,,,,,,,,,,,,,,,,,,,,,,,,
498.008,0.60186,1.02841,10,,,,,,,,,,,,,,,,,,,,,,,,,,,,,,,,,,,,,
498.708,0.60186,1.0547,10,,,,,,,,,,,,,,,,,,,,,,,,,,,,,,,,,,,,,
499.408,0.60174,0.99468,10,,,,,,,,,,,,,,,,,,,,,,,,,,,,,,,,,,,,,
500.108,0.60174,1.03715,10,,,,,,,,,,,,,,,,,,,,,,,,,,,,,,,,,,,,,
500.808,0.60174,1.01963,10,,,,,,,,,,,,,,,,,,,,,,,,,,,,,,,,,,,,,
501.508,0.60169,0.96966,10,,,,,,,,,,,,,,,,,,,,,,,,,,,,,,,,,,,,,
502.208,0.6018,0.98613,10,,,,,,,,,,,,,,,,,,,,,,,,,,,,,,,,,,,,,
502.908,0.6018,0.99779,10,,,,,,,,,,,,,,,,,,,,,,,,,,,,,,,,,,,,,
503.608,0.60186,0.97295,10,,,,,,,,,,,,,,,,,,,,,,,,,,,,,,,,,,,,,
504.308,0.60174,1.02266,10,,,,,,,,,,,,,,,,,,,,,,,,,,,,,,,,,,,,,
505.008,0.60186,1.02466,10,,,,,,,,,,,,,,,,,,,,,,,,,,,,,,,,,,,,,
505.708,0.60174,1.01282,10,,,,,,,,,,,,,,,,,,,,,,,,,,,,,,,,,,,,,
506.408,0.60186,1.01707,10,,,,,,,,,,,,,,,,,,,,,,,,,,,,,,,,,,,,,
507.108,0.60174,1.03374,10,,,,,,,,,,,,,,,,,,,,,,,,,,,,,,,,,,,,,
507.808,0.60186,1.02523,10,,,,,,,,,,,,,,,,,,,,,,,,,,,,,,,,,,,,,
508.508,0.60186,0.98348,10,,,,,,,,,,,,,,,,,,,,,,,,,,,,,,,,,,,,,
509.208,0.60186,1.02676,10,,,,,,,,,,,,,,,,,,,,,,,,,,,,,,,,,,,,,
509.908,0.60174,1.02717,10,,,,,,,,,,,,,,,,,,,,,,,,,,,,,,,,,,,,,
510.51,0.60186,1.02939,10,,,,,,,,,,,,,,,,,,,,,,,,,,,,,,,,,,,,,
511.21,6.20183,274.05194,10,,,,,,,,,,,,,,,,,,,,,,,,,,,,,,,,,,,,,
511.91,12.03515,320.80945,10,,,,,,,,,,,,,,,,,,,,,,,,,,,,,,,,,,,,,
512.61,17.86859,80.21688,10,,,,,,,,,,,,,,,,,,,,,,,,,,,,,,,,,,,,,
513.31,23.70191,22.44946,10,,,,,,,,,,,,,,,,,,,,,,,,,,,,,,,,,,,,,
514.01,29.53523,3.79535,10,,,,,,,,,,,,,,,,,,,,,,,,,,,,,,,,,,,,,
514.71,35.3685,-1.31593,10,,,,,,,,,,,,,,,,,,,,,,,,,,,,,,,,,,,,,
515.41,41.20182,-6.15247,10,,,,,,,,,,,,,,,,,,,,,,,,,,,,,,,,,,,,,
516.11,47.0352,-6.11214,10,,,,,,,,,,,,,,,,,,,,,,,,,,,,,,,,,,,,,
516.81,52.86863,-6.14116,10,,,,,,,,,,,,,,,,,,,,,,,,,,,,,,,,,,,,,
517.51,58.70185,-6.07844,10,,,,,,,,,,,,,,,,,,,,,,,,,,,,,,,,,,,,,
517.694,60.23519,-6.16477,10,,,,,,,,,,,,,,,,,,,,,,,,,,,,,,,,,,,,,