File: combined_ligament_solver/data/processed/Data Sheet 3_S160302_ACL.csv
Specimen properties : Length,28,mm,Unnamed: 3,Unnamed: 4,Unnamed: 5,Unnamed: 6,Unnamed: 7,Unnamed: 8,Unnamed: 9,Unnamed: 10,Unnamed: 11,Stress-Strain,Unnamed: 13,Unnamed: 14,Unnamed: 15,Unnamed: 16,Unnamed: 17,Unnamed: 18,Unnamed: 19,Unnamed: 20,Unnamed: 21,Unnamed: 22,Unnamed: 23,Unnamed: 24,Unnamed: 25,Unnamed: 26,Unnamed: 27,Linear,Unnamed: 29,Unnamed: 30,Unnamed: 31,Unnamed: 32,Unnamed: 33,Modulus,Unnamed: 35,Failure,Unnamed: 37,Unnamed: 38,Unnamed: 39,Unnamed: 40
Cross Section Average,53.638999999999996,mm2,,,,,,,,,,Polynomial Coefficients,,,,,,,,,,,,,,,,Force,,Stress,Extension,Strain,,Secant,Tangent,Load,Stress,Extension,Strain,Stiffness
Time,Extension,Load,Total cycle count,,,Extension,Load,Strain,Stress,E-tan,,X6,-635340.9464615068,,,,,,,,,Strain,Stress,E-tan,,,,(N),,(MPa),(mm),(%),,(MPa),(MPa),(N),(MPa),(mm),(%),(N/mm)
(s),(mm),(N),,,,(mm),(N),(mm/mm),(MPa),(MPa),,X5,315723.94982350967,,,,,,,,,(mm/mm),(MPa),(MPa),,,,267.2913466572319,,4.983153053883031,4.984,17.8,,27.99524187574736,36.60714613694612,309.09641,5.746212084490763,5.599909999999999,19.999678571428568,53.62988496332902
0.5,0.08619,4.92804,0,,,4.0617,204.9416,0.1404767857142857,3.8044381886314067,28.329873788114384,,,,,,,,,,,,0.005,0.06558671453685813,14.187241157103346,,,,,,,,,,,,,,,,
1.1,0.18638,8.66058,0,,,9.06174,411.09116,,,,,,,,,,,,,,,0.011,0.16208615535642598,17.435071896350056,,,,,,,,,,,,,,,,
1.7,0.28639,13.62282,0,,,14.06172,453.45578,,,,,,,,,,,,,,,0.017,0.27778755132877886,20.578029108271537,,,,,,,,,,,,,,,,
2.3,0.3863,18.34109,0,,,19.0617,-3.81686,,,,,,,,,,,,,,,0.023,0.4115238266696912,23.468153803299952,,,,,,,,,,,,,,,,
2.9,0.48626,23.47067,0,,,24.06169,-15.10023,,,,,,,,,,,,,,,0.029,0.5613794986122042,25.996806366368784,,,,,,,,,,,,,,,,
3.5,0.58627,29.33787,0,,,,,,,,,,,,,,,,,,,0.035,0.7249141438174089,28.091109460848223,,,,,,,,,,,,,,,,
4.1,0.68646,35.76003,0,,,,,,,,,,,,,,,,,,,0.041,0.8993645222088484,29.710390932482927,,,,,,,,,,,,,,,,
4.544,0.76035,40.03421,0.5,,,,,,,,,,,,,,,,,,,0.047,1.0818253582305355,30.842626713327018,,,,,,,,,,,,,,,,
5.144,0.66005,31.69402,0.5,,,,,,,,,,,,,,,,,,,0.053,1.269408779528589,31.50088372568002,,,,,,,,,,,,,,,,
5.744,0.55992,22.51405,0.5,,,,,,,,,,,,,,,,,,,0.059,1.4593824130564883,31.719762786025917,,,,,,,,,,,,,,,,
6.344,0.46013,15.68135,0.5,,,,,,,,,,,,,,,,,,,0.065,1.6492861386039412,31.551841508964365,,,,,,,,,,,,,,,,
6.944,0.36,10.56354,0.5,,,,,,,,,,,,,,,,,,,0.071,1.8370274997493738,31.064117211152062,,,,,,,,,,,,,,,,
7.544,0.2601,6.13291,0.5,,,,,,,,,,,,,,,,,,,0.077,2.0209557722360367,30.334449815235114,,,,,,,,,,,,,,,,
8.144,0.15991,2.23383,0.5,,,,,,,,,,,,,,,,,,,0.083,2.1999146897717266,29.44800475378881,,,,,,,,,,,,,,,,
8.464,0.13583,1.63721,1,,,,,,,,,,,,,,,,,,,0.089,2.3732738272521243,28.49369587324888,,,,,,,,,,,,,,,,
9.064,0.241,8.2045,1,,,,,,,,,,,,,,,,,,,0.095,2.5409386414077586,27.56062833785486,,,,,,,,,,,,,,,,
9.664,0.34108,13.33048,1,,,,,,,,,,,,,,,,,,,0.101,2.703339168874571,26.73454153357732,,,,,,,,,,,,,,,,
10.264,0.44087,18.94209,1,,,,,,,,,,,,,,,,,,,0.107,2.861397381688121,26.094251972064583,,,,,,,,,,,,,,,,
10.864,0.54088,25.21512,1,,,,,,,,,,,,,,,,,,,0.113,3.016473200201382,25.708096194567684,,,,,,,,,,,,,,,,
11.464,0.64101,31.81871,1,,,,,,,,,,,,,,,,,,,0.119,3.1702891634261783,25.630373675883142,,,,,,,,,,,,,,,,
12.064,0.74114,38.15553,1,,,,,,,,,,,,,,,,,,,0.125,3.324833756798225,25.897789728293017,,,,,,,,,,,,,,,,
12.554,0.72233,36.54385,1.5,,,,,,,,,,,,,,,,,,,0.131,3.4822433973657887,26.52589840549033,,,,,,,,,,,,,,,,
13.154,0.62237,27.64401,1.5,,,,,,,,,,,,,,,,,,,0.137,3.644663076401975,27.505545406531134,,,,,,,,,,,,,,,,
13.754,0.52241,19.39712,1.5,,,,,,,,,,,,,,,,,,,0.143,3.81408565944061,28.799310979751496,,,,,,,,,,,,,,,,
14.354,0.42245,13.2817,1.5,,,,,,,,,,,,,,,,,,,0.149,3.9921698437357622,30.33795282670268,,,,,,,,,,,,,,,,
14.954,0.32232,8.47486,1.5,,,,,,,,,,,,,,,,,,,0.155,4.180036773144881,32.0168490061343,,,,,,,,,,,,,,,,
15.554,0.22225,4.30927,1.5,,,,,,,,,,,,,,,,,,,0.161,4.378045310435528,33.6924408378447,,,,,,,,,,,,,,,,
16.082,0.13436,0.99217,2,,,,,,,,,,,,,,,,,,,0.167,4.5855459670157765,35.17867580672981,,,,,,,,,,,,,,,,
16.486,0.20128,5.42506,2,,,,,,,,,,,,,,,,,,,0.173,4.800613490088118,36.24345046657137,,,,,,,,,,,,,,,,
17.086,0.3013,10.56922,2,,,,,,,,,,,,,,,,,,,0.179,5.019758107227178,36.60505334414662,,,,,,,,,,,,,,,,
17.686,0.40137,15.92282,2,,,,,,,,,,,,,,,,,,,0.185,5.237615428380844,35.92860784302317,,,,,,,,,,,,,,,,
18.286,0.50127,21.99757,2,,,,,,,,,,,,,,,,,,,0.191,5.446615005295107,33.82251514752795,,,,,,,,,,,,,,,,
18.886,0.60129,28.60071,2,,,,,,,,,,,,,,,,,,,0.197,5.636627548362574,29.834897126810283,,,,,,,,,,,,,,,,
19.486,0.70131,35.07335,2,,,,,,,,,,,,,,,,,,,,,,,,,,,,,,,,,,,,,
19.964,0.78092,40.02728,2.5,,,,,,,,,,,,,,,,,,,,,,,,,,,,,,,,,,,,,
20.564,0.68074,32.89885,2.5,,,,,,,,,,,,,,,,,,,,,,,,,,,,,,,,,,,,,
21.164,0.58078,23.34411,2.5,,,,,,,,,,,,,,,,,,,,,,,,,,,,,,,,,,,,,
21.764,0.4807,16.34106,2.5,,,,,,,,,,,,,,,,,,,,,,,,,,,,,,,,,,,,,
22.364,0.38057,10.91309,2.5,,,,,,,,,,,,,,,,,,,,,,,,,,,,,,,,,,,,,
22.964,0.28067,6.38926,2.5,,,,,,,,,,,,,,,,,,,,,,,,,,,,,,,,,,,,,
23.564,0.18071,2.46962,2.5,,,,,,,,,,,,,,,,,,,,,,,,,,,,,,,,,,,,,
23.906,0.15277,1.4995,3,,,,,,,,,,,,,,,,,,,,,,,,,,,,,,,,,,,,,
24.506,0.25795,8.01926,3,,,,,,,,,,,,,,,,,,,,,,,,,,,,,,,,,,,,,
25.106,0.35796,13.12998,3,,,,,,,,,,,,,,,,,,,,,,,,,,,,,,,,,,,,,
25.706,0.45815,18.904,3,,,,,,,,,,,,,,,,,,,,,,,,,,,,,,,,,,,,,
26.306,0.55794,25.26206,3,,,,,,,,,,,,,,,,,,,,,,,,,,,,,,,,,,,,,
26.906,0.6579,31.8803,3,,,,,,,,,,,,,,,,,,,,,,,,,,,,,,,,,,,,,
27.506,0.75803,38.16063,3,,,,,,,,,,,,,,,,,,,,,,,,,,,,,,,,,,,,,
27.986,0.73774,36.60959,3.5,,,,,,,,,,,,,,,,,,,,,,,,,,,,,,,,,,,,,
28.586,0.63778,28.62881,3.5,,,,,,,,,,,,,,,,,,,,,,,,,,,,,,,,,,,,,
29.186,0.53777,19.94626,3.5,,,,,,,,,,,,,,,,,,,,,,,,,,,,,,,,,,,,,
29.786,0.43752,13.59727,3.5,,,,,,,,,,,,,,,,,,,,,,,,,,,,,,,,,,,,,
30.386,0.33762,8.78387,3.5,,,,,,,,,,,,,,,,,,,,,,,,,,,,,,,,,,,,,
30.986,0.23777,4.47292,3.5,,,,,,,,,,,,,,,,,,,,,,,,,,,,,,,,,,,,,
31.538,0.14558,0.99342,4,,,,,,,,,,,,,,,,,,,,,,,,,,,,,,,,,,,,,
31.942,0.21261,5.39316,4,,,,,,,,,,,,,,,,,,,,,,,,,,,,,,,,,,,,,
32.542,0.31257,10.40891,4,,,,,,,,,,,,,,,,,,,,,,,,,,,,,,,,,,,,,
33.142,0.41265,15.81003,4,,,,,,,,,,,,,,,,,,,,,,,,,,,,,,,,,,,,,
33.742,0.51272,21.9008,4,,,,,,,,,,,,,,,,,,,,,,,,,,,,,,,,,,,,,
34.342,0.61262,28.53187,4,,,,,,,,,,,,,,,,,,,,,,,,,,,,,,,,,,,,,
34.942,0.71258,34.89938,4,,,,,,,,,,,,,,,,,,,,,,,,,,,,,,,,,,,,,
35.424,0.79294,40.02146,4.5,,,,,,,,,,,,,,,,,,,,,,,,,,,,,,,,,,,,,
36.024,0.69281,32.96152,4.5,,,,,,,,,,,,,,,,,,,,,,,,,,,,,,,,,,,,,
36.624,0.59279,23.87731,4.5,,,,,,,,,,,,,,,,,,,,,,,,,,,,,,,,,,,,,
37.224,0.4926,16.63976,4.5,,,,,,,,,,,,,,,,,,,,,,,,,,,,,,,,,,,,,
37.824,0.39259,11.02005,4.5,,,,,,,,,,,,,,,,,,,,,,,,,,,,,,,,,,,,,
38.424,0.29274,6.52567,4.5,,,,,,,,,,,,,,,,,,,,,,,,,,,,,,,,,,,,,
39.024,0.19272,2.48444,4.5,,,,,,,,,,,,,,,,,,,,,,,,,,,,,,,,,,,,,
39.36,0.16581,1.42546,5,,,,,,,,,,,,,,,,,,,,,,,,,,,,,,,,,,,,,
39.96,0.27087,8.01038,5,,,,,,,,,,,,,,,,,,,,,,,,,,,,,,,,,,,,,
40.56,0.37094,13.23308,5,,,,,,,,,,,,,,,,,,,,,,,,,,,,,,,,,,,,,
41.16,0.47101,18.95878,5,,,,,,,,,,,,,,,,,,,,,,,,,,,,,,,,,,,,,
41.76,0.57103,25.40837,5,,,,,,,,,,,,,,,,,,,,,,,,,,,,,,,,,,,,,
42.36,0.67088,32.00386,5,,,,,,,,,,,,,,,,,,,,,,,,,,,,,,,,,,,,,
42.96,0.77106,38.26948,5,,,,,,,,,,,,,,,,,,,,,,,,,,,,,,,,,,,,,
43.426,0.7484,36.66105,5.5,,,,,,,,,,,,,,,,,,,,,,,,,,,,,,,,,,,,,
44.026,0.64849,29.22293,5.5,,,,,,,,,,,,,,,,,,,,,,,,,,,,,,,,,,,,,
44.626,0.54836,20.18565,5.5,,,,,,,,,,,,,,,,,,,,,,,,,,,,,,,,,,,,,
45.226,0.44829,13.74064,5.5,,,,,,,,,,,,,,,,,,,,,,,,,,,,,,,,,,,,,
45.826,0.34833,8.78087,5.5,,,,,,,,,,,,,,,,,,,,,,,,,,,,,,,,,,,,,
46.426,0.24843,4.47877,5.5,,,,,,,,,,,,,,,,,,,,,,,,,,,,,,,,,,,,,
46.962,0.15878,0.98717,6,,,,,,,,,,,,,,,,,,,,,,,,,,,,,,,,,,,,,
47.366,0.22599,5.4719,6,,,,,,,,,,,,,,,,,,,,,,,,,,,,,,,,,,,,,
47.966,0.32589,10.49884,6,,,,,,,,,,,,,,,,,,,,,,,,,,,,,,,,,,,,,
48.566,0.42596,16.06256,6,,,,,,,,,,,,,,,,,,,,,,,,,,,,,,,,,,,,,
49.166,0.52604,22.2162,6,,,,,,,,,,,,,,,,,,,,,,,,,,,,,,,,,,,,,
49.766,0.62605,28.79252,6,,,,,,,,,,,,,,,,,,,,,,,,,,,,,,,,,,,,,
50.366,0.7259,35.09822,6,,,,,,,,,,,,,,,,,,,,,,,,,,,,,,,,,,,,,
50.83,0.80331,40.0354,6.5,,,,,,,,,,,,,,,,,,,,,,,,,,,,,,,,,,,,,
51.43,0.70312,33.0042,6.5,,,,,,,,,,,,,,,,,,,,,,,,,,,,,,,,,,,,,
52.03,0.60305,24.26258,6.5,,,,,,,,,,,,,,,,,,,,,,,,,,,,,,,,,,,,,
52.63,0.50292,16.92693,6.5,,,,,,,,,,,,,,,,,,,,,,,,,,,,,,,,,,,,,
53.23,0.40307,11.03695,6.5,,,,,,,,,,,,,,,,,,,,,,,,,,,,,,,,,,,,,
53.83,0.30305,6.52848,6.5,,,,,,,,,,,,,,,,,,,,,,,,,,,,,,,,,,,,,
54.43,0.20304,2.47441,6.5,,,,,,,,,,,,,,,,,,,,,,,,,,,,,,,,,,,,,
54.762,0.17691,1.38708,7,,,,,,,,,,,,,,,,,,,,,,,,,,,,,,,,,,,,,
55.362,0.28192,8.05144,7,,,,,,,,,,,,,,,,,,,,,,,,,,,,,,,,,,,,,
55.962,0.38193,13.30528,7,,,,,,,,,,,,,,,,,,,,,,,,,,,,,,,,,,,,,
56.562,0.48195,19.1739,7,,,,,,,,,,,,,,,,,,,,,,,,,,,,,,,,,,,,,
57.162,0.58202,25.64907,7,,,,,,,,,,,,,,,,,,,,,,,,,,,,,,,,,,,,,
57.762,0.68204,32.0857,7,,,,,,,,,,,,,,,,,,,,,,,,,,,,,,,,,,,,,
58.362,0.782,38.39044,7,,,,,,,,,,,,,,,,,,,,,,,,,,,,,,,,,,,,,
58.808,0.75616,36.56641,7.5,,,,,,,,,,,,,,,,,,,,,,,,,,,,,,,,,,,,,
59.408,0.65609,29.52109,7.5,,,,,,,,,,,,,,,,,,,,,,,,,,,,,,,,,,,,,
60.008,0.55596,20.24068,7.5,,,,,,,,,,,,,,,,,,,,,,,,,,,,,,,,,,,,,
60.608,0.45605,13.76336,7.5,,,,,,,,,,,,,,,,,,,,,,,,,,,,,,,,,,,,,
61.208,0.35609,8.66907,7.5,,,,,,,,,,,,,,,,,,,,,,,,,,,,,,,,,,,,,
61.808,0.25608,4.33811,7.5,,,,,,,,,,,,,,,,,,,,,,,,,,,,,,,,,,,,,
62.332,0.16853,0.99768,8,,,,,,,,,,,,,,,,,,,,,,,,,,,,,,,,,,,,,
62.736,0.23573,5.54166,8,,,,,,,,,,,,,,,,,,,,,,,,,,,,,,,,,,,,,
63.336,0.33558,10.54556,8,,,,,,,,,,,,,,,,,,,,,,,,,,,,,,,,,,,,,
63.936,0.4356,16.23672,8,,,,,,,,,,,,,,,,,,,,,,,,,,,,,,,,,,,,,
64.536,0.53567,22.35896,8,,,,,,,,,,,,,,,,,,,,,,,,,,,,,,,,,,,,,
65.136,0.63574,28.97943,8,,,,,,,,,,,,,,,,,,,,,,,,,,,,,,,,,,,,,
65.736,0.73559,35.14114,8,,,,,,,,,,,,,,,,,,,,,,,,,,,,,,,,,,,,,
66.19,0.81124,40.02474,8.5,,,,,,,,,,,,,,,,,,,,,,,,,,,,,,,,,,,,,
66.79,0.71111,32.98144,8.5,,,,,,,,,,,,,,,,,,,,,,,,,,,,,,,,,,,,,
67.39,0.61092,24.72848,8.5,,,,,,,,,,,,,,,,,,,,,,,,,,,,,,,,,,,,,
67.99,0.51102,17.07592,8.5,,,,,,,,,,,,,,,,,,,,,,,,,,,,,,,,,,,,,
68.59,0.41106,11.17163,8.5,,,,,,,,,,,,,,,,,,,,,,,,,,,,,,,,,,,,,
69.19,0.3111,6.52513,8.5,,,,,,,,,,,,,,,,,,,,,,,,,,,,,,,,,,,,,
69.79,0.21091,2.42031,8.5,,,,,,,,,,,,,,,,,,,,,,,,,,,,,,,,,,,,,
70.132,0.18315,1.30453,9,,,,,,,,,,,,,,,,,,,,,,,,,,,,,,,,,,,,,
70.732,0.28843,7.97553,9,,,,,,,,,,,,,,,,,,,,,,,,,,,,,,,,,,,,,
71.332,0.38822,13.28993,9,,,,,,,,,,,,,,,,,,,,,,,,,,,,,,,,,,,,,
71.932,0.48824,19.22668,9,,,,,,,,,,,,,,,,,,,,,,,,,,,,,,,,,,,,,
72.532,0.58831,25.6677,9,,,,,,,,,,,,,,,,,,,,,,,,,,,,,,,,,,,,,
73.132,0.68844,32.00469,9,,,,,,,,,,,,,,,,,,,,,,,,,,,,,,,,,,,,,
73.732,0.78835,38.36096,9,,,,,,,,,,,,,,,,,,,,,,,,,,,,,,,,,,,,,
74.19,0.76443,36.67422,9.5,,,,,,,,,,,,,,,,,,,,,,,,,,,,,,,,,,,,,
74.79,0.6643,29.75383,9.5,,,,,,,,,,,,,,,,,,,,,,,,,,,,,,,,,,,,,
75.39,0.56434,20.5815,9.5,,,,,,,,,,,,,,,,,,,,,,,,,,,,,,,,,,,,,
75.99,0.4645,13.99502,9.5,,,,,,,,,,,,,,,,,,,,,,,,,,,,,,,,,,,,,
76.59,0.36442,8.80925,9.5,,,,,,,,,,,,,,,,,,,,,,,,,,,,,,,,,,,,,
77.19,0.26435,4.46986,9.5,,,,,,,,,,,,,,,,,,,,,,,,,,,,,,,,,,,,,
77.724,0.17533,0.99986,10,,,,,,,,,,,,,,,,,,,,,,,,,,,,,,,,,,,,,
78.226,0.14869,0.15143,10,,,,,,,,,,,,,,,,,,,,,,,,,,,,,,,,,,,,,
78.826,0.15232,0.50988,10,,,,,,,,,,,,,,,,,,,,,,,,,,,,,,,,,,,,,
79.426,0.15787,1.07107,10,,,,,,,,,,,,,,,,,,,,,,,,,,,,,,,,,,,,,
80.026,0.15759,1.11316,10,,,,,,,,,,,,,,,,,,,,,,,,,,,,,,,,,,,,,
80.626,0.15651,1.16074,10,,,,,,,,,,,,,,,,,,,,,,,,,,,,,,,,,,,,,
81.226,0.15379,0.9373,10,,,,,,,,,,,,,,,,,,,,,,,,,,,,,,,,,,,,,
81.826,0.15232,0.86668,10,,,,,,,,,,,,,,,,,,,,,,,,,,,,,,,,,,,,,
82.426,0.15181,0.88071,10,,,,,,,,,,,,,,,,,,,,,,,,,,,,,,,,,,,,,
83.026,0.15164,0.90547,10,,,,,,,,,,,,,,,,,,,,,,,,,,,,,,,,,,,,,
83.626,0.15136,0.94326,10,,,,,,,,,,,,,,,,,,,,,,,,,,,,,,,,,,,,,
84.226,0.15096,0.88477,10,,,,,,,,,,,,,,,,,,,,,,,,,,,,,,,,,,,,,
84.826,0.15056,0.85392,10,,,,,,,,,,,,,,,,,,,,,,,,,,,,,,,,,,,,,
85.426,0.15039,0.90383,10,,,,,,,,,,,,,,,,,,,,,,,,,,,,,,,,,,,,,
86.026,0.15,0.93616,10,,,,,,,,,,,,,,,,,,,,,,,,,,,,,,,,,,,,,
86.626,0.14977,0.86698,10,,,,,,,,,,,,,,,,,,,,,,,,,,,,,,,,,,,,,
87.226,0.1496,0.87558,10,,,,,,,,,,,,,,,,,,,,,,,,,,,,,,,,,,,,,
87.826,0.14937,0.91057,10,,,,,,,,,,,,,,,,,,,,,,,,,,,,,,,,,,,,,
88.426,0.1492,0.88973,10,,,,,,,,,,,,,,,,,,,,,,,,,,,,,,,,,,,,,
89.026,0.14903,0.86545,10,,,,,,,,,,,,,,,,,,,,,,,,,,,,,,,,,,,,,
89.626,0.14886,0.86983,10,,,,,,,,,,,,,,,,,,,,,,,,,,,,,,,,,,,,,
90.226,0.14864,0.88378,10,,,,,,,,,,,,,,,,,,,,,,,,,,,,,,,,,,,,,
90.826,0.14847,0.88561,10,,,,,,,,,,,,,,,,,,,,,,,,,,,,,,,,,,,,,
91.426,0.14813,0.91179,10,,,,,,,,,,,,,,,,,,,,,,,,,,,,,,,,,,,,,
92.026,0.14779,0.797,10,,,,,,,,,,,,,,,,,,,,,,,,,,,,,,,,,,,,,
92.626,0.14767,0.85246,10,,,,,,,,,,,,,,,,,,,,,,,,,,,,,,,,,,,,,
93.226,0.14762,0.89708,10,,,,,,,,,,,,,,,,,,,,,,,,,,,,,,,,,,,,,
93.826,0.14762,0.87332,10,,,,,,,,,,,,,,,,,,,,,,,,,,,,,,,,,,,,,
94.426,0.14773,0.9035,10,,,,,,,,,,,,,,,,,,,,,,,,,,,,,,,,,,,,,
95.026,0.14762,0.91821,10,,,,,,,,,,,,,,,,,,,,,,,,,,,,,,,,,,,,,
95.626,0.14762,0.91981,10,,,,,,,,,,,,,,,,,,,,,,,,,,,,,,,,,,,,,
96.226,0.1475,0.91851,10,,,,,,,,,,,,,,,,,,,,,,,,,,,,,,,,,,,,,
96.826,0.14722,0.91206,10,,,,,,,,,,,,,,,,,,,,,,,,,,,,,,,,,,,,,
97.426,0.14699,0.87035,10,,,,,,,,,,,,,,,,,,,,,,,,,,,,,,,,,,,,,
98.026,0.14677,0.85825,10,,,,,,,,,,,,,,,,,,,,,,,,,,,,,,,,,,,,,
98.626,0.1466,0.85537,10,,,,,,,,,,,,,,,,,,,,,,,,,,,,,,,,,,,,,
99.226,0.14654,0.89135,10,,,,,,,,,,,,,,,,,,,,,,,,,,,,,,,,,,,,,
99.826,0.14648,0.86659,10,,,,,,,,,,,,,,,,,,,,,,,,,,,,,,,,,,,,,
100.426,0.14643,0.90216,10,,,,,,,,,,,,,,,,,,,,,,,,,,,,,,,,,,,,,
101.026,0.14631,0.88072,10,,,,,,,,,,,,,,,,,,,,,,,,,,,,,,,,,,,,,
101.626,0.14626,0.90459,10,,,,,,,,,,,,,,,,,,,,,,,,,,,,,,,,,,,,,
102.226,0.1462,0.91434,10,,,,,,,,,,,,,,,,,,,,,,,,,,,,,,,,,,,,,
102.826,0.14614,0.9081,10,,,,,,,,,,,,,,,,,,,,,,,,,,,,,,,,,,,,,
103.426,0.14603,0.94362,10,,,,,,,,,,,,,,,,,,,,,,,,,,,,,,,,,,,,,
104.026,0.14586,0.89053,10,,,,,,,,,,,,,,,,,,,,,,,,,,,,,,,,,,,,,
104.626,0.14569,0.87332,10,,,,,,,,,,,,,,,,,,,,,,,,,,,,,,,,,,,,,
105.226,0.14552,0.89459,10,,,,,,,,,,,,,,,,,,,,,,,,,,,,,,,,,,,,,
105.826,0.14541,0.87331,10,,,,,,,,,,,,,,,,,,,,,,,,,,,,,,,,,,,,,
106.426,0.14529,0.85797,10,,,,,,,,,,,,,,,,,,,,,,,,,,,,,,,,,,,,,
107.026,0.14524,0.88178,10,,,,,,,,,,,,,,,,,,,,,,,,,,,,,,,,,,,,,
107.626,0.14518,0.89237,10,,,,,,,,,,,,,,,,,,,,,,,,,,,,,,,,,,,,,
108.226,0.14512,0.89052,10,,,,,,,,,,,,,,,,,,,,,,,,,,,,,,,,,,,,,
108.826,0.14507,0.87605,10,,,,,,,,,,,,,,,,,,,,,,,,,,,,,,,,,,,,,
109.426,0.14495,0.92515,10,,,,,,,,,,,,,,,,,,,,,,,,,,,,,,,,,,,,,
110.026,0.14484,0.87164,10,,,,,,,,,,,,,,,,,,,,,,,,,,,,,,,,,,,,,
110.626,0.14473,0.86458,10,,,,,,,,,,,,,,,,,,,,,,,,,,,,,,,,,,,,,
111.226,0.14456,0.90267,10,,,,,,,,,,,,,,,,,,,,,,,,,,,,,,,,,,,,,
111.826,0.14444,0.86758,10,,,,,,,,,,,,,,,,,,,,,,,,,,,,,,,,,,,,,
112.426,0.14439,0.90839,10,,,,,,,,,,,,,,,,,,,,,,,,,,,,,,,,,,,,,
113.026,0.14439,0.8801,10,,,,,,,,,,,,,,,,,,,,,,,,,,,,,,,,,,,,,
113.626,0.14439,0.91353,10,,,,,,,,,,,,,,,,,,,,,,,,,,,,,,,,,,,,,
114.226,0.14439,0.88138,10,,,,,,,,,,,,,,,,,,,,,,,,,,,,,,,,,,,,,
114.826,0.14444,0.88617,10,,,,,,,,,,,,,,,,,,,,,,,,,,,,,,,,,,,,,
115.426,0.14444,0.92563,10,,,,,,,,,,,,,,,,,,,,,,,,,,,,,,,,,,,,,
116.026,0.14433,0.94042,10,,,,,,,,,,,,,,,,,,,,,,,,,,,,,,,,,,,,,
116.626,0.14422,0.87089,10,,,,,,,,,,,,,,,,,,,,,,,,,,,,,,,,,,,,,
117.226,0.14388,0.9158,10,,,,,,,,,,,,,,,,,,,,,,,,,,,,,,,,,,,,,
117.826,0.14359,0.85424,10,,,,,,,,,,,,,,,,,,,,,,,,,,,,,,,,,,,,,
118.426,0.14348,0.8573,10,,,,,,,,,,,,,,,,,,,,,,,,,,,,,,,,,,,,,
119.026,0.14348,0.83667,10,,,,,,,,,,,,,,,,,,,,,,,,,,,,,,,,,,,,,
119.626,0.14348,0.84472,10,,,,,,,,,,,,,,,,,,,,,,,,,,,,,,,,,,,,,
120.226,0.14348,0.86631,10,,,,,,,,,,,,,,,,,,,,,,,,,,,,,,,,,,,,,
120.826,0.14348,0.87028,10,,,,,,,,,,,,,,,,,,,,,,,,,,,,,,,,,,,,,
121.426,0.14348,0.90943,10,,,,,,,,,,,,,,,,,,,,,,,,,,,,,,,,,,,,,
122.026,0.14342,0.92764,10,,,,,,,,,,,,,,,,,,,,,,,,,,,,,,,,,,,,,
122.626,0.14331,0.92075,10,,,,,,,,,,,,,,,,,,,,,,,,,,,,,,,,,,,,,
123.226,0.14325,0.86915,10,,,,,,,,,,,,,,,,,,,,,,,,,,,,,,,,,,,,,
123.826,0.14314,0.8765,10,,,,,,,,,,,,,,,,,,,,,,,,,,,,,,,,,,,,,
124.426,0.14308,0.92195,10,,,,,,,,,,,,,,,,,,,,,,,,,,,,,,,,,,,,,
125.026,0.14291,0.81756,10,,,,,,,,,,,,,,,,,,,,,,,,,,,,,,,,,,,,,
125.626,0.14286,0.83713,10,,,,,,,,,,,,,,,,,,,,,,,,,,,,,,,,,,,,,
126.226,0.14286,0.88665,10,,,,,,,,,,,,,,,,,,,,,,,,,,,,,,,,,,,,,
126.826,0.1428,0.83398,10,,,,,,,,,,,,,,,,,,,,,,,,,,,,,,,,,,,,,
127.426,0.14274,0.8784,10,,,,,,,,,,,,,,,,,,,,,,,,,,,,,,,,,,,,,
128.026,0.14274,0.87535,10,,,,,,,,,,,,,,,,,,,,,,,,,,,,,,,,,,,,,
128.626,0.14274,0.86755,10,,,,,,,,,,,,,,,,,,,,,,,,,,,,,,,,,,,,,
129.226,0.14274,0.86503,10,,,,,,,,,,,,,,,,,,,,,,,,,,,,,,,,,,,,,
129.826,0.14274,0.90702,10,,,,,,,,,,,,,,,,,,,,,,,,,,,,,,,,,,,,,
130.426,0.14274,0.92673,10,,,,,,,,,,,,,,,,,,,,,,,,,,,,,,,,,,,,,
131.026,0.14274,0.92943,10,,,,,,,,,,,,,,,,,,,,,,,,,,,,,,,,,,,,,
131.626,0.14274,0.9089,10,,,,,,,,,,,,,,,,,,,,,,,,,,,,,,,,,,,,,
132.226,0.14263,0.8946,10,,,,,,,,,,,,,,,,,,,,,,,,,,,,,,,,,,,,,
132.826,0.1424,0.91583,10,,,,,,,,,,,,,,,,,,,,,,,,,,,,,,,,,,,,,
133.426,0.14212,0.89805,10,,,,,,,,,,,,,,,,,,,,,,,,,,,,,,,,,,,,,
134.026,0.14195,0.87824,10,,,,,,,,,,,,,,,,,,,,,,,,,,,,,,,,,,,,,
134.626,0.14189,0.87357,10,,,,,,,,,,,,,,,,,,,,,,,,,,,,,,,,,,,,,
135.226,0.14195,0.88761,10,,,,,,,,,,,,,,,,,,,,,,,,,,,,,,,,,,,,,
135.826,0.14195,0.86224,10,,,,,,,,,,,,,,,,,,,,,,,,,,,,,,,,,,,,,
136.426,0.14195,0.8619,10,,,,,,,,,,,,,,,,,,,,,,,,,,,,,,,,,,,,,
137.026,0.14201,0.86551,10,,,,,,,,,,,,,,,,,,,,,,,,,,,,,,,,,,,,,
137.626,0.14201,0.83572,10,,,,,,,,,,,,,,,,,,,,,,,,,,,,,,,,,,,,,
138.226,0.14201,0.86693,10,,,,,,,,,,,,,,,,,,,,,,,,,,,,,,,,,,,,,
138.826,0.14201,0.86273,10,,,,,,,,,,,,,,,,,,,,,,,,,,,,,,,,,,,,,
139.426,0.14189,0.91792,10,,,,,,,,,,,,,,,,,,,,,,,,,,,,,,,,,,,,,
140.026,0.14189,0.87981,10,,,,,,,,,,,,,,,,,,,,,,,,,,,,,,,,,,,,,
140.626,0.14184,0.92771,10,,,,,,,,,,,,,,,,,,,,,,,,,,,,,,,,,,,,,
141.226,0.14178,0.89884,10,,,,,,,,,,,,,,,,,,,,,,,,,,,,,,,,,,,,,
141.826,0.14161,0.90241,10,,,,,,,,,,,,,,,,,,,,,,,,,,,,,,,,,,,,,
142.426,0.14133,0.91205,10,,,,,,,,,,,,,,,,,,,,,,,,,,,,,,,,,,,,,
143.026,0.14116,0.85072,10,,,,,,,,,,,,,,,,,,,,,,,,,,,,,,,,,,,,,
143.626,0.14104,0.85134,10,,,,,,,,,,,,,,,,,,,,,,,,,,,,,,,,,,,,,
144.226,0.14099,0.89276,10,,,,,,,,,,,,,,,,,,,,,,,,,,,,,,,,,,,,,
144.826,0.14099,0.86877,10,,,,,,,,,,,,,,,,,,,,,,,,,,,,,,,,,,,,,
145.426,0.1411,0.92435,10,,,,,,,,,,,,,,,,,,,,,,,,,,,,,,,,,,,,,
146.026,0.1411,0.89371,10,,,,,,,,,,,,,,,,,,,,,,,,,,,,,,,,,,,,,
146.626,0.14116,0.8884,10,,,,,,,,,,,,,,,,,,,,,,,,,,,,,,,,,,,,,
147.226,0.14116,0.85872,10,,,,,,,,,,,,,,,,,,,,,,,,,,,,,,,,,,,,,
147.826,0.14116,0.84368,10,,,,,,,,,,,,,,,,,,,,,,,,,,,,,,,,,,,,,
148.426,0.14121,0.90306,10,,,,,,,,,,,,,,,,,,,,,,,,,,,,,,,,,,,,,
149.026,0.14121,0.85861,10,,,,,,,,,,,,,,,,,,,,,,,,,,,,,,,,,,,,,
149.626,0.14121,0.88387,10,,,,,,,,,,,,,,,,,,,,,,,,,,,,,,,,,,,,,
150.226,0.14121,0.90902,10,,,,,,,,,,,,,,,,,,,,,,,,,,,,,,,,,,,,,
150.826,0.14121,0.9163,10,,,,,,,,,,,,,,,,,,,,,,,,,,,,,,,,,,,,,
151.426,0.14121,0.88456,10,,,,,,,,,,,,,,,,,,,,,,,,,,,,,,,,,,,,,
152.026,0.14121,0.86903,10,,,,,,,,,,,,,,,,,,,,,,,,,,,,,,,,,,,,,
152.626,0.1411,0.93571,10,,,,,,,,,,,,,,,,,,,,,,,,,,,,,,,,,,,,,
153.226,0.14104,0.9119,10,,,,,,,,,,,,,,,,,,,,,,,,,,,,,,,,,,,,,
153.826,0.14104,0.87373,10,,,,,,,,,,,,,,,,,,,,,,,,,,,,,,,,,,,,,
154.426,0.14099,0.91753,10,,,,,,,,,,,,,,,,,,,,,,,,,,,,,,,,,,,,,
155.026,0.14082,0.92667,10,,,,,,,,,,,,,,,,,,,,,,,,,,,,,,,,,,,,,
155.626,0.1407,0.92448,10,,,,,,,,,,,,,,,,,,,,,,,,,,,,,,,,,,,,,
156.226,0.14042,0.90202,10,,,,,,,,,,,,,,,,,,,,,,,,,,,,,,,,,,,,,
156.826,0.14014,0.86722,10,,,,,,,,,,,,,,,,,,,,,,,,,,,,,,,,,,,,,
157.426,0.13997,0.90493,10,,,,,,,,,,,,,,,,,,,,,,,,,,,,,,,,,,,,,
158.026,0.13991,0.82871,10,,,,,,,,,,,,,,,,,,,,,,,,,,,,,,,,,,,,,
158.626,0.13991,0.86076,10,,,,,,,,,,,,,,,,,,,,,,,,,,,,,,,,,,,,,
159.226,0.13991,0.83614,10,,,,,,,,,,,,,,,,,,,,,,,,,,,,,,,,,,,,,
159.826,0.13997,0.87726,10,,,,,,,,,,,,,,,,,,,,,,,,,,,,,,,,,,,,,
160.426,0.14008,0.88751,10,,,,,,,,,,,,,,,,,,,,,,,,,,,,,,,,,,,,,
161.026,0.14008,0.83495,10,,,,,,,,,,,,,,,,,,,,,,,,,,,,,,,,,,,,,
161.626,0.14008,0.89331,10,,,,,,,,,,,,,,,,,,,,,,,,,,,,,,,,,,,,,
162.226,0.14014,0.87041,10,,,,,,,,,,,,,,,,,,,,,,,,,,,,,,,,,,,,,
162.826,0.14014,0.86741,10,,,,,,,,,,,,,,,,,,,,,,,,,,,,,,,,,,,,,
163.426,0.14014,0.88091,10,,,,,,,,,,,,,,,,,,,,,,,,,,,,,,,,,,,,,
164.026,0.14019,0.83832,10,,,,,,,,,,,,,,,,,,,,,,,,,,,,,,,,,,,,,
164.626,0.14019,0.85827,10,,,,,,,,,,,,,,,,,,,,,,,,,,,,,,,,,,,,,
165.226,0.14019,0.89608,10,,,,,,,,,,,,,,,,,,,,,,,,,,,,,,,,,,,,,
165.826,0.14019,0.89847,10,,,,,,,,,,,,,,,,,,,,,,,,,,,,,,,,,,,,,
166.426,0.14019,0.91696,10,,,,,,,,,,,,,,,,,,,,,,,,,,,,,,,,,,,,,
167.026,0.14008,0.901,10,,,,,,,,,,,,,,,,,,,,,,,,,,,,,,,,,,,,,
167.626,0.14008,0.87138,10,,,,,,,,,,,,,,,,,,,,,,,,,,,,,,,,,,,,,
168.226,0.14002,0.87505,10,,,,,,,,,,,,,,,,,,,,,,,,,,,,,,,,,,,,,
168.826,0.13997,0.94166,10,,,,,,,,,,,,,,,,,,,,,,,,,,,,,,,,,,,,,
169.426,0.13991,0.91429,10,,,,,,,,,,,,,,,,,,,,,,,,,,,,,,,,,,,,,
170.026,0.13985,0.90544,10,,,,,,,,,,,,,,,,,,,,,,,,,,,,,,,,,,,,,
170.626,0.1398,0.94331,10,,,,,,,,,,,,,,,,,,,,,,,,,,,,,,,,,,,,,
171.226,0.13957,0.88343,10,,,,,,,,,,,,,,,,,,,,,,,,,,,,,,,,,,,,,
171.826,0.13934,0.98417,10,,,,,,,,,,,,,,,,,,,,,,,,,,,,,,,,,,,,,
172.426,0.13906,0.88326,10,,,,,,,,,,,,,,,,,,,,,,,,,,,,,,,,,,,,,
173.026,0.13889,0.88114,10,,,,,,,,,,,,,,,,,,,,,,,,,,,,,,,,,,,,,
173.626,0.13883,0.85148,10,,,,,,,,,,,,,,,,,,,,,,,,,,,,,,,,,,,,,
174.226,0.13883,0.88436,10,,,,,,,,,,,,,,,,,,,,,,,,,,,,,,,,,,,,,
174.826,0.13889,0.90244,10,,,,,,,,,,,,,,,,,,,,,,,,,,,,,,,,,,,,,
175.426,0.139,0.85377,10,,,,,,,,,,,,,,,,,,,,,,,,,,,,,,,,,,,,,
176.026,0.139,0.82151,10,,,,,,,,,,,,,,,,,,,,,,,,,,,,,,,,,,,,,
176.626,0.13906,0.87251,10,,,,,,,,,,,,,,,,,,,,,,,,,,,,,,,,,,,,,
177.226,0.13906,0.8992,10,,,,,,,,,,,,,,,,,,,,,,,,,,,,,,,,,,,,,
177.826,0.13912,0.94326,10,,,,,,,,,,,,,,,,,,,,,,,,,,,,,,,,,,,,,
178.426,0.13912,0.86898,10,,,,,,,,,,,,,,,,,,,,,,,,,,,,,,,,,,,,,
179.026,0.13917,0.89583,10,,,,,,,,,,,,,,,,,,,,,,,,,,,,,,,,,,,,,
179.626,0.13906,0.8614,10,,,,,,,,,,,,,,,,,,,,,,,,,,,,,,,,,,,,,
180.226,0.13917,0.91571,10,,,,,,,,,,,,,,,,,,,,,,,,,,,,,,,,,,,,,
180.826,0.13906,0.90945,10,,,,,,,,,,,,,,,,,,,,,,,,,,,,,,,,,,,,,
181.426,0.13906,0.91089,10,,,,,,,,,,,,,,,,,,,,,,,,,,,,,,,,,,,,,
182.026,0.13906,0.91959,10,,,,,,,,,,,,,,,,,,,,,,,,,,,,,,,,,,,,,
182.626,0.13906,0.88113,10,,,,,,,,,,,,,,,,,,,,,,,,,,,,,,,,,,,,,
183.226,0.139,0.89411,10,,,,,,,,,,,,,,,,,,,,,,,,,,,,,,,,,,,,,
183.826,0.13895,0.94086,10,,,,,,,,,,,,,,,,,,,,,,,,,,,,,,,,,,,,,
184.426,0.13895,0.91758,10,,,,,,,,,,,,,,,,,,,,,,,,,,,,,,,,,,,,,
185.026,0.13889,0.89454,10,,,,,,,,,,,,,,,,,,,,,,,,,,,,,,,,,,,,,
185.626,0.13883,0.88616,10,,,,,,,,,,,,,,,,,,,,,,,,,,,,,,,,,,,,,
186.226,0.13866,0.97792,10,,,,,,,,,,,,,,,,,,,,,,,,,,,,,,,,,,,,,
186.826,0.13849,0.8887,10,,,,,,,,,,,,,,,,,,,,,,,,,,,,,,,,,,,,,
187.426,0.13827,0.86095,10,,,,,,,,,,,,,,,,,,,,,,,,,,,,,,,,,,,,,
188.026,0.13815,0.83688,10,,,,,,,,,,,,,,,,,,,,,,,,,,,,,,,,,,,,,
188.626,0.1381,0.85207,10,,,,,,,,,,,,,,,,,,,,,,,,,,,,,,,,,,,,,
189.226,0.13804,0.8387,10,,,,,,,,,,,,,,,,,,,,,,,,,,,,,,,,,,,,,
189.826,0.13804,0.83367,10,,,,,,,,,,,,,,,,,,,,,,,,,,,,,,,,,,,,,
190.426,0.13815,0.83524,10,,,,,,,,,,,,,,,,,,,,,,,,,,,,,,,,,,,,,
191.026,0.1381,0.88862,10,,,,,,,,,,,,,,,,,,,,,,,,,,,,,,,,,,,,,
191.626,0.1381,0.89896,10,,,,,,,,,,,,,,,,,,,,,,,,,,,,,,,,,,,,,
192.226,0.1381,0.87373,10,,,,,,,,,,,,,,,,,,,,,,,,,,,,,,,,,,,,,
192.826,0.1381,0.86459,10,,,,,,,,,,,,,,,,,,,,,,,,,,,,,,,,,,,,,
193.426,0.13821,0.88722,10,,,,,,,,,,,,,,,,,,,,,,,,,,,,,,,,,,,,,
194.026,0.1381,0.89703,10,,,,,,,,,,,,,,,,,,,,,,,,,,,,,,,,,,,,,
194.626,0.13815,0.89375,10,,,,,,,,,,,,,,,,,,,,,,,,,,,,,,,,,,,,,
195.226,0.13815,0.91775,10,,,,,,,,,,,,,,,,,,,,,,,,,,,,,,,,,,,,,
195.826,0.13815,0.85203,10,,,,,,,,,,,,,,,,,,,,,,,,,,,,,,,,,,,,,
196.426,0.13804,0.8957,10,,,,,,,,,,,,,,,,,,,,,,,,,,,,,,,,,,,,,
197.026,0.13798,0.93727,10,,,,,,,,,,,,,,,,,,,,,,,,,,,,,,,,,,,,,
197.626,0.13793,0.89034,10,,,,,,,,,,,,,,,,,,,,,,,,,,,,,,,,,,,,,
198.226,0.13781,0.93668,10,,,,,,,,,,,,,,,,,,,,,,,,,,,,,,,,,,,,,
198.826,0.13764,0.85603,10,,,,,,,,,,,,,,,,,,,,,,,,,,,,,,,,,,,,,
199.426,0.13753,0.90432,10,,,,,,,,,,,,,,,,,,,,,,,,,,,,,,,,,,,,,
200.026,0.13753,0.84606,10,,,,,,,,,,,,,,,,,,,,,,,,,,,,,,,,,,,,,
200.626,0.13753,0.86559,10,,,,,,,,,,,,,,,,,,,,,,,,,,,,,,,,,,,,,
201.226,0.13753,0.86793,10,,,,,,,,,,,,,,,,,,,,,,,,,,,,,,,,,,,,,
201.826,0.13764,0.85176,10,,,,,,,,,,,,,,,,,,,,,,,,,,,,,,,,,,,,,
202.426,0.13764,0.89938,10,,,,,,,,,,,,,,,,,,,,,,,,,,,,,,,,,,,,,
203.026,0.13764,0.88219,10,,,,,,,,,,,,,,,,,,,,,,,,,,,,,,,,,,,,,
203.626,0.13764,0.83621,10,,,,,,,,,,,,,,,,,,,,,,,,,,,,,,,,,,,,,
204.226,0.1377,0.89755,10,,,,,,,,,,,,,,,,,,,,,,,,,,,,,,,,,,,,,
204.826,0.1377,0.86729,10,,,,,,,,,,,,,,,,,,,,,,,,,,,,,,,,,,,,,
205.426,0.1377,0.89982,10,,,,,,,,,,,,,,,,,,,,,,,,,,,,,,,,,,,,,
206.026,0.1377,0.87993,10,,,,,,,,,,,,,,,,,,,,,,,,,,,,,,,,,,,,,
206.626,0.13764,0.85501,10,,,,,,,,,,,,,,,,,,,,,,,,,,,,,,,,,,,,,
207.226,0.1377,0.89377,10,,,,,,,,,,,,,,,,,,,,,,,,,,,,,,,,,,,,,
207.826,0.1377,0.8781,10,,,,,,,,,,,,,,,,,,,,,,,,,,,,,,,,,,,,,
208.426,0.1377,0.88726,10,,,,,,,,,,,,,,,,,,,,,,,,,,,,,,,,,,,,,
209.026,0.13759,0.8692,10,,,,,,,,,,,,,,,,,,,,,,,,,,,,,,,,,,,,,
209.626,0.13759,0.86514,10,,,,,,,,,,,,,,,,,,,,,,,,,,,,,,,,,,,,,
210.226,0.13759,0.95758,10,,,,,,,,,,,,,,,,,,,,,,,,,,,,,,,,,,,,,
210.826,0.13759,0.92114,10,,,,,,,,,,,,,,,,,,,,,,,,,,,,,,,,,,,,,
211.426,0.13747,0.91568,10,,,,,,,,,,,,,,,,,,,,,,,,,,,,,,,,,,,,,
212.026,0.13742,0.86482,10,,,,,,,,,,,,,,,,,,,,,,,,,,,,,,,,,,,,,
212.626,0.13742,0.9131,10,,,,,,,,,,,,,,,,,,,,,,,,,,,,,,,,,,,,,
213.226,0.13736,0.9122,10,,,,,,,,,,,,,,,,,,,,,,,,,,,,,,,,,,,,,
213.826,0.13725,0.85058,10,,,,,,,,,,,,,,,,,,,,,,,,,,,,,,,,,,,,,
214.426,0.13719,0.89133,10,,,,,,,,,,,,,,,,,,,,,,,,,,,,,,,,,,,,,
215.026,0.13713,0.89759,10,,,,,,,,,,,,,,,,,,,,,,,,,,,,,,,,,,,,,
215.626,0.13702,0.87888,10,,,,,,,,,,,,,,,,,,,,,,,,,,,,,,,,,,,,,
216.226,0.13691,0.87379,10,,,,,,,,,,,,,,,,,,,,,,,,,,,,,,,,,,,,,
216.826,0.13685,0.81446,10,,,,,,,,,,,,,,,,,,,,,,,,,,,,,,,,,,,,,
217.426,0.13696,0.90279,10,,,,,,,,,,,,,,,,,,,,,,,,,,,,,,,,,,,,,
218.026,0.13691,0.84331,10,,,,,,,,,,,,,,,,,,,,,,,,,,,,,,,,,,,,,
218.626,0.13702,0.86887,10,,,,,,,,,,,,,,,,,,,,,,,,,,,,,,,,,,,,,
219.226,0.13696,0.89297,10,,,,,,,,,,,,,,,,,,,,,,,,,,,,,,,,,,,,,
219.826,0.13708,0.87724,10,,,,,,,,,,,,,,,,,,,,,,,,,,,,,,,,,,,,,
220.426,0.13708,0.88674,10,,,,,,,,,,,,,,,,,,,,,,,,,,,,,,,,,,,,,
221.026,0.13696,0.90768,10,,,,,,,,,,,,,,,,,,,,,,,,,,,,,,,,,,,,,
221.626,0.13708,0.85658,10,,,,,,,,,,,,,,,,,,,,,,,,,,,,,,,,,,,,,
222.226,0.13696,0.90766,10,,,,,,,,,,,,,,,,,,,,,,,,,,,,,,,,,,,,,
222.826,0.13696,0.85507,10,,,,,,,,,,,,,,,,,,,,,,,,,,,,,,,,,,,,,
223.426,0.13696,0.92494,10,,,,,,,,,,,,,,,,,,,,,,,,,,,,,,,,,,,,,
224.026,0.13696,0.87188,10,,,,,,,,,,,,,,,,,,,,,,,,,,,,,,,,,,,,,
224.626,0.13702,0.8674,10,,,,,,,,,,,,,,,,,,,,,,,,,,,,,,,,,,,,,
225.226,0.13702,0.88981,10,,,,,,,,,,,,,,,,,,,,,,,,,,,,,,,,,,,,,
225.826,0.13702,0.93603,10,,,,,,,,,,,,,,,,,,,,,,,,,,,,,,,,,,,,,
226.426,0.13696,0.93103,10,,,,,,,,,,,,,,,,,,,,,,,,,,,,,,,,,,,,,
227.026,0.13685,0.86309,10,,,,,,,,,,,,,,,,,,,,,,,,,,,,,,,,,,,,,
227.626,0.13685,0.88038,10,,,,,,,,,,,,,,,,,,,,,,,,,,,,,,,,,,,,,
228.226,0.13679,0.91916,10,,,,,,,,,,,,,,,,,,,,,,,,,,,,,,,,,,,,,
228.826,0.13674,0.91526,10,,,,,,,,,,,,,,,,,,,,,,,,,,,,,,,,,,,,,
229.426,0.13657,0.8943,10,,,,,,,,,,,,,,,,,,,,,,,,,,,,,,,,,,,,,
230.026,0.13645,0.84722,10,,,,,,,,,,,,,,,,,,,,,,,,,,,,,,,,,,,,,
230.626,0.13628,0.85982,10,,,,,,,,,,,,,,,,,,,,,,,,,,,,,,,,,,,,,
231.226,0.13623,0.86505,10,,,,,,,,,,,,,,,,,,,,,,,,,,,,,,,,,,,,,
231.826,0.13623,0.82237,10,,,,,,,,,,,,,,,,,,,,,,,,,,,,,,,,,,,,,
232.426,0.13634,0.86024,10,,,,,,,,,,,,,,,,,,,,,,,,,,,,,,,,,,,,,
233.026,0.13634,0.85476,10,,,,,,,,,,,,,,,,,,,,,,,,,,,,,,,,,,,,,
233.626,0.1364,0.8318,10,,,,,,,,,,,,,,,,,,,,,,,,,,,,,,,,,,,,,
234.226,0.1364,0.86013,10,,,,,,,,,,,,,,,,,,,,,,,,,,,,,,,,,,,,,
234.826,0.13645,0.85198,10,,,,,,,,,,,,,,,,,,,,,,,,,,,,,,,,,,,,,
235.426,0.13645,0.87916,10,,,,,,,,,,,,,,,,,,,,,,,,,,,,,,,,,,,,,
236.026,0.13651,0.85923,10,,,,,,,,,,,,,,,,,,,,,,,,,,,,,,,,,,,,,
236.626,0.13651,0.88924,10,,,,,,,,,,,,,,,,,,,,,,,,,,,,,,,,,,,,,
237.226,0.13651,0.84549,10,,,,,,,,,,,,,,,,,,,,,,,,,,,,,,,,,,,,,
237.826,0.13651,0.89016,10,,,,,,,,,,,,,,,,,,,,,,,,,,,,,,,,,,,,,
238.426,0.1364,0.89348,10,,,,,,,,,,,,,,,,,,,,,,,,,,,,,,,,,,,,,
239.026,0.13645,0.88096,10,,,,,,,,,,,,,,,,,,,,,,,,,,,,,,,,,,,,,
239.626,0.13645,0.85708,10,,,,,,,,,,,,,,,,,,,,,,,,,,,,,,,,,,,,,
240.226,0.13645,0.88618,10,,,,,,,,,,,,,,,,,,,,,,,,,,,,,,,,,,,,,
240.826,0.1364,0.89233,10,,,,,,,,,,,,,,,,,,,,,,,,,,,,,,,,,,,,,
241.426,0.13628,0.93918,10,,,,,,,,,,,,,,,,,,,,,,,,,,,,,,,,,,,,,
242.026,0.13623,0.92488,10,,,,,,,,,,,,,,,,,,,,,,,,,,,,,,,,,,,,,
242.626,0.13611,0.88746,10,,,,,,,,,,,,,,,,,,,,,,,,,,,,,,,,,,,,,
243.226,0.136,0.91042,10,,,,,,,,,,,,,,,,,,,,,,,,,,,,,,,,,,,,,
243.826,0.13577,0.88707,10,,,,,,,,,,,,,,,,,,,,,,,,,,,,,,,,,,,,,
244.426,0.1356,0.85672,10,,,,,,,,,,,,,,,,,,,,,,,,,,,,,,,,,,,,,
245.026,0.13555,0.82938,10,,,,,,,,,,,,,,,,,,,,,,,,,,,,,,,,,,,,,
245.626,0.1356,0.8128,10,,,,,,,,,,,,,,,,,,,,,,,,,,,,,,,,,,,,,
246.226,0.1356,0.8664,10,,,,,,,,,,,,,,,,,,,,,,,,,,,,,,,,,,,,,
246.826,0.13566,0.85387,10,,,,,,,,,,,,,,,,,,,,,,,,,,,,,,,,,,,,,
247.426,0.13566,0.8555,10,,,,,,,,,,,,,,,,,,,,,,,,,,,,,,,,,,,,,
248.026,0.13572,0.83491,10,,,,,,,,,,,,,,,,,,,,,,,,,,,,,,,,,,,,,
248.626,0.13577,0.83642,10,,,,,,,,,,,,,,,,,,,,,,,,,,,,,,,,,,,,,
249.226,0.13577,0.86836,10,,,,,,,,,,,,,,,,,,,,,,,,,,,,,,,,,,,,,
249.826,0.13583,0.89005,10,,,,,,,,,,,,,,,,,,,,,,,,,,,,,,,,,,,,,
250.426,0.13583,0.8733,10,,,,,,,,,,,,,,,,,,,,,,,,,,,,,,,,,,,,,
251.026,0.13583,0.90076,10,,,,,,,,,,,,,,,,,,,,,,,,,,,,,,,,,,,,,
251.626,0.13589,0.90242,10,,,,,,,,,,,,,,,,,,,,,,,,,,,,,,,,,,,,,
252.226,0.13577,0.89867,10,,,,,,,,,,,,,,,,,,,,,,,,,,,,,,,,,,,,,
252.826,0.13577,0.91199,10,,,,,,,,,,,,,,,,,,,,,,,,,,,,,,,,,,,,,
253.426,0.13583,0.92042,10,,,,,,,,,,,,,,,,,,,,,,,,,,,,,,,,,,,,,
254.026,0.13572,0.94497,10,,,,,,,,,,,,,,,,,,,,,,,,,,,,,,,,,,,,,
254.626,0.13577,0.85811,10,,,,,,,,,,,,,,,,,,,,,,,,,,,,,,,,,,,,,
255.226,0.13566,0.8766,10,,,,,,,,,,,,,,,,,,,,,,,,,,,,,,,,,,,,,
255.826,0.1356,0.9178,10,,,,,,,,,,,,,,,,,,,,,,,,,,,,,,,,,,,,,
256.426,0.13566,0.91845,10,,,,,,,,,,,,,,,,,,,,,,,,,,,,,,,,,,,,,
257.026,0.1356,0.92348,10,,,,,,,,,,,,,,,,,,,,,,,,,,,,,,,,,,,,,
257.626,0.13549,0.84411,10,,,,,,,,,,,,,,,,,,,,,,,,,,,,,,,,,,,,,
258.226,0.13532,0.90611,10,,,,,,,,,,,,,,,,,,,,,,,,,,,,,,,,,,,,,
258.826,0.13521,0.89085,10,,,,,,,,,,,,,,,,,,,,,,,,,,,,,,,,,,,,,
259.426,0.13509,0.88949,10,,,,,,,,,,,,,,,,,,,,,,,,,,,,,,,,,,,,,
260.026,0.13504,0.87171,10,,,,,,,,,,,,,,,,,,,,,,,,,,,,,,,,,,,,,
260.626,0.13504,0.82041,10,,,,,,,,,,,,,,,,,,,,,,,,,,,,,,,,,,,,,
261.226,0.13504,0.83637,10,,,,,,,,,,,,,,,,,,,,,,,,,,,,,,,,,,,,,
261.826,0.13504,0.86309,10,,,,,,,,,,,,,,,,,,,,,,,,,,,,,,,,,,,,,
262.426,0.13504,0.90568,10,,,,,,,,,,,,,,,,,,,,,,,,,,,,,,,,,,,,,
263.026,0.13504,0.8661,10,,,,,,,,,,,,,,,,,,,,,,,,,,,,,,,,,,,,,
263.626,0.13504,0.87056,10,,,,,,,,,,,,,,,,,,,,,,,,,,,,,,,,,,,,,
264.226,0.13504,0.82417,10,,,,,,,,,,,,,,,,,,,,,,,,,,,,,,,,,,,,,
264.826,0.13504,0.89303,10,,,,,,,,,,,,,,,,,,,,,,,,,,,,,,,,,,,,,
265.426,0.13509,0.90111,10,,,,,,,,,,,,,,,,,,,,,,,,,,,,,,,,,,,,,
266.026,0.13509,0.91469,10,,,,,,,,,,,,,,,,,,,,,,,,,,,,,,,,,,,,,
266.626,0.13509,0.88213,10,,,,,,,,,,,,,,,,,,,,,,,,,,,,,,,,,,,,,
267.226,0.13509,0.85502,10,,,,,,,,,,,,,,,,,,,,,,,,,,,,,,,,,,,,,
267.826,0.13509,0.847,10,,,,,,,,,,,,,,,,,,,,,,,,,,,,,,,,,,,,,
268.426,0.13509,0.86443,10,,,,,,,,,,,,,,,,,,,,,,,,,,,,,,,,,,,,,
269.026,0.13509,0.87678,10,,,,,,,,,,,,,,,,,,,,,,,,,,,,,,,,,,,,,
269.626,0.13498,0.88094,10,,,,,,,,,,,,,,,,,,,,,,,,,,,,,,,,,,,,,
270.226,0.13498,0.8889,10,,,,,,,,,,,,,,,,,,,,,,,,,,,,,,,,,,,,,
270.826,0.13492,0.88026,10,,,,,,,,,,,,,,,,,,,,,,,,,,,,,,,,,,,,,
271.426,0.13487,0.9475,10,,,,,,,,,,,,,,,,,,,,,,,,,,,,,,,,,,,,,
272.026,0.13458,0.92336,10,,,,,,,,,,,,,,,,,,,,,,,,,,,,,,,,,,,,,
272.626,0.13441,0.86125,10,,,,,,,,,,,,,,,,,,,,,,,,,,,,,,,,,,,,,
273.226,0.13441,0.85868,10,,,,,,,,,,,,,,,,,,,,,,,,,,,,,,,,,,,,,
273.826,0.13441,0.8312,10,,,,,,,,,,,,,,,,,,,,,,,,,,,,,,,,,,,,,
274.426,0.13453,0.85086,10,,,,,,,,,,,,,,,,,,,,,,,,,,,,,,,,,,,,,
275.026,0.13458,0.88941,10,,,,,,,,,,,,,,,,,,,,,,,,,,,,,,,,,,,,,
275.626,0.13458,0.81728,10,,,,,,,,,,,,,,,,,,,,,,,,,,,,,,,,,,,,,
276.226,0.13464,0.8626,10,,,,,,,,,,,,,,,,,,,,,,,,,,,,,,,,,,,,,
276.826,0.13464,0.84577,10,,,,,,,,,,,,,,,,,,,,,,,,,,,,,,,,,,,,,
277.426,0.13464,0.87821,10,,,,,,,,,,,,,,,,,,,,,,,,,,,,,,,,,,,,,
278.026,0.13475,0.90255,10,,,,,,,,,,,,,,,,,,,,,,,,,,,,,,,,,,,,,
278.626,0.13475,0.85353,10,,,,,,,,,,,,,,,,,,,,,,,,,,,,,,,,,,,,,
279.226,0.13475,0.84113,10,,,,,,,,,,,,,,,,,,,,,,,,,,,,,,,,,,,,,
279.826,0.13481,0.86697,10,,,,,,,,,,,,,,,,,,,,,,,,,,,,,,,,,,,,,
280.426,0.13487,0.8758,10,,,,,,,,,,,,,,,,,,,,,,,,,,,,,,,,,,,,,
281.026,0.13487,0.9519,10,,,,,,,,,,,,,,,,,,,,,,,,,,,,,,,,,,,,,
281.626,0.13487,0.88061,10,,,,,,,,,,,,,,,,,,,,,,,,,,,,,,,,,,,,,
282.226,0.13481,0.8458,10,,,,,,,,,,,,,,,,,,,,,,,,,,,,,,,,,,,,,
282.826,0.13481,0.89624,10,,,,,,,,,,,,,,,,,,,,,,,,,,,,,,,,,,,,,
283.426,0.13481,0.94949,10,,,,,,,,,,,,,,,,,,,,,,,,,,,,,,,,,,,,,
284.026,0.13475,0.9633,10,,,,,,,,,,,,,,,,,,,,,,,,,,,,,,,,,,,,,
284.626,0.13475,0.83264,10,,,,,,,,,,,,,,,,,,,,,,,,,,,,,,,,,,,,,
285.226,0.13475,0.89583,10,,,,,,,,,,,,,,,,,,,,,,,,,,,,,,,,,,,,,
285.826,0.1347,0.89292,10,,,,,,,,,,,,,,,,,,,,,,,,,,,,,,,,,,,,,
286.426,0.13464,0.93005,10,,,,,,,,,,,,,,,,,,,,,,,,,,,,,,,,,,,,,
287.026,0.13464,0.8984,10,,,,,,,,,,,,,,,,,,,,,,,,,,,,,,,,,,,,,
287.626,0.13453,0.89586,10,,,,,,,,,,,,,,,,,,,,,,,,,,,,,,,,,,,,,
288.226,0.13441,0.95646,10,,,,,,,,,,,,,,,,,,,,,,,,,,,,,,,,,,,,,
288.826,0.1343,0.90493,10,,,,,,,,,,,,,,,,,,,,,,,,,,,,,,,,,,,,,
289.426,0.13407,0.92335,10,,,,,,,,,,,,,,,,,,,,,,,,,,,,,,,,,,,,,
290.026,0.13396,0.88374,10,,,,,,,,,,,,,,,,,,,,,,,,,,,,,,,,,,,,,
290.626,0.13385,0.82301,10,,,,,,,,,,,,,,,,,,,,,,,,,,,,,,,,,,,,,
291.226,0.13396,0.83882,10,,,,,,,,,,,,,,,,,,,,,,,,,,,,,,,,,,,,,
291.826,0.13396,0.79486,10,,,,,,,,,,,,,,,,,,,,,,,,,,,,,,,,,,,,,
292.426,0.13396,0.85362,10,,,,,,,,,,,,,,,,,,,,,,,,,,,,,,,,,,,,,
293.026,0.13396,0.87635,10,,,,,,,,,,,,,,,,,,,,,,,,,,,,,,,,,,,,,
293.626,0.13396,0.87935,10,,,,,,,,,,,,,,,,,,,,,,,,,,,,,,,,,,,,,
294.226,0.13396,0.85386,10,,,,,,,,,,,,,,,,,,,,,,,,,,,,,,,,,,,,,
294.826,0.13385,0.9049,10,,,,,,,,,,,,,,,,,,,,,,,,,,,,,,,,,,,,,
295.426,0.13396,0.9071,10,,,,,,,,,,,,,,,,,,,,,,,,,,,,,,,,,,,,,
296.026,0.13396,0.85888,10,,,,,,,,,,,,,,,,,,,,,,,,,,,,,,,,,,,,,
296.626,0.13396,0.90866,10,,,,,,,,,,,,,,,,,,,,,,,,,,,,,,,,,,,,,
297.226,0.13385,0.89058,10,,,,,,,,,,,,,,,,,,,,,,,,,,,,,,,,,,,,,
297.826,0.13385,0.8963,10,,,,,,,,,,,,,,,,,,,,,,,,,,,,,,,,,,,,,
298.426,0.13385,0.8604,10,,,,,,,,,,,,,,,,,,,,,,,,,,,,,,,,,,,,,
299.026,0.13385,0.86172,10,,,,,,,,,,,,,,,,,,,,,,,,,,,,,,,,,,,,,
299.626,0.13385,0.83852,10,,,,,,,,,,,,,,,,,,,,,,,,,,,,,,,,,,,,,
300.226,0.13385,0.87635,10,,,,,,,,,,,,,,,,,,,,,,,,,,,,,,,,,,,,,
300.826,0.13385,0.91361,10,,,,,,,,,,,,,,,,,,,,,,,,,,,,,,,,,,,,,
301.426,0.13385,0.91282,10,,,,,,,,,,,,,,,,,,,,,,,,,,,,,,,,,,,,,
302.026,0.13385,0.89416,10,,,,,,,,,,,,,,,,,,,,,,,,,,,,,,,,,,,,,
302.626,0.13385,0.82659,10,,,,,,,,,,,,,,,,,,,,,,,,,,,,,,,,,,,,,
303.226,0.1339,0.89986,10,,,,,,,,,,,,,,,,,,,,,,,,,,,,,,,,,,,,,
303.826,0.1339,0.8217,10,,,,,,,,,,,,,,,,,,,,,,,,,,,,,,,,,,,,,
304.426,0.13385,0.9217,10,,,,,,,,,,,,,,,,,,,,,,,,,,,,,,,,,,,,,
305.026,0.1339,0.85346,10,,,,,,,,,,,,,,,,,,,,,,,,,,,,,,,,,,,,,
305.626,0.1339,0.89585,10,,,,,,,,,,,,,,,,,,,,,,,,,,,,,,,,,,,,,
306.226,0.13379,0.90784,10,,,,,,,,,,,,,,,,,,,,,,,,,,,,,,,,,,,,,
306.826,0.13379,0.91176,10,,,,,,,,,,,,,,,,,,,,,,,,,,,,,,,,,,,,,
307.426,0.13373,0.92936,10,,,,,,,,,,,,,,,,,,,,,,,,,,,,,,,,,,,,,
308.026,0.13373,0.92992,10,,,,,,,,,,,,,,,,,,,,,,,,,,,,,,,,,,,,,
308.626,0.13368,0.84596,10,,,,,,,,,,,,,,,,,,,,,,,,,,,,,,,,,,,,,
309.226,0.13362,0.89317,10,,,,,,,,,,,,,,,,,,,,,,,,,,,,,,,,,,,,,
309.826,0.13356,0.8795,10,,,,,,,,,,,,,,,,,,,,,,,,,,,,,,,,,,,,,
310.426,0.13339,0.82728,10,,,,,,,,,,,,,,,,,,,,,,,,,,,,,,,,,,,,,
311.026,0.13322,0.82522,10,,,,,,,,,,,,,,,,,,,,,,,,,,,,,,,,,,,,,
311.626,0.13311,0.82691,10,,,,,,,,,,,,,,,,,,,,,,,,,,,,,,,,,,,,,
312.226,0.13305,0.86571,10,,,,,,,,,,,,,,,,,,,,,,,,,,,,,,,,,,,,,
312.826,0.13305,0.88214,10,,,,,,,,,,,,,,,,,,,,,,,,,,,,,,,,,,,,,
313.426,0.13305,0.87467,10,,,,,,,,,,,,,,,,,,,,,,,,,,,,,,,,,,,,,
314.026,0.13305,0.88906,10,,,,,,,,,,,,,,,,,,,,,,,,,,,,,,,,,,,,,
314.626,0.13311,0.85964,10,,,,,,,,,,,,,,,,,,,,,,,,,,,,,,,,,,,,,
315.226,0.13311,0.85532,10,,,,,,,,,,,,,,,,,,,,,,,,,,,,,,,,,,,,,
315.826,0.13311,0.83585,10,,,,,,,,,,,,,,,,,,,,,,,,,,,,,,,,,,,,,
316.426,0.13311,0.90213,10,,,,,,,,,,,,,,,,,,,,,,,,,,,,,,,,,,,,,
317.026,0.13311,0.87179,10,,,,,,,,,,,,,,,,,,,,,,,,,,,,,,,,,,,,,
317.626,0.13305,0.88067,10,,,,,,,,,,,,,,,,,,,,,,,,,,,,,,,,,,,,,
318.226,0.13317,0.86102,10,,,,,,,,,,,,,,,,,,,,,,,,,,,,,,,,,,,,,
318.826,0.13317,0.88833,10,,,,,,,,,,,,,,,,,,,,,,,,,,,,,,,,,,,,,
319.426,0.13317,0.88947,10,,,,,,,,,,,,,,,,,,,,,,,,,,,,,,,,,,,,,
320.026,0.13317,0.89575,10,,,,,,,,,,,,,,,,,,,,,,,,,,,,,,,,,,,,,
320.626,0.13305,0.90344,10,,,,,,,,,,,,,,,,,,,,,,,,,,,,,,,,,,,,,
321.226,0.13305,0.86932,10,,,,,,,,,,,,,,,,,,,,,,,,,,,,,,,,,,,,,
321.826,0.13305,0.90892,10,,,,,,,,,,,,,,,,,,,,,,,,,,,,,,,,,,,,,
322.426,0.13311,0.89919,10,,,,,,,,,,,,,,,,,,,,,,,,,,,,,,,,,,,,,
323.026,0.13311,0.87642,10,,,,,,,,,,,,,,,,,,,,,,,,,,,,,,,,,,,,,
323.626,0.13311,0.88788,10,,,,,,,,,,,,,,,,,,,,,,,,,,,,,,,,,,,,,
324.226,0.133,0.86163,10,,,,,,,,,,,,,,,,,,,,,,,,,,,,,,,,,,,,,
324.826,0.133,0.8669,10,,,,,,,,,,,,,,,,,,,,,,,,,,,,,,,,,,,,,
325.426,0.13305,0.9042,10,,,,,,,,,,,,,,,,,,,,,,,,,,,,,,,,,,,,,
326.026,0.13294,0.8213,10,,,,,,,,,,,,,,,,,,,,,,,,,,,,,,,,,,,,,
326.626,0.13294,0.89325,10,,,,,,,,,,,,,,,,,,,,,,,,,,,,,,,,,,,,,
327.226,0.13288,0.92036,10,,,,,,,,,,,,,,,,,,,,,,,,,,,,,,,,,,,,,
327.826,0.13283,0.84951,10,,,,,,,,,,,,,,,,,,,,,,,,,,,,,,,,,,,,,
328.426,0.13283,0.8708,10,,,,,,,,,,,,,,,,,,,,,,,,,,,,,,,,,,,,,
329.026,0.13283,0.87751,10,,,,,,,,,,,,,,,,,,,,,,,,,,,,,,,,,,,,,
329.626,0.13283,0.86906,10,,,,,,,,,,,,,,,,,,,,,,,,,,,,,,,,,,,,,
330.226,0.13283,0.8427,10,,,,,,,,,,,,,,,,,,,,,,,,,,,,,,,,,,,,,
330.826,0.13283,0.86332,10,,,,,,,,,,,,,,,,,,,,,,,,,,,,,,,,,,,,,
331.426,0.13283,0.92591,10,,,,,,,,,,,,,,,,,,,,,,,,,,,,,,,,,,,,,
332.026,0.13283,0.88005,10,,,,,,,,,,,,,,,,,,,,,,,,,,,,,,,,,,,,,
332.626,0.13283,0.86124,10,,,,,,,,,,,,,,,,,,,,,,,,,,,,,,,,,,,,,
333.226,0.13294,0.85912,10,,,,,,,,,,,,,,,,,,,,,,,,,,,,,,,,,,,,,
333.826,0.13283,0.86137,10,,,,,,,,,,,,,,,,,,,,,,,,,,,,,,,,,,,,,
334.426,0.13283,0.8596,10,,,,,,,,,,,,,,,,,,,,,,,,,,,,,,,,,,,,,
335.026,0.13283,0.84623,10,,,,,,,,,,,,,,,,,,,,,,,,,,,,,,,,,,,,,
335.626,0.13283,0.87678,10,,,,,,,,,,,,,,,,,,,,,,,,,,,,,,,,,,,,,
336.226,0.13283,0.8789,10,,,,,,,,,,,,,,,,,,,,,,,,,,,,,,,,,,,,,
336.826,0.13283,0.88891,10,,,,,,,,,,,,,,,,,,,,,,,,,,,,,,,,,,,,,
337.426,0.13283,0.9718,10,,,,,,,,,,,,,,,,,,,,,,,,,,,,,,,,,,,,,
338.026,0.13277,0.87233,10,,,,,,,,,,,,,,,,,,,,,,,,,,,,,,,,,,,,,
338.626,0.13277,0.92279,10,,,,,,,,,,,,,,,,,,,,,,,,,,,,,,,,,,,,,
339.226,0.13271,0.88498,10,,,,,,,,,,,,,,,,,,,,,,,,,,,,,,,,,,,,,
339.826,0.1326,0.89265,10,,,,,,,,,,,,,,,,,,,,,,,,,,,,,,,,,,,,,
340.426,0.13254,0.89652,10,,,,,,,,,,,,,,,,,,,,,,,,,,,,,,,,,,,,,
341.026,0.13254,0.82964,10,,,,,,,,,,,,,,,,,,,,,,,,,,,,,,,,,,,,,
341.626,0.13249,0.84078,10,,,,,,,,,,,,,,,,,,,,,,,,,,,,,,,,,,,,,
342.226,0.13249,0.85075,10,,,,,,,,,,,,,,,,,,,,,,,,,,,,,,,,,,,,,
342.826,0.13249,0.8406,10,,,,,,,,,,,,,,,,,,,,,,,,,,,,,,,,,,,,,
343.426,0.13249,0.88399,10,,,,,,,,,,,,,,,,,,,,,,,,,,,,,,,,,,,,,
344.026,0.13249,0.88182,10,,,,,,,,,,,,,,,,,,,,,,,,,,,,,,,,,,,,,
344.626,0.1326,0.84335,10,,,,,,,,,,,,,,,,,,,,,,,,,,,,,,,,,,,,,
345.226,0.1326,0.88357,10,,,,,,,,,,,,,,,,,,,,,,,,,,,,,,,,,,,,,
345.826,0.1326,0.88381,10,,,,,,,,,,,,,,,,,,,,,,,,,,,,,,,,,,,,,
346.426,0.1326,0.84932,10,,,,,,,,,,,,,,,,,,,,,,,,,,,,,,,,,,,,,
347.026,0.1326,0.89051,10,,,,,,,,,,,,,,,,,,,,,,,,,,,,,,,,,,,,,
347.626,0.1326,0.87715,10,,,,,,,,,,,,,,,,,,,,,,,,,,,,,,,,,,,,,
348.226,0.1326,0.88112,10,,,,,,,,,,,,,,,,,,,,,,,,,,,,,,,,,,,,,
348.826,0.1326,0.89049,10,,,,,,,,,,,,,,,,,,,,,,,,,,,,,,,,,,,,,
349.426,0.1326,0.9093,10,,,,,,,,,,,,,,,,,,,,,,,,,,,,,,,,,,,,,
350.026,0.1326,0.84279,10,,,,,,,,,,,,,,,,,,,,,,,,,,,,,,,,,,,,,
350.626,0.1326,0.88251,10,,,,,,,,,,,,,,,,,,,,,,,,,,,,,,,,,,,,,
351.226,0.1326,0.88284,10,,,,,,,,,,,,,,,,,,,,,,,,,,,,,,,,,,,,,
351.826,0.13249,0.91319,10,,,,,,,,,,,,,,,,,,,,,,,,,,,,,,,,,,,,,
352.426,0.13232,0.99034,10,,,,,,,,,,,,,,,,,,,,,,,,,,,,,,,,,,,,,
353.026,0.13152,0.95223,10,,,,,,,,,,,,,,,,,,,,,,,,,,,,,,,,,,,,,
353.626,0.13016,0.77284,10,,,,,,,,,,,,,,,,,,,,,,,,,,,,,,,,,,,,,
354.226,0.13011,0.74409,10,,,,,,,,,,,,,,,,,,,,,,,,,,,,,,,,,,,,,
354.826,0.13033,0.76325,10,,,,,,,,,,,,,,,,,,,,,,,,,,,,,,,,,,,,,
355.426,0.13045,0.81141,10,,,,,,,,,,,,,,,,,,,,,,,,,,,,,,,,,,,,,
356.026,0.13067,0.89884,10,,,,,,,,,,,,,,,,,,,,,,,,,,,,,,,,,,,,,
356.626,0.13079,0.83677,10,,,,,,,,,,,,,,,,,,,,,,,,,,,,,,,,,,,,,
357.226,0.13101,0.96699,10,,,,,,,,,,,,,,,,,,,,,,,,,,,,,,,,,,,,,
357.826,0.13101,0.87393,10,,,,,,,,,,,,,,,,,,,,,,,,,,,,,,,,,,,,,
358.426,0.13101,0.92838,10,,,,,,,,,,,,,,,,,,,,,,,,,,,,,,,,,,,,,
359.026,0.1309,0.87011,10,,,,,,,,,,,,,,,,,,,,,,,,,,,,,,,,,,,,,
359.626,0.13096,0.94686,10,,,,,,,,,,,,,,,,,,,,,,,,,,,,,,,,,,,,,
360.226,0.13073,0.99339,10,,,,,,,,,,,,,,,,,,,,,,,,,,,,,,,,,,,,,
360.826,0.1305,0.98004,10,,,,,,,,,,,,,,,,,,,,,,,,,,,,,,,,,,,,,
361.426,0.13016,1.00126,10,,,,,,,,,,,,,,,,,,,,,,,,,,,,,,,,,,,,,
362.026,0.12943,0.94829,10,,,,,,,,,,,,,,,,,,,,,,,,,,,,,,,,,,,,,
362.626,0.12829,0.80667,10,,,,,,,,,,,,,,,,,,,,,,,,,,,,,,,,,,,,,
363.226,0.12818,0.87283,10,,,,,,,,,,,,,,,,,,,,,,,,,,,,,,,,,,,,,
363.826,0.12835,0.81,10,,,,,,,,,,,,,,,,,,,,,,,,,,,,,,,,,,,,,
364.426,0.12835,0.85524,10,,,,,,,,,,,,,,,,,,,,,,,,,,,,,,,,,,,,,
365.026,0.12841,0.88306,10,,,,,,,,,,,,,,,,,,,,,,,,,,,,,,,,,,,,,
365.626,0.12852,0.79431,10,,,,,,,,,,,,,,,,,,,,,,,,,,,,,,,,,,,,,
366.226,0.12852,0.88196,10,,,,,,,,,,,,,,,,,,,,,,,,,,,,,,,,,,,,,
366.826,0.12858,0.89029,10,,,,,,,,,,,,,,,,,,,,,,,,,,,,,,,,,,,,,
367.426,0.12852,0.87904,10,,,,,,,,,,,,,,,,,,,,,,,,,,,,,,,,,,,,,
368.026,0.12863,0.90361,10,,,,,,,,,,,,,,,,,,,,,,,,,,,,,,,,,,,,,
368.626,0.12863,0.8736,10,,,,,,,,,,,,,,,,,,,,,,,,,,,,,,,,,,,,,
369.226,0.12852,0.94406,10,,,,,,,,,,,,,,,,,,,,,,,,,,,,,,,,,,,,,
369.826,0.12852,0.90775,10,,,,,,,,,,,,,,,,,,,,,,,,,,,,,,,,,,,,,
370.426,0.12846,0.90214,10,,,,,,,,,,,,,,,,,,,,,,,,,,,,,,,,,,,,,
371.026,0.12846,0.85165,10,,,,,,,,,,,,,,,,,,,,,,,,,,,,,,,,,,,,,
371.626,0.12846,0.89033,10,,,,,,,,,,,,,,,,,,,,,,,,,,,,,,,,,,,,,
372.226,0.12852,0.97003,10,,,,,,,,,,,,,,,,,,,,,,,,,,,,,,,,,,,,,
372.826,0.12852,0.85564,10,,,,,,,,,,,,,,,,,,,,,,,,,,,,,,,,,,,,,
373.426,0.12852,0.88006,10,,,,,,,,,,,,,,,,,,,,,,,,,,,,,,,,,,,,,
374.026,0.12841,0.89444,10,,,,,,,,,,,,,,,,,,,,,,,,,,,,,,,,,,,,,
374.626,0.12841,0.9065,10,,,,,,,,,,,,,,,,,,,,,,,,,,,,,,,,,,,,,
375.226,0.12841,0.93932,10,,,,,,,,,,,,,,,,,,,,,,,,,,,,,,,,,,,,,
375.826,0.12841,0.86404,10,,,,,,,,,,,,,,,,,,,,,,,,,,,,,,,,,,,,,
376.426,0.12841,0.89982,10,,,,,,,,,,,,,,,,,,,,,,,,,,,,,,,,,,,,,
377.026,0.12841,0.87138,10,,,,,,,,,,,,,,,,,,,,,,,,,,,,,,,,,,,,,
377.626,0.12835,0.86997,10,,,,,,,,,,,,,,,,,,,,,,,,,,,,,,,,,,,,,
378.128,3.22819,159.30412,10,,,,,,,,,,,,,,,,,,,,,,,,,,,,,,,,,,,,,
378.728,8.22823,429.95688,10,,,,,,,,,,,,,,,,,,,,,,,,,,,,,,,,,,,,,
379.328,13.22844,472.27039,10,,,,,,,,,,,,,,,,,,,,,,,,,,,,,,,,,,,,,
379.928,18.22831,4.91103,10,,,,,,,,,,,,,,,,,,,,,,,,,,,,,,,,,,,,,
380.528,23.22834,-10.33689,10,,,,,,,,,,,,,,,,,,,,,,,,,,,,,,,,,,,,,
381.128,28.22827,-18.46384,10,,,,,,,,,,,,,,,,,,,,,,,,,,,,,,,,,,,,,
381.728,33.22831,-18.95072,10,,,,,,,,,,,,,,,,,,,,,,,,,,,,,,,,,,,,,
382.328,38.22829,-19.31141,10,,,,,,,,,,,,,,,,,,,,,,,,,,,,,,,,,,,,,
382.928,43.22828,-19.26786,10,,,,,,,,,,,,,,,,,,,,,,,,,,,,,,,,,,,,,
383.528,48.22832,-20.00316,10,,,,,,,,,,,,,,,,,,,,,,,,,,,,,,,,,,,,,
384.128,53.22836,-20.19972,10,,,,,,,,,,,,,,,,,,,,,,,,,,,,,,,,,,,,,
384.728,58.22828,-20.22417,10,,,,,,,,,,,,,,,,,,,,,,,,,,,,,,,,,,,,,
385.328,63.22837,-20.27076,10,,,,,,,,,,,,,,,,,,,,,,,,,,,,,,,,,,,,,
385.928,68.2283,-20.23677,10,,,,,,,,,,,,,,,,,,,,,,,,,,,,,,,,,,,,,
385.962,68.51158,-20.25159,10,,,,,,,,,,,,,,,,,,,,,,,,,,,,,,,,,,,,,