File: combined_ligament_solver/data/processed/Data Sheet 3_S151568_PCL.csv
Specimen properties : Length,44,mm,Unnamed: 3,Unnamed: 4,Unnamed: 5,Unnamed: 6,Unnamed: 7,Unnamed: 8,Unnamed: 9,Unnamed: 10,Unnamed: 11,Stress-Strain,Unnamed: 13,Unnamed: 14,Unnamed: 15,Unnamed: 16,Unnamed: 17,Unnamed: 18,Unnamed: 19,Unnamed: 20,Unnamed: 21,Unnamed: 22,Unnamed: 23,Unnamed: 24,Unnamed: 25,Unnamed: 26,Unnamed: 27,Linear,Unnamed: 29,Unnamed: 30,Unnamed: 31,Unnamed: 32,Unnamed: 33,Modulus,Unnamed: 35,Failure,Unnamed: 37,Unnamed: 38,Unnamed: 39,Unnamed: 40
Cross Section Average,84.7915,mm2,,,,,,,,,,Polynomial Coefficients,,,,,,,,,,,,,,,,Force,,Stress,Extension,Strain,,Secant,Tangent,Load,Stress,Extension,Strain,Stiffness
Time,Extension,Load,Total cycle count,,,Extension,Load,Strain,Stress,E-tan,,X6,-3109574.9263338232,,,,,,,,,Strain,Stress,E-tan,,,,(N),,(MPa),(mm),(%),,(MPa),(MPa),(N),(MPa),(mm),(%),(N/mm)
(s),(mm),(N),,,,(mm),(N),(mm/mm),(MPa),(MPa),,X5,1087173.3349838906,,,,,,,,,(mm/mm),(MPa),(MPa),,,,630.720793651389,,7.438490811595373,4.928,11.200000000000001,,66.41509653210153,124.91768827797932,923.90033,10.887188928135487,6.39999,14.545431818181816,127.98717403640198
0.6,0.21919,1.99302,0,,,5.12782,586.19373,0.10757249999999999,6.904400559018298,118.70764051595738,,,,,,,,,,,,0.006,0.021810814750707112,4.631898158537317,,,,,,,,,,,,,,,,
1.3,0.33598,3.52632,0,,,10.96143,820.91565,,,,,,,,,,,,,,,0.013,0.07324400293271588,9.76926395285458,,,,,,,,,,,,,,,,
2,0.45265,5.15449,0,,,16.79469,674.3714,,,,,,,,,,,,,,,0.02,0.1700490697772662,17.12907524313643,,,,,,,,,,,,,,,,
2.7,0.56927,7.12651,0,,,22.62802,137.40901,,,,,,,,,,,,,,,0.027,0.3244739741998527,25.916503144805453,,,,,,,,,,,,,,,,
3.4,0.68589,9.25353,0,,,,,,,,,,,,,,,,,,,0.034,0.5440580252058995,35.54513125941047,,,,,,,,,,,,,,,,
4.1,0.80257,11.66633,0,,,,,,,,,,,,,,,,,,,0.041,0.8329402529313742,45.59932658405914,,,,,,,,,,,,,,,,
4.8,0.91936,14.71792,0,,,,,,,,,,,,,,,,,,,0.048,1.1929043760494367,55.79661042085243,,,,,,,,,,,,,,,,
5.5,1.03609,18.20875,0,,,,,,,,,,,,,,,,,,,0.055,1.6241603655431223,65.95002928631615,,,,,,,,,,,,,,,,
6.2,1.15288,21.89894,0,,,,,,,,,,,,,,,,,,,0.062,2.1258626048440594,75.93052582083796,,,,,,,,,,,,,,,,
6.9,1.26939,25.76021,0,,,,,,,,,,,,,,,,,,,0.069,2.696364646337218,85.62930969809504,,,,,,,,,,,,,,,,
7.6,1.38601,30.13749,0,,,,,,,,,,,,,,,,,,,0.076,3.333210564231697,94.92022853449669,,,,,,,,,,,,,,,,
8.3,1.50269,35.89278,0,,,,,,,,,,,,,,,,,,,0.083,4.032862903797545,103.62213879860683,,,,,,,,,,,,,,,,
8.854,1.56649,39.81423,0.5,,,,,,,,,,,,,,,,,,,0.09,4.790167226968605,111.46127672058437,,,,,,,,,,,,,,,,
9.554,1.44511,30.48693,0.5,,,,,,,,,,,,,,,,,,,0.097,5.597553254311409,118.03362920161209,,,,,,,,,,,,,,,,
10.254,1.32844,23.86788,0.5,,,,,,,,,,,,,,,,,,,0.104,6.443972603360107,122.76730472334563,,,,,,,,,,,,,,,,
10.954,1.21176,18.99983,0.5,,,,,,,,,,,,,,,,,,,0.111,7.3135731233173935,124.88490425731312,,,,,,,,,,,,,,,,
11.654,1.09508,15.38845,0.5,,,,,,,,,,,,,,,,,,,0.118,8.18410982612154,123.36589217438551,,,,,,,,,,,,,,,,
12.354,0.97835,11.96847,0.5,,,,,,,,,,,,,,,,,,,0.125,9.025092413879381,116.90896715418997,,,,,,,,,,,,,,,,
13.054,0.86162,8.8819,0.5,,,,,,,,,,,,,,,,,,,0.132,9.79566940266539,103.89443309456315,,,,,,,,,,,,,,,,
13.754,0.74494,6.65559,0.5,,,,,,,,,,,,,,,,,,,0.139,10.442248842686755,82.34657002093284,,,,,,,,,,,,,,,,
14.454,0.62832,4.68878,0.5,,,,,,,,,,,,,,,,,,,0.146,10.895855634814529,49.89600499579434,,,,,,,,,,,,,,,,
15.154,0.51159,3.02582,0.5,,,,,,,,,,,,,,,,,,,0.153,,,,,,,,,,,,,,,,,,
15.854,0.39485,1.61819,0.5,,,,,,,,,,,,,,,,,,,0.16,,,,,,,,,,,,,,,,,,
16.33,0.34453,0.96081,1,,,,,,,,,,,,,,,,,,,0.167,,,,,,,,,,,,,,,,,,
17.03,0.46637,2.71281,1,,,,,,,,,,,,,,,,,,,0.174,,,,,,,,,,,,,,,,,,
17.73,0.58304,4.64853,1,,,,,,,,,,,,,,,,,,,0.181,,,,,,,,,,,,,,,,,,
18.43,0.69978,7.01567,1,,,,,,,,,,,,,,,,,,,0.188,,,,,,,,,,,,,,,,,,
19.13,0.81645,9.33877,1,,,,,,,,,,,,,,,,,,,0.195,,,,,,,,,,,,,,,,,,
19.83,0.93302,12.23656,1,,,,,,,,,,,,,,,,,,,,,,,,,,,,,,,,,,,,,
20.53,1.04964,15.54275,1,,,,,,,,,,,,,,,,,,,,,,,,,,,,,,,,,,,,,
21.23,1.16631,19.81938,1,,,,,,,,,,,,,,,,,,,,,,,,,,,,,,,,,,,,,
21.93,1.28299,23.6293,1,,,,,,,,,,,,,,,,,,,,,,,,,,,,,,,,,,,,,
22.63,1.39967,28.39645,1,,,,,,,,,,,,,,,,,,,,,,,,,,,,,,,,,,,,,
23.33,1.51629,34.48133,1,,,,,,,,,,,,,,,,,,,,,,,,,,,,,,,,,,,,,
23.88,1.60814,40.02747,1.5,,,,,,,,,,,,,,,,,,,,,,,,,,,,,,,,,,,,,
24.58,1.49141,31.7735,1.5,,,,,,,,,,,,,,,,,,,,,,,,,,,,,,,,,,,,,
25.28,1.37479,24.87928,1.5,,,,,,,,,,,,,,,,,,,,,,,,,,,,,,,,,,,,,
25.98,1.258,19.68669,1.5,,,,,,,,,,,,,,,,,,,,,,,,,,,,,,,,,,,,,
26.68,1.14121,15.97799,1.5,,,,,,,,,,,,,,,,,,,,,,,,,,,,,,,,,,,,,
27.38,1.02459,12.37417,1.5,,,,,,,,,,,,,,,,,,,,,,,,,,,,,,,,,,,,,
28.08,0.90791,9.23729,1.5,,,,,,,,,,,,,,,,,,,,,,,,,,,,,,,,,,,,,
28.78,0.79129,6.9283,1.5,,,,,,,,,,,,,,,,,,,,,,,,,,,,,,,,,,,,,
29.48,0.67456,4.88187,1.5,,,,,,,,,,,,,,,,,,,,,,,,,,,,,,,,,,,,,
30.18,0.55794,3.17062,1.5,,,,,,,,,,,,,,,,,,,,,,,,,,,,,,,,,,,,,
30.88,0.44138,1.67797,1.5,,,,,,,,,,,,,,,,,,,,,,,,,,,,,,,,,,,,,
31.312,0.36941,0.98426,2,,,,,,,,,,,,,,,,,,,,,,,,,,,,,,,,,,,,,
32.012,0.48665,2.44352,2,,,,,,,,,,,,,,,,,,,,,,,,,,,,,,,,,,,,,
32.712,0.60333,4.36197,2,,,,,,,,,,,,,,,,,,,,,,,,,,,,,,,,,,,,,
33.412,0.72001,6.66844,2,,,,,,,,,,,,,,,,,,,,,,,,,,,,,,,,,,,,,
34.112,0.83657,9.0615,2,,,,,,,,,,,,,,,,,,,,,,,,,,,,,,,,,,,,,
34.812,0.95325,11.9537,2,,,,,,,,,,,,,,,,,,,,,,,,,,,,,,,,,,,,,
35.512,1.06992,15.42251,2,,,,,,,,,,,,,,,,,,,,,,,,,,,,,,,,,,,,,
36.212,1.18666,19.80253,2,,,,,,,,,,,,,,,,,,,,,,,,,,,,,,,,,,,,,
36.912,1.30322,23.69934,2,,,,,,,,,,,,,,,,,,,,,,,,,,,,,,,,,,,,,
37.612,1.41995,28.33679,2,,,,,,,,,,,,,,,,,,,,,,,,,,,,,,,,,,,,,
38.312,1.53657,34.57969,2,,,,,,,,,,,,,,,,,,,,,,,,,,,,,,,,,,,,,
38.838,1.62429,40.0351,2.5,,,,,,,,,,,,,,,,,,,,,,,,,,,,,,,,,,,,,
39.538,1.50773,31.7817,2.5,,,,,,,,,,,,,,,,,,,,,,,,,,,,,,,,,,,,,
40.238,1.39105,24.84541,2.5,,,,,,,,,,,,,,,,,,,,,,,,,,,,,,,,,,,,,
40.938,1.27443,19.65466,2.5,,,,,,,,,,,,,,,,,,,,,,,,,,,,,,,,,,,,,
41.638,1.1577,15.97291,2.5,,,,,,,,,,,,,,,,,,,,,,,,,,,,,,,,,,,,,
42.338,1.04102,12.33582,2.5,,,,,,,,,,,,,,,,,,,,,,,,,,,,,,,,,,,,,
43.038,0.9244,9.18741,2.5,,,,,,,,,,,,,,,,,,,,,,,,,,,,,,,,,,,,,
43.738,0.80767,6.87609,2.5,,,,,,,,,,,,,,,,,,,,,,,,,,,,,,,,,,,,,
44.438,0.69099,4.83359,2.5,,,,,,,,,,,,,,,,,,,,,,,,,,,,,,,,,,,,,
45.138,0.57432,3.09771,2.5,,,,,,,,,,,,,,,,,,,,,,,,,,,,,,,,,,,,,
45.838,0.45758,1.57532,2.5,,,,,,,,,,,,,,,,,,,,,,,,,,,,,,,,,,,,,
46.342,0.4025,0.92564,3,,,,,,,,,,,,,,,,,,,,,,,,,,,,,,,,,,,,,
47.042,0.52439,2.66986,3,,,,,,,,,,,,,,,,,,,,,,,,,,,,,,,,,,,,,
47.742,0.64101,4.72182,3,,,,,,,,,,,,,,,,,,,,,,,,,,,,,,,,,,,,,
48.442,0.75775,7.0927,3,,,,,,,,,,,,,,,,,,,,,,,,,,,,,,,,,,,,,
49.142,0.87442,9.41956,3,,,,,,,,,,,,,,,,,,,,,,,,,,,,,,,,,,,,,
49.842,0.9911,12.50325,3,,,,,,,,,,,,,,,,,,,,,,,,,,,,,,,,,,,,,
50.542,1.10761,16.08692,3,,,,,,,,,,,,,,,,,,,,,,,,,,,,,,,,,,,,,
51.242,1.22428,20.6172,3,,,,,,,,,,,,,,,,,,,,,,,,,,,,,,,,,,,,,
51.942,1.34096,24.44122,3,,,,,,,,,,,,,,,,,,,,,,,,,,,,,,,,,,,,,
52.642,1.45764,29.46148,3,,,,,,,,,,,,,,,,,,,,,,,,,,,,,,,,,,,,,
53.342,1.57431,36.08543,3,,,,,,,,,,,,,,,,,,,,,,,,,,,,,,,,,,,,,
53.914,1.60361,38.03015,3.5,,,,,,,,,,,,,,,,,,,,,,,,,,,,,,,,,,,,,
54.614,1.48642,29.68199,3.5,,,,,,,,,,,,,,,,,,,,,,,,,,,,,,,,,,,,,
55.314,1.36963,23.25019,3.5,,,,,,,,,,,,,,,,,,,,,,,,,,,,,,,,,,,,,
56.014,1.25301,18.38937,3.5,,,,,,,,,,,,,,,,,,,,,,,,,,,,,,,,,,,,,
56.714,1.13622,14.89539,3.5,,,,,,,,,,,,,,,,,,,,,,,,,,,,,,,,,,,,,
57.414,1.0196,11.38525,3.5,,,,,,,,,,,,,,,,,,,,,,,,,,,,,,,,,,,,,
58.114,0.90287,8.42865,3.5,,,,,,,,,,,,,,,,,,,,,,,,,,,,,,,,,,,,,
58.814,0.78631,6.17869,3.5,,,,,,,,,,,,,,,,,,,,,,,,,,,,,,,,,,,,,
59.514,0.66969,4.25396,3.5,,,,,,,,,,,,,,,,,,,,,,,,,,,,,,,,,,,,,
60.214,0.55307,2.54206,3.5,,,,,,,,,,,,,,,,,,,,,,,,,,,,,,,,,,,,,
60.914,0.43639,1.2183,3.5,,,,,,,,,,,,,,,,,,,,,,,,,,,,,,,,,,,,,
61.34,0.46597,1.57319,4,,,,,,,,,,,,,,,,,,,,,,,,,,,,,,,,,,,,,
62.04,0.58276,3.30882,4,,,,,,,,,,,,,,,,,,,,,,,,,,,,,,,,,,,,,
62.74,0.69949,5.47683,4,,,,,,,,,,,,,,,,,,,,,,,,,,,,,,,,,,,,,
63.44,0.81606,7.98612,4,,,,,,,,,,,,,,,,,,,,,,,,,,,,,,,,,,,,,
64.14,0.93268,10.50285,4,,,,,,,,,,,,,,,,,,,,,,,,,,,,,,,,,,,,,
64.84,1.04935,13.84668,4,,,,,,,,,,,,,,,,,,,,,,,,,,,,,,,,,,,,,
65.54,1.16603,17.72437,4,,,,,,,,,,,,,,,,,,,,,,,,,,,,,,,,,,,,,
66.24,1.28271,22.30574,4,,,,,,,,,,,,,,,,,,,,,,,,,,,,,,,,,,,,,
66.94,1.39938,26.42771,4,,,,,,,,,,,,,,,,,,,,,,,,,,,,,,,,,,,,,
67.64,1.51595,32.04604,4,,,,,,,,,,,,,,,,,,,,,,,,,,,,,,,,,,,,,
68.34,1.63257,39.25426,4,,,,,,,,,,,,,,,,,,,,,,,,,,,,,,,,,,,,,
68.912,1.56139,34.12454,4.5,,,,,,,,,,,,,,,,,,,,,,,,,,,,,,,,,,,,,
69.612,1.44472,26.65587,4.5,,,,,,,,,,,,,,,,,,,,,,,,,,,,,,,,,,,,,
70.312,1.3281,20.88014,4.5,,,,,,,,,,,,,,,,,,,,,,,,,,,,,,,,,,,,,
71.012,1.21142,16.94566,4.5,,,,,,,,,,,,,,,,,,,,,,,,,,,,,,,,,,,,,
71.712,1.09474,13.2573,4.5,,,,,,,,,,,,,,,,,,,,,,,,,,,,,,,,,,,,,
72.412,0.97801,9.92965,4.5,,,,,,,,,,,,,,,,,,,,,,,,,,,,,,,,,,,,,
73.112,0.86133,7.42105,4.5,,,,,,,,,,,,,,,,,,,,,,,,,,,,,,,,,,,,,
73.812,0.74466,5.25896,4.5,,,,,,,,,,,,,,,,,,,,,,,,,,,,,,,,,,,,,
74.512,0.62798,3.42805,4.5,,,,,,,,,,,,,,,,,,,,,,,,,,,,,,,,,,,,,
75.212,0.51125,1.85983,4.5,,,,,,,,,,,,,,,,,,,,,,,,,,,,,,,,,,,,,
75.71,0.42834,0.98208,5,,,,,,,,,,,,,,,,,,,,,,,,,,,,,,,,,,,,,
76.41,0.54559,2.52664,5,,,,,,,,,,,,,,,,,,,,,,,,,,,,,,,,,,,,,
77.11,0.66226,4.4986,5,,,,,,,,,,,,,,,,,,,,,,,,,,,,,,,,,,,,,
77.81,0.77894,6.91101,5,,,,,,,,,,,,,,,,,,,,,,,,,,,,,,,,,,,,,
78.51,0.89556,9.32736,5,,,,,,,,,,,,,,,,,,,,,,,,,,,,,,,,,,,,,
79.21,1.01235,12.41293,5,,,,,,,,,,,,,,,,,,,,,,,,,,,,,,,,,,,,,
79.91,1.12891,16.05282,5,,,,,,,,,,,,,,,,,,,,,,,,,,,,,,,,,,,,,
80.61,1.24548,20.62511,5,,,,,,,,,,,,,,,,,,,,,,,,,,,,,,,,,,,,,
81.31,1.36221,24.57001,5,,,,,,,,,,,,,,,,,,,,,,,,,,,,,,,,,,,,,
82.01,1.479,29.67037,5,,,,,,,,,,,,,,,,,,,,,,,,,,,,,,,,,,,,,
82.71,1.59568,36.38824,5,,,,,,,,,,,,,,,,,,,,,,,,,,,,,,,,,,,,,
83.248,1.61925,38.043,5.5,,,,,,,,,,,,,,,,,,,,,,,,,,,,,,,,,,,,,
83.948,1.50218,29.707,5.5,,,,,,,,,,,,,,,,,,,,,,,,,,,,,,,,,,,,,
84.648,1.38544,23.17332,5.5,,,,,,,,,,,,,,,,,,,,,,,,,,,,,,,,,,,,,
85.348,1.26871,18.41323,5.5,,,,,,,,,,,,,,,,,,,,,,,,,,,,,,,,,,,,,
86.048,1.15203,14.79681,5.5,,,,,,,,,,,,,,,,,,,,,,,,,,,,,,,,,,,,,
86.748,1.03536,11.3535,5.5,,,,,,,,,,,,,,,,,,,,,,,,,,,,,,,,,,,,,
87.448,0.91868,8.29814,5.5,,,,,,,,,,,,,,,,,,,,,,,,,,,,,,,,,,,,,
88.148,0.802,6.11968,5.5,,,,,,,,,,,,,,,,,,,,,,,,,,,,,,,,,,,,,
88.848,0.68521,4.1273,5.5,,,,,,,,,,,,,,,,,,,,,,,,,,,,,,,,,,,,,
89.548,0.56854,2.53812,5.5,,,,,,,,,,,,,,,,,,,,,,,,,,,,,,,,,,,,,
90.248,0.4518,1.0615,5.5,,,,,,,,,,,,,,,,,,,,,,,,,,,,,,,,,,,,,
90.728,0.50592,1.78122,6,,,,,,,,,,,,,,,,,,,,,,,,,,,,,,,,,,,,,
91.428,0.6226,3.61006,6,,,,,,,,,,,,,,,,,,,,,,,,,,,,,,,,,,,,,
92.128,0.73922,5.86525,6,,,,,,,,,,,,,,,,,,,,,,,,,,,,,,,,,,,,,
92.828,0.85578,8.37555,6,,,,,,,,,,,,,,,,,,,,,,,,,,,,,,,,,,,,,
93.528,0.97274,11.01347,6,,,,,,,,,,,,,,,,,,,,,,,,,,,,,,,,,,,,,
94.228,1.08942,14.39035,6,,,,,,,,,,,,,,,,,,,,,,,,,,,,,,,,,,,,,
94.928,1.20615,18.63129,6,,,,,,,,,,,,,,,,,,,,,,,,,,,,,,,,,,,,,
95.628,1.3226,23.11198,6,,,,,,,,,,,,,,,,,,,,,,,,,,,,,,,,,,,,,
96.328,1.43939,27.50113,6,,,,,,,,,,,,,,,,,,,,,,,,,,,,,,,,,,,,,
97.028,1.55607,33.54576,6,,,,,,,,,,,,,,,,,,,,,,,,,,,,,,,,,,,,,
97.636,1.65739,40.01665,6.5,,,,,,,,,,,,,,,,,,,,,,,,,,,,,,,,,,,,,
98.238,1.55782,32.96167,6.5,,,,,,,,,,,,,,,,,,,,,,,,,,,,,,,,,,,,,
98.938,1.44109,25.74556,6.5,,,,,,,,,,,,,,,,,,,,,,,,,,,,,,,,,,,,,
99.638,1.32436,20.23358,6.5,,,,,,,,,,,,,,,,,,,,,,,,,,,,,,,,,,,,,
100.338,1.20774,16.46994,6.5,,,,,,,,,,,,,,,,,,,,,,,,,,,,,,,,,,,,,
101.038,1.09106,12.66422,6.5,,,,,,,,,,,,,,,,,,,,,,,,,,,,,,,,,,,,,
101.738,0.97433,9.45438,6.5,,,,,,,,,,,,,,,,,,,,,,,,,,,,,,,,,,,,,
102.438,0.85759,6.95661,6.5,,,,,,,,,,,,,,,,,,,,,,,,,,,,,,,,,,,,,
103.138,0.74086,4.92361,6.5,,,,,,,,,,,,,,,,,,,,,,,,,,,,,,,,,,,,,
103.838,0.62424,3.11831,6.5,,,,,,,,,,,,,,,,,,,,,,,,,,,,,,,,,,,,,
104.538,0.50756,1.55971,6.5,,,,,,,,,,,,,,,,,,,,,,,,,,,,,,,,,,,,,
105.026,0.45509,0.98591,7,,,,,,,,,,,,,,,,,,,,,,,,,,,,,,,,,,,,,
105.726,0.57698,2.75632,7,,,,,,,,,,,,,,,,,,,,,,,,,,,,,,,,,,,,,
106.426,0.69366,4.84997,7,,,,,,,,,,,,,,,,,,,,,,,,,,,,,,,,,,,,,
107.126,0.81039,7.31415,7,,,,,,,,,,,,,,,,,,,,,,,,,,,,,,,,,,,,,
107.826,0.92729,9.6412,7,,,,,,,,,,,,,,,,,,,,,,,,,,,,,,,,,,,,,
108.526,1.04374,12.84137,7,,,,,,,,,,,,,,,,,,,,,,,,,,,,,,,,,,,,,
109.226,1.16036,16.60488,7,,,,,,,,,,,,,,,,,,,,,,,,,,,,,,,,,,,,,
109.926,1.27698,21.292,7,,,,,,,,,,,,,,,,,,,,,,,,,,,,,,,,,,,,,
110.626,1.39366,25.28246,7,,,,,,,,,,,,,,,,,,,,,,,,,,,,,,,,,,,,,
111.326,1.51034,30.68272,7,,,,,,,,,,,,,,,,,,,,,,,,,,,,,,,,,,,,,
112.026,1.62701,37.68906,7,,,,,,,,,,,,,,,,,,,,,,,,,,,,,,,,,,,,,
112.534,1.61183,36.60912,7.5,,,,,,,,,,,,,,,,,,,,,,,,,,,,,,,,,,,,,
113.234,1.49509,28.6368,7.5,,,,,,,,,,,,,,,,,,,,,,,,,,,,,,,,,,,,,
113.934,1.37842,22.32535,7.5,,,,,,,,,,,,,,,,,,,,,,,,,,,,,,,,,,,,,
114.634,1.26174,17.81077,7.5,,,,,,,,,,,,,,,,,,,,,,,,,,,,,,,,,,,,,
115.334,1.14501,14.27213,7.5,,,,,,,,,,,,,,,,,,,,,,,,,,,,,,,,,,,,,
116.034,1.02833,10.71625,7.5,,,,,,,,,,,,,,,,,,,,,,,,,,,,,,,,,,,,,
116.734,0.91154,7.89477,7.5,,,,,,,,,,,,,,,,,,,,,,,,,,,,,,,,,,,,,
117.434,0.79492,5.69243,7.5,,,,,,,,,,,,,,,,,,,,,,,,,,,,,,,,,,,,,
118.134,0.67819,3.78245,7.5,,,,,,,,,,,,,,,,,,,,,,,,,,,,,,,,,,,,,
118.834,0.56162,2.219,7.5,,,,,,,,,,,,,,,,,,,,,,,,,,,,,,,,,,,,,
119.45,0.45877,0.99954,8,,,,,,,,,,,,,,,,,,,,,,,,,,,,,,,,,,,,,
119.954,0.5423,2.07332,8,,,,,,,,,,,,,,,,,,,,,,,,,,,,,,,,,,,,,
120.654,0.65898,3.92955,8,,,,,,,,,,,,,,,,,,,,,,,,,,,,,,,,,,,,,
121.354,0.77565,6.40687,8,,,,,,,,,,,,,,,,,,,,,,,,,,,,,,,,,,,,,
122.054,0.89227,8.76242,8,,,,,,,,,,,,,,,,,,,,,,,,,,,,,,,,,,,,,
122.754,1.00895,11.68587,8,,,,,,,,,,,,,,,,,,,,,,,,,,,,,,,,,,,,,
123.454,1.12557,15.20116,8,,,,,,,,,,,,,,,,,,,,,,,,,,,,,,,,,,,,,
124.154,1.24225,19.66237,8,,,,,,,,,,,,,,,,,,,,,,,,,,,,,,,,,,,,,
124.854,1.35909,23.81697,8,,,,,,,,,,,,,,,,,,,,,,,,,,,,,,,,,,,,,
125.554,1.4756,28.63831,8,,,,,,,,,,,,,,,,,,,,,,,,,,,,,,,,,,,,,
126.254,1.59228,35.27931,8,,,,,,,,,,,,,,,,,,,,,,,,,,,,,,,,,,,,,
126.794,1.65365,39.90972,8.5,,,,,,,,,,,,,,,,,,,,,,,,,,,,,,,,,,,,,
127.494,1.53227,30.64613,8.5,,,,,,,,,,,,,,,,,,,,,,,,,,,,,,,,,,,,,
128.194,1.41565,23.99607,8.5,,,,,,,,,,,,,,,,,,,,,,,,,,,,,,,,,,,,,
128.894,1.29897,18.92014,8.5,,,,,,,,,,,,,,,,,,,,,,,,,,,,,,,,,,,,,
129.594,1.18229,15.20316,8.5,,,,,,,,,,,,,,,,,,,,,,,,,,,,,,,,,,,,,
130.294,1.06567,11.73267,8.5,,,,,,,,,,,,,,,,,,,,,,,,,,,,,,,,,,,,,
130.994,0.949,8.63405,8.5,,,,,,,,,,,,,,,,,,,,,,,,,,,,,,,,,,,,,
131.694,0.83243,6.35517,8.5,,,,,,,,,,,,,,,,,,,,,,,,,,,,,,,,,,,,,
132.394,0.71576,4.41384,8.5,,,,,,,,,,,,,,,,,,,,,,,,,,,,,,,,,,,,,
133.094,0.59902,2.61806,8.5,,,,,,,,,,,,,,,,,,,,,,,,,,,,,,,,,,,,,
133.794,0.48235,1.17873,8.5,,,,,,,,,,,,,,,,,,,,,,,,,,,,,,,,,,,,,
134.208,0.51385,1.56766,9,,,,,,,,,,,,,,,,,,,,,,,,,,,,,,,,,,,,,
134.908,0.63059,3.37047,9,,,,,,,,,,,,,,,,,,,,,,,,,,,,,,,,,,,,,
135.608,0.74732,5.57818,9,,,,,,,,,,,,,,,,,,,,,,,,,,,,,,,,,,,,,
136.308,0.864,8.19075,9,,,,,,,,,,,,,,,,,,,,,,,,,,,,,,,,,,,,,
137.008,0.98084,10.7521,9,,,,,,,,,,,,,,,,,,,,,,,,,,,,,,,,,,,,,
137.708,1.09741,14.11044,9,,,,,,,,,,,,,,,,,,,,,,,,,,,,,,,,,,,,,
138.408,1.21403,18.32778,9,,,,,,,,,,,,,,,,,,,,,,,,,,,,,,,,,,,,,
139.108,1.33065,22.83214,9,,,,,,,,,,,,,,,,,,,,,,,,,,,,,,,,,,,,,
139.808,1.44738,27.08514,9,,,,,,,,,,,,,,,,,,,,,,,,,,,,,,,,,,,,,
140.508,1.564,33.20598,9,,,,,,,,,,,,,,,,,,,,,,,,,,,,,,,,,,,,,
141.144,1.67002,40.01829,9.5,,,,,,,,,,,,,,,,,,,,,,,,,,,,,,,,,,,,,
141.746,1.5704,32.926,9.5,,,,,,,,,,,,,,,,,,,,,,,,,,,,,,,,,,,,,
142.446,1.45378,25.71016,9.5,,,,,,,,,,,,,,,,,,,,,,,,,,,,,,,,,,,,,
143.146,1.33705,20.18249,9.5,,,,,,,,,,,,,,,,,,,,,,,,,,,,,,,,,,,,,
143.846,1.22037,16.57832,9.5,,,,,,,,,,,,,,,,,,,,,,,,,,,,,,,,,,,,,
144.546,1.10375,12.63318,9.5,,,,,,,,,,,,,,,,,,,,,,,,,,,,,,,,,,,,,
145.246,0.98708,9.42709,9.5,,,,,,,,,,,,,,,,,,,,,,,,,,,,,,,,,,,,,
145.946,0.87034,6.98,9.5,,,,,,,,,,,,,,,,,,,,,,,,,,,,,,,,,,,,,
146.646,0.75372,4.89932,9.5,,,,,,,,,,,,,,,,,,,,,,,,,,,,,,,,,,,,,
147.346,0.63705,3.06393,9.5,,,,,,,,,,,,,,,,,,,,,,,,,,,,,,,,,,,,,
148.046,0.52026,1.5153,9.5,,,,,,,,,,,,,,,,,,,,,,,,,,,,,,,,,,,,,
148.644,0.41707,0.40492,10,,,,,,,,,,,,,,,,,,,,,,,,,,,,,,,,,,,,,
149.344,0.38669,0.27136,10,,,,,,,,,,,,,,,,,,,,,,,,,,,,,,,,,,,,,
150.044,0.38975,0.35346,10,,,,,,,,,,,,,,,,,,,,,,,,,,,,,,,,,,,,,
150.744,0.44166,0.90021,10,,,,,,,,,,,,,,,,,,,,,,,,,,,,,,,,,,,,,
151.444,0.4543,1.05796,10,,,,,,,,,,,,,,,,,,,,,,,,,,,,,,,,,,,,,
152.144,0.4518,1.04828,10,,,,,,,,,,,,,,,,,,,,,,,,,,,,,,,,,,,,,
152.844,0.42738,0.78419,10,,,,,,,,,,,,,,,,,,,,,,,,,,,,,,,,,,,,,
153.544,0.41248,0.61065,10,,,,,,,,,,,,,,,,,,,,,,,,,,,,,,,,,,,,,
154.244,0.41242,0.67986,10,,,,,,,,,,,,,,,,,,,,,,,,,,,,,,,,,,,,,
154.944,0.41265,0.60121,10,,,,,,,,,,,,,,,,,,,,,,,,,,,,,,,,,,,,,
155.644,0.41293,0.68172,10,,,,,,,,,,,,,,,,,,,,,,,,,,,,,,,,,,,,,
156.344,0.41344,0.6804,10,,,,,,,,,,,,,,,,,,,,,,,,,,,,,,,,,,,,,
157.044,0.4148,0.71791,10,,,,,,,,,,,,,,,,,,,,,,,,,,,,,,,,,,,,,
157.744,0.4165,0.73727,10,,,,,,,,,,,,,,,,,,,,,,,,,,,,,,,,,,,,,
158.444,0.41792,0.79742,10,,,,,,,,,,,,,,,,,,,,,,,,,,,,,,,,,,,,,
159.144,0.41871,0.74391,10,,,,,,,,,,,,,,,,,,,,,,,,,,,,,,,,,,,,,
159.844,0.41905,0.77563,10,,,,,,,,,,,,,,,,,,,,,,,,,,,,,,,,,,,,,
160.544,0.41911,0.74865,10,,,,,,,,,,,,,,,,,,,,,,,,,,,,,,,,,,,,,
161.244,0.41899,0.7532,10,,,,,,,,,,,,,,,,,,,,,,,,,,,,,,,,,,,,,
161.944,0.41894,0.78358,10,,,,,,,,,,,,,,,,,,,,,,,,,,,,,,,,,,,,,
162.644,0.41894,0.7738,10,,,,,,,,,,,,,,,,,,,,,,,,,,,,,,,,,,,,,
163.344,0.41871,0.78059,10,,,,,,,,,,,,,,,,,,,,,,,,,,,,,,,,,,,,,
164.044,0.41854,0.78336,10,,,,,,,,,,,,,,,,,,,,,,,,,,,,,,,,,,,,,
164.744,0.41814,0.74451,10,,,,,,,,,,,,,,,,,,,,,,,,,,,,,,,,,,,,,
165.444,0.41769,0.82857,10,,,,,,,,,,,,,,,,,,,,,,,,,,,,,,,,,,,,,
166.144,0.41678,0.75742,10,,,,,,,,,,,,,,,,,,,,,,,,,,,,,,,,,,,,,
166.844,0.41582,0.7797,10,,,,,,,,,,,,,,,,,,,,,,,,,,,,,,,,,,,,,
167.544,0.4144,0.73425,10,,,,,,,,,,,,,,,,,,,,,,,,,,,,,,,,,,,,,
168.244,0.4127,0.73588,10,,,,,,,,,,,,,,,,,,,,,,,,,,,,,,,,,,,,,
168.944,0.41123,0.74471,10,,,,,,,,,,,,,,,,,,,,,,,,,,,,,,,,,,,,,
169.644,0.41044,0.74459,10,,,,,,,,,,,,,,,,,,,,,,,,,,,,,,,,,,,,,
170.344,0.4101,0.73731,10,,,,,,,,,,,,,,,,,,,,,,,,,,,,,,,,,,,,,
171.044,0.4097,0.72708,10,,,,,,,,,,,,,,,,,,,,,,,,,,,,,,,,,,,,,
171.744,0.40919,0.68944,10,,,,,,,,,,,,,,,,,,,,,,,,,,,,,,,,,,,,,
172.444,0.40896,0.75813,10,,,,,,,,,,,,,,,,,,,,,,,,,,,,,,,,,,,,,
173.144,0.40879,0.72329,10,,,,,,,,,,,,,,,,,,,,,,,,,,,,,,,,,,,,,
173.844,0.40862,0.70449,10,,,,,,,,,,,,,,,,,,,,,,,,,,,,,,,,,,,,,
174.544,0.40868,0.68967,10,,,,,,,,,,,,,,,,,,,,,,,,,,,,,,,,,,,,,
175.244,0.40874,0.72624,10,,,,,,,,,,,,,,,,,,,,,,,,,,,,,,,,,,,,,
175.944,0.40874,0.76935,10,,,,,,,,,,,,,,,,,,,,,,,,,,,,,,,,,,,,,
176.644,0.40868,0.72874,10,,,,,,,,,,,,,,,,,,,,,,,,,,,,,,,,,,,,,
177.344,0.40868,0.73655,10,,,,,,,,,,,,,,,,,,,,,,,,,,,,,,,,,,,,,
178.044,0.40879,0.71646,10,,,,,,,,,,,,,,,,,,,,,,,,,,,,,,,,,,,,,
178.744,0.40874,0.79886,10,,,,,,,,,,,,,,,,,,,,,,,,,,,,,,,,,,,,,
179.444,0.40874,0.72207,10,,,,,,,,,,,,,,,,,,,,,,,,,,,,,,,,,,,,,
180.144,0.40868,0.66527,10,,,,,,,,,,,,,,,,,,,,,,,,,,,,,,,,,,,,,
180.844,0.40879,0.71028,10,,,,,,,,,,,,,,,,,,,,,,,,,,,,,,,,,,,,,
181.544,0.40879,0.71868,10,,,,,,,,,,,,,,,,,,,,,,,,,,,,,,,,,,,,,
182.244,0.40874,0.74045,10,,,,,,,,,,,,,,,,,,,,,,,,,,,,,,,,,,,,,
182.944,0.40874,0.74529,10,,,,,,,,,,,,,,,,,,,,,,,,,,,,,,,,,,,,,
183.644,0.40868,0.77901,10,,,,,,,,,,,,,,,,,,,,,,,,,,,,,,,,,,,,,
184.344,0.40879,0.72916,10,,,,,,,,,,,,,,,,,,,,,,,,,,,,,,,,,,,,,
185.044,0.40879,0.70726,10,,,,,,,,,,,,,,,,,,,,,,,,,,,,,,,,,,,,,
185.744,0.40874,0.75876,10,,,,,,,,,,,,,,,,,,,,,,,,,,,,,,,,,,,,,
186.444,0.40868,0.83888,10,,,,,,,,,,,,,,,,,,,,,,,,,,,,,,,,,,,,,
187.144,0.40868,0.77654,10,,,,,,,,,,,,,,,,,,,,,,,,,,,,,,,,,,,,,
187.844,0.40862,0.78817,10,,,,,,,,,,,,,,,,,,,,,,,,,,,,,,,,,,,,,
188.544,0.40862,0.76352,10,,,,,,,,,,,,,,,,,,,,,,,,,,,,,,,,,,,,,
189.244,0.40857,0.75246,10,,,,,,,,,,,,,,,,,,,,,,,,,,,,,,,,,,,,,
189.944,0.40845,0.79205,10,,,,,,,,,,,,,,,,,,,,,,,,,,,,,,,,,,,,,
190.644,0.40794,0.78444,10,,,,,,,,,,,,,,,,,,,,,,,,,,,,,,,,,,,,,
191.344,0.40624,0.76492,10,,,,,,,,,,,,,,,,,,,,,,,,,,,,,,,,,,,,,
192.044,0.40375,0.77408,10,,,,,,,,,,,,,,,,,,,,,,,,,,,,,,,,,,,,,
192.744,0.40256,0.68069,10,,,,,,,,,,,,,,,,,,,,,,,,,,,,,,,,,,,,,
193.444,0.40228,0.66186,10,,,,,,,,,,,,,,,,,,,,,,,,,,,,,,,,,,,,,
194.144,0.40228,0.66016,10,,,,,,,,,,,,,,,,,,,,,,,,,,,,,,,,,,,,,
194.844,0.40233,0.67873,10,,,,,,,,,,,,,,,,,,,,,,,,,,,,,,,,,,,,,
195.544,0.40239,0.71452,10,,,,,,,,,,,,,,,,,,,,,,,,,,,,,,,,,,,,,
196.244,0.4025,0.67942,10,,,,,,,,,,,,,,,,,,,,,,,,,,,,,,,,,,,,,
196.944,0.40256,0.70281,10,,,,,,,,,,,,,,,,,,,,,,,,,,,,,,,,,,,,,
197.644,0.40267,0.72658,10,,,,,,,,,,,,,,,,,,,,,,,,,,,,,,,,,,,,,
198.344,0.40279,0.70405,10,,,,,,,,,,,,,,,,,,,,,,,,,,,,,,,,,,,,,
199.044,0.4029,0.70274,10,,,,,,,,,,,,,,,,,,,,,,,,,,,,,,,,,,,,,
199.744,0.40296,0.72652,10,,,,,,,,,,,,,,,,,,,,,,,,,,,,,,,,,,,,,
200.444,0.40307,0.76431,10,,,,,,,,,,,,,,,,,,,,,,,,,,,,,,,,,,,,,
201.144,0.40318,0.69105,10,,,,,,,,,,,,,,,,,,,,,,,,,,,,,,,,,,,,,
201.844,0.40324,0.75113,10,,,,,,,,,,,,,,,,,,,,,,,,,,,,,,,,,,,,,
202.544,0.40324,0.76001,10,,,,,,,,,,,,,,,,,,,,,,,,,,,,,,,,,,,,,
203.244,0.40335,0.7687,10,,,,,,,,,,,,,,,,,,,,,,,,,,,,,,,,,,,,,
203.944,0.40341,0.74229,10,,,,,,,,,,,,,,,,,,,,,,,,,,,,,,,,,,,,,
204.644,0.40352,0.69749,10,,,,,,,,,,,,,,,,,,,,,,,,,,,,,,,,,,,,,
205.344,0.40341,0.75367,10,,,,,,,,,,,,,,,,,,,,,,,,,,,,,,,,,,,,,
206.044,0.40341,0.68586,10,,,,,,,,,,,,,,,,,,,,,,,,,,,,,,,,,,,,,
206.744,0.40341,0.75502,10,,,,,,,,,,,,,,,,,,,,,,,,,,,,,,,,,,,,,
207.444,0.40341,0.76257,10,,,,,,,,,,,,,,,,,,,,,,,,,,,,,,,,,,,,,
208.144,0.40335,0.72333,10,,,,,,,,,,,,,,,,,,,,,,,,,,,,,,,,,,,,,
208.844,0.40335,0.71656,10,,,,,,,,,,,,,,,,,,,,,,,,,,,,,,,,,,,,,
209.544,0.40335,0.8234,10,,,,,,,,,,,,,,,,,,,,,,,,,,,,,,,,,,,,,
210.244,0.4033,0.75165,10,,,,,,,,,,,,,,,,,,,,,,,,,,,,,,,,,,,,,
210.944,0.4033,0.70417,10,,,,,,,,,,,,,,,,,,,,,,,,,,,,,,,,,,,,,
211.644,0.4033,0.74936,10,,,,,,,,,,,,,,,,,,,,,,,,,,,,,,,,,,,,,
212.344,0.40335,0.74205,10,,,,,,,,,,,,,,,,,,,,,,,,,,,,,,,,,,,,,
213.044,0.40335,0.72265,10,,,,,,,,,,,,,,,,,,,,,,,,,,,,,,,,,,,,,
213.744,0.40335,0.74066,10,,,,,,,,,,,,,,,,,,,,,,,,,,,,,,,,,,,,,
214.444,0.40335,0.73632,10,,,,,,,,,,,,,,,,,,,,,,,,,,,,,,,,,,,,,
215.144,0.40335,0.6887,10,,,,,,,,,,,,,,,,,,,,,,,,,,,,,,,,,,,,,
215.844,0.40335,0.77882,10,,,,,,,,,,,,,,,,,,,,,,,,,,,,,,,,,,,,,
216.544,0.4033,0.84715,10,,,,,,,,,,,,,,,,,,,,,,,,,,,,,,,,,,,,,
217.244,0.4033,0.71593,10,,,,,,,,,,,,,,,,,,,,,,,,,,,,,,,,,,,,,
217.944,0.4033,0.74568,10,,,,,,,,,,,,,,,,,,,,,,,,,,,,,,,,,,,,,
218.644,0.40335,0.71734,10,,,,,,,,,,,,,,,,,,,,,,,,,,,,,,,,,,,,,
219.344,0.40335,0.72266,10,,,,,,,,,,,,,,,,,,,,,,,,,,,,,,,,,,,,,
220.044,0.40335,0.73902,10,,,,,,,,,,,,,,,,,,,,,,,,,,,,,,,,,,,,,
220.744,0.40335,0.78454,10,,,,,,,,,,,,,,,,,,,,,,,,,,,,,,,,,,,,,
221.444,0.40335,0.77311,10,,,,,,,,,,,,,,,,,,,,,,,,,,,,,,,,,,,,,
222.144,0.40335,0.77611,10,,,,,,,,,,,,,,,,,,,,,,,,,,,,,,,,,,,,,
222.844,0.40335,0.69742,10,,,,,,,,,,,,,,,,,,,,,,,,,,,,,,,,,,,,,
223.544,0.40335,0.74795,10,,,,,,,,,,,,,,,,,,,,,,,,,,,,,,,,,,,,,
224.244,0.40335,0.72992,10,,,,,,,,,,,,,,,,,,,,,,,,,,,,,,,,,,,,,
224.944,0.40324,0.71678,10,,,,,,,,,,,,,,,,,,,,,,,,,,,,,,,,,,,,,
225.644,0.40324,0.73248,10,,,,,,,,,,,,,,,,,,,,,,,,,,,,,,,,,,,,,
226.344,0.40324,0.70428,10,,,,,,,,,,,,,,,,,,,,,,,,,,,,,,,,,,,,,
227.044,0.40324,0.75634,10,,,,,,,,,,,,,,,,,,,,,,,,,,,,,,,,,,,,,
227.744,0.40318,0.70701,10,,,,,,,,,,,,,,,,,,,,,,,,,,,,,,,,,,,,,
228.444,0.40318,0.75238,10,,,,,,,,,,,,,,,,,,,,,,,,,,,,,,,,,,,,,
229.144,0.40307,0.78176,10,,,,,,,,,,,,,,,,,,,,,,,,,,,,,,,,,,,,,
229.844,0.40301,0.75748,10,,,,,,,,,,,,,,,,,,,,,,,,,,,,,,,,,,,,,
230.544,0.40296,0.71582,10,,,,,,,,,,,,,,,,,,,,,,,,,,,,,,,,,,,,,
231.244,0.4029,0.74822,10,,,,,,,,,,,,,,,,,,,,,,,,,,,,,,,,,,,,,
231.944,0.40273,0.75061,10,,,,,,,,,,,,,,,,,,,,,,,,,,,,,,,,,,,,,
232.644,0.40256,0.73459,10,,,,,,,,,,,,,,,,,,,,,,,,,,,,,,,,,,,,,
233.344,0.40233,0.77471,10,,,,,,,,,,,,,,,,,,,,,,,,,,,,,,,,,,,,,
234.044,0.40205,0.77518,10,,,,,,,,,,,,,,,,,,,,,,,,,,,,,,,,,,,,,
234.744,0.40103,0.74854,10,,,,,,,,,,,,,,,,,,,,,,,,,,,,,,,,,,,,,
235.444,0.39808,0.70575,10,,,,,,,,,,,,,,,,,,,,,,,,,,,,,,,,,,,,,
236.144,0.39684,0.72907,10,,,,,,,,,,,,,,,,,,,,,,,,,,,,,,,,,,,,,
236.844,0.3965,0.76007,10,,,,,,,,,,,,,,,,,,,,,,,,,,,,,,,,,,,,,
237.544,0.39644,0.71222,10,,,,,,,,,,,,,,,,,,,,,,,,,,,,,,,,,,,,,
238.244,0.39644,0.67657,10,,,,,,,,,,,,,,,,,,,,,,,,,,,,,,,,,,,,,
238.944,0.39661,0.67678,10,,,,,,,,,,,,,,,,,,,,,,,,,,,,,,,,,,,,,
239.644,0.39672,0.63925,10,,,,,,,,,,,,,,,,,,,,,,,,,,,,,,,,,,,,,
240.344,0.39672,0.74222,10,,,,,,,,,,,,,,,,,,,,,,,,,,,,,,,,,,,,,
241.044,0.39689,0.69757,10,,,,,,,,,,,,,,,,,,,,,,,,,,,,,,,,,,,,,
241.744,0.39695,0.7129,10,,,,,,,,,,,,,,,,,,,,,,,,,,,,,,,,,,,,,
242.444,0.39695,0.71817,10,,,,,,,,,,,,,,,,,,,,,,,,,,,,,,,,,,,,,
243.144,0.39695,0.72725,10,,,,,,,,,,,,,,,,,,,,,,,,,,,,,,,,,,,,,
243.844,0.39695,0.76461,10,,,,,,,,,,,,,,,,,,,,,,,,,,,,,,,,,,,,,
244.544,0.39695,0.75205,10,,,,,,,,,,,,,,,,,,,,,,,,,,,,,,,,,,,,,
245.244,0.39695,0.73954,10,,,,,,,,,,,,,,,,,,,,,,,,,,,,,,,,,,,,,
245.944,0.39695,0.7069,10,,,,,,,,,,,,,,,,,,,,,,,,,,,,,,,,,,,,,
246.644,0.39695,0.71036,10,,,,,,,,,,,,,,,,,,,,,,,,,,,,,,,,,,,,,
247.344,0.39695,0.75759,10,,,,,,,,,,,,,,,,,,,,,,,,,,,,,,,,,,,,,
248.044,0.39689,0.70857,10,,,,,,,,,,,,,,,,,,,,,,,,,,,,,,,,,,,,,
248.744,0.39701,0.71694,10,,,,,,,,,,,,,,,,,,,,,,,,,,,,,,,,,,,,,
249.444,0.39701,0.7309,10,,,,,,,,,,,,,,,,,,,,,,,,,,,,,,,,,,,,,
250.144,0.39701,0.72158,10,,,,,,,,,,,,,,,,,,,,,,,,,,,,,,,,,,,,,
250.844,0.39701,0.7641,10,,,,,,,,,,,,,,,,,,,,,,,,,,,,,,,,,,,,,
251.544,0.39701,0.74863,10,,,,,,,,,,,,,,,,,,,,,,,,,,,,,,,,,,,,,
252.244,0.39701,0.7452,10,,,,,,,,,,,,,,,,,,,,,,,,,,,,,,,,,,,,,
252.944,0.39701,0.7547,10,,,,,,,,,,,,,,,,,,,,,,,,,,,,,,,,,,,,,
253.644,0.39695,0.74236,10,,,,,,,,,,,,,,,,,,,,,,,,,,,,,,,,,,,,,
254.344,0.39695,0.7732,10,,,,,,,,,,,,,,,,,,,,,,,,,,,,,,,,,,,,,
255.044,0.39701,0.7035,10,,,,,,,,,,,,,,,,,,,,,,,,,,,,,,,,,,,,,
255.744,0.39701,0.7075,10,,,,,,,,,,,,,,,,,,,,,,,,,,,,,,,,,,,,,
256.444,0.39701,0.72529,10,,,,,,,,,,,,,,,,,,,,,,,,,,,,,,,,,,,,,
257.144,0.39701,0.72803,10,,,,,,,,,,,,,,,,,,,,,,,,,,,,,,,,,,,,,
257.844,0.39701,0.79023,10,,,,,,,,,,,,,,,,,,,,,,,,,,,,,,,,,,,,,
258.544,0.39701,0.72261,10,,,,,,,,,,,,,,,,,,,,,,,,,,,,,,,,,,,,,
259.244,0.39701,0.73215,10,,,,,,,,,,,,,,,,,,,,,,,,,,,,,,,,,,,,,
259.944,0.39701,0.71472,10,,,,,,,,,,,,,,,,,,,,,,,,,,,,,,,,,,,,,
260.644,0.39701,0.8052,10,,,,,,,,,,,,,,,,,,,,,,,,,,,,,,,,,,,,,
261.344,0.39701,0.78096,10,,,,,,,,,,,,,,,,,,,,,,,,,,,,,,,,,,,,,
262.044,0.39689,0.75394,10,,,,,,,,,,,,,,,,,,,,,,,,,,,,,,,,,,,,,
262.744,0.39701,0.70824,10,,,,,,,,,,,,,,,,,,,,,,,,,,,,,,,,,,,,,
263.444,0.39701,0.71965,10,,,,,,,,,,,,,,,,,,,,,,,,,,,,,,,,,,,,,
264.144,0.39701,0.70542,10,,,,,,,,,,,,,,,,,,,,,,,,,,,,,,,,,,,,,
264.844,0.39701,0.71056,10,,,,,,,,,,,,,,,,,,,,,,,,,,,,,,,,,,,,,
265.544,0.39701,0.74803,10,,,,,,,,,,,,,,,,,,,,,,,,,,,,,,,,,,,,,
266.244,0.39701,0.7168,10,,,,,,,,,,,,,,,,,,,,,,,,,,,,,,,,,,,,,
266.944,0.39701,0.71595,10,,,,,,,,,,,,,,,,,,,,,,,,,,,,,,,,,,,,,
267.644,0.39701,0.7115,10,,,,,,,,,,,,,,,,,,,,,,,,,,,,,,,,,,,,,
268.344,0.39701,0.7328,10,,,,,,,,,,,,,,,,,,,,,,,,,,,,,,,,,,,,,
269.044,0.39701,0.76424,10,,,,,,,,,,,,,,,,,,,,,,,,,,,,,,,,,,,,,
269.744,0.39701,0.7071,10,,,,,,,,,,,,,,,,,,,,,,,,,,,,,,,,,,,,,
270.444,0.39701,0.72122,10,,,,,,,,,,,,,,,,,,,,,,,,,,,,,,,,,,,,,
271.144,0.39701,0.76275,10,,,,,,,,,,,,,,,,,,,,,,,,,,,,,,,,,,,,,
271.844,0.39701,0.78391,10,,,,,,,,,,,,,,,,,,,,,,,,,,,,,,,,,,,,,
272.544,0.39701,0.72247,10,,,,,,,,,,,,,,,,,,,,,,,,,,,,,,,,,,,,,
273.244,0.39701,0.7181,10,,,,,,,,,,,,,,,,,,,,,,,,,,,,,,,,,,,,,
273.944,0.39701,0.74447,10,,,,,,,,,,,,,,,,,,,,,,,,,,,,,,,,,,,,,
274.644,0.39701,0.73308,10,,,,,,,,,,,,,,,,,,,,,,,,,,,,,,,,,,,,,
275.344,0.39701,0.73023,10,,,,,,,,,,,,,,,,,,,,,,,,,,,,,,,,,,,,,
276.044,0.39701,0.75712,10,,,,,,,,,,,,,,,,,,,,,,,,,,,,,,,,,,,,,
276.744,0.39701,0.74683,10,,,,,,,,,,,,,,,,,,,,,,,,,,,,,,,,,,,,,
277.444,0.39701,0.73251,10,,,,,,,,,,,,,,,,,,,,,,,,,,,,,,,,,,,,,
278.144,0.39701,0.78939,10,,,,,,,,,,,,,,,,,,,,,,,,,,,,,,,,,,,,,
278.844,0.39701,0.74573,10,,,,,,,,,,,,,,,,,,,,,,,,,,,,,,,,,,,,,
279.544,0.39701,0.73147,10,,,,,,,,,,,,,,,,,,,,,,,,,,,,,,,,,,,,,
280.244,0.39701,0.73123,10,,,,,,,,,,,,,,,,,,,,,,,,,,,,,,,,,,,,,
280.944,0.39701,0.72559,10,,,,,,,,,,,,,,,,,,,,,,,,,,,,,,,,,,,,,
281.644,0.39701,0.73369,10,,,,,,,,,,,,,,,,,,,,,,,,,,,,,,,,,,,,,
282.344,0.39701,0.7491,10,,,,,,,,,,,,,,,,,,,,,,,,,,,,,,,,,,,,,
283.044,0.39701,0.71732,10,,,,,,,,,,,,,,,,,,,,,,,,,,,,,,,,,,,,,
283.744,0.39701,0.74409,10,,,,,,,,,,,,,,,,,,,,,,,,,,,,,,,,,,,,,
284.444,0.39701,0.6935,10,,,,,,,,,,,,,,,,,,,,,,,,,,,,,,,,,,,,,
285.144,0.39695,0.73656,10,,,,,,,,,,,,,,,,,,,,,,,,,,,,,,,,,,,,,
285.844,0.39701,0.73913,10,,,,,,,,,,,,,,,,,,,,,,,,,,,,,,,,,,,,,
286.544,0.39701,0.71622,10,,,,,,,,,,,,,,,,,,,,,,,,,,,,,,,,,,,,,
287.244,0.39701,0.73545,10,,,,,,,,,,,,,,,,,,,,,,,,,,,,,,,,,,,,,
287.944,0.39701,0.70028,10,,,,,,,,,,,,,,,,,,,,,,,,,,,,,,,,,,,,,
288.644,0.39701,0.76019,10,,,,,,,,,,,,,,,,,,,,,,,,,,,,,,,,,,,,,
289.344,0.39701,0.77143,10,,,,,,,,,,,,,,,,,,,,,,,,,,,,,,,,,,,,,
290.044,0.39701,0.72453,10,,,,,,,,,,,,,,,,,,,,,,,,,,,,,,,,,,,,,
290.744,0.39701,0.70468,10,,,,,,,,,,,,,,,,,,,,,,,,,,,,,,,,,,,,,
291.444,0.39701,0.75657,10,,,,,,,,,,,,,,,,,,,,,,,,,,,,,,,,,,,,,
292.144,0.39701,0.76727,10,,,,,,,,,,,,,,,,,,,,,,,,,,,,,,,,,,,,,
292.844,0.39701,0.73853,10,,,,,,,,,,,,,,,,,,,,,,,,,,,,,,,,,,,,,
293.544,0.39701,0.77445,10,,,,,,,,,,,,,,,,,,,,,,,,,,,,,,,,,,,,,
294.244,0.39701,0.7243,10,,,,,,,,,,,,,,,,,,,,,,,,,,,,,,,,,,,,,
294.944,0.39701,0.71066,10,,,,,,,,,,,,,,,,,,,,,,,,,,,,,,,,,,,,,
295.644,0.39701,0.73212,10,,,,,,,,,,,,,,,,,,,,,,,,,,,,,,,,,,,,,
296.344,0.39689,0.77804,10,,,,,,,,,,,,,,,,,,,,,,,,,,,,,,,,,,,,,
297.044,0.39701,0.69807,10,,,,,,,,,,,,,,,,,,,,,,,,,,,,,,,,,,,,,
297.744,0.39701,0.72712,10,,,,,,,,,,,,,,,,,,,,,,,,,,,,,,,,,,,,,
298.444,0.39701,0.75289,10,,,,,,,,,,,,,,,,,,,,,,,,,,,,,,,,,,,,,
299.144,0.39701,0.72371,10,,,,,,,,,,,,,,,,,,,,,,,,,,,,,,,,,,,,,
299.844,0.39701,0.75733,10,,,,,,,,,,,,,,,,,,,,,,,,,,,,,,,,,,,,,
300.544,0.39701,0.75066,10,,,,,,,,,,,,,,,,,,,,,,,,,,,,,,,,,,,,,
301.244,0.39701,0.72151,10,,,,,,,,,,,,,,,,,,,,,,,,,,,,,,,,,,,,,
301.944,0.39701,0.73368,10,,,,,,,,,,,,,,,,,,,,,,,,,,,,,,,,,,,,,
302.644,0.39701,0.74623,10,,,,,,,,,,,,,,,,,,,,,,,,,,,,,,,,,,,,,
303.344,0.39701,0.75696,10,,,,,,,,,,,,,,,,,,,,,,,,,,,,,,,,,,,,,
304.044,0.39701,0.7412,10,,,,,,,,,,,,,,,,,,,,,,,,,,,,,,,,,,,,,
304.744,0.39701,0.76863,10,,,,,,,,,,,,,,,,,,,,,,,,,,,,,,,,,,,,,
305.444,0.39701,0.72989,10,,,,,,,,,,,,,,,,,,,,,,,,,,,,,,,,,,,,,
306.144,0.39701,0.75093,10,,,,,,,,,,,,,,,,,,,,,,,,,,,,,,,,,,,,,
306.844,0.39695,0.7942,10,,,,,,,,,,,,,,,,,,,,,,,,,,,,,,,,,,,,,
307.544,0.39684,0.76096,10,,,,,,,,,,,,,,,,,,,,,,,,,,,,,,,,,,,,,
308.244,0.39678,0.74546,10,,,,,,,,,,,,,,,,,,,,,,,,,,,,,,,,,,,,,
308.944,0.39678,0.78186,10,,,,,,,,,,,,,,,,,,,,,,,,,,,,,,,,,,,,,
309.644,0.39661,0.78282,10,,,,,,,,,,,,,,,,,,,,,,,,,,,,,,,,,,,,,
310.344,0.3965,0.79381,10,,,,,,,,,,,,,,,,,,,,,,,,,,,,,,,,,,,,,
311.044,0.39627,0.80552,10,,,,,,,,,,,,,,,,,,,,,,,,,,,,,,,,,,,,,
311.744,0.39582,0.7768,10,,,,,,,,,,,,,,,,,,,,,,,,,,,,,,,,,,,,,
312.444,0.3944,0.74591,10,,,,,,,,,,,,,,,,,,,,,,,,,,,,,,,,,,,,,
313.144,0.39253,0.69913,10,,,,,,,,,,,,,,,,,,,,,,,,,,,,,,,,,,,,,
313.844,0.39185,0.70796,10,,,,,,,,,,,,,,,,,,,,,,,,,,,,,,,,,,,,,
314.544,0.39168,0.69419,10,,,,,,,,,,,,,,,,,,,,,,,,,,,,,,,,,,,,,
315.244,0.39157,0.66241,10,,,,,,,,,,,,,,,,,,,,,,,,,,,,,,,,,,,,,
315.944,0.39174,0.69544,10,,,,,,,,,,,,,,,,,,,,,,,,,,,,,,,,,,,,,
316.644,0.39179,0.69905,10,,,,,,,,,,,,,,,,,,,,,,,,,,,,,,,,,,,,,
317.344,0.39185,0.71516,10,,,,,,,,,,,,,,,,,,,,,,,,,,,,,,,,,,,,,
318.044,0.39191,0.74348,10,,,,,,,,,,,,,,,,,,,,,,,,,,,,,,,,,,,,,
318.744,0.39202,0.7811,10,,,,,,,,,,,,,,,,,,,,,,,,,,,,,,,,,,,,,
319.444,0.39208,0.70006,10,,,,,,,,,,,,,,,,,,,,,,,,,,,,,,,,,,,,,
320.144,0.39213,0.75413,10,,,,,,,,,,,,,,,,,,,,,,,,,,,,,,,,,,,,,
320.844,0.39225,0.71895,10,,,,,,,,,,,,,,,,,,,,,,,,,,,,,,,,,,,,,
321.544,0.3923,0.74485,10,,,,,,,,,,,,,,,,,,,,,,,,,,,,,,,,,,,,,
322.244,0.39242,0.74056,10,,,,,,,,,,,,,,,,,,,,,,,,,,,,,,,,,,,,,
322.944,0.39253,0.74425,10,,,,,,,,,,,,,,,,,,,,,,,,,,,,,,,,,,,,,
323.644,0.39264,0.69603,10,,,,,,,,,,,,,,,,,,,,,,,,,,,,,,,,,,,,,
324.344,0.3927,0.72441,10,,,,,,,,,,,,,,,,,,,,,,,,,,,,,,,,,,,,,
325.044,0.39276,0.73709,10,,,,,,,,,,,,,,,,,,,,,,,,,,,,,,,,,,,,,
325.744,0.39287,0.73402,10,,,,,,,,,,,,,,,,,,,,,,,,,,,,,,,,,,,,,
326.444,0.39293,0.74385,10,,,,,,,,,,,,,,,,,,,,,,,,,,,,,,,,,,,,,
327.144,0.39298,0.76627,10,,,,,,,,,,,,,,,,,,,,,,,,,,,,,,,,,,,,,
327.844,0.39298,0.70511,10,,,,,,,,,,,,,,,,,,,,,,,,,,,,,,,,,,,,,
328.544,0.39304,0.66899,10,,,,,,,,,,,,,,,,,,,,,,,,,,,,,,,,,,,,,
329.244,0.3931,0.76535,10,,,,,,,,,,,,,,,,,,,,,,,,,,,,,,,,,,,,,
329.944,0.39321,0.75744,10,,,,,,,,,,,,,,,,,,,,,,,,,,,,,,,,,,,,,
330.644,0.39321,0.77823,10,,,,,,,,,,,,,,,,,,,,,,,,,,,,,,,,,,,,,
331.344,0.39327,0.76401,10,,,,,,,,,,,,,,,,,,,,,,,,,,,,,,,,,,,,,
332.044,0.39321,0.72659,10,,,,,,,,,,,,,,,,,,,,,,,,,,,,,,,,,,,,,
332.744,0.39332,0.7519,10,,,,,,,,,,,,,,,,,,,,,,,,,,,,,,,,,,,,,
333.444,0.39332,0.71006,10,,,,,,,,,,,,,,,,,,,,,,,,,,,,,,,,,,,,,
334.144,0.39332,0.72085,10,,,,,,,,,,,,,,,,,,,,,,,,,,,,,,,,,,,,,
334.844,0.39332,0.75558,10,,,,,,,,,,,,,,,,,,,,,,,,,,,,,,,,,,,,,
335.544,0.39332,0.74209,10,,,,,,,,,,,,,,,,,,,,,,,,,,,,,,,,,,,,,
336.244,0.39332,0.77131,10,,,,,,,,,,,,,,,,,,,,,,,,,,,,,,,,,,,,,
336.944,0.39321,0.77228,10,,,,,,,,,,,,,,,,,,,,,,,,,,,,,,,,,,,,,
337.644,0.39332,0.75287,10,,,,,,,,,,,,,,,,,,,,,,,,,,,,,,,,,,,,,
338.344,0.39321,0.78959,10,,,,,,,,,,,,,,,,,,,,,,,,,,,,,,,,,,,,,
339.044,0.39332,0.71585,10,,,,,,,,,,,,,,,,,,,,,,,,,,,,,,,,,,,,,
339.744,0.39332,0.72342,10,,,,,,,,,,,,,,,,,,,,,,,,,,,,,,,,,,,,,
340.444,0.39332,0.71747,10,,,,,,,,,,,,,,,,,,,,,,,,,,,,,,,,,,,,,
341.144,0.39332,0.72916,10,,,,,,,,,,,,,,,,,,,,,,,,,,,,,,,,,,,,,
341.844,0.39321,0.73797,10,,,,,,,,,,,,,,,,,,,,,,,,,,,,,,,,,,,,,
342.544,0.39321,0.73427,10,,,,,,,,,,,,,,,,,,,,,,,,,,,,,,,,,,,,,
343.244,0.39332,0.70696,10,,,,,,,,,,,,,,,,,,,,,,,,,,,,,,,,,,,,,
343.944,0.39321,0.75489,10,,,,,,,,,,,,,,,,,,,,,,,,,,,,,,,,,,,,,
344.644,0.39321,0.76227,10,,,,,,,,,,,,,,,,,,,,,,,,,,,,,,,,,,,,,
345.344,0.39332,0.73331,10,,,,,,,,,,,,,,,,,,,,,,,,,,,,,,,,,,,,,
346.044,0.39321,0.73859,10,,,,,,,,,,,,,,,,,,,,,,,,,,,,,,,,,,,,,
346.744,0.39321,0.73815,10,,,,,,,,,,,,,,,,,,,,,,,,,,,,,,,,,,,,,
347.444,0.39321,0.74159,10,,,,,,,,,,,,,,,,,,,,,,,,,,,,,,,,,,,,,
348.144,0.39321,0.73689,10,,,,,,,,,,,,,,,,,,,,,,,,,,,,,,,,,,,,,
348.844,0.39321,0.72254,10,,,,,,,,,,,,,,,,,,,,,,,,,,,,,,,,,,,,,
349.544,0.39321,0.74233,10,,,,,,,,,,,,,,,,,,,,,,,,,,,,,,,,,,,,,
350.244,0.39327,0.74417,10,,,,,,,,,,,,,,,,,,,,,,,,,,,,,,,,,,,,,
350.944,0.39327,0.7204,10,,,,,,,,,,,,,,,,,,,,,,,,,,,,,,,,,,,,,
351.644,0.39321,0.80092,10,,,,,,,,,,,,,,,,,,,,,,,,,,,,,,,,,,,,,
352.344,0.39327,0.75794,10,,,,,,,,,,,,,,,,,,,,,,,,,,,,,,,,,,,,,
353.044,0.39327,0.75648,10,,,,,,,,,,,,,,,,,,,,,,,,,,,,,,,,,,,,,
353.744,0.39327,0.74297,10,,,,,,,,,,,,,,,,,,,,,,,,,,,,,,,,,,,,,
354.444,0.39315,0.6872,10,,,,,,,,,,,,,,,,,,,,,,,,,,,,,,,,,,,,,
355.144,0.39321,0.75269,10,,,,,,,,,,,,,,,,,,,,,,,,,,,,,,,,,,,,,
355.844,0.39321,0.80034,10,,,,,,,,,,,,,,,,,,,,,,,,,,,,,,,,,,,,,
356.544,0.39321,0.70785,10,,,,,,,,,,,,,,,,,,,,,,,,,,,,,,,,,,,,,
357.244,0.3931,0.70691,10,,,,,,,,,,,,,,,,,,,,,,,,,,,,,,,,,,,,,
357.944,0.3931,0.73464,10,,,,,,,,,,,,,,,,,,,,,,,,,,,,,,,,,,,,,
358.644,0.3931,0.69718,10,,,,,,,,,,,,,,,,,,,,,,,,,,,,,,,,,,,,,
359.344,0.3931,0.72066,10,,,,,,,,,,,,,,,,,,,,,,,,,,,,,,,,,,,,,
360.044,0.3931,0.69422,10,,,,,,,,,,,,,,,,,,,,,,,,,,,,,,,,,,,,,
360.744,0.3931,0.7476,10,,,,,,,,,,,,,,,,,,,,,,,,,,,,,,,,,,,,,
361.444,0.39304,0.70004,10,,,,,,,,,,,,,,,,,,,,,,,,,,,,,,,,,,,,,
362.144,0.39304,0.73632,10,,,,,,,,,,,,,,,,,,,,,,,,,,,,,,,,,,,,,
362.844,0.39315,0.81424,10,,,,,,,,,,,,,,,,,,,,,,,,,,,,,,,,,,,,,
363.544,0.39315,0.72195,10,,,,,,,,,,,,,,,,,,,,,,,,,,,,,,,,,,,,,
364.244,0.39315,0.72643,10,,,,,,,,,,,,,,,,,,,,,,,,,,,,,,,,,,,,,
364.944,0.3931,0.73048,10,,,,,,,,,,,,,,,,,,,,,,,,,,,,,,,,,,,,,
365.644,0.3931,0.72835,10,,,,,,,,,,,,,,,,,,,,,,,,,,,,,,,,,,,,,
366.344,0.3931,0.71622,10,,,,,,,,,,,,,,,,,,,,,,,,,,,,,,,,,,,,,
367.044,0.3931,0.73582,10,,,,,,,,,,,,,,,,,,,,,,,,,,,,,,,,,,,,,
367.744,0.3931,0.74191,10,,,,,,,,,,,,,,,,,,,,,,,,,,,,,,,,,,,,,
368.444,0.3931,0.71074,10,,,,,,,,,,,,,,,,,,,,,,,,,,,,,,,,,,,,,
369.144,0.3931,0.79256,10,,,,,,,,,,,,,,,,,,,,,,,,,,,,,,,,,,,,,
369.844,0.3931,0.76888,10,,,,,,,,,,,,,,,,,,,,,,,,,,,,,,,,,,,,,
370.544,0.3931,0.72617,10,,,,,,,,,,,,,,,,,,,,,,,,,,,,,,,,,,,,,
371.244,0.3931,0.73916,10,,,,,,,,,,,,,,,,,,,,,,,,,,,,,,,,,,,,,
371.944,0.3931,0.74149,10,,,,,,,,,,,,,,,,,,,,,,,,,,,,,,,,,,,,,
372.644,0.3931,0.75069,10,,,,,,,,,,,,,,,,,,,,,,,,,,,,,,,,,,,,,
373.344,0.3931,0.74717,10,,,,,,,,,,,,,,,,,,,,,,,,,,,,,,,,,,,,,
374.044,0.39304,0.7061,10,,,,,,,,,,,,,,,,,,,,,,,,,,,,,,,,,,,,,
374.744,0.39304,0.74214,10,,,,,,,,,,,,,,,,,,,,,,,,,,,,,,,,,,,,,
375.444,0.3931,0.70338,10,,,,,,,,,,,,,,,,,,,,,,,,,,,,,,,,,,,,,
376.144,0.3931,0.71927,10,,,,,,,,,,,,,,,,,,,,,,,,,,,,,,,,,,,,,
376.844,0.3931,0.79037,10,,,,,,,,,,,,,,,,,,,,,,,,,,,,,,,,,,,,,
377.544,0.3931,0.71045,10,,,,,,,,,,,,,,,,,,,,,,,,,,,,,,,,,,,,,
378.244,0.39304,0.69883,10,,,,,,,,,,,,,,,,,,,,,,,,,,,,,,,,,,,,,
378.944,0.39304,0.70991,10,,,,,,,,,,,,,,,,,,,,,,,,,,,,,,,,,,,,,
379.644,0.39315,0.68307,10,,,,,,,,,,,,,,,,,,,,,,,,,,,,,,,,,,,,,
380.344,0.39315,0.72586,10,,,,,,,,,,,,,,,,,,,,,,,,,,,,,,,,,,,,,
381.044,0.39315,0.73,10,,,,,,,,,,,,,,,,,,,,,,,,,,,,,,,,,,,,,
381.744,0.39315,0.65928,10,,,,,,,,,,,,,,,,,,,,,,,,,,,,,,,,,,,,,
382.444,0.39304,0.72944,10,,,,,,,,,,,,,,,,,,,,,,,,,,,,,,,,,,,,,
383.144,0.3931,0.77154,10,,,,,,,,,,,,,,,,,,,,,,,,,,,,,,,,,,,,,
383.844,0.3931,0.736,10,,,,,,,,,,,,,,,,,,,,,,,,,,,,,,,,,,,,,
384.544,0.3931,0.74193,10,,,,,,,,,,,,,,,,,,,,,,,,,,,,,,,,,,,,,
385.244,0.3931,0.75443,10,,,,,,,,,,,,,,,,,,,,,,,,,,,,,,,,,,,,,
385.944,0.3931,0.72611,10,,,,,,,,,,,,,,,,,,,,,,,,,,,,,,,,,,,,,
386.644,0.3931,0.72883,10,,,,,,,,,,,,,,,,,,,,,,,,,,,,,,,,,,,,,
387.344,0.3931,0.72356,10,,,,,,,,,,,,,,,,,,,,,,,,,,,,,,,,,,,,,
388.044,0.3931,0.73867,10,,,,,,,,,,,,,,,,,,,,,,,,,,,,,,,,,,,,,
388.744,0.3931,0.7251,10,,,,,,,,,,,,,,,,,,,,,,,,,,,,,,,,,,,,,
389.444,0.3931,0.76312,10,,,,,,,,,,,,,,,,,,,,,,,,,,,,,,,,,,,,,
390.144,0.3931,0.72272,10,,,,,,,,,,,,,,,,,,,,,,,,,,,,,,,,,,,,,
390.844,0.39304,0.75627,10,,,,,,,,,,,,,,,,,,,,,,,,,,,,,,,,,,,,,
391.544,0.39304,0.74183,10,,,,,,,,,,,,,,,,,,,,,,,,,,,,,,,,,,,,,
392.244,0.39315,0.66429,10,,,,,,,,,,,,,,,,,,,,,,,,,,,,,,,,,,,,,
392.944,0.39315,0.72059,10,,,,,,,,,,,,,,,,,,,,,,,,,,,,,,,,,,,,,
393.644,0.39315,0.73288,10,,,,,,,,,,,,,,,,,,,,,,,,,,,,,,,,,,,,,
394.344,0.39315,0.75589,10,,,,,,,,,,,,,,,,,,,,,,,,,,,,,,,,,,,,,
395.044,0.3931,0.69539,10,,,,,,,,,,,,,,,,,,,,,,,,,,,,,,,,,,,,,
395.744,0.3931,0.73934,10,,,,,,,,,,,,,,,,,,,,,,,,,,,,,,,,,,,,,
396.444,0.3931,0.68959,10,,,,,,,,,,,,,,,,,,,,,,,,,,,,,,,,,,,,,
397.144,0.3931,0.71255,10,,,,,,,,,,,,,,,,,,,,,,,,,,,,,,,,,,,,,
397.844,0.39321,0.79545,10,,,,,,,,,,,,,,,,,,,,,,,,,,,,,,,,,,,,,
398.544,0.39321,0.75388,10,,,,,,,,,,,,,,,,,,,,,,,,,,,,,,,,,,,,,
399.244,0.39321,0.73589,10,,,,,,,,,,,,,,,,,,,,,,,,,,,,,,,,,,,,,
399.944,0.39327,0.77873,10,,,,,,,,,,,,,,,,,,,,,,,,,,,,,,,,,,,,,
400.644,0.39321,0.68743,10,,,,,,,,,,,,,,,,,,,,,,,,,,,,,,,,,,,,,
401.344,0.39321,0.74414,10,,,,,,,,,,,,,,,,,,,,,,,,,,,,,,,,,,,,,
402.044,0.39332,0.75947,10,,,,,,,,,,,,,,,,,,,,,,,,,,,,,,,,,,,,,
402.744,0.39332,0.71201,10,,,,,,,,,,,,,,,,,,,,,,,,,,,,,,,,,,,,,
403.444,0.39332,0.7274,10,,,,,,,,,,,,,,,,,,,,,,,,,,,,,,,,,,,,,
404.144,0.39332,0.69217,10,,,,,,,,,,,,,,,,,,,,,,,,,,,,,,,,,,,,,
404.844,0.39332,0.76195,10,,,,,,,,,,,,,,,,,,,,,,,,,,,,,,,,,,,,,
405.544,0.39332,0.7205,10,,,,,,,,,,,,,,,,,,,,,,,,,,,,,,,,,,,,,
406.244,0.39338,0.70145,10,,,,,,,,,,,,,,,,,,,,,,,,,,,,,,,,,,,,,
406.944,0.39338,0.82366,10,,,,,,,,,,,,,,,,,,,,,,,,,,,,,,,,,,,,,
407.644,0.39338,0.73219,10,,,,,,,,,,,,,,,,,,,,,,,,,,,,,,,,,,,,,
408.344,0.39332,0.74688,10,,,,,,,,,,,,,,,,,,,,,,,,,,,,,,,,,,,,,
409.044,0.39332,0.80406,10,,,,,,,,,,,,,,,,,,,,,,,,,,,,,,,,,,,,,
409.744,0.39338,0.64605,10,,,,,,,,,,,,,,,,,,,,,,,,,,,,,,,,,,,,,
410.444,0.39338,0.70161,10,,,,,,,,,,,,,,,,,,,,,,,,,,,,,,,,,,,,,
411.144,0.39332,0.66554,10,,,,,,,,,,,,,,,,,,,,,,,,,,,,,,,,,,,,,
411.844,0.39338,0.709,10,,,,,,,,,,,,,,,,,,,,,,,,,,,,,,,,,,,,,
412.544,0.39361,0.70596,10,,,,,,,,,,,,,,,,,,,,,,,,,,,,,,,,,,,,,
413.244,0.39383,0.75856,10,,,,,,,,,,,,,,,,,,,,,,,,,,,,,,,,,,,,,
413.944,0.39389,0.84172,10,,,,,,,,,,,,,,,,,,,,,,,,,,,,,,,,,,,,,
414.644,0.39412,0.7534,10,,,,,,,,,,,,,,,,,,,,,,,,,,,,,,,,,,,,,
415.344,0.39412,0.76967,10,,,,,,,,,,,,,,,,,,,,,,,,,,,,,,,,,,,,,
416.044,0.39423,0.73942,10,,,,,,,,,,,,,,,,,,,,,,,,,,,,,,,,,,,,,
416.744,0.39423,0.76935,10,,,,,,,,,,,,,,,,,,,,,,,,,,,,,,,,,,,,,
417.444,0.39412,0.70325,10,,,,,,,,,,,,,,,,,,,,,,,,,,,,,,,,,,,,,
418.144,0.39412,0.7263,10,,,,,,,,,,,,,,,,,,,,,,,,,,,,,,,,,,,,,
418.844,0.39417,0.74949,10,,,,,,,,,,,,,,,,,,,,,,,,,,,,,,,,,,,,,
419.544,0.39417,0.72053,10,,,,,,,,,,,,,,,,,,,,,,,,,,,,,,,,,,,,,
420.244,0.39417,0.72231,10,,,,,,,,,,,,,,,,,,,,,,,,,,,,,,,,,,,,,
420.944,0.39412,0.77065,10,,,,,,,,,,,,,,,,,,,,,,,,,,,,,,,,,,,,,
421.644,0.39417,0.75708,10,,,,,,,,,,,,,,,,,,,,,,,,,,,,,,,,,,,,,
422.344,0.39417,0.70335,10,,,,,,,,,,,,,,,,,,,,,,,,,,,,,,,,,,,,,
423.044,0.39412,0.72215,10,,,,,,,,,,,,,,,,,,,,,,,,,,,,,,,,,,,,,
423.744,0.39412,0.69494,10,,,,,,,,,,,,,,,,,,,,,,,,,,,,,,,,,,,,,
424.444,0.39412,0.71177,10,,,,,,,,,,,,,,,,,,,,,,,,,,,,,,,,,,,,,
425.144,0.39417,0.787,10,,,,,,,,,,,,,,,,,,,,,,,,,,,,,,,,,,,,,
425.844,0.39406,0.73398,10,,,,,,,,,,,,,,,,,,,,,,,,,,,,,,,,,,,,,
426.544,0.39412,0.76059,10,,,,,,,,,,,,,,,,,,,,,,,,,,,,,,,,,,,,,
427.244,0.39412,0.74451,10,,,,,,,,,,,,,,,,,,,,,,,,,,,,,,,,,,,,,
427.944,0.39412,0.68221,10,,,,,,,,,,,,,,,,,,,,,,,,,,,,,,,,,,,,,
428.644,0.394,0.75746,10,,,,,,,,,,,,,,,,,,,,,,,,,,,,,,,,,,,,,
429.344,0.39412,0.75158,10,,,,,,,,,,,,,,,,,,,,,,,,,,,,,,,,,,,,,
430.044,0.394,0.67965,10,,,,,,,,,,,,,,,,,,,,,,,,,,,,,,,,,,,,,
430.744,0.39412,0.76096,10,,,,,,,,,,,,,,,,,,,,,,,,,,,,,,,,,,,,,
431.444,0.39412,0.74969,10,,,,,,,,,,,,,,,,,,,,,,,,,,,,,,,,,,,,,
432.144,0.39412,0.70939,10,,,,,,,,,,,,,,,,,,,,,,,,,,,,,,,,,,,,,
432.844,0.39412,0.693,10,,,,,,,,,,,,,,,,,,,,,,,,,,,,,,,,,,,,,
433.544,0.39412,0.72454,10,,,,,,,,,,,,,,,,,,,,,,,,,,,,,,,,,,,,,
434.244,0.394,0.80731,10,,,,,,,,,,,,,,,,,,,,,,,,,,,,,,,,,,,,,
434.944,0.394,0.73524,10,,,,,,,,,,,,,,,,,,,,,,,,,,,,,,,,,,,,,
435.644,0.394,0.76573,10,,,,,,,,,,,,,,,,,,,,,,,,,,,,,,,,,,,,,
436.344,0.394,0.76358,10,,,,,,,,,,,,,,,,,,,,,,,,,,,,,,,,,,,,,
437.044,0.394,0.74913,10,,,,,,,,,,,,,,,,,,,,,,,,,,,,,,,,,,,,,
437.744,0.39412,0.68641,10,,,,,,,,,,,,,,,,,,,,,,,,,,,,,,,,,,,,,
438.444,0.394,0.74752,10,,,,,,,,,,,,,,,,,,,,,,,,,,,,,,,,,,,,,
439.144,0.394,0.71082,10,,,,,,,,,,,,,,,,,,,,,,,,,,,,,,,,,,,,,
439.844,0.39412,0.73836,10,,,,,,,,,,,,,,,,,,,,,,,,,,,,,,,,,,,,,
440.544,0.394,0.74794,10,,,,,,,,,,,,,,,,,,,,,,,,,,,,,,,,,,,,,
441.244,0.394,0.75164,10,,,,,,,,,,,,,,,,,,,,,,,,,,,,,,,,,,,,,
441.944,0.39412,0.73483,10,,,,,,,,,,,,,,,,,,,,,,,,,,,,,,,,,,,,,
442.644,0.39412,0.68799,10,,,,,,,,,,,,,,,,,,,,,,,,,,,,,,,,,,,,,
443.344,0.39412,0.75222,10,,,,,,,,,,,,,,,,,,,,,,,,,,,,,,,,,,,,,
444.044,0.39417,0.75284,10,,,,,,,,,,,,,,,,,,,,,,,,,,,,,,,,,,,,,
444.744,0.39412,0.68802,10,,,,,,,,,,,,,,,,,,,,,,,,,,,,,,,,,,,,,
445.444,0.39412,0.69562,10,,,,,,,,,,,,,,,,,,,,,,,,,,,,,,,,,,,,,
446.144,0.39423,0.73829,10,,,,,,,,,,,,,,,,,,,,,,,,,,,,,,,,,,,,,
446.844,0.39429,0.73866,10,,,,,,,,,,,,,,,,,,,,,,,,,,,,,,,,,,,,,
447.544,0.39446,0.72732,10,,,,,,,,,,,,,,,,,,,,,,,,,,,,,,,,,,,,,
448.244,0.39457,0.76582,10,,,,,,,,,,,,,,,,,,,,,,,,,,,,,,,,,,,,,
448.846,4.29448,396.57016,10,,,,,,,,,,,,,,,,,,,,,,,,,,,,,,,,,,,,,
449.546,10.12803,789.67395,10,,,,,,,,,,,,,,,,,,,,,,,,,,,,,,,,,,,,,
450.246,15.9613,678.70691,10,,,,,,,,,,,,,,,,,,,,,,,,,,,,,,,,,,,,,
450.946,21.79468,234.995,10,,,,,,,,,,,,,,,,,,,,,,,,,,,,,,,,,,,,,
451.646,27.62794,98.90919,10,,,,,,,,,,,,,,,,,,,,,,,,,,,,,,,,,,,,,
452.346,33.46127,61.41534,10,,,,,,,,,,,,,,,,,,,,,,,,,,,,,,,,,,,,,
453.046,39.29464,34.89259,10,,,,,,,,,,,,,,,,,,,,,,,,,,,,,,,,,,,,,
453.746,45.12803,17.39159,10,,,,,,,,,,,,,,,,,,,,,,,,,,,,,,,,,,,,,
454.446,50.9613,7.4952,10,,,,,,,,,,,,,,,,,,,,,,,,,,,,,,,,,,,,,
455.146,56.79468,1.37606,10,,,,,,,,,,,,,,,,,,,,,,,,,,,,,,,,,,,,,
455.846,62.62793,-1.52178,10,,,,,,,,,,,,,,,,,,,,,,,,,,,,,,,,,,,,,
456.546,68.46126,-2.54842,10,,,,,,,,,,,,,,,,,,,,,,,,,,,,,,,,,,,,,
457.246,74.29458,-2.59059,10,,,,,,,,,,,,,,,,,,,,,,,,,,,,,,,,,,,,,
457.946,80.12802,-2.57439,10,,,,,,,,,,,,,,,,,,,,,,,,,,,,,,,,,,,,,
458.646,85.96129,-2.5912,10,,,,,,,,,,,,,,,,,,,,,,,,,,,,,,,,,,,,,
459.346,91.79461,-2.55798,10,,,,,,,,,,,,,,,,,,,,,,,,,,,,,,,,,,,,,
459.554,93.52793,-2.60824,10,,,,,,,,,,,,,,,,,,,,,,,,,,,,,,,,,,,,,