File: combined_ligament_solver/data/processed/Data Sheet 3_S160134_ACL.csv
Specimen properties : Length,30,mm,Unnamed: 3,Start here,Unnamed: 5,Unnamed: 6,Unnamed: 7,Unnamed: 8,Unnamed: 9,Unnamed: 10,Unnamed: 11,Stress-Strain,Unnamed: 13,Unnamed: 14,Unnamed: 15,Unnamed: 16,Unnamed: 17,Unnamed: 18,Unnamed: 19,Unnamed: 20,Unnamed: 21,Unnamed: 22,Unnamed: 23,Unnamed: 24,Unnamed: 25,Unnamed: 26,Unnamed: 27,Linear,Unnamed: 29,Unnamed: 30,Unnamed: 31,Unnamed: 32,Unnamed: 33,Modulus,Unnamed: 35,Failure,Unnamed: 37,Unnamed: 38,Unnamed: 39,Unnamed: 40
Cross Section Average,48.4585,mm2,,,,,,,,,,Polynomial Coefficients,,,,,,,,,,,,,,,,Force,,Stress,Extension,Strain,,Secant,Tangent,Load,Stress,Extension,Strain,Stiffness
Time,Extension,Load,Total cycle count,,,Extension,Load,Strain,Stress,E-tan,,X6,,,,,,,,,,Strain,Stress,E-tan,,,,(N),,(MPa),(mm),(%),,(MPa),(MPa),(N),(MPa),(mm),(%),(N/mm)
(s),(mm),(N),,,,(mm),(N),(mm/mm),(MPa),(MPa),,X5,,,,,,,,,,(mm/mm),(MPa),(MPa),,,,777.074474709825,,16.03587553700228,4.11,13.700000000000001,,117.05018640147648,167.36312540644235,1554.16492,32.05435805895766,8.09999,26.99996666666667,189.06921525786493
0.4,0.11356,2.85851,0,,,3.41536,516.40558,0.103326,10.638933726797157,157.0660118083583,,,,,,,,,,,,0.004,0.07583920142709952,22.324158304533007,,,,,,,,,,,,,,,,
0.9,0.19686,5.68652,0,,,7.58217,1508.58105,0.24221966666666667,31.113679540225142,77.53151697057864,,,,,,,,,,,,0.009,0.22030906031596587,33.215091528994925,,,,,,,,,,,,,,,,
1.4,0.28022,8.86135,0,,,,,,,,,,,,,,,,,,,0.014,0.41791357519086,43.66626350316106,,,,,,,,,,,,,,,,
1.9,0.3634,12.70866,0,,,,,,,,,,,,,,,,,,,0.019,0.6664593876907616,53.67949019051771,,,,,,,,,,,,,,,,
2.4,0.44699,16.92546,0,,,,,,,,,,,,,,,,,,,0.024,0.9637622192720819,63.25658755455104,,,,,,,,,,,,,,,,
2.9,0.53012,20.88333,0,,,,,,,,,,,,,,,,,,,0.029,1.307646871208663,72.39937155874692,,,,,,,,,,,,,,,,
3.4,0.61347,26.26254,0,,,,,,,,,,,,,,,,,,,0.034,1.6959472245917788,81.10965816659258,,,,,,,,,,,,,,,,
3.9,0.69683,32.43982,0,,,,,,,,,,,,,,,,,,,0.039,2.1265062403301336,89.38926334157351,,,,,,,,,,,,,,,,
4.4,0.78013,39.6102,0,,,,,,,,,,,,,,,,,,,0.044,2.5971759591498635,97.24000304717686,,,,,,,,,,,,,,,,
4.724,0.734,33.36139,0.5,,,,,,,,,,,,,,,,,,,0.049,3.1058175015945353,104.66369324688641,,,,,,,,,,,,,,,,
5.224,0.65059,24.10069,0.5,,,,,,,,,,,,,,,,,,,0.054,3.6503010680251475,111.66214990419154,,,,,,,,,,,,,,,,
5.724,0.56729,17.16939,0.5,,,,,,,,,,,,,,,,,,,0.059,4.228505938620129,118.23718898257667,,,,,,,,,,,,,,,,
6.224,0.48388,12.41931,0.5,,,,,,,,,,,,,,,,,,,0.064,4.838320473375343,124.39062644552732,,,,,,,,,,,,,,,,
6.724,0.40058,8.4909,0.5,,,,,,,,,,,,,,,,,,,0.069,5.477642112104078,130.1242782565327,,,,,,,,,,,,,,,,
7.224,0.31705,5.2569,0.5,,,,,,,,,,,,,,,,,,,0.074,6.144377374437059,135.43996037907556,,,,,,,,,,,,,,,,
7.724,0.23392,2.55373,0.5,,,,,,,,,,,,,,,,,,,0.079,6.8364418598224415,140.33948877664568,,,,,,,,,,,,,,,,
8.1,0.1713,0.9894,1,,,,,,,,,,,,,,,,,,,0.084,7.551760247525808,144.8246794127249,,,,,,,,,,,,,,,,
8.502,0.23851,2.93037,1,,,,,,,,,,,,,,,,,,,0.089,8.288266296630177,148.8973482508039,,,,,,,,,,,,,,,,
9.002,0.3217,6.12384,1,,,,,,,,,,,,,,,,,,,0.094,9.043902846035998,152.55931125436626,,,,,,,,,,,,,,,,
9.502,0.40522,10.06032,1,,,,,,,,,,,,,,,,,,,0.099,9.816621814461147,155.81238438689823,,,,,,,,,,,,,,,,
10.002,0.48841,14.76846,1,,,,,,,,,,,,,,,,,,,0.104,10.604384200440935,158.65838361188784,,,,,,,,,,,,,,,,
10.502,0.57188,19.03957,1,,,,,,,,,,,,,,,,,,,0.109,11.405160082328107,161.0991248928196,,,,,,,,,,,,,,,,
11.002,0.65512,25.05806,1,,,,,,,,,,,,,,,,,,,0.114,12.216928618292835,163.1364241931815,,,,,,,,,,,,,,,,
11.502,0.73865,32.29644,1,,,,,,,,,,,,,,,,,,,0.119,13.037678046322716,164.77209747646157,,,,,,,,,,,,,,,,
11.972,0.81685,40.02605,1.5,,,,,,,,,,,,,,,,,,,0.124,13.865405684222797,166.00796070614072,,,,,,,,,,,,,,,,
12.374,0.75027,31.49168,1.5,,,,,,,,,,,,,,,,,,,0.129,14.698117929615533,166.84582984570523,,,,,,,,,,,,,,,,
12.874,0.66691,22.76137,1.5,,,,,,,,,,,,,,,,,,,0.134,15.53383025994083,167.28752085864315,,,,,,,,,,,,,,,,
13.374,0.58361,16.1791,1.5,,,,,,,,,,,,,,,,,,,0.139,16.370567232456015,167.33484970844952,,,,,,,,,,,,,,,,
13.874,0.50008,11.92236,1.5,,,,,,,,,,,,,,,,,,,0.144,17.20636248423584,166.9896323585965,,,,,,,,,,,,,,,,
14.374,0.41695,7.96076,1.5,,,,,,,,,,,,,,,,,,,0.149,18.039258732172506,166.25368477257382,,,,,,,,,,,,,,,,
14.874,0.33354,4.67394,1.5,,,,,,,,,,,,,,,,,,,0.154,18.867307772975632,165.1288229138677,,,,,,,,,,,,,,,,
15.374,0.25018,2.03312,1.5,,,,,,,,,,,,,,,,,,,0.159,19.688570483172278,163.61686274597517,,,,,,,,,,,,,,,,
15.618,0.20944,0.96841,2,,,,,,,,,,,,,,,,,,,0.164,20.501116819106915,161.7196202323717,,,,,,,,,,,,,,,,
16.118,0.29393,3.60026,2,,,,,,,,,,,,,,,,,,,0.169,21.30302581694147,159.43891133654714,,,,,,,,,,,,,,,,
16.618,0.37706,7.03384,2,,,,,,,,,,,,,,,,,,,0.174,22.092385592655283,156.77655202197712,,,,,,,,,,,,,,,,
17.118,0.46053,11.25668,2,,,,,,,,,,,,,,,,,,,0.179,22.86729334204514,153.73435825216558,,,,,,,,,,,,,,,,
17.618,0.54383,16.20579,2,,,,,,,,,,,,,,,,,,,0.184,23.62585534072525,150.31414599058465,,,,,,,,,,,,,,,,
18.118,0.62724,20.72791,2,,,,,,,,,,,,,,,,,,,0.189,24.36618694412725,146.51773120073472,,,,,,,,,,,,,,,,
18.618,0.71043,27.37769,2,,,,,,,,,,,,,,,,,,,0.194,25.086412587500217,142.34692984609498,,,,,,,,,,,,,,,,
19.118,0.79396,35.32385,2,,,,,,,,,,,,,,,,,,,0.199,25.784665785910644,137.80355789014095,,,,,,,,,,,,,,,,
19.486,0.82603,39.40286,2.5,,,,,,,,,,,,,,,,,,,,,,,,,,,,,,,,,,,,,
19.986,0.73831,27.65389,2.5,,,,,,,,,,,,,,,,,,,,,,,,,,,,,,,,,,,,,
20.486,0.6549,19.87034,2.5,,,,,,,,,,,,,,,,,,,,,,,,,,,,,,,,,,,,,
20.986,0.57165,14.19068,2.5,,,,,,,,,,,,,,,,,,,,,,,,,,,,,,,,,,,,,
21.486,0.48807,10.10815,2.5,,,,,,,,,,,,,,,,,,,,,,,,,,,,,,,,,,,,,
21.986,0.40494,6.50917,2.5,,,,,,,,,,,,,,,,,,,,,,,,,,,,,,,,,,,,,
22.486,0.32147,3.42486,2.5,,,,,,,,,,,,,,,,,,,,,,,,,,,,,,,,,,,,,
22.986,0.23823,1.08913,2.5,,,,,,,,,,,,,,,,,,,,,,,,,,,,,,,,,,,,,
23.224,0.26571,1.77484,3,,,,,,,,,,,,,,,,,,,,,,,,,,,,,,,,,,,,,
23.724,0.34958,4.8582,3,,,,,,,,,,,,,,,,,,,,,,,,,,,,,,,,,,,,,
24.224,0.43276,8.65081,3,,,,,,,,,,,,,,,,,,,,,,,,,,,,,,,,,,,,,
24.724,0.51623,13.22436,3,,,,,,,,,,,,,,,,,,,,,,,,,,,,,,,,,,,,,
25.224,0.59948,17.60009,3,,,,,,,,,,,,,,,,,,,,,,,,,,,,,,,,,,,,,
25.724,0.68295,23.44304,3,,,,,,,,,,,,,,,,,,,,,,,,,,,,,,,,,,,,,
26.224,0.76613,30.79455,3,,,,,,,,,,,,,,,,,,,,,,,,,,,,,,,,,,,,,
26.724,0.8496,39.43089,3,,,,,,,,,,,,,,,,,,,,,,,,,,,,,,,,,,,,,
27.058,0.80495,33.76619,3.5,,,,,,,,,,,,,,,,,,,,,,,,,,,,,,,,,,,,,
27.558,0.72148,24.37647,3.5,,,,,,,,,,,,,,,,,,,,,,,,,,,,,,,,,,,,,
28.058,0.63829,17.36815,3.5,,,,,,,,,,,,,,,,,,,,,,,,,,,,,,,,,,,,,
28.558,0.55477,12.65904,3.5,,,,,,,,,,,,,,,,,,,,,,,,,,,,,,,,,,,,,
29.058,0.47164,8.59495,3.5,,,,,,,,,,,,,,,,,,,,,,,,,,,,,,,,,,,,,
29.558,0.38817,5.16231,3.5,,,,,,,,,,,,,,,,,,,,,,,,,,,,,,,,,,,,,
30.058,0.30481,2.37351,3.5,,,,,,,,,,,,,,,,,,,,,,,,,,,,,,,,,,,,,
30.39,0.2495,0.97906,4,,,,,,,,,,,,,,,,,,,,,,,,,,,,,,,,,,,,,
30.792,0.31682,2.89841,4,,,,,,,,,,,,,,,,,,,,,,,,,,,,,,,,,,,,,
31.292,0.40024,6.24687,4,,,,,,,,,,,,,,,,,,,,,,,,,,,,,,,,,,,,,
31.792,0.48337,10.31589,4,,,,,,,,,,,,,,,,,,,,,,,,,,,,,,,,,,,,,
32.292,0.56695,15.27581,4,,,,,,,,,,,,,,,,,,,,,,,,,,,,,,,,,,,,,
32.792,0.65014,19.95525,4,,,,,,,,,,,,,,,,,,,,,,,,,,,,,,,,,,,,,
33.292,0.73355,26.48703,4,,,,,,,,,,,,,,,,,,,,,,,,,,,,,,,,,,,,,
33.792,0.81679,34.44757,4,,,,,,,,,,,,,,,,,,,,,,,,,,,,,,,,,,,,,
34.104,0.86881,40.03909,4.5,,,,,,,,,,,,,,,,,,,,,,,,,,,,,,,,,,,,,
34.604,0.78529,29.71162,4.5,,,,,,,,,,,,,,,,,,,,,,,,,,,,,,,,,,,,,
35.104,0.70199,21.35214,4.5,,,,,,,,,,,,,,,,,,,,,,,,,,,,,,,,,,,,,
35.604,0.61857,15.12036,4.5,,,,,,,,,,,,,,,,,,,,,,,,,,,,,,,,,,,,,
36.104,0.53522,11.04034,4.5,,,,,,,,,,,,,,,,,,,,,,,,,,,,,,,,,,,,,
36.604,0.45192,7.0188,4.5,,,,,,,,,,,,,,,,,,,,,,,,,,,,,,,,,,,,,
37.104,0.3685,3.90064,4.5,,,,,,,,,,,,,,,,,,,,,,,,,,,,,,,,,,,,,
37.604,0.28526,1.41506,4.5,,,,,,,,,,,,,,,,,,,,,,,,,,,,,,,,,,,,,
37.888,0.30509,1.90978,5,,,,,,,,,,,,,,,,,,,,,,,,,,,,,,,,,,,,,
38.388,0.38879,5.06233,5,,,,,,,,,,,,,,,,,,,,,,,,,,,,,,,,,,,,,
38.888,0.47215,8.96916,5,,,,,,,,,,,,,,,,,,,,,,,,,,,,,,,,,,,,,
39.388,0.5555,13.7154,5,,,,,,,,,,,,,,,,,,,,,,,,,,,,,,,,,,,,,
39.888,0.6388,18.17769,5,,,,,,,,,,,,,,,,,,,,,,,,,,,,,,,,,,,,,
40.388,0.72199,24.43402,5,,,,,,,,,,,,,,,,,,,,,,,,,,,,,,,,,,,,,
40.888,0.80557,32.12616,5,,,,,,,,,,,,,,,,,,,,,,,,,,,,,,,,,,,,,
41.33,0.87913,40.02062,5.5,,,,,,,,,,,,,,,,,,,,,,,,,,,,,,,,,,,,,
41.732,0.81266,31.61142,5.5,,,,,,,,,,,,,,,,,,,,,,,,,,,,,,,,,,,,,
42.232,0.72919,22.74753,5.5,,,,,,,,,,,,,,,,,,,,,,,,,,,,,,,,,,,,,
42.732,0.64594,16.13588,5.5,,,,,,,,,,,,,,,,,,,,,,,,,,,,,,,,,,,,,
43.232,0.56253,11.78864,5.5,,,,,,,,,,,,,,,,,,,,,,,,,,,,,,,,,,,,,
43.732,0.47923,7.73516,5.5,,,,,,,,,,,,,,,,,,,,,,,,,,,,,,,,,,,,,
44.232,0.39593,4.35225,5.5,,,,,,,,,,,,,,,,,,,,,,,,,,,,,,,,,,,,,
44.732,0.31252,1.72145,5.5,,,,,,,,,,,,,,,,,,,,,,,,,,,,,,,,,,,,,
45.03,0.29229,0.94776,6,,,,,,,,,,,,,,,,,,,,,,,,,,,,,,,,,,,,,
45.53,0.38052,4.20021,6,,,,,,,,,,,,,,,,,,,,,,,,,,,,,,,,,,,,,
46.03,0.46382,7.94799,6,,,,,,,,,,,,,,,,,,,,,,,,,,,,,,,,,,,,,
46.53,0.54706,12.48643,6,,,,,,,,,,,,,,,,,,,,,,,,,,,,,,,,,,,,,
47.03,0.63059,17.31542,6,,,,,,,,,,,,,,,,,,,,,,,,,,,,,,,,,,,,,
47.53,0.71377,22.92246,6,,,,,,,,,,,,,,,,,,,,,,,,,,,,,,,,,,,,,
48.03,0.79724,30.358,6,,,,,,,,,,,,,,,,,,,,,,,,,,,,,,,,,,,,,
48.53,0.88043,39.06567,6,,,,,,,,,,,,,,,,,,,,,,,,,,,,,,,,,,,,,
48.88,0.83861,33.76913,6.5,,,,,,,,,,,,,,,,,,,,,,,,,,,,,,,,,,,,,
49.38,0.75531,24.34642,6.5,,,,,,,,,,,,,,,,,,,,,,,,,,,,,,,,,,,,,
49.88,0.67184,17.28145,6.5,,,,,,,,,,,,,,,,,,,,,,,,,,,,,,,,,,,,,
50.38,0.5886,12.53175,6.5,,,,,,,,,,,,,,,,,,,,,,,,,,,,,,,,,,,,,
50.88,0.5053,8.39728,6.5,,,,,,,,,,,,,,,,,,,,,,,,,,,,,,,,,,,,,
51.38,0.42188,4.91074,6.5,,,,,,,,,,,,,,,,,,,,,,,,,,,,,,,,,,,,,
51.88,0.33853,2.17027,6.5,,,,,,,,,,,,,,,,,,,,,,,,,,,,,,,,,,,,,
52.15,0.29353,0.98923,7,,,,,,,,,,,,,,,,,,,,,,,,,,,,,,,,,,,,,
52.65,0.37774,3.63412,7,,,,,,,,,,,,,,,,,,,,,,,,,,,,,,,,,,,,,
53.15,0.46121,7.30929,7,,,,,,,,,,,,,,,,,,,,,,,,,,,,,,,,,,,,,
53.65,0.54445,11.63471,7,,,,,,,,,,,,,,,,,,,,,,,,,,,,,,,,,,,,,
54.15,0.62792,16.7406,7,,,,,,,,,,,,,,,,,,,,,,,,,,,,,,,,,,,,,
54.65,0.71105,21.98947,7,,,,,,,,,,,,,,,,,,,,,,,,,,,,,,,,,,,,,
55.15,0.79458,29.22349,7,,,,,,,,,,,,,,,,,,,,,,,,,,,,,,,,,,,,,
55.65,0.87782,37.86678,7,,,,,,,,,,,,,,,,,,,,,,,,,,,,,,,,,,,,,
55.966,0.86411,36.14713,7.5,,,,,,,,,,,,,,,,,,,,,,,,,,,,,,,,,,,,,
56.466,0.78013,25.9933,7.5,,,,,,,,,,,,,,,,,,,,,,,,,,,,,,,,,,,,,
56.966,0.697,18.6399,7.5,,,,,,,,,,,,,,,,,,,,,,,,,,,,,,,,,,,,,
57.466,0.61353,13.19548,7.5,,,,,,,,,,,,,,,,,,,,,,,,,,,,,,,,,,,,,
57.966,0.53023,9.20623,7.5,,,,,,,,,,,,,,,,,,,,,,,,,,,,,,,,,,,,,
58.466,0.44682,5.45684,7.5,,,,,,,,,,,,,,,,,,,,,,,,,,,,,,,,,,,,,
58.966,0.36357,2.6672,7.5,,,,,,,,,,,,,,,,,,,,,,,,,,,,,,,,,,,,,
59.3,0.30787,0.98608,8,,,,,,,,,,,,,,,,,,,,,,,,,,,,,,,,,,,,,
59.702,0.37508,3.10591,8,,,,,,,,,,,,,,,,,,,,,,,,,,,,,,,,,,,,,
60.202,0.45866,6.60872,8,,,,,,,,,,,,,,,,,,,,,,,,,,,,,,,,,,,,,
60.702,0.54179,10.96269,8,,,,,,,,,,,,,,,,,,,,,,,,,,,,,,,,,,,,,
61.202,0.6252,15.9839,8,,,,,,,,,,,,,,,,,,,,,,,,,,,,,,,,,,,,,
61.702,0.70845,21.15043,8,,,,,,,,,,,,,,,,,,,,,,,,,,,,,,,,,,,,,
62.202,0.79192,28.29662,8,,,,,,,,,,,,,,,,,,,,,,,,,,,,,,,,,,,,,
62.702,0.8751,36.65508,8,,,,,,,,,,,,,,,,,,,,,,,,,,,,,,,,,,,,,
63.08,0.87176,36.13966,8.5,,,,,,,,,,,,,,,,,,,,,,,,,,,,,,,,,,,,,
63.58,0.78789,26.04744,8.5,,,,,,,,,,,,,,,,,,,,,,,,,,,,,,,,,,,,,
64.08,0.70459,18.54665,8.5,,,,,,,,,,,,,,,,,,,,,,,,,,,,,,,,,,,,,
64.58,0.62129,13.17644,8.5,,,,,,,,,,,,,,,,,,,,,,,,,,,,,,,,,,,,,
65.08,0.53788,9.09148,8.5,,,,,,,,,,,,,,,,,,,,,,,,,,,,,,,,,,,,,
65.58,0.45452,5.42929,8.5,,,,,,,,,,,,,,,,,,,,,,,,,,,,,,,,,,,,,
66.08,0.37117,2.5006,8.5,,,,,,,,,,,,,,,,,,,,,,,,,,,,,,,,,,,,,
66.408,0.31637,0.98949,9,,,,,,,,,,,,,,,,,,,,,,,,,,,,,,,,,,,,,
66.81,0.3838,3.07159,9,,,,,,,,,,,,,,,,,,,,,,,,,,,,,,,,,,,,,
67.31,0.46716,6.64028,9,,,,,,,,,,,,,,,,,,,,,,,,,,,,,,,,,,,,,
67.81,0.55035,10.86291,9,,,,,,,,,,,,,,,,,,,,,,,,,,,,,,,,,,,,,
68.31,0.63382,16.04043,9,,,,,,,,,,,,,,,,,,,,,,,,,,,,,,,,,,,,,
68.81,0.71712,21.2662,9,,,,,,,,,,,,,,,,,,,,,,,,,,,,,,,,,,,,,
69.31,0.80059,28.4052,9,,,,,,,,,,,,,,,,,,,,,,,,,,,,,,,,,,,,,
69.81,0.88377,36.8617,9,,,,,,,,,,,,,,,,,,,,,,,,,,,,,,,,,,,,,
70.176,0.87839,36.15715,9.5,,,,,,,,,,,,,,,,,,,,,,,,,,,,,,,,,,,,,
70.676,0.79464,26.01648,9.5,,,,,,,,,,,,,,,,,,,,,,,,,,,,,,,,,,,,,
71.176,0.71122,18.52906,9.5,,,,,,,,,,,,,,,,,,,,,,,,,,,,,,,,,,,,,
71.676,0.62792,13.12048,9.5,,,,,,,,,,,,,,,,,,,,,,,,,,,,,,,,,,,,,
72.176,0.54451,9.05834,9.5,,,,,,,,,,,,,,,,,,,,,,,,,,,,,,,,,,,,,
72.676,0.46127,5.30849,9.5,,,,,,,,,,,,,,,,,,,,,,,,,,,,,,,,,,,,,
73.176,0.37774,2.45314,9.5,,,,,,,,,,,,,,,,,,,,,,,,,,,,,,,,,,,,,
73.492,0.32498,0.9769,10,,,,,,,,,,,,,,,,,,,,,,,,,,,,,,,,,,,,,
73.992,0.29121,0.27964,10,,,,,,,,,,,,,,,,,,,,,,,,,,,,,,,,,,,,,
74.492,0.29319,0.33591,10,,,,,,,,,,,,,,,,,,,,,,,,,,,,,,,,,,,,,
74.992,0.31892,1.12579,10,,,,,,,,,,,,,,,,,,,,,,,,,,,,,,,,,,,,,
75.492,0.3247,1.26108,10,,,,,,,,,,,,,,,,,,,,,,,,,,,,,,,,,,,,,
75.992,0.32266,1.37487,10,,,,,,,,,,,,,,,,,,,,,,,,,,,,,,,,,,,,,
76.492,0.30946,0.8378,10,,,,,,,,,,,,,,,,,,,,,,,,,,,,,,,,,,,,,
76.992,0.30526,0.81481,10,,,,,,,,,,,,,,,,,,,,,,,,,,,,,,,,,,,,,
77.492,0.30515,0.83966,10,,,,,,,,,,,,,,,,,,,,,,,,,,,,,,,,,,,,,
77.992,0.30532,0.92249,10,,,,,,,,,,,,,,,,,,,,,,,,,,,,,,,,,,,,,
78.492,0.30538,0.82756,10,,,,,,,,,,,,,,,,,,,,,,,,,,,,,,,,,,,,,
78.992,0.30543,0.94329,10,,,,,,,,,,,,,,,,,,,,,,,,,,,,,,,,,,,,,
79.492,0.30555,0.89011,10,,,,,,,,,,,,,,,,,,,,,,,,,,,,,,,,,,,,,
79.992,0.3056,0.88857,10,,,,,,,,,,,,,,,,,,,,,,,,,,,,,,,,,,,,,
80.492,0.30566,0.8815,10,,,,,,,,,,,,,,,,,,,,,,,,,,,,,,,,,,,,,
80.992,0.30572,0.94056,10,,,,,,,,,,,,,,,,,,,,,,,,,,,,,,,,,,,,,
81.492,0.30577,0.89269,10,,,,,,,,,,,,,,,,,,,,,,,,,,,,,,,,,,,,,
81.992,0.30589,0.9781,10,,,,,,,,,,,,,,,,,,,,,,,,,,,,,,,,,,,,,
82.492,0.30594,0.91463,10,,,,,,,,,,,,,,,,,,,,,,,,,,,,,,,,,,,,,
82.992,0.306,0.96676,10,,,,,,,,,,,,,,,,,,,,,,,,,,,,,,,,,,,,,
83.492,0.306,0.97307,10,,,,,,,,,,,,,,,,,,,,,,,,,,,,,,,,,,,,,
83.992,0.30589,1.03492,10,,,,,,,,,,,,,,,,,,,,,,,,,,,,,,,,,,,,,
84.492,0.30583,0.95706,10,,,,,,,,,,,,,,,,,,,,,,,,,,,,,,,,,,,,,
84.992,0.30577,1.01282,10,,,,,,,,,,,,,,,,,,,,,,,,,,,,,,,,,,,,,
85.492,0.30583,0.91875,10,,,,,,,,,,,,,,,,,,,,,,,,,,,,,,,,,,,,,
85.992,0.30572,0.96344,10,,,,,,,,,,,,,,,,,,,,,,,,,,,,,,,,,,,,,
86.492,0.3056,1.01539,10,,,,,,,,,,,,,,,,,,,,,,,,,,,,,,,,,,,,,
86.992,0.30538,0.99058,10,,,,,,,,,,,,,,,,,,,,,,,,,,,,,,,,,,,,,
87.492,0.30521,0.95899,10,,,,,,,,,,,,,,,,,,,,,,,,,,,,,,,,,,,,,
87.992,0.30396,1.04335,10,,,,,,,,,,,,,,,,,,,,,,,,,,,,,,,,,,,,,
88.492,0.30192,0.87851,10,,,,,,,,,,,,,,,,,,,,,,,,,,,,,,,,,,,,,
88.992,0.30096,0.88773,10,,,,,,,,,,,,,,,,,,,,,,,,,,,,,,,,,,,,,
89.492,0.30073,0.87984,10,,,,,,,,,,,,,,,,,,,,,,,,,,,,,,,,,,,,,
89.992,0.30067,0.86382,10,,,,,,,,,,,,,,,,,,,,,,,,,,,,,,,,,,,,,
90.492,0.30079,0.87061,10,,,,,,,,,,,,,,,,,,,,,,,,,,,,,,,,,,,,,
90.992,0.3009,0.87502,10,,,,,,,,,,,,,,,,,,,,,,,,,,,,,,,,,,,,,
91.492,0.3009,0.87909,10,,,,,,,,,,,,,,,,,,,,,,,,,,,,,,,,,,,,,
91.992,0.30096,0.85778,10,,,,,,,,,,,,,,,,,,,,,,,,,,,,,,,,,,,,,
92.492,0.30096,0.84645,10,,,,,,,,,,,,,,,,,,,,,,,,,,,,,,,,,,,,,
92.992,0.30096,0.94415,10,,,,,,,,,,,,,,,,,,,,,,,,,,,,,,,,,,,,,
93.492,0.30096,0.85394,10,,,,,,,,,,,,,,,,,,,,,,,,,,,,,,,,,,,,,
93.992,0.30101,0.9083,10,,,,,,,,,,,,,,,,,,,,,,,,,,,,,,,,,,,,,
94.492,0.30101,0.88857,10,,,,,,,,,,,,,,,,,,,,,,,,,,,,,,,,,,,,,
94.992,0.30101,0.90158,10,,,,,,,,,,,,,,,,,,,,,,,,,,,,,,,,,,,,,
95.492,0.30101,0.87019,10,,,,,,,,,,,,,,,,,,,,,,,,,,,,,,,,,,,,,
95.992,0.30096,0.92263,10,,,,,,,,,,,,,,,,,,,,,,,,,,,,,,,,,,,,,
96.492,0.30096,0.92188,10,,,,,,,,,,,,,,,,,,,,,,,,,,,,,,,,,,,,,
96.992,0.30096,0.88199,10,,,,,,,,,,,,,,,,,,,,,,,,,,,,,,,,,,,,,
97.492,0.30096,0.95728,10,,,,,,,,,,,,,,,,,,,,,,,,,,,,,,,,,,,,,
97.992,0.30101,0.91209,10,,,,,,,,,,,,,,,,,,,,,,,,,,,,,,,,,,,,,
98.492,0.30101,0.91261,10,,,,,,,,,,,,,,,,,,,,,,,,,,,,,,,,,,,,,
98.992,0.30096,0.97373,10,,,,,,,,,,,,,,,,,,,,,,,,,,,,,,,,,,,,,
99.492,0.30101,0.89426,10,,,,,,,,,,,,,,,,,,,,,,,,,,,,,,,,,,,,,
99.992,0.30101,0.97362,10,,,,,,,,,,,,,,,,,,,,,,,,,,,,,,,,,,,,,
100.492,0.30101,0.88798,10,,,,,,,,,,,,,,,,,,,,,,,,,,,,,,,,,,,,,
100.992,0.30101,0.86295,10,,,,,,,,,,,,,,,,,,,,,,,,,,,,,,,,,,,,,
101.492,0.30101,0.94637,10,,,,,,,,,,,,,,,,,,,,,,,,,,,,,,,,,,,,,
101.992,0.30101,0.94493,10,,,,,,,,,,,,,,,,,,,,,,,,,,,,,,,,,,,,,
102.492,0.30101,0.90218,10,,,,,,,,,,,,,,,,,,,,,,,,,,,,,,,,,,,,,
102.992,0.3009,0.96208,10,,,,,,,,,,,,,,,,,,,,,,,,,,,,,,,,,,,,,
103.492,0.3009,0.89561,10,,,,,,,,,,,,,,,,,,,,,,,,,,,,,,,,,,,,,
103.992,0.3009,0.90062,10,,,,,,,,,,,,,,,,,,,,,,,,,,,,,,,,,,,,,
104.492,0.3009,0.87332,10,,,,,,,,,,,,,,,,,,,,,,,,,,,,,,,,,,,,,
104.992,0.3009,0.92759,10,,,,,,,,,,,,,,,,,,,,,,,,,,,,,,,,,,,,,
105.492,0.3009,0.91133,10,,,,,,,,,,,,,,,,,,,,,,,,,,,,,,,,,,,,,
105.992,0.3009,0.95532,10,,,,,,,,,,,,,,,,,,,,,,,,,,,,,,,,,,,,,
106.492,0.3009,0.87362,10,,,,,,,,,,,,,,,,,,,,,,,,,,,,,,,,,,,,,
106.992,0.3009,0.86856,10,,,,,,,,,,,,,,,,,,,,,,,,,,,,,,,,,,,,,
107.492,0.30101,0.90853,10,,,,,,,,,,,,,,,,,,,,,,,,,,,,,,,,,,,,,
107.992,0.3009,0.90582,10,,,,,,,,,,,,,,,,,,,,,,,,,,,,,,,,,,,,,
108.492,0.3009,0.88988,10,,,,,,,,,,,,,,,,,,,,,,,,,,,,,,,,,,,,,
108.992,0.3009,0.89549,10,,,,,,,,,,,,,,,,,,,,,,,,,,,,,,,,,,,,,
109.492,0.3009,0.92388,10,,,,,,,,,,,,,,,,,,,,,,,,,,,,,,,,,,,,,
109.992,0.3009,0.91877,10,,,,,,,,,,,,,,,,,,,,,,,,,,,,,,,,,,,,,
110.492,0.30101,0.96143,10,,,,,,,,,,,,,,,,,,,,,,,,,,,,,,,,,,,,,
110.992,0.3009,0.91862,10,,,,,,,,,,,,,,,,,,,,,,,,,,,,,,,,,,,,,
111.492,0.30101,0.94265,10,,,,,,,,,,,,,,,,,,,,,,,,,,,,,,,,,,,,,
111.992,0.3009,0.9732,10,,,,,,,,,,,,,,,,,,,,,,,,,,,,,,,,,,,,,
112.492,0.30084,0.91953,10,,,,,,,,,,,,,,,,,,,,,,,,,,,,,,,,,,,,,
112.992,0.30084,0.96583,10,,,,,,,,,,,,,,,,,,,,,,,,,,,,,,,,,,,,,
113.492,0.30079,0.95474,10,,,,,,,,,,,,,,,,,,,,,,,,,,,,,,,,,,,,,
113.992,0.30079,0.92392,10,,,,,,,,,,,,,,,,,,,,,,,,,,,,,,,,,,,,,
114.492,0.30073,1.00099,10,,,,,,,,,,,,,,,,,,,,,,,,,,,,,,,,,,,,,
114.992,0.30073,0.97448,10,,,,,,,,,,,,,,,,,,,,,,,,,,,,,,,,,,,,,
115.492,0.30067,0.94726,10,,,,,,,,,,,,,,,,,,,,,,,,,,,,,,,,,,,,,
115.992,0.30056,0.90992,10,,,,,,,,,,,,,,,,,,,,,,,,,,,,,,,,,,,,,
116.492,0.30033,0.9488,10,,,,,,,,,,,,,,,,,,,,,,,,,,,,,,,,,,,,,
116.992,0.29977,0.93725,10,,,,,,,,,,,,,,,,,,,,,,,,,,,,,,,,,,,,,
117.492,0.2992,0.89894,10,,,,,,,,,,,,,,,,,,,,,,,,,,,,,,,,,,,,,
117.992,0.2988,0.9237,10,,,,,,,,,,,,,,,,,,,,,,,,,,,,,,,,,,,,,
118.492,0.29858,0.86935,10,,,,,,,,,,,,,,,,,,,,,,,,,,,,,,,,,,,,,
118.992,0.29846,0.86228,10,,,,,,,,,,,,,,,,,,,,,,,,,,,,,,,,,,,,,
119.492,0.29846,0.89462,10,,,,,,,,,,,,,,,,,,,,,,,,,,,,,,,,,,,,,
119.992,0.29846,0.83391,10,,,,,,,,,,,,,,,,,,,,,,,,,,,,,,,,,,,,,
120.492,0.29858,0.84803,10,,,,,,,,,,,,,,,,,,,,,,,,,,,,,,,,,,,,,
120.992,0.29863,0.87651,10,,,,,,,,,,,,,,,,,,,,,,,,,,,,,,,,,,,,,
121.492,0.29869,0.85872,10,,,,,,,,,,,,,,,,,,,,,,,,,,,,,,,,,,,,,
121.992,0.29875,0.84604,10,,,,,,,,,,,,,,,,,,,,,,,,,,,,,,,,,,,,,
122.492,0.2988,0.84775,10,,,,,,,,,,,,,,,,,,,,,,,,,,,,,,,,,,,,,
122.992,0.29892,0.86327,10,,,,,,,,,,,,,,,,,,,,,,,,,,,,,,,,,,,,,
123.492,0.29903,0.82172,10,,,,,,,,,,,,,,,,,,,,,,,,,,,,,,,,,,,,,
123.992,0.29926,0.87995,10,,,,,,,,,,,,,,,,,,,,,,,,,,,,,,,,,,,,,
124.492,0.29954,0.83949,10,,,,,,,,,,,,,,,,,,,,,,,,,,,,,,,,,,,,,
124.992,0.29999,0.84609,10,,,,,,,,,,,,,,,,,,,,,,,,,,,,,,,,,,,,,
125.492,0.30062,0.8826,10,,,,,,,,,,,,,,,,,,,,,,,,,,,,,,,,,,,,,
125.992,0.30118,0.9524,10,,,,,,,,,,,,,,,,,,,,,,,,,,,,,,,,,,,,,
126.492,0.30135,0.89835,10,,,,,,,,,,,,,,,,,,,,,,,,,,,,,,,,,,,,,
126.992,0.30147,0.93524,10,,,,,,,,,,,,,,,,,,,,,,,,,,,,,,,,,,,,,
127.492,0.30152,0.97185,10,,,,,,,,,,,,,,,,,,,,,,,,,,,,,,,,,,,,,
127.992,0.30141,0.93167,10,,,,,,,,,,,,,,,,,,,,,,,,,,,,,,,,,,,,,
128.492,0.30141,1.01388,10,,,,,,,,,,,,,,,,,,,,,,,,,,,,,,,,,,,,,
128.992,0.30135,0.98878,10,,,,,,,,,,,,,,,,,,,,,,,,,,,,,,,,,,,,,
129.492,0.30135,0.87754,10,,,,,,,,,,,,,,,,,,,,,,,,,,,,,,,,,,,,,
129.992,0.30135,0.94166,10,,,,,,,,,,,,,,,,,,,,,,,,,,,,,,,,,,,,,
130.492,0.30135,0.91188,10,,,,,,,,,,,,,,,,,,,,,,,,,,,,,,,,,,,,,
130.992,0.3013,0.92161,10,,,,,,,,,,,,,,,,,,,,,,,,,,,,,,,,,,,,,
131.492,0.30124,1.00795,10,,,,,,,,,,,,,,,,,,,,,,,,,,,,,,,,,,,,,
131.992,0.30118,0.95797,10,,,,,,,,,,,,,,,,,,,,,,,,,,,,,,,,,,,,,
132.492,0.30118,0.90183,10,,,,,,,,,,,,,,,,,,,,,,,,,,,,,,,,,,,,,
132.992,0.30113,0.98743,10,,,,,,,,,,,,,,,,,,,,,,,,,,,,,,,,,,,,,
133.492,0.30113,0.92943,10,,,,,,,,,,,,,,,,,,,,,,,,,,,,,,,,,,,,,
133.992,0.30113,0.92901,10,,,,,,,,,,,,,,,,,,,,,,,,,,,,,,,,,,,,,
134.492,0.30107,0.89275,10,,,,,,,,,,,,,,,,,,,,,,,,,,,,,,,,,,,,,
134.992,0.30101,0.97974,10,,,,,,,,,,,,,,,,,,,,,,,,,,,,,,,,,,,,,
135.492,0.3009,0.96254,10,,,,,,,,,,,,,,,,,,,,,,,,,,,,,,,,,,,,,
135.992,0.30079,0.92576,10,,,,,,,,,,,,,,,,,,,,,,,,,,,,,,,,,,,,,
136.492,0.30067,0.92207,10,,,,,,,,,,,,,,,,,,,,,,,,,,,,,,,,,,,,,
136.992,0.30056,0.94721,10,,,,,,,,,,,,,,,,,,,,,,,,,,,,,,,,,,,,,
137.492,0.30045,0.9216,10,,,,,,,,,,,,,,,,,,,,,,,,,,,,,,,,,,,,,
137.992,0.30039,0.89096,10,,,,,,,,,,,,,,,,,,,,,,,,,,,,,,,,,,,,,
138.492,0.30033,0.94897,10,,,,,,,,,,,,,,,,,,,,,,,,,,,,,,,,,,,,,
138.992,0.30022,0.91816,10,,,,,,,,,,,,,,,,,,,,,,,,,,,,,,,,,,,,,
139.492,0.30022,0.83305,10,,,,,,,,,,,,,,,,,,,,,,,,,,,,,,,,,,,,,
139.992,0.30033,0.82714,10,,,,,,,,,,,,,,,,,,,,,,,,,,,,,,,,,,,,,
140.492,0.30028,0.92487,10,,,,,,,,,,,,,,,,,,,,,,,,,,,,,,,,,,,,,
140.992,0.30033,0.90294,10,,,,,,,,,,,,,,,,,,,,,,,,,,,,,,,,,,,,,
141.492,0.30033,0.9371,10,,,,,,,,,,,,,,,,,,,,,,,,,,,,,,,,,,,,,
141.992,0.30033,0.95039,10,,,,,,,,,,,,,,,,,,,,,,,,,,,,,,,,,,,,,
142.492,0.30033,0.91524,10,,,,,,,,,,,,,,,,,,,,,,,,,,,,,,,,,,,,,
142.992,0.30028,0.93751,10,,,,,,,,,,,,,,,,,,,,,,,,,,,,,,,,,,,,,
143.492,0.30022,0.8613,10,,,,,,,,,,,,,,,,,,,,,,,,,,,,,,,,,,,,,
143.992,0.30022,0.89482,10,,,,,,,,,,,,,,,,,,,,,,,,,,,,,,,,,,,,,
144.492,0.30016,0.88407,10,,,,,,,,,,,,,,,,,,,,,,,,,,,,,,,,,,,,,
144.992,0.30016,0.94875,10,,,,,,,,,,,,,,,,,,,,,,,,,,,,,,,,,,,,,
145.492,0.30028,0.88326,10,,,,,,,,,,,,,,,,,,,,,,,,,,,,,,,,,,,,,
145.992,0.30028,0.86937,10,,,,,,,,,,,,,,,,,,,,,,,,,,,,,,,,,,,,,
146.492,0.30028,0.92074,10,,,,,,,,,,,,,,,,,,,,,,,,,,,,,,,,,,,,,
146.992,0.30033,0.86804,10,,,,,,,,,,,,,,,,,,,,,,,,,,,,,,,,,,,,,
147.492,0.30039,0.82998,10,,,,,,,,,,,,,,,,,,,,,,,,,,,,,,,,,,,,,
147.992,0.30039,0.85232,10,,,,,,,,,,,,,,,,,,,,,,,,,,,,,,,,,,,,,
148.492,0.3005,0.86166,10,,,,,,,,,,,,,,,,,,,,,,,,,,,,,,,,,,,,,
148.992,0.30056,0.84489,10,,,,,,,,,,,,,,,,,,,,,,,,,,,,,,,,,,,,,
149.492,0.30067,0.88712,10,,,,,,,,,,,,,,,,,,,,,,,,,,,,,,,,,,,,,
149.992,0.30073,0.88321,10,,,,,,,,,,,,,,,,,,,,,,,,,,,,,,,,,,,,,
150.492,0.30084,0.84977,10,,,,,,,,,,,,,,,,,,,,,,,,,,,,,,,,,,,,,
150.992,0.30107,0.90882,10,,,,,,,,,,,,,,,,,,,,,,,,,,,,,,,,,,,,,
151.492,0.30124,0.87072,10,,,,,,,,,,,,,,,,,,,,,,,,,,,,,,,,,,,,,
151.992,0.30152,0.84896,10,,,,,,,,,,,,,,,,,,,,,,,,,,,,,,,,,,,,,
152.492,0.30198,0.91116,10,,,,,,,,,,,,,,,,,,,,,,,,,,,,,,,,,,,,,
152.992,0.3026,0.95011,10,,,,,,,,,,,,,,,,,,,,,,,,,,,,,,,,,,,,,
153.492,0.30305,0.91143,10,,,,,,,,,,,,,,,,,,,,,,,,,,,,,,,,,,,,,
153.992,0.30328,0.9862,10,,,,,,,,,,,,,,,,,,,,,,,,,,,,,,,,,,,,,
154.492,0.30339,0.90846,10,,,,,,,,,,,,,,,,,,,,,,,,,,,,,,,,,,,,,
154.992,0.30339,0.90722,10,,,,,,,,,,,,,,,,,,,,,,,,,,,,,,,,,,,,,
155.492,0.30334,0.94914,10,,,,,,,,,,,,,,,,,,,,,,,,,,,,,,,,,,,,,
155.992,0.30334,0.96156,10,,,,,,,,,,,,,,,,,,,,,,,,,,,,,,,,,,,,,
156.492,0.30328,0.96312,10,,,,,,,,,,,,,,,,,,,,,,,,,,,,,,,,,,,,,
156.992,0.30328,0.97731,10,,,,,,,,,,,,,,,,,,,,,,,,,,,,,,,,,,,,,
157.492,0.30322,0.94011,10,,,,,,,,,,,,,,,,,,,,,,,,,,,,,,,,,,,,,
157.992,0.30322,0.89266,10,,,,,,,,,,,,,,,,,,,,,,,,,,,,,,,,,,,,,
158.492,0.30317,0.96293,10,,,,,,,,,,,,,,,,,,,,,,,,,,,,,,,,,,,,,
158.992,0.30317,0.88964,10,,,,,,,,,,,,,,,,,,,,,,,,,,,,,,,,,,,,,
159.492,0.30311,0.89791,10,,,,,,,,,,,,,,,,,,,,,,,,,,,,,,,,,,,,,
159.992,0.30311,0.92824,10,,,,,,,,,,,,,,,,,,,,,,,,,,,,,,,,,,,,,
160.492,0.30305,0.90925,10,,,,,,,,,,,,,,,,,,,,,,,,,,,,,,,,,,,,,
160.992,0.30305,0.87092,10,,,,,,,,,,,,,,,,,,,,,,,,,,,,,,,,,,,,,
161.492,0.30305,0.92019,10,,,,,,,,,,,,,,,,,,,,,,,,,,,,,,,,,,,,,
161.992,0.303,0.91928,10,,,,,,,,,,,,,,,,,,,,,,,,,,,,,,,,,,,,,
162.492,0.30294,0.93851,10,,,,,,,,,,,,,,,,,,,,,,,,,,,,,,,,,,,,,
162.992,0.30283,0.91653,10,,,,,,,,,,,,,,,,,,,,,,,,,,,,,,,,,,,,,
163.492,0.30271,0.93319,10,,,,,,,,,,,,,,,,,,,,,,,,,,,,,,,,,,,,,
163.992,0.30266,0.898,10,,,,,,,,,,,,,,,,,,,,,,,,,,,,,,,,,,,,,
164.492,0.30254,0.93988,10,,,,,,,,,,,,,,,,,,,,,,,,,,,,,,,,,,,,,
164.992,0.30243,0.94916,10,,,,,,,,,,,,,,,,,,,,,,,,,,,,,,,,,,,,,
165.492,0.30232,0.85424,10,,,,,,,,,,,,,,,,,,,,,,,,,,,,,,,,,,,,,
165.992,0.30232,0.90759,10,,,,,,,,,,,,,,,,,,,,,,,,,,,,,,,,,,,,,
166.492,0.30232,0.94063,10,,,,,,,,,,,,,,,,,,,,,,,,,,,,,,,,,,,,,
166.992,0.30232,0.84266,10,,,,,,,,,,,,,,,,,,,,,,,,,,,,,,,,,,,,,
167.492,0.30232,0.883,10,,,,,,,,,,,,,,,,,,,,,,,,,,,,,,,,,,,,,
167.992,0.30243,0.93223,10,,,,,,,,,,,,,,,,,,,,,,,,,,,,,,,,,,,,,
168.492,0.30237,0.94635,10,,,,,,,,,,,,,,,,,,,,,,,,,,,,,,,,,,,,,
168.992,0.30237,0.89981,10,,,,,,,,,,,,,,,,,,,,,,,,,,,,,,,,,,,,,
169.492,0.30249,0.84977,10,,,,,,,,,,,,,,,,,,,,,,,,,,,,,,,,,,,,,
169.992,0.30249,0.90958,10,,,,,,,,,,,,,,,,,,,,,,,,,,,,,,,,,,,,,
170.492,0.30249,0.89143,10,,,,,,,,,,,,,,,,,,,,,,,,,,,,,,,,,,,,,
170.992,0.30249,0.91992,10,,,,,,,,,,,,,,,,,,,,,,,,,,,,,,,,,,,,,
171.492,0.30249,0.89847,10,,,,,,,,,,,,,,,,,,,,,,,,,,,,,,,,,,,,,
171.992,0.30254,0.95403,10,,,,,,,,,,,,,,,,,,,,,,,,,,,,,,,,,,,,,
172.492,0.30254,0.85637,10,,,,,,,,,,,,,,,,,,,,,,,,,,,,,,,,,,,,,
172.992,0.3026,0.85489,10,,,,,,,,,,,,,,,,,,,,,,,,,,,,,,,,,,,,,
173.492,0.30266,0.97359,10,,,,,,,,,,,,,,,,,,,,,,,,,,,,,,,,,,,,,
173.992,0.30271,0.87368,10,,,,,,,,,,,,,,,,,,,,,,,,,,,,,,,,,,,,,
174.492,0.30277,0.86073,10,,,,,,,,,,,,,,,,,,,,,,,,,,,,,,,,,,,,,
174.992,0.30277,0.97143,10,,,,,,,,,,,,,,,,,,,,,,,,,,,,,,,,,,,,,
175.492,0.30283,0.86174,10,,,,,,,,,,,,,,,,,,,,,,,,,,,,,,,,,,,,,
175.992,0.30294,0.87213,10,,,,,,,,,,,,,,,,,,,,,,,,,,,,,,,,,,,,,
176.492,0.30317,0.87948,10,,,,,,,,,,,,,,,,,,,,,,,,,,,,,,,,,,,,,
176.992,0.30334,0.89407,10,,,,,,,,,,,,,,,,,,,,,,,,,,,,,,,,,,,,,
177.492,0.30362,0.86841,10,,,,,,,,,,,,,,,,,,,,,,,,,,,,,,,,,,,,,
177.992,0.30396,0.91758,10,,,,,,,,,,,,,,,,,,,,,,,,,,,,,,,,,,,,,
178.492,0.30419,0.95265,10,,,,,,,,,,,,,,,,,,,,,,,,,,,,,,,,,,,,,
178.992,0.30441,0.91775,10,,,,,,,,,,,,,,,,,,,,,,,,,,,,,,,,,,,,,
179.492,0.30458,0.93917,10,,,,,,,,,,,,,,,,,,,,,,,,,,,,,,,,,,,,,
179.992,0.30481,0.93528,10,,,,,,,,,,,,,,,,,,,,,,,,,,,,,,,,,,,,,
180.492,0.30487,0.92744,10,,,,,,,,,,,,,,,,,,,,,,,,,,,,,,,,,,,,,
180.992,0.30487,0.95635,10,,,,,,,,,,,,,,,,,,,,,,,,,,,,,,,,,,,,,
181.492,0.30487,0.89681,10,,,,,,,,,,,,,,,,,,,,,,,,,,,,,,,,,,,,,
181.992,0.30475,0.89309,10,,,,,,,,,,,,,,,,,,,,,,,,,,,,,,,,,,,,,
182.492,0.30475,0.94389,10,,,,,,,,,,,,,,,,,,,,,,,,,,,,,,,,,,,,,
182.992,0.30481,0.95496,10,,,,,,,,,,,,,,,,,,,,,,,,,,,,,,,,,,,,,
183.492,0.30481,0.86605,10,,,,,,,,,,,,,,,,,,,,,,,,,,,,,,,,,,,,,
183.992,0.3047,0.93681,10,,,,,,,,,,,,,,,,,,,,,,,,,,,,,,,,,,,,,
184.492,0.30475,0.91413,10,,,,,,,,,,,,,,,,,,,,,,,,,,,,,,,,,,,,,
184.992,0.30475,0.89256,10,,,,,,,,,,,,,,,,,,,,,,,,,,,,,,,,,,,,,
185.492,0.3047,0.93289,10,,,,,,,,,,,,,,,,,,,,,,,,,,,,,,,,,,,,,
185.992,0.3047,0.908,10,,,,,,,,,,,,,,,,,,,,,,,,,,,,,,,,,,,,,
186.492,0.30458,0.93611,10,,,,,,,,,,,,,,,,,,,,,,,,,,,,,,,,,,,,,
186.992,0.30458,0.90562,10,,,,,,,,,,,,,,,,,,,,,,,,,,,,,,,,,,,,,
187.492,0.30458,0.91094,10,,,,,,,,,,,,,,,,,,,,,,,,,,,,,,,,,,,,,
187.992,0.30458,0.87665,10,,,,,,,,,,,,,,,,,,,,,,,,,,,,,,,,,,,,,
188.492,0.30464,0.92447,10,,,,,,,,,,,,,,,,,,,,,,,,,,,,,,,,,,,,,
188.992,0.30464,0.9245,10,,,,,,,,,,,,,,,,,,,,,,,,,,,,,,,,,,,,,
189.492,0.30464,0.89069,10,,,,,,,,,,,,,,,,,,,,,,,,,,,,,,,,,,,,,
189.992,0.30464,0.95814,10,,,,,,,,,,,,,,,,,,,,,,,,,,,,,,,,,,,,,
190.492,0.30453,0.91354,10,,,,,,,,,,,,,,,,,,,,,,,,,,,,,,,,,,,,,
190.992,0.30453,0.88913,10,,,,,,,,,,,,,,,,,,,,,,,,,,,,,,,,,,,,,
191.492,0.30453,0.9204,10,,,,,,,,,,,,,,,,,,,,,,,,,,,,,,,,,,,,,
191.992,0.30453,0.9151,10,,,,,,,,,,,,,,,,,,,,,,,,,,,,,,,,,,,,,
192.492,0.30453,0.90916,10,,,,,,,,,,,,,,,,,,,,,,,,,,,,,,,,,,,,,
192.992,0.30453,0.9291,10,,,,,,,,,,,,,,,,,,,,,,,,,,,,,,,,,,,,,
193.492,0.30453,0.88549,10,,,,,,,,,,,,,,,,,,,,,,,,,,,,,,,,,,,,,
193.992,0.30453,0.90252,10,,,,,,,,,,,,,,,,,,,,,,,,,,,,,,,,,,,,,
194.492,0.30447,0.97926,10,,,,,,,,,,,,,,,,,,,,,,,,,,,,,,,,,,,,,
194.992,0.30447,0.91879,10,,,,,,,,,,,,,,,,,,,,,,,,,,,,,,,,,,,,,
195.492,0.30447,0.97035,10,,,,,,,,,,,,,,,,,,,,,,,,,,,,,,,,,,,,,
195.992,0.30447,0.94888,10,,,,,,,,,,,,,,,,,,,,,,,,,,,,,,,,,,,,,
196.492,0.30447,0.90341,10,,,,,,,,,,,,,,,,,,,,,,,,,,,,,,,,,,,,,
196.992,0.30447,0.84939,10,,,,,,,,,,,,,,,,,,,,,,,,,,,,,,,,,,,,,
197.492,0.30447,0.94796,10,,,,,,,,,,,,,,,,,,,,,,,,,,,,,,,,,,,,,
197.992,0.30447,0.90661,10,,,,,,,,,,,,,,,,,,,,,,,,,,,,,,,,,,,,,
198.492,0.30458,0.89108,10,,,,,,,,,,,,,,,,,,,,,,,,,,,,,,,,,,,,,
198.992,0.30458,0.92207,10,,,,,,,,,,,,,,,,,,,,,,,,,,,,,,,,,,,,,
199.492,0.30458,0.89641,10,,,,,,,,,,,,,,,,,,,,,,,,,,,,,,,,,,,,,
199.992,0.30464,0.86731,10,,,,,,,,,,,,,,,,,,,,,,,,,,,,,,,,,,,,,
200.492,0.30464,0.87168,10,,,,,,,,,,,,,,,,,,,,,,,,,,,,,,,,,,,,,
200.992,0.3047,0.925,10,,,,,,,,,,,,,,,,,,,,,,,,,,,,,,,,,,,,,
201.492,0.3047,0.86323,10,,,,,,,,,,,,,,,,,,,,,,,,,,,,,,,,,,,,,
201.992,0.30475,0.89131,10,,,,,,,,,,,,,,,,,,,,,,,,,,,,,,,,,,,,,
202.492,0.30481,0.8917,10,,,,,,,,,,,,,,,,,,,,,,,,,,,,,,,,,,,,,
202.992,0.30487,0.84675,10,,,,,,,,,,,,,,,,,,,,,,,,,,,,,,,,,,,,,
203.492,0.30504,0.92684,10,,,,,,,,,,,,,,,,,,,,,,,,,,,,,,,,,,,,,
203.992,0.30532,0.88402,10,,,,,,,,,,,,,,,,,,,,,,,,,,,,,,,,,,,,,
204.492,0.30645,0.83254,10,,,,,,,,,,,,,,,,,,,,,,,,,,,,,,,,,,,,,
204.992,0.30736,1.00959,10,,,,,,,,,,,,,,,,,,,,,,,,,,,,,,,,,,,,,
205.492,0.3077,0.93097,10,,,,,,,,,,,,,,,,,,,,,,,,,,,,,,,,,,,,,
205.992,0.30787,0.91735,10,,,,,,,,,,,,,,,,,,,,,,,,,,,,,,,,,,,,,
206.492,0.30793,0.94335,10,,,,,,,,,,,,,,,,,,,,,,,,,,,,,,,,,,,,,
206.992,0.30781,0.99527,10,,,,,,,,,,,,,,,,,,,,,,,,,,,,,,,,,,,,,
207.492,0.30781,0.9217,10,,,,,,,,,,,,,,,,,,,,,,,,,,,,,,,,,,,,,
207.992,0.30776,0.95347,10,,,,,,,,,,,,,,,,,,,,,,,,,,,,,,,,,,,,,
208.492,0.30776,0.94413,10,,,,,,,,,,,,,,,,,,,,,,,,,,,,,,,,,,,,,
208.992,0.3077,0.92556,10,,,,,,,,,,,,,,,,,,,,,,,,,,,,,,,,,,,,,
209.492,0.30764,0.94008,10,,,,,,,,,,,,,,,,,,,,,,,,,,,,,,,,,,,,,
209.992,0.30759,0.94534,10,,,,,,,,,,,,,,,,,,,,,,,,,,,,,,,,,,,,,
210.492,0.30747,0.9496,10,,,,,,,,,,,,,,,,,,,,,,,,,,,,,,,,,,,,,
210.992,0.30736,0.9776,10,,,,,,,,,,,,,,,,,,,,,,,,,,,,,,,,,,,,,
211.492,0.30713,0.9583,10,,,,,,,,,,,,,,,,,,,,,,,,,,,,,,,,,,,,,
211.992,0.30685,0.92202,10,,,,,,,,,,,,,,,,,,,,,,,,,,,,,,,,,,,,,
212.492,0.30645,0.93887,10,,,,,,,,,,,,,,,,,,,,,,,,,,,,,,,,,,,,,
212.992,0.30617,0.947,10,,,,,,,,,,,,,,,,,,,,,,,,,,,,,,,,,,,,,
213.492,0.30594,0.91862,10,,,,,,,,,,,,,,,,,,,,,,,,,,,,,,,,,,,,,
213.992,0.30566,0.92137,10,,,,,,,,,,,,,,,,,,,,,,,,,,,,,,,,,,,,,
214.492,0.30543,0.87425,10,,,,,,,,,,,,,,,,,,,,,,,,,,,,,,,,,,,,,
214.992,0.30538,0.87652,10,,,,,,,,,,,,,,,,,,,,,,,,,,,,,,,,,,,,,
215.492,0.30532,0.84444,10,,,,,,,,,,,,,,,,,,,,,,,,,,,,,,,,,,,,,
215.992,0.30543,0.94304,10,,,,,,,,,,,,,,,,,,,,,,,,,,,,,,,,,,,,,
216.492,0.30543,0.89268,10,,,,,,,,,,,,,,,,,,,,,,,,,,,,,,,,,,,,,
216.992,0.30549,0.86772,10,,,,,,,,,,,,,,,,,,,,,,,,,,,,,,,,,,,,,
217.492,0.3056,0.88857,10,,,,,,,,,,,,,,,,,,,,,,,,,,,,,,,,,,,,,
217.992,0.30566,0.94832,10,,,,,,,,,,,,,,,,,,,,,,,,,,,,,,,,,,,,,
218.492,0.30577,0.89924,10,,,,,,,,,,,,,,,,,,,,,,,,,,,,,,,,,,,,,
218.992,0.30583,0.93676,10,,,,,,,,,,,,,,,,,,,,,,,,,,,,,,,,,,,,,
219.492,0.30583,0.86094,10,,,,,,,,,,,,,,,,,,,,,,,,,,,,,,,,,,,,,
219.992,0.30594,0.89326,10,,,,,,,,,,,,,,,,,,,,,,,,,,,,,,,,,,,,,
220.492,0.30623,0.85458,10,,,,,,,,,,,,,,,,,,,,,,,,,,,,,,,,,,,,,
220.992,0.30657,0.89929,10,,,,,,,,,,,,,,,,,,,,,,,,,,,,,,,,,,,,,
221.492,0.30696,0.9195,10,,,,,,,,,,,,,,,,,,,,,,,,,,,,,,,,,,,,,
221.992,0.30747,0.9318,10,,,,,,,,,,,,,,,,,,,,,,,,,,,,,,,,,,,,,
222.492,0.30793,0.88305,10,,,,,,,,,,,,,,,,,,,,,,,,,,,,,,,,,,,,,
222.992,0.30815,0.95992,10,,,,,,,,,,,,,,,,,,,,,,,,,,,,,,,,,,,,,
223.492,0.30827,0.97711,10,,,,,,,,,,,,,,,,,,,,,,,,,,,,,,,,,,,,,
223.992,0.30827,0.92962,10,,,,,,,,,,,,,,,,,,,,,,,,,,,,,,,,,,,,,
224.492,0.30827,0.97945,10,,,,,,,,,,,,,,,,,,,,,,,,,,,,,,,,,,,,,
224.992,0.30815,0.98524,10,,,,,,,,,,,,,,,,,,,,,,,,,,,,,,,,,,,,,
225.492,0.3081,0.96027,10,,,,,,,,,,,,,,,,,,,,,,,,,,,,,,,,,,,,,
225.992,0.30804,0.99797,10,,,,,,,,,,,,,,,,,,,,,,,,,,,,,,,,,,,,,
226.492,0.30804,0.92123,10,,,,,,,,,,,,,,,,,,,,,,,,,,,,,,,,,,,,,
226.992,0.30798,1.00519,10,,,,,,,,,,,,,,,,,,,,,,,,,,,,,,,,,,,,,
227.492,0.30798,0.95179,10,,,,,,,,,,,,,,,,,,,,,,,,,,,,,,,,,,,,,
227.992,0.30793,0.95134,10,,,,,,,,,,,,,,,,,,,,,,,,,,,,,,,,,,,,,
228.492,0.30781,0.90647,10,,,,,,,,,,,,,,,,,,,,,,,,,,,,,,,,,,,,,
228.992,0.30781,0.90061,10,,,,,,,,,,,,,,,,,,,,,,,,,,,,,,,,,,,,,
229.492,0.30776,0.9971,10,,,,,,,,,,,,,,,,,,,,,,,,,,,,,,,,,,,,,
229.992,0.3077,0.95192,10,,,,,,,,,,,,,,,,,,,,,,,,,,,,,,,,,,,,,
230.492,0.30753,0.98035,10,,,,,,,,,,,,,,,,,,,,,,,,,,,,,,,,,,,,,
230.992,0.3073,0.9629,10,,,,,,,,,,,,,,,,,,,,,,,,,,,,,,,,,,,,,
231.492,0.30708,0.9372,10,,,,,,,,,,,,,,,,,,,,,,,,,,,,,,,,,,,,,
231.992,0.30685,0.92242,10,,,,,,,,,,,,,,,,,,,,,,,,,,,,,,,,,,,,,
232.492,0.30668,0.91146,10,,,,,,,,,,,,,,,,,,,,,,,,,,,,,,,,,,,,,
232.992,0.30657,0.92707,10,,,,,,,,,,,,,,,,,,,,,,,,,,,,,,,,,,,,,
233.492,0.30651,0.92406,10,,,,,,,,,,,,,,,,,,,,,,,,,,,,,,,,,,,,,
233.992,0.30651,0.88089,10,,,,,,,,,,,,,,,,,,,,,,,,,,,,,,,,,,,,,
234.492,0.3064,0.86653,10,,,,,,,,,,,,,,,,,,,,,,,,,,,,,,,,,,,,,
234.992,0.30651,0.89007,10,,,,,,,,,,,,,,,,,,,,,,,,,,,,,,,,,,,,,
235.492,0.30651,0.86016,10,,,,,,,,,,,,,,,,,,,,,,,,,,,,,,,,,,,,,
235.992,0.30657,0.7969,10,,,,,,,,,,,,,,,,,,,,,,,,,,,,,,,,,,,,,
236.492,0.30668,0.88069,10,,,,,,,,,,,,,,,,,,,,,,,,,,,,,,,,,,,,,
236.992,0.30668,0.94711,10,,,,,,,,,,,,,,,,,,,,,,,,,,,,,,,,,,,,,
237.492,0.30674,0.82873,10,,,,,,,,,,,,,,,,,,,,,,,,,,,,,,,,,,,,,
237.992,0.30685,0.90217,10,,,,,,,,,,,,,,,,,,,,,,,,,,,,,,,,,,,,,
238.492,0.30696,0.86124,10,,,,,,,,,,,,,,,,,,,,,,,,,,,,,,,,,,,,,
238.992,0.30719,0.84638,10,,,,,,,,,,,,,,,,,,,,,,,,,,,,,,,,,,,,,
239.492,0.30764,0.89322,10,,,,,,,,,,,,,,,,,,,,,,,,,,,,,,,,,,,,,
239.992,0.30798,0.87435,10,,,,,,,,,,,,,,,,,,,,,,,,,,,,,,,,,,,,,
240.492,0.30849,0.8771,10,,,,,,,,,,,,,,,,,,,,,,,,,,,,,,,,,,,,,
240.992,0.30883,0.98271,10,,,,,,,,,,,,,,,,,,,,,,,,,,,,,,,,,,,,,
241.492,0.30906,0.91302,10,,,,,,,,,,,,,,,,,,,,,,,,,,,,,,,,,,,,,
241.992,0.30934,0.9206,10,,,,,,,,,,,,,,,,,,,,,,,,,,,,,,,,,,,,,
242.492,0.30951,0.9181,10,,,,,,,,,,,,,,,,,,,,,,,,,,,,,,,,,,,,,
242.992,0.30963,0.98016,10,,,,,,,,,,,,,,,,,,,,,,,,,,,,,,,,,,,,,
243.492,0.30951,0.94947,10,,,,,,,,,,,,,,,,,,,,,,,,,,,,,,,,,,,,,
243.992,0.30946,0.98414,10,,,,,,,,,,,,,,,,,,,,,,,,,,,,,,,,,,,,,
244.492,0.3094,0.94644,10,,,,,,,,,,,,,,,,,,,,,,,,,,,,,,,,,,,,,
244.992,0.30946,0.96354,10,,,,,,,,,,,,,,,,,,,,,,,,,,,,,,,,,,,,,
245.492,0.30929,0.96789,10,,,,,,,,,,,,,,,,,,,,,,,,,,,,,,,,,,,,,
245.992,0.30923,0.90524,10,,,,,,,,,,,,,,,,,,,,,,,,,,,,,,,,,,,,,
246.492,0.30912,0.92302,10,,,,,,,,,,,,,,,,,,,,,,,,,,,,,,,,,,,,,
246.992,0.30895,0.90437,10,,,,,,,,,,,,,,,,,,,,,,,,,,,,,,,,,,,,,
247.492,0.30889,0.90506,10,,,,,,,,,,,,,,,,,,,,,,,,,,,,,,,,,,,,,
247.992,0.30866,0.92097,10,,,,,,,,,,,,,,,,,,,,,,,,,,,,,,,,,,,,,
248.492,0.30832,0.97331,10,,,,,,,,,,,,,,,,,,,,,,,,,,,,,,,,,,,,,
248.992,0.30793,0.96887,10,,,,,,,,,,,,,,,,,,,,,,,,,,,,,,,,,,,,,
249.492,0.30759,0.92784,10,,,,,,,,,,,,,,,,,,,,,,,,,,,,,,,,,,,,,
249.992,0.30736,0.89374,10,,,,,,,,,,,,,,,,,,,,,,,,,,,,,,,,,,,,,
250.492,0.30725,0.90996,10,,,,,,,,,,,,,,,,,,,,,,,,,,,,,,,,,,,,,
250.992,0.30719,0.83511,10,,,,,,,,,,,,,,,,,,,,,,,,,,,,,,,,,,,,,
251.492,0.30719,0.87197,10,,,,,,,,,,,,,,,,,,,,,,,,,,,,,,,,,,,,,
251.992,0.30719,0.90962,10,,,,,,,,,,,,,,,,,,,,,,,,,,,,,,,,,,,,,
252.492,0.3073,0.86412,10,,,,,,,,,,,,,,,,,,,,,,,,,,,,,,,,,,,,,
252.992,0.30736,0.94915,10,,,,,,,,,,,,,,,,,,,,,,,,,,,,,,,,,,,,,
253.492,0.30736,0.85958,10,,,,,,,,,,,,,,,,,,,,,,,,,,,,,,,,,,,,,
253.992,0.30742,0.83689,10,,,,,,,,,,,,,,,,,,,,,,,,,,,,,,,,,,,,,
254.492,0.30747,0.93824,10,,,,,,,,,,,,,,,,,,,,,,,,,,,,,,,,,,,,,
254.992,0.30753,0.90527,10,,,,,,,,,,,,,,,,,,,,,,,,,,,,,,,,,,,,,
255.492,0.30753,0.91621,10,,,,,,,,,,,,,,,,,,,,,,,,,,,,,,,,,,,,,
255.992,0.30753,0.98809,10,,,,,,,,,,,,,,,,,,,,,,,,,,,,,,,,,,,,,
256.492,0.30753,0.90537,10,,,,,,,,,,,,,,,,,,,,,,,,,,,,,,,,,,,,,
256.992,0.30753,0.87371,10,,,,,,,,,,,,,,,,,,,,,,,,,,,,,,,,,,,,,
257.492,0.30753,0.89669,10,,,,,,,,,,,,,,,,,,,,,,,,,,,,,,,,,,,,,
257.992,0.30759,0.92266,10,,,,,,,,,,,,,,,,,,,,,,,,,,,,,,,,,,,,,
258.492,0.30759,0.85316,10,,,,,,,,,,,,,,,,,,,,,,,,,,,,,,,,,,,,,
258.992,0.30776,0.90692,10,,,,,,,,,,,,,,,,,,,,,,,,,,,,,,,,,,,,,
259.492,0.30793,0.91576,10,,,,,,,,,,,,,,,,,,,,,,,,,,,,,,,,,,,,,
259.992,0.30827,0.88134,10,,,,,,,,,,,,,,,,,,,,,,,,,,,,,,,,,,,,,
260.492,0.30861,0.89902,10,,,,,,,,,,,,,,,,,,,,,,,,,,,,,,,,,,,,,
260.992,0.30923,0.9339,10,,,,,,,,,,,,,,,,,,,,,,,,,,,,,,,,,,,,,
261.492,0.30957,0.89162,10,,,,,,,,,,,,,,,,,,,,,,,,,,,,,,,,,,,,,
261.992,0.3098,0.93774,10,,,,,,,,,,,,,,,,,,,,,,,,,,,,,,,,,,,,,
262.492,0.30997,0.89334,10,,,,,,,,,,,,,,,,,,,,,,,,,,,,,,,,,,,,,
262.992,0.31008,0.889,10,,,,,,,,,,,,,,,,,,,,,,,,,,,,,,,,,,,,,
263.492,0.31014,0.91597,10,,,,,,,,,,,,,,,,,,,,,,,,,,,,,,,,,,,,,
263.992,0.31019,0.95985,10,,,,,,,,,,,,,,,,,,,,,,,,,,,,,,,,,,,,,
264.492,0.31019,0.94048,10,,,,,,,,,,,,,,,,,,,,,,,,,,,,,,,,,,,,,
264.992,0.31008,0.98054,10,,,,,,,,,,,,,,,,,,,,,,,,,,,,,,,,,,,,,
265.492,0.31008,0.90388,10,,,,,,,,,,,,,,,,,,,,,,,,,,,,,,,,,,,,,
265.992,0.31002,0.92698,10,,,,,,,,,,,,,,,,,,,,,,,,,,,,,,,,,,,,,
266.492,0.31002,0.94735,10,,,,,,,,,,,,,,,,,,,,,,,,,,,,,,,,,,,,,
266.992,0.30997,0.96829,10,,,,,,,,,,,,,,,,,,,,,,,,,,,,,,,,,,,,,
267.492,0.30997,0.90735,10,,,,,,,,,,,,,,,,,,,,,,,,,,,,,,,,,,,,,
267.992,0.30991,0.96784,10,,,,,,,,,,,,,,,,,,,,,,,,,,,,,,,,,,,,,
268.492,0.30985,0.92932,10,,,,,,,,,,,,,,,,,,,,,,,,,,,,,,,,,,,,,
268.992,0.3098,0.90837,10,,,,,,,,,,,,,,,,,,,,,,,,,,,,,,,,,,,,,
269.492,0.30974,0.95903,10,,,,,,,,,,,,,,,,,,,,,,,,,,,,,,,,,,,,,
269.992,0.30974,0.87278,10,,,,,,,,,,,,,,,,,,,,,,,,,,,,,,,,,,,,,
270.492,0.30974,0.90477,10,,,,,,,,,,,,,,,,,,,,,,,,,,,,,,,,,,,,,
270.992,0.30974,0.94495,10,,,,,,,,,,,,,,,,,,,,,,,,,,,,,,,,,,,,,
271.492,0.3098,0.97588,10,,,,,,,,,,,,,,,,,,,,,,,,,,,,,,,,,,,,,
271.992,0.30968,0.92567,10,,,,,,,,,,,,,,,,,,,,,,,,,,,,,,,,,,,,,
272.492,0.30963,0.94394,10,,,,,,,,,,,,,,,,,,,,,,,,,,,,,,,,,,,,,
272.992,0.30963,0.86743,10,,,,,,,,,,,,,,,,,,,,,,,,,,,,,,,,,,,,,
273.492,0.30957,0.86386,10,,,,,,,,,,,,,,,,,,,,,,,,,,,,,,,,,,,,,
273.992,0.30951,0.90082,10,,,,,,,,,,,,,,,,,,,,,,,,,,,,,,,,,,,,,
274.492,0.30951,0.93803,10,,,,,,,,,,,,,,,,,,,,,,,,,,,,,,,,,,,,,
274.992,0.30951,0.91787,10,,,,,,,,,,,,,,,,,,,,,,,,,,,,,,,,,,,,,
275.492,0.30951,0.91009,10,,,,,,,,,,,,,,,,,,,,,,,,,,,,,,,,,,,,,
275.992,0.30951,0.92275,10,,,,,,,,,,,,,,,,,,,,,,,,,,,,,,,,,,,,,
276.492,0.3094,0.89166,10,,,,,,,,,,,,,,,,,,,,,,,,,,,,,,,,,,,,,
276.992,0.3094,0.93733,10,,,,,,,,,,,,,,,,,,,,,,,,,,,,,,,,,,,,,
277.492,0.30951,0.81767,10,,,,,,,,,,,,,,,,,,,,,,,,,,,,,,,,,,,,,
277.992,0.30957,0.84764,10,,,,,,,,,,,,,,,,,,,,,,,,,,,,,,,,,,,,,
278.492,0.30957,0.88688,10,,,,,,,,,,,,,,,,,,,,,,,,,,,,,,,,,,,,,
278.992,0.30963,0.86247,10,,,,,,,,,,,,,,,,,,,,,,,,,,,,,,,,,,,,,
279.492,0.30968,0.82918,10,,,,,,,,,,,,,,,,,,,,,,,,,,,,,,,,,,,,,
279.992,0.3098,0.89209,10,,,,,,,,,,,,,,,,,,,,,,,,,,,,,,,,,,,,,
280.492,0.3098,0.90767,10,,,,,,,,,,,,,,,,,,,,,,,,,,,,,,,,,,,,,
280.992,0.30985,0.9149,10,,,,,,,,,,,,,,,,,,,,,,,,,,,,,,,,,,,,,
281.492,0.30985,0.96369,10,,,,,,,,,,,,,,,,,,,,,,,,,,,,,,,,,,,,,
281.992,0.30985,0.88994,10,,,,,,,,,,,,,,,,,,,,,,,,,,,,,,,,,,,,,
282.492,0.30991,0.85851,10,,,,,,,,,,,,,,,,,,,,,,,,,,,,,,,,,,,,,
282.992,0.30997,0.87636,10,,,,,,,,,,,,,,,,,,,,,,,,,,,,,,,,,,,,,
283.492,0.31019,0.83443,10,,,,,,,,,,,,,,,,,,,,,,,,,,,,,,,,,,,,,
283.992,0.31065,0.85323,10,,,,,,,,,,,,,,,,,,,,,,,,,,,,,,,,,,,,,
284.492,0.31161,0.9204,10,,,,,,,,,,,,,,,,,,,,,,,,,,,,,,,,,,,,,
284.992,0.31274,0.94153,10,,,,,,,,,,,,,,,,,,,,,,,,,,,,,,,,,,,,,
285.492,0.3132,0.95288,10,,,,,,,,,,,,,,,,,,,,,,,,,,,,,,,,,,,,,
285.992,0.31331,0.92588,10,,,,,,,,,,,,,,,,,,,,,,,,,,,,,,,,,,,,,
286.492,0.31325,0.94784,10,,,,,,,,,,,,,,,,,,,,,,,,,,,,,,,,,,,,,
286.992,0.31325,0.91286,10,,,,,,,,,,,,,,,,,,,,,,,,,,,,,,,,,,,,,
287.492,0.3132,0.98732,10,,,,,,,,,,,,,,,,,,,,,,,,,,,,,,,,,,,,,
287.992,0.3132,0.95778,10,,,,,,,,,,,,,,,,,,,,,,,,,,,,,,,,,,,,,
288.492,0.31308,0.95921,10,,,,,,,,,,,,,,,,,,,,,,,,,,,,,,,,,,,,,
288.992,0.31303,0.98556,10,,,,,,,,,,,,,,,,,,,,,,,,,,,,,,,,,,,,,
289.492,0.31297,0.94045,10,,,,,,,,,,,,,,,,,,,,,,,,,,,,,,,,,,,,,
289.992,0.31286,0.98292,10,,,,,,,,,,,,,,,,,,,,,,,,,,,,,,,,,,,,,
290.492,0.31257,0.95927,10,,,,,,,,,,,,,,,,,,,,,,,,,,,,,,,,,,,,,
290.992,0.31206,0.95196,10,,,,,,,,,,,,,,,,,,,,,,,,,,,,,,,,,,,,,
291.492,0.31133,0.92549,10,,,,,,,,,,,,,,,,,,,,,,,,,,,,,,,,,,,,,
291.992,0.31093,0.92932,10,,,,,,,,,,,,,,,,,,,,,,,,,,,,,,,,,,,,,
292.492,0.3107,0.87729,10,,,,,,,,,,,,,,,,,,,,,,,,,,,,,,,,,,,,,
292.992,0.31059,0.84871,10,,,,,,,,,,,,,,,,,,,,,,,,,,,,,,,,,,,,,
293.492,0.31048,0.92117,10,,,,,,,,,,,,,,,,,,,,,,,,,,,,,,,,,,,,,
293.992,0.31042,0.88991,10,,,,,,,,,,,,,,,,,,,,,,,,,,,,,,,,,,,,,
294.492,0.31042,0.88821,10,,,,,,,,,,,,,,,,,,,,,,,,,,,,,,,,,,,,,
294.992,0.31053,0.91106,10,,,,,,,,,,,,,,,,,,,,,,,,,,,,,,,,,,,,,
295.492,0.31053,0.82074,10,,,,,,,,,,,,,,,,,,,,,,,,,,,,,,,,,,,,,
295.992,0.31059,0.82017,10,,,,,,,,,,,,,,,,,,,,,,,,,,,,,,,,,,,,,
296.492,0.3107,0.84238,10,,,,,,,,,,,,,,,,,,,,,,,,,,,,,,,,,,,,,
296.992,0.31076,0.84443,10,,,,,,,,,,,,,,,,,,,,,,,,,,,,,,,,,,,,,
297.492,0.31093,0.83663,10,,,,,,,,,,,,,,,,,,,,,,,,,,,,,,,,,,,,,
297.992,0.31116,0.88071,10,,,,,,,,,,,,,,,,,,,,,,,,,,,,,,,,,,,,,
298.492,0.3115,0.82641,10,,,,,,,,,,,,,,,,,,,,,,,,,,,,,,,,,,,,,
298.992,0.31218,0.88308,10,,,,,,,,,,,,,,,,,,,,,,,,,,,,,,,,,,,,,
299.492,0.31263,0.92451,10,,,,,,,,,,,,,,,,,,,,,,,,,,,,,,,,,,,,,
299.992,0.31308,0.95029,10,,,,,,,,,,,,,,,,,,,,,,,,,,,,,,,,,,,,,
300.492,0.31337,0.86251,10,,,,,,,,,,,,,,,,,,,,,,,,,,,,,,,,,,,,,
300.992,0.31359,0.94104,10,,,,,,,,,,,,,,,,,,,,,,,,,,,,,,,,,,,,,
301.492,0.31371,0.91497,10,,,,,,,,,,,,,,,,,,,,,,,,,,,,,,,,,,,,,
301.992,0.31376,0.97101,10,,,,,,,,,,,,,,,,,,,,,,,,,,,,,,,,,,,,,
302.492,0.31365,0.96128,10,,,,,,,,,,,,,,,,,,,,,,,,,,,,,,,,,,,,,
302.992,0.31365,0.94957,10,,,,,,,,,,,,,,,,,,,,,,,,,,,,,,,,,,,,,
303.492,0.31359,0.94209,10,,,,,,,,,,,,,,,,,,,,,,,,,,,,,,,,,,,,,
303.992,0.31359,0.97153,10,,,,,,,,,,,,,,,,,,,,,,,,,,,,,,,,,,,,,
304.492,0.31359,0.92321,10,,,,,,,,,,,,,,,,,,,,,,,,,,,,,,,,,,,,,
304.992,0.31348,0.94982,10,,,,,,,,,,,,,,,,,,,,,,,,,,,,,,,,,,,,,
305.492,0.31342,0.97316,10,,,,,,,,,,,,,,,,,,,,,,,,,,,,,,,,,,,,,
305.992,0.31342,0.94851,10,,,,,,,,,,,,,,,,,,,,,,,,,,,,,,,,,,,,,
306.492,0.31342,0.87359,10,,,,,,,,,,,,,,,,,,,,,,,,,,,,,,,,,,,,,
306.992,0.31342,0.94077,10,,,,,,,,,,,,,,,,,,,,,,,,,,,,,,,,,,,,,
307.492,0.31337,0.96563,10,,,,,,,,,,,,,,,,,,,,,,,,,,,,,,,,,,,,,
307.992,0.31337,0.92274,10,,,,,,,,,,,,,,,,,,,,,,,,,,,,,,,,,,,,,
308.492,0.31331,0.9095,10,,,,,,,,,,,,,,,,,,,,,,,,,,,,,,,,,,,,,
308.992,0.3132,0.9352,10,,,,,,,,,,,,,,,,,,,,,,,,,,,,,,,,,,,,,
309.492,0.31303,0.93399,10,,,,,,,,,,,,,,,,,,,,,,,,,,,,,,,,,,,,,
309.992,0.31274,0.93317,10,,,,,,,,,,,,,,,,,,,,,,,,,,,,,,,,,,,,,
310.492,0.3124,0.94922,10,,,,,,,,,,,,,,,,,,,,,,,,,,,,,,,,,,,,,
310.992,0.31218,0.94929,10,,,,,,,,,,,,,,,,,,,,,,,,,,,,,,,,,,,,,
311.492,0.31201,0.90469,10,,,,,,,,,,,,,,,,,,,,,,,,,,,,,,,,,,,,,
311.992,0.31189,0.88903,10,,,,,,,,,,,,,,,,,,,,,,,,,,,,,,,,,,,,,
312.492,0.31189,0.84738,10,,,,,,,,,,,,,,,,,,,,,,,,,,,,,,,,,,,,,
312.992,0.31201,0.87155,10,,,,,,,,,,,,,,,,,,,,,,,,,,,,,,,,,,,,,
313.492,0.31206,0.90193,10,,,,,,,,,,,,,,,,,,,,,,,,,,,,,,,,,,,,,
313.992,0.31206,0.8484,10,,,,,,,,,,,,,,,,,,,,,,,,,,,,,,,,,,,,,
314.492,0.31212,0.92533,10,,,,,,,,,,,,,,,,,,,,,,,,,,,,,,,,,,,,,
314.992,0.31218,0.87532,10,,,,,,,,,,,,,,,,,,,,,,,,,,,,,,,,,,,,,
315.492,0.31229,0.87721,10,,,,,,,,,,,,,,,,,,,,,,,,,,,,,,,,,,,,,
315.992,0.3124,0.85841,10,,,,,,,,,,,,,,,,,,,,,,,,,,,,,,,,,,,,,
316.492,0.31257,0.87216,10,,,,,,,,,,,,,,,,,,,,,,,,,,,,,,,,,,,,,
316.992,0.31297,0.83168,10,,,,,,,,,,,,,,,,,,,,,,,,,,,,,,,,,,,,,
317.492,0.31342,0.93954,10,,,,,,,,,,,,,,,,,,,,,,,,,,,,,,,,,,,,,
317.992,0.31382,0.90142,10,,,,,,,,,,,,,,,,,,,,,,,,,,,,,,,,,,,,,
318.492,0.31416,0.95052,10,,,,,,,,,,,,,,,,,,,,,,,,,,,,,,,,,,,,,
318.992,0.31456,0.90511,10,,,,,,,,,,,,,,,,,,,,,,,,,,,,,,,,,,,,,
319.492,0.31478,0.98354,10,,,,,,,,,,,,,,,,,,,,,,,,,,,,,,,,,,,,,
319.992,0.31484,0.90207,10,,,,,,,,,,,,,,,,,,,,,,,,,,,,,,,,,,,,,
320.492,0.31495,0.99945,10,,,,,,,,,,,,,,,,,,,,,,,,,,,,,,,,,,,,,
320.992,0.31484,0.93808,10,,,,,,,,,,,,,,,,,,,,,,,,,,,,,,,,,,,,,
321.492,0.3149,0.9805,10,,,,,,,,,,,,,,,,,,,,,,,,,,,,,,,,,,,,,
321.992,0.31473,0.98899,10,,,,,,,,,,,,,,,,,,,,,,,,,,,,,,,,,,,,,
322.492,0.31473,0.93698,10,,,,,,,,,,,,,,,,,,,,,,,,,,,,,,,,,,,,,
322.992,0.31467,0.90909,10,,,,,,,,,,,,,,,,,,,,,,,,,,,,,,,,,,,,,
323.492,0.31461,1.0276,10,,,,,,,,,,,,,,,,,,,,,,,,,,,,,,,,,,,,,
323.992,0.31456,0.9535,10,,,,,,,,,,,,,,,,,,,,,,,,,,,,,,,,,,,,,
324.492,0.31439,1.04734,10,,,,,,,,,,,,,,,,,,,,,,,,,,,,,,,,,,,,,
324.992,0.31433,0.95384,10,,,,,,,,,,,,,,,,,,,,,,,,,,,,,,,,,,,,,
325.492,0.3141,1.00967,10,,,,,,,,,,,,,,,,,,,,,,,,,,,,,,,,,,,,,
325.992,0.31376,0.93492,10,,,,,,,,,,,,,,,,,,,,,,,,,,,,,,,,,,,,,
326.492,0.31337,0.98961,10,,,,,,,,,,,,,,,,,,,,,,,,,,,,,,,,,,,,,
326.992,0.31303,0.92542,10,,,,,,,,,,,,,,,,,,,,,,,,,,,,,,,,,,,,,
327.492,0.31274,0.88576,10,,,,,,,,,,,,,,,,,,,,,,,,,,,,,,,,,,,,,
327.992,0.31252,0.92459,10,,,,,,,,,,,,,,,,,,,,,,,,,,,,,,,,,,,,,
328.492,0.31235,0.97729,10,,,,,,,,,,,,,,,,,,,,,,,,,,,,,,,,,,,,,
328.992,0.31229,0.9062,10,,,,,,,,,,,,,,,,,,,,,,,,,,,,,,,,,,,,,
329.492,0.31223,0.95093,10,,,,,,,,,,,,,,,,,,,,,,,,,,,,,,,,,,,,,
329.992,0.31223,0.89656,10,,,,,,,,,,,,,,,,,,,,,,,,,,,,,,,,,,,,,
330.492,0.31235,0.93067,10,,,,,,,,,,,,,,,,,,,,,,,,,,,,,,,,,,,,,
330.992,0.31235,0.91787,10,,,,,,,,,,,,,,,,,,,,,,,,,,,,,,,,,,,,,
331.492,0.31246,0.86304,10,,,,,,,,,,,,,,,,,,,,,,,,,,,,,,,,,,,,,
331.992,0.31252,0.84517,10,,,,,,,,,,,,,,,,,,,,,,,,,,,,,,,,,,,,,
332.492,0.31269,0.92094,10,,,,,,,,,,,,,,,,,,,,,,,,,,,,,,,,,,,,,
332.992,0.31286,0.87206,10,,,,,,,,,,,,,,,,,,,,,,,,,,,,,,,,,,,,,
333.492,0.31331,0.93322,10,,,,,,,,,,,,,,,,,,,,,,,,,,,,,,,,,,,,,
333.992,0.31376,0.92742,10,,,,,,,,,,,,,,,,,,,,,,,,,,,,,,,,,,,,,
334.492,0.31433,0.94888,10,,,,,,,,,,,,,,,,,,,,,,,,,,,,,,,,,,,,,
334.992,0.31467,0.92559,10,,,,,,,,,,,,,,,,,,,,,,,,,,,,,,,,,,,,,
335.492,0.31501,0.97889,10,,,,,,,,,,,,,,,,,,,,,,,,,,,,,,,,,,,,,
335.992,0.31518,0.90616,10,,,,,,,,,,,,,,,,,,,,,,,,,,,,,,,,,,,,,
336.492,0.31535,0.91368,10,,,,,,,,,,,,,,,,,,,,,,,,,,,,,,,,,,,,,
336.992,0.31546,0.92358,10,,,,,,,,,,,,,,,,,,,,,,,,,,,,,,,,,,,,,
337.492,0.31558,0.95749,10,,,,,,,,,,,,,,,,,,,,,,,,,,,,,,,,,,,,,
337.992,0.31563,0.88761,10,,,,,,,,,,,,,,,,,,,,,,,,,,,,,,,,,,,,,
338.492,0.31563,0.96984,10,,,,,,,,,,,,,,,,,,,,,,,,,,,,,,,,,,,,,
338.992,0.31563,0.9252,10,,,,,,,,,,,,,,,,,,,,,,,,,,,,,,,,,,,,,
339.492,0.31569,0.94261,10,,,,,,,,,,,,,,,,,,,,,,,,,,,,,,,,,,,,,
339.992,0.31558,0.96408,10,,,,,,,,,,,,,,,,,,,,,,,,,,,,,,,,,,,,,
340.492,0.31558,0.94932,10,,,,,,,,,,,,,,,,,,,,,,,,,,,,,,,,,,,,,
340.992,0.31558,0.85723,10,,,,,,,,,,,,,,,,,,,,,,,,,,,,,,,,,,,,,
341.492,0.31558,0.96888,10,,,,,,,,,,,,,,,,,,,,,,,,,,,,,,,,,,,,,
341.992,0.31552,0.96349,10,,,,,,,,,,,,,,,,,,,,,,,,,,,,,,,,,,,,,
342.492,0.31552,0.91636,10,,,,,,,,,,,,,,,,,,,,,,,,,,,,,,,,,,,,,
342.992,0.31552,0.92321,10,,,,,,,,,,,,,,,,,,,,,,,,,,,,,,,,,,,,,
343.492,0.31546,0.92615,10,,,,,,,,,,,,,,,,,,,,,,,,,,,,,,,,,,,,,
343.992,0.31546,0.87279,10,,,,,,,,,,,,,,,,,,,,,,,,,,,,,,,,,,,,,
344.492,0.31546,0.93777,10,,,,,,,,,,,,,,,,,,,,,,,,,,,,,,,,,,,,,
344.992,0.31546,0.92918,10,,,,,,,,,,,,,,,,,,,,,,,,,,,,,,,,,,,,,
345.492,0.31541,0.90899,10,,,,,,,,,,,,,,,,,,,,,,,,,,,,,,,,,,,,,
345.992,0.31546,0.96416,10,,,,,,,,,,,,,,,,,,,,,,,,,,,,,,,,,,,,,
346.492,0.31546,0.96455,10,,,,,,,,,,,,,,,,,,,,,,,,,,,,,,,,,,,,,
346.992,0.31541,0.89413,10,,,,,,,,,,,,,,,,,,,,,,,,,,,,,,,,,,,,,
347.492,0.31529,0.9705,10,,,,,,,,,,,,,,,,,,,,,,,,,,,,,,,,,,,,,
347.992,0.31529,0.9571,10,,,,,,,,,,,,,,,,,,,,,,,,,,,,,,,,,,,,,
348.492,0.31529,0.88441,10,,,,,,,,,,,,,,,,,,,,,,,,,,,,,,,,,,,,,
348.992,0.31524,0.99612,10,,,,,,,,,,,,,,,,,,,,,,,,,,,,,,,,,,,,,
349.492,0.31524,0.86712,10,,,,,,,,,,,,,,,,,,,,,,,,,,,,,,,,,,,,,
349.992,0.31524,0.894,10,,,,,,,,,,,,,,,,,,,,,,,,,,,,,,,,,,,,,
350.492,0.31524,0.92624,10,,,,,,,,,,,,,,,,,,,,,,,,,,,,,,,,,,,,,
350.992,0.31524,0.91626,10,,,,,,,,,,,,,,,,,,,,,,,,,,,,,,,,,,,,,
351.492,0.31524,0.87934,10,,,,,,,,,,,,,,,,,,,,,,,,,,,,,,,,,,,,,
351.992,0.31524,0.92398,10,,,,,,,,,,,,,,,,,,,,,,,,,,,,,,,,,,,,,
352.492,0.31524,0.89525,10,,,,,,,,,,,,,,,,,,,,,,,,,,,,,,,,,,,,,
352.992,0.31524,0.86827,10,,,,,,,,,,,,,,,,,,,,,,,,,,,,,,,,,,,,,
353.492,0.31524,0.95439,10,,,,,,,,,,,,,,,,,,,,,,,,,,,,,,,,,,,,,
353.992,0.31524,0.88055,10,,,,,,,,,,,,,,,,,,,,,,,,,,,,,,,,,,,,,
354.492,0.31524,0.87336,10,,,,,,,,,,,,,,,,,,,,,,,,,,,,,,,,,,,,,
354.992,0.31524,0.95358,10,,,,,,,,,,,,,,,,,,,,,,,,,,,,,,,,,,,,,
355.492,0.31535,0.86643,10,,,,,,,,,,,,,,,,,,,,,,,,,,,,,,,,,,,,,
355.992,0.31535,0.80893,10,,,,,,,,,,,,,,,,,,,,,,,,,,,,,,,,,,,,,
356.492,0.31541,0.86312,10,,,,,,,,,,,,,,,,,,,,,,,,,,,,,,,,,,,,,
356.992,0.31541,0.91484,10,,,,,,,,,,,,,,,,,,,,,,,,,,,,,,,,,,,,,
357.492,0.31546,0.84366,10,,,,,,,,,,,,,,,,,,,,,,,,,,,,,,,,,,,,,
357.992,0.31552,0.90114,10,,,,,,,,,,,,,,,,,,,,,,,,,,,,,,,,,,,,,
358.492,0.31563,0.80599,10,,,,,,,,,,,,,,,,,,,,,,,,,,,,,,,,,,,,,
358.992,0.31569,0.8507,10,,,,,,,,,,,,,,,,,,,,,,,,,,,,,,,,,,,,,
359.492,0.31592,0.83715,10,,,,,,,,,,,,,,,,,,,,,,,,,,,,,,,,,,,,,
359.992,0.31643,0.87525,10,,,,,,,,,,,,,,,,,,,,,,,,,,,,,,,,,,,,,
360.492,0.31733,0.90282,10,,,,,,,,,,,,,,,,,,,,,,,,,,,,,,,,,,,,,
360.992,0.31779,1.00373,10,,,,,,,,,,,,,,,,,,,,,,,,,,,,,,,,,,,,,
361.492,0.31796,0.93215,10,,,,,,,,,,,,,,,,,,,,,,,,,,,,,,,,,,,,,
361.992,0.31807,0.88699,10,,,,,,,,,,,,,,,,,,,,,,,,,,,,,,,,,,,,,
362.492,0.31813,0.94599,10,,,,,,,,,,,,,,,,,,,,,,,,,,,,,,,,,,,,,
362.992,0.31813,0.92819,10,,,,,,,,,,,,,,,,,,,,,,,,,,,,,,,,,,,,,
363.492,0.31813,0.9279,10,,,,,,,,,,,,,,,,,,,,,,,,,,,,,,,,,,,,,
363.992,0.31801,0.98567,10,,,,,,,,,,,,,,,,,,,,,,,,,,,,,,,,,,,,,
364.492,0.31796,0.97684,10,,,,,,,,,,,,,,,,,,,,,,,,,,,,,,,,,,,,,
364.992,0.3179,0.94824,10,,,,,,,,,,,,,,,,,,,,,,,,,,,,,,,,,,,,,
365.492,0.31784,0.95239,10,,,,,,,,,,,,,,,,,,,,,,,,,,,,,,,,,,,,,
365.992,0.31784,0.91585,10,,,,,,,,,,,,,,,,,,,,,,,,,,,,,,,,,,,,,
366.492,0.31779,0.90552,10,,,,,,,,,,,,,,,,,,,,,,,,,,,,,,,,,,,,,
366.992,0.31767,1.0232,10,,,,,,,,,,,,,,,,,,,,,,,,,,,,,,,,,,,,,
367.492,0.31762,0.96771,10,,,,,,,,,,,,,,,,,,,,,,,,,,,,,,,,,,,,,
367.992,0.31733,0.92346,10,,,,,,,,,,,,,,,,,,,,,,,,,,,,,,,,,,,,,
368.492,0.31694,0.99874,10,,,,,,,,,,,,,,,,,,,,,,,,,,,,,,,,,,,,,
368.992,0.31631,0.9525,10,,,,,,,,,,,,,,,,,,,,,,,,,,,,,,,,,,,,,
369.492,0.31586,0.90329,10,,,,,,,,,,,,,,,,,,,,,,,,,,,,,,,,,,,,,
369.992,0.31552,0.89452,10,,,,,,,,,,,,,,,,,,,,,,,,,,,,,,,,,,,,,
370.492,0.31535,0.9236,10,,,,,,,,,,,,,,,,,,,,,,,,,,,,,,,,,,,,,
370.992,0.31524,0.83457,10,,,,,,,,,,,,,,,,,,,,,,,,,,,,,,,,,,,,,
371.492,0.31535,0.88347,10,,,,,,,,,,,,,,,,,,,,,,,,,,,,,,,,,,,,,
371.992,0.31535,0.89306,10,,,,,,,,,,,,,,,,,,,,,,,,,,,,,,,,,,,,,
372.492,0.31541,0.84262,10,,,,,,,,,,,,,,,,,,,,,,,,,,,,,,,,,,,,,
372.992,0.31546,0.89214,10,,,,,,,,,,,,,,,,,,,,,,,,,,,,,,,,,,,,,
373.492,0.31558,0.86104,10,,,,,,,,,,,,,,,,,,,,,,,,,,,,,,,,,,,,,
373.894,3.41536,516.40558,10,,,,,,,,,,,,,,,,,,,,,,,,,,,,,,,,,,,,,
374.394,7.58217,1508.58105,10,,,,,,,,,,,,,,,,,,,,,,,,,,,,,,,,,,,,,
374.7,10.13257,-1.27769,10,,,,,,,,,,,,,,,,,,,,,,,,,,,,,,,,,,,,,