File: combined_ligament_solver/data/processed/Data Sheet 3_S152718_ACL.csv
Specimen properties : Length,29,mm,Unnamed: 3,Unnamed: 4,Unnamed: 5,Unnamed: 6,Unnamed: 7,Unnamed: 8,Unnamed: 9,Unnamed: 10,Unnamed: 11,Stress-Strain,Unnamed: 13,Unnamed: 14,Unnamed: 15,Unnamed: 16,Unnamed: 17,Unnamed: 18,Unnamed: 19,Unnamed: 20,Unnamed: 21,Unnamed: 22,Unnamed: 23,Unnamed: 24,Unnamed: 25,Unnamed: 26,Unnamed: 27,Linear,Unnamed: 29,Unnamed: 30,Unnamed: 31,Unnamed: 32,Unnamed: 33,Modulus,Unnamed: 35,Failure,Unnamed: 37,Unnamed: 38,Unnamed: 39,Unnamed: 40
Cross Section Average,101.8435,mm2,,,,,,,,,,Polynomial Coefficients,,,,,,,,,,,,,,,,Force,,Stress,Extension,Strain,,Secant,Tangent,Load,Stress,Extension,Strain,Stiffness
Time,Extension,Load,Total cycle count,,,Extension,Load,Strain,Stress,E-tan,,X6,,,,,,,,,,Strain,Stress,E-tan,,,,(N),,(MPa),(mm),(%),,(MPa),(MPa),(N),(MPa),(mm),(%),(N/mm)
(s),(mm),(N),,,,(mm),(N),(mm/mm),(MPa),(MPa),,X5,,,,,,,,,,(mm/mm),(MPa),(MPa),,,,229.3361079478118,,2.2518482568628513,1.9720000000000002,6.800000000000001,,33.11541554210075,56.760607751112644,613.77087,6.0174500090825624,4.64995,16.034310344827585,116.29620078489441
0.4,0.09894,3.32236,0,,,3.18342,392.20993,0.10286758620689654,3.8419460250285975,,,,,,,,,,,,,0.004,0.0003889513209706947,1.6613036633284795,,,,,,,,,,,,,,,,
0.9,0.1823,6.55514,0,,,7.35035,283.05493,0.2465548275862069,2.7701545017600533,,,,,,,,,,,,,0.009,0.024936628191692806,7.113246066823857,,,,,,,,,,,,,,,,
1.4,0.2656,9.83248,0,,,11.51688,6.17191,,,,,,,,,,,,,,,0.014,0.07747494811914495,12.793185618701228,,,,,,,,,,,,,,,,
1.9,0.34907,13.57763,0,,,15.68363,-0.24027,,,,,,,,,,,,,,,0.019,0.15879184988943323,18.58377333369261,,,,,,,,,,,,,,,,
2.4,0.43231,17.84567,0,,,19.85028,-4.88123,,,,,,,,,,,,,,,0.024,0.2690885273623243,24.367660226530226,,,,,,,,,,,,,,,,
2.9,0.51572,21.8086,0,,,24.01686,-7.13434,,,,,,,,,,,,,,,0.029,0.4079794294712448,30.027497311945897,,,,,,,,,,,,,,,,
3.4,0.59897,27.06733,0,,,,,,,,,,,,,,,,,,,0.034,0.5744922602232819,35.445935604671874,,,,,,,,,,,,,,,,
3.766,0.63093,41.35021,0.5,,,,,,,,,,,,,,,,,,,0.039,0.767067978699183,40.50562611944027,,,,,,,,,,,,,,,,
4.266,0.54298,34.1745,0.5,,,,,,,,,,,,,,,,,,,0.044,0.9835607990533556,45.089219870982866,,,,,,,,,,,,,,,,
4.766,0.45979,13.49674,0.5,,,,,,,,,,,,,,,,,,,0.049,1.221238190513868,49.07936787403195,,,,,,,,,,,,,,,,
5.266,0.37627,9.14218,0.5,,,,,,,,,,,,,,,,,,,0.054,1.4767808773824482,52.35872114331958,,,,,,,,,,,,,,,,
5.766,0.29302,5.66171,0.5,,,,,,,,,,,,,,,,,,,0.059,1.7462828390344851,54.809930693577535,,,,,,,,,,,,,,,,
6.266,0.20961,2.64745,0.5,,,,,,,,,,,,,,,,,,,0.064,2.0252513099190277,56.31564753953805,,,,,,,,,,,,,,,,
6.658,0.14427,0.9856,1,,,,,,,,,,,,,,,,,,,0.069,2.308606779558785,56.75852269593346,,,,,,,,,,,,,,,,
7.06,0.21154,3.88096,1,,,,,,,,,,,,,,,,,,,0.074,2.590682992550126,56.021207177494986,,,,,,,,,,,,,,,,
7.56,0.29501,7.51752,1,,,,,,,,,,,,,,,,,,,0.079,2.8652269485630817,53.98635199895669,,,,,,,,,,,,,,,,
8.06,0.37831,11.12449,1,,,,,,,,,,,,,,,,,,,0.084,3.1253989023413413,50.536608175048634,,,,,,,,,,,,,,,,
8.56,0.46161,15.56132,1,,,,,,,,,,,,,,,,,,,0.089,3.3637723637022545,45.55462672050354,,,,,,,,,,,,,,,,
9.06,0.54496,21.01021,1,,,,,,,,,,,,,,,,,,,0.094,3.572334097536834,38.92305865005282,,,,,,,,,,,,,,,,
9.56,0.62843,27.1568,1,,,,,,,,,,,,,,,,,,,0.099,3.7424841238097497,30.524554978429617,,,,,,,,,,,,,,,,
10.06,0.71168,34.03692,1,,,,,,,,,,,,,,,,,,,0.104,3.8650357175593317,20.24176672036535,,,,,,,,,,,,,,,,
10.462,0.77871,40.03516,1.5,,,,,,,,,,,,,,,,,,,0.109,3.930215408897574,7.957344890590515,,,,,,,,,,,,,,,,
10.962,0.69513,30.9494,1.5,,,,,,,,,,,,,,,,,,,0.114,,,,,,,,,,,,,,,,,,
11.462,0.61177,23.10207,1.5,,,,,,,,,,,,,,,,,,,0.119,,,,,,,,,,,,,,,,,,
11.962,0.52842,16.75838,1.5,,,,,,,,,,,,,,,,,,,0.124,,,,,,,,,,,,,,,,,,
12.462,0.445,11.84948,1.5,,,,,,,,,,,,,,,,,,,0.129,,,,,,,,,,,,,,,,,,
12.962,0.36176,7.97454,1.5,,,,,,,,,,,,,,,,,,,0.134,,,,,,,,,,,,,,,,,,
13.462,0.27846,4.91943,1.5,,,,,,,,,,,,,,,,,,,0.139,,,,,,,,,,,,,,,,,,
13.962,0.19499,2.1033,1.5,,,,,,,,,,,,,,,,,,,0.144,,,,,,,,,,,,,,,,,,
14.19,0.15697,0.97068,2,,,,,,,,,,,,,,,,,,,0.149,,,,,,,,,,,,,,,,,,
14.69,0.24129,4.07089,2,,,,,,,,,,,,,,,,,,,0.154,,,,,,,,,,,,,,,,,,
15.19,0.32464,7.72287,2,,,,,,,,,,,,,,,,,,,0.159,,,,,,,,,,,,,,,,,,
15.69,0.40794,11.40188,2,,,,,,,,,,,,,,,,,,,0.164,,,,,,,,,,,,,,,,,,
16.19,0.49124,15.91155,2,,,,,,,,,,,,,,,,,,,0.169,,,,,,,,,,,,,,,,,,
16.69,0.57477,21.50429,2,,,,,,,,,,,,,,,,,,,0.174,,,,,,,,,,,,,,,,,,
17.19,0.65796,27.85521,2,,,,,,,,,,,,,,,,,,,0.179,,,,,,,,,,,,,,,,,,
17.69,0.74137,35.10884,2,,,,,,,,,,,,,,,,,,,0.184,,,,,,,,,,,,,,,,,,
18.006,0.79413,40.04279,2.5,,,,,,,,,,,,,,,,,,,0.189,,,,,,,,,,,,,,,,,,
18.506,0.71037,30.95026,2.5,,,,,,,,,,,,,,,,,,,0.194,,,,,,,,,,,,,,,,,,
19.006,0.62707,23.08777,2.5,,,,,,,,,,,,,,,,,,,0.199,,,,,,,,,,,,,,,,,,
19.506,0.54366,16.78709,2.5,,,,,,,,,,,,,,,,,,,,,,,,,,,,,,,,,,,,,
20.006,0.46042,11.79999,2.5,,,,,,,,,,,,,,,,,,,,,,,,,,,,,,,,,,,,,
20.506,0.37689,7.98729,2.5,,,,,,,,,,,,,,,,,,,,,,,,,,,,,,,,,,,,,
21.006,0.2937,4.89445,2.5,,,,,,,,,,,,,,,,,,,,,,,,,,,,,,,,,,,,,
21.506,0.21029,2.05776,2.5,,,,,,,,,,,,,,,,,,,,,,,,,,,,,,,,,,,,,
21.73,0.17306,0.98301,3,,,,,,,,,,,,,,,,,,,,,,,,,,,,,,,,,,,,,
22.23,0.25721,4.08755,3,,,,,,,,,,,,,,,,,,,,,,,,,,,,,,,,,,,,,
22.73,0.34074,7.81271,3,,,,,,,,,,,,,,,,,,,,,,,,,,,,,,,,,,,,,
23.23,0.42398,11.49139,3,,,,,,,,,,,,,,,,,,,,,,,,,,,,,,,,,,,,,
23.73,0.50745,16.00626,3,,,,,,,,,,,,,,,,,,,,,,,,,,,,,,,,,,,,,
24.23,0.59058,21.60197,3,,,,,,,,,,,,,,,,,,,,,,,,,,,,,,,,,,,,,
24.73,0.67405,28.14945,3,,,,,,,,,,,,,,,,,,,,,,,,,,,,,,,,,,,,,
25.23,0.75741,35.44897,3,,,,,,,,,,,,,,,,,,,,,,,,,,,,,,,,,,,,,
25.618,0.79299,39.69876,3.5,,,,,,,,,,,,,,,,,,,,,,,,,,,,,,,,,,,,,
26.118,0.7051,29.3943,3.5,,,,,,,,,,,,,,,,,,,,,,,,,,,,,,,,,,,,,
26.618,0.6218,21.74724,3.5,,,,,,,,,,,,,,,,,,,,,,,,,,,,,,,,,,,,,
27.118,0.53833,15.6706,3.5,,,,,,,,,,,,,,,,,,,,,,,,,,,,,,,,,,,,,
27.618,0.45503,10.93601,3.5,,,,,,,,,,,,,,,,,,,,,,,,,,,,,,,,,,,,,
28.118,0.37168,7.35458,3.5,,,,,,,,,,,,,,,,,,,,,,,,,,,,,,,,,,,,,
28.618,0.28843,4.26927,3.5,,,,,,,,,,,,,,,,,,,,,,,,,,,,,,,,,,,,,
29.118,0.20491,1.56027,3.5,,,,,,,,,,,,,,,,,,,,,,,,,,,,,,,,,,,,,
29.336,0.19811,1.07825,4,,,,,,,,,,,,,,,,,,,,,,,,,,,,,,,,,,,,,
29.836,0.28639,4.81396,4,,,,,,,,,,,,,,,,,,,,,,,,,,,,,,,,,,,,,
30.336,0.36969,8.61649,4,,,,,,,,,,,,,,,,,,,,,,,,,,,,,,,,,,,,,
30.836,0.45311,12.36626,4,,,,,,,,,,,,,,,,,,,,,,,,,,,,,,,,,,,,,
31.336,0.53624,17.14383,4,,,,,,,,,,,,,,,,,,,,,,,,,,,,,,,,,,,,,
31.836,0.61982,23.00814,4,,,,,,,,,,,,,,,,,,,,,,,,,,,,,,,,,,,,,
32.336,0.70301,29.72834,4,,,,,,,,,,,,,,,,,,,,,,,,,,,,,,,,,,,,,
32.836,0.78636,37.31219,4,,,,,,,,,,,,,,,,,,,,,,,,,,,,,,,,,,,,,
33.202,0.78081,36.77,4.5,,,,,,,,,,,,,,,,,,,,,,,,,,,,,,,,,,,,,
33.702,0.69717,27.6441,4.5,,,,,,,,,,,,,,,,,,,,,,,,,,,,,,,,,,,,,
34.202,0.6137,20.40822,4.5,,,,,,,,,,,,,,,,,,,,,,,,,,,,,,,,,,,,,
34.702,0.5304,14.62701,4.5,,,,,,,,,,,,,,,,,,,,,,,,,,,,,,,,,,,,,
35.202,0.44704,10.19235,4.5,,,,,,,,,,,,,,,,,,,,,,,,,,,,,,,,,,,,,
35.702,0.3638,6.69043,4.5,,,,,,,,,,,,,,,,,,,,,,,,,,,,,,,,,,,,,
36.202,0.28044,3.65628,4.5,,,,,,,,,,,,,,,,,,,,,,,,,,,,,,,,,,,,,
36.702,0.19697,1.04851,4.5,,,,,,,,,,,,,,,,,,,,,,,,,,,,,,,,,,,,,
36.914,0.22905,2.03343,5,,,,,,,,,,,,,,,,,,,,,,,,,,,,,,,,,,,,,
37.414,0.31263,5.62123,5,,,,,,,,,,,,,,,,,,,,,,,,,,,,,,,,,,,,,
37.914,0.39599,9.22517,5,,,,,,,,,,,,,,,,,,,,,,,,,,,,,,,,,,,,,
38.414,0.47929,13.2124,5,,,,,,,,,,,,,,,,,,,,,,,,,,,,,,,,,,,,,
38.914,0.56276,18.31239,5,,,,,,,,,,,,,,,,,,,,,,,,,,,,,,,,,,,,,
39.414,0.64594,24.36359,5,,,,,,,,,,,,,,,,,,,,,,,,,,,,,,,,,,,,,
39.914,0.72936,31.32643,5,,,,,,,,,,,,,,,,,,,,,,,,,,,,,,,,,,,,,
40.414,0.81271,39.2188,5,,,,,,,,,,,,,,,,,,,,,,,,,,,,,,,,,,,,,
40.76,0.77004,34.60437,5.5,,,,,,,,,,,,,,,,,,,,,,,,,,,,,,,,,,,,,
41.26,0.6868,26.01937,5.5,,,,,,,,,,,,,,,,,,,,,,,,,,,,,,,,,,,,,
41.76,0.60327,19.12687,5.5,,,,,,,,,,,,,,,,,,,,,,,,,,,,,,,,,,,,,
42.26,0.52003,13.6123,5.5,,,,,,,,,,,,,,,,,,,,,,,,,,,,,,,,,,,,,
42.76,0.43662,9.34357,5.5,,,,,,,,,,,,,,,,,,,,,,,,,,,,,,,,,,,,,
43.26,0.35343,6.01265,5.5,,,,,,,,,,,,,,,,,,,,,,,,,,,,,,,,,,,,,
43.76,0.2699,3.01648,5.5,,,,,,,,,,,,,,,,,,,,,,,,,,,,,,,,,,,,,
44.16,0.20321,0.99156,6,,,,,,,,,,,,,,,,,,,,,,,,,,,,,,,,,,,,,
44.562,0.27064,3.49891,6,,,,,,,,,,,,,,,,,,,,,,,,,,,,,,,,,,,,,
45.062,0.35394,7.15992,6,,,,,,,,,,,,,,,,,,,,,,,,,,,,,,,,,,,,,
45.562,0.43724,10.80057,6,,,,,,,,,,,,,,,,,,,,,,,,,,,,,,,,,,,,,
46.062,0.52071,15.14958,6,,,,,,,,,,,,,,,,,,,,,,,,,,,,,,,,,,,,,
46.562,0.60395,20.77158,6,,,,,,,,,,,,,,,,,,,,,,,,,,,,,,,,,,,,,
47.062,0.68731,27.11895,6,,,,,,,,,,,,,,,,,,,,,,,,,,,,,,,,,,,,,
47.562,0.77061,34.51667,6,,,,,,,,,,,,,,,,,,,,,,,,,,,,,,,,,,,,,
47.896,0.82626,40.04097,6.5,,,,,,,,,,,,,,,,,,,,,,,,,,,,,,,,,,,,,
48.396,0.74279,30.92807,6.5,,,,,,,,,,,,,,,,,,,,,,,,,,,,,,,,,,,,,
48.896,0.65926,23.04841,6.5,,,,,,,,,,,,,,,,,,,,,,,,,,,,,,,,,,,,,
49.396,0.57613,16.74352,6.5,,,,,,,,,,,,,,,,,,,,,,,,,,,,,,,,,,,,,
49.896,0.49266,11.77316,6.5,,,,,,,,,,,,,,,,,,,,,,,,,,,,,,,,,,,,,
50.396,0.40942,7.93503,6.5,,,,,,,,,,,,,,,,,,,,,,,,,,,,,,,,,,,,,
50.896,0.326,4.7112,6.5,,,,,,,,,,,,,,,,,,,,,,,,,,,,,,,,,,,,,
51.396,0.24276,1.91835,6.5,,,,,,,,,,,,,,,,,,,,,,,,,,,,,,,,,,,,,
51.686,0.22372,1.06688,7,,,,,,,,,,,,,,,,,,,,,,,,,,,,,,,,,,,,,
52.186,0.31189,5.03433,7,,,,,,,,,,,,,,,,,,,,,,,,,,,,,,,,,,,,,
52.686,0.39536,8.7548,7,,,,,,,,,,,,,,,,,,,,,,,,,,,,,,,,,,,,,
53.186,0.47866,12.45536,7,,,,,,,,,,,,,,,,,,,,,,,,,,,,,,,,,,,,,
53.686,0.56202,17.43344,7,,,,,,,,,,,,,,,,,,,,,,,,,,,,,,,,,,,,,
54.186,0.64526,23.34212,7,,,,,,,,,,,,,,,,,,,,,,,,,,,,,,,,,,,,,
54.686,0.72873,30.25156,7,,,,,,,,,,,,,,,,,,,,,,,,,,,,,,,,,,,,,
55.186,0.81203,38.01787,7,,,,,,,,,,,,,,,,,,,,,,,,,,,,,,,,,,,,,
55.506,0.79894,36.7644,7.5,,,,,,,,,,,,,,,,,,,,,,,,,,,,,,,,,,,,,
56.006,0.71491,27.68019,7.5,,,,,,,,,,,,,,,,,,,,,,,,,,,,,,,,,,,,,
56.506,0.63178,20.34116,7.5,,,,,,,,,,,,,,,,,,,,,,,,,,,,,,,,,,,,,
57.006,0.54831,14.65236,7.5,,,,,,,,,,,,,,,,,,,,,,,,,,,,,,,,,,,,,
57.506,0.46501,10.11299,7.5,,,,,,,,,,,,,,,,,,,,,,,,,,,,,,,,,,,,,
58.006,0.38165,6.59434,7.5,,,,,,,,,,,,,,,,,,,,,,,,,,,,,,,,,,,,,
58.506,0.29841,3.54087,7.5,,,,,,,,,,,,,,,,,,,,,,,,,,,,,,,,,,,,,
58.996,0.21664,0.99785,8,,,,,,,,,,,,,,,,,,,,,,,,,,,,,,,,,,,,,
59.3,0.26684,2.76998,8,,,,,,,,,,,,,,,,,,,,,,,,,,,,,,,,,,,,,
59.8,0.35037,6.4542,8,,,,,,,,,,,,,,,,,,,,,,,,,,,,,,,,,,,,,
60.3,0.43361,10.0237,8,,,,,,,,,,,,,,,,,,,,,,,,,,,,,,,,,,,,,
60.8,0.51703,14.2532,8,,,,,,,,,,,,,,,,,,,,,,,,,,,,,,,,,,,,,
61.3,0.60027,19.69542,8,,,,,,,,,,,,,,,,,,,,,,,,,,,,,,,,,,,,,
61.8,0.6838,25.9602,8,,,,,,,,,,,,,,,,,,,,,,,,,,,,,,,,,,,,,
62.3,0.76698,33.16568,8,,,,,,,,,,,,,,,,,,,,,,,,,,,,,,,,,,,,,
62.712,0.83566,40.01392,8.5,,,,,,,,,,,,,,,,,,,,,,,,,,,,,,,,,,,,,
63.114,0.76902,32.73989,8.5,,,,,,,,,,,,,,,,,,,,,,,,,,,,,,,,,,,,,
63.614,0.68584,24.49289,8.5,,,,,,,,,,,,,,,,,,,,,,,,,,,,,,,,,,,,,
64.114,0.60231,17.91587,8.5,,,,,,,,,,,,,,,,,,,,,,,,,,,,,,,,,,,,,
64.614,0.51901,12.59664,8.5,,,,,,,,,,,,,,,,,,,,,,,,,,,,,,,,,,,,,
65.114,0.4356,8.57279,8.5,,,,,,,,,,,,,,,,,,,,,,,,,,,,,,,,,,,,,
65.614,0.35241,5.24114,8.5,,,,,,,,,,,,,,,,,,,,,,,,,,,,,,,,,,,,,
66.114,0.26894,2.43302,8.5,,,,,,,,,,,,,,,,,,,,,,,,,,,,,,,,,,,,,
66.396,0.22208,0.98251,9,,,,,,,,,,,,,,,,,,,,,,,,,,,,,,,,,,,,,
66.896,0.30628,4.24673,9,,,,,,,,,,,,,,,,,,,,,,,,,,,,,,,,,,,,,
67.396,0.3897,7.98019,9,,,,,,,,,,,,,,,,,,,,,,,,,,,,,,,,,,,,,
67.896,0.47294,11.60035,9,,,,,,,,,,,,,,,,,,,,,,,,,,,,,,,,,,,,,
68.396,0.5563,16.36036,9,,,,,,,,,,,,,,,,,,,,,,,,,,,,,,,,,,,,,
68.896,0.63971,22.13948,9,,,,,,,,,,,,,,,,,,,,,,,,,,,,,,,,,,,,,
69.396,0.72301,28.90824,9,,,,,,,,,,,,,,,,,,,,,,,,,,,,,,,,,,,,,
69.896,0.80637,36.65172,9,,,,,,,,,,,,,,,,,,,,,,,,,,,,,,,,,,,,,
70.204,0.82852,39.83338,9.5,,,,,,,,,,,,,,,,,,,,,,,,,,,,,,,,,,,,,
70.704,0.7408,29.28921,9.5,,,,,,,,,,,,,,,,,,,,,,,,,,,,,,,,,,,,,
71.204,0.65728,21.71426,9.5,,,,,,,,,,,,,,,,,,,,,,,,,,,,,,,,,,,,,
71.704,0.57409,15.69795,9.5,,,,,,,,,,,,,,,,,,,,,,,,,,,,,,,,,,,,,
72.204,0.49062,10.88162,9.5,,,,,,,,,,,,,,,,,,,,,,,,,,,,,,,,,,,,,
72.704,0.40743,7.21496,9.5,,,,,,,,,,,,,,,,,,,,,,,,,,,,,,,,,,,,,
73.204,0.32391,3.98871,9.5,,,,,,,,,,,,,,,,,,,,,,,,,,,,,,,,,,,,,
73.704,0.24078,1.37248,9.5,,,,,,,,,,,,,,,,,,,,,,,,,,,,,,,,,,,,,
74.082,0.19918,0.15055,10,,,,,,,,,,,,,,,,,,,,,,,,,,,,,,,,,,,,,
74.582,0.20026,0.30467,10,,,,,,,,,,,,,,,,,,,,,,,,,,,,,,,,,,,,,
75.082,0.21715,0.92388,10,,,,,,,,,,,,,,,,,,,,,,,,,,,,,,,,,,,,,
75.582,0.22791,1.39046,10,,,,,,,,,,,,,,,,,,,,,,,,,,,,,,,,,,,,,
76.082,0.22536,1.33479,10,,,,,,,,,,,,,,,,,,,,,,,,,,,,,,,,,,,,,
76.582,0.21165,0.86788,10,,,,,,,,,,,,,,,,,,,,,,,,,,,,,,,,,,,,,
77.082,0.20995,0.84095,10,,,,,,,,,,,,,,,,,,,,,,,,,,,,,,,,,,,,,
77.582,0.21012,0.84046,10,,,,,,,,,,,,,,,,,,,,,,,,,,,,,,,,,,,,,
78.082,0.21029,0.83669,10,,,,,,,,,,,,,,,,,,,,,,,,,,,,,,,,,,,,,
78.582,0.2104,0.87601,10,,,,,,,,,,,,,,,,,,,,,,,,,,,,,,,,,,,,,
79.082,0.21052,0.87823,10,,,,,,,,,,,,,,,,,,,,,,,,,,,,,,,,,,,,,
79.582,0.21074,0.89714,10,,,,,,,,,,,,,,,,,,,,,,,,,,,,,,,,,,,,,
80.082,0.21108,0.91065,10,,,,,,,,,,,,,,,,,,,,,,,,,,,,,,,,,,,,,
80.582,0.21131,0.95656,10,,,,,,,,,,,,,,,,,,,,,,,,,,,,,,,,,,,,,
81.082,0.21154,0.94131,10,,,,,,,,,,,,,,,,,,,,,,,,,,,,,,,,,,,,,
81.582,0.21159,1.01706,10,,,,,,,,,,,,,,,,,,,,,,,,,,,,,,,,,,,,,
82.082,0.21154,1.01763,10,,,,,,,,,,,,,,,,,,,,,,,,,,,,,,,,,,,,,
82.582,0.21148,1.0411,10,,,,,,,,,,,,,,,,,,,,,,,,,,,,,,,,,,,,,
83.082,0.21137,1.03426,10,,,,,,,,,,,,,,,,,,,,,,,,,,,,,,,,,,,,,
83.582,0.21125,1.06401,10,,,,,,,,,,,,,,,,,,,,,,,,,,,,,,,,,,,,,
84.082,0.21114,1.01593,10,,,,,,,,,,,,,,,,,,,,,,,,,,,,,,,,,,,,,
84.582,0.21086,1.03664,10,,,,,,,,,,,,,,,,,,,,,,,,,,,,,,,,,,,,,
85.082,0.20995,1.04933,10,,,,,,,,,,,,,,,,,,,,,,,,,,,,,,,,,,,,,
85.582,0.20836,0.97773,10,,,,,,,,,,,,,,,,,,,,,,,,,,,,,,,,,,,,,
86.082,0.20717,0.93652,10,,,,,,,,,,,,,,,,,,,,,,,,,,,,,,,,,,,,,
86.582,0.20678,0.93305,10,,,,,,,,,,,,,,,,,,,,,,,,,,,,,,,,,,,,,
87.082,0.20661,0.91759,10,,,,,,,,,,,,,,,,,,,,,,,,,,,,,,,,,,,,,
87.582,0.20649,0.91937,10,,,,,,,,,,,,,,,,,,,,,,,,,,,,,,,,,,,,,
88.082,0.20644,0.9827,10,,,,,,,,,,,,,,,,,,,,,,,,,,,,,,,,,,,,,
88.582,0.20632,0.91464,10,,,,,,,,,,,,,,,,,,,,,,,,,,,,,,,,,,,,,
89.082,0.20627,0.95536,10,,,,,,,,,,,,,,,,,,,,,,,,,,,,,,,,,,,,,
89.582,0.20621,0.92225,10,,,,,,,,,,,,,,,,,,,,,,,,,,,,,,,,,,,,,
90.082,0.20615,0.91523,10,,,,,,,,,,,,,,,,,,,,,,,,,,,,,,,,,,,,,
90.582,0.2061,0.98154,10,,,,,,,,,,,,,,,,,,,,,,,,,,,,,,,,,,,,,
91.082,0.20598,0.95951,10,,,,,,,,,,,,,,,,,,,,,,,,,,,,,,,,,,,,,
91.582,0.20598,0.98306,10,,,,,,,,,,,,,,,,,,,,,,,,,,,,,,,,,,,,,
92.082,0.20581,0.96943,10,,,,,,,,,,,,,,,,,,,,,,,,,,,,,,,,,,,,,
92.582,0.20576,1.01435,10,,,,,,,,,,,,,,,,,,,,,,,,,,,,,,,,,,,,,
93.082,0.20559,1.00462,10,,,,,,,,,,,,,,,,,,,,,,,,,,,,,,,,,,,,,
93.582,0.2053,0.98003,10,,,,,,,,,,,,,,,,,,,,,,,,,,,,,,,,,,,,,
94.082,0.20496,0.98934,10,,,,,,,,,,,,,,,,,,,,,,,,,,,,,,,,,,,,,
94.582,0.20457,0.92124,10,,,,,,,,,,,,,,,,,,,,,,,,,,,,,,,,,,,,,
95.082,0.20434,0.92224,10,,,,,,,,,,,,,,,,,,,,,,,,,,,,,,,,,,,,,
95.582,0.20411,1.00144,10,,,,,,,,,,,,,,,,,,,,,,,,,,,,,,,,,,,,,
96.082,0.204,0.91906,10,,,,,,,,,,,,,,,,,,,,,,,,,,,,,,,,,,,,,
96.582,0.20394,0.93789,10,,,,,,,,,,,,,,,,,,,,,,,,,,,,,,,,,,,,,
97.082,0.20389,0.93841,10,,,,,,,,,,,,,,,,,,,,,,,,,,,,,,,,,,,,,
97.582,0.20389,0.97146,10,,,,,,,,,,,,,,,,,,,,,,,,,,,,,,,,,,,,,
98.082,0.20383,0.92705,10,,,,,,,,,,,,,,,,,,,,,,,,,,,,,,,,,,,,,
98.582,0.20377,1.00761,10,,,,,,,,,,,,,,,,,,,,,,,,,,,,,,,,,,,,,
99.082,0.20372,0.99078,10,,,,,,,,,,,,,,,,,,,,,,,,,,,,,,,,,,,,,
99.582,0.2036,0.96492,10,,,,,,,,,,,,,,,,,,,,,,,,,,,,,,,,,,,,,
100.082,0.20338,0.98224,10,,,,,,,,,,,,,,,,,,,,,,,,,,,,,,,,,,,,,
100.582,0.20315,0.87159,10,,,,,,,,,,,,,,,,,,,,,,,,,,,,,,,,,,,,,
101.082,0.20292,0.99725,10,,,,,,,,,,,,,,,,,,,,,,,,,,,,,,,,,,,,,
101.582,0.20275,0.97453,10,,,,,,,,,,,,,,,,,,,,,,,,,,,,,,,,,,,,,
102.082,0.20258,0.92032,10,,,,,,,,,,,,,,,,,,,,,,,,,,,,,,,,,,,,,
102.582,0.20247,0.93561,10,,,,,,,,,,,,,,,,,,,,,,,,,,,,,,,,,,,,,
103.082,0.20258,0.93548,10,,,,,,,,,,,,,,,,,,,,,,,,,,,,,,,,,,,,,
103.582,0.20247,0.90133,10,,,,,,,,,,,,,,,,,,,,,,,,,,,,,,,,,,,,,
104.082,0.20258,0.98024,10,,,,,,,,,,,,,,,,,,,,,,,,,,,,,,,,,,,,,
104.582,0.20258,0.93548,10,,,,,,,,,,,,,,,,,,,,,,,,,,,,,,,,,,,,,
105.082,0.20258,0.94726,10,,,,,,,,,,,,,,,,,,,,,,,,,,,,,,,,,,,,,
105.582,0.20258,0.95719,10,,,,,,,,,,,,,,,,,,,,,,,,,,,,,,,,,,,,,
106.082,0.20258,0.94509,10,,,,,,,,,,,,,,,,,,,,,,,,,,,,,,,,,,,,,
106.582,0.20258,0.94746,10,,,,,,,,,,,,,,,,,,,,,,,,,,,,,,,,,,,,,
107.082,0.20258,0.97725,10,,,,,,,,,,,,,,,,,,,,,,,,,,,,,,,,,,,,,
107.582,0.20258,0.98023,10,,,,,,,,,,,,,,,,,,,,,,,,,,,,,,,,,,,,,
108.082,0.20247,0.94914,10,,,,,,,,,,,,,,,,,,,,,,,,,,,,,,,,,,,,,
108.582,0.20258,0.95798,10,,,,,,,,,,,,,,,,,,,,,,,,,,,,,,,,,,,,,
109.082,0.20258,0.96334,10,,,,,,,,,,,,,,,,,,,,,,,,,,,,,,,,,,,,,
109.582,0.20247,0.93489,10,,,,,,,,,,,,,,,,,,,,,,,,,,,,,,,,,,,,,
110.082,0.20247,1.06224,10,,,,,,,,,,,,,,,,,,,,,,,,,,,,,,,,,,,,,
110.582,0.20247,0.94073,10,,,,,,,,,,,,,,,,,,,,,,,,,,,,,,,,,,,,,
111.082,0.20247,1.02647,10,,,,,,,,,,,,,,,,,,,,,,,,,,,,,,,,,,,,,
111.582,0.20247,0.94304,10,,,,,,,,,,,,,,,,,,,,,,,,,,,,,,,,,,,,,
112.082,0.20247,0.9094,10,,,,,,,,,,,,,,,,,,,,,,,,,,,,,,,,,,,,,
112.582,0.20247,0.97682,10,,,,,,,,,,,,,,,,,,,,,,,,,,,,,,,,,,,,,
113.082,0.20247,0.98558,10,,,,,,,,,,,,,,,,,,,,,,,,,,,,,,,,,,,,,
113.582,0.20236,1.01914,10,,,,,,,,,,,,,,,,,,,,,,,,,,,,,,,,,,,,,
114.082,0.20224,1.01931,10,,,,,,,,,,,,,,,,,,,,,,,,,,,,,,,,,,,,,
114.582,0.20202,0.99368,10,,,,,,,,,,,,,,,,,,,,,,,,,,,,,,,,,,,,,
115.082,0.20168,0.98775,10,,,,,,,,,,,,,,,,,,,,,,,,,,,,,,,,,,,,,
115.582,0.20105,0.93778,10,,,,,,,,,,,,,,,,,,,,,,,,,,,,,,,,,,,,,
116.082,0.20071,0.94327,10,,,,,,,,,,,,,,,,,,,,,,,,,,,,,,,,,,,,,
116.582,0.20032,0.94591,10,,,,,,,,,,,,,,,,,,,,,,,,,,,,,,,,,,,,,
117.082,0.2002,0.92899,10,,,,,,,,,,,,,,,,,,,,,,,,,,,,,,,,,,,,,
117.582,0.20009,0.94021,10,,,,,,,,,,,,,,,,,,,,,,,,,,,,,,,,,,,,,
118.082,0.2002,0.91949,10,,,,,,,,,,,,,,,,,,,,,,,,,,,,,,,,,,,,,
118.582,0.20015,0.90534,10,,,,,,,,,,,,,,,,,,,,,,,,,,,,,,,,,,,,,
119.082,0.20026,0.90971,10,,,,,,,,,,,,,,,,,,,,,,,,,,,,,,,,,,,,,
119.582,0.20032,0.92352,10,,,,,,,,,,,,,,,,,,,,,,,,,,,,,,,,,,,,,
120.082,0.20032,0.95228,10,,,,,,,,,,,,,,,,,,,,,,,,,,,,,,,,,,,,,
120.582,0.20037,0.92698,10,,,,,,,,,,,,,,,,,,,,,,,,,,,,,,,,,,,,,
121.082,0.20043,0.91643,10,,,,,,,,,,,,,,,,,,,,,,,,,,,,,,,,,,,,,
121.582,0.20049,0.92941,10,,,,,,,,,,,,,,,,,,,,,,,,,,,,,,,,,,,,,
122.082,0.20054,0.88737,10,,,,,,,,,,,,,,,,,,,,,,,,,,,,,,,,,,,,,
122.582,0.2006,0.96759,10,,,,,,,,,,,,,,,,,,,,,,,,,,,,,,,,,,,,,
123.082,0.2006,0.89423,10,,,,,,,,,,,,,,,,,,,,,,,,,,,,,,,,,,,,,
123.582,0.20071,0.8745,10,,,,,,,,,,,,,,,,,,,,,,,,,,,,,,,,,,,,,
124.082,0.20088,0.90677,10,,,,,,,,,,,,,,,,,,,,,,,,,,,,,,,,,,,,,
124.582,0.20094,0.91178,10,,,,,,,,,,,,,,,,,,,,,,,,,,,,,,,,,,,,,
125.082,0.201,0.90718,10,,,,,,,,,,,,,,,,,,,,,,,,,,,,,,,,,,,,,
125.582,0.20105,0.95602,10,,,,,,,,,,,,,,,,,,,,,,,,,,,,,,,,,,,,,
126.082,0.20111,0.89245,10,,,,,,,,,,,,,,,,,,,,,,,,,,,,,,,,,,,,,
126.582,0.20117,0.94124,10,,,,,,,,,,,,,,,,,,,,,,,,,,,,,,,,,,,,,
127.082,0.20122,0.96713,10,,,,,,,,,,,,,,,,,,,,,,,,,,,,,,,,,,,,,
127.582,0.20122,0.9839,10,,,,,,,,,,,,,,,,,,,,,,,,,,,,,,,,,,,,,
128.082,0.20122,0.96359,10,,,,,,,,,,,,,,,,,,,,,,,,,,,,,,,,,,,,,
128.582,0.20122,0.98331,10,,,,,,,,,,,,,,,,,,,,,,,,,,,,,,,,,,,,,
129.082,0.20122,0.98645,10,,,,,,,,,,,,,,,,,,,,,,,,,,,,,,,,,,,,,
129.582,0.20122,0.93155,10,,,,,,,,,,,,,,,,,,,,,,,,,,,,,,,,,,,,,
130.082,0.20122,0.89799,10,,,,,,,,,,,,,,,,,,,,,,,,,,,,,,,,,,,,,
130.582,0.20117,0.9613,10,,,,,,,,,,,,,,,,,,,,,,,,,,,,,,,,,,,,,
131.082,0.20117,0.96039,10,,,,,,,,,,,,,,,,,,,,,,,,,,,,,,,,,,,,,
131.582,0.20117,0.97691,10,,,,,,,,,,,,,,,,,,,,,,,,,,,,,,,,,,,,,
132.082,0.20117,0.94915,10,,,,,,,,,,,,,,,,,,,,,,,,,,,,,,,,,,,,,
132.582,0.20122,1.03923,10,,,,,,,,,,,,,,,,,,,,,,,,,,,,,,,,,,,,,
133.082,0.20111,0.97435,10,,,,,,,,,,,,,,,,,,,,,,,,,,,,,,,,,,,,,
133.582,0.20105,0.94166,10,,,,,,,,,,,,,,,,,,,,,,,,,,,,,,,,,,,,,
134.082,0.20105,0.98458,10,,,,,,,,,,,,,,,,,,,,,,,,,,,,,,,,,,,,,
134.582,0.20111,0.99304,10,,,,,,,,,,,,,,,,,,,,,,,,,,,,,,,,,,,,,
135.082,0.201,0.93502,10,,,,,,,,,,,,,,,,,,,,,,,,,,,,,,,,,,,,,
135.582,0.20111,0.95855,10,,,,,,,,,,,,,,,,,,,,,,,,,,,,,,,,,,,,,
136.082,0.20111,0.94816,10,,,,,,,,,,,,,,,,,,,,,,,,,,,,,,,,,,,,,
136.582,0.201,1.04553,10,,,,,,,,,,,,,,,,,,,,,,,,,,,,,,,,,,,,,
137.082,0.201,0.99243,10,,,,,,,,,,,,,,,,,,,,,,,,,,,,,,,,,,,,,
137.582,0.201,0.9822,10,,,,,,,,,,,,,,,,,,,,,,,,,,,,,,,,,,,,,
138.082,0.20111,0.95867,10,,,,,,,,,,,,,,,,,,,,,,,,,,,,,,,,,,,,,
138.582,0.201,0.98468,10,,,,,,,,,,,,,,,,,,,,,,,,,,,,,,,,,,,,,
139.082,0.201,0.95594,10,,,,,,,,,,,,,,,,,,,,,,,,,,,,,,,,,,,,,
139.582,0.201,0.95643,10,,,,,,,,,,,,,,,,,,,,,,,,,,,,,,,,,,,,,
140.082,0.201,0.93068,10,,,,,,,,,,,,,,,,,,,,,,,,,,,,,,,,,,,,,
140.582,0.201,0.9524,10,,,,,,,,,,,,,,,,,,,,,,,,,,,,,,,,,,,,,
141.082,0.20105,0.95957,10,,,,,,,,,,,,,,,,,,,,,,,,,,,,,,,,,,,,,
141.582,0.20094,0.98582,10,,,,,,,,,,,,,,,,,,,,,,,,,,,,,,,,,,,,,
142.082,0.20088,1.00741,10,,,,,,,,,,,,,,,,,,,,,,,,,,,,,,,,,,,,,
142.582,0.20088,0.95552,10,,,,,,,,,,,,,,,,,,,,,,,,,,,,,,,,,,,,,
143.082,0.20088,0.9102,10,,,,,,,,,,,,,,,,,,,,,,,,,,,,,,,,,,,,,
143.582,0.20083,0.95961,10,,,,,,,,,,,,,,,,,,,,,,,,,,,,,,,,,,,,,
144.082,0.20083,0.98893,10,,,,,,,,,,,,,,,,,,,,,,,,,,,,,,,,,,,,,
144.582,0.20083,0.93414,10,,,,,,,,,,,,,,,,,,,,,,,,,,,,,,,,,,,,,
145.082,0.20083,1.01264,10,,,,,,,,,,,,,,,,,,,,,,,,,,,,,,,,,,,,,
145.582,0.20088,0.95818,10,,,,,,,,,,,,,,,,,,,,,,,,,,,,,,,,,,,,,
146.082,0.20088,0.97045,10,,,,,,,,,,,,,,,,,,,,,,,,,,,,,,,,,,,,,
146.582,0.20088,0.95068,10,,,,,,,,,,,,,,,,,,,,,,,,,,,,,,,,,,,,,
147.082,0.20088,0.94216,10,,,,,,,,,,,,,,,,,,,,,,,,,,,,,,,,,,,,,
147.582,0.20077,0.96476,10,,,,,,,,,,,,,,,,,,,,,,,,,,,,,,,,,,,,,
148.082,0.20077,0.98624,10,,,,,,,,,,,,,,,,,,,,,,,,,,,,,,,,,,,,,
148.582,0.20077,0.94017,10,,,,,,,,,,,,,,,,,,,,,,,,,,,,,,,,,,,,,
149.082,0.20071,0.9471,10,,,,,,,,,,,,,,,,,,,,,,,,,,,,,,,,,,,,,
149.582,0.20071,1.00592,10,,,,,,,,,,,,,,,,,,,,,,,,,,,,,,,,,,,,,
150.082,0.20066,0.97158,10,,,,,,,,,,,,,,,,,,,,,,,,,,,,,,,,,,,,,
150.582,0.20054,0.94626,10,,,,,,,,,,,,,,,,,,,,,,,,,,,,,,,,,,,,,
151.082,0.20054,0.92094,10,,,,,,,,,,,,,,,,,,,,,,,,,,,,,,,,,,,,,
151.582,0.20054,0.97975,10,,,,,,,,,,,,,,,,,,,,,,,,,,,,,,,,,,,,,
152.082,0.20054,0.92358,10,,,,,,,,,,,,,,,,,,,,,,,,,,,,,,,,,,,,,
152.582,0.20049,0.92587,10,,,,,,,,,,,,,,,,,,,,,,,,,,,,,,,,,,,,,
153.082,0.20049,0.9596,10,,,,,,,,,,,,,,,,,,,,,,,,,,,,,,,,,,,,,
153.582,0.20054,0.96381,10,,,,,,,,,,,,,,,,,,,,,,,,,,,,,,,,,,,,,
154.082,0.20049,0.95561,10,,,,,,,,,,,,,,,,,,,,,,,,,,,,,,,,,,,,,
154.582,0.20037,0.97515,10,,,,,,,,,,,,,,,,,,,,,,,,,,,,,,,,,,,,,
155.082,0.20037,0.97577,10,,,,,,,,,,,,,,,,,,,,,,,,,,,,,,,,,,,,,
155.582,0.20037,0.97547,10,,,,,,,,,,,,,,,,,,,,,,,,,,,,,,,,,,,,,
156.082,0.20037,0.94803,10,,,,,,,,,,,,,,,,,,,,,,,,,,,,,,,,,,,,,
156.582,0.20037,0.95632,10,,,,,,,,,,,,,,,,,,,,,,,,,,,,,,,,,,,,,
157.082,0.20037,0.96243,10,,,,,,,,,,,,,,,,,,,,,,,,,,,,,,,,,,,,,
157.582,0.20032,0.97584,10,,,,,,,,,,,,,,,,,,,,,,,,,,,,,,,,,,,,,
158.082,0.20032,0.92907,10,,,,,,,,,,,,,,,,,,,,,,,,,,,,,,,,,,,,,
158.582,0.20026,0.97631,10,,,,,,,,,,,,,,,,,,,,,,,,,,,,,,,,,,,,,
159.082,0.2002,0.95849,10,,,,,,,,,,,,,,,,,,,,,,,,,,,,,,,,,,,,,
159.582,0.20009,0.98769,10,,,,,,,,,,,,,,,,,,,,,,,,,,,,,,,,,,,,,
160.082,0.19986,0.96611,10,,,,,,,,,,,,,,,,,,,,,,,,,,,,,,,,,,,,,
160.582,0.19952,0.97453,10,,,,,,,,,,,,,,,,,,,,,,,,,,,,,,,,,,,,,
161.082,0.19913,0.95746,10,,,,,,,,,,,,,,,,,,,,,,,,,,,,,,,,,,,,,
161.582,0.19884,0.94035,10,,,,,,,,,,,,,,,,,,,,,,,,,,,,,,,,,,,,,
162.082,0.19867,0.95035,10,,,,,,,,,,,,,,,,,,,,,,,,,,,,,,,,,,,,,
162.582,0.19862,0.88007,10,,,,,,,,,,,,,,,,,,,,,,,,,,,,,,,,,,,,,
163.082,0.19873,0.92903,10,,,,,,,,,,,,,,,,,,,,,,,,,,,,,,,,,,,,,
163.582,0.19879,0.92313,10,,,,,,,,,,,,,,,,,,,,,,,,,,,,,,,,,,,,,
164.082,0.19884,0.88368,10,,,,,,,,,,,,,,,,,,,,,,,,,,,,,,,,,,,,,
164.582,0.19884,0.96832,10,,,,,,,,,,,,,,,,,,,,,,,,,,,,,,,,,,,,,
165.082,0.1989,0.92499,10,,,,,,,,,,,,,,,,,,,,,,,,,,,,,,,,,,,,,
165.582,0.19896,0.96968,10,,,,,,,,,,,,,,,,,,,,,,,,,,,,,,,,,,,,,
166.082,0.19907,0.90465,10,,,,,,,,,,,,,,,,,,,,,,,,,,,,,,,,,,,,,
166.582,0.19907,0.94877,10,,,,,,,,,,,,,,,,,,,,,,,,,,,,,,,,,,,,,
167.082,0.19907,0.9313,10,,,,,,,,,,,,,,,,,,,,,,,,,,,,,,,,,,,,,
167.582,0.19907,0.99004,10,,,,,,,,,,,,,,,,,,,,,,,,,,,,,,,,,,,,,
168.082,0.19907,0.92545,10,,,,,,,,,,,,,,,,,,,,,,,,,,,,,,,,,,,,,
168.582,0.19907,0.93539,10,,,,,,,,,,,,,,,,,,,,,,,,,,,,,,,,,,,,,
169.082,0.19907,0.96602,10,,,,,,,,,,,,,,,,,,,,,,,,,,,,,,,,,,,,,
169.582,0.19907,0.94703,10,,,,,,,,,,,,,,,,,,,,,,,,,,,,,,,,,,,,,
170.082,0.19907,0.94359,10,,,,,,,,,,,,,,,,,,,,,,,,,,,,,,,,,,,,,
170.582,0.19907,0.93042,10,,,,,,,,,,,,,,,,,,,,,,,,,,,,,,,,,,,,,
171.082,0.19907,0.93777,10,,,,,,,,,,,,,,,,,,,,,,,,,,,,,,,,,,,,,
171.582,0.19901,0.90724,10,,,,,,,,,,,,,,,,,,,,,,,,,,,,,,,,,,,,,
172.082,0.19901,0.90057,10,,,,,,,,,,,,,,,,,,,,,,,,,,,,,,,,,,,,,
172.582,0.19918,0.89669,10,,,,,,,,,,,,,,,,,,,,,,,,,,,,,,,,,,,,,
173.082,0.19918,0.92235,10,,,,,,,,,,,,,,,,,,,,,,,,,,,,,,,,,,,,,
173.582,0.1993,0.89864,10,,,,,,,,,,,,,,,,,,,,,,,,,,,,,,,,,,,,,
174.082,0.19935,0.91662,10,,,,,,,,,,,,,,,,,,,,,,,,,,,,,,,,,,,,,
174.582,0.19947,0.89851,10,,,,,,,,,,,,,,,,,,,,,,,,,,,,,,,,,,,,,
175.082,0.19958,0.88504,10,,,,,,,,,,,,,,,,,,,,,,,,,,,,,,,,,,,,,
175.582,0.19975,0.92803,10,,,,,,,,,,,,,,,,,,,,,,,,,,,,,,,,,,,,,
176.082,0.19986,0.90425,10,,,,,,,,,,,,,,,,,,,,,,,,,,,,,,,,,,,,,
176.582,0.19998,0.95678,10,,,,,,,,,,,,,,,,,,,,,,,,,,,,,,,,,,,,,
177.082,0.20003,0.93465,10,,,,,,,,,,,,,,,,,,,,,,,,,,,,,,,,,,,,,
177.582,0.20009,0.91278,10,,,,,,,,,,,,,,,,,,,,,,,,,,,,,,,,,,,,,
178.082,0.20015,0.91588,10,,,,,,,,,,,,,,,,,,,,,,,,,,,,,,,,,,,,,
178.582,0.2002,0.95717,10,,,,,,,,,,,,,,,,,,,,,,,,,,,,,,,,,,,,,
179.082,0.2002,0.94455,10,,,,,,,,,,,,,,,,,,,,,,,,,,,,,,,,,,,,,
179.582,0.20015,1.00695,10,,,,,,,,,,,,,,,,,,,,,,,,,,,,,,,,,,,,,
180.082,0.20015,0.96928,10,,,,,,,,,,,,,,,,,,,,,,,,,,,,,,,,,,,,,
180.582,0.20009,0.99706,10,,,,,,,,,,,,,,,,,,,,,,,,,,,,,,,,,,,,,
181.082,0.20009,0.94967,10,,,,,,,,,,,,,,,,,,,,,,,,,,,,,,,,,,,,,
181.582,0.20003,0.94685,10,,,,,,,,,,,,,,,,,,,,,,,,,,,,,,,,,,,,,
182.082,0.20009,0.96499,10,,,,,,,,,,,,,,,,,,,,,,,,,,,,,,,,,,,,,
182.582,0.19998,0.9567,10,,,,,,,,,,,,,,,,,,,,,,,,,,,,,,,,,,,,,
183.082,0.19992,0.94494,10,,,,,,,,,,,,,,,,,,,,,,,,,,,,,,,,,,,,,
183.582,0.19992,0.94403,10,,,,,,,,,,,,,,,,,,,,,,,,,,,,,,,,,,,,,
184.082,0.19992,1.00242,10,,,,,,,,,,,,,,,,,,,,,,,,,,,,,,,,,,,,,
184.582,0.19986,0.9417,10,,,,,,,,,,,,,,,,,,,,,,,,,,,,,,,,,,,,,
185.082,0.19986,0.95782,10,,,,,,,,,,,,,,,,,,,,,,,,,,,,,,,,,,,,,
185.582,0.19986,0.97459,10,,,,,,,,,,,,,,,,,,,,,,,,,,,,,,,,,,,,,
186.082,0.19986,0.94794,10,,,,,,,,,,,,,,,,,,,,,,,,,,,,,,,,,,,,,
186.582,0.19986,0.9592,10,,,,,,,,,,,,,,,,,,,,,,,,,,,,,,,,,,,,,
187.082,0.19986,0.94859,10,,,,,,,,,,,,,,,,,,,,,,,,,,,,,,,,,,,,,
187.582,0.19986,0.93175,10,,,,,,,,,,,,,,,,,,,,,,,,,,,,,,,,,,,,,
188.082,0.19986,0.95975,10,,,,,,,,,,,,,,,,,,,,,,,,,,,,,,,,,,,,,
188.582,0.19986,1.02618,10,,,,,,,,,,,,,,,,,,,,,,,,,,,,,,,,,,,,,
189.082,0.19986,0.93884,10,,,,,,,,,,,,,,,,,,,,,,,,,,,,,,,,,,,,,
189.582,0.19986,0.95677,10,,,,,,,,,,,,,,,,,,,,,,,,,,,,,,,,,,,,,
190.082,0.19986,1.01076,10,,,,,,,,,,,,,,,,,,,,,,,,,,,,,,,,,,,,,
190.582,0.19986,0.94536,10,,,,,,,,,,,,,,,,,,,,,,,,,,,,,,,,,,,,,
191.082,0.19986,0.9732,10,,,,,,,,,,,,,,,,,,,,,,,,,,,,,,,,,,,,,
191.582,0.19986,0.93085,10,,,,,,,,,,,,,,,,,,,,,,,,,,,,,,,,,,,,,
192.082,0.19986,0.95045,10,,,,,,,,,,,,,,,,,,,,,,,,,,,,,,,,,,,,,
192.582,0.19986,0.93545,10,,,,,,,,,,,,,,,,,,,,,,,,,,,,,,,,,,,,,
193.082,0.19986,0.9659,10,,,,,,,,,,,,,,,,,,,,,,,,,,,,,,,,,,,,,
193.582,0.19992,0.96778,10,,,,,,,,,,,,,,,,,,,,,,,,,,,,,,,,,,,,,
194.082,0.19992,0.98727,10,,,,,,,,,,,,,,,,,,,,,,,,,,,,,,,,,,,,,
194.582,0.19992,1.01955,10,,,,,,,,,,,,,,,,,,,,,,,,,,,,,,,,,,,,,
195.082,0.19992,0.96586,10,,,,,,,,,,,,,,,,,,,,,,,,,,,,,,,,,,,,,
195.582,0.19981,0.95883,10,,,,,,,,,,,,,,,,,,,,,,,,,,,,,,,,,,,,,
196.082,0.19981,0.97692,10,,,,,,,,,,,,,,,,,,,,,,,,,,,,,,,,,,,,,
196.582,0.19981,0.97324,10,,,,,,,,,,,,,,,,,,,,,,,,,,,,,,,,,,,,,
197.082,0.19981,0.95148,10,,,,,,,,,,,,,,,,,,,,,,,,,,,,,,,,,,,,,
197.582,0.19981,0.96219,10,,,,,,,,,,,,,,,,,,,,,,,,,,,,,,,,,,,,,
198.082,0.19975,0.95038,10,,,,,,,,,,,,,,,,,,,,,,,,,,,,,,,,,,,,,
198.582,0.19958,0.98358,10,,,,,,,,,,,,,,,,,,,,,,,,,,,,,,,,,,,,,
199.082,0.19958,0.96344,10,,,,,,,,,,,,,,,,,,,,,,,,,,,,,,,,,,,,,
199.582,0.19958,0.90565,10,,,,,,,,,,,,,,,,,,,,,,,,,,,,,,,,,,,,,
200.082,0.19958,0.93897,10,,,,,,,,,,,,,,,,,,,,,,,,,,,,,,,,,,,,,
200.582,0.19958,0.95355,10,,,,,,,,,,,,,,,,,,,,,,,,,,,,,,,,,,,,,
201.082,0.19958,0.97104,10,,,,,,,,,,,,,,,,,,,,,,,,,,,,,,,,,,,,,
201.582,0.19969,0.96381,10,,,,,,,,,,,,,,,,,,,,,,,,,,,,,,,,,,,,,
202.082,0.19958,0.9665,10,,,,,,,,,,,,,,,,,,,,,,,,,,,,,,,,,,,,,
202.582,0.19958,0.97061,10,,,,,,,,,,,,,,,,,,,,,,,,,,,,,,,,,,,,,
203.082,0.19964,0.97663,10,,,,,,,,,,,,,,,,,,,,,,,,,,,,,,,,,,,,,
203.582,0.19964,0.92372,10,,,,,,,,,,,,,,,,,,,,,,,,,,,,,,,,,,,,,
204.082,0.19964,0.94427,10,,,,,,,,,,,,,,,,,,,,,,,,,,,,,,,,,,,,,
204.582,0.19964,0.9607,10,,,,,,,,,,,,,,,,,,,,,,,,,,,,,,,,,,,,,
205.082,0.19964,0.95708,10,,,,,,,,,,,,,,,,,,,,,,,,,,,,,,,,,,,,,
205.582,0.19952,0.94536,10,,,,,,,,,,,,,,,,,,,,,,,,,,,,,,,,,,,,,
206.082,0.19952,0.94621,10,,,,,,,,,,,,,,,,,,,,,,,,,,,,,,,,,,,,,
206.582,0.19947,0.93293,10,,,,,,,,,,,,,,,,,,,,,,,,,,,,,,,,,,,,,
207.082,0.19947,0.92991,10,,,,,,,,,,,,,,,,,,,,,,,,,,,,,,,,,,,,,
207.582,0.19952,0.98906,10,,,,,,,,,,,,,,,,,,,,,,,,,,,,,,,,,,,,,
208.082,0.19952,0.97406,10,,,,,,,,,,,,,,,,,,,,,,,,,,,,,,,,,,,,,
208.582,0.19941,1.01067,10,,,,,,,,,,,,,,,,,,,,,,,,,,,,,,,,,,,,,
209.082,0.19941,0.97915,10,,,,,,,,,,,,,,,,,,,,,,,,,,,,,,,,,,,,,
209.582,0.19924,0.97898,10,,,,,,,,,,,,,,,,,,,,,,,,,,,,,,,,,,,,,
210.082,0.19924,0.92806,10,,,,,,,,,,,,,,,,,,,,,,,,,,,,,,,,,,,,,
210.582,0.19924,0.99067,10,,,,,,,,,,,,,,,,,,,,,,,,,,,,,,,,,,,,,
211.082,0.19924,0.94231,10,,,,,,,,,,,,,,,,,,,,,,,,,,,,,,,,,,,,,
211.582,0.19918,0.924,10,,,,,,,,,,,,,,,,,,,,,,,,,,,,,,,,,,,,,
212.082,0.19918,0.95814,10,,,,,,,,,,,,,,,,,,,,,,,,,,,,,,,,,,,,,
212.582,0.19918,0.96513,10,,,,,,,,,,,,,,,,,,,,,,,,,,,,,,,,,,,,,
213.082,0.19918,1.00776,10,,,,,,,,,,,,,,,,,,,,,,,,,,,,,,,,,,,,,
213.582,0.19918,0.94469,10,,,,,,,,,,,,,,,,,,,,,,,,,,,,,,,,,,,,,
214.082,0.19918,0.98438,10,,,,,,,,,,,,,,,,,,,,,,,,,,,,,,,,,,,,,
214.582,0.19924,0.94526,10,,,,,,,,,,,,,,,,,,,,,,,,,,,,,,,,,,,,,
215.082,0.19924,0.97703,10,,,,,,,,,,,,,,,,,,,,,,,,,,,,,,,,,,,,,
215.582,0.19924,0.92662,10,,,,,,,,,,,,,,,,,,,,,,,,,,,,,,,,,,,,,
216.082,0.19924,0.98582,10,,,,,,,,,,,,,,,,,,,,,,,,,,,,,,,,,,,,,
216.582,0.19924,0.97897,10,,,,,,,,,,,,,,,,,,,,,,,,,,,,,,,,,,,,,
217.082,0.19918,0.94378,10,,,,,,,,,,,,,,,,,,,,,,,,,,,,,,,,,,,,,
217.582,0.19918,0.90296,10,,,,,,,,,,,,,,,,,,,,,,,,,,,,,,,,,,,,,
218.082,0.1993,0.95348,10,,,,,,,,,,,,,,,,,,,,,,,,,,,,,,,,,,,,,
218.582,0.19924,0.97452,10,,,,,,,,,,,,,,,,,,,,,,,,,,,,,,,,,,,,,
219.082,0.1993,0.96336,10,,,,,,,,,,,,,,,,,,,,,,,,,,,,,,,,,,,,,
219.582,0.19924,0.92129,10,,,,,,,,,,,,,,,,,,,,,,,,,,,,,,,,,,,,,
220.082,0.19924,0.97007,10,,,,,,,,,,,,,,,,,,,,,,,,,,,,,,,,,,,,,
220.582,0.19935,0.95367,10,,,,,,,,,,,,,,,,,,,,,,,,,,,,,,,,,,,,,
221.082,0.19935,0.95647,10,,,,,,,,,,,,,,,,,,,,,,,,,,,,,,,,,,,,,
221.582,0.19935,0.97849,10,,,,,,,,,,,,,,,,,,,,,,,,,,,,,,,,,,,,,
222.082,0.19935,0.94273,10,,,,,,,,,,,,,,,,,,,,,,,,,,,,,,,,,,,,,
222.582,0.19935,0.98224,10,,,,,,,,,,,,,,,,,,,,,,,,,,,,,,,,,,,,,
223.082,0.19935,0.96841,10,,,,,,,,,,,,,,,,,,,,,,,,,,,,,,,,,,,,,
223.582,0.19935,0.94107,10,,,,,,,,,,,,,,,,,,,,,,,,,,,,,,,,,,,,,
224.082,0.19935,0.93156,10,,,,,,,,,,,,,,,,,,,,,,,,,,,,,,,,,,,,,
224.582,0.1993,0.964,10,,,,,,,,,,,,,,,,,,,,,,,,,,,,,,,,,,,,,
225.082,0.1993,0.94942,10,,,,,,,,,,,,,,,,,,,,,,,,,,,,,,,,,,,,,
225.582,0.19935,0.97589,10,,,,,,,,,,,,,,,,,,,,,,,,,,,,,,,,,,,,,
226.082,0.1993,0.95765,10,,,,,,,,,,,,,,,,,,,,,,,,,,,,,,,,,,,,,
226.582,0.1993,0.94204,10,,,,,,,,,,,,,,,,,,,,,,,,,,,,,,,,,,,,,
227.082,0.19941,0.89706,10,,,,,,,,,,,,,,,,,,,,,,,,,,,,,,,,,,,,,
227.582,0.1993,0.95121,10,,,,,,,,,,,,,,,,,,,,,,,,,,,,,,,,,,,,,
228.082,0.19941,0.95229,10,,,,,,,,,,,,,,,,,,,,,,,,,,,,,,,,,,,,,
228.582,0.19941,0.91292,10,,,,,,,,,,,,,,,,,,,,,,,,,,,,,,,,,,,,,
229.082,0.19941,0.9383,10,,,,,,,,,,,,,,,,,,,,,,,,,,,,,,,,,,,,,
229.582,0.19941,0.94673,10,,,,,,,,,,,,,,,,,,,,,,,,,,,,,,,,,,,,,
230.082,0.19941,0.93889,10,,,,,,,,,,,,,,,,,,,,,,,,,,,,,,,,,,,,,
230.582,0.1993,0.94261,10,,,,,,,,,,,,,,,,,,,,,,,,,,,,,,,,,,,,,
231.082,0.1993,0.9641,10,,,,,,,,,,,,,,,,,,,,,,,,,,,,,,,,,,,,,
231.582,0.1993,0.91937,10,,,,,,,,,,,,,,,,,,,,,,,,,,,,,,,,,,,,,
232.082,0.19941,0.92287,10,,,,,,,,,,,,,,,,,,,,,,,,,,,,,,,,,,,,,
232.582,0.19941,0.92106,10,,,,,,,,,,,,,,,,,,,,,,,,,,,,,,,,,,,,,
233.082,0.19941,0.96728,10,,,,,,,,,,,,,,,,,,,,,,,,,,,,,,,,,,,,,
233.582,0.1993,0.92729,10,,,,,,,,,,,,,,,,,,,,,,,,,,,,,,,,,,,,,
234.082,0.1993,0.93342,10,,,,,,,,,,,,,,,,,,,,,,,,,,,,,,,,,,,,,
234.582,0.19941,0.94037,10,,,,,,,,,,,,,,,,,,,,,,,,,,,,,,,,,,,,,
235.082,0.1993,0.95429,10,,,,,,,,,,,,,,,,,,,,,,,,,,,,,,,,,,,,,
235.582,0.19935,0.92129,10,,,,,,,,,,,,,,,,,,,,,,,,,,,,,,,,,,,,,
236.082,0.19935,0.97025,10,,,,,,,,,,,,,,,,,,,,,,,,,,,,,,,,,,,,,
236.582,0.19935,0.99808,10,,,,,,,,,,,,,,,,,,,,,,,,,,,,,,,,,,,,,
237.082,0.19935,0.97281,10,,,,,,,,,,,,,,,,,,,,,,,,,,,,,,,,,,,,,
237.582,0.19935,0.98717,10,,,,,,,,,,,,,,,,,,,,,,,,,,,,,,,,,,,,,
238.082,0.19935,0.9487,10,,,,,,,,,,,,,,,,,,,,,,,,,,,,,,,,,,,,,
238.582,0.19935,0.92699,10,,,,,,,,,,,,,,,,,,,,,,,,,,,,,,,,,,,,,
239.082,0.19935,0.99915,10,,,,,,,,,,,,,,,,,,,,,,,,,,,,,,,,,,,,,
239.582,0.19924,1.017,10,,,,,,,,,,,,,,,,,,,,,,,,,,,,,,,,,,,,,
240.082,0.19935,0.95336,10,,,,,,,,,,,,,,,,,,,,,,,,,,,,,,,,,,,,,
240.582,0.19935,0.95951,10,,,,,,,,,,,,,,,,,,,,,,,,,,,,,,,,,,,,,
241.082,0.19924,0.9285,10,,,,,,,,,,,,,,,,,,,,,,,,,,,,,,,,,,,,,
241.582,0.19924,0.9592,10,,,,,,,,,,,,,,,,,,,,,,,,,,,,,,,,,,,,,
242.082,0.19924,0.94301,10,,,,,,,,,,,,,,,,,,,,,,,,,,,,,,,,,,,,,
242.582,0.19924,0.94794,10,,,,,,,,,,,,,,,,,,,,,,,,,,,,,,,,,,,,,
243.082,0.1993,0.95238,10,,,,,,,,,,,,,,,,,,,,,,,,,,,,,,,,,,,,,
243.582,0.1993,0.93015,10,,,,,,,,,,,,,,,,,,,,,,,,,,,,,,,,,,,,,
244.082,0.1993,0.96963,10,,,,,,,,,,,,,,,,,,,,,,,,,,,,,,,,,,,,,
244.582,0.1993,0.91939,10,,,,,,,,,,,,,,,,,,,,,,,,,,,,,,,,,,,,,
245.082,0.1993,0.96513,10,,,,,,,,,,,,,,,,,,,,,,,,,,,,,,,,,,,,,
245.582,0.1993,0.95589,10,,,,,,,,,,,,,,,,,,,,,,,,,,,,,,,,,,,,,
246.082,0.1993,0.9783,10,,,,,,,,,,,,,,,,,,,,,,,,,,,,,,,,,,,,,
246.582,0.1993,0.95907,10,,,,,,,,,,,,,,,,,,,,,,,,,,,,,,,,,,,,,
247.082,0.1993,0.97949,10,,,,,,,,,,,,,,,,,,,,,,,,,,,,,,,,,,,,,
247.582,0.1993,0.92655,10,,,,,,,,,,,,,,,,,,,,,,,,,,,,,,,,,,,,,
248.082,0.19918,0.96469,10,,,,,,,,,,,,,,,,,,,,,,,,,,,,,,,,,,,,,
248.582,0.1993,0.95695,10,,,,,,,,,,,,,,,,,,,,,,,,,,,,,,,,,,,,,
249.082,0.1993,0.92701,10,,,,,,,,,,,,,,,,,,,,,,,,,,,,,,,,,,,,,
249.582,0.1993,0.93603,10,,,,,,,,,,,,,,,,,,,,,,,,,,,,,,,,,,,,,
250.082,0.1993,0.95036,10,,,,,,,,,,,,,,,,,,,,,,,,,,,,,,,,,,,,,
250.582,0.19924,0.93879,10,,,,,,,,,,,,,,,,,,,,,,,,,,,,,,,,,,,,,
251.082,0.1993,0.93238,10,,,,,,,,,,,,,,,,,,,,,,,,,,,,,,,,,,,,,
251.582,0.19924,1.00327,10,,,,,,,,,,,,,,,,,,,,,,,,,,,,,,,,,,,,,
252.082,0.19924,0.99321,10,,,,,,,,,,,,,,,,,,,,,,,,,,,,,,,,,,,,,
252.582,0.19924,0.92318,10,,,,,,,,,,,,,,,,,,,,,,,,,,,,,,,,,,,,,
253.082,0.19924,0.94792,10,,,,,,,,,,,,,,,,,,,,,,,,,,,,,,,,,,,,,
253.582,0.19935,0.96103,10,,,,,,,,,,,,,,,,,,,,,,,,,,,,,,,,,,,,,
254.082,0.19935,0.94101,10,,,,,,,,,,,,,,,,,,,,,,,,,,,,,,,,,,,,,
254.582,0.19935,0.94999,10,,,,,,,,,,,,,,,,,,,,,,,,,,,,,,,,,,,,,
255.082,0.19935,0.97232,10,,,,,,,,,,,,,,,,,,,,,,,,,,,,,,,,,,,,,
255.582,0.19935,0.95331,10,,,,,,,,,,,,,,,,,,,,,,,,,,,,,,,,,,,,,
256.082,0.19935,0.95809,10,,,,,,,,,,,,,,,,,,,,,,,,,,,,,,,,,,,,,
256.582,0.19935,0.94545,10,,,,,,,,,,,,,,,,,,,,,,,,,,,,,,,,,,,,,
257.082,0.1993,0.94895,10,,,,,,,,,,,,,,,,,,,,,,,,,,,,,,,,,,,,,
257.582,0.19935,0.97455,10,,,,,,,,,,,,,,,,,,,,,,,,,,,,,,,,,,,,,
258.082,0.19935,0.92936,10,,,,,,,,,,,,,,,,,,,,,,,,,,,,,,,,,,,,,
258.582,0.19935,0.95556,10,,,,,,,,,,,,,,,,,,,,,,,,,,,,,,,,,,,,,
259.082,0.19935,0.97436,10,,,,,,,,,,,,,,,,,,,,,,,,,,,,,,,,,,,,,
259.582,0.1993,0.92409,10,,,,,,,,,,,,,,,,,,,,,,,,,,,,,,,,,,,,,
260.082,0.19941,0.98727,10,,,,,,,,,,,,,,,,,,,,,,,,,,,,,,,,,,,,,
260.582,0.1993,0.96788,10,,,,,,,,,,,,,,,,,,,,,,,,,,,,,,,,,,,,,
261.082,0.1993,0.95683,10,,,,,,,,,,,,,,,,,,,,,,,,,,,,,,,,,,,,,
261.582,0.1993,0.91772,10,,,,,,,,,,,,,,,,,,,,,,,,,,,,,,,,,,,,,
262.082,0.19935,0.95604,10,,,,,,,,,,,,,,,,,,,,,,,,,,,,,,,,,,,,,
262.582,0.19935,0.93057,10,,,,,,,,,,,,,,,,,,,,,,,,,,,,,,,,,,,,,
263.082,0.19935,0.92906,10,,,,,,,,,,,,,,,,,,,,,,,,,,,,,,,,,,,,,
263.582,0.1993,0.90302,10,,,,,,,,,,,,,,,,,,,,,,,,,,,,,,,,,,,,,
264.082,0.1993,0.92857,10,,,,,,,,,,,,,,,,,,,,,,,,,,,,,,,,,,,,,
264.582,0.19941,0.93638,10,,,,,,,,,,,,,,,,,,,,,,,,,,,,,,,,,,,,,
265.082,0.19935,0.91152,10,,,,,,,,,,,,,,,,,,,,,,,,,,,,,,,,,,,,,
265.582,0.19947,0.95199,10,,,,,,,,,,,,,,,,,,,,,,,,,,,,,,,,,,,,,
266.082,0.19947,1.06688,10,,,,,,,,,,,,,,,,,,,,,,,,,,,,,,,,,,,,,
266.582,0.19941,1.02366,10,,,,,,,,,,,,,,,,,,,,,,,,,,,,,,,,,,,,,
267.082,0.19941,1.00299,10,,,,,,,,,,,,,,,,,,,,,,,,,,,,,,,,,,,,,
267.582,0.19941,0.94063,10,,,,,,,,,,,,,,,,,,,,,,,,,,,,,,,,,,,,,
268.082,0.19947,0.94867,10,,,,,,,,,,,,,,,,,,,,,,,,,,,,,,,,,,,,,
268.582,0.19947,0.90719,10,,,,,,,,,,,,,,,,,,,,,,,,,,,,,,,,,,,,,
269.082,0.19947,0.96664,10,,,,,,,,,,,,,,,,,,,,,,,,,,,,,,,,,,,,,
269.582,0.19941,0.95396,10,,,,,,,,,,,,,,,,,,,,,,,,,,,,,,,,,,,,,
270.082,0.19941,0.93498,10,,,,,,,,,,,,,,,,,,,,,,,,,,,,,,,,,,,,,
270.582,0.19941,0.94997,10,,,,,,,,,,,,,,,,,,,,,,,,,,,,,,,,,,,,,
271.082,0.19952,0.9701,10,,,,,,,,,,,,,,,,,,,,,,,,,,,,,,,,,,,,,
271.582,0.19952,0.94413,10,,,,,,,,,,,,,,,,,,,,,,,,,,,,,,,,,,,,,
272.082,0.19952,0.98683,10,,,,,,,,,,,,,,,,,,,,,,,,,,,,,,,,,,,,,
272.582,0.19952,0.99323,10,,,,,,,,,,,,,,,,,,,,,,,,,,,,,,,,,,,,,
273.082,0.19952,0.97675,10,,,,,,,,,,,,,,,,,,,,,,,,,,,,,,,,,,,,,
273.582,0.19952,0.96257,10,,,,,,,,,,,,,,,,,,,,,,,,,,,,,,,,,,,,,
274.082,0.19952,0.974,10,,,,,,,,,,,,,,,,,,,,,,,,,,,,,,,,,,,,,
274.582,0.19941,0.95607,10,,,,,,,,,,,,,,,,,,,,,,,,,,,,,,,,,,,,,
275.082,0.19952,0.94388,10,,,,,,,,,,,,,,,,,,,,,,,,,,,,,,,,,,,,,
275.582,0.19952,0.93837,10,,,,,,,,,,,,,,,,,,,,,,,,,,,,,,,,,,,,,
276.082,0.19952,0.96764,10,,,,,,,,,,,,,,,,,,,,,,,,,,,,,,,,,,,,,
276.582,0.19952,1.00763,10,,,,,,,,,,,,,,,,,,,,,,,,,,,,,,,,,,,,,
277.082,0.19952,0.93279,10,,,,,,,,,,,,,,,,,,,,,,,,,,,,,,,,,,,,,
277.582,0.19941,1.00218,10,,,,,,,,,,,,,,,,,,,,,,,,,,,,,,,,,,,,,
278.082,0.19952,0.98917,10,,,,,,,,,,,,,,,,,,,,,,,,,,,,,,,,,,,,,
278.582,0.19941,0.9975,10,,,,,,,,,,,,,,,,,,,,,,,,,,,,,,,,,,,,,
279.082,0.19952,0.92871,10,,,,,,,,,,,,,,,,,,,,,,,,,,,,,,,,,,,,,
279.582,0.19941,1.02085,10,,,,,,,,,,,,,,,,,,,,,,,,,,,,,,,,,,,,,
280.082,0.19952,1.00776,10,,,,,,,,,,,,,,,,,,,,,,,,,,,,,,,,,,,,,
280.582,0.19941,0.99422,10,,,,,,,,,,,,,,,,,,,,,,,,,,,,,,,,,,,,,
281.082,0.19941,0.94152,10,,,,,,,,,,,,,,,,,,,,,,,,,,,,,,,,,,,,,
281.582,0.19941,0.97665,10,,,,,,,,,,,,,,,,,,,,,,,,,,,,,,,,,,,,,
282.082,0.19941,0.93947,10,,,,,,,,,,,,,,,,,,,,,,,,,,,,,,,,,,,,,
282.582,0.19941,0.95796,10,,,,,,,,,,,,,,,,,,,,,,,,,,,,,,,,,,,,,
283.082,0.19941,0.98166,10,,,,,,,,,,,,,,,,,,,,,,,,,,,,,,,,,,,,,
283.582,0.19947,1.04015,10,,,,,,,,,,,,,,,,,,,,,,,,,,,,,,,,,,,,,
284.082,0.19947,0.97536,10,,,,,,,,,,,,,,,,,,,,,,,,,,,,,,,,,,,,,
284.582,0.19947,0.99756,10,,,,,,,,,,,,,,,,,,,,,,,,,,,,,,,,,,,,,
285.082,0.19947,0.95646,10,,,,,,,,,,,,,,,,,,,,,,,,,,,,,,,,,,,,,
285.582,0.19947,1.06327,10,,,,,,,,,,,,,,,,,,,,,,,,,,,,,,,,,,,,,
286.082,0.19947,0.95982,10,,,,,,,,,,,,,,,,,,,,,,,,,,,,,,,,,,,,,
286.582,0.19947,0.99357,10,,,,,,,,,,,,,,,,,,,,,,,,,,,,,,,,,,,,,
287.082,0.19947,0.96379,10,,,,,,,,,,,,,,,,,,,,,,,,,,,,,,,,,,,,,
287.582,0.19947,1.00658,10,,,,,,,,,,,,,,,,,,,,,,,,,,,,,,,,,,,,,
288.082,0.19935,0.98777,10,,,,,,,,,,,,,,,,,,,,,,,,,,,,,,,,,,,,,
288.582,0.19947,1.0276,10,,,,,,,,,,,,,,,,,,,,,,,,,,,,,,,,,,,,,
289.082,0.19947,0.9406,10,,,,,,,,,,,,,,,,,,,,,,,,,,,,,,,,,,,,,
289.582,0.19947,0.96244,10,,,,,,,,,,,,,,,,,,,,,,,,,,,,,,,,,,,,,
290.082,0.19941,0.98208,10,,,,,,,,,,,,,,,,,,,,,,,,,,,,,,,,,,,,,
290.582,0.19941,1.0924,10,,,,,,,,,,,,,,,,,,,,,,,,,,,,,,,,,,,,,
291.082,0.19935,0.90964,10,,,,,,,,,,,,,,,,,,,,,,,,,,,,,,,,,,,,,
291.582,0.19935,1.01383,10,,,,,,,,,,,,,,,,,,,,,,,,,,,,,,,,,,,,,
292.082,0.19947,0.94898,10,,,,,,,,,,,,,,,,,,,,,,,,,,,,,,,,,,,,,
292.582,0.19947,1.03179,10,,,,,,,,,,,,,,,,,,,,,,,,,,,,,,,,,,,,,
293.082,0.19947,0.96853,10,,,,,,,,,,,,,,,,,,,,,,,,,,,,,,,,,,,,,
293.582,0.19935,1.08215,10,,,,,,,,,,,,,,,,,,,,,,,,,,,,,,,,,,,,,
294.082,0.19947,1.01124,10,,,,,,,,,,,,,,,,,,,,,,,,,,,,,,,,,,,,,
294.582,0.19947,1.04599,10,,,,,,,,,,,,,,,,,,,,,,,,,,,,,,,,,,,,,
295.082,0.19947,0.94344,10,,,,,,,,,,,,,,,,,,,,,,,,,,,,,,,,,,,,,
295.582,0.19947,1.03595,10,,,,,,,,,,,,,,,,,,,,,,,,,,,,,,,,,,,,,
296.082,0.19947,0.95102,10,,,,,,,,,,,,,,,,,,,,,,,,,,,,,,,,,,,,,
296.582,0.19935,1.03981,10,,,,,,,,,,,,,,,,,,,,,,,,,,,,,,,,,,,,,
297.082,0.19947,0.93145,10,,,,,,,,,,,,,,,,,,,,,,,,,,,,,,,,,,,,,
297.582,0.19935,1.02537,10,,,,,,,,,,,,,,,,,,,,,,,,,,,,,,,,,,,,,
298.082,0.19947,0.93312,10,,,,,,,,,,,,,,,,,,,,,,,,,,,,,,,,,,,,,
298.582,0.19947,0.95907,10,,,,,,,,,,,,,,,,,,,,,,,,,,,,,,,,,,,,,
299.082,0.19947,0.96525,10,,,,,,,,,,,,,,,,,,,,,,,,,,,,,,,,,,,,,
299.582,0.19947,0.93217,10,,,,,,,,,,,,,,,,,,,,,,,,,,,,,,,,,,,,,
300.082,0.19947,0.9756,10,,,,,,,,,,,,,,,,,,,,,,,,,,,,,,,,,,,,,
300.582,0.19947,0.95493,10,,,,,,,,,,,,,,,,,,,,,,,,,,,,,,,,,,,,,
301.082,0.19947,0.96504,10,,,,,,,,,,,,,,,,,,,,,,,,,,,,,,,,,,,,,
301.582,0.19947,0.94267,10,,,,,,,,,,,,,,,,,,,,,,,,,,,,,,,,,,,,,
302.082,0.19941,0.97712,10,,,,,,,,,,,,,,,,,,,,,,,,,,,,,,,,,,,,,
302.582,0.19941,0.97291,10,,,,,,,,,,,,,,,,,,,,,,,,,,,,,,,,,,,,,
303.082,0.19941,0.94978,10,,,,,,,,,,,,,,,,,,,,,,,,,,,,,,,,,,,,,
303.582,0.19941,0.93653,10,,,,,,,,,,,,,,,,,,,,,,,,,,,,,,,,,,,,,
304.082,0.19952,0.97073,10,,,,,,,,,,,,,,,,,,,,,,,,,,,,,,,,,,,,,
304.582,0.19952,0.973,10,,,,,,,,,,,,,,,,,,,,,,,,,,,,,,,,,,,,,
305.082,0.19941,0.93077,10,,,,,,,,,,,,,,,,,,,,,,,,,,,,,,,,,,,,,
305.582,0.19941,0.89913,10,,,,,,,,,,,,,,,,,,,,,,,,,,,,,,,,,,,,,
306.082,0.19941,0.97787,10,,,,,,,,,,,,,,,,,,,,,,,,,,,,,,,,,,,,,
306.582,0.19941,0.91276,10,,,,,,,,,,,,,,,,,,,,,,,,,,,,,,,,,,,,,
307.082,0.19941,1.01064,10,,,,,,,,,,,,,,,,,,,,,,,,,,,,,,,,,,,,,
307.582,0.19941,0.93048,10,,,,,,,,,,,,,,,,,,,,,,,,,,,,,,,,,,,,,
308.082,0.19941,0.9701,10,,,,,,,,,,,,,,,,,,,,,,,,,,,,,,,,,,,,,
308.582,0.19941,0.92846,10,,,,,,,,,,,,,,,,,,,,,,,,,,,,,,,,,,,,,
309.082,0.19941,0.95076,10,,,,,,,,,,,,,,,,,,,,,,,,,,,,,,,,,,,,,
309.582,0.19952,0.93748,10,,,,,,,,,,,,,,,,,,,,,,,,,,,,,,,,,,,,,
310.082,0.19952,0.94605,10,,,,,,,,,,,,,,,,,,,,,,,,,,,,,,,,,,,,,
310.582,0.19952,0.90492,10,,,,,,,,,,,,,,,,,,,,,,,,,,,,,,,,,,,,,
311.082,0.19952,0.92224,10,,,,,,,,,,,,,,,,,,,,,,,,,,,,,,,,,,,,,
311.582,0.19952,0.94679,10,,,,,,,,,,,,,,,,,,,,,,,,,,,,,,,,,,,,,
312.082,0.19952,0.93238,10,,,,,,,,,,,,,,,,,,,,,,,,,,,,,,,,,,,,,
312.582,0.19952,1.00514,10,,,,,,,,,,,,,,,,,,,,,,,,,,,,,,,,,,,,,
313.082,0.19952,0.93057,10,,,,,,,,,,,,,,,,,,,,,,,,,,,,,,,,,,,,,
313.582,0.19952,0.92164,10,,,,,,,,,,,,,,,,,,,,,,,,,,,,,,,,,,,,,
314.082,0.19952,0.95264,10,,,,,,,,,,,,,,,,,,,,,,,,,,,,,,,,,,,,,
314.582,0.19952,0.9021,10,,,,,,,,,,,,,,,,,,,,,,,,,,,,,,,,,,,,,
315.082,0.19952,0.94198,10,,,,,,,,,,,,,,,,,,,,,,,,,,,,,,,,,,,,,
315.582,0.19941,0.96144,10,,,,,,,,,,,,,,,,,,,,,,,,,,,,,,,,,,,,,
316.082,0.19952,0.95361,10,,,,,,,,,,,,,,,,,,,,,,,,,,,,,,,,,,,,,
316.582,0.19952,0.96438,10,,,,,,,,,,,,,,,,,,,,,,,,,,,,,,,,,,,,,
317.082,0.19952,1.00059,10,,,,,,,,,,,,,,,,,,,,,,,,,,,,,,,,,,,,,
317.582,0.19952,0.90119,10,,,,,,,,,,,,,,,,,,,,,,,,,,,,,,,,,,,,,
318.082,0.19952,0.96189,10,,,,,,,,,,,,,,,,,,,,,,,,,,,,,,,,,,,,,
318.582,0.19947,0.97686,10,,,,,,,,,,,,,,,,,,,,,,,,,,,,,,,,,,,,,
319.082,0.19952,0.94041,10,,,,,,,,,,,,,,,,,,,,,,,,,,,,,,,,,,,,,
319.582,0.19952,0.9203,10,,,,,,,,,,,,,,,,,,,,,,,,,,,,,,,,,,,,,
320.082,0.19952,0.96221,10,,,,,,,,,,,,,,,,,,,,,,,,,,,,,,,,,,,,,
320.582,0.19952,0.9462,10,,,,,,,,,,,,,,,,,,,,,,,,,,,,,,,,,,,,,
321.082,0.19952,0.99776,10,,,,,,,,,,,,,,,,,,,,,,,,,,,,,,,,,,,,,
321.582,0.19952,0.99484,10,,,,,,,,,,,,,,,,,,,,,,,,,,,,,,,,,,,,,
322.082,0.19952,0.96401,10,,,,,,,,,,,,,,,,,,,,,,,,,,,,,,,,,,,,,
322.582,0.19952,0.94438,10,,,,,,,,,,,,,,,,,,,,,,,,,,,,,,,,,,,,,
323.082,0.19947,0.93007,10,,,,,,,,,,,,,,,,,,,,,,,,,,,,,,,,,,,,,
323.582,0.19958,0.90317,10,,,,,,,,,,,,,,,,,,,,,,,,,,,,,,,,,,,,,
324.082,0.19958,0.92309,10,,,,,,,,,,,,,,,,,,,,,,,,,,,,,,,,,,,,,
324.582,0.19964,0.90927,10,,,,,,,,,,,,,,,,,,,,,,,,,,,,,,,,,,,,,
325.082,0.19975,0.94792,10,,,,,,,,,,,,,,,,,,,,,,,,,,,,,,,,,,,,,
325.582,0.19975,0.92667,10,,,,,,,,,,,,,,,,,,,,,,,,,,,,,,,,,,,,,
326.082,0.19981,0.90755,10,,,,,,,,,,,,,,,,,,,,,,,,,,,,,,,,,,,,,
326.582,0.19992,0.94007,10,,,,,,,,,,,,,,,,,,,,,,,,,,,,,,,,,,,,,
327.082,0.19998,0.91855,10,,,,,,,,,,,,,,,,,,,,,,,,,,,,,,,,,,,,,
327.582,0.19998,0.93575,10,,,,,,,,,,,,,,,,,,,,,,,,,,,,,,,,,,,,,
328.082,0.20003,0.9682,10,,,,,,,,,,,,,,,,,,,,,,,,,,,,,,,,,,,,,
328.582,0.19992,0.9408,10,,,,,,,,,,,,,,,,,,,,,,,,,,,,,,,,,,,,,
329.082,0.19992,0.98169,10,,,,,,,,,,,,,,,,,,,,,,,,,,,,,,,,,,,,,
329.582,0.19998,0.9475,10,,,,,,,,,,,,,,,,,,,,,,,,,,,,,,,,,,,,,
330.082,0.19986,0.9177,10,,,,,,,,,,,,,,,,,,,,,,,,,,,,,,,,,,,,,
330.582,0.19998,0.90748,10,,,,,,,,,,,,,,,,,,,,,,,,,,,,,,,,,,,,,
331.082,0.19998,0.95478,10,,,,,,,,,,,,,,,,,,,,,,,,,,,,,,,,,,,,,
331.582,0.19998,0.92197,10,,,,,,,,,,,,,,,,,,,,,,,,,,,,,,,,,,,,,
332.082,0.19998,0.98629,10,,,,,,,,,,,,,,,,,,,,,,,,,,,,,,,,,,,,,
332.582,0.19998,0.96125,10,,,,,,,,,,,,,,,,,,,,,,,,,,,,,,,,,,,,,
333.082,0.19986,0.98515,10,,,,,,,,,,,,,,,,,,,,,,,,,,,,,,,,,,,,,
333.582,0.19986,1.00609,10,,,,,,,,,,,,,,,,,,,,,,,,,,,,,,,,,,,,,
334.082,0.19992,0.92965,10,,,,,,,,,,,,,,,,,,,,,,,,,,,,,,,,,,,,,
334.582,0.19992,0.92452,10,,,,,,,,,,,,,,,,,,,,,,,,,,,,,,,,,,,,,
335.082,0.19998,0.96756,10,,,,,,,,,,,,,,,,,,,,,,,,,,,,,,,,,,,,,
335.582,0.19986,0.93105,10,,,,,,,,,,,,,,,,,,,,,,,,,,,,,,,,,,,,,
336.082,0.19998,0.98353,10,,,,,,,,,,,,,,,,,,,,,,,,,,,,,,,,,,,,,
336.582,0.19998,0.93456,10,,,,,,,,,,,,,,,,,,,,,,,,,,,,,,,,,,,,,
337.082,0.19986,0.95726,10,,,,,,,,,,,,,,,,,,,,,,,,,,,,,,,,,,,,,
337.582,0.19986,0.93417,10,,,,,,,,,,,,,,,,,,,,,,,,,,,,,,,,,,,,,
338.082,0.19986,0.91903,10,,,,,,,,,,,,,,,,,,,,,,,,,,,,,,,,,,,,,
338.582,0.19986,0.96061,10,,,,,,,,,,,,,,,,,,,,,,,,,,,,,,,,,,,,,
339.082,0.19986,0.9748,10,,,,,,,,,,,,,,,,,,,,,,,,,,,,,,,,,,,,,
339.582,0.19986,0.9626,10,,,,,,,,,,,,,,,,,,,,,,,,,,,,,,,,,,,,,
340.082,0.19986,0.95232,10,,,,,,,,,,,,,,,,,,,,,,,,,,,,,,,,,,,,,
340.582,0.19986,0.91828,10,,,,,,,,,,,,,,,,,,,,,,,,,,,,,,,,,,,,,
341.082,0.19998,0.95411,10,,,,,,,,,,,,,,,,,,,,,,,,,,,,,,,,,,,,,
341.582,0.19986,0.94481,10,,,,,,,,,,,,,,,,,,,,,,,,,,,,,,,,,,,,,
342.082,0.19998,0.92653,10,,,,,,,,,,,,,,,,,,,,,,,,,,,,,,,,,,,,,
342.582,0.19998,0.99074,10,,,,,,,,,,,,,,,,,,,,,,,,,,,,,,,,,,,,,
343.082,0.19998,0.93607,10,,,,,,,,,,,,,,,,,,,,,,,,,,,,,,,,,,,,,
343.582,0.19998,0.95319,10,,,,,,,,,,,,,,,,,,,,,,,,,,,,,,,,,,,,,
344.082,0.19998,0.94038,10,,,,,,,,,,,,,,,,,,,,,,,,,,,,,,,,,,,,,
344.582,0.19998,0.96514,10,,,,,,,,,,,,,,,,,,,,,,,,,,,,,,,,,,,,,
345.082,0.19986,0.92171,10,,,,,,,,,,,,,,,,,,,,,,,,,,,,,,,,,,,,,
345.582,0.19986,0.94203,10,,,,,,,,,,,,,,,,,,,,,,,,,,,,,,,,,,,,,
346.082,0.19986,0.93051,10,,,,,,,,,,,,,,,,,,,,,,,,,,,,,,,,,,,,,
346.582,0.19986,0.92404,10,,,,,,,,,,,,,,,,,,,,,,,,,,,,,,,,,,,,,
347.082,0.19986,0.9365,10,,,,,,,,,,,,,,,,,,,,,,,,,,,,,,,,,,,,,
347.582,0.19986,0.9497,10,,,,,,,,,,,,,,,,,,,,,,,,,,,,,,,,,,,,,
348.082,0.19986,0.95217,10,,,,,,,,,,,,,,,,,,,,,,,,,,,,,,,,,,,,,
348.582,0.19986,0.96072,10,,,,,,,,,,,,,,,,,,,,,,,,,,,,,,,,,,,,,
349.082,0.19986,0.94432,10,,,,,,,,,,,,,,,,,,,,,,,,,,,,,,,,,,,,,
349.582,0.19986,0.95393,10,,,,,,,,,,,,,,,,,,,,,,,,,,,,,,,,,,,,,
350.082,0.19986,0.9966,10,,,,,,,,,,,,,,,,,,,,,,,,,,,,,,,,,,,,,
350.582,0.19986,0.97173,10,,,,,,,,,,,,,,,,,,,,,,,,,,,,,,,,,,,,,
351.082,0.19986,0.96312,10,,,,,,,,,,,,,,,,,,,,,,,,,,,,,,,,,,,,,
351.582,0.19986,0.93,10,,,,,,,,,,,,,,,,,,,,,,,,,,,,,,,,,,,,,
352.082,0.19986,0.96619,10,,,,,,,,,,,,,,,,,,,,,,,,,,,,,,,,,,,,,
352.582,0.19986,0.97524,10,,,,,,,,,,,,,,,,,,,,,,,,,,,,,,,,,,,,,
353.082,0.19998,0.95337,10,,,,,,,,,,,,,,,,,,,,,,,,,,,,,,,,,,,,,
353.582,0.19998,0.9206,10,,,,,,,,,,,,,,,,,,,,,,,,,,,,,,,,,,,,,
354.082,0.19986,0.94512,10,,,,,,,,,,,,,,,,,,,,,,,,,,,,,,,,,,,,,
354.582,0.19986,0.94681,10,,,,,,,,,,,,,,,,,,,,,,,,,,,,,,,,,,,,,
355.082,0.19998,0.9504,10,,,,,,,,,,,,,,,,,,,,,,,,,,,,,,,,,,,,,
355.582,0.19998,0.99092,10,,,,,,,,,,,,,,,,,,,,,,,,,,,,,,,,,,,,,
356.082,0.19986,0.93823,10,,,,,,,,,,,,,,,,,,,,,,,,,,,,,,,,,,,,,
356.582,0.19998,0.9867,10,,,,,,,,,,,,,,,,,,,,,,,,,,,,,,,,,,,,,
357.082,0.19986,0.89846,10,,,,,,,,,,,,,,,,,,,,,,,,,,,,,,,,,,,,,
357.582,0.19986,0.92453,10,,,,,,,,,,,,,,,,,,,,,,,,,,,,,,,,,,,,,
358.082,0.19992,0.95022,10,,,,,,,,,,,,,,,,,,,,,,,,,,,,,,,,,,,,,
358.582,0.19998,0.91387,10,,,,,,,,,,,,,,,,,,,,,,,,,,,,,,,,,,,,,
359.082,0.19992,0.9373,10,,,,,,,,,,,,,,,,,,,,,,,,,,,,,,,,,,,,,
359.582,0.19992,0.95889,10,,,,,,,,,,,,,,,,,,,,,,,,,,,,,,,,,,,,,
360.082,0.19992,0.97367,10,,,,,,,,,,,,,,,,,,,,,,,,,,,,,,,,,,,,,
360.582,0.19992,0.97842,10,,,,,,,,,,,,,,,,,,,,,,,,,,,,,,,,,,,,,
361.082,0.19992,0.9174,10,,,,,,,,,,,,,,,,,,,,,,,,,,,,,,,,,,,,,
361.582,0.19998,0.94102,10,,,,,,,,,,,,,,,,,,,,,,,,,,,,,,,,,,,,,
362.082,0.19986,0.98995,10,,,,,,,,,,,,,,,,,,,,,,,,,,,,,,,,,,,,,
362.582,0.19998,0.90744,10,,,,,,,,,,,,,,,,,,,,,,,,,,,,,,,,,,,,,
363.082,0.19998,0.90764,10,,,,,,,,,,,,,,,,,,,,,,,,,,,,,,,,,,,,,
363.582,0.19998,0.967,10,,,,,,,,,,,,,,,,,,,,,,,,,,,,,,,,,,,,,
364.082,0.19986,0.94801,10,,,,,,,,,,,,,,,,,,,,,,,,,,,,,,,,,,,,,
364.582,0.19998,0.97093,10,,,,,,,,,,,,,,,,,,,,,,,,,,,,,,,,,,,,,
365.082,0.19998,0.93568,10,,,,,,,,,,,,,,,,,,,,,,,,,,,,,,,,,,,,,
365.582,0.19998,0.96266,10,,,,,,,,,,,,,,,,,,,,,,,,,,,,,,,,,,,,,
366.082,0.19992,0.91269,10,,,,,,,,,,,,,,,,,,,,,,,,,,,,,,,,,,,,,
366.582,0.19992,0.92658,10,,,,,,,,,,,,,,,,,,,,,,,,,,,,,,,,,,,,,
367.082,0.19992,0.90525,10,,,,,,,,,,,,,,,,,,,,,,,,,,,,,,,,,,,,,
367.582,0.19992,0.96432,10,,,,,,,,,,,,,,,,,,,,,,,,,,,,,,,,,,,,,
368.082,0.19998,0.94772,10,,,,,,,,,,,,,,,,,,,,,,,,,,,,,,,,,,,,,
368.582,0.19998,0.94347,10,,,,,,,,,,,,,,,,,,,,,,,,,,,,,,,,,,,,,
369.082,0.19998,0.93529,10,,,,,,,,,,,,,,,,,,,,,,,,,,,,,,,,,,,,,
369.582,0.19992,0.93319,10,,,,,,,,,,,,,,,,,,,,,,,,,,,,,,,,,,,,,
370.082,0.19992,0.93738,10,,,,,,,,,,,,,,,,,,,,,,,,,,,,,,,,,,,,,
370.582,0.20003,0.95662,10,,,,,,,,,,,,,,,,,,,,,,,,,,,,,,,,,,,,,
371.082,0.20003,0.95402,10,,,,,,,,,,,,,,,,,,,,,,,,,,,,,,,,,,,,,
371.582,0.20003,0.90357,10,,,,,,,,,,,,,,,,,,,,,,,,,,,,,,,,,,,,,
372.082,0.20003,0.87608,10,,,,,,,,,,,,,,,,,,,,,,,,,,,,,,,,,,,,,
372.582,0.20009,0.86835,10,,,,,,,,,,,,,,,,,,,,,,,,,,,,,,,,,,,,,
373.082,0.20009,0.86772,10,,,,,,,,,,,,,,,,,,,,,,,,,,,,,,,,,,,,,
373.582,0.2002,0.95775,10,,,,,,,,,,,,,,,,,,,,,,,,,,,,,,,,,,,,,
373.984,1.5066,105.99874,10,,,,,,,,,,,,,,,,,,,,,,,,,,,,,,,,,,,,,
374.484,5.68367,522.05457,10,,,,,,,,,,,,,,,,,,,,,,,,,,,,,,,,,,,,,
374.984,9.85031,17.84782,10,,,,,,,,,,,,,,,,,,,,,,,,,,,,,,,,,,,,,
375.484,14.0169,1.50337,10,,,,,,,,,,,,,,,,,,,,,,,,,,,,,,,,,,,,,
375.984,18.18365,-3.79012,10,,,,,,,,,,,,,,,,,,,,,,,,,,,,,,,,,,,,,
376.484,22.35024,-6.83325,10,,,,,,,,,,,,,,,,,,,,,,,,,,,,,,,,,,,,,
376.984,26.51694,-7.17487,10,,,,,,,,,,,,,,,,,,,,,,,,,,,,,,,,,,,,,
377.484,30.6837,-7.1547,10,,,,,,,,,,,,,,,,,,,,,,,,,,,,,,,,,,,,,
377.984,34.85022,-7.20856,10,,,,,,,,,,,,,,,,,,,,,,,,,,,,,,,,,,,,,
378.484,39.01687,-7.1026,10,,,,,,,,,,,,,,,,,,,,,,,,,,,,,,,,,,,,,
378.67,40.56693,-7.18418,10,,,,,,,,,,,,,,,,,,,,,,,,,,,,,,,,,,,,,