File: combined_ligament_solver/data/processed/Data Sheet 3_S160798_PCL.csv
Specimen properties : Length,46,mm,Unnamed: 3,Unnamed: 4,Unnamed: 5,Unnamed: 6,Unnamed: 7,Unnamed: 8,Unnamed: 9,Unnamed: 10,Unnamed: 11,Stress-Strain,Unnamed: 13,Unnamed: 14,Unnamed: 15,Unnamed: 16,Unnamed: 17,Unnamed: 18,Unnamed: 19,Unnamed: 20,Unnamed: 21,Unnamed: 22,Unnamed: 23,Unnamed: 24,Unnamed: 25,Unnamed: 26,Unnamed: 27,Linear,Unnamed: 29,Unnamed: 30,Unnamed: 31,Unnamed: 32,Unnamed: 33,Modulus,Unnamed: 35,Failure,Unnamed: 37,Unnamed: 38,Unnamed: 39,Unnamed: 40
Cross Section Average,98.66749999999999,mm2,,,,,,,,,,Polynomial Coefficients,,,,,,,,,,,,,,,,Force,,Stress,Extension,Strain,,Secant,Tangent,Load,Stress,Extension,Strain,Stiffness
Time,Extension,Load,Total cycle count,,,Extension,Load,Strain,Stress,E-tan,,X6,705213.9665821374,,,,,,,,,Strain,Stress,E-tan,,,,(N),,(MPa),(mm),(%),,(MPa),(MPa),(N),(MPa),(mm),(%),(N/mm)
(s),(mm),(N),,,,(mm),(N),(mm/mm),(MPa),(MPa),,X5,-586879.642398883,,,,,,,,,(mm/mm),(MPa),(MPa),,,,750.5798737118971,,7.607164200085106,5.474,11.899999999999999,,63.92574958054712,103.39838852309659,1121.87878,11.3603880710467,8.199950000000001,17.82597826086957,137.11725862475288
0.5,0.11962,3.50436,0,,,4.3932,450.57156,0.08767934782608697,4.5566561431069,89.0667272570872,,,,,,,,,,,,0.005,0.01794320562887993,7.950474701821394,,,,,,,,,,,,,,,,
1.1,0.21981,6.7526,0,,,9.39318,1240.58801,,,,,,,,,,,,,,,0.011,0.10564366485539117,19.03871574302018,,,,,,,,,,,,,,,,
1.7,0.31971,10.09101,0,,,14.39339,764.36273,,,,,,,,,,,,,,,0.017,0.2520626422220867,27.975334379676667,,,,,,,,,,,,,,,,
2.3,0.41956,13.63568,0,,,19.39326,22.05616,,,,,,,,,,,,,,,0.023,0.4462031571093784,35.29538894177544,,,,,,,,,,,,,,,,
2.9,0.51975,17.43884,0,,,24.3933,4.80641,,,,,,,,,,,,,,,0.029,0.6799952115848679,41.453524050047946,,,,,,,,,,,,,,,,
3.5,0.61976,21.57542,0,,,,,,,,,,,,,,,,,,,0.035,0.947827127182209,46.82791891150979,,,,,,,,,,,,,,,,
4.1,0.71978,25.98981,0,,,,,,,,,,,,,,,,,,,0.041,1.2461005714532083,51.72423561500268,,,,,,,,,,,,,,,,
4.7,0.81957,30.62977,0,,,,,,,,,,,,,,,,,,,0.047,1.5728092742931548,56.37956742672928,,,,,,,,,,,,,,,,
5.3,0.9197,35.6169,0,,,,,,,,,,,,,,,,,,,0.053,1.927141434039389,60.96638708579632,,,,,,,,,,,,,,,,
5.8,1.00306,40.02761,0.5,,,,,,,,,,,,,,,,,,,0.059,2.3091058133431,65.59649509975158,,,,,,,,,,,,,,,,
6.4,0.90281,31.26415,0.5,,,,,,,,,,,,,,,,,,,0.065,2.719181524814362,70.32496804012206,,,,,,,,,,,,,,,,
7,0.80274,24.3352,0.5,,,,,,,,,,,,,,,,,,,0.071,3.1579915064404003,75.15410683795719,,,,,,,,,,,,,,,,
7.6,0.70261,18.88141,0.5,,,,,,,,,,,,,,,,,,,0.077,3.6259996867770914,80.03738507935624,,,,,,,,,,,,,,,,
8.2,0.60276,14.11576,0.5,,,,,,,,,,,,,,,,,,,0.083,4.123231839913704,84.88339730102359,,,,,,,,,,,,,,,,
8.8,0.50275,10.0526,0.5,,,,,,,,,,,,,,,,,,,0.089,4.649020130210862,89.55980728580207,,,,,,,,,,,,,,,,
9.4,0.40273,6.62161,0.5,,,,,,,,,,,,,,,,,,,0.095,5.2017713468117535,93.89729635819934,,,,,,,,,,,,,,,,
10,0.30266,3.73323,0.5,,,,,,,,,,,,,,,,,,,0.101,5.778758827926572,97.69351167995123,,,,,,,,,,,,,,,,
10.6,0.20264,1.21749,0.5,,,,,,,,,,,,,,,,,,,0.107,6.375938074890156,100.71701454552507,,,,,,,,,,,,,,,,
10.956,0.24429,2.57605,1,,,,,,,,,,,,,,,,,,,0.113,6.987786055992957,102.71122867771066,,,,,,,,,,,,,,,,
11.556,0.34431,6.05989,1,,,,,,,,,,,,,,,,,,MAX,0.119,7.607164200085106,103.39838852309659,,,,,,,,,,,,,,,,
12.156,0.44449,9.68617,1,,,,,,,,,,,,,,,,,,,0.125,8.225205079953843,102.48348754766558,,,,,,,,,,,,,,,,
12.756,0.54434,13.6577,1,,,,,,,,,,,,,,,,,,,0.131,8.831222785474102,99.6582265323055,,,,,,,,,,,,,,,,
13.356,0.6443,18.01026,1,,,,,,,,,,,,,,,,,,,0.137,9.412646986532325,94.60496186833458,,,,,,,,,,,,,,,,
13.956,0.74426,22.91345,1,,,,,,,,,,,,,,,,,,,0.143,9.954980685723584,87.00065385305136,,,,,,,,,,,,,,,,
14.556,0.8445,28.19697,1,,,,,,,,,,,,,,,,,,,0.149,,,,,,,,,,,,,,,,,,
15.156,0.94446,33.92823,1,,,,,,,,,,,,,,,,,,,0.155,,,,,,,,,,,,,,,,,,
15.748,1.04295,40.00008,1.5,,,,,,,,,,,,,,,,,,,0.161,,,,,,,,,,,,,,,,,,
16.25,0.95988,32.69691,1.5,,,,,,,,,,,,,,,,,,,0.167,,,,,,,,,,,,,,,,,,
16.85,0.8598,25.46273,1.5,,,,,,,,,,,,,,,,,,,0.173,,,,,,,,,,,,,,,,,,
17.45,0.75962,19.70566,1.5,,,,,,,,,,,,,,,,,,,0.179,,,,,,,,,,,,,,,,,,
18.05,0.65971,14.77322,1.5,,,,,,,,,,,,,,,,,,,0.185,,,,,,,,,,,,,,,,,,
18.65,0.55975,10.65268,1.5,,,,,,,,,,,,,,,,,,,0.191,,,,,,,,,,,,,,,,,,
19.25,0.45979,7.09609,1.5,,,,,,,,,,,,,,,,,,,0.197,,,,,,,,,,,,,,,,,,
19.85,0.35961,4.02086,1.5,,,,,,,,,,,,,,,,,,,,,,,,,,,,,,,,,,,,,
20.45,0.25965,1.42245,1.5,,,,,,,,,,,,,,,,,,,,,,,,,,,,,,,,,,,,,
20.782,0.27166,1.90846,2,,,,,,,,,,,,,,,,,,,,,,,,,,,,,,,,,,,,,
21.382,0.37207,5.41797,2,,,,,,,,,,,,,,,,,,,,,,,,,,,,,,,,,,,,,
21.982,0.47198,9.10855,2,,,,,,,,,,,,,,,,,,,,,,,,,,,,,,,,,,,,,
22.582,0.57199,13.13202,2,,,,,,,,,,,,,,,,,,,,,,,,,,,,,,,,,,,,,
23.182,0.67212,17.5289,2,,,,,,,,,,,,,,,,,,,,,,,,,,,,,,,,,,,,,
23.782,0.77208,22.50667,2,,,,,,,,,,,,,,,,,,,,,,,,,,,,,,,,,,,,,
24.382,0.87193,27.76349,2,,,,,,,,,,,,,,,,,,,,,,,,,,,,,,,,,,,,,
24.982,0.97195,33.65026,2,,,,,,,,,,,,,,,,,,,,,,,,,,,,,,,,,,,,,
25.574,1.07077,40.00733,2.5,,,,,,,,,,,,,,,,,,,,,,,,,,,,,,,,,,,,,
26.076,0.9873,32.78862,2.5,,,,,,,,,,,,,,,,,,,,,,,,,,,,,,,,,,,,,
26.676,0.8874,25.54309,2.5,,,,,,,,,,,,,,,,,,,,,,,,,,,,,,,,,,,,,
27.276,0.78744,19.80424,2.5,,,,,,,,,,,,,,,,,,,,,,,,,,,,,,,,,,,,,
27.876,0.68742,14.81949,2.5,,,,,,,,,,,,,,,,,,,,,,,,,,,,,,,,,,,,,
28.476,0.58724,10.65588,2.5,,,,,,,,,,,,,,,,,,,,,,,,,,,,,,,,,,,,,
29.076,0.48733,7.0483,2.5,,,,,,,,,,,,,,,,,,,,,,,,,,,,,,,,,,,,,
29.676,0.38749,3.99507,2.5,,,,,,,,,,,,,,,,,,,,,,,,,,,,,,,,,,,,,
30.276,0.28747,1.34763,2.5,,,,,,,,,,,,,,,,,,,,,,,,,,,,,,,,,,,,,
30.67,0.32266,2.5684,3,,,,,,,,,,,,,,,,,,,,,,,,,,,,,,,,,,,,,
31.27,0.42256,6.14849,3,,,,,,,,,,,,,,,,,,,,,,,,,,,,,,,,,,,,,
31.87,0.52275,10.00209,3,,,,,,,,,,,,,,,,,,,,,,,,,,,,,,,,,,,,,
32.47,0.62271,14.08348,3,,,,,,,,,,,,,,,,,,,,,,,,,,,,,,,,,,,,,
33.07,0.72278,18.61674,3,,,,,,,,,,,,,,,,,,,,,,,,,,,,,,,,,,,,,
33.67,0.82263,23.76088,3,,,,,,,,,,,,,,,,,,,,,,,,,,,,,,,,,,,,,
34.27,0.9227,29.38913,3,,,,,,,,,,,,,,,,,,,,,,,,,,,,,,,,,,,,,
34.87,1.02272,35.55959,3,,,,,,,,,,,,,,,,,,,,,,,,,,,,,,,,,,,,,
35.278,1.09061,40.0351,3.5,,,,,,,,,,,,,,,,,,,,,,,,,,,,,,,,,,,,,
35.878,0.99031,31.43779,3.5,,,,,,,,,,,,,,,,,,,,,,,,,,,,,,,,,,,,,
36.478,0.89046,24.47012,3.5,,,,,,,,,,,,,,,,,,,,,,,,,,,,,,,,,,,,,
37.078,0.79039,18.85894,3.5,,,,,,,,,,,,,,,,,,,,,,,,,,,,,,,,,,,,,
37.678,0.69043,14.04694,3.5,,,,,,,,,,,,,,,,,,,,,,,,,,,,,,,,,,,,,
38.278,0.59035,9.97222,3.5,,,,,,,,,,,,,,,,,,,,,,,,,,,,,,,,,,,,,
38.878,0.49034,6.44607,3.5,,,,,,,,,,,,,,,,,,,,,,,,,,,,,,,,,,,,,
39.478,0.39043,3.46243,3.5,,,,,,,,,,,,,,,,,,,,,,,,,,,,,,,,,,,,,
40.048,0.29535,0.99406,4,,,,,,,,,,,,,,,,,,,,,,,,,,,,,,,,,,,,,
40.452,0.36227,3.14011,4,,,,,,,,,,,,,,,,,,,,,,,,,,,,,,,,,,,,,
41.052,0.46229,6.78516,4,,,,,,,,,,,,,,,,,,,,,,,,,,,,,,,,,,,,,
41.652,0.56242,10.83788,4,,,,,,,,,,,,,,,,,,,,,,,,,,,,,,,,,,,,,
42.252,0.66243,14.91551,4,,,,,,,,,,,,,,,,,,,,,,,,,,,,,,,,,,,,,
42.852,0.76234,19.65829,4,,,,,,,,,,,,,,,,,,,,,,,,,,,,,,,,,,,,,
43.452,0.86224,24.9332,4,,,,,,,,,,,,,,,,,,,,,,,,,,,,,,,,,,,,,
44.052,0.96237,30.56914,4,,,,,,,,,,,,,,,,,,,,,,,,,,,,,,,,,,,,,
44.652,1.06244,37.07299,4,,,,,,,,,,,,,,,,,,,,,,,,,,,,,,,,,,,,,
45.126,1.07497,37.35804,4.5,,,,,,,,,,,,,,,,,,,,,,,,,,,,,,,,,,,,,
45.726,0.97438,29.08274,4.5,,,,,,,,,,,,,,,,,,,,,,,,,,,,,,,,,,,,,
46.326,0.87431,22.51116,4.5,,,,,,,,,,,,,,,,,,,,,,,,,,,,,,,,,,,,,
46.926,0.77446,17.1518,4.5,,,,,,,,,,,,,,,,,,,,,,,,,,,,,,,,,,,,,
47.526,0.67445,12.62694,4.5,,,,,,,,,,,,,,,,,,,,,,,,,,,,,,,,,,,,,
48.126,0.57443,8.71762,4.5,,,,,,,,,,,,,,,,,,,,,,,,,,,,,,,,,,,,,
48.726,0.4743,5.32759,4.5,,,,,,,,,,,,,,,,,,,,,,,,,,,,,,,,,,,,,
49.326,0.37434,2.50866,4.5,,,,,,,,,,,,,,,,,,,,,,,,,,,,,,,,,,,,,
49.68,0.31524,0.97441,5,,,,,,,,,,,,,,,,,,,,,,,,,,,,,,,,,,,,,
50.28,0.41633,4.39694,5,,,,,,,,,,,,,,,,,,,,,,,,,,,,,,,,,,,,,
50.88,0.51629,8.08215,5,,,,,,,,,,,,,,,,,,,,,,,,,,,,,,,,,,,,,
51.48,0.61636,12.1629,5,,,,,,,,,,,,,,,,,,,,,,,,,,,,,,,,,,,,,
52.08,0.71638,16.60464,5,,,,,,,,,,,,,,,,,,,,,,,,,,,,,,,,,,,,,
52.68,0.81634,21.55023,5,,,,,,,,,,,,,,,,,,,,,,,,,,,,,,,,,,,,,
53.28,0.91624,27.01274,5,,,,,,,,,,,,,,,,,,,,,,,,,,,,,,,,,,,,,
53.88,1.01643,32.98572,5,,,,,,,,,,,,,,,,,,,,,,,,,,,,,,,,,,,,,
54.48,1.11645,39.7159,5,,,,,,,,,,,,,,,,,,,,,,,,,,,,,,,,,,,,,
54.906,1.05377,34.15385,5.5,,,,,,,,,,,,,,,,,,,,,,,,,,,,,,,,,,,,,
55.506,0.95381,26.54325,5.5,,,,,,,,,,,,,,,,,,,,,,,,,,,,,,,,,,,,,
56.106,0.8538,20.57341,5.5,,,,,,,,,,,,,,,,,,,,,,,,,,,,,,,,,,,,,
56.706,0.75372,15.45981,5.5,,,,,,,,,,,,,,,,,,,,,,,,,,,,,,,,,,,,,
57.306,0.65365,11.09818,5.5,,,,,,,,,,,,,,,,,,,,,,,,,,,,,,,,,,,,,
57.906,0.55375,7.41746,5.5,,,,,,,,,,,,,,,,,,,,,,,,,,,,,,,,,,,,,
58.506,0.45373,4.29143,5.5,,,,,,,,,,,,,,,,,,,,,,,,,,,,,,,,,,,,,
59.106,0.35383,1.49244,5.5,,,,,,,,,,,,,,,,,,,,,,,,,,,,,,,,,,,,,
59.446,0.36414,1.9454,6,,,,,,,,,,,,,,,,,,,,,,,,,,,,,,,,,,,,,
60.046,0.46461,5.62583,6,,,,,,,,,,,,,,,,,,,,,,,,,,,,,,,,,,,,,
60.646,0.56474,9.405,6,,,,,,,,,,,,,,,,,,,,,,,,,,,,,,,,,,,,,
61.246,0.66476,13.58774,6,,,,,,,,,,,,,,,,,,,,,,,,,,,,,,,,,,,,,
61.846,0.7646,18.18188,6,,,,,,,,,,,,,,,,,,,,,,,,,,,,,,,,,,,,,
62.446,0.86462,23.37231,6,,,,,,,,,,,,,,,,,,,,,,,,,,,,,,,,,,,,,
63.046,0.96475,29.03398,6,,,,,,,,,,,,,,,,,,,,,,,,,,,,,,,,,,,,,
63.646,1.06477,35.28432,6,,,,,,,,,,,,,,,,,,,,,,,,,,,,,,,,,,,,,
64.06,1.13367,40.03835,6.5,,,,,,,,,,,,,,,,,,,,,,,,,,,,,,,,,,,,,
64.66,1.03349,31.45773,6.5,,,,,,,,,,,,,,,,,,,,,,,,,,,,,,,,,,,,,
65.26,0.93336,24.455,6.5,,,,,,,,,,,,,,,,,,,,,,,,,,,,,,,,,,,,,
65.86,0.8334,18.75471,6.5,,,,,,,,,,,,,,,,,,,,,,,,,,,,,,,,,,,,,
66.46,0.73344,13.89275,6.5,,,,,,,,,,,,,,,,,,,,,,,,,,,,,,,,,,,,,
67.06,0.63342,9.81004,6.5,,,,,,,,,,,,,,,,,,,,,,,,,,,,,,,,,,,,,
67.66,0.53329,6.27578,6.5,,,,,,,,,,,,,,,,,,,,,,,,,,,,,,,,,,,,,
68.26,0.43333,3.27678,6.5,,,,,,,,,,,,,,,,,,,,,,,,,,,,,,,,,,,,,
68.774,0.34771,0.99465,7,,,,,,,,,,,,,,,,,,,,,,,,,,,,,,,,,,,,,
69.178,0.41469,3.19138,7,,,,,,,,,,,,,,,,,,,,,,,,,,,,,,,,,,,,,
69.778,0.5147,6.90285,7,,,,,,,,,,,,,,,,,,,,,,,,,,,,,,,,,,,,,
70.378,0.61472,10.85067,7,,,,,,,,,,,,,,,,,,,,,,,,,,,,,,,,,,,,,
70.978,0.71474,15.20128,7,,,,,,,,,,,,,,,,,,,,,,,,,,,,,,,,,,,,,
71.578,0.8147,20.0595,7,,,,,,,,,,,,,,,,,,,,,,,,,,,,,,,,,,,,,
72.178,0.91466,25.41694,7,,,,,,,,,,,,,,,,,,,,,,,,,,,,,,,,,,,,,
72.778,1.01479,31.34082,7,,,,,,,,,,,,,,,,,,,,,,,,,,,,,,,,,,,,,
73.378,1.11475,37.95484,7,,,,,,,,,,,,,,,,,,,,,,,,,,,,,,,,,,,,,
73.852,1.0935,35.64454,7.5,,,,,,,,,,,,,,,,,,,,,,,,,,,,,,,,,,,,,
74.452,0.99325,27.71892,7.5,,,,,,,,,,,,,,,,,,,,,,,,,,,,,,,,,,,,,
75.052,0.89346,21.45702,7.5,,,,,,,,,,,,,,,,,,,,,,,,,,,,,,,,,,,,,
75.652,0.79339,16.22826,7.5,,,,,,,,,,,,,,,,,,,,,,,,,,,,,,,,,,,,,
76.252,0.69337,11.74731,7.5,,,,,,,,,,,,,,,,,,,,,,,,,,,,,,,,,,,,,
76.852,0.59336,7.92852,7.5,,,,,,,,,,,,,,,,,,,,,,,,,,,,,,,,,,,,,
77.452,0.49334,4.68072,7.5,,,,,,,,,,,,,,,,,,,,,,,,,,,,,,,,,,,,,
78.052,0.39344,1.83175,7.5,,,,,,,,,,,,,,,,,,,,,,,,,,,,,,,,,,,,,
78.452,0.39406,1.96046,8,,,,,,,,,,,,,,,,,,,,,,,,,,,,,,,,,,,,,
79.052,0.49442,5.69669,8,,,,,,,,,,,,,,,,,,,,,,,,,,,,,,,,,,,,,
79.652,0.59426,9.56843,8,,,,,,,,,,,,,,,,,,,,,,,,,,,,,,,,,,,,,
80.252,0.69434,13.78107,8,,,,,,,,,,,,,,,,,,,,,,,,,,,,,,,,,,,,,
80.852,0.79435,18.48106,8,,,,,,,,,,,,,,,,,,,,,,,,,,,,,,,,,,,,,
81.452,0.89443,23.73313,8,,,,,,,,,,,,,,,,,,,,,,,,,,,,,,,,,,,,,
82.052,0.99433,29.46763,8,,,,,,,,,,,,,,,,,,,,,,,,,,,,,,,,,,,,,
82.652,1.0944,35.87994,8,,,,,,,,,,,,,,,,,,,,,,,,,,,,,,,,,,,,,
83.112,1.14212,39.65541,8.5,,,,,,,,,,,,,,,,,,,,,,,,,,,,,,,,,,,,,
83.712,1.0374,30.13878,8.5,,,,,,,,,,,,,,,,,,,,,,,,,,,,,,,,,,,,,
84.312,0.93738,23.32063,8.5,,,,,,,,,,,,,,,,,,,,,,,,,,,,,,,,,,,,,
84.912,0.83748,17.90549,8.5,,,,,,,,,,,,,,,,,,,,,,,,,,,,,,,,,,,,,
85.512,0.7374,13.12531,8.5,,,,,,,,,,,,,,,,,,,,,,,,,,,,,,,,,,,,,
86.112,0.63739,9.07659,8.5,,,,,,,,,,,,,,,,,,,,,,,,,,,,,,,,,,,,,
86.712,0.53731,5.60912,8.5,,,,,,,,,,,,,,,,,,,,,,,,,,,,,,,,,,,,,
87.312,0.43735,2.68398,8.5,,,,,,,,,,,,,,,,,,,,,,,,,,,,,,,,,,,,,
87.69,0.37434,0.96181,9,,,,,,,,,,,,,,,,,,,,,,,,,,,,,,,,,,,,,
88.29,0.47521,4.4785,9,,,,,,,,,,,,,,,,,,,,,,,,,,,,,,,,,,,,,
88.89,0.57539,8.25815,9,,,,,,,,,,,,,,,,,,,,,,,,,,,,,,,,,,,,,
89.49,0.67541,12.39688,9,,,,,,,,,,,,,,,,,,,,,,,,,,,,,,,,,,,,,
90.09,0.77543,17.05215,9,,,,,,,,,,,,,,,,,,,,,,,,,,,,,,,,,,,,,
90.69,0.87527,22.09587,9,,,,,,,,,,,,,,,,,,,,,,,,,,,,,,,,,,,,,
91.29,0.97535,27.71655,9,,,,,,,,,,,,,,,,,,,,,,,,,,,,,,,,,,,,,
91.89,1.07548,33.9214,9,,,,,,,,,,,,,,,,,,,,,,,,,,,,,,,,,,,,,
92.412,1.16218,40.01377,9.5,,,,,,,,,,,,,,,,,,,,,,,,,,,,,,,,,,,,,
92.914,1.07916,32.71212,9.5,,,,,,,,,,,,,,,,,,,,,,,,,,,,,,,,,,,,,
93.514,0.97909,25.38628,9.5,,,,,,,,,,,,,,,,,,,,,,,,,,,,,,,,,,,,,
94.114,0.87901,19.60449,9.5,,,,,,,,,,,,,,,,,,,,,,,,,,,,,,,,,,,,,
94.714,0.77911,14.5209,9.5,,,,,,,,,,,,,,,,,,,,,,,,,,,,,,,,,,,,,
95.314,0.67909,10.29781,9.5,,,,,,,,,,,,,,,,,,,,,,,,,,,,,,,,,,,,,
95.914,0.57908,6.71325,9.5,,,,,,,,,,,,,,,,,,,,,,,,,,,,,,,,,,,,,
96.514,0.47889,3.56165,9.5,,,,,,,,,,,,,,,,,,,,,,,,,,,,,,,,,,,,,
97.09,0.38301,0.99065,10,,,,,,,,,,,,,,,,,,,,,,,,,,,,,,,,,,,,,
97.592,0.35388,0.3552,10,,,,,,,,,,,,,,,,,,,,,,,,,,,,,,,,,,,,,
98.192,0.35694,0.56112,10,,,,,,,,,,,,,,,,,,,,,,,,,,,,,,,,,,,,,
98.792,0.37955,1.43003,10,,,,,,,,,,,,,,,,,,,,,,,,,,,,,,,,,,,,,
99.392,0.37921,1.47723,10,,,,,,,,,,,,,,,,,,,,,,,,,,,,,,,,,,,,,
99.992,0.36771,1.1104,10,,,,,,,,,,,,,,,,,,,,,,,,,,,,,,,,,,,,,
100.592,0.36199,0.99034,10,,,,,,,,,,,,,,,,,,,,,,,,,,,,,,,,,,,,,
101.192,0.36153,0.99365,10,,,,,,,,,,,,,,,,,,,,,,,,,,,,,,,,,,,,,
101.792,0.36136,1.13073,10,,,,,,,,,,,,,,,,,,,,,,,,,,,,,,,,,,,,,
102.392,0.36131,1.03075,10,,,,,,,,,,,,,,,,,,,,,,,,,,,,,,,,,,,,,
102.992,0.36125,1.05726,10,,,,,,,,,,,,,,,,,,,,,,,,,,,,,,,,,,,,,
103.592,0.36074,1.08783,10,,,,,,,,,,,,,,,,,,,,,,,,,,,,,,,,,,,,,
104.192,0.35927,1.07519,10,,,,,,,,,,,,,,,,,,,,,,,,,,,,,,,,,,,,,
104.792,0.35779,1.066,10,,,,,,,,,,,,,,,,,,,,,,,,,,,,,,,,,,,,,
105.392,0.35706,1.00771,10,,,,,,,,,,,,,,,,,,,,,,,,,,,,,,,,,,,,,
105.992,0.35666,0.99731,10,,,,,,,,,,,,,,,,,,,,,,,,,,,,,,,,,,,,,
106.592,0.35632,1.05542,10,,,,,,,,,,,,,,,,,,,,,,,,,,,,,,,,,,,,,
107.192,0.35592,1.04016,10,,,,,,,,,,,,,,,,,,,,,,,,,,,,,,,,,,,,,
107.792,0.35558,1.08746,10,,,,,,,,,,,,,,,,,,,,,,,,,,,,,,,,,,,,,
108.392,0.3549,1.01758,10,,,,,,,,,,,,,,,,,,,,,,,,,,,,,,,,,,,,,
108.992,0.35434,1.02652,10,,,,,,,,,,,,,,,,,,,,,,,,,,,,,,,,,,,,,
109.592,0.35371,1.01179,10,,,,,,,,,,,,,,,,,,,,,,,,,,,,,,,,,,,,,
110.192,0.35343,1.00476,10,,,,,,,,,,,,,,,,,,,,,,,,,,,,,,,,,,,,,
110.792,0.35337,1.03112,10,,,,,,,,,,,,,,,,,,,,,,,,,,,,,,,,,,,,,
111.392,0.35337,1.00662,10,,,,,,,,,,,,,,,,,,,,,,,,,,,,,,,,,,,,,
111.992,0.35332,0.9804,10,,,,,,,,,,,,,,,,,,,,,,,,,,,,,,,,,,,,,
112.592,0.35343,1.00342,10,,,,,,,,,,,,,,,,,,,,,,,,,,,,,,,,,,,,,
113.192,0.35343,1.00554,10,,,,,,,,,,,,,,,,,,,,,,,,,,,,,,,,,,,,,
113.792,0.35343,1.08459,10,,,,,,,,,,,,,,,,,,,,,,,,,,,,,,,,,,,,,
114.392,0.35343,0.9963,10,,,,,,,,,,,,,,,,,,,,,,,,,,,,,,,,,,,,,
114.992,0.35332,1.07151,10,,,,,,,,,,,,,,,,,,,,,,,,,,,,,,,,,,,,,
115.592,0.35332,1.08739,10,,,,,,,,,,,,,,,,,,,,,,,,,,,,,,,,,,,,,
116.192,0.35326,1.08163,10,,,,,,,,,,,,,,,,,,,,,,,,,,,,,,,,,,,,,
116.792,0.35258,1.20893,10,,,,,,,,,,,,,,,,,,,,,,,,,,,,,,,,,,,,,
117.392,0.35031,1.05545,10,,,,,,,,,,,,,,,,,,,,,,,,,,,,,,,,,,,,,
117.992,0.34918,0.98285,10,,,,,,,,,,,,,,,,,,,,,,,,,,,,,,,,,,,,,
118.592,0.3489,1.02668,10,,,,,,,,,,,,,,,,,,,,,,,,,,,,,,,,,,,,,
119.192,0.3489,1.01398,10,,,,,,,,,,,,,,,,,,,,,,,,,,,,,,,,,,,,,
119.792,0.34901,1.01108,10,,,,,,,,,,,,,,,,,,,,,,,,,,,,,,,,,,,,,
120.392,0.34907,1.00769,10,,,,,,,,,,,,,,,,,,,,,,,,,,,,,,,,,,,,,
120.992,0.34912,0.9902,10,,,,,,,,,,,,,,,,,,,,,,,,,,,,,,,,,,,,,
121.592,0.34918,1.02942,10,,,,,,,,,,,,,,,,,,,,,,,,,,,,,,,,,,,,,
122.192,0.34924,0.99705,10,,,,,,,,,,,,,,,,,,,,,,,,,,,,,,,,,,,,,
122.792,0.34929,1.03501,10,,,,,,,,,,,,,,,,,,,,,,,,,,,,,,,,,,,,,
123.392,0.34935,1.0063,10,,,,,,,,,,,,,,,,,,,,,,,,,,,,,,,,,,,,,
123.992,0.34941,0.99917,10,,,,,,,,,,,,,,,,,,,,,,,,,,,,,,,,,,,,,
124.592,0.34941,1.04452,10,,,,,,,,,,,,,,,,,,,,,,,,,,,,,,,,,,,,,
125.192,0.34941,1.00069,10,,,,,,,,,,,,,,,,,,,,,,,,,,,,,,,,,,,,,
125.792,0.34941,1.01468,10,,,,,,,,,,,,,,,,,,,,,,,,,,,,,,,,,,,,,
126.392,0.34941,1.05361,10,,,,,,,,,,,,,,,,,,,,,,,,,,,,,,,,,,,,,
126.992,0.34946,1.01767,10,,,,,,,,,,,,,,,,,,,,,,,,,,,,,,,,,,,,,
127.592,0.34946,0.96837,10,,,,,,,,,,,,,,,,,,,,,,,,,,,,,,,,,,,,,
128.192,0.34952,1.04949,10,,,,,,,,,,,,,,,,,,,,,,,,,,,,,,,,,,,,,
128.792,0.34958,1.06823,10,,,,,,,,,,,,,,,,,,,,,,,,,,,,,,,,,,,,,
129.392,0.34958,1.04831,10,,,,,,,,,,,,,,,,,,,,,,,,,,,,,,,,,,,,,
129.992,0.34946,1.03601,10,,,,,,,,,,,,,,,,,,,,,,,,,,,,,,,,,,,,,
130.592,0.34958,1.02119,10,,,,,,,,,,,,,,,,,,,,,,,,,,,,,,,,,,,,,
131.192,0.34958,0.98753,10,,,,,,,,,,,,,,,,,,,,,,,,,,,,,,,,,,,,,
131.792,0.34946,1.06548,10,,,,,,,,,,,,,,,,,,,,,,,,,,,,,,,,,,,,,
132.392,0.34952,1.06567,10,,,,,,,,,,,,,,,,,,,,,,,,,,,,,,,,,,,,,
132.992,0.34952,1.04859,10,,,,,,,,,,,,,,,,,,,,,,,,,,,,,,,,,,,,,
133.592,0.34941,1.07883,10,,,,,,,,,,,,,,,,,,,,,,,,,,,,,,,,,,,,,
134.192,0.34946,1.01499,10,,,,,,,,,,,,,,,,,,,,,,,,,,,,,,,,,,,,,
134.792,0.34935,1.09255,10,,,,,,,,,,,,,,,,,,,,,,,,,,,,,,,,,,,,,
135.392,0.34929,1.09429,10,,,,,,,,,,,,,,,,,,,,,,,,,,,,,,,,,,,,,
135.992,0.34918,1.01652,10,,,,,,,,,,,,,,,,,,,,,,,,,,,,,,,,,,,,,
136.592,0.34912,1.068,10,,,,,,,,,,,,,,,,,,,,,,,,,,,,,,,,,,,,,
137.192,0.3489,1.10841,10,,,,,,,,,,,,,,,,,,,,,,,,,,,,,,,,,,,,,
137.792,0.3485,1.12039,10,,,,,,,,,,,,,,,,,,,,,,,,,,,,,,,,,,,,,
138.392,0.34714,1.01722,10,,,,,,,,,,,,,,,,,,,,,,,,,,,,,,,,,,,,,
138.992,0.34612,1.01984,10,,,,,,,,,,,,,,,,,,,,,,,,,,,,,,,,,,,,,
139.592,0.34572,1.01199,10,,,,,,,,,,,,,,,,,,,,,,,,,,,,,,,,,,,,,
140.192,0.34578,0.96338,10,,,,,,,,,,,,,,,,,,,,,,,,,,,,,,,,,,,,,
140.792,0.34578,0.99307,10,,,,,,,,,,,,,,,,,,,,,,,,,,,,,,,,,,,,,
141.392,0.34589,0.95521,10,,,,,,,,,,,,,,,,,,,,,,,,,,,,,,,,,,,,,
141.992,0.34601,0.93908,10,,,,,,,,,,,,,,,,,,,,,,,,,,,,,,,,,,,,,
142.592,0.34612,0.99509,10,,,,,,,,,,,,,,,,,,,,,,,,,,,,,,,,,,,,,
143.192,0.34623,0.93542,10,,,,,,,,,,,,,,,,,,,,,,,,,,,,,,,,,,,,,
143.792,0.34652,0.94689,10,,,,,,,,,,,,,,,,,,,,,,,,,,,,,,,,,,,,,
144.392,0.34697,0.94876,10,,,,,,,,,,,,,,,,,,,,,,,,,,,,,,,,,,,,,
144.992,0.34742,0.94997,10,,,,,,,,,,,,,,,,,,,,,,,,,,,,,,,,,,,,,
145.592,0.34805,1.03713,10,,,,,,,,,,,,,,,,,,,,,,,,,,,,,,,,,,,,,
146.192,0.34867,1.02093,10,,,,,,,,,,,,,,,,,,,,,,,,,,,,,,,,,,,,,
146.792,0.34924,1.05926,10,,,,,,,,,,,,,,,,,,,,,,,,,,,,,,,,,,,,,
147.392,0.34941,1.07056,10,,,,,,,,,,,,,,,,,,,,,,,,,,,,,,,,,,,,,
147.992,0.34941,1.09503,10,,,,,,,,,,,,,,,,,,,,,,,,,,,,,,,,,,,,,
148.592,0.34929,1.06323,10,,,,,,,,,,,,,,,,,,,,,,,,,,,,,,,,,,,,,
149.192,0.34929,1.03245,10,,,,,,,,,,,,,,,,,,,,,,,,,,,,,,,,,,,,,
149.792,0.34929,1.02362,10,,,,,,,,,,,,,,,,,,,,,,,,,,,,,,,,,,,,,
150.392,0.34924,1.06585,10,,,,,,,,,,,,,,,,,,,,,,,,,,,,,,,,,,,,,
150.992,0.34924,1.01883,10,,,,,,,,,,,,,,,,,,,,,,,,,,,,,,,,,,,,,
151.592,0.34912,1.07714,10,,,,,,,,,,,,,,,,,,,,,,,,,,,,,,,,,,,,,
152.192,0.34907,1.07776,10,,,,,,,,,,,,,,,,,,,,,,,,,,,,,,,,,,,,,
152.792,0.34895,1.15055,10,,,,,,,,,,,,,,,,,,,,,,,,,,,,,,,,,,,,,
153.392,0.34878,1.02012,10,,,,,,,,,,,,,,,,,,,,,,,,,,,,,,,,,,,,,
153.992,0.34867,1.07142,10,,,,,,,,,,,,,,,,,,,,,,,,,,,,,,,,,,,,,
154.592,0.34839,1.10711,10,,,,,,,,,,,,,,,,,,,,,,,,,,,,,,,,,,,,,
155.192,0.34805,1.09369,10,,,,,,,,,,,,,,,,,,,,,,,,,,,,,,,,,,,,,
155.792,0.34765,1.0829,10,,,,,,,,,,,,,,,,,,,,,,,,,,,,,,,,,,,,,
156.392,0.3472,1.05665,10,,,,,,,,,,,,,,,,,,,,,,,,,,,,,,,,,,,,,
156.992,0.34674,1.02442,10,,,,,,,,,,,,,,,,,,,,,,,,,,,,,,,,,,,,,
157.592,0.34652,1.04652,10,,,,,,,,,,,,,,,,,,,,,,,,,,,,,,,,,,,,,
158.192,0.34623,1.03545,10,,,,,,,,,,,,,,,,,,,,,,,,,,,,,,,,,,,,,
158.792,0.34606,0.99858,10,,,,,,,,,,,,,,,,,,,,,,,,,,,,,,,,,,,,,
159.392,0.34601,0.98672,10,,,,,,,,,,,,,,,,,,,,,,,,,,,,,,,,,,,,,
159.992,0.34601,0.94852,10,,,,,,,,,,,,,,,,,,,,,,,,,,,,,,,,,,,,,
160.592,0.34612,0.99662,10,,,,,,,,,,,,,,,,,,,,,,,,,,,,,,,,,,,,,
161.192,0.34618,1.01735,10,,,,,,,,,,,,,,,,,,,,,,,,,,,,,,,,,,,,,
161.792,0.34629,0.97721,10,,,,,,,,,,,,,,,,,,,,,,,,,,,,,,,,,,,,,
162.392,0.34635,1.0109,10,,,,,,,,,,,,,,,,,,,,,,,,,,,,,,,,,,,,,
162.992,0.3464,1.00216,10,,,,,,,,,,,,,,,,,,,,,,,,,,,,,,,,,,,,,
163.592,0.34652,0.96802,10,,,,,,,,,,,,,,,,,,,,,,,,,,,,,,,,,,,,,
164.192,0.34657,1.00469,10,,,,,,,,,,,,,,,,,,,,,,,,,,,,,,,,,,,,,
164.792,0.34669,0.98681,10,,,,,,,,,,,,,,,,,,,,,,,,,,,,,,,,,,,,,
165.392,0.34691,0.95682,10,,,,,,,,,,,,,,,,,,,,,,,,,,,,,,,,,,,,,
165.992,0.3472,0.97562,10,,,,,,,,,,,,,,,,,,,,,,,,,,,,,,,,,,,,,
166.592,0.34737,0.9932,10,,,,,,,,,,,,,,,,,,,,,,,,,,,,,,,,,,,,,
167.192,0.34759,0.9964,10,,,,,,,,,,,,,,,,,,,,,,,,,,,,,,,,,,,,,
167.792,0.34788,1.02386,10,,,,,,,,,,,,,,,,,,,,,,,,,,,,,,,,,,,,,
168.392,0.34816,1.00343,10,,,,,,,,,,,,,,,,,,,,,,,,,,,,,,,,,,,,,
168.992,0.34844,1.00974,10,,,,,,,,,,,,,,,,,,,,,,,,,,,,,,,,,,,,,
169.592,0.34861,1.05193,10,,,,,,,,,,,,,,,,,,,,,,,,,,,,,,,,,,,,,
170.192,0.34867,1.06853,10,,,,,,,,,,,,,,,,,,,,,,,,,,,,,,,,,,,,,
170.792,0.34856,1.04315,10,,,,,,,,,,,,,,,,,,,,,,,,,,,,,,,,,,,,,
171.392,0.34856,0.99343,10,,,,,,,,,,,,,,,,,,,,,,,,,,,,,,,,,,,,,
171.992,0.34856,1.00821,10,,,,,,,,,,,,,,,,,,,,,,,,,,,,,,,,,,,,,
172.592,0.34856,1.08362,10,,,,,,,,,,,,,,,,,,,,,,,,,,,,,,,,,,,,,
173.192,0.34844,1.02394,10,,,,,,,,,,,,,,,,,,,,,,,,,,,,,,,,,,,,,
173.792,0.3485,1.0197,10,,,,,,,,,,,,,,,,,,,,,,,,,,,,,,,,,,,,,
174.392,0.34833,1.05925,10,,,,,,,,,,,,,,,,,,,,,,,,,,,,,,,,,,,,,
174.992,0.34833,1.03872,10,,,,,,,,,,,,,,,,,,,,,,,,,,,,,,,,,,,,,
175.592,0.34839,1.0503,10,,,,,,,,,,,,,,,,,,,,,,,,,,,,,,,,,,,,,
176.192,0.34822,1.01336,10,,,,,,,,,,,,,,,,,,,,,,,,,,,,,,,,,,,,,
176.792,0.34822,1.06082,10,,,,,,,,,,,,,,,,,,,,,,,,,,,,,,,,,,,,,
177.392,0.34816,1.05331,10,,,,,,,,,,,,,,,,,,,,,,,,,,,,,,,,,,,,,
177.992,0.34799,1.0685,10,,,,,,,,,,,,,,,,,,,,,,,,,,,,,,,,,,,,,
178.592,0.34788,1.03174,10,,,,,,,,,,,,,,,,,,,,,,,,,,,,,,,,,,,,,
179.192,0.34776,1.04757,10,,,,,,,,,,,,,,,,,,,,,,,,,,,,,,,,,,,,,
179.792,0.34765,1.03856,10,,,,,,,,,,,,,,,,,,,,,,,,,,,,,,,,,,,,,
180.392,0.34759,1.03099,10,,,,,,,,,,,,,,,,,,,,,,,,,,,,,,,,,,,,,
180.992,0.34759,1.05485,10,,,,,,,,,,,,,,,,,,,,,,,,,,,,,,,,,,,,,
181.592,0.34754,1.04759,10,,,,,,,,,,,,,,,,,,,,,,,,,,,,,,,,,,,,,
182.192,0.34748,1.06566,10,,,,,,,,,,,,,,,,,,,,,,,,,,,,,,,,,,,,,
182.792,0.34742,1.03721,10,,,,,,,,,,,,,,,,,,,,,,,,,,,,,,,,,,,,,
183.392,0.34725,1.03441,10,,,,,,,,,,,,,,,,,,,,,,,,,,,,,,,,,,,,,
183.992,0.3472,1.06783,10,,,,,,,,,,,,,,,,,,,,,,,,,,,,,,,,,,,,,
184.592,0.34714,1.06374,10,,,,,,,,,,,,,,,,,,,,,,,,,,,,,,,,,,,,,
185.192,0.34697,1.03005,10,,,,,,,,,,,,,,,,,,,,,,,,,,,,,,,,,,,,,
185.792,0.34691,1.02225,10,,,,,,,,,,,,,,,,,,,,,,,,,,,,,,,,,,,,,
186.392,0.3468,0.936,10,,,,,,,,,,,,,,,,,,,,,,,,,,,,,,,,,,,,,
186.992,0.3468,1.02468,10,,,,,,,,,,,,,,,,,,,,,,,,,,,,,,,,,,,,,
187.592,0.34691,1.04319,10,,,,,,,,,,,,,,,,,,,,,,,,,,,,,,,,,,,,,
188.192,0.34691,1.0458,10,,,,,,,,,,,,,,,,,,,,,,,,,,,,,,,,,,,,,
188.792,0.34697,1.02825,10,,,,,,,,,,,,,,,,,,,,,,,,,,,,,,,,,,,,,
189.392,0.34703,1.00042,10,,,,,,,,,,,,,,,,,,,,,,,,,,,,,,,,,,,,,
189.992,0.34703,1.05479,10,,,,,,,,,,,,,,,,,,,,,,,,,,,,,,,,,,,,,
190.592,0.34708,0.99588,10,,,,,,,,,,,,,,,,,,,,,,,,,,,,,,,,,,,,,
191.192,0.34708,1.02263,10,,,,,,,,,,,,,,,,,,,,,,,,,,,,,,,,,,,,,
191.792,0.34714,1.02831,10,,,,,,,,,,,,,,,,,,,,,,,,,,,,,,,,,,,,,
192.392,0.3472,1.01426,10,,,,,,,,,,,,,,,,,,,,,,,,,,,,,,,,,,,,,
192.992,0.34731,0.96383,10,,,,,,,,,,,,,,,,,,,,,,,,,,,,,,,,,,,,,
193.592,0.34748,0.9817,10,,,,,,,,,,,,,,,,,,,,,,,,,,,,,,,,,,,,,
194.192,0.34765,0.98323,10,,,,,,,,,,,,,,,,,,,,,,,,,,,,,,,,,,,,,
194.792,0.34793,0.978,10,,,,,,,,,,,,,,,,,,,,,,,,,,,,,,,,,,,,,
195.392,0.3481,0.98773,10,,,,,,,,,,,,,,,,,,,,,,,,,,,,,,,,,,,,,
195.992,0.34833,1.0616,10,,,,,,,,,,,,,,,,,,,,,,,,,,,,,,,,,,,,,
196.592,0.34856,0.98003,10,,,,,,,,,,,,,,,,,,,,,,,,,,,,,,,,,,,,,
197.192,0.34895,0.99874,10,,,,,,,,,,,,,,,,,,,,,,,,,,,,,,,,,,,,,
197.792,0.34958,1.03244,10,,,,,,,,,,,,,,,,,,,,,,,,,,,,,,,,,,,,,
198.392,0.34997,1.04033,10,,,,,,,,,,,,,,,,,,,,,,,,,,,,,,,,,,,,,
198.992,0.3502,1.06203,10,,,,,,,,,,,,,,,,,,,,,,,,,,,,,,,,,,,,,
199.592,0.35031,1.06921,10,,,,,,,,,,,,,,,,,,,,,,,,,,,,,,,,,,,,,
200.192,0.35037,1.09144,10,,,,,,,,,,,,,,,,,,,,,,,,,,,,,,,,,,,,,
200.792,0.35037,1.10531,10,,,,,,,,,,,,,,,,,,,,,,,,,,,,,,,,,,,,,
201.392,0.3502,1.08326,10,,,,,,,,,,,,,,,,,,,,,,,,,,,,,,,,,,,,,
201.992,0.35009,1.1714,10,,,,,,,,,,,,,,,,,,,,,,,,,,,,,,,,,,,,,
202.592,0.35003,1.0691,10,,,,,,,,,,,,,,,,,,,,,,,,,,,,,,,,,,,,,
203.192,0.34997,1.06579,10,,,,,,,,,,,,,,,,,,,,,,,,,,,,,,,,,,,,,
203.792,0.34986,1.09762,10,,,,,,,,,,,,,,,,,,,,,,,,,,,,,,,,,,,,,
204.392,0.34958,1.0821,10,,,,,,,,,,,,,,,,,,,,,,,,,,,,,,,,,,,,,
204.992,0.34929,1.13698,10,,,,,,,,,,,,,,,,,,,,,,,,,,,,,,,,,,,,,
205.592,0.34901,1.05929,10,,,,,,,,,,,,,,,,,,,,,,,,,,,,,,,,,,,,,
206.192,0.34867,1.03126,10,,,,,,,,,,,,,,,,,,,,,,,,,,,,,,,,,,,,,
206.792,0.34839,1.03995,10,,,,,,,,,,,,,,,,,,,,,,,,,,,,,,,,,,,,,
207.392,0.34793,1.03399,10,,,,,,,,,,,,,,,,,,,,,,,,,,,,,,,,,,,,,
207.992,0.34754,1.14011,10,,,,,,,,,,,,,,,,,,,,,,,,,,,,,,,,,,,,,
208.592,0.34748,1.07249,10,,,,,,,,,,,,,,,,,,,,,,,,,,,,,,,,,,,,,
209.192,0.34737,0.95816,10,,,,,,,,,,,,,,,,,,,,,,,,,,,,,,,,,,,,,
209.792,0.34748,0.99184,10,,,,,,,,,,,,,,,,,,,,,,,,,,,,,,,,,,,,,
210.392,0.34754,0.96471,10,,,,,,,,,,,,,,,,,,,,,,,,,,,,,,,,,,,,,
210.992,0.34759,0.9782,10,,,,,,,,,,,,,,,,,,,,,,,,,,,,,,,,,,,,,
211.592,0.34765,0.99281,10,,,,,,,,,,,,,,,,,,,,,,,,,,,,,,,,,,,,,
212.192,0.34776,0.9274,10,,,,,,,,,,,,,,,,,,,,,,,,,,,,,,,,,,,,,
212.792,0.34788,1.018,10,,,,,,,,,,,,,,,,,,,,,,,,,,,,,,,,,,,,,
213.392,0.34799,0.94388,10,,,,,,,,,,,,,,,,,,,,,,,,,,,,,,,,,,,,,
213.992,0.34816,1.02929,10,,,,,,,,,,,,,,,,,,,,,,,,,,,,,,,,,,,,,
214.592,0.3485,0.96224,10,,,,,,,,,,,,,,,,,,,,,,,,,,,,,,,,,,,,,
215.192,0.34884,0.95095,10,,,,,,,,,,,,,,,,,,,,,,,,,,,,,,,,,,,,,
215.792,0.34941,0.98008,10,,,,,,,,,,,,,,,,,,,,,,,,,,,,,,,,,,,,,
216.392,0.34997,0.99513,10,,,,,,,,,,,,,,,,,,,,,,,,,,,,,,,,,,,,,
216.992,0.35048,1.13256,10,,,,,,,,,,,,,,,,,,,,,,,,,,,,,,,,,,,,,
217.592,0.35088,1.03083,10,,,,,,,,,,,,,,,,,,,,,,,,,,,,,,,,,,,,,
218.192,0.35111,1.01253,10,,,,,,,,,,,,,,,,,,,,,,,,,,,,,,,,,,,,,
218.792,0.35122,1.15682,10,,,,,,,,,,,,,,,,,,,,,,,,,,,,,,,,,,,,,
219.392,0.35116,1.0452,10,,,,,,,,,,,,,,,,,,,,,,,,,,,,,,,,,,,,,
219.992,0.35099,1.08692,10,,,,,,,,,,,,,,,,,,,,,,,,,,,,,,,,,,,,,
220.592,0.35094,1.06296,10,,,,,,,,,,,,,,,,,,,,,,,,,,,,,,,,,,,,,
221.192,0.35094,1.07871,10,,,,,,,,,,,,,,,,,,,,,,,,,,,,,,,,,,,,,
221.792,0.35088,1.04385,10,,,,,,,,,,,,,,,,,,,,,,,,,,,,,,,,,,,,,
222.392,0.35088,1.04721,10,,,,,,,,,,,,,,,,,,,,,,,,,,,,,,,,,,,,,
222.992,0.35082,0.99625,10,,,,,,,,,,,,,,,,,,,,,,,,,,,,,,,,,,,,,
223.592,0.35077,1.07667,10,,,,,,,,,,,,,,,,,,,,,,,,,,,,,,,,,,,,,
224.192,0.3506,1.0826,10,,,,,,,,,,,,,,,,,,,,,,,,,,,,,,,,,,,,,
224.792,0.35043,1.0608,10,,,,,,,,,,,,,,,,,,,,,,,,,,,,,,,,,,,,,
225.392,0.35031,1.02996,10,,,,,,,,,,,,,,,,,,,,,,,,,,,,,,,,,,,,,
225.992,0.35014,1.06006,10,,,,,,,,,,,,,,,,,,,,,,,,,,,,,,,,,,,,,
226.592,0.34992,1.06587,10,,,,,,,,,,,,,,,,,,,,,,,,,,,,,,,,,,,,,
227.192,0.3498,1.01749,10,,,,,,,,,,,,,,,,,,,,,,,,,,,,,,,,,,,,,
227.792,0.34969,1.04464,10,,,,,,,,,,,,,,,,,,,,,,,,,,,,,,,,,,,,,
228.392,0.34958,1.05082,10,,,,,,,,,,,,,,,,,,,,,,,,,,,,,,,,,,,,,
228.992,0.34941,1.05329,10,,,,,,,,,,,,,,,,,,,,,,,,,,,,,,,,,,,,,
229.592,0.34924,1.05811,10,,,,,,,,,,,,,,,,,,,,,,,,,,,,,,,,,,,,,
230.192,0.34912,1.05691,10,,,,,,,,,,,,,,,,,,,,,,,,,,,,,,,,,,,,,
230.792,0.34912,0.96033,10,,,,,,,,,,,,,,,,,,,,,,,,,,,,,,,,,,,,,
231.392,0.34918,0.95177,10,,,,,,,,,,,,,,,,,,,,,,,,,,,,,,,,,,,,,
231.992,0.34935,1.00546,10,,,,,,,,,,,,,,,,,,,,,,,,,,,,,,,,,,,,,
232.592,0.34935,1.00595,10,,,,,,,,,,,,,,,,,,,,,,,,,,,,,,,,,,,,,
233.192,0.34946,0.9563,10,,,,,,,,,,,,,,,,,,,,,,,,,,,,,,,,,,,,,
233.792,0.34958,0.96943,10,,,,,,,,,,,,,,,,,,,,,,,,,,,,,,,,,,,,,
234.392,0.34975,0.95029,10,,,,,,,,,,,,,,,,,,,,,,,,,,,,,,,,,,,,,
234.992,0.34986,0.97555,10,,,,,,,,,,,,,,,,,,,,,,,,,,,,,,,,,,,,,
235.592,0.35003,0.96562,10,,,,,,,,,,,,,,,,,,,,,,,,,,,,,,,,,,,,,
236.192,0.35031,0.98483,10,,,,,,,,,,,,,,,,,,,,,,,,,,,,,,,,,,,,,
236.792,0.35082,1.0133,10,,,,,,,,,,,,,,,,,,,,,,,,,,,,,,,,,,,,,
237.392,0.35162,1.00208,10,,,,,,,,,,,,,,,,,,,,,,,,,,,,,,,,,,,,,
237.992,0.35281,1.03361,10,,,,,,,,,,,,,,,,,,,,,,,,,,,,,,,,,,,,,
238.592,0.35337,1.07206,10,,,,,,,,,,,,,,,,,,,,,,,,,,,,,,,,,,,,,
239.192,0.3536,1.08694,10,,,,,,,,,,,,,,,,,,,,,,,,,,,,,,,,,,,,,
239.792,0.35349,1.04247,10,,,,,,,,,,,,,,,,,,,,,,,,,,,,,,,,,,,,,
240.392,0.35337,1.12175,10,,,,,,,,,,,,,,,,,,,,,,,,,,,,,,,,,,,,,
240.992,0.35332,1.10087,10,,,,,,,,,,,,,,,,,,,,,,,,,,,,,,,,,,,,,
241.592,0.35326,1.0766,10,,,,,,,,,,,,,,,,,,,,,,,,,,,,,,,,,,,,,
242.192,0.3532,1.10557,10,,,,,,,,,,,,,,,,,,,,,,,,,,,,,,,,,,,,,
242.792,0.35303,1.09424,10,,,,,,,,,,,,,,,,,,,,,,,,,,,,,,,,,,,,,
243.392,0.35269,1.13612,10,,,,,,,,,,,,,,,,,,,,,,,,,,,,,,,,,,,,,
243.992,0.35213,1.06086,10,,,,,,,,,,,,,,,,,,,,,,,,,,,,,,,,,,,,,
244.592,0.35139,1.05611,10,,,,,,,,,,,,,,,,,,,,,,,,,,,,,,,,,,,,,
245.192,0.35082,1.07678,10,,,,,,,,,,,,,,,,,,,,,,,,,,,,,,,,,,,,,
245.792,0.35054,1.04185,10,,,,,,,,,,,,,,,,,,,,,,,,,,,,,,,,,,,,,
246.392,0.35043,0.95418,10,,,,,,,,,,,,,,,,,,,,,,,,,,,,,,,,,,,,,
246.992,0.35048,0.94544,10,,,,,,,,,,,,,,,,,,,,,,,,,,,,,,,,,,,,,
247.592,0.35043,1.04246,10,,,,,,,,,,,,,,,,,,,,,,,,,,,,,,,,,,,,,
248.192,0.35048,0.95659,10,,,,,,,,,,,,,,,,,,,,,,,,,,,,,,,,,,,,,
248.792,0.3506,0.96666,10,,,,,,,,,,,,,,,,,,,,,,,,,,,,,,,,,,,,,
249.392,0.35071,1.00565,10,,,,,,,,,,,,,,,,,,,,,,,,,,,,,,,,,,,,,
249.992,0.35077,0.97951,10,,,,,,,,,,,,,,,,,,,,,,,,,,,,,,,,,,,,,
250.592,0.35088,0.9786,10,,,,,,,,,,,,,,,,,,,,,,,,,,,,,,,,,,,,,
251.192,0.35099,0.99948,10,,,,,,,,,,,,,,,,,,,,,,,,,,,,,,,,,,,,,
251.792,0.35122,0.98482,10,,,,,,,,,,,,,,,,,,,,,,,,,,,,,,,,,,,,,
252.392,0.3515,0.97556,10,,,,,,,,,,,,,,,,,,,,,,,,,,,,,,,,,,,,,
252.992,0.3519,0.93171,10,,,,,,,,,,,,,,,,,,,,,,,,,,,,,,,,,,,,,
253.592,0.35235,0.98307,10,,,,,,,,,,,,,,,,,,,,,,,,,,,,,,,,,,,,,
254.192,0.35269,1.06334,10,,,,,,,,,,,,,,,,,,,,,,,,,,,,,,,,,,,,,
254.792,0.35269,1.07457,10,,,,,,,,,,,,,,,,,,,,,,,,,,,,,,,,,,,,,
255.392,0.35269,1.10171,10,,,,,,,,,,,,,,,,,,,,,,,,,,,,,,,,,,,,,
255.992,0.35258,1.07905,10,,,,,,,,,,,,,,,,,,,,,,,,,,,,,,,,,,,,,
256.592,0.35252,1.04275,10,,,,,,,,,,,,,,,,,,,,,,,,,,,,,,,,,,,,,
257.192,0.35247,1.0305,10,,,,,,,,,,,,,,,,,,,,,,,,,,,,,,,,,,,,,
257.792,0.35247,1.05962,10,,,,,,,,,,,,,,,,,,,,,,,,,,,,,,,,,,,,,
258.392,0.35247,0.98824,10,,,,,,,,,,,,,,,,,,,,,,,,,,,,,,,,,,,,,
258.992,0.35247,1.05534,10,,,,,,,,,,,,,,,,,,,,,,,,,,,,,,,,,,,,,
259.592,0.35241,1.07721,10,,,,,,,,,,,,,,,,,,,,,,,,,,,,,,,,,,,,,
260.192,0.35247,0.99207,10,,,,,,,,,,,,,,,,,,,,,,,,,,,,,,,,,,,,,
260.792,0.35235,1.07196,10,,,,,,,,,,,,,,,,,,,,,,,,,,,,,,,,,,,,,
261.392,0.35235,1.01216,10,,,,,,,,,,,,,,,,,,,,,,,,,,,,,,,,,,,,,
261.992,0.35247,1.02622,10,,,,,,,,,,,,,,,,,,,,,,,,,,,,,,,,,,,,,
262.592,0.35235,1.01081,10,,,,,,,,,,,,,,,,,,,,,,,,,,,,,,,,,,,,,
263.192,0.35241,1.06979,10,,,,,,,,,,,,,,,,,,,,,,,,,,,,,,,,,,,,,
263.792,0.3523,1.06055,10,,,,,,,,,,,,,,,,,,,,,,,,,,,,,,,,,,,,,
264.392,0.35224,1.02938,10,,,,,,,,,,,,,,,,,,,,,,,,,,,,,,,,,,,,,
264.992,0.35224,1.0416,10,,,,,,,,,,,,,,,,,,,,,,,,,,,,,,,,,,,,,
265.592,0.35224,1.03694,10,,,,,,,,,,,,,,,,,,,,,,,,,,,,,,,,,,,,,
266.192,0.35218,1.03574,10,,,,,,,,,,,,,,,,,,,,,,,,,,,,,,,,,,,,,
266.792,0.35218,1.04577,10,,,,,,,,,,,,,,,,,,,,,,,,,,,,,,,,,,,,,
267.392,0.35218,1.03423,10,,,,,,,,,,,,,,,,,,,,,,,,,,,,,,,,,,,,,
267.992,0.35218,1.02442,10,,,,,,,,,,,,,,,,,,,,,,,,,,,,,,,,,,,,,
268.592,0.35218,1.07336,10,,,,,,,,,,,,,,,,,,,,,,,,,,,,,,,,,,,,,
269.192,0.35224,0.9546,10,,,,,,,,,,,,,,,,,,,,,,,,,,,,,,,,,,,,,
269.792,0.35224,0.96877,10,,,,,,,,,,,,,,,,,,,,,,,,,,,,,,,,,,,,,
270.392,0.3523,1.02874,10,,,,,,,,,,,,,,,,,,,,,,,,,,,,,,,,,,,,,
270.992,0.3523,1.03908,10,,,,,,,,,,,,,,,,,,,,,,,,,,,,,,,,,,,,,
271.592,0.35218,1.06001,10,,,,,,,,,,,,,,,,,,,,,,,,,,,,,,,,,,,,,
272.192,0.35218,1.0219,10,,,,,,,,,,,,,,,,,,,,,,,,,,,,,,,,,,,,,
272.792,0.35224,0.99857,10,,,,,,,,,,,,,,,,,,,,,,,,,,,,,,,,,,,,,
273.392,0.3523,1.01802,10,,,,,,,,,,,,,,,,,,,,,,,,,,,,,,,,,,,,,
273.992,0.3523,1.01684,10,,,,,,,,,,,,,,,,,,,,,,,,,,,,,,,,,,,,,
274.592,0.3523,1.03873,10,,,,,,,,,,,,,,,,,,,,,,,,,,,,,,,,,,,,,
275.192,0.35235,1.03572,10,,,,,,,,,,,,,,,,,,,,,,,,,,,,,,,,,,,,,
275.792,0.35224,1.02291,10,,,,,,,,,,,,,,,,,,,,,,,,,,,,,,,,,,,,,
276.392,0.35235,1.00976,10,,,,,,,,,,,,,,,,,,,,,,,,,,,,,,,,,,,,,
276.992,0.35241,1.04515,10,,,,,,,,,,,,,,,,,,,,,,,,,,,,,,,,,,,,,
277.592,0.35241,1.04224,10,,,,,,,,,,,,,,,,,,,,,,,,,,,,,,,,,,,,,
278.192,0.35241,1.04065,10,,,,,,,,,,,,,,,,,,,,,,,,,,,,,,,,,,,,,
278.792,0.35241,1.03277,10,,,,,,,,,,,,,,,,,,,,,,,,,,,,,,,,,,,,,
279.392,0.3523,1.01834,10,,,,,,,,,,,,,,,,,,,,,,,,,,,,,,,,,,,,,
279.992,0.35241,1.04483,10,,,,,,,,,,,,,,,,,,,,,,,,,,,,,,,,,,,,,
280.592,0.3523,1.04987,10,,,,,,,,,,,,,,,,,,,,,,,,,,,,,,,,,,,,,
281.192,0.3523,1.04521,10,,,,,,,,,,,,,,,,,,,,,,,,,,,,,,,,,,,,,
281.792,0.3523,1.04231,10,,,,,,,,,,,,,,,,,,,,,,,,,,,,,,,,,,,,,
282.392,0.35241,1.02666,10,,,,,,,,,,,,,,,,,,,,,,,,,,,,,,,,,,,,,
282.992,0.35241,0.99125,10,,,,,,,,,,,,,,,,,,,,,,,,,,,,,,,,,,,,,
283.592,0.35241,1.03633,10,,,,,,,,,,,,,,,,,,,,,,,,,,,,,,,,,,,,,
284.192,0.35252,1.02385,10,,,,,,,,,,,,,,,,,,,,,,,,,,,,,,,,,,,,,
284.792,0.35258,1.03954,10,,,,,,,,,,,,,,,,,,,,,,,,,,,,,,,,,,,,,
285.392,0.35258,1.00604,10,,,,,,,,,,,,,,,,,,,,,,,,,,,,,,,,,,,,,
285.992,0.35264,0.96098,10,,,,,,,,,,,,,,,,,,,,,,,,,,,,,,,,,,,,,
286.592,0.35269,0.98476,10,,,,,,,,,,,,,,,,,,,,,,,,,,,,,,,,,,,,,
287.192,0.35309,0.98975,10,,,,,,,,,,,,,,,,,,,,,,,,,,,,,,,,,,,,,
287.792,0.35377,0.96199,10,,,,,,,,,,,,,,,,,,,,,,,,,,,,,,,,,,,,,
288.392,0.35502,1.0226,10,,,,,,,,,,,,,,,,,,,,,,,,,,,,,,,,,,,,,
288.992,0.35575,1.06903,10,,,,,,,,,,,,,,,,,,,,,,,,,,,,,,,,,,,,,
289.592,0.35587,1.12305,10,,,,,,,,,,,,,,,,,,,,,,,,,,,,,,,,,,,,,
290.192,0.3557,1.15379,10,,,,,,,,,,,,,,,,,,,,,,,,,,,,,,,,,,,,,
290.792,0.35564,1.07861,10,,,,,,,,,,,,,,,,,,,,,,,,,,,,,,,,,,,,,
291.392,0.35553,1.06036,10,,,,,,,,,,,,,,,,,,,,,,,,,,,,,,,,,,,,,
291.992,0.35541,1.06535,10,,,,,,,,,,,,,,,,,,,,,,,,,,,,,,,,,,,,,
292.592,0.35524,1.15099,10,,,,,,,,,,,,,,,,,,,,,,,,,,,,,,,,,,,,,
293.192,0.35456,1.08945,10,,,,,,,,,,,,,,,,,,,,,,,,,,,,,,,,,,,,,
293.792,0.35377,1.10614,10,,,,,,,,,,,,,,,,,,,,,,,,,,,,,,,,,,,,,
294.392,0.35303,1.03342,10,,,,,,,,,,,,,,,,,,,,,,,,,,,,,,,,,,,,,
294.992,0.35269,1.03168,10,,,,,,,,,,,,,,,,,,,,,,,,,,,,,,,,,,,,,
295.592,0.35235,1.0449,10,,,,,,,,,,,,,,,,,,,,,,,,,,,,,,,,,,,,,
296.192,0.3523,1.04664,10,,,,,,,,,,,,,,,,,,,,,,,,,,,,,,,,,,,,,
296.792,0.35241,0.97932,10,,,,,,,,,,,,,,,,,,,,,,,,,,,,,,,,,,,,,
297.392,0.35247,0.97949,10,,,,,,,,,,,,,,,,,,,,,,,,,,,,,,,,,,,,,
297.992,0.35252,0.95329,10,,,,,,,,,,,,,,,,,,,,,,,,,,,,,,,,,,,,,
298.592,0.35258,0.98136,10,,,,,,,,,,,,,,,,,,,,,,,,,,,,,,,,,,,,,
299.192,0.35264,1.07452,10,,,,,,,,,,,,,,,,,,,,,,,,,,,,,,,,,,,,,
299.792,0.35269,0.9659,10,,,,,,,,,,,,,,,,,,,,,,,,,,,,,,,,,,,,,
300.392,0.35275,1.02663,10,,,,,,,,,,,,,,,,,,,,,,,,,,,,,,,,,,,,,
300.992,0.35275,0.97161,10,,,,,,,,,,,,,,,,,,,,,,,,,,,,,,,,,,,,,
301.592,0.35292,1.01252,10,,,,,,,,,,,,,,,,,,,,,,,,,,,,,,,,,,,,,
302.192,0.3532,1.01168,10,,,,,,,,,,,,,,,,,,,,,,,,,,,,,,,,,,,,,
302.792,0.35366,0.98916,10,,,,,,,,,,,,,,,,,,,,,,,,,,,,,,,,,,,,,
303.392,0.35451,1.0314,10,,,,,,,,,,,,,,,,,,,,,,,,,,,,,,,,,,,,,
303.992,0.35536,0.99996,10,,,,,,,,,,,,,,,,,,,,,,,,,,,,,,,,,,,,,
304.592,0.35564,1.0205,10,,,,,,,,,,,,,,,,,,,,,,,,,,,,,,,,,,,,,
305.192,0.35581,1.12942,10,,,,,,,,,,,,,,,,,,,,,,,,,,,,,,,,,,,,,
305.792,0.35581,1.04352,10,,,,,,,,,,,,,,,,,,,,,,,,,,,,,,,,,,,,,
306.392,0.35581,1.0731,10,,,,,,,,,,,,,,,,,,,,,,,,,,,,,,,,,,,,,
306.992,0.3557,1.03887,10,,,,,,,,,,,,,,,,,,,,,,,,,,,,,,,,,,,,,
307.592,0.3557,1.04438,10,,,,,,,,,,,,,,,,,,,,,,,,,,,,,,,,,,,,,
308.192,0.35564,1.05706,10,,,,,,,,,,,,,,,,,,,,,,,,,,,,,,,,,,,,,
308.792,0.35564,1.05789,10,,,,,,,,,,,,,,,,,,,,,,,,,,,,,,,,,,,,,
309.392,0.35558,1.0726,10,,,,,,,,,,,,,,,,,,,,,,,,,,,,,,,,,,,,,
309.992,0.35558,1.02382,10,,,,,,,,,,,,,,,,,,,,,,,,,,,,,,,,,,,,,
310.592,0.35547,1.10172,10,,,,,,,,,,,,,,,,,,,,,,,,,,,,,,,,,,,,,
311.192,0.35547,1.12909,10,,,,,,,,,,,,,,,,,,,,,,,,,,,,,,,,,,,,,
311.792,0.35547,1.00732,10,,,,,,,,,,,,,,,,,,,,,,,,,,,,,,,,,,,,,
312.392,0.35541,1.08337,10,,,,,,,,,,,,,,,,,,,,,,,,,,,,,,,,,,,,,
312.992,0.35536,1.05398,10,,,,,,,,,,,,,,,,,,,,,,,,,,,,,,,,,,,,,
313.592,0.3553,1.07659,10,,,,,,,,,,,,,,,,,,,,,,,,,,,,,,,,,,,,,
314.192,0.35519,1.11565,10,,,,,,,,,,,,,,,,,,,,,,,,,,,,,,,,,,,,,
314.792,0.35502,1.05623,10,,,,,,,,,,,,,,,,,,,,,,,,,,,,,,,,,,,,,
315.392,0.35485,1.06467,10,,,,,,,,,,,,,,,,,,,,,,,,,,,,,,,,,,,,,
315.992,0.35473,1.05536,10,,,,,,,,,,,,,,,,,,,,,,,,,,,,,,,,,,,,,
316.592,0.35456,1.05814,10,,,,,,,,,,,,,,,,,,,,,,,,,,,,,,,,,,,,,
317.192,0.35451,1.05289,10,,,,,,,,,,,,,,,,,,,,,,,,,,,,,,,,,,,,,
317.792,0.35445,1.06679,10,,,,,,,,,,,,,,,,,,,,,,,,,,,,,,,,,,,,,
318.392,0.35439,1.04432,10,,,,,,,,,,,,,,,,,,,,,,,,,,,,,,,,,,,,,
318.992,0.35439,0.97031,10,,,,,,,,,,,,,,,,,,,,,,,,,,,,,,,,,,,,,
319.592,0.35445,1.02297,10,,,,,,,,,,,,,,,,,,,,,,,,,,,,,,,,,,,,,
320.192,0.35451,1.03468,10,,,,,,,,,,,,,,,,,,,,,,,,,,,,,,,,,,,,,
320.792,0.35456,1.0409,10,,,,,,,,,,,,,,,,,,,,,,,,,,,,,,,,,,,,,
321.392,0.35462,1.03166,10,,,,,,,,,,,,,,,,,,,,,,,,,,,,,,,,,,,,,
321.992,0.35468,1.05908,10,,,,,,,,,,,,,,,,,,,,,,,,,,,,,,,,,,,,,
322.592,0.35473,0.95094,10,,,,,,,,,,,,,,,,,,,,,,,,,,,,,,,,,,,,,
323.192,0.3549,0.97037,10,,,,,,,,,,,,,,,,,,,,,,,,,,,,,,,,,,,,,
323.792,0.35524,0.96145,10,,,,,,,,,,,,,,,,,,,,,,,,,,,,,,,,,,,,,
324.392,0.35581,0.92424,10,,,,,,,,,,,,,,,,,,,,,,,,,,,,,,,,,,,,,
324.992,0.35677,0.98203,10,,,,,,,,,,,,,,,,,,,,,,,,,,,,,,,,,,,,,
325.592,0.35785,1.04703,10,,,,,,,,,,,,,,,,,,,,,,,,,,,,,,,,,,,,,
326.192,0.3583,1.03087,10,,,,,,,,,,,,,,,,,,,,,,,,,,,,,,,,,,,,,
326.792,0.35847,1.09288,10,,,,,,,,,,,,,,,,,,,,,,,,,,,,,,,,,,,,,
327.392,0.35836,1.09058,10,,,,,,,,,,,,,,,,,,,,,,,,,,,,,,,,,,,,,
327.992,0.3583,1.06438,10,,,,,,,,,,,,,,,,,,,,,,,,,,,,,,,,,,,,,
328.592,0.35819,1.09796,10,,,,,,,,,,,,,,,,,,,,,,,,,,,,,,,,,,,,,
329.192,0.35819,1.0331,10,,,,,,,,,,,,,,,,,,,,,,,,,,,,,,,,,,,,,
329.792,0.35808,1.11534,10,,,,,,,,,,,,,,,,,,,,,,,,,,,,,,,,,,,,,
330.392,0.35802,1.05921,10,,,,,,,,,,,,,,,,,,,,,,,,,,,,,,,,,,,,,
330.992,0.35796,1.04766,10,,,,,,,,,,,,,,,,,,,,,,,,,,,,,,,,,,,,,
331.592,0.35774,1.13007,10,,,,,,,,,,,,,,,,,,,,,,,,,,,,,,,,,,,,,
332.192,0.35734,1.06835,10,,,,,,,,,,,,,,,,,,,,,,,,,,,,,,,,,,,,,
332.792,0.35677,1.0557,10,,,,,,,,,,,,,,,,,,,,,,,,,,,,,,,,,,,,,
333.392,0.35632,1.01181,10,,,,,,,,,,,,,,,,,,,,,,,,,,,,,,,,,,,,,
333.992,0.35609,0.98647,10,,,,,,,,,,,,,,,,,,,,,,,,,,,,,,,,,,,,,
334.592,0.35592,1.0559,10,,,,,,,,,,,,,,,,,,,,,,,,,,,,,,,,,,,,,
335.192,0.35587,0.96606,10,,,,,,,,,,,,,,,,,,,,,,,,,,,,,,,,,,,,,
335.792,0.35598,1.00451,10,,,,,,,,,,,,,,,,,,,,,,,,,,,,,,,,,,,,,
336.392,0.35598,1.02454,10,,,,,,,,,,,,,,,,,,,,,,,,,,,,,,,,,,,,,
336.992,0.35598,1.03041,10,,,,,,,,,,,,,,,,,,,,,,,,,,,,,,,,,,,,,
337.592,0.35609,1.02341,10,,,,,,,,,,,,,,,,,,,,,,,,,,,,,,,,,,,,,
338.192,0.35615,0.97123,10,,,,,,,,,,,,,,,,,,,,,,,,,,,,,,,,,,,,,
338.792,0.35626,0.97001,10,,,,,,,,,,,,,,,,,,,,,,,,,,,,,,,,,,,,,
339.392,0.35632,0.96791,10,,,,,,,,,,,,,,,,,,,,,,,,,,,,,,,,,,,,,
339.992,0.35655,0.96963,10,,,,,,,,,,,,,,,,,,,,,,,,,,,,,,,,,,,,,
340.592,0.35689,0.99097,10,,,,,,,,,,,,,,,,,,,,,,,,,,,,,,,,,,,,,
341.192,0.35762,1.02524,10,,,,,,,,,,,,,,,,,,,,,,,,,,,,,,,,,,,,,
341.792,0.35813,1.0013,10,,,,,,,,,,,,,,,,,,,,,,,,,,,,,,,,,,,,,
342.392,0.35842,0.9939,10,,,,,,,,,,,,,,,,,,,,,,,,,,,,,,,,,,,,,
342.992,0.35876,1.01085,10,,,,,,,,,,,,,,,,,,,,,,,,,,,,,,,,,,,,,
343.592,0.35893,1.03566,10,,,,,,,,,,,,,,,,,,,,,,,,,,,,,,,,,,,,,
344.192,0.35898,1.10723,10,,,,,,,,,,,,,,,,,,,,,,,,,,,,,,,,,,,,,
344.792,0.35893,1.06385,10,,,,,,,,,,,,,,,,,,,,,,,,,,,,,,,,,,,,,
345.392,0.35887,1.08763,10,,,,,,,,,,,,,,,,,,,,,,,,,,,,,,,,,,,,,
345.992,0.35876,1.01385,10,,,,,,,,,,,,,,,,,,,,,,,,,,,,,,,,,,,,,
346.592,0.3587,1.08018,10,,,,,,,,,,,,,,,,,,,,,,,,,,,,,,,,,,,,,
347.192,0.35859,1.04775,10,,,,,,,,,,,,,,,,,,,,,,,,,,,,,,,,,,,,,
347.792,0.35859,1.04269,10,,,,,,,,,,,,,,,,,,,,,,,,,,,,,,,,,,,,,
348.392,0.35853,1.04055,10,,,,,,,,,,,,,,,,,,,,,,,,,,,,,,,,,,,,,
348.992,0.35853,1.04457,10,,,,,,,,,,,,,,,,,,,,,,,,,,,,,,,,,,,,,
349.592,0.35842,1.06577,10,,,,,,,,,,,,,,,,,,,,,,,,,,,,,,,,,,,,,
350.192,0.3583,1.08296,10,,,,,,,,,,,,,,,,,,,,,,,,,,,,,,,,,,,,,
350.792,0.35825,1.04513,10,,,,,,,,,,,,,,,,,,,,,,,,,,,,,,,,,,,,,
351.392,0.35825,1.08259,10,,,,,,,,,,,,,,,,,,,,,,,,,,,,,,,,,,,,,
351.992,0.35819,1.03457,10,,,,,,,,,,,,,,,,,,,,,,,,,,,,,,,,,,,,,
352.592,0.35808,1.05883,10,,,,,,,,,,,,,,,,,,,,,,,,,,,,,,,,,,,,,
353.192,0.35796,1.05677,10,,,,,,,,,,,,,,,,,,,,,,,,,,,,,,,,,,,,,
353.792,0.35791,0.98355,10,,,,,,,,,,,,,,,,,,,,,,,,,,,,,,,,,,,,,
354.392,0.35791,1.00589,10,,,,,,,,,,,,,,,,,,,,,,,,,,,,,,,,,,,,,
354.992,0.35791,1.06244,10,,,,,,,,,,,,,,,,,,,,,,,,,,,,,,,,,,,,,
355.592,0.35791,1.02812,10,,,,,,,,,,,,,,,,,,,,,,,,,,,,,,,,,,,,,
356.192,0.35802,1.00589,10,,,,,,,,,,,,,,,,,,,,,,,,,,,,,,,,,,,,,
356.792,0.35802,1.00304,10,,,,,,,,,,,,,,,,,,,,,,,,,,,,,,,,,,,,,
357.392,0.35808,1.02149,10,,,,,,,,,,,,,,,,,,,,,,,,,,,,,,,,,,,,,
357.992,0.35813,1.01143,10,,,,,,,,,,,,,,,,,,,,,,,,,,,,,,,,,,,,,
358.592,0.35813,1.04532,10,,,,,,,,,,,,,,,,,,,,,,,,,,,,,,,,,,,,,
359.192,0.35819,1.01702,10,,,,,,,,,,,,,,,,,,,,,,,,,,,,,,,,,,,,,
359.792,0.35825,1.02114,10,,,,,,,,,,,,,,,,,,,,,,,,,,,,,,,,,,,,,
360.392,0.35836,0.97672,10,,,,,,,,,,,,,,,,,,,,,,,,,,,,,,,,,,,,,
360.992,0.35853,0.97754,10,,,,,,,,,,,,,,,,,,,,,,,,,,,,,,,,,,,,,
361.592,0.35887,1.00334,10,,,,,,,,,,,,,,,,,,,,,,,,,,,,,,,,,,,,,
362.192,0.35921,1.00878,10,,,,,,,,,,,,,,,,,,,,,,,,,,,,,,,,,,,,,
362.792,0.35972,1.03778,10,,,,,,,,,,,,,,,,,,,,,,,,,,,,,,,,,,,,,
363.392,0.36034,1.03051,10,,,,,,,,,,,,,,,,,,,,,,,,,,,,,,,,,,,,,
363.992,0.36068,1.03229,10,,,,,,,,,,,,,,,,,,,,,,,,,,,,,,,,,,,,,
364.592,0.36085,1.0967,10,,,,,,,,,,,,,,,,,,,,,,,,,,,,,,,,,,,,,
365.192,0.36074,1.10799,10,,,,,,,,,,,,,,,,,,,,,,,,,,,,,,,,,,,,,
365.792,0.36068,1.06356,10,,,,,,,,,,,,,,,,,,,,,,,,,,,,,,,,,,,,,
366.392,0.36063,1.11011,10,,,,,,,,,,,,,,,,,,,,,,,,,,,,,,,,,,,,,
366.992,0.36057,1.0726,10,,,,,,,,,,,,,,,,,,,,,,,,,,,,,,,,,,,,,
367.592,0.36046,1.11397,10,,,,,,,,,,,,,,,,,,,,,,,,,,,,,,,,,,,,,
368.192,0.3604,1.02782,10,,,,,,,,,,,,,,,,,,,,,,,,,,,,,,,,,,,,,
368.792,0.36029,1.06565,10,,,,,,,,,,,,,,,,,,,,,,,,,,,,,,,,,,,,,
369.392,0.36006,1.09377,10,,,,,,,,,,,,,,,,,,,,,,,,,,,,,,,,,,,,,
369.992,0.35972,1.05639,10,,,,,,,,,,,,,,,,,,,,,,,,,,,,,,,,,,,,,
370.592,0.35932,1.07917,10,,,,,,,,,,,,,,,,,,,,,,,,,,,,,,,,,,,,,
371.192,0.35898,1.05869,10,,,,,,,,,,,,,,,,,,,,,,,,,,,,,,,,,,,,,
371.792,0.35864,0.99149,10,,,,,,,,,,,,,,,,,,,,,,,,,,,,,,,,,,,,,
372.392,0.35853,1.00789,10,,,,,,,,,,,,,,,,,,,,,,,,,,,,,,,,,,,,,
372.992,0.35847,0.95039,10,,,,,,,,,,,,,,,,,,,,,,,,,,,,,,,,,,,,,
373.592,0.35859,0.9962,10,,,,,,,,,,,,,,,,,,,,,,,,,,,,,,,,,,,,,
374.192,0.35864,1.00693,10,,,,,,,,,,,,,,,,,,,,,,,,,,,,,,,,,,,,,
374.792,0.3587,0.95411,10,,,,,,,,,,,,,,,,,,,,,,,,,,,,,,,,,,,,,
375.392,0.35881,1.06204,10,,,,,,,,,,,,,,,,,,,,,,,,,,,,,,,,,,,,,
375.992,0.35881,1.03931,10,,,,,,,,,,,,,,,,,,,,,,,,,,,,,,,,,,,,,
376.592,0.35887,1.03519,10,,,,,,,,,,,,,,,,,,,,,,,,,,,,,,,,,,,,,
377.192,0.35898,0.963,10,,,,,,,,,,,,,,,,,,,,,,,,,,,,,,,,,,,,,
377.792,0.3591,1.0305,10,,,,,,,,,,,,,,,,,,,,,,,,,,,,,,,,,,,,,
378.392,0.35938,0.9746,10,,,,,,,,,,,,,,,,,,,,,,,,,,,,,,,,,,,,,
378.992,0.35972,0.99136,10,,,,,,,,,,,,,,,,,,,,,,,,,,,,,,,,,,,,,
379.592,0.35989,1.03616,10,,,,,,,,,,,,,,,,,,,,,,,,,,,,,,,,,,,,,
380.192,0.36,1.05331,10,,,,,,,,,,,,,,,,,,,,,,,,,,,,,,,,,,,,,
380.792,0.36,0.99166,10,,,,,,,,,,,,,,,,,,,,,,,,,,,,,,,,,,,,,
381.392,0.35989,1.00365,10,,,,,,,,,,,,,,,,,,,,,,,,,,,,,,,,,,,,,
381.992,0.35983,1.06938,10,,,,,,,,,,,,,,,,,,,,,,,,,,,,,,,,,,,,,
382.592,0.35983,1.02633,10,,,,,,,,,,,,,,,,,,,,,,,,,,,,,,,,,,,,,
383.192,0.35989,1.09063,10,,,,,,,,,,,,,,,,,,,,,,,,,,,,,,,,,,,,,
383.792,0.35978,1.06046,10,,,,,,,,,,,,,,,,,,,,,,,,,,,,,,,,,,,,,
384.392,0.35972,1.03058,10,,,,,,,,,,,,,,,,,,,,,,,,,,,,,,,,,,,,,
384.992,0.35972,1.03866,10,,,,,,,,,,,,,,,,,,,,,,,,,,,,,,,,,,,,,
385.592,0.35966,1.08281,10,,,,,,,,,,,,,,,,,,,,,,,,,,,,,,,,,,,,,
386.192,0.35966,1.04715,10,,,,,,,,,,,,,,,,,,,,,,,,,,,,,,,,,,,,,
386.792,0.35961,1.01032,10,,,,,,,,,,,,,,,,,,,,,,,,,,,,,,,,,,,,,
387.392,0.35961,1.04764,10,,,,,,,,,,,,,,,,,,,,,,,,,,,,,,,,,,,,,
387.992,0.35966,1.03108,10,,,,,,,,,,,,,,,,,,,,,,,,,,,,,,,,,,,,,
388.592,0.35955,1.07844,10,,,,,,,,,,,,,,,,,,,,,,,,,,,,,,,,,,,,,
389.192,0.35955,1.011,10,,,,,,,,,,,,,,,,,,,,,,,,,,,,,,,,,,,,,
389.792,0.35955,1.03866,10,,,,,,,,,,,,,,,,,,,,,,,,,,,,,,,,,,,,,
390.392,0.35955,1.03895,10,,,,,,,,,,,,,,,,,,,,,,,,,,,,,,,,,,,,,
390.992,0.35955,1.03662,10,,,,,,,,,,,,,,,,,,,,,,,,,,,,,,,,,,,,,
391.592,0.35955,1.01421,10,,,,,,,,,,,,,,,,,,,,,,,,,,,,,,,,,,,,,
392.192,0.35955,1.0209,10,,,,,,,,,,,,,,,,,,,,,,,,,,,,,,,,,,,,,
392.792,0.35955,1.02508,10,,,,,,,,,,,,,,,,,,,,,,,,,,,,,,,,,,,,,
393.392,0.35955,0.99553,10,,,,,,,,,,,,,,,,,,,,,,,,,,,,,,,,,,,,,
393.992,0.35966,0.98406,10,,,,,,,,,,,,,,,,,,,,,,,,,,,,,,,,,,,,,
394.592,0.35966,1.01447,10,,,,,,,,,,,,,,,,,,,,,,,,,,,,,,,,,,,,,
395.192,0.35966,1.05958,10,,,,,,,,,,,,,,,,,,,,,,,,,,,,,,,,,,,,,
395.792,0.35972,0.98417,10,,,,,,,,,,,,,,,,,,,,,,,,,,,,,,,,,,,,,
396.392,0.35983,1.05969,10,,,,,,,,,,,,,,,,,,,,,,,,,,,,,,,,,,,,,
396.992,0.35989,0.95771,10,,,,,,,,,,,,,,,,,,,,,,,,,,,,,,,,,,,,,
397.494,3.55986,300.66083,10,,,,,,,,,,,,,,,,,,,,,,,,,,,,,,,,,,,,,
398.094,8.5599,1121.87878,10,,,,,,,,,,,,,,,,,,,,,,,,,,,,,,,,,,,,,
398.694,13.56005,905.43799,10,,,,,,,,,,,,,,,,,,,,,,,,,,,,,,,,,,,,,
399.294,18.55992,27.9544,10,,,,,,,,,,,,,,,,,,,,,,,,,,,,,,,,,,,,,
399.894,23.5599,5.83953,10,,,,,,,,,,,,,,,,,,,,,,,,,,,,,,,,,,,,,
400.494,28.55988,2.61233,10,,,,,,,,,,,,,,,,,,,,,,,,,,,,,,,,,,,,,
401.094,33.55992,-2.80338,10,,,,,,,,,,,,,,,,,,,,,,,,,,,,,,,,,,,,,
401.694,38.55985,-11.51357,10,,,,,,,,,,,,,,,,,,,,,,,,,,,,,,,,,,,,,
402.294,43.55989,-11.87487,10,,,,,,,,,,,,,,,,,,,,,,,,,,,,,,,,,,,,,
402.894,48.55993,-11.96232,10,,,,,,,,,,,,,,,,,,,,,,,,,,,,,,,,,,,,,
403.494,53.55997,-12.01105,10,,,,,,,,,,,,,,,,,,,,,,,,,,,,,,,,,,,,,
404.094,58.56001,-11.94346,10,,,,,,,,,,,,,,,,,,,,,,,,,,,,,,,,,,,,,
404.684,63.47658,-12.01963,10,,,,,,,,,,,,,,,,,,,,,,,,,,,,,,,,,,,,,