File: combined_ligament_solver/data/processed/Data Sheet 3_S160134_LCL.csv
Specimen properties : Length,55,mm,Unnamed: 3,Unnamed: 4,Unnamed: 5,Unnamed: 6,Unnamed: 7,Unnamed: 8,Unnamed: 9,Unnamed: 10,Unnamed: 11,Stress-Strain,Unnamed: 13,Unnamed: 14,Unnamed: 15,Unnamed: 16,Unnamed: 17,Unnamed: 18,Unnamed: 19,Unnamed: 20,Unnamed: 21,Unnamed: 22,Unnamed: 23,Unnamed: 24,Unnamed: 25,Unnamed: 26,Unnamed: 27,Linear,Unnamed: 29,Unnamed: 30,Unnamed: 31,Unnamed: 32,Unnamed: 33,Modulus,Unnamed: 35,Failure,Unnamed: 37,Unnamed: 38,Unnamed: 39,Unnamed: 40
Cross Section Average,71.748,mm2,,,,,,,,,,Polynomial Coefficients,,,,,,,,,,,,,,,,Force,,Stress,Extension,Strain,,Secant,Tangent,Load,Stress,Extension,Strain,Stiffness
Time,Extension,Load,Total cycle count,,,Extension,Load,Strain,Stress,E-tan,,X6,962802.0774391623,,,,,,,,,Strain,Stress,E-tan,,,,(N),,(MPa),(mm),(%),,(MPa),(MPa),(N),(MPa),(mm),(%),(N/mm)
(s),(mm),(N),,,,(mm),(N),(mm/mm),(MPa),(MPa),,X5,-435666.4459794146,,,,,,,,,(mm/mm),(MPa),(MPa),,,,260.45628524575125,,3.6301539449984843,6.16,11.200000000000001,,32.41208879462933,51.90592823616619,479.7262,6.676294112727881,9.80005,17.818272727272728,42.281864487946635
0.6,0.18643,2.18556,0,,,6.21883,174.87137,0.08727290909090908,2.4273278697664047,45.803880346197964,,,,,,,,,,,,0.006,0.04189378723828538,8.614902802654735,,,,,,,,,,,,,,,,
1.3,0.30311,3.43189,0,,,12.05226,463.83405,,,,,,,,,,,,,,,0.013,0.11836236649777751,12.559093503351056,,,,,,,,,,,,,,,,
2,0.41984,4.80957,0,,,17.88553,229.66257,,,,,,,,,,,,,,,0.02,0.2202326957363714,15.999099006831536,,,,,,,,,,,,,,,,
2.7,0.53658,6.2885,0,,,23.71879,37.30125,,,,,,,,,,,,,,,0.027,0.34516701994210763,19.21867700193423,,,,,,,,,,,,,,,,
3.4,0.65325,7.84988,0,,,,,,,,,,,,,,,,,,,0.034,0.49243495778457297,22.408517057624405,,,,,,,,,,,,,,,,
4.1,0.76999,9.50402,0,,,,,,,,,,,,,,,,,,,0.041,0.6623086284015931,25.677891529445304,,,,,,,,,,,,,,,,
4.8,0.88661,11.31888,0,,,,,,,,,,,,,,,,,,,0.048,0.8555393345310849,29.066306465969497,,,,,,,,,,,,,,,,
5.5,1.00328,13.17786,0,,,,,,,,,,,,,,,,,,,0.055,1.0729158019880658,32.555152515250064,,,,,,,,,,,,,,,,
6.2,1.12002,15.11131,0,,,,,,,,,,,,,,,,,,,0.062,1.3149039754868233,36.07935583127172,,,,,,,,,,,,,,,,
6.9,1.23669,17.13271,0,,,,,,,,,,,,,,,,,,,0.069,1.581368370808239,39.53902898040247,,,,,,,,,,,,,,,,
7.6,1.35326,19.23394,0,,,,,,,,,,,,,,,,,,,0.076,1.8713749833122746,42.81112184784282,,,,,,,,,,,,,,,,
8.3,1.46988,21.46491,0,,,,,,,,,,,,,,,,,,,0.083,2.1830757527956166,45.76107254408109,,,,,,,,,,,,,,,,
9,1.58655,23.64612,0,,,,,,,,,,,,,,,,,,,0.09,2.513674584694471,48.25445831133864,,,,,,,,,,,,,,,,
9.7,1.70329,26.00156,0,,,,,,,,,,,,,,,,,,,0.097,2.859474927632533,50.16864643002833,,,,,,,,,,,,,,,,
10.4,1.81991,28.27218,0,,,,,,,,,,,,,,,,,,,0.104,3.216008907314092,51.40444512519777,,,,,,,,,,,,,,,,
11.1,1.93653,24.92135,0,,,,,,,,,,,,,,,,,,,0.111,3.578248016762318,51.89775447298656,,,,,,,,,,,,,,,,
11.8,2.05315,26.62784,0,,,,,,,,,,,,,,,,,,,0.118,3.940895362902689,51.631217307077435,,,,,,,,,,,,,,,,
12.5,2.16988,28.73192,0,,,,,,,,,,,,,,,,,,,0.125,4.2987594694915865,50.645870125139275,,,,,,,,,,,,,,,,
13.2,2.28656,30.81364,0,,,,,,,,,,,,,,,,,,,0.132,4.647209636390042,49.052793995291346,,,,,,,,,,,,,,,,
13.9,2.40318,32.442,0,,,,,,,,,,,,,,,,,,,0.139,4.982712855182653,47.044765462540056,,,,,,,,,,,,,,,,
14.6,2.51991,34.61013,0,,,,,,,,,,,,,,,,,,,0.146,5.3034522811416345,44.90790745524005,,,,,,,,,,,,,,,,
15.3,2.63659,36.96487,0,,,,,,,,,,,,,,,,,,,0.153,5.610027261536073,43.03334019155787,,,,,,,,,,,,,,,,
16,2.75326,39.6308,0,,,,,,,,,,,,,,,,,,,0.16,5.906234920286268,41.92883208587701,,,,,,,,,,,,,,,,
16.522,2.70668,36.72407,0.5,,,,,,,,,,,,,,,,,,,0.167,6.199933298963331,42.23045065532279,,,,,,,,,,,,,,,,
17.222,2.59006,31.63108,0.5,,,,,,,,,,,,,,,,,,,0.174,,,,,,,,,,,,,,,,,,
17.922,2.47333,27.44517,0.5,,,,,,,,,,,,,,,,,,,0.181,,,,,,,,,,,,,,,,,,
18.622,2.3566,23.86465,0.5,,,,,,,,,,,,,,,,,,,0.188,,,,,,,,,,,,,,,,,,
19.322,2.23986,20.64208,0.5,,,,,,,,,,,,,,,,,,,0.195,,,,,,,,,,,,,,,,,,
20.022,2.12319,17.83661,0.5,,,,,,,,,,,,,,,,,,,,,,,,,,,,,,,,,,,,,
20.722,2.00651,15.45532,0.5,,,,,,,,,,,,,,,,,,,,,,,,,,,,,,,,,,,,,
21.422,1.88983,13.03976,0.5,,,,,,,,,,,,,,,,,,,,,,,,,,,,,,,,,,,,,
22.122,1.77316,10.99694,0.5,,,,,,,,,,,,,,,,,,,,,,,,,,,,,,,,,,,,,
22.822,1.65654,9.07397,0.5,,,,,,,,,,,,,,,,,,,,,,,,,,,,,,,,,,,,,
23.522,1.53992,7.32469,0.5,,,,,,,,,,,,,,,,,,,,,,,,,,,,,,,,,,,,,
24.222,1.4233,5.72071,0.5,,,,,,,,,,,,,,,,,,,,,,,,,,,,,,,,,,,,,
24.922,1.30662,4.2161,0.5,,,,,,,,,,,,,,,,,,,,,,,,,,,,,,,,,,,,,
25.622,1.19,2.84199,0.5,,,,,,,,,,,,,,,,,,,,,,,,,,,,,,,,,,,,,
26.322,1.07327,1.67863,0.5,,,,,,,,,,,,,,,,,,,,,,,,,,,,,,,,,,,,,
26.768,0.99892,0.99804,1,,,,,,,,,,,,,,,,,,,,,,,,,,,,,,,,,,,,,
27.468,1.11667,2.37161,1,,,,,,,,,,,,,,,,,,,,,,,,,,,,,,,,,,,,,
28.168,1.23324,3.92392,1,,,,,,,,,,,,,,,,,,,,,,,,,,,,,,,,,,,,,
28.868,1.34991,5.55776,1,,,,,,,,,,,,,,,,,,,,,,,,,,,,,,,,,,,,,
29.568,1.46659,7.33422,1,,,,,,,,,,,,,,,,,,,,,,,,,,,,,,,,,,,,,
30.268,1.58327,9.16287,1,,,,,,,,,,,,,,,,,,,,,,,,,,,,,,,,,,,,,
30.968,1.69994,11.17884,1,,,,,,,,,,,,,,,,,,,,,,,,,,,,,,,,,,,,,
31.668,1.81651,13.30403,1,,,,,,,,,,,,,,,,,,,,,,,,,,,,,,,,,,,,,
32.368,1.93318,15.61632,1,,,,,,,,,,,,,,,,,,,,,,,,,,,,,,,,,,,,,
33.068,2.04986,17.86261,1,,,,,,,,,,,,,,,,,,,,,,,,,,,,,,,,,,,,,
33.768,2.16659,20.4048,1,,,,,,,,,,,,,,,,,,,,,,,,,,,,,,,,,,,,,
34.468,2.28321,23.09605,1,,,,,,,,,,,,,,,,,,,,,,,,,,,,,,,,,,,,,
35.168,2.39983,25.92252,1,,,,,,,,,,,,,,,,,,,,,,,,,,,,,,,,,,,,,
35.868,2.51651,29.06078,1,,,,,,,,,,,,,,,,,,,,,,,,,,,,,,,,,,,,,
36.568,2.63319,32.31097,1,,,,,,,,,,,,,,,,,,,,,,,,,,,,,,,,,,,,,
37.268,2.74986,35.71861,1,,,,,,,,,,,,,,,,,,,,,,,,,,,,,,,,,,,,,
37.968,2.86665,39.21712,1,,,,,,,,,,,,,,,,,,,,,,,,,,,,,,,,,,,,,
38.552,2.83039,36.90039,1.5,,,,,,,,,,,,,,,,,,,,,,,,,,,,,,,,,,,,,
39.252,2.71365,31.93584,1.5,,,,,,,,,,,,,,,,,,,,,,,,,,,,,,,,,,,,,
39.952,2.59698,27.8143,1.5,,,,,,,,,,,,,,,,,,,,,,,,,,,,,,,,,,,,,
40.652,2.4803,24.18037,1.5,,,,,,,,,,,,,,,,,,,,,,,,,,,,,,,,,,,,,
41.352,2.36368,20.95374,1.5,,,,,,,,,,,,,,,,,,,,,,,,,,,,,,,,,,,,,
42.052,2.24695,18.107,1.5,,,,,,,,,,,,,,,,,,,,,,,,,,,,,,,,,,,,,
42.752,2.13027,15.57883,1.5,,,,,,,,,,,,,,,,,,,,,,,,,,,,,,,,,,,,,
43.452,2.01354,13.26006,1.5,,,,,,,,,,,,,,,,,,,,,,,,,,,,,,,,,,,,,
44.152,1.89686,11.166,1.5,,,,,,,,,,,,,,,,,,,,,,,,,,,,,,,,,,,,,
44.852,1.78024,9.22105,1.5,,,,,,,,,,,,,,,,,,,,,,,,,,,,,,,,,,,,,
45.552,1.66356,7.5168,1.5,,,,,,,,,,,,,,,,,,,,,,,,,,,,,,,,,,,,,
46.252,1.54677,5.78771,1.5,,,,,,,,,,,,,,,,,,,,,,,,,,,,,,,,,,,,,
46.952,1.43015,4.31039,1.5,,,,,,,,,,,,,,,,,,,,,,,,,,,,,,,,,,,,,
47.652,1.31353,2.93009,1.5,,,,,,,,,,,,,,,,,,,,,,,,,,,,,,,,,,,,,
48.352,1.19691,1.73798,1.5,,,,,,,,,,,,,,,,,,,,,,,,,,,,,,,,,,,,,
48.83,1.1173,0.99112,2,,,,,,,,,,,,,,,,,,,,,,,,,,,,,,,,,,,,,
49.53,1.23494,2.37823,2,,,,,,,,,,,,,,,,,,,,,,,,,,,,,,,,,,,,,
50.23,1.35156,3.9507,2,,,,,,,,,,,,,,,,,,,,,,,,,,,,,,,,,,,,,
50.93,1.46818,5.56747,2,,,,,,,,,,,,,,,,,,,,,,,,,,,,,,,,,,,,,
51.63,1.58491,7.32187,2,,,,,,,,,,,,,,,,,,,,,,,,,,,,,,,,,,,,,
52.33,1.70159,9.20301,2,,,,,,,,,,,,,,,,,,,,,,,,,,,,,,,,,,,,,
53.03,1.81821,11.26711,2,,,,,,,,,,,,,,,,,,,,,,,,,,,,,,,,,,,,,
53.73,1.93483,13.45038,2,,,,,,,,,,,,,,,,,,,,,,,,,,,,,,,,,,,,,
54.43,2.0515,15.70838,2,,,,,,,,,,,,,,,,,,,,,,,,,,,,,,,,,,,,,
55.13,2.16824,18.07642,2,,,,,,,,,,,,,,,,,,,,,,,,,,,,,,,,,,,,,
55.83,2.28491,20.71654,2,,,,,,,,,,,,,,,,,,,,,,,,,,,,,,,,,,,,,
56.53,2.40159,23.49701,2,,,,,,,,,,,,,,,,,,,,,,,,,,,,,,,,,,,,,
57.23,2.51815,26.50703,2,,,,,,,,,,,,,,,,,,,,,,,,,,,,,,,,,,,,,
57.93,2.63489,29.75949,2,,,,,,,,,,,,,,,,,,,,,,,,,,,,,,,,,,,,,
58.63,2.75156,33.23603,2,,,,,,,,,,,,,,,,,,,,,,,,,,,,,,,,,,,,,
59.33,2.86835,36.8414,2,,,,,,,,,,,,,,,,,,,,,,,,,,,,,,,,,,,,,
59.926,2.96752,40.02818,2.5,,,,,,,,,,,,,,,,,,,,,,,,,,,,,,,,,,,,,
60.626,2.85056,34.66938,2.5,,,,,,,,,,,,,,,,,,,,,,,,,,,,,,,,,,,,,
61.326,2.73388,30.19564,2.5,,,,,,,,,,,,,,,,,,,,,,,,,,,,,,,,,,,,,
62.026,2.61726,26.21063,2.5,,,,,,,,,,,,,,,,,,,,,,,,,,,,,,,,,,,,,
62.726,2.50059,22.74219,2.5,,,,,,,,,,,,,,,,,,,,,,,,,,,,,,,,,,,,,
63.426,2.38397,19.70389,2.5,,,,,,,,,,,,,,,,,,,,,,,,,,,,,,,,,,,,,
64.126,2.26729,16.92157,2.5,,,,,,,,,,,,,,,,,,,,,,,,,,,,,,,,,,,,,
64.826,2.15067,14.4332,2.5,,,,,,,,,,,,,,,,,,,,,,,,,,,,,,,,,,,,,
65.526,2.03394,12.21316,2.5,,,,,,,,,,,,,,,,,,,,,,,,,,,,,,,,,,,,,
66.226,1.91726,10.25981,2.5,,,,,,,,,,,,,,,,,,,,,,,,,,,,,,,,,,,,,
66.926,1.80058,8.42548,2.5,,,,,,,,,,,,,,,,,,,,,,,,,,,,,,,,,,,,,
67.626,1.68402,6.67776,2.5,,,,,,,,,,,,,,,,,,,,,,,,,,,,,,,,,,,,,
68.326,1.56729,5.12191,2.5,,,,,,,,,,,,,,,,,,,,,,,,,,,,,,,,,,,,,
69.026,1.45055,3.68271,2.5,,,,,,,,,,,,,,,,,,,,,,,,,,,,,,,,,,,,,
69.726,1.33388,2.3455,2.5,,,,,,,,,,,,,,,,,,,,,,,,,,,,,,,,,,,,,
70.426,1.2172,1.19041,2.5,,,,,,,,,,,,,,,,,,,,,,,,,,,,,,,,,,,,,
70.84,1.24916,1.58369,3,,,,,,,,,,,,,,,,,,,,,,,,,,,,,,,,,,,,,
71.54,1.36589,3.0384,3,,,,,,,,,,,,,,,,,,,,,,,,,,,,,,,,,,,,,
72.24,1.48251,4.65249,3,,,,,,,,,,,,,,,,,,,,,,,,,,,,,,,,,,,,,
72.94,1.59913,6.39531,3,,,,,,,,,,,,,,,,,,,,,,,,,,,,,,,,,,,,,
73.64,1.71587,8.21429,3,,,,,,,,,,,,,,,,,,,,,,,,,,,,,,,,,,,,,
74.34,1.83254,10.23159,3,,,,,,,,,,,,,,,,,,,,,,,,,,,,,,,,,,,,,
75.04,1.94916,12.35147,3,,,,,,,,,,,,,,,,,,,,,,,,,,,,,,,,,,,,,
75.74,2.06584,14.54582,3,,,,,,,,,,,,,,,,,,,,,,,,,,,,,,,,,,,,,
76.44,2.18257,16.91558,3,,,,,,,,,,,,,,,,,,,,,,,,,,,,,,,,,,,,,
77.14,2.29925,19.44572,3,,,,,,,,,,,,,,,,,,,,,,,,,,,,,,,,,,,,,
77.84,2.41598,22.18516,3,,,,,,,,,,,,,,,,,,,,,,,,,,,,,,,,,,,,,
78.54,2.53272,25.11044,3,,,,,,,,,,,,,,,,,,,,,,,,,,,,,,,,,,,,,
79.24,2.64934,28.32685,3,,,,,,,,,,,,,,,,,,,,,,,,,,,,,,,,,,,,,
79.94,2.76596,31.68179,3,,,,,,,,,,,,,,,,,,,,,,,,,,,,,,,,,,,,,
80.64,2.88258,35.24507,3,,,,,,,,,,,,,,,,,,,,,,,,,,,,,,,,,,,,,
81.34,2.99925,38.823,3,,,,,,,,,,,,,,,,,,,,,,,,,,,,,,,,,,,,,
81.878,2.98877,37.59672,3.5,,,,,,,,,,,,,,,,,,,,,,,,,,,,,,,,,,,,,
82.578,2.87204,32.44434,3.5,,,,,,,,,,,,,,,,,,,,,,,,,,,,,,,,,,,,,
83.278,2.75536,28.15988,3.5,,,,,,,,,,,,,,,,,,,,,,,,,,,,,,,,,,,,,
83.978,2.63857,24.42038,3.5,,,,,,,,,,,,,,,,,,,,,,,,,,,,,,,,,,,,,
84.678,2.52184,21.12397,3.5,,,,,,,,,,,,,,,,,,,,,,,,,,,,,,,,,,,,,
85.378,2.40522,18.19905,3.5,,,,,,,,,,,,,,,,,,,,,,,,,,,,,,,,,,,,,
86.078,2.28848,15.52351,3.5,,,,,,,,,,,,,,,,,,,,,,,,,,,,,,,,,,,,,
86.778,2.17186,13.17629,3.5,,,,,,,,,,,,,,,,,,,,,,,,,,,,,,,,,,,,,
87.478,2.05513,11.12718,3.5,,,,,,,,,,,,,,,,,,,,,,,,,,,,,,,,,,,,,
88.178,1.93857,9.1716,3.5,,,,,,,,,,,,,,,,,,,,,,,,,,,,,,,,,,,,,
88.878,1.82195,7.43281,3.5,,,,,,,,,,,,,,,,,,,,,,,,,,,,,,,,,,,,,
89.578,1.70527,5.80801,3.5,,,,,,,,,,,,,,,,,,,,,,,,,,,,,,,,,,,,,
90.278,1.58865,4.22622,3.5,,,,,,,,,,,,,,,,,,,,,,,,,,,,,,,,,,,,,
90.978,1.47192,2.97881,3.5,,,,,,,,,,,,,,,,,,,,,,,,,,,,,,,,,,,,,
91.678,1.3553,1.67743,3.5,,,,,,,,,,,,,,,,,,,,,,,,,,,,,,,,,,,,,
92.13,1.27993,0.97836,4,,,,,,,,,,,,,,,,,,,,,,,,,,,,,,,,,,,,,
92.83,1.39768,2.35085,4,,,,,,,,,,,,,,,,,,,,,,,,,,,,,,,,,,,,,
93.53,1.51425,3.90469,4,,,,,,,,,,,,,,,,,,,,,,,,,,,,,,,,,,,,,
94.23,1.63092,5.58064,4,,,,,,,,,,,,,,,,,,,,,,,,,,,,,,,,,,,,,
94.93,1.7476,7.41865,4,,,,,,,,,,,,,,,,,,,,,,,,,,,,,,,,,,,,,
95.63,1.86433,9.32574,4,,,,,,,,,,,,,,,,,,,,,,,,,,,,,,,,,,,,,
96.33,1.98095,11.33466,4,,,,,,,,,,,,,,,,,,,,,,,,,,,,,,,,,,,,,
97.03,2.09752,13.54526,4,,,,,,,,,,,,,,,,,,,,,,,,,,,,,,,,,,,,,
97.73,2.21414,15.85055,4,,,,,,,,,,,,,,,,,,,,,,,,,,,,,,,,,,,,,
98.43,2.33093,18.29239,4,,,,,,,,,,,,,,,,,,,,,,,,,,,,,,,,,,,,,
99.13,2.4476,21.02904,4,,,,,,,,,,,,,,,,,,,,,,,,,,,,,,,,,,,,,
99.83,2.56428,23.92331,4,,,,,,,,,,,,,,,,,,,,,,,,,,,,,,,,,,,,,
100.53,2.68079,27.07726,4,,,,,,,,,,,,,,,,,,,,,,,,,,,,,,,,,,,,,
101.23,2.79746,30.4549,4,,,,,,,,,,,,,,,,,,,,,,,,,,,,,,,,,,,,,
101.93,2.91414,34.15658,4,,,,,,,,,,,,,,,,,,,,,,,,,,,,,,,,,,,,,
102.63,3.03093,37.93565,4,,,,,,,,,,,,,,,,,,,,,,,,,,,,,,,,,,,,,
103.196,3.05881,38.56305,4.5,,,,,,,,,,,,,,,,,,,,,,,,,,,,,,,,,,,,,
103.896,2.94168,33.16902,4.5,,,,,,,,,,,,,,,,,,,,,,,,,,,,,,,,,,,,,
104.596,2.82495,28.82616,4.5,,,,,,,,,,,,,,,,,,,,,,,,,,,,,,,,,,,,,
105.296,2.70833,24.8927,4.5,,,,,,,,,,,,,,,,,,,,,,,,,,,,,,,,,,,,,
105.996,2.59171,21.54378,4.5,,,,,,,,,,,,,,,,,,,,,,,,,,,,,,,,,,,,,
106.696,2.47497,18.55623,4.5,,,,,,,,,,,,,,,,,,,,,,,,,,,,,,,,,,,,,
107.396,2.35824,15.86831,4.5,,,,,,,,,,,,,,,,,,,,,,,,,,,,,,,,,,,,,
108.096,2.24156,13.42384,4.5,,,,,,,,,,,,,,,,,,,,,,,,,,,,,,,,,,,,,
108.796,2.12483,11.39929,4.5,,,,,,,,,,,,,,,,,,,,,,,,,,,,,,,,,,,,,
109.496,2.00821,9.43269,4.5,,,,,,,,,,,,,,,,,,,,,,,,,,,,,,,,,,,,,
110.196,1.89153,7.64953,4.5,,,,,,,,,,,,,,,,,,,,,,,,,,,,,,,,,,,,,
110.896,1.7748,6.00585,4.5,,,,,,,,,,,,,,,,,,,,,,,,,,,,,,,,,,,,,
111.596,1.65818,4.43898,4.5,,,,,,,,,,,,,,,,,,,,,,,,,,,,,,,,,,,,,
112.296,1.54156,3.1173,4.5,,,,,,,,,,,,,,,,,,,,,,,,,,,,,,,,,,,,,
112.996,1.42494,1.84371,4.5,,,,,,,,,,,,,,,,,,,,,,,,,,,,,,,,,,,,,
113.53,1.33592,0.994,5,,,,,,,,,,,,,,,,,,,,,,,,,,,,,,,,,,,,,
114.132,1.43644,2.10157,5,,,,,,,,,,,,,,,,,,,,,,,,,,,,,,,,,,,,,
114.832,1.55312,3.68458,5,,,,,,,,,,,,,,,,,,,,,,,,,,,,,,,,,,,,,
115.532,1.66985,5.33356,5,,,,,,,,,,,,,,,,,,,,,,,,,,,,,,,,,,,,,
116.232,1.78659,7.06624,5,,,,,,,,,,,,,,,,,,,,,,,,,,,,,,,,,,,,,
116.932,1.90332,9.00515,5,,,,,,,,,,,,,,,,,,,,,,,,,,,,,,,,,,,,,
117.632,2.02,11.05794,5,,,,,,,,,,,,,,,,,,,,,,,,,,,,,,,,,,,,,
118.332,2.13667,13.22017,5,,,,,,,,,,,,,,,,,,,,,,,,,,,,,,,,,,,,,
119.032,2.25335,15.55046,5,,,,,,,,,,,,,,,,,,,,,,,,,,,,,,,,,,,,,
119.732,2.36997,17.95809,5,,,,,,,,,,,,,,,,,,,,,,,,,,,,,,,,,,,,,
120.432,2.48659,20.66637,5,,,,,,,,,,,,,,,,,,,,,,,,,,,,,,,,,,,,,
121.132,2.60315,23.49666,5,,,,,,,,,,,,,,,,,,,,,,,,,,,,,,,,,,,,,
121.832,2.71983,26.62219,5,,,,,,,,,,,,,,,,,,,,,,,,,,,,,,,,,,,,,
122.532,2.83662,30.12405,5,,,,,,,,,,,,,,,,,,,,,,,,,,,,,,,,,,,,,
123.232,2.95324,33.83936,5,,,,,,,,,,,,,,,,,,,,,,,,,,,,,,,,,,,,,
123.932,3.06992,37.81777,5,,,,,,,,,,,,,,,,,,,,,,,,,,,,,,,,,,,,,
124.436,3.12488,39.81165,5.5,,,,,,,,,,,,,,,,,,,,,,,,,,,,,,,,,,,,,
125.136,3.00373,33.93724,5.5,,,,,,,,,,,,,,,,,,,,,,,,,,,,,,,,,,,,,
125.836,2.887,29.48309,5.5,,,,,,,,,,,,,,,,,,,,,,,,,,,,,,,,,,,,,
126.536,2.77026,25.47581,5.5,,,,,,,,,,,,,,,,,,,,,,,,,,,,,,,,,,,,,
127.236,2.65364,22.02473,5.5,,,,,,,,,,,,,,,,,,,,,,,,,,,,,,,,,,,,,
127.936,2.53697,18.97197,5.5,,,,,,,,,,,,,,,,,,,,,,,,,,,,,,,,,,,,,
128.636,2.42029,16.26514,5.5,,,,,,,,,,,,,,,,,,,,,,,,,,,,,,,,,,,,,
129.336,2.30361,13.7247,5.5,,,,,,,,,,,,,,,,,,,,,,,,,,,,,,,,,,,,,
130.036,2.18699,11.60062,5.5,,,,,,,,,,,,,,,,,,,,,,,,,,,,,,,,,,,,,
130.736,2.07026,9.62561,5.5,,,,,,,,,,,,,,,,,,,,,,,,,,,,,,,,,,,,,
131.436,1.95353,7.88328,5.5,,,,,,,,,,,,,,,,,,,,,,,,,,,,,,,,,,,,,
132.136,1.83679,6.17325,5.5,,,,,,,,,,,,,,,,,,,,,,,,,,,,,,,,,,,,,
132.836,1.72017,4.64499,5.5,,,,,,,,,,,,,,,,,,,,,,,,,,,,,,,,,,,,,
133.536,1.60344,3.23591,5.5,,,,,,,,,,,,,,,,,,,,,,,,,,,,,,,,,,,,,
134.236,1.48682,1.9989,5.5,,,,,,,,,,,,,,,,,,,,,,,,,,,,,,,,,,,,,
134.856,1.38352,0.99324,6,,,,,,,,,,,,,,,,,,,,,,,,,,,,,,,,,,,,,
135.36,1.46721,1.96317,6,,,,,,,,,,,,,,,,,,,,,,,,,,,,,,,,,,,,,
136.06,1.58389,3.46751,6,,,,,,,,,,,,,,,,,,,,,,,,,,,,,,,,,,,,,
136.76,1.70057,5.07266,6,,,,,,,,,,,,,,,,,,,,,,,,,,,,,,,,,,,,,
137.46,1.81713,6.84639,6,,,,,,,,,,,,,,,,,,,,,,,,,,,,,,,,,,,,,
138.16,1.93381,8.698,6,,,,,,,,,,,,,,,,,,,,,,,,,,,,,,,,,,,,,
138.86,2.05054,10.70986,6,,,,,,,,,,,,,,,,,,,,,,,,,,,,,,,,,,,,,
139.56,2.16727,12.95837,6,,,,,,,,,,,,,,,,,,,,,,,,,,,,,,,,,,,,,
140.26,2.28389,15.25252,6,,,,,,,,,,,,,,,,,,,,,,,,,,,,,,,,,,,,,
140.96,2.40051,17.85771,6,,,,,,,,,,,,,,,,,,,,,,,,,,,,,,,,,,,,,
141.66,2.51713,20.36182,6,,,,,,,,,,,,,,,,,,,,,,,,,,,,,,,,,,,,,
142.36,2.63387,23.22136,6,,,,,,,,,,,,,,,,,,,,,,,,,,,,,,,,,,,,,
143.06,2.7506,26.44077,6,,,,,,,,,,,,,,,,,,,,,,,,,,,,,,,,,,,,,
143.76,2.86728,29.85649,6,,,,,,,,,,,,,,,,,,,,,,,,,,,,,,,,,,,,,
144.46,2.98401,33.56923,6,,,,,,,,,,,,,,,,,,,,,,,,,,,,,,,,,,,,,
145.16,3.10063,37.5407,6,,,,,,,,,,,,,,,,,,,,,,,,,,,,,,,,,,,,,
145.678,3.15792,39.82609,6.5,,,,,,,,,,,,,,,,,,,,,,,,,,,,,,,,,,,,,
146.378,3.03665,33.9502,6.5,,,,,,,,,,,,,,,,,,,,,,,,,,,,,,,,,,,,,
147.078,2.91992,29.49277,6.5,,,,,,,,,,,,,,,,,,,,,,,,,,,,,,,,,,,,,
147.778,2.80319,25.52241,6.5,,,,,,,,,,,,,,,,,,,,,,,,,,,,,,,,,,,,,
148.478,2.68651,22.04898,6.5,,,,,,,,,,,,,,,,,,,,,,,,,,,,,,,,,,,,,
149.178,2.56983,18.92261,6.5,,,,,,,,,,,,,,,,,,,,,,,,,,,,,,,,,,,,,
149.878,2.45316,16.18305,6.5,,,,,,,,,,,,,,,,,,,,,,,,,,,,,,,,,,,,,
150.578,2.33648,13.72532,6.5,,,,,,,,,,,,,,,,,,,,,,,,,,,,,,,,,,,,,
151.278,2.21992,11.61606,6.5,,,,,,,,,,,,,,,,,,,,,,,,,,,,,,,,,,,,,
151.978,2.10324,9.65581,6.5,,,,,,,,,,,,,,,,,,,,,,,,,,,,,,,,,,,,,
152.678,1.98668,7.92543,6.5,,,,,,,,,,,,,,,,,,,,,,,,,,,,,,,,,,,,,
153.378,1.86994,6.15369,6.5,,,,,,,,,,,,,,,,,,,,,,,,,,,,,,,,,,,,,
154.078,1.75327,4.63395,6.5,,,,,,,,,,,,,,,,,,,,,,,,,,,,,,,,,,,,,
154.778,1.63659,3.24978,6.5,,,,,,,,,,,,,,,,,,,,,,,,,,,,,,,,,,,,,
155.478,1.51997,1.97508,6.5,,,,,,,,,,,,,,,,,,,,,,,,,,,,,,,,,,,,,
156.12,1.41298,0.9988,7,,,,,,,,,,,,,,,,,,,,,,,,,,,,,,,,,,,,,
156.624,1.49651,1.93575,7,,,,,,,,,,,,,,,,,,,,,,,,,,,,,,,,,,,,,
157.324,1.61319,3.42248,7,,,,,,,,,,,,,,,,,,,,,,,,,,,,,,,,,,,,,
158.024,1.72998,5.01901,7,,,,,,,,,,,,,,,,,,,,,,,,,,,,,,,,,,,,,
158.724,1.8466,6.74104,7,,,,,,,,,,,,,,,,,,,,,,,,,,,,,,,,,,,,,
159.424,1.96333,8.65569,7,,,,,,,,,,,,,,,,,,,,,,,,,,,,,,,,,,,,,
160.124,2.08006,10.66233,7,,,,,,,,,,,,,,,,,,,,,,,,,,,,,,,,,,,,,
160.824,2.19668,12.82936,7,,,,,,,,,,,,,,,,,,,,,,,,,,,,,,,,,,,,,
161.524,2.3133,15.13265,7,,,,,,,,,,,,,,,,,,,,,,,,,,,,,,,,,,,,,
162.224,2.42987,17.62021,7,,,,,,,,,,,,,,,,,,,,,,,,,,,,,,,,,,,,,
162.924,2.54654,20.1959,7,,,,,,,,,,,,,,,,,,,,,,,,,,,,,,,,,,,,,
163.624,2.66328,23.12556,7,,,,,,,,,,,,,,,,,,,,,,,,,,,,,,,,,,,,,
164.324,2.7799,26.31025,7,,,,,,,,,,,,,,,,,,,,,,,,,,,,,,,,,,,,,
165.024,2.89652,29.78772,7,,,,,,,,,,,,,,,,,,,,,,,,,,,,,,,,,,,,,
165.724,3.01319,33.51234,7,,,,,,,,,,,,,,,,,,,,,,,,,,,,,,,,,,,,,
166.424,3.12981,37.55321,7,,,,,,,,,,,,,,,,,,,,,,,,,,,,,,,,,,,,,
166.94,3.18676,39.83059,7.5,,,,,,,,,,,,,,,,,,,,,,,,,,,,,,,,,,,,,
167.64,3.06567,34.00513,7.5,,,,,,,,,,,,,,,,,,,,,,,,,,,,,,,,,,,,,
168.34,2.94899,29.43114,7.5,,,,,,,,,,,,,,,,,,,,,,,,,,,,,,,,,,,,,
169.04,2.83226,25.43732,7.5,,,,,,,,,,,,,,,,,,,,,,,,,,,,,,,,,,,,,
169.74,2.71558,21.92161,7.5,,,,,,,,,,,,,,,,,,,,,,,,,,,,,,,,,,,,,
170.44,2.59896,18.9123,7.5,,,,,,,,,,,,,,,,,,,,,,,,,,,,,,,,,,,,,
171.14,2.48234,16.12871,7.5,,,,,,,,,,,,,,,,,,,,,,,,,,,,,,,,,,,,,
171.84,2.36566,13.70382,7.5,,,,,,,,,,,,,,,,,,,,,,,,,,,,,,,,,,,,,
172.54,2.24893,11.51224,7.5,,,,,,,,,,,,,,,,,,,,,,,,,,,,,,,,,,,,,
173.24,2.13225,9.57077,7.5,,,,,,,,,,,,,,,,,,,,,,,,,,,,,,,,,,,,,
173.94,2.01558,7.78687,7.5,,,,,,,,,,,,,,,,,,,,,,,,,,,,,,,,,,,,,
174.64,1.8989,6.15263,7.5,,,,,,,,,,,,,,,,,,,,,,,,,,,,,,,,,,,,,
175.34,1.78222,4.54146,7.5,,,,,,,,,,,,,,,,,,,,,,,,,,,,,,,,,,,,,
176.04,1.66549,3.27438,7.5,,,,,,,,,,,,,,,,,,,,,,,,,,,,,,,,,,,,,
176.74,1.54876,1.97309,7.5,,,,,,,,,,,,,,,,,,,,,,,,,,,,,,,,,,,,,
177.346,1.44795,0.99903,8,,,,,,,,,,,,,,,,,,,,,,,,,,,,,,,,,,,,,
177.85,1.53153,1.94561,8,,,,,,,,,,,,,,,,,,,,,,,,,,,,,,,,,,,,,
178.55,1.64821,3.47317,8,,,,,,,,,,,,,,,,,,,,,,,,,,,,,,,,,,,,,
179.25,1.76488,5.04783,8,,,,,,,,,,,,,,,,,,,,,,,,,,,,,,,,,,,,,
179.95,1.88145,6.83751,8,,,,,,,,,,,,,,,,,,,,,,,,,,,,,,,,,,,,,
180.65,1.99812,8.66832,8,,,,,,,,,,,,,,,,,,,,,,,,,,,,,,,,,,,,,
181.35,2.1148,10.68335,8,,,,,,,,,,,,,,,,,,,,,,,,,,,,,,,,,,,,,
182.05,2.23159,12.88628,8,,,,,,,,,,,,,,,,,,,,,,,,,,,,,,,,,,,,,
182.75,2.34821,15.23745,8,,,,,,,,,,,,,,,,,,,,,,,,,,,,,,,,,,,,,
183.45,2.46489,17.72325,8,,,,,,,,,,,,,,,,,,,,,,,,,,,,,,,,,,,,,
184.15,2.58156,20.34622,8,,,,,,,,,,,,,,,,,,,,,,,,,,,,,,,,,,,,,
184.85,2.6983,23.29723,8,,,,,,,,,,,,,,,,,,,,,,,,,,,,,,,,,,,,,
185.55,2.81503,26.49342,8,,,,,,,,,,,,,,,,,,,,,,,,,,,,,,,,,,,,,
186.25,2.93171,30.06991,8,,,,,,,,,,,,,,,,,,,,,,,,,,,,,,,,,,,,,
186.95,3.04827,33.91014,8,,,,,,,,,,,,,,,,,,,,,,,,,,,,,,,,,,,,,
187.65,3.16489,37.86547,8,,,,,,,,,,,,,,,,,,,,,,,,,,,,,,,,,,,,,
188.192,3.18869,38.61555,8.5,,,,,,,,,,,,,,,,,,,,,,,,,,,,,,,,,,,,,
188.892,3.07162,33.2714,8.5,,,,,,,,,,,,,,,,,,,,,,,,,,,,,,,,,,,,,
189.592,2.95494,28.83262,8.5,,,,,,,,,,,,,,,,,,,,,,,,,,,,,,,,,,,,,
190.292,2.83832,24.92406,8.5,,,,,,,,,,,,,,,,,,,,,,,,,,,,,,,,,,,,,
190.992,2.7217,21.48616,8.5,,,,,,,,,,,,,,,,,,,,,,,,,,,,,,,,,,,,,
191.692,2.60497,18.37853,8.5,,,,,,,,,,,,,,,,,,,,,,,,,,,,,,,,,,,,,
192.392,2.48823,15.73792,8.5,,,,,,,,,,,,,,,,,,,,,,,,,,,,,,,,,,,,,
193.092,2.37161,13.41857,8.5,,,,,,,,,,,,,,,,,,,,,,,,,,,,,,,,,,,,,
193.792,2.25499,11.26665,8.5,,,,,,,,,,,,,,,,,,,,,,,,,,,,,,,,,,,,,
194.492,2.13837,9.29292,8.5,,,,,,,,,,,,,,,,,,,,,,,,,,,,,,,,,,,,,
195.192,2.02164,7.50319,8.5,,,,,,,,,,,,,,,,,,,,,,,,,,,,,,,,,,,,,
195.892,1.90496,5.86668,8.5,,,,,,,,,,,,,,,,,,,,,,,,,,,,,,,,,,,,,
196.592,1.78823,4.3087,8.5,,,,,,,,,,,,,,,,,,,,,,,,,,,,,,,,,,,,,
197.292,1.6715,3.0503,8.5,,,,,,,,,,,,,,,,,,,,,,,,,,,,,,,,,,,,,
197.992,1.55482,1.77582,8.5,,,,,,,,,,,,,,,,,,,,,,,,,,,,,,,,,,,,,
198.456,1.47764,0.9947,9,,,,,,,,,,,,,,,,,,,,,,,,,,,,,,,,,,,,,
199.156,1.59522,2.39446,9,,,,,,,,,,,,,,,,,,,,,,,,,,,,,,,,,,,,,
199.856,1.71196,3.91793,9,,,,,,,,,,,,,,,,,,,,,,,,,,,,,,,,,,,,,
200.556,1.82852,5.57976,9,,,,,,,,,,,,,,,,,,,,,,,,,,,,,,,,,,,,,
201.256,1.94514,7.35082,9,,,,,,,,,,,,,,,,,,,,,,,,,,,,,,,,,,,,,
201.956,2.06182,9.32115,9,,,,,,,,,,,,,,,,,,,,,,,,,,,,,,,,,,,,,
202.656,2.17861,11.39486,9,,,,,,,,,,,,,,,,,,,,,,,,,,,,,,,,,,,,,
203.356,2.29528,13.61474,9,,,,,,,,,,,,,,,,,,,,,,,,,,,,,,,,,,,,,
204.056,2.41196,16.00889,9,,,,,,,,,,,,,,,,,,,,,,,,,,,,,,,,,,,,,
204.756,2.52869,18.49275,9,,,,,,,,,,,,,,,,,,,,,,,,,,,,,,,,,,,,,
205.456,2.64531,21.30722,9,,,,,,,,,,,,,,,,,,,,,,,,,,,,,,,,,,,,,
206.156,2.76205,24.36517,9,,,,,,,,,,,,,,,,,,,,,,,,,,,,,,,,,,,,,
206.856,2.87867,27.69468,9,,,,,,,,,,,,,,,,,,,,,,,,,,,,,,,,,,,,,
207.556,2.99529,31.37189,9,,,,,,,,,,,,,,,,,,,,,,,,,,,,,,,,,,,,,
208.256,3.11185,35.28632,9,,,,,,,,,,,,,,,,,,,,,,,,,,,,,,,,,,,,,
208.956,3.22853,39.42136,9,,,,,,,,,,,,,,,,,,,,,,,,,,,,,,,,,,,,,
209.554,3.16138,36.24451,9.5,,,,,,,,,,,,,,,,,,,,,,,,,,,,,,,,,,,,,
210.254,3.04476,31.30093,9.5,,,,,,,,,,,,,,,,,,,,,,,,,,,,,,,,,,,,,
210.954,2.92797,27.07524,9.5,,,,,,,,,,,,,,,,,,,,,,,,,,,,,,,,,,,,,
211.654,2.81123,23.34385,9.5,,,,,,,,,,,,,,,,,,,,,,,,,,,,,,,,,,,,,
212.354,2.69461,20.12936,9.5,,,,,,,,,,,,,,,,,,,,,,,,,,,,,,,,,,,,,
213.054,2.57782,17.19409,9.5,,,,,,,,,,,,,,,,,,,,,,,,,,,,,,,,,,,,,
213.754,2.4612,14.66063,9.5,,,,,,,,,,,,,,,,,,,,,,,,,,,,,,,,,,,,,
214.454,2.34453,12.37568,9.5,,,,,,,,,,,,,,,,,,,,,,,,,,,,,,,,,,,,,
215.154,2.22779,10.29746,9.5,,,,,,,,,,,,,,,,,,,,,,,,,,,,,,,,,,,,,
215.854,2.11117,8.46219,9.5,,,,,,,,,,,,,,,,,,,,,,,,,,,,,,,,,,,,,
216.554,1.99455,6.72713,9.5,,,,,,,,,,,,,,,,,,,,,,,,,,,,,,,,,,,,,
217.254,1.87793,5.13119,9.5,,,,,,,,,,,,,,,,,,,,,,,,,,,,,,,,,,,,,
217.954,1.76126,3.65539,9.5,,,,,,,,,,,,,,,,,,,,,,,,,,,,,,,,,,,,,
218.654,1.64469,2.40499,9.5,,,,,,,,,,,,,,,,,,,,,,,,,,,,,,,,,,,,,
219.354,1.5279,1.26043,9.5,,,,,,,,,,,,,,,,,,,,,,,,,,,,,,,,,,,,,
219.942,1.43185,0.41979,10,,,,,,,,,,,,,,,,,,,,,,,,,,,,,,,,,,,,,
220.642,1.41298,0.36047,10,,,,,,,,,,,,,,,,,,,,,,,,,,,,,,,,,,,,,
221.342,1.4157,0.32091,10,,,,,,,,,,,,,,,,,,,,,,,,,,,,,,,,,,,,,
222.042,1.45781,0.82911,10,,,,,,,,,,,,,,,,,,,,,,,,,,,,,,,,,,,,,
222.742,1.47367,1.06353,10,,,,,,,,,,,,,,,,,,,,,,,,,,,,,,,,,,,,,
223.442,1.47129,1.07426,10,,,,,,,,,,,,,,,,,,,,,,,,,,,,,,,,,,,,,
224.142,1.4399,0.72297,10,,,,,,,,,,,,,,,,,,,,,,,,,,,,,,,,,,,,,
224.842,1.42613,0.60363,10,,,,,,,,,,,,,,,,,,,,,,,,,,,,,,,,,,,,,
225.542,1.42636,0.5853,10,,,,,,,,,,,,,,,,,,,,,,,,,,,,,,,,,,,,,
226.242,1.42653,0.59633,10,,,,,,,,,,,,,,,,,,,,,,,,,,,,,,,,,,,,,
226.942,1.42698,0.65832,10,,,,,,,,,,,,,,,,,,,,,,,,,,,,,,,,,,,,,
227.642,1.42857,0.6288,10,,,,,,,,,,,,,,,,,,,,,,,,,,,,,,,,,,,,,
228.342,1.43231,0.65397,10,,,,,,,,,,,,,,,,,,,,,,,,,,,,,,,,,,,,,
229.042,1.44126,0.79929,10,,,,,,,,,,,,,,,,,,,,,,,,,,,,,,,,,,,,,
229.742,1.4446,0.82605,10,,,,,,,,,,,,,,,,,,,,,,,,,,,,,,,,,,,,,
230.442,1.44449,0.84328,10,,,,,,,,,,,,,,,,,,,,,,,,,,,,,,,,,,,,,
231.142,1.44426,0.91701,10,,,,,,,,,,,,,,,,,,,,,,,,,,,,,,,,,,,,,
231.842,1.44302,0.85944,10,,,,,,,,,,,,,,,,,,,,,,,,,,,,,,,,,,,,,
232.542,1.43695,0.81605,10,,,,,,,,,,,,,,,,,,,,,,,,,,,,,,,,,,,,,
233.242,1.42964,0.74912,10,,,,,,,,,,,,,,,,,,,,,,,,,,,,,,,,,,,,,
233.942,1.42845,0.7447,10,,,,,,,,,,,,,,,,,,,,,,,,,,,,,,,,,,,,,
234.642,1.42806,0.75421,10,,,,,,,,,,,,,,,,,,,,,,,,,,,,,,,,,,,,,
235.342,1.42772,0.72475,10,,,,,,,,,,,,,,,,,,,,,,,,,,,,,,,,,,,,,
236.042,1.42715,0.71877,10,,,,,,,,,,,,,,,,,,,,,,,,,,,,,,,,,,,,,
236.742,1.42641,0.69036,10,,,,,,,,,,,,,,,,,,,,,,,,,,,,,,,,,,,,,
237.442,1.42596,0.75154,10,,,,,,,,,,,,,,,,,,,,,,,,,,,,,,,,,,,,,
238.142,1.42568,0.78624,10,,,,,,,,,,,,,,,,,,,,,,,,,,,,,,,,,,,,,
238.842,1.42539,0.71659,10,,,,,,,,,,,,,,,,,,,,,,,,,,,,,,,,,,,,,
239.542,1.42511,0.73075,10,,,,,,,,,,,,,,,,,,,,,,,,,,,,,,,,,,,,,
240.242,1.42488,0.74926,10,,,,,,,,,,,,,,,,,,,,,,,,,,,,,,,,,,,,,
240.942,1.42466,0.74298,10,,,,,,,,,,,,,,,,,,,,,,,,,,,,,,,,,,,,,
241.642,1.42432,0.72771,10,,,,,,,,,,,,,,,,,,,,,,,,,,,,,,,,,,,,,
242.342,1.42375,0.75539,10,,,,,,,,,,,,,,,,,,,,,,,,,,,,,,,,,,,,,
243.042,1.42301,0.75406,10,,,,,,,,,,,,,,,,,,,,,,,,,,,,,,,,,,,,,
243.742,1.42211,0.78089,10,,,,,,,,,,,,,,,,,,,,,,,,,,,,,,,,,,,,,
244.442,1.4212,0.71731,10,,,,,,,,,,,,,,,,,,,,,,,,,,,,,,,,,,,,,
245.142,1.4208,0.73375,10,,,,,,,,,,,,,,,,,,,,,,,,,,,,,,,,,,,,,
245.842,1.42058,0.75562,10,,,,,,,,,,,,,,,,,,,,,,,,,,,,,,,,,,,,,
246.542,1.42041,0.69618,10,,,,,,,,,,,,,,,,,,,,,,,,,,,,,,,,,,,,,
247.242,1.42029,0.75057,10,,,,,,,,,,,,,,,,,,,,,,,,,,,,,,,,,,,,,
247.942,1.42024,0.73086,10,,,,,,,,,,,,,,,,,,,,,,,,,,,,,,,,,,,,,
248.642,1.42024,0.75516,10,,,,,,,,,,,,,,,,,,,,,,,,,,,,,,,,,,,,,
249.342,1.42029,0.66332,10,,,,,,,,,,,,,,,,,,,,,,,,,,,,,,,,,,,,,
250.042,1.42029,0.75467,10,,,,,,,,,,,,,,,,,,,,,,,,,,,,,,,,,,,,,
250.742,1.42024,0.71585,10,,,,,,,,,,,,,,,,,,,,,,,,,,,,,,,,,,,,,
251.442,1.42035,0.72035,10,,,,,,,,,,,,,,,,,,,,,,,,,,,,,,,,,,,,,
252.142,1.42035,0.72846,10,,,,,,,,,,,,,,,,,,,,,,,,,,,,,,,,,,,,,
252.842,1.42041,0.67224,10,,,,,,,,,,,,,,,,,,,,,,,,,,,,,,,,,,,,,
253.542,1.42041,0.70906,10,,,,,,,,,,,,,,,,,,,,,,,,,,,,,,,,,,,,,
254.242,1.42041,0.77542,10,,,,,,,,,,,,,,,,,,,,,,,,,,,,,,,,,,,,,
254.942,1.42035,0.74287,10,,,,,,,,,,,,,,,,,,,,,,,,,,,,,,,,,,,,,
255.642,1.42035,0.68911,10,,,,,,,,,,,,,,,,,,,,,,,,,,,,,,,,,,,,,
256.342,1.42046,0.6892,10,,,,,,,,,,,,,,,,,,,,,,,,,,,,,,,,,,,,,
257.042,1.42046,0.73477,10,,,,,,,,,,,,,,,,,,,,,,,,,,,,,,,,,,,,,
257.742,1.42046,0.695,10,,,,,,,,,,,,,,,,,,,,,,,,,,,,,,,,,,,,,
258.442,1.42046,0.78134,10,,,,,,,,,,,,,,,,,,,,,,,,,,,,,,,,,,,,,
259.142,1.42046,0.73596,10,,,,,,,,,,,,,,,,,,,,,,,,,,,,,,,,,,,,,
259.842,1.42046,0.69388,10,,,,,,,,,,,,,,,,,,,,,,,,,,,,,,,,,,,,,
260.542,1.42041,0.71794,10,,,,,,,,,,,,,,,,,,,,,,,,,,,,,,,,,,,,,
261.242,1.42041,0.74596,10,,,,,,,,,,,,,,,,,,,,,,,,,,,,,,,,,,,,,
261.942,1.42041,0.7246,10,,,,,,,,,,,,,,,,,,,,,,,,,,,,,,,,,,,,,
262.642,1.42041,0.71698,10,,,,,,,,,,,,,,,,,,,,,,,,,,,,,,,,,,,,,
263.342,1.42041,0.76657,10,,,,,,,,,,,,,,,,,,,,,,,,,,,,,,,,,,,,,
264.042,1.42029,0.72153,10,,,,,,,,,,,,,,,,,,,,,,,,,,,,,,,,,,,,,
264.742,1.42029,0.7284,10,,,,,,,,,,,,,,,,,,,,,,,,,,,,,,,,,,,,,
265.442,1.42024,0.79904,10,,,,,,,,,,,,,,,,,,,,,,,,,,,,,,,,,,,,,
266.142,1.42018,0.76148,10,,,,,,,,,,,,,,,,,,,,,,,,,,,,,,,,,,,,,
266.842,1.41995,0.80688,10,,,,,,,,,,,,,,,,,,,,,,,,,,,,,,,,,,,,,
267.542,1.41876,0.75327,10,,,,,,,,,,,,,,,,,,,,,,,,,,,,,,,,,,,,,
268.242,1.41604,0.7279,10,,,,,,,,,,,,,,,,,,,,,,,,,,,,,,,,,,,,,
268.942,1.41383,0.73217,10,,,,,,,,,,,,,,,,,,,,,,,,,,,,,,,,,,,,,
269.642,1.41293,0.71524,10,,,,,,,,,,,,,,,,,,,,,,,,,,,,,,,,,,,,,
270.342,1.41264,0.64348,10,,,,,,,,,,,,,,,,,,,,,,,,,,,,,,,,,,,,,
271.042,1.4127,0.70611,10,,,,,,,,,,,,,,,,,,,,,,,,,,,,,,,,,,,,,
271.742,1.41281,0.693,10,,,,,,,,,,,,,,,,,,,,,,,,,,,,,,,,,,,,,
272.442,1.41287,0.7143,10,,,,,,,,,,,,,,,,,,,,,,,,,,,,,,,,,,,,,
273.142,1.41298,0.69195,10,,,,,,,,,,,,,,,,,,,,,,,,,,,,,,,,,,,,,
273.842,1.4131,0.60783,10,,,,,,,,,,,,,,,,,,,,,,,,,,,,,,,,,,,,,
274.542,1.41338,0.6448,10,,,,,,,,,,,,,,,,,,,,,,,,,,,,,,,,,,,,,
275.242,1.41378,0.69681,10,,,,,,,,,,,,,,,,,,,,,,,,,,,,,,,,,,,,,
275.942,1.41429,0.69373,10,,,,,,,,,,,,,,,,,,,,,,,,,,,,,,,,,,,,,
276.642,1.41519,0.6885,10,,,,,,,,,,,,,,,,,,,,,,,,,,,,,,,,,,,,,
277.342,1.41746,0.67308,10,,,,,,,,,,,,,,,,,,,,,,,,,,,,,,,,,,,,,
278.042,1.41973,0.70525,10,,,,,,,,,,,,,,,,,,,,,,,,,,,,,,,,,,,,,
278.742,1.42075,0.73016,10,,,,,,,,,,,,,,,,,,,,,,,,,,,,,,,,,,,,,
279.442,1.42097,0.81161,10,,,,,,,,,,,,,,,,,,,,,,,,,,,,,,,,,,,,,
280.142,1.42086,0.77463,10,,,,,,,,,,,,,,,,,,,,,,,,,,,,,,,,,,,,,
280.842,1.4208,0.72059,10,,,,,,,,,,,,,,,,,,,,,,,,,,,,,,,,,,,,,
281.542,1.42063,0.87271,10,,,,,,,,,,,,,,,,,,,,,,,,,,,,,,,,,,,,,
282.242,1.42052,0.83716,10,,,,,,,,,,,,,,,,,,,,,,,,,,,,,,,,,,,,,
282.942,1.42024,0.83598,10,,,,,,,,,,,,,,,,,,,,,,,,,,,,,,,,,,,,,
283.642,1.41973,0.78021,10,,,,,,,,,,,,,,,,,,,,,,,,,,,,,,,,,,,,,
284.342,1.41848,0.81056,10,,,,,,,,,,,,,,,,,,,,,,,,,,,,,,,,,,,,,
285.042,1.41723,0.75188,10,,,,,,,,,,,,,,,,,,,,,,,,,,,,,,,,,,,,,
285.742,1.41604,0.78852,10,,,,,,,,,,,,,,,,,,,,,,,,,,,,,,,,,,,,,
286.442,1.41468,0.75651,10,,,,,,,,,,,,,,,,,,,,,,,,,,,,,,,,,,,,,
287.142,1.41304,0.70578,10,,,,,,,,,,,,,,,,,,,,,,,,,,,,,,,,,,,,,
287.842,1.41236,0.70908,10,,,,,,,,,,,,,,,,,,,,,,,,,,,,,,,,,,,,,
288.542,1.41213,0.67834,10,,,,,,,,,,,,,,,,,,,,,,,,,,,,,,,,,,,,,
289.242,1.41196,0.72288,10,,,,,,,,,,,,,,,,,,,,,,,,,,,,,,,,,,,,,
289.942,1.41185,0.69378,10,,,,,,,,,,,,,,,,,,,,,,,,,,,,,,,,,,,,,
290.642,1.41179,0.67507,10,,,,,,,,,,,,,,,,,,,,,,,,,,,,,,,,,,,,,
291.342,1.41191,0.64874,10,,,,,,,,,,,,,,,,,,,,,,,,,,,,,,,,,,,,,
292.042,1.41185,0.71695,10,,,,,,,,,,,,,,,,,,,,,,,,,,,,,,,,,,,,,
292.742,1.41191,0.69184,10,,,,,,,,,,,,,,,,,,,,,,,,,,,,,,,,,,,,,
293.442,1.41202,0.72026,10,,,,,,,,,,,,,,,,,,,,,,,,,,,,,,,,,,,,,
294.142,1.41202,0.72177,10,,,,,,,,,,,,,,,,,,,,,,,,,,,,,,,,,,,,,
294.842,1.41202,0.72851,10,,,,,,,,,,,,,,,,,,,,,,,,,,,,,,,,,,,,,
295.542,1.41202,0.76766,10,,,,,,,,,,,,,,,,,,,,,,,,,,,,,,,,,,,,,
296.242,1.41202,0.74503,10,,,,,,,,,,,,,,,,,,,,,,,,,,,,,,,,,,,,,
296.942,1.41202,0.78508,10,,,,,,,,,,,,,,,,,,,,,,,,,,,,,,,,,,,,,
297.642,1.41202,0.72259,10,,,,,,,,,,,,,,,,,,,,,,,,,,,,,,,,,,,,,
298.342,1.41202,0.68955,10,,,,,,,,,,,,,,,,,,,,,,,,,,,,,,,,,,,,,
299.042,1.41202,0.72218,10,,,,,,,,,,,,,,,,,,,,,,,,,,,,,,,,,,,,,
299.742,1.41202,0.69876,10,,,,,,,,,,,,,,,,,,,,,,,,,,,,,,,,,,,,,
300.442,1.41202,0.74361,10,,,,,,,,,,,,,,,,,,,,,,,,,,,,,,,,,,,,,
301.142,1.41202,0.72877,10,,,,,,,,,,,,,,,,,,,,,,,,,,,,,,,,,,,,,
301.842,1.41202,0.73163,10,,,,,,,,,,,,,,,,,,,,,,,,,,,,,,,,,,,,,
302.542,1.41202,0.73661,10,,,,,,,,,,,,,,,,,,,,,,,,,,,,,,,,,,,,,
303.242,1.41202,0.73737,10,,,,,,,,,,,,,,,,,,,,,,,,,,,,,,,,,,,,,
303.942,1.41202,0.737,10,,,,,,,,,,,,,,,,,,,,,,,,,,,,,,,,,,,,,
304.642,1.41202,0.73996,10,,,,,,,,,,,,,,,,,,,,,,,,,,,,,,,,,,,,,
305.342,1.41196,0.7201,10,,,,,,,,,,,,,,,,,,,,,,,,,,,,,,,,,,,,,
306.042,1.41208,0.70397,10,,,,,,,,,,,,,,,,,,,,,,,,,,,,,,,,,,,,,
306.742,1.41208,0.72977,10,,,,,,,,,,,,,,,,,,,,,,,,,,,,,,,,,,,,,
307.442,1.41208,0.71168,10,,,,,,,,,,,,,,,,,,,,,,,,,,,,,,,,,,,,,
308.142,1.41213,0.70445,10,,,,,,,,,,,,,,,,,,,,,,,,,,,,,,,,,,,,,
308.842,1.41213,0.76214,10,,,,,,,,,,,,,,,,,,,,,,,,,,,,,,,,,,,,,
309.542,1.41219,0.69217,10,,,,,,,,,,,,,,,,,,,,,,,,,,,,,,,,,,,,,
310.242,1.41219,0.67576,10,,,,,,,,,,,,,,,,,,,,,,,,,,,,,,,,,,,,,
310.942,1.4123,0.6869,10,,,,,,,,,,,,,,,,,,,,,,,,,,,,,,,,,,,,,
311.642,1.41242,0.74017,10,,,,,,,,,,,,,,,,,,,,,,,,,,,,,,,,,,,,,
312.342,1.41259,0.70932,10,,,,,,,,,,,,,,,,,,,,,,,,,,,,,,,,,,,,,
313.042,1.41276,0.71802,10,,,,,,,,,,,,,,,,,,,,,,,,,,,,,,,,,,,,,
313.742,1.4131,0.6465,10,,,,,,,,,,,,,,,,,,,,,,,,,,,,,,,,,,,,,
314.442,1.41349,0.72944,10,,,,,,,,,,,,,,,,,,,,,,,,,,,,,,,,,,,,,
315.142,1.414,0.68249,10,,,,,,,,,,,,,,,,,,,,,,,,,,,,,,,,,,,,,
315.842,1.4148,0.6979,10,,,,,,,,,,,,,,,,,,,,,,,,,,,,,,,,,,,,,
316.542,1.41559,0.71843,10,,,,,,,,,,,,,,,,,,,,,,,,,,,,,,,,,,,,,
317.242,1.41604,0.78885,10,,,,,,,,,,,,,,,,,,,,,,,,,,,,,,,,,,,,,
317.942,1.41621,0.76826,10,,,,,,,,,,,,,,,,,,,,,,,,,,,,,,,,,,,,,
318.642,1.41633,0.74452,10,,,,,,,,,,,,,,,,,,,,,,,,,,,,,,,,,,,,,
319.342,1.41633,0.73139,10,,,,,,,,,,,,,,,,,,,,,,,,,,,,,,,,,,,,,
320.042,1.41627,0.77233,10,,,,,,,,,,,,,,,,,,,,,,,,,,,,,,,,,,,,,
320.742,1.41627,0.7268,10,,,,,,,,,,,,,,,,,,,,,,,,,,,,,,,,,,,,,
321.442,1.41621,0.80613,10,,,,,,,,,,,,,,,,,,,,,,,,,,,,,,,,,,,,,
322.142,1.41621,0.71326,10,,,,,,,,,,,,,,,,,,,,,,,,,,,,,,,,,,,,,
322.842,1.4161,0.79845,10,,,,,,,,,,,,,,,,,,,,,,,,,,,,,,,,,,,,,
323.542,1.4161,0.74021,10,,,,,,,,,,,,,,,,,,,,,,,,,,,,,,,,,,,,,
324.242,1.41599,0.75493,10,,,,,,,,,,,,,,,,,,,,,,,,,,,,,,,,,,,,,
324.942,1.41587,0.81534,10,,,,,,,,,,,,,,,,,,,,,,,,,,,,,,,,,,,,,
325.642,1.41559,0.77512,10,,,,,,,,,,,,,,,,,,,,,,,,,,,,,,,,,,,,,
326.342,1.41525,0.8275,10,,,,,,,,,,,,,,,,,,,,,,,,,,,,,,,,,,,,,
327.042,1.4148,0.77884,10,,,,,,,,,,,,,,,,,,,,,,,,,,,,,,,,,,,,,
327.742,1.41406,0.78055,10,,,,,,,,,,,,,,,,,,,,,,,,,,,,,,,,,,,,,
328.442,1.41293,0.76231,10,,,,,,,,,,,,,,,,,,,,,,,,,,,,,,,,,,,,,
329.142,1.41219,0.73747,10,,,,,,,,,,,,,,,,,,,,,,,,,,,,,,,,,,,,,
329.842,1.41179,0.72938,10,,,,,,,,,,,,,,,,,,,,,,,,,,,,,,,,,,,,,
330.542,1.4114,0.73609,10,,,,,,,,,,,,,,,,,,,,,,,,,,,,,,,,,,,,,
331.242,1.411,0.74373,10,,,,,,,,,,,,,,,,,,,,,,,,,,,,,,,,,,,,,
331.942,1.4106,0.72508,10,,,,,,,,,,,,,,,,,,,,,,,,,,,,,,,,,,,,,
332.642,1.40981,0.67055,10,,,,,,,,,,,,,,,,,,,,,,,,,,,,,,,,,,,,,
333.342,1.40947,0.72488,10,,,,,,,,,,,,,,,,,,,,,,,,,,,,,,,,,,,,,
334.042,1.40936,0.7418,10,,,,,,,,,,,,,,,,,,,,,,,,,,,,,,,,,,,,,
334.742,1.4093,0.73015,10,,,,,,,,,,,,,,,,,,,,,,,,,,,,,,,,,,,,,
335.442,1.40941,0.69499,10,,,,,,,,,,,,,,,,,,,,,,,,,,,,,,,,,,,,,
336.142,1.40947,0.69071,10,,,,,,,,,,,,,,,,,,,,,,,,,,,,,,,,,,,,,
336.842,1.40953,0.73091,10,,,,,,,,,,,,,,,,,,,,,,,,,,,,,,,,,,,,,
337.542,1.40958,0.66995,10,,,,,,,,,,,,,,,,,,,,,,,,,,,,,,,,,,,,,
338.242,1.40964,0.68185,10,,,,,,,,,,,,,,,,,,,,,,,,,,,,,,,,,,,,,
338.942,1.4097,0.68024,10,,,,,,,,,,,,,,,,,,,,,,,,,,,,,,,,,,,,,
339.642,1.40975,0.64602,10,,,,,,,,,,,,,,,,,,,,,,,,,,,,,,,,,,,,,
340.342,1.40998,0.76144,10,,,,,,,,,,,,,,,,,,,,,,,,,,,,,,,,,,,,,
341.042,1.41026,0.70441,10,,,,,,,,,,,,,,,,,,,,,,,,,,,,,,,,,,,,,
341.742,1.41043,0.68922,10,,,,,,,,,,,,,,,,,,,,,,,,,,,,,,,,,,,,,
342.442,1.41066,0.66236,10,,,,,,,,,,,,,,,,,,,,,,,,,,,,,,,,,,,,,
343.142,1.41111,0.68036,10,,,,,,,,,,,,,,,,,,,,,,,,,,,,,,,,,,,,,
343.842,1.41213,0.68644,10,,,,,,,,,,,,,,,,,,,,,,,,,,,,,,,,,,,,,
344.542,1.41406,0.70493,10,,,,,,,,,,,,,,,,,,,,,,,,,,,,,,,,,,,,,
345.242,1.41559,0.7247,10,,,,,,,,,,,,,,,,,,,,,,,,,,,,,,,,,,,,,
345.942,1.41655,0.77186,10,,,,,,,,,,,,,,,,,,,,,,,,,,,,,,,,,,,,,
346.642,1.41684,0.72813,10,,,,,,,,,,,,,,,,,,,,,,,,,,,,,,,,,,,,,
347.342,1.41695,0.82968,10,,,,,,,,,,,,,,,,,,,,,,,,,,,,,,,,,,,,,
348.042,1.41684,0.73466,10,,,,,,,,,,,,,,,,,,,,,,,,,,,,,,,,,,,,,
348.742,1.41678,0.77915,10,,,,,,,,,,,,,,,,,,,,,,,,,,,,,,,,,,,,,
349.442,1.41678,0.75557,10,,,,,,,,,,,,,,,,,,,,,,,,,,,,,,,,,,,,,
350.142,1.41667,0.72683,10,,,,,,,,,,,,,,,,,,,,,,,,,,,,,,,,,,,,,
350.842,1.41661,0.76364,10,,,,,,,,,,,,,,,,,,,,,,,,,,,,,,,,,,,,,
351.542,1.4165,0.72179,10,,,,,,,,,,,,,,,,,,,,,,,,,,,,,,,,,,,,,
352.242,1.41633,0.72514,10,,,,,,,,,,,,,,,,,,,,,,,,,,,,,,,,,,,,,
352.942,1.41593,0.80913,10,,,,,,,,,,,,,,,,,,,,,,,,,,,,,,,,,,,,,
353.642,1.41531,0.77065,10,,,,,,,,,,,,,,,,,,,,,,,,,,,,,,,,,,,,,
354.342,1.41434,0.77931,10,,,,,,,,,,,,,,,,,,,,,,,,,,,,,,,,,,,,,
355.042,1.41332,0.7608,10,,,,,,,,,,,,,,,,,,,,,,,,,,,,,,,,,,,,,
355.742,1.41242,0.75595,10,,,,,,,,,,,,,,,,,,,,,,,,,,,,,,,,,,,,,
356.442,1.41157,0.7661,10,,,,,,,,,,,,,,,,,,,,,,,,,,,,,,,,,,,,,
357.142,1.41043,0.74062,10,,,,,,,,,,,,,,,,,,,,,,,,,,,,,,,,,,,,,
357.842,1.40941,0.68615,10,,,,,,,,,,,,,,,,,,,,,,,,,,,,,,,,,,,,,
358.542,1.40907,0.67492,10,,,,,,,,,,,,,,,,,,,,,,,,,,,,,,,,,,,,,
359.242,1.40896,0.65093,10,,,,,,,,,,,,,,,,,,,,,,,,,,,,,,,,,,,,,
359.942,1.40907,0.71639,10,,,,,,,,,,,,,,,,,,,,,,,,,,,,,,,,,,,,,
360.642,1.40913,0.71145,10,,,,,,,,,,,,,,,,,,,,,,,,,,,,,,,,,,,,,
361.342,1.40919,0.73328,10,,,,,,,,,,,,,,,,,,,,,,,,,,,,,,,,,,,,,
362.042,1.40924,0.68762,10,,,,,,,,,,,,,,,,,,,,,,,,,,,,,,,,,,,,,
362.742,1.40941,0.72432,10,,,,,,,,,,,,,,,,,,,,,,,,,,,,,,,,,,,,,
363.442,1.40958,0.72167,10,,,,,,,,,,,,,,,,,,,,,,,,,,,,,,,,,,,,,
364.142,1.40987,0.60827,10,,,,,,,,,,,,,,,,,,,,,,,,,,,,,,,,,,,,,
364.842,1.41038,0.74071,10,,,,,,,,,,,,,,,,,,,,,,,,,,,,,,,,,,,,,
365.542,1.41106,0.68416,10,,,,,,,,,,,,,,,,,,,,,,,,,,,,,,,,,,,,,
366.242,1.41247,0.68848,10,,,,,,,,,,,,,,,,,,,,,,,,,,,,,,,,,,,,,
366.942,1.41514,0.77083,10,,,,,,,,,,,,,,,,,,,,,,,,,,,,,,,,,,,,,
367.642,1.41678,0.73894,10,,,,,,,,,,,,,,,,,,,,,,,,,,,,,,,,,,,,,
368.342,1.41735,0.69727,10,,,,,,,,,,,,,,,,,,,,,,,,,,,,,,,,,,,,,
369.042,1.41763,0.74448,10,,,,,,,,,,,,,,,,,,,,,,,,,,,,,,,,,,,,,
369.742,1.41769,0.72052,10,,,,,,,,,,,,,,,,,,,,,,,,,,,,,,,,,,,,,
370.442,1.41763,0.7935,10,,,,,,,,,,,,,,,,,,,,,,,,,,,,,,,,,,,,,
371.142,1.41763,0.72912,10,,,,,,,,,,,,,,,,,,,,,,,,,,,,,,,,,,,,,
371.842,1.41757,0.74559,10,,,,,,,,,,,,,,,,,,,,,,,,,,,,,,,,,,,,,
372.542,1.41752,0.7571,10,,,,,,,,,,,,,,,,,,,,,,,,,,,,,,,,,,,,,
373.242,1.41752,0.71232,10,,,,,,,,,,,,,,,,,,,,,,,,,,,,,,,,,,,,,
373.942,1.41746,0.72555,10,,,,,,,,,,,,,,,,,,,,,,,,,,,,,,,,,,,,,
374.642,1.4174,0.74902,10,,,,,,,,,,,,,,,,,,,,,,,,,,,,,,,,,,,,,
375.342,1.41735,0.71705,10,,,,,,,,,,,,,,,,,,,,,,,,,,,,,,,,,,,,,
376.042,1.41723,0.73419,10,,,,,,,,,,,,,,,,,,,,,,,,,,,,,,,,,,,,,
376.742,1.41706,0.77072,10,,,,,,,,,,,,,,,,,,,,,,,,,,,,,,,,,,,,,
377.442,1.41678,0.77874,10,,,,,,,,,,,,,,,,,,,,,,,,,,,,,,,,,,,,,
378.142,1.41616,0.76483,10,,,,,,,,,,,,,,,,,,,,,,,,,,,,,,,,,,,,,
378.842,1.41531,0.79721,10,,,,,,,,,,,,,,,,,,,,,,,,,,,,,,,,,,,,,
379.542,1.41457,0.73185,10,,,,,,,,,,,,,,,,,,,,,,,,,,,,,,,,,,,,,
380.242,1.41383,0.72165,10,,,,,,,,,,,,,,,,,,,,,,,,,,,,,,,,,,,,,
380.942,1.4131,0.7327,10,,,,,,,,,,,,,,,,,,,,,,,,,,,,,,,,,,,,,
381.642,1.41247,0.72549,10,,,,,,,,,,,,,,,,,,,,,,,,,,,,,,,,,,,,,
382.342,1.41225,0.7141,10,,,,,,,,,,,,,,,,,,,,,,,,,,,,,,,,,,,,,
383.042,1.41202,0.76398,10,,,,,,,,,,,,,,,,,,,,,,,,,,,,,,,,,,,,,
383.742,1.41185,0.69305,10,,,,,,,,,,,,,,,,,,,,,,,,,,,,,,,,,,,,,
384.442,1.41174,0.75743,10,,,,,,,,,,,,,,,,,,,,,,,,,,,,,,,,,,,,,
385.142,1.41168,0.67388,10,,,,,,,,,,,,,,,,,,,,,,,,,,,,,,,,,,,,,
385.842,1.41168,0.73335,10,,,,,,,,,,,,,,,,,,,,,,,,,,,,,,,,,,,,,
386.542,1.41179,0.6829,10,,,,,,,,,,,,,,,,,,,,,,,,,,,,,,,,,,,,,
387.242,1.41185,0.69667,10,,,,,,,,,,,,,,,,,,,,,,,,,,,,,,,,,,,,,
387.942,1.41179,0.73669,10,,,,,,,,,,,,,,,,,,,,,,,,,,,,,,,,,,,,,
388.642,1.41191,0.70136,10,,,,,,,,,,,,,,,,,,,,,,,,,,,,,,,,,,,,,
389.342,1.41196,0.68776,10,,,,,,,,,,,,,,,,,,,,,,,,,,,,,,,,,,,,,
390.042,1.41196,0.73041,10,,,,,,,,,,,,,,,,,,,,,,,,,,,,,,,,,,,,,
390.742,1.41202,0.68901,10,,,,,,,,,,,,,,,,,,,,,,,,,,,,,,,,,,,,,
391.442,1.41202,0.82669,10,,,,,,,,,,,,,,,,,,,,,,,,,,,,,,,,,,,,,
392.142,1.41202,0.70115,10,,,,,,,,,,,,,,,,,,,,,,,,,,,,,,,,,,,,,
392.842,1.41202,0.71572,10,,,,,,,,,,,,,,,,,,,,,,,,,,,,,,,,,,,,,
393.542,1.41202,0.71325,10,,,,,,,,,,,,,,,,,,,,,,,,,,,,,,,,,,,,,
394.242,1.41202,0.7089,10,,,,,,,,,,,,,,,,,,,,,,,,,,,,,,,,,,,,,
394.942,1.41202,0.74478,10,,,,,,,,,,,,,,,,,,,,,,,,,,,,,,,,,,,,,
395.642,1.41202,0.77724,10,,,,,,,,,,,,,,,,,,,,,,,,,,,,,,,,,,,,,
396.342,1.41208,0.71834,10,,,,,,,,,,,,,,,,,,,,,,,,,,,,,,,,,,,,,
397.042,1.41208,0.73004,10,,,,,,,,,,,,,,,,,,,,,,,,,,,,,,,,,,,,,
397.742,1.41219,0.64499,10,,,,,,,,,,,,,,,,,,,,,,,,,,,,,,,,,,,,,
398.442,1.41236,0.73941,10,,,,,,,,,,,,,,,,,,,,,,,,,,,,,,,,,,,,,
399.142,1.41259,0.65743,10,,,,,,,,,,,,,,,,,,,,,,,,,,,,,,,,,,,,,
399.842,1.41293,0.68252,10,,,,,,,,,,,,,,,,,,,,,,,,,,,,,,,,,,,,,
400.542,1.41372,0.6414,10,,,,,,,,,,,,,,,,,,,,,,,,,,,,,,,,,,,,,
401.242,1.4148,0.70317,10,,,,,,,,,,,,,,,,,,,,,,,,,,,,,,,,,,,,,
401.942,1.41621,0.74426,10,,,,,,,,,,,,,,,,,,,,,,,,,,,,,,,,,,,,,
402.642,1.41678,0.71625,10,,,,,,,,,,,,,,,,,,,,,,,,,,,,,,,,,,,,,
403.342,1.41701,0.73584,10,,,,,,,,,,,,,,,,,,,,,,,,,,,,,,,,,,,,,
404.042,1.41712,0.75244,10,,,,,,,,,,,,,,,,,,,,,,,,,,,,,,,,,,,,,
404.742,1.41701,0.76608,10,,,,,,,,,,,,,,,,,,,,,,,,,,,,,,,,,,,,,
405.442,1.41701,0.70417,10,,,,,,,,,,,,,,,,,,,,,,,,,,,,,,,,,,,,,
406.142,1.41701,0.74444,10,,,,,,,,,,,,,,,,,,,,,,,,,,,,,,,,,,,,,
406.842,1.41695,0.79237,10,,,,,,,,,,,,,,,,,,,,,,,,,,,,,,,,,,,,,
407.542,1.41678,0.80221,10,,,,,,,,,,,,,,,,,,,,,,,,,,,,,,,,,,,,,
408.242,1.41678,0.72624,10,,,,,,,,,,,,,,,,,,,,,,,,,,,,,,,,,,,,,
408.942,1.41672,0.76754,10,,,,,,,,,,,,,,,,,,,,,,,,,,,,,,,,,,,,,
409.642,1.41661,0.77745,10,,,,,,,,,,,,,,,,,,,,,,,,,,,,,,,,,,,,,
410.342,1.41633,0.73635,10,,,,,,,,,,,,,,,,,,,,,,,,,,,,,,,,,,,,,
411.042,1.41593,0.77623,10,,,,,,,,,,,,,,,,,,,,,,,,,,,,,,,,,,,,,
411.742,1.41497,0.74663,10,,,,,,,,,,,,,,,,,,,,,,,,,,,,,,,,,,,,,
412.442,1.41412,0.76996,10,,,,,,,,,,,,,,,,,,,,,,,,,,,,,,,,,,,,,
413.142,1.41287,0.7715,10,,,,,,,,,,,,,,,,,,,,,,,,,,,,,,,,,,,,,
413.842,1.41213,0.74715,10,,,,,,,,,,,,,,,,,,,,,,,,,,,,,,,,,,,,,
414.542,1.41174,0.74842,10,,,,,,,,,,,,,,,,,,,,,,,,,,,,,,,,,,,,,
415.242,1.41111,0.74148,10,,,,,,,,,,,,,,,,,,,,,,,,,,,,,,,,,,,,,
415.942,1.40998,0.75373,10,,,,,,,,,,,,,,,,,,,,,,,,,,,,,,,,,,,,,
416.642,1.40924,0.71609,10,,,,,,,,,,,,,,,,,,,,,,,,,,,,,,,,,,,,,
417.342,1.4089,0.7034,10,,,,,,,,,,,,,,,,,,,,,,,,,,,,,,,,,,,,,
418.042,1.40868,0.73021,10,,,,,,,,,,,,,,,,,,,,,,,,,,,,,,,,,,,,,
418.742,1.40862,0.66831,10,,,,,,,,,,,,,,,,,,,,,,,,,,,,,,,,,,,,,
419.442,1.40873,0.74973,10,,,,,,,,,,,,,,,,,,,,,,,,,,,,,,,,,,,,,
420.142,1.40873,0.66946,10,,,,,,,,,,,,,,,,,,,,,,,,,,,,,,,,,,,,,
420.842,1.40885,0.69398,10,,,,,,,,,,,,,,,,,,,,,,,,,,,,,,,,,,,,,
421.542,1.40885,0.73683,10,,,,,,,,,,,,,,,,,,,,,,,,,,,,,,,,,,,,,
422.242,1.4089,0.76026,10,,,,,,,,,,,,,,,,,,,,,,,,,,,,,,,,,,,,,
422.942,1.40896,0.70919,10,,,,,,,,,,,,,,,,,,,,,,,,,,,,,,,,,,,,,
423.642,1.40902,0.67407,10,,,,,,,,,,,,,,,,,,,,,,,,,,,,,,,,,,,,,
424.342,1.40907,0.67598,10,,,,,,,,,,,,,,,,,,,,,,,,,,,,,,,,,,,,,
425.042,1.40913,0.69523,10,,,,,,,,,,,,,,,,,,,,,,,,,,,,,,,,,,,,,
425.742,1.40941,0.63844,10,,,,,,,,,,,,,,,,,,,,,,,,,,,,,,,,,,,,,
426.442,1.40981,0.68191,10,,,,,,,,,,,,,,,,,,,,,,,,,,,,,,,,,,,,,
427.142,1.41032,0.68301,10,,,,,,,,,,,,,,,,,,,,,,,,,,,,,,,,,,,,,
427.842,1.41083,0.66689,10,,,,,,,,,,,,,,,,,,,,,,,,,,,,,,,,,,,,,
428.542,1.41191,0.71117,10,,,,,,,,,,,,,,,,,,,,,,,,,,,,,,,,,,,,,
429.242,1.41366,0.71173,10,,,,,,,,,,,,,,,,,,,,,,,,,,,,,,,,,,,,,
429.942,1.41576,0.72891,10,,,,,,,,,,,,,,,,,,,,,,,,,,,,,,,,,,,,,
430.642,1.4165,0.77768,10,,,,,,,,,,,,,,,,,,,,,,,,,,,,,,,,,,,,,
431.342,1.41661,0.71437,10,,,,,,,,,,,,,,,,,,,,,,,,,,,,,,,,,,,,,
432.042,1.41655,0.73924,10,,,,,,,,,,,,,,,,,,,,,,,,,,,,,,,,,,,,,
432.742,1.41661,0.81506,10,,,,,,,,,,,,,,,,,,,,,,,,,,,,,,,,,,,,,
433.442,1.4165,0.75749,10,,,,,,,,,,,,,,,,,,,,,,,,,,,,,,,,,,,,,
434.142,1.41644,0.705,10,,,,,,,,,,,,,,,,,,,,,,,,,,,,,,,,,,,,,
434.842,1.41633,0.7344,10,,,,,,,,,,,,,,,,,,,,,,,,,,,,,,,,,,,,,
435.542,1.41633,0.72925,10,,,,,,,,,,,,,,,,,,,,,,,,,,,,,,,,,,,,,
436.242,1.41616,0.72296,10,,,,,,,,,,,,,,,,,,,,,,,,,,,,,,,,,,,,,
436.942,1.41593,0.77366,10,,,,,,,,,,,,,,,,,,,,,,,,,,,,,,,,,,,,,
437.642,1.41553,0.75961,10,,,,,,,,,,,,,,,,,,,,,,,,,,,,,,,,,,,,,
438.342,1.41491,0.79403,10,,,,,,,,,,,,,,,,,,,,,,,,,,,,,,,,,,,,,
439.042,1.41366,0.77449,10,,,,,,,,,,,,,,,,,,,,,,,,,,,,,,,,,,,,,
439.742,1.41259,0.74432,10,,,,,,,,,,,,,,,,,,,,,,,,,,,,,,,,,,,,,
440.442,1.41185,0.73281,10,,,,,,,,,,,,,,,,,,,,,,,,,,,,,,,,,,,,,
441.142,1.41128,0.7309,10,,,,,,,,,,,,,,,,,,,,,,,,,,,,,,,,,,,,,
441.842,1.41077,0.7551,10,,,,,,,,,,,,,,,,,,,,,,,,,,,,,,,,,,,,,
442.542,1.41015,0.74919,10,,,,,,,,,,,,,,,,,,,,,,,,,,,,,,,,,,,,,
443.242,1.40975,0.73675,10,,,,,,,,,,,,,,,,,,,,,,,,,,,,,,,,,,,,,
443.942,1.40958,0.73329,10,,,,,,,,,,,,,,,,,,,,,,,,,,,,,,,,,,,,,
444.642,1.40958,0.69866,10,,,,,,,,,,,,,,,,,,,,,,,,,,,,,,,,,,,,,
445.342,1.40958,0.69296,10,,,,,,,,,,,,,,,,,,,,,,,,,,,,,,,,,,,,,
446.042,1.40964,0.69542,10,,,,,,,,,,,,,,,,,,,,,,,,,,,,,,,,,,,,,
446.742,1.4097,0.70303,10,,,,,,,,,,,,,,,,,,,,,,,,,,,,,,,,,,,,,
447.442,1.40975,0.7298,10,,,,,,,,,,,,,,,,,,,,,,,,,,,,,,,,,,,,,
448.142,1.40981,0.68079,10,,,,,,,,,,,,,,,,,,,,,,,,,,,,,,,,,,,,,
448.842,1.40992,0.65059,10,,,,,,,,,,,,,,,,,,,,,,,,,,,,,,,,,,,,,
449.542,1.40998,0.66059,10,,,,,,,,,,,,,,,,,,,,,,,,,,,,,,,,,,,,,
450.242,1.41015,0.67781,10,,,,,,,,,,,,,,,,,,,,,,,,,,,,,,,,,,,,,
450.942,1.41049,0.69803,10,,,,,,,,,,,,,,,,,,,,,,,,,,,,,,,,,,,,,
451.642,1.41083,0.72516,10,,,,,,,,,,,,,,,,,,,,,,,,,,,,,,,,,,,,,
452.342,1.4114,0.6767,10,,,,,,,,,,,,,,,,,,,,,,,,,,,,,,,,,,,,,
453.042,1.41259,0.67053,10,,,,,,,,,,,,,,,,,,,,,,,,,,,,,,,,,,,,,
453.742,1.4148,0.71184,10,,,,,,,,,,,,,,,,,,,,,,,,,,,,,,,,,,,,,
454.442,1.41621,0.74187,10,,,,,,,,,,,,,,,,,,,,,,,,,,,,,,,,,,,,,
455.142,1.41661,0.75647,10,,,,,,,,,,,,,,,,,,,,,,,,,,,,,,,,,,,,,
455.842,1.41678,0.75413,10,,,,,,,,,,,,,,,,,,,,,,,,,,,,,,,,,,,,,
456.542,1.41684,0.7723,10,,,,,,,,,,,,,,,,,,,,,,,,,,,,,,,,,,,,,
457.242,1.41672,0.7659,10,,,,,,,,,,,,,,,,,,,,,,,,,,,,,,,,,,,,,
457.942,1.41672,0.72719,10,,,,,,,,,,,,,,,,,,,,,,,,,,,,,,,,,,,,,
458.642,1.41667,0.79095,10,,,,,,,,,,,,,,,,,,,,,,,,,,,,,,,,,,,,,
459.342,1.41667,0.72713,10,,,,,,,,,,,,,,,,,,,,,,,,,,,,,,,,,,,,,
460.042,1.41672,0.78546,10,,,,,,,,,,,,,,,,,,,,,,,,,,,,,,,,,,,,,
460.742,1.41655,0.7498,10,,,,,,,,,,,,,,,,,,,,,,,,,,,,,,,,,,,,,
461.442,1.4165,0.76224,10,,,,,,,,,,,,,,,,,,,,,,,,,,,,,,,,,,,,,
462.142,1.41644,0.69064,10,,,,,,,,,,,,,,,,,,,,,,,,,,,,,,,,,,,,,
462.842,1.41638,0.7541,10,,,,,,,,,,,,,,,,,,,,,,,,,,,,,,,,,,,,,
463.542,1.41627,0.73334,10,,,,,,,,,,,,,,,,,,,,,,,,,,,,,,,,,,,,,
464.242,1.4161,0.80394,10,,,,,,,,,,,,,,,,,,,,,,,,,,,,,,,,,,,,,
464.942,1.4157,0.82513,10,,,,,,,,,,,,,,,,,,,,,,,,,,,,,,,,,,,,,
465.642,1.41514,0.77986,10,,,,,,,,,,,,,,,,,,,,,,,,,,,,,,,,,,,,,
466.342,1.41457,0.81287,10,,,,,,,,,,,,,,,,,,,,,,,,,,,,,,,,,,,,,
467.042,1.41395,0.74165,10,,,,,,,,,,,,,,,,,,,,,,,,,,,,,,,,,,,,,
467.742,1.41332,0.71635,10,,,,,,,,,,,,,,,,,,,,,,,,,,,,,,,,,,,,,
468.442,1.41276,0.78209,10,,,,,,,,,,,,,,,,,,,,,,,,,,,,,,,,,,,,,
469.142,1.41236,0.7525,10,,,,,,,,,,,,,,,,,,,,,,,,,,,,,,,,,,,,,
469.842,1.41225,0.70752,10,,,,,,,,,,,,,,,,,,,,,,,,,,,,,,,,,,,,,
470.542,1.4123,0.65467,10,,,,,,,,,,,,,,,,,,,,,,,,,,,,,,,,,,,,,
471.242,1.4123,0.70846,10,,,,,,,,,,,,,,,,,,,,,,,,,,,,,,,,,,,,,
471.942,1.41236,0.74919,10,,,,,,,,,,,,,,,,,,,,,,,,,,,,,,,,,,,,,
472.642,1.41242,0.71711,10,,,,,,,,,,,,,,,,,,,,,,,,,,,,,,,,,,,,,
473.342,1.41242,0.6857,10,,,,,,,,,,,,,,,,,,,,,,,,,,,,,,,,,,,,,
474.042,1.41247,0.70371,10,,,,,,,,,,,,,,,,,,,,,,,,,,,,,,,,,,,,,
474.742,1.41259,0.65358,10,,,,,,,,,,,,,,,,,,,,,,,,,,,,,,,,,,,,,
475.442,1.41276,0.72716,10,,,,,,,,,,,,,,,,,,,,,,,,,,,,,,,,,,,,,
476.142,1.41293,0.64278,10,,,,,,,,,,,,,,,,,,,,,,,,,,,,,,,,,,,,,
476.842,1.41338,0.71002,10,,,,,,,,,,,,,,,,,,,,,,,,,,,,,,,,,,,,,
477.542,1.41383,0.69488,10,,,,,,,,,,,,,,,,,,,,,,,,,,,,,,,,,,,,,
478.242,1.41491,0.68783,10,,,,,,,,,,,,,,,,,,,,,,,,,,,,,,,,,,,,,
478.942,1.41627,0.71469,10,,,,,,,,,,,,,,,,,,,,,,,,,,,,,,,,,,,,,
479.642,1.41684,0.74474,10,,,,,,,,,,,,,,,,,,,,,,,,,,,,,,,,,,,,,
480.342,1.41729,0.7123,10,,,,,,,,,,,,,,,,,,,,,,,,,,,,,,,,,,,,,
481.042,1.41757,0.71813,10,,,,,,,,,,,,,,,,,,,,,,,,,,,,,,,,,,,,,
481.742,1.41774,0.7126,10,,,,,,,,,,,,,,,,,,,,,,,,,,,,,,,,,,,,,
482.442,1.41786,0.73693,10,,,,,,,,,,,,,,,,,,,,,,,,,,,,,,,,,,,,,
483.142,1.41791,0.77625,10,,,,,,,,,,,,,,,,,,,,,,,,,,,,,,,,,,,,,
483.842,1.4178,0.74287,10,,,,,,,,,,,,,,,,,,,,,,,,,,,,,,,,,,,,,
484.542,1.4178,0.76372,10,,,,,,,,,,,,,,,,,,,,,,,,,,,,,,,,,,,,,
485.242,1.4178,0.73219,10,,,,,,,,,,,,,,,,,,,,,,,,,,,,,,,,,,,,,
485.942,1.4178,0.77222,10,,,,,,,,,,,,,,,,,,,,,,,,,,,,,,,,,,,,,
486.642,1.4178,0.86507,10,,,,,,,,,,,,,,,,,,,,,,,,,,,,,,,,,,,,,
487.342,1.4178,0.71131,10,,,,,,,,,,,,,,,,,,,,,,,,,,,,,,,,,,,,,
488.042,1.4178,0.71422,10,,,,,,,,,,,,,,,,,,,,,,,,,,,,,,,,,,,,,
488.742,1.41769,0.74721,10,,,,,,,,,,,,,,,,,,,,,,,,,,,,,,,,,,,,,
489.442,1.41763,0.77559,10,,,,,,,,,,,,,,,,,,,,,,,,,,,,,,,,,,,,,
490.142,1.41763,0.67297,10,,,,,,,,,,,,,,,,,,,,,,,,,,,,,,,,,,,,,
490.842,1.41757,0.76073,10,,,,,,,,,,,,,,,,,,,,,,,,,,,,,,,,,,,,,
491.542,1.41757,0.753,10,,,,,,,,,,,,,,,,,,,,,,,,,,,,,,,,,,,,,
492.242,1.41757,0.67385,10,,,,,,,,,,,,,,,,,,,,,,,,,,,,,,,,,,,,,
492.942,1.41752,0.79469,10,,,,,,,,,,,,,,,,,,,,,,,,,,,,,,,,,,,,,
493.642,1.41746,0.8177,10,,,,,,,,,,,,,,,,,,,,,,,,,,,,,,,,,,,,,
494.342,1.41746,0.69799,10,,,,,,,,,,,,,,,,,,,,,,,,,,,,,,,,,,,,,
495.042,1.41746,0.71664,10,,,,,,,,,,,,,,,,,,,,,,,,,,,,,,,,,,,,,
495.742,1.41746,0.70432,10,,,,,,,,,,,,,,,,,,,,,,,,,,,,,,,,,,,,,
496.442,1.41746,0.74051,10,,,,,,,,,,,,,,,,,,,,,,,,,,,,,,,,,,,,,
497.142,1.4174,0.74767,10,,,,,,,,,,,,,,,,,,,,,,,,,,,,,,,,,,,,,
497.842,1.4174,0.69728,10,,,,,,,,,,,,,,,,,,,,,,,,,,,,,,,,,,,,,
498.542,1.41723,0.72208,10,,,,,,,,,,,,,,,,,,,,,,,,,,,,,,,,,,,,,
499.242,1.41712,0.77402,10,,,,,,,,,,,,,,,,,,,,,,,,,,,,,,,,,,,,,
499.942,1.41695,0.76658,10,,,,,,,,,,,,,,,,,,,,,,,,,,,,,,,,,,,,,
500.642,1.41678,0.73645,10,,,,,,,,,,,,,,,,,,,,,,,,,,,,,,,,,,,,,
501.342,1.41644,0.71331,10,,,,,,,,,,,,,,,,,,,,,,,,,,,,,,,,,,,,,
502.042,1.41587,0.7535,10,,,,,,,,,,,,,,,,,,,,,,,,,,,,,,,,,,,,,
502.742,1.41542,0.69496,10,,,,,,,,,,,,,,,,,,,,,,,,,,,,,,,,,,,,,
503.442,1.41508,0.73923,10,,,,,,,,,,,,,,,,,,,,,,,,,,,,,,,,,,,,,
504.142,1.41485,0.74106,10,,,,,,,,,,,,,,,,,,,,,,,,,,,,,,,,,,,,,
504.842,1.41457,0.70896,10,,,,,,,,,,,,,,,,,,,,,,,,,,,,,,,,,,,,,
505.542,1.41446,0.73642,10,,,,,,,,,,,,,,,,,,,,,,,,,,,,,,,,,,,,,
506.242,1.41406,0.76487,10,,,,,,,,,,,,,,,,,,,,,,,,,,,,,,,,,,,,,
506.942,1.41378,0.73967,10,,,,,,,,,,,,,,,,,,,,,,,,,,,,,,,,,,,,,
507.642,1.41372,0.71569,10,,,,,,,,,,,,,,,,,,,,,,,,,,,,,,,,,,,,,
508.342,1.41366,0.66637,10,,,,,,,,,,,,,,,,,,,,,,,,,,,,,,,,,,,,,
509.042,1.41378,0.71107,10,,,,,,,,,,,,,,,,,,,,,,,,,,,,,,,,,,,,,
509.742,1.41372,0.7088,10,,,,,,,,,,,,,,,,,,,,,,,,,,,,,,,,,,,,,
510.442,1.41383,0.72916,10,,,,,,,,,,,,,,,,,,,,,,,,,,,,,,,,,,,,,
511.142,1.41378,0.69196,10,,,,,,,,,,,,,,,,,,,,,,,,,,,,,,,,,,,,,
511.842,1.41395,0.7113,10,,,,,,,,,,,,,,,,,,,,,,,,,,,,,,,,,,,,,
512.542,1.414,0.68226,10,,,,,,,,,,,,,,,,,,,,,,,,,,,,,,,,,,,,,
513.242,1.41412,0.64866,10,,,,,,,,,,,,,,,,,,,,,,,,,,,,,,,,,,,,,
513.942,1.41429,0.70043,10,,,,,,,,,,,,,,,,,,,,,,,,,,,,,,,,,,,,,
514.642,1.41446,0.70332,10,,,,,,,,,,,,,,,,,,,,,,,,,,,,,,,,,,,,,
515.342,1.4148,0.63876,10,,,,,,,,,,,,,,,,,,,,,,,,,,,,,,,,,,,,,
516.042,1.41548,0.70516,10,,,,,,,,,,,,,,,,,,,,,,,,,,,,,,,,,,,,,
516.742,1.4161,0.71025,10,,,,,,,,,,,,,,,,,,,,,,,,,,,,,,,,,,,,,
517.442,1.41672,0.72523,10,,,,,,,,,,,,,,,,,,,,,,,,,,,,,,,,,,,,,
518.142,1.41763,0.67137,10,,,,,,,,,,,,,,,,,,,,,,,,,,,,,,,,,,,,,
518.842,1.4182,0.69312,10,,,,,,,,,,,,,,,,,,,,,,,,,,,,,,,,,,,,,
519.542,1.41882,0.71707,10,,,,,,,,,,,,,,,,,,,,,,,,,,,,,,,,,,,,,
520.144,6.21883,174.87137,10,,,,,,,,,,,,,,,,,,,,,,,,,,,,,,,,,,,,,
520.844,12.05226,463.83405,10,,,,,,,,,,,,,,,,,,,,,,,,,,,,,,,,,,,,,
521.544,17.88553,229.66257,10,,,,,,,,,,,,,,,,,,,,,,,,,,,,,,,,,,,,,
522.244,23.71879,37.30125,10,,,,,,,,,,,,,,,,,,,,,,,,,,,,,,,,,,,,,
522.944,29.55212,2.48424,10,,,,,,,,,,,,,,,,,,,,,,,,,,,,,,,,,,,,,
523.644,35.3855,-5.03414,10,,,,,,,,,,,,,,,,,,,,,,,,,,,,,,,,,,,,,
524.344,41.21888,-6.3515,10,,,,,,,,,,,,,,,,,,,,,,,,,,,,,,,,,,,,,
525.044,47.0522,-6.52928,10,,,,,,,,,,,,,,,,,,,,,,,,,,,,,,,,,,,,,
525.744,52.88552,-6.48031,10,,,,,,,,,,,,,,,,,,,,,,,,,,,,,,,,,,,,,
526.444,58.71879,-6.47635,10,,,,,,,,,,,,,,,,,,,,,,,,,,,,,,,,,,,,,
526.664,60.55219,-6.49822,10,,,,,,,,,,,,,,,,,,,,,,,,,,,,,,,,,,,,,