File: combined_ligament_solver/data/processed/Data Sheet 3_S152718_PCL.csv
Specimen properties : Length,31,mm,Unnamed: 3,Unnamed: 4,Unnamed: 5,Unnamed: 6,Unnamed: 7,Unnamed: 8,Unnamed: 9,Unnamed: 10,Unnamed: 11,Stress-Strain,Unnamed: 13,Unnamed: 14,Unnamed: 15,Unnamed: 16,Unnamed: 17,Unnamed: 18,Unnamed: 19,Unnamed: 20,Unnamed: 21,Unnamed: 22,Unnamed: 23,Unnamed: 24,Unnamed: 25,Unnamed: 26,Unnamed: 27,Linear,Unnamed: 29,Unnamed: 30,Unnamed: 31,Unnamed: 32,Unnamed: 33,Modulus,Unnamed: 35,Failure,Unnamed: 37,Unnamed: 38,Unnamed: 39,Unnamed: 40
Cross Section Average,91.3365,mm2,,,,,,,,,,Polynomial Coefficients,,,,,,,,,,,,,,,,Force,,Stress,Extension,Strain,,Secant,Tangent,Load,Stress,Extension,Strain,Stiffness
Time,Extension,Load,Total cycle count,,,Extension,Load,Strain,Stress,E-tan,,X6,-351353.2398752706,,,,,,,,,Strain,Stress,E-tan,,,,(N),,(MPa),(mm),(%),,(MPa),(MPa),(N),(MPa),(mm),(%),(N/mm)
(s),(mm),(N),,,,(mm),(N),(mm/mm),(MPa),(MPa),,X5,188805.2515671974,,,,,,,,,(mm/mm),(MPa),(MPa),,,,873.6437718157691,,9.56511112004258,4.2780000000000005,13.8,,69.3123994205984,113.39864982145353,1432.70374,15.677215899448742,6.51655,21.021129032258063,204.21780547353177
0.5,0.11577,3.83808,0,,,4.19736,791.67352,0.1295638709677419,8.658880184811112,110.22468107518687,,,,,,,,,,,,0.005,0.012414292962914882,4.298936147467767,,,,,,,,,,,,,,,,
1.1,0.21562,7.5763,0,,,9.19751,1058.45569,,,,,,,,,,,,,,,0.011,0.0588367375360457,10.282080911941362,,,,,,,,,,,,,,,,
1.7,0.31546,11.74683,0,,,14.19755,154.3833,,,,,,,,,,,,,,,0.017,0.14316054423268607,16.8110821756713,,,,,,,,,,,,,,,,
2.3,0.41565,16.50816,0,,,19.19748,103.77398,,,,,,,,,,,,,,,0.023,0.2680304557136063,23.709290165957857,,,,,,,,,,,,,,,,
2.9,0.51572,21.96578,0,,,24.19751,55.86561,,,,,,,,,,,,,,,0.029,0.43511610910993204,30.824008499694436,,,,,,,,,,,,,,,,
3.5,0.61568,27.96848,0,,,,,,,,,,,,,,,,,,,0.035,0.6452488714112631,38.024527054956366,,,,,,,,,,,,,,,,
4.1,0.71553,34.31038,0,,,,,,,,,,,,,,,,,,,0.041,0.8985468720833258,45.20015484258939,,,,,,,,,,,,,,,,
4.57,0.79407,40.03259,0.5,,,,,,,,,,,,,,,,,,,0.047,1.1945282329151592,52.25825287779923,,,,,,,,,,,,,,,,
5.17,0.69371,30.43286,0.5,,,,,,,,,,,,,,,,,,,0.053,1.5322124950958333,59.12226705174012,,,,,,,,,,,,,,,,
5.77,0.5937,22.5524,0.5,,,,,,,,,,,,,,,,,,,0.059,1.9102102435206993,65.7297610031033,,,,,,,,,,,,,,,,
6.37,0.49362,16.19914,0.5,,,,,,,,,,,,,,,,,,,0.065,2.326800928327177,72.03044898970606,,,,,,,,,,,,,,,,
6.97,0.39366,10.96688,0.5,,,,,,,,,,,,,,,,,,,0.071,2.7799988836600678,77.98422876008019,,,,,,,,,,,,,,,,
7.57,0.2937,6.67261,0.5,,,,,,,,,,,,,,,,,,,0.077,3.2676075436664136,83.55921442506312,,,,,,,,,,,,,,,,
8.17,0.19369,3.13012,0.5,,,,,,,,,,,,,,,,,,,0.083,3.7872618557198714,88.72976932938306,,,,,,,,,,,,,,,,
8.592,0.12331,0.97521,1,,,,,,,,,,,,,,,,,,,0.089,4.336458890874635,93.47453892325133,,,,,,,,,,,,,,,,
9.094,0.20712,3.91601,1,,,,,,,,,,,,,,,,,,,0.095,4.9125766515488865,97.77448363394637,,,,,,,,,,,,,,,,
9.694,0.30725,8.13923,1,,,,,,,,,,,,,,,,,,,0.101,5.512881076437777,101.61091173741077,,,,,,,,,,,,,,,,
10.294,0.40732,12.89516,1,,,,,,,,,,,,,,,,,,,0.107,6.134521242655942,104.96351222983326,,,,,,,,,,,,,,,,
10.894,0.50734,18.22284,1,,,,,,,,,,,,,,,,,,,0.113,6.774512765109553,107.80838769923561,,,,,,,,,,,,,,,,
11.494,0.60718,24.52674,1,,,,,,,,,,,,,,,,,,,0.119,7.4297093930978955,110.11608719706777,,,,,,,,,,,,,,,,
12.094,0.70731,31.55605,1,,,,,,,,,,,,,,,,,,,0.125,8.096762804144495,111.84963910979818,,,,,,,,,,,,,,,,
12.694,0.80727,39.44176,1,,,,,,,,,,,,,,,,,,,0.131,8.77207059505775,112.9625840304963,,,,,,,,,,,,,,,,
13.142,0.7484,33.76683,1.5,,,,,,,,,,,,,,,,,,,0.137,9.451712470221127,113.39700763041616,,,,,,,,,,,,,,,,
13.742,0.64838,25.10907,1.5,,,,,,,,,,,,,,,,,,,0.143,10.131374627112864,113.08157353061243,,,,,,,,,,,,,,,,
14.342,0.54825,18.26041,1.5,,,,,,,,,,,,,,,,,,,0.149,10.806262339055232,111.92955617348044,,,,,,,,,,,,,,,,
14.942,0.44835,12.59553,1.5,,,,,,,,,,,,,,,,,,,0.155,11.471000735193302,109.83687369440875,,,,,,,,,,,,,,,,
15.542,0.34833,8.02135,1.5,,,,,,,,,,,,,,,,,,,0.161,12.119523777703257,106.68012079329249,,,,,,,,,,,,,,,,
16.142,0.24837,4.17208,1.5,,,,,,,,,,,,,,,,,,,0.167,12.744951436230272,102.31460160621698,,,,,,,,,,,,,,,,
16.742,0.14818,1.0612,1.5,,,,,,,,,,,,,,,,,,,0.173,13.33945505955584,96.57236257694449,,,,,,,,,,,,,,,,
17.068,0.19482,2.62168,2,,,,,,,,,,,,,,,,,,,0.179,13.89411094449473,89.26022532857472,,,,,,,,,,,,,,,,
17.668,0.29489,6.601,2,,,,,,,,,,,,,,,,,,,0.185,14.398742102021398,80.15781953508842,,,,,,,,,,,,,,,,
18.268,0.39514,11.29205,2,,,,,,,,,,,,,,,,,,,0.191,14.841748220626027,69.01561579300436,,,,,,,,,,,,,,,,
18.868,0.49487,16.46197,2,,,,,,,,,,,,,,,,,,,0.197,15.209923826899933,55.55295849286951,,,,,,,,,,,,,,,,
19.468,0.59483,22.54838,2,,,,,,,,,,,,,,,,,,,,,,,,,,,,,,,,,,,,,
20.068,0.6949,29.44421,2,,,,,,,,,,,,,,,,,,,,,,,,,,,,,,,,,,,,,
20.668,0.79509,37.26588,2,,,,,,,,,,,,,,,,,,,,,,,,,,,,,,,,,,,,,
21.166,0.77775,35.41533,2.5,,,,,,,,,,,,,,,,,,,,,,,,,,,,,,,,,,,,,
21.766,0.67773,26.43431,2.5,,,,,,,,,,,,,,,,,,,,,,,,,,,,,,,,,,,,,
22.366,0.57772,19.25954,2.5,,,,,,,,,,,,,,,,,,,,,,,,,,,,,,,,,,,,,
22.966,0.47764,13.44463,2.5,,,,,,,,,,,,,,,,,,,,,,,,,,,,,,,,,,,,,
23.566,0.37751,8.68189,2.5,,,,,,,,,,,,,,,,,,,,,,,,,,,,,,,,,,,,,
24.166,0.27767,4.78014,2.5,,,,,,,,,,,,,,,,,,,,,,,,,,,,,,,,,,,,,
24.766,0.17759,1.45874,2.5,,,,,,,,,,,,,,,,,,,,,,,,,,,,,,,,,,,,,
25.164,0.21222,2.71862,3,,,,,,,,,,,,,,,,,,,,,,,,,,,,,,,,,,,,,
25.764,0.31223,6.73474,3,,,,,,,,,,,,,,,,,,,,,,,,,,,,,,,,,,,,,
26.364,0.41219,11.3752,3,,,,,,,,,,,,,,,,,,,,,,,,,,,,,,,,,,,,,
26.964,0.51238,16.69871,3,,,,,,,,,,,,,,,,,,,,,,,,,,,,,,,,,,,,,
27.564,0.61228,22.88829,3,,,,,,,,,,,,,,,,,,,,,,,,,,,,,,,,,,,,,
28.164,0.71219,29.85922,3,,,,,,,,,,,,,,,,,,,,,,,,,,,,,,,,,,,,,
28.764,0.8122,37.87582,3,,,,,,,,,,,,,,,,,,,,,,,,,,,,,,,,,,,,,
29.214,0.7871,35.33736,3.5,,,,,,,,,,,,,,,,,,,,,,,,,,,,,,,,,,,,,
29.814,0.68703,26.3813,3.5,,,,,,,,,,,,,,,,,,,,,,,,,,,,,,,,,,,,,
30.414,0.58701,19.2059,3.5,,,,,,,,,,,,,,,,,,,,,,,,,,,,,,,,,,,,,
31.014,0.48688,13.39601,3.5,,,,,,,,,,,,,,,,,,,,,,,,,,,,,,,,,,,,,
31.614,0.38698,8.55303,3.5,,,,,,,,,,,,,,,,,,,,,,,,,,,,,,,,,,,,,
32.214,0.28696,4.61309,3.5,,,,,,,,,,,,,,,,,,,,,,,,,,,,,,,,,,,,,
32.814,0.18694,1.36112,3.5,,,,,,,,,,,,,,,,,,,,,,,,,,,,,,,,,,,,,
33.202,0.22332,2.58266,4,,,,,,,,,,,,,,,,,,,,,,,,,,,,,,,,,,,,,
33.802,0.32317,6.78707,4,,,,,,,,,,,,,,,,,,,,,,,,,,,,,,,,,,,,,
34.402,0.42324,11.40243,4,,,,,,,,,,,,,,,,,,,,,,,,,,,,,,,,,,,,,
35.002,0.52326,16.75061,4,,,,,,,,,,,,,,,,,,,,,,,,,,,,,,,,,,,,,
35.602,0.62339,22.93167,4,,,,,,,,,,,,,,,,,,,,,,,,,,,,,,,,,,,,,
36.202,0.72324,29.99836,4,,,,,,,,,,,,,,,,,,,,,,,,,,,,,,,,,,,,,
36.802,0.82325,38.10265,4,,,,,,,,,,,,,,,,,,,,,,,,,,,,,,,,,,,,,
37.234,0.79509,35.38068,4.5,,,,,,,,,,,,,,,,,,,,,,,,,,,,,,,,,,,,,
37.834,0.69507,26.38769,4.5,,,,,,,,,,,,,,,,,,,,,,,,,,,,,,,,,,,,,
38.434,0.59506,19.16984,4.5,,,,,,,,,,,,,,,,,,,,,,,,,,,,,,,,,,,,,
39.034,0.49493,13.34615,4.5,,,,,,,,,,,,,,,,,,,,,,,,,,,,,,,,,,,,,
39.634,0.39502,8.47493,4.5,,,,,,,,,,,,,,,,,,,,,,,,,,,,,,,,,,,,,
40.234,0.29501,4.59288,4.5,,,,,,,,,,,,,,,,,,,,,,,,,,,,,,,,,,,,,
40.834,0.19505,1.27904,4.5,,,,,,,,,,,,,,,,,,,,,,,,,,,,,,,,,,,,,
41.202,0.2346,2.61414,5,,,,,,,,,,,,,,,,,,,,,,,,,,,,,,,,,,,,,
41.802,0.33467,6.75933,5,,,,,,,,,,,,,,,,,,,,,,,,,,,,,,,,,,,,,
42.402,0.43452,11.4731,5,,,,,,,,,,,,,,,,,,,,,,,,,,,,,,,,,,,,,
43.002,0.53459,16.94075,5,,,,,,,,,,,,,,,,,,,,,,,,,,,,,,,,,,,,,
43.602,0.63461,23.17783,5,,,,,,,,,,,,,,,,,,,,,,,,,,,,,,,,,,,,,
44.202,0.73468,30.32802,5,,,,,,,,,,,,,,,,,,,,,,,,,,,,,,,,,,,,,
44.802,0.83464,38.50636,5,,,,,,,,,,,,,,,,,,,,,,,,,,,,,,,,,,,,,
45.302,0.78432,33.6354,5.5,,,,,,,,,,,,,,,,,,,,,,,,,,,,,,,,,,,,,
45.902,0.68436,25.05296,5.5,,,,,,,,,,,,,,,,,,,,,,,,,,,,,,,,,,,,,
46.502,0.5844,18.07049,5.5,,,,,,,,,,,,,,,,,,,,,,,,,,,,,,,,,,,,,
47.102,0.48427,12.39119,5.5,,,,,,,,,,,,,,,,,,,,,,,,,,,,,,,,,,,,,
47.702,0.3842,7.73335,5.5,,,,,,,,,,,,,,,,,,,,,,,,,,,,,,,,,,,,,
48.302,0.2843,3.91336,5.5,,,,,,,,,,,,,,,,,,,,,,,,,,,,,,,,,,,,,
48.85,0.19301,0.99017,6,,,,,,,,,,,,,,,,,,,,,,,,,,,,,,,,,,,,,
49.254,0.25982,3.26547,6,,,,,,,,,,,,,,,,,,,,,,,,,,,,,,,,,,,,,
49.854,0.35989,7.53708,6,,,,,,,,,,,,,,,,,,,,,,,,,,,,,,,,,,,,,
50.454,0.46002,12.36286,6,,,,,,,,,,,,,,,,,,,,,,,,,,,,,,,,,,,,,
51.054,0.55998,17.92939,6,,,,,,,,,,,,,,,,,,,,,,,,,,,,,,,,,,,,,
51.654,0.65988,24.35676,6,,,,,,,,,,,,,,,,,,,,,,,,,,,,,,,,,,,,,
52.254,0.7599,31.77317,6,,,,,,,,,,,,,,,,,,,,,,,,,,,,,,,,,,,,,
52.842,0.85799,40.0268,6.5,,,,,,,,,,,,,,,,,,,,,,,,,,,,,,,,,,,,,
53.344,0.77463,32.14428,6.5,,,,,,,,,,,,,,,,,,,,,,,,,,,,,,,,,,,,,
53.944,0.67467,23.79712,6.5,,,,,,,,,,,,,,,,,,,,,,,,,,,,,,,,,,,,,
54.544,0.57466,17.083,6.5,,,,,,,,,,,,,,,,,,,,,,,,,,,,,,,,,,,,,
55.144,0.4747,11.58359,6.5,,,,,,,,,,,,,,,,,,,,,,,,,,,,,,,,,,,,,
55.744,0.37451,6.99419,6.5,,,,,,,,,,,,,,,,,,,,,,,,,,,,,,,,,,,,,
56.344,0.27461,3.24504,6.5,,,,,,,,,,,,,,,,,,,,,,,,,,,,,,,,,,,,,
56.79,0.2002,0.97623,7,,,,,,,,,,,,,,,,,,,,,,,,,,,,,,,,,,,,,
57.292,0.28441,4.01065,7,,,,,,,,,,,,,,,,,,,,,,,,,,,,,,,,,,,,,
57.892,0.38431,8.33963,7,,,,,,,,,,,,,,,,,,,,,,,,,,,,,,,,,,,,,
58.492,0.48422,13.32509,7,,,,,,,,,,,,,,,,,,,,,,,,,,,,,,,,,,,,,
59.092,0.58418,19.06391,7,,,,,,,,,,,,,,,,,,,,,,,,,,,,,,,,,,,,,
59.692,0.68436,25.68933,7,,,,,,,,,,,,,,,,,,,,,,,,,,,,,,,,,,,,,
60.292,0.78432,33.25944,7,,,,,,,,,,,,,,,,,,,,,,,,,,,,,,,,,,,,,
60.77,0.86383,40.07479,7.5,,,,,,,,,,,,,,,,,,,,,,,,,,,,,,,,,,,,,
61.37,0.76364,30.61741,7.5,,,,,,,,,,,,,,,,,,,,,,,,,,,,,,,,,,,,,
61.97,0.66357,22.56857,7.5,,,,,,,,,,,,,,,,,,,,,,,,,,,,,,,,,,,,,
62.57,0.56372,16.08779,7.5,,,,,,,,,,,,,,,,,,,,,,,,,,,,,,,,,,,,,
63.17,0.4637,10.74653,7.5,,,,,,,,,,,,,,,,,,,,,,,,,,,,,,,,,,,,,
63.77,0.36363,6.33514,7.5,,,,,,,,,,,,,,,,,,,,,,,,,,,,,,,,,,,,,
64.37,0.2635,2.6561,7.5,,,,,,,,,,,,,,,,,,,,,,,,,,,,,,,,,,,,,
64.714,0.20621,0.95278,8,,,,,,,,,,,,,,,,,,,,,,,,,,,,,,,,,,,,,
65.314,0.30725,4.69247,8,,,,,,,,,,,,,,,,,,,,,,,,,,,,,,,,,,,,,
65.914,0.40732,9.14635,8,,,,,,,,,,,,,,,,,,,,,,,,,,,,,,,,,,,,,
66.514,0.50734,14.24237,8,,,,,,,,,,,,,,,,,,,,,,,,,,,,,,,,,,,,,
67.114,0.60718,20.11611,8,,,,,,,,,,,,,,,,,,,,,,,,,,,,,,,,,,,,,
67.714,0.70731,26.93695,8,,,,,,,,,,,,,,,,,,,,,,,,,,,,,,,,,,,,,
68.314,0.80727,34.74817,8,,,,,,,,,,,,,,,,,,,,,,,,,,,,,,,,,,,,,
68.774,0.85487,39.75938,8.5,,,,,,,,,,,,,,,,,,,,,,,,,,,,,,,,,,,,,
69.374,0.75044,29.08254,8.5,,,,,,,,,,,,,,,,,,,,,,,,,,,,,,,,,,,,,
69.974,0.65031,21.32904,8.5,,,,,,,,,,,,,,,,,,,,,,,,,,,,,,,,,,,,,
70.574,0.55023,15.03301,8.5,,,,,,,,,,,,,,,,,,,,,,,,,,,,,,,,,,,,,
71.174,0.45039,9.87325,8.5,,,,,,,,,,,,,,,,,,,,,,,,,,,,,,,,,,,,,
71.774,0.35031,5.65705,8.5,,,,,,,,,,,,,,,,,,,,,,,,,,,,,,,,,,,,,
72.374,0.25035,2.1397,8.5,,,,,,,,,,,,,,,,,,,,,,,,,,,,,,,,,,,,,
72.704,0.22485,1.02763,9,,,,,,,,,,,,,,,,,,,,,,,,,,,,,,,,,,,,,
73.304,0.32969,5.36396,9,,,,,,,,,,,,,,,,,,,,,,,,,,,,,,,,,,,,,
73.904,0.42953,9.9227,9,,,,,,,,,,,,,,,,,,,,,,,,,,,,,,,,,,,,,
74.504,0.52949,15.15065,9,,,,,,,,,,,,,,,,,,,,,,,,,,,,,,,,,,,,,
75.104,0.62974,21.25333,9,,,,,,,,,,,,,,,,,,,,,,,,,,,,,,,,,,,,,
75.704,0.7297,28.21911,9,,,,,,,,,,,,,,,,,,,,,,,,,,,,,,,,,,,,,
76.304,0.82954,36.26948,9,,,,,,,,,,,,,,,,,,,,,,,,,,,,,,,,,,,,,
76.762,0.83952,37.24916,9.5,,,,,,,,,,,,,,,,,,,,,,,,,,,,,,,,,,,,,
77.362,0.73899,27.68664,9.5,,,,,,,,,,,,,,,,,,,,,,,,,,,,,,,,,,,,,
77.962,0.63909,20.19992,9.5,,,,,,,,,,,,,,,,,,,,,,,,,,,,,,,,,,,,,
78.562,0.53896,14.09962,9.5,,,,,,,,,,,,,,,,,,,,,,,,,,,,,,,,,,,,,
79.162,0.43888,9.08296,9.5,,,,,,,,,,,,,,,,,,,,,,,,,,,,,,,,,,,,,
79.762,0.33898,4.90669,9.5,,,,,,,,,,,,,,,,,,,,,,,,,,,,,,,,,,,,,
80.362,0.23902,1.58547,9.5,,,,,,,,,,,,,,,,,,,,,,,,,,,,,,,,,,,,,
80.798,0.18473,-0.05275,10,,,,,,,,,,,,,,,,,,,,,,,,,,,,,,,,,,,,,
81.398,0.18626,0.1685,10,,,,,,,,,,,,,,,,,,,,,,,,,,,,,,,,,,,,,
81.998,0.21244,1.11996,10,,,,,,,,,,,,,,,,,,,,,,,,,,,,,,,,,,,,,
82.598,0.21273,1.14706,10,,,,,,,,,,,,,,,,,,,,,,,,,,,,,,,,,,,,,
83.198,0.20326,0.87369,10,,,,,,,,,,,,,,,,,,,,,,,,,,,,,,,,,,,,,
83.798,0.19607,0.67332,10,,,,,,,,,,,,,,,,,,,,,,,,,,,,,,,,,,,,,
84.398,0.19573,0.70458,10,,,,,,,,,,,,,,,,,,,,,,,,,,,,,,,,,,,,,
84.998,0.19567,0.71686,10,,,,,,,,,,,,,,,,,,,,,,,,,,,,,,,,,,,,,
85.598,0.19578,0.7071,10,,,,,,,,,,,,,,,,,,,,,,,,,,,,,,,,,,,,,
86.198,0.19567,0.76842,10,,,,,,,,,,,,,,,,,,,,,,,,,,,,,,,,,,,,,
86.798,0.19567,0.75146,10,,,,,,,,,,,,,,,,,,,,,,,,,,,,,,,,,,,,,
87.398,0.1955,0.77886,10,,,,,,,,,,,,,,,,,,,,,,,,,,,,,,,,,,,,,
87.998,0.19414,0.82986,10,,,,,,,,,,,,,,,,,,,,,,,,,,,,,,,,,,,,,
88.598,0.19216,0.77308,10,,,,,,,,,,,,,,,,,,,,,,,,,,,,,,,,,,,,,
89.198,0.19131,0.78752,10,,,,,,,,,,,,,,,,,,,,,,,,,,,,,,,,,,,,,
89.798,0.19074,0.70451,10,,,,,,,,,,,,,,,,,,,,,,,,,,,,,,,,,,,,,
90.398,0.19057,0.74843,10,,,,,,,,,,,,,,,,,,,,,,,,,,,,,,,,,,,,,
90.998,0.1904,0.75026,10,,,,,,,,,,,,,,,,,,,,,,,,,,,,,,,,,,,,,
91.598,0.19017,0.75384,10,,,,,,,,,,,,,,,,,,,,,,,,,,,,,,,,,,,,,
92.198,0.18989,0.76272,10,,,,,,,,,,,,,,,,,,,,,,,,,,,,,,,,,,,,,
92.798,0.18949,0.72318,10,,,,,,,,,,,,,,,,,,,,,,,,,,,,,,,,,,,,,
93.398,0.18915,0.71561,10,,,,,,,,,,,,,,,,,,,,,,,,,,,,,,,,,,,,,
93.998,0.18898,0.76995,10,,,,,,,,,,,,,,,,,,,,,,,,,,,,,,,,,,,,,
94.598,0.18893,0.72144,10,,,,,,,,,,,,,,,,,,,,,,,,,,,,,,,,,,,,,
95.198,0.18887,0.75863,10,,,,,,,,,,,,,,,,,,,,,,,,,,,,,,,,,,,,,
95.798,0.18876,0.75591,10,,,,,,,,,,,,,,,,,,,,,,,,,,,,,,,,,,,,,
96.398,0.18864,0.80664,10,,,,,,,,,,,,,,,,,,,,,,,,,,,,,,,,,,,,,
96.998,0.18842,0.74337,10,,,,,,,,,,,,,,,,,,,,,,,,,,,,,,,,,,,,,
97.598,0.18819,0.79671,10,,,,,,,,,,,,,,,,,,,,,,,,,,,,,,,,,,,,,
98.198,0.18768,0.78001,10,,,,,,,,,,,,,,,,,,,,,,,,,,,,,,,,,,,,,
98.798,0.18717,0.75197,10,,,,,,,,,,,,,,,,,,,,,,,,,,,,,,,,,,,,,
99.398,0.18689,0.80338,10,,,,,,,,,,,,,,,,,,,,,,,,,,,,,,,,,,,,,
99.998,0.18666,0.73448,10,,,,,,,,,,,,,,,,,,,,,,,,,,,,,,,,,,,,,
100.598,0.18649,0.71391,10,,,,,,,,,,,,,,,,,,,,,,,,,,,,,,,,,,,,,
101.198,0.18632,0.74815,10,,,,,,,,,,,,,,,,,,,,,,,,,,,,,,,,,,,,,
101.798,0.18621,0.74513,10,,,,,,,,,,,,,,,,,,,,,,,,,,,,,,,,,,,,,
102.398,0.18609,0.78022,10,,,,,,,,,,,,,,,,,,,,,,,,,,,,,,,,,,,,,
102.998,0.18592,0.72523,10,,,,,,,,,,,,,,,,,,,,,,,,,,,,,,,,,,,,,
103.598,0.18587,0.76013,10,,,,,,,,,,,,,,,,,,,,,,,,,,,,,,,,,,,,,
104.198,0.18564,0.72819,10,,,,,,,,,,,,,,,,,,,,,,,,,,,,,,,,,,,,,
104.798,0.18558,0.74924,10,,,,,,,,,,,,,,,,,,,,,,,,,,,,,,,,,,,,,
105.398,0.18547,0.69539,10,,,,,,,,,,,,,,,,,,,,,,,,,,,,,,,,,,,,,
105.998,0.18541,0.74855,10,,,,,,,,,,,,,,,,,,,,,,,,,,,,,,,,,,,,,
106.598,0.18541,0.76314,10,,,,,,,,,,,,,,,,,,,,,,,,,,,,,,,,,,,,,
107.198,0.18541,0.78636,10,,,,,,,,,,,,,,,,,,,,,,,,,,,,,,,,,,,,,
107.798,0.18547,0.7794,10,,,,,,,,,,,,,,,,,,,,,,,,,,,,,,,,,,,,,
108.398,0.18547,0.74003,10,,,,,,,,,,,,,,,,,,,,,,,,,,,,,,,,,,,,,
108.998,0.18547,0.76123,10,,,,,,,,,,,,,,,,,,,,,,,,,,,,,,,,,,,,,
109.598,0.18536,0.76701,10,,,,,,,,,,,,,,,,,,,,,,,,,,,,,,,,,,,,,
110.198,0.1853,0.83449,10,,,,,,,,,,,,,,,,,,,,,,,,,,,,,,,,,,,,,
110.798,0.18502,0.78359,10,,,,,,,,,,,,,,,,,,,,,,,,,,,,,,,,,,,,,
111.398,0.18422,0.75964,10,,,,,,,,,,,,,,,,,,,,,,,,,,,,,,,,,,,,,
111.998,0.18269,0.71574,10,,,,,,,,,,,,,,,,,,,,,,,,,,,,,,,,,,,,,
112.598,0.18218,0.70016,10,,,,,,,,,,,,,,,,,,,,,,,,,,,,,,,,,,,,,
113.198,0.18207,0.68396,10,,,,,,,,,,,,,,,,,,,,,,,,,,,,,,,,,,,,,
113.798,0.18224,0.70968,10,,,,,,,,,,,,,,,,,,,,,,,,,,,,,,,,,,,,,
114.398,0.1823,0.76505,10,,,,,,,,,,,,,,,,,,,,,,,,,,,,,,,,,,,,,
114.998,0.18235,0.74447,10,,,,,,,,,,,,,,,,,,,,,,,,,,,,,,,,,,,,,
115.598,0.18247,0.69369,10,,,,,,,,,,,,,,,,,,,,,,,,,,,,,,,,,,,,,
116.198,0.18252,0.706,10,,,,,,,,,,,,,,,,,,,,,,,,,,,,,,,,,,,,,
116.798,0.18264,0.70072,10,,,,,,,,,,,,,,,,,,,,,,,,,,,,,,,,,,,,,
117.398,0.18292,0.70566,10,,,,,,,,,,,,,,,,,,,,,,,,,,,,,,,,,,,,,
117.998,0.18332,0.68826,10,,,,,,,,,,,,,,,,,,,,,,,,,,,,,,,,,,,,,
118.598,0.1836,0.71634,10,,,,,,,,,,,,,,,,,,,,,,,,,,,,,,,,,,,,,
119.198,0.184,0.78631,10,,,,,,,,,,,,,,,,,,,,,,,,,,,,,,,,,,,,,
119.798,0.18445,0.791,10,,,,,,,,,,,,,,,,,,,,,,,,,,,,,,,,,,,,,
120.398,0.18479,0.76652,10,,,,,,,,,,,,,,,,,,,,,,,,,,,,,,,,,,,,,
120.998,0.18496,0.74369,10,,,,,,,,,,,,,,,,,,,,,,,,,,,,,,,,,,,,,
121.598,0.18502,0.77287,10,,,,,,,,,,,,,,,,,,,,,,,,,,,,,,,,,,,,,
122.198,0.18507,0.80328,10,,,,,,,,,,,,,,,,,,,,,,,,,,,,,,,,,,,,,
122.798,0.18502,0.75956,10,,,,,,,,,,,,,,,,,,,,,,,,,,,,,,,,,,,,,
123.398,0.1849,0.72661,10,,,,,,,,,,,,,,,,,,,,,,,,,,,,,,,,,,,,,
123.998,0.18485,0.85583,10,,,,,,,,,,,,,,,,,,,,,,,,,,,,,,,,,,,,,
124.598,0.18479,0.7852,10,,,,,,,,,,,,,,,,,,,,,,,,,,,,,,,,,,,,,
125.198,0.18462,0.84426,10,,,,,,,,,,,,,,,,,,,,,,,,,,,,,,,,,,,,,
125.798,0.18445,0.76941,10,,,,,,,,,,,,,,,,,,,,,,,,,,,,,,,,,,,,,
126.398,0.18422,0.8508,10,,,,,,,,,,,,,,,,,,,,,,,,,,,,,,,,,,,,,
126.998,0.18383,0.78723,10,,,,,,,,,,,,,,,,,,,,,,,,,,,,,,,,,,,,,
127.598,0.18343,0.84366,10,,,,,,,,,,,,,,,,,,,,,,,,,,,,,,,,,,,,,
128.198,0.18241,0.75864,10,,,,,,,,,,,,,,,,,,,,,,,,,,,,,,,,,,,,,
128.798,0.18167,0.74042,10,,,,,,,,,,,,,,,,,,,,,,,,,,,,,,,,,,,,,
129.398,0.18116,0.74112,10,,,,,,,,,,,,,,,,,,,,,,,,,,,,,,,,,,,,,
129.998,0.18088,0.79033,10,,,,,,,,,,,,,,,,,,,,,,,,,,,,,,,,,,,,,
130.598,0.18071,0.74225,10,,,,,,,,,,,,,,,,,,,,,,,,,,,,,,,,,,,,,
131.198,0.1806,0.75927,10,,,,,,,,,,,,,,,,,,,,,,,,,,,,,,,,,,,,,
131.798,0.18054,0.69967,10,,,,,,,,,,,,,,,,,,,,,,,,,,,,,,,,,,,,,
132.398,0.18065,0.69054,10,,,,,,,,,,,,,,,,,,,,,,,,,,,,,,,,,,,,,
132.998,0.18065,0.73575,10,,,,,,,,,,,,,,,,,,,,,,,,,,,,,,,,,,,,,
133.598,0.18071,0.74641,10,,,,,,,,,,,,,,,,,,,,,,,,,,,,,,,,,,,,,
134.198,0.18077,0.77345,10,,,,,,,,,,,,,,,,,,,,,,,,,,,,,,,,,,,,,
134.798,0.18082,0.73527,10,,,,,,,,,,,,,,,,,,,,,,,,,,,,,,,,,,,,,
135.398,0.18082,0.79272,10,,,,,,,,,,,,,,,,,,,,,,,,,,,,,,,,,,,,,
135.998,0.18082,0.75243,10,,,,,,,,,,,,,,,,,,,,,,,,,,,,,,,,,,,,,
136.598,0.18082,0.79609,10,,,,,,,,,,,,,,,,,,,,,,,,,,,,,,,,,,,,,
137.198,0.18082,0.76612,10,,,,,,,,,,,,,,,,,,,,,,,,,,,,,,,,,,,,,
137.798,0.18082,0.79042,10,,,,,,,,,,,,,,,,,,,,,,,,,,,,,,,,,,,,,
138.398,0.18082,0.77456,10,,,,,,,,,,,,,,,,,,,,,,,,,,,,,,,,,,,,,
138.998,0.18082,0.8077,10,,,,,,,,,,,,,,,,,,,,,,,,,,,,,,,,,,,,,
139.598,0.18077,0.74967,10,,,,,,,,,,,,,,,,,,,,,,,,,,,,,,,,,,,,,
140.198,0.18088,0.74084,10,,,,,,,,,,,,,,,,,,,,,,,,,,,,,,,,,,,,,
140.798,0.18088,0.81189,10,,,,,,,,,,,,,,,,,,,,,,,,,,,,,,,,,,,,,
141.398,0.18088,0.78367,10,,,,,,,,,,,,,,,,,,,,,,,,,,,,,,,,,,,,,
141.998,0.18082,0.71943,10,,,,,,,,,,,,,,,,,,,,,,,,,,,,,,,,,,,,,
142.598,0.18082,0.78181,10,,,,,,,,,,,,,,,,,,,,,,,,,,,,,,,,,,,,,
143.198,0.18088,0.79352,10,,,,,,,,,,,,,,,,,,,,,,,,,,,,,,,,,,,,,
143.798,0.18088,0.85069,10,,,,,,,,,,,,,,,,,,,,,,,,,,,,,,,,,,,,,
144.398,0.18077,0.7845,10,,,,,,,,,,,,,,,,,,,,,,,,,,,,,,,,,,,,,
144.998,0.18077,0.79684,10,,,,,,,,,,,,,,,,,,,,,,,,,,,,,,,,,,,,,
145.598,0.18077,0.77228,10,,,,,,,,,,,,,,,,,,,,,,,,,,,,,,,,,,,,,
146.198,0.18077,0.73769,10,,,,,,,,,,,,,,,,,,,,,,,,,,,,,,,,,,,,,
146.798,0.18077,0.76065,10,,,,,,,,,,,,,,,,,,,,,,,,,,,,,,,,,,,,,
147.398,0.18077,0.76372,10,,,,,,,,,,,,,,,,,,,,,,,,,,,,,,,,,,,,,
147.998,0.18082,0.77642,10,,,,,,,,,,,,,,,,,,,,,,,,,,,,,,,,,,,,,
148.598,0.18082,0.77538,10,,,,,,,,,,,,,,,,,,,,,,,,,,,,,,,,,,,,,
149.198,0.18082,0.78743,10,,,,,,,,,,,,,,,,,,,,,,,,,,,,,,,,,,,,,
149.798,0.18071,0.91423,10,,,,,,,,,,,,,,,,,,,,,,,,,,,,,,,,,,,,,
150.398,0.18077,0.74652,10,,,,,,,,,,,,,,,,,,,,,,,,,,,,,,,,,,,,,
150.998,0.18077,0.73336,10,,,,,,,,,,,,,,,,,,,,,,,,,,,,,,,,,,,,,
151.598,0.18077,0.74341,10,,,,,,,,,,,,,,,,,,,,,,,,,,,,,,,,,,,,,
152.198,0.18077,0.80823,10,,,,,,,,,,,,,,,,,,,,,,,,,,,,,,,,,,,,,
152.798,0.18071,0.93296,10,,,,,,,,,,,,,,,,,,,,,,,,,,,,,,,,,,,,,
153.398,0.18071,0.76808,10,,,,,,,,,,,,,,,,,,,,,,,,,,,,,,,,,,,,,
153.998,0.18071,0.74637,10,,,,,,,,,,,,,,,,,,,,,,,,,,,,,,,,,,,,,
154.598,0.1806,0.74814,10,,,,,,,,,,,,,,,,,,,,,,,,,,,,,,,,,,,,,
155.198,0.18054,0.83198,10,,,,,,,,,,,,,,,,,,,,,,,,,,,,,,,,,,,,,
155.798,0.18048,0.8575,10,,,,,,,,,,,,,,,,,,,,,,,,,,,,,,,,,,,,,
156.398,0.18037,0.79769,10,,,,,,,,,,,,,,,,,,,,,,,,,,,,,,,,,,,,,
156.998,0.17986,0.76207,10,,,,,,,,,,,,,,,,,,,,,,,,,,,,,,,,,,,,,
157.598,0.17895,0.75241,10,,,,,,,,,,,,,,,,,,,,,,,,,,,,,,,,,,,,,
158.198,0.17827,0.78396,10,,,,,,,,,,,,,,,,,,,,,,,,,,,,,,,,,,,,,
158.798,0.17805,0.77187,10,,,,,,,,,,,,,,,,,,,,,,,,,,,,,,,,,,,,,
159.398,0.1781,0.66326,10,,,,,,,,,,,,,,,,,,,,,,,,,,,,,,,,,,,,,
159.998,0.17816,0.71169,10,,,,,,,,,,,,,,,,,,,,,,,,,,,,,,,,,,,,,
160.598,0.17822,0.74686,10,,,,,,,,,,,,,,,,,,,,,,,,,,,,,,,,,,,,,
161.198,0.17827,0.7332,10,,,,,,,,,,,,,,,,,,,,,,,,,,,,,,,,,,,,,
161.798,0.17833,0.72762,10,,,,,,,,,,,,,,,,,,,,,,,,,,,,,,,,,,,,,
162.398,0.17844,0.74386,10,,,,,,,,,,,,,,,,,,,,,,,,,,,,,,,,,,,,,
162.998,0.17856,0.67906,10,,,,,,,,,,,,,,,,,,,,,,,,,,,,,,,,,,,,,
163.598,0.17873,0.71394,10,,,,,,,,,,,,,,,,,,,,,,,,,,,,,,,,,,,,,
164.198,0.1789,0.69254,10,,,,,,,,,,,,,,,,,,,,,,,,,,,,,,,,,,,,,
164.798,0.17918,0.71977,10,,,,,,,,,,,,,,,,,,,,,,,,,,,,,,,,,,,,,
165.398,0.17941,0.72079,10,,,,,,,,,,,,,,,,,,,,,,,,,,,,,,,,,,,,,
165.998,0.17975,0.76437,10,,,,,,,,,,,,,,,,,,,,,,,,,,,,,,,,,,,,,
166.598,0.18009,0.71398,10,,,,,,,,,,,,,,,,,,,,,,,,,,,,,,,,,,,,,
167.198,0.18043,0.75548,10,,,,,,,,,,,,,,,,,,,,,,,,,,,,,,,,,,,,,
167.798,0.18071,0.79463,10,,,,,,,,,,,,,,,,,,,,,,,,,,,,,,,,,,,,,
168.398,0.18082,0.81326,10,,,,,,,,,,,,,,,,,,,,,,,,,,,,,,,,,,,,,
168.998,0.18071,0.81066,10,,,,,,,,,,,,,,,,,,,,,,,,,,,,,,,,,,,,,
169.598,0.18077,0.76678,10,,,,,,,,,,,,,,,,,,,,,,,,,,,,,,,,,,,,,
170.198,0.1806,0.83565,10,,,,,,,,,,,,,,,,,,,,,,,,,,,,,,,,,,,,,
170.798,0.1806,0.80704,10,,,,,,,,,,,,,,,,,,,,,,,,,,,,,,,,,,,,,
171.398,0.18054,0.77042,10,,,,,,,,,,,,,,,,,,,,,,,,,,,,,,,,,,,,,
171.998,0.18048,0.80847,10,,,,,,,,,,,,,,,,,,,,,,,,,,,,,,,,,,,,,
172.598,0.18048,0.77661,10,,,,,,,,,,,,,,,,,,,,,,,,,,,,,,,,,,,,,
173.198,0.18026,0.79307,10,,,,,,,,,,,,,,,,,,,,,,,,,,,,,,,,,,,,,
173.798,0.1802,0.73704,10,,,,,,,,,,,,,,,,,,,,,,,,,,,,,,,,,,,,,
174.398,0.18014,0.79246,10,,,,,,,,,,,,,,,,,,,,,,,,,,,,,,,,,,,,,
174.998,0.18003,0.81234,10,,,,,,,,,,,,,,,,,,,,,,,,,,,,,,,,,,,,,
175.598,0.17986,0.76775,10,,,,,,,,,,,,,,,,,,,,,,,,,,,,,,,,,,,,,
176.198,0.17958,0.81595,10,,,,,,,,,,,,,,,,,,,,,,,,,,,,,,,,,,,,,
176.798,0.17935,0.79596,10,,,,,,,,,,,,,,,,,,,,,,,,,,,,,,,,,,,,,
177.398,0.17873,0.7584,10,,,,,,,,,,,,,,,,,,,,,,,,,,,,,,,,,,,,,
177.998,0.17822,0.77144,10,,,,,,,,,,,,,,,,,,,,,,,,,,,,,,,,,,,,,
178.598,0.17788,0.70638,10,,,,,,,,,,,,,,,,,,,,,,,,,,,,,,,,,,,,,
179.198,0.17782,0.77947,10,,,,,,,,,,,,,,,,,,,,,,,,,,,,,,,,,,,,,
179.798,0.17782,0.75558,10,,,,,,,,,,,,,,,,,,,,,,,,,,,,,,,,,,,,,
180.398,0.17788,0.76443,10,,,,,,,,,,,,,,,,,,,,,,,,,,,,,,,,,,,,,
180.998,0.17788,0.70734,10,,,,,,,,,,,,,,,,,,,,,,,,,,,,,,,,,,,,,
181.598,0.17788,0.76676,10,,,,,,,,,,,,,,,,,,,,,,,,,,,,,,,,,,,,,
182.198,0.17793,0.72491,10,,,,,,,,,,,,,,,,,,,,,,,,,,,,,,,,,,,,,
182.798,0.17799,0.74992,10,,,,,,,,,,,,,,,,,,,,,,,,,,,,,,,,,,,,,
183.398,0.17799,0.72297,10,,,,,,,,,,,,,,,,,,,,,,,,,,,,,,,,,,,,,
183.998,0.17799,0.74347,10,,,,,,,,,,,,,,,,,,,,,,,,,,,,,,,,,,,,,
184.598,0.17799,0.75765,10,,,,,,,,,,,,,,,,,,,,,,,,,,,,,,,,,,,,,
185.198,0.17799,0.74915,10,,,,,,,,,,,,,,,,,,,,,,,,,,,,,,,,,,,,,
185.798,0.17805,0.75746,10,,,,,,,,,,,,,,,,,,,,,,,,,,,,,,,,,,,,,
186.398,0.17805,0.70726,10,,,,,,,,,,,,,,,,,,,,,,,,,,,,,,,,,,,,,
186.998,0.17816,0.72804,10,,,,,,,,,,,,,,,,,,,,,,,,,,,,,,,,,,,,,
187.598,0.17822,0.74575,10,,,,,,,,,,,,,,,,,,,,,,,,,,,,,,,,,,,,,
188.198,0.17827,0.74504,10,,,,,,,,,,,,,,,,,,,,,,,,,,,,,,,,,,,,,
188.798,0.17827,0.79011,10,,,,,,,,,,,,,,,,,,,,,,,,,,,,,,,,,,,,,
189.398,0.17827,0.73988,10,,,,,,,,,,,,,,,,,,,,,,,,,,,,,,,,,,,,,
189.998,0.17839,0.71963,10,,,,,,,,,,,,,,,,,,,,,,,,,,,,,,,,,,,,,
190.598,0.17839,0.79709,10,,,,,,,,,,,,,,,,,,,,,,,,,,,,,,,,,,,,,
191.198,0.17839,0.7578,10,,,,,,,,,,,,,,,,,,,,,,,,,,,,,,,,,,,,,
191.798,0.17839,0.76691,10,,,,,,,,,,,,,,,,,,,,,,,,,,,,,,,,,,,,,
192.398,0.17839,0.74503,10,,,,,,,,,,,,,,,,,,,,,,,,,,,,,,,,,,,,,
192.998,0.1785,0.77257,10,,,,,,,,,,,,,,,,,,,,,,,,,,,,,,,,,,,,,
193.598,0.17856,0.72517,10,,,,,,,,,,,,,,,,,,,,,,,,,,,,,,,,,,,,,
194.198,0.17867,0.73018,10,,,,,,,,,,,,,,,,,,,,,,,,,,,,,,,,,,,,,
194.798,0.17884,0.74878,10,,,,,,,,,,,,,,,,,,,,,,,,,,,,,,,,,,,,,
195.398,0.17901,0.68979,10,,,,,,,,,,,,,,,,,,,,,,,,,,,,,,,,,,,,,
195.998,0.17924,0.74836,10,,,,,,,,,,,,,,,,,,,,,,,,,,,,,,,,,,,,,
196.598,0.17935,0.74367,10,,,,,,,,,,,,,,,,,,,,,,,,,,,,,,,,,,,,,
197.198,0.17935,0.80162,10,,,,,,,,,,,,,,,,,,,,,,,,,,,,,,,,,,,,,
197.798,0.17924,0.79839,10,,,,,,,,,,,,,,,,,,,,,,,,,,,,,,,,,,,,,
198.398,0.17918,0.78597,10,,,,,,,,,,,,,,,,,,,,,,,,,,,,,,,,,,,,,
198.998,0.17912,0.8241,10,,,,,,,,,,,,,,,,,,,,,,,,,,,,,,,,,,,,,
199.598,0.17912,0.77679,10,,,,,,,,,,,,,,,,,,,,,,,,,,,,,,,,,,,,,
200.198,0.17901,0.79831,10,,,,,,,,,,,,,,,,,,,,,,,,,,,,,,,,,,,,,
200.798,0.17895,0.80066,10,,,,,,,,,,,,,,,,,,,,,,,,,,,,,,,,,,,,,
201.398,0.17878,0.85005,10,,,,,,,,,,,,,,,,,,,,,,,,,,,,,,,,,,,,,
201.998,0.17844,0.80041,10,,,,,,,,,,,,,,,,,,,,,,,,,,,,,,,,,,,,,
202.598,0.17816,0.83928,10,,,,,,,,,,,,,,,,,,,,,,,,,,,,,,,,,,,,,
203.198,0.17776,0.7762,10,,,,,,,,,,,,,,,,,,,,,,,,,,,,,,,,,,,,,
203.798,0.17731,0.76881,10,,,,,,,,,,,,,,,,,,,,,,,,,,,,,,,,,,,,,
204.398,0.17646,0.74427,10,,,,,,,,,,,,,,,,,,,,,,,,,,,,,,,,,,,,,
204.998,0.17584,0.76677,10,,,,,,,,,,,,,,,,,,,,,,,,,,,,,,,,,,,,,
205.598,0.17555,0.69471,10,,,,,,,,,,,,,,,,,,,,,,,,,,,,,,,,,,,,,
206.198,0.1755,0.75215,10,,,,,,,,,,,,,,,,,,,,,,,,,,,,,,,,,,,,,
206.798,0.17544,0.68121,10,,,,,,,,,,,,,,,,,,,,,,,,,,,,,,,,,,,,,
207.398,0.17555,0.73208,10,,,,,,,,,,,,,,,,,,,,,,,,,,,,,,,,,,,,,
207.998,0.17561,0.71822,10,,,,,,,,,,,,,,,,,,,,,,,,,,,,,,,,,,,,,
208.598,0.17561,0.77905,10,,,,,,,,,,,,,,,,,,,,,,,,,,,,,,,,,,,,,
209.198,0.17567,0.71851,10,,,,,,,,,,,,,,,,,,,,,,,,,,,,,,,,,,,,,
209.798,0.17572,0.73232,10,,,,,,,,,,,,,,,,,,,,,,,,,,,,,,,,,,,,,
210.398,0.17578,0.68931,10,,,,,,,,,,,,,,,,,,,,,,,,,,,,,,,,,,,,,
210.998,0.17595,0.68246,10,,,,,,,,,,,,,,,,,,,,,,,,,,,,,,,,,,,,,
211.598,0.17623,0.71792,10,,,,,,,,,,,,,,,,,,,,,,,,,,,,,,,,,,,,,
212.198,0.17657,0.71225,10,,,,,,,,,,,,,,,,,,,,,,,,,,,,,,,,,,,,,
212.798,0.17725,0.71506,10,,,,,,,,,,,,,,,,,,,,,,,,,,,,,,,,,,,,,
213.398,0.17805,0.75939,10,,,,,,,,,,,,,,,,,,,,,,,,,,,,,,,,,,,,,
213.998,0.17901,0.78273,10,,,,,,,,,,,,,,,,,,,,,,,,,,,,,,,,,,,,,
214.598,0.17929,0.73512,10,,,,,,,,,,,,,,,,,,,,,,,,,,,,,,,,,,,,,
215.198,0.17941,0.82796,10,,,,,,,,,,,,,,,,,,,,,,,,,,,,,,,,,,,,,
215.798,0.17946,0.80803,10,,,,,,,,,,,,,,,,,,,,,,,,,,,,,,,,,,,,,
216.398,0.17935,0.78739,10,,,,,,,,,,,,,,,,,,,,,,,,,,,,,,,,,,,,,
216.998,0.17935,0.77159,10,,,,,,,,,,,,,,,,,,,,,,,,,,,,,,,,,,,,,
217.598,0.17929,0.7815,10,,,,,,,,,,,,,,,,,,,,,,,,,,,,,,,,,,,,,
218.198,0.17924,0.8193,10,,,,,,,,,,,,,,,,,,,,,,,,,,,,,,,,,,,,,
218.798,0.17918,0.78283,10,,,,,,,,,,,,,,,,,,,,,,,,,,,,,,,,,,,,,
219.398,0.17924,0.8211,10,,,,,,,,,,,,,,,,,,,,,,,,,,,,,,,,,,,,,
219.998,0.17912,0.79196,10,,,,,,,,,,,,,,,,,,,,,,,,,,,,,,,,,,,,,
220.598,0.17901,0.79014,10,,,,,,,,,,,,,,,,,,,,,,,,,,,,,,,,,,,,,
221.198,0.1789,0.81471,10,,,,,,,,,,,,,,,,,,,,,,,,,,,,,,,,,,,,,
221.798,0.17873,0.82412,10,,,,,,,,,,,,,,,,,,,,,,,,,,,,,,,,,,,,,
222.398,0.17856,0.74729,10,,,,,,,,,,,,,,,,,,,,,,,,,,,,,,,,,,,,,
222.998,0.17833,0.82165,10,,,,,,,,,,,,,,,,,,,,,,,,,,,,,,,,,,,,,
223.598,0.1781,0.77975,10,,,,,,,,,,,,,,,,,,,,,,,,,,,,,,,,,,,,,
224.198,0.17776,0.77646,10,,,,,,,,,,,,,,,,,,,,,,,,,,,,,,,,,,,,,
224.798,0.17754,0.78418,10,,,,,,,,,,,,,,,,,,,,,,,,,,,,,,,,,,,,,
225.398,0.17737,0.72205,10,,,,,,,,,,,,,,,,,,,,,,,,,,,,,,,,,,,,,
225.998,0.17731,0.77526,10,,,,,,,,,,,,,,,,,,,,,,,,,,,,,,,,,,,,,
226.598,0.17725,0.77404,10,,,,,,,,,,,,,,,,,,,,,,,,,,,,,,,,,,,,,
227.198,0.17737,0.74623,10,,,,,,,,,,,,,,,,,,,,,,,,,,,,,,,,,,,,,
227.798,0.17737,0.74065,10,,,,,,,,,,,,,,,,,,,,,,,,,,,,,,,,,,,,,
228.398,0.17737,0.77504,10,,,,,,,,,,,,,,,,,,,,,,,,,,,,,,,,,,,,,
228.998,0.17742,0.7418,10,,,,,,,,,,,,,,,,,,,,,,,,,,,,,,,,,,,,,
229.598,0.17742,0.72833,10,,,,,,,,,,,,,,,,,,,,,,,,,,,,,,,,,,,,,
230.198,0.17748,0.72539,10,,,,,,,,,,,,,,,,,,,,,,,,,,,,,,,,,,,,,
230.798,0.17748,0.76671,10,,,,,,,,,,,,,,,,,,,,,,,,,,,,,,,,,,,,,
231.398,0.17748,0.74688,10,,,,,,,,,,,,,,,,,,,,,,,,,,,,,,,,,,,,,
231.998,0.17754,0.8028,10,,,,,,,,,,,,,,,,,,,,,,,,,,,,,,,,,,,,,
232.598,0.17754,0.74496,10,,,,,,,,,,,,,,,,,,,,,,,,,,,,,,,,,,,,,
233.198,0.17754,0.75483,10,,,,,,,,,,,,,,,,,,,,,,,,,,,,,,,,,,,,,
233.798,0.17759,0.74062,10,,,,,,,,,,,,,,,,,,,,,,,,,,,,,,,,,,,,,
234.398,0.17754,0.7414,10,,,,,,,,,,,,,,,,,,,,,,,,,,,,,,,,,,,,,
234.998,0.17765,0.76891,10,,,,,,,,,,,,,,,,,,,,,,,,,,,,,,,,,,,,,
235.598,0.17765,0.78253,10,,,,,,,,,,,,,,,,,,,,,,,,,,,,,,,,,,,,,
236.198,0.17771,0.75196,10,,,,,,,,,,,,,,,,,,,,,,,,,,,,,,,,,,,,,
236.798,0.17771,0.74374,10,,,,,,,,,,,,,,,,,,,,,,,,,,,,,,,,,,,,,
237.398,0.17776,0.70974,10,,,,,,,,,,,,,,,,,,,,,,,,,,,,,,,,,,,,,
237.998,0.17782,0.81738,10,,,,,,,,,,,,,,,,,,,,,,,,,,,,,,,,,,,,,
238.598,0.17782,0.74155,10,,,,,,,,,,,,,,,,,,,,,,,,,,,,,,,,,,,,,
239.198,0.17799,0.72045,10,,,,,,,,,,,,,,,,,,,,,,,,,,,,,,,,,,,,,
239.798,0.1781,0.70349,10,,,,,,,,,,,,,,,,,,,,,,,,,,,,,,,,,,,,,
240.398,0.17822,0.76272,10,,,,,,,,,,,,,,,,,,,,,,,,,,,,,,,,,,,,,
240.998,0.17833,0.82229,10,,,,,,,,,,,,,,,,,,,,,,,,,,,,,,,,,,,,,
241.598,0.17839,0.78005,10,,,,,,,,,,,,,,,,,,,,,,,,,,,,,,,,,,,,,
242.198,0.17844,0.80381,10,,,,,,,,,,,,,,,,,,,,,,,,,,,,,,,,,,,,,
242.798,0.17833,0.77901,10,,,,,,,,,,,,,,,,,,,,,,,,,,,,,,,,,,,,,
243.398,0.17839,0.74425,10,,,,,,,,,,,,,,,,,,,,,,,,,,,,,,,,,,,,,
243.998,0.17827,0.84517,10,,,,,,,,,,,,,,,,,,,,,,,,,,,,,,,,,,,,,
244.598,0.17822,0.75232,10,,,,,,,,,,,,,,,,,,,,,,,,,,,,,,,,,,,,,
245.198,0.17822,0.7841,10,,,,,,,,,,,,,,,,,,,,,,,,,,,,,,,,,,,,,
245.798,0.17822,0.76619,10,,,,,,,,,,,,,,,,,,,,,,,,,,,,,,,,,,,,,
246.398,0.17816,0.73438,10,,,,,,,,,,,,,,,,,,,,,,,,,,,,,,,,,,,,,
246.998,0.17816,0.78462,10,,,,,,,,,,,,,,,,,,,,,,,,,,,,,,,,,,,,,
247.598,0.1781,0.79798,10,,,,,,,,,,,,,,,,,,,,,,,,,,,,,,,,,,,,,
248.198,0.17816,0.73726,10,,,,,,,,,,,,,,,,,,,,,,,,,,,,,,,,,,,,,
248.798,0.17816,0.82035,10,,,,,,,,,,,,,,,,,,,,,,,,,,,,,,,,,,,,,
249.398,0.17816,0.78317,10,,,,,,,,,,,,,,,,,,,,,,,,,,,,,,,,,,,,,
249.998,0.17816,0.86695,10,,,,,,,,,,,,,,,,,,,,,,,,,,,,,,,,,,,,,
250.598,0.17816,0.76959,10,,,,,,,,,,,,,,,,,,,,,,,,,,,,,,,,,,,,,
251.198,0.17816,0.75672,10,,,,,,,,,,,,,,,,,,,,,,,,,,,,,,,,,,,,,
251.798,0.1781,0.76749,10,,,,,,,,,,,,,,,,,,,,,,,,,,,,,,,,,,,,,
252.398,0.17816,0.77165,10,,,,,,,,,,,,,,,,,,,,,,,,,,,,,,,,,,,,,
252.998,0.17816,0.83215,10,,,,,,,,,,,,,,,,,,,,,,,,,,,,,,,,,,,,,
253.598,0.17816,0.76279,10,,,,,,,,,,,,,,,,,,,,,,,,,,,,,,,,,,,,,
254.198,0.17816,0.80111,10,,,,,,,,,,,,,,,,,,,,,,,,,,,,,,,,,,,,,
254.798,0.17822,0.73077,10,,,,,,,,,,,,,,,,,,,,,,,,,,,,,,,,,,,,,
255.398,0.17822,0.79014,10,,,,,,,,,,,,,,,,,,,,,,,,,,,,,,,,,,,,,
255.998,0.17822,0.77555,10,,,,,,,,,,,,,,,,,,,,,,,,,,,,,,,,,,,,,
256.598,0.17822,0.7582,10,,,,,,,,,,,,,,,,,,,,,,,,,,,,,,,,,,,,,
257.198,0.17822,0.80547,10,,,,,,,,,,,,,,,,,,,,,,,,,,,,,,,,,,,,,
257.798,0.1781,0.74816,10,,,,,,,,,,,,,,,,,,,,,,,,,,,,,,,,,,,,,
258.398,0.1781,0.75331,10,,,,,,,,,,,,,,,,,,,,,,,,,,,,,,,,,,,,,
258.998,0.1781,0.78382,10,,,,,,,,,,,,,,,,,,,,,,,,,,,,,,,,,,,,,
259.598,0.17822,0.7542,10,,,,,,,,,,,,,,,,,,,,,,,,,,,,,,,,,,,,,
260.198,0.17822,0.72621,10,,,,,,,,,,,,,,,,,,,,,,,,,,,,,,,,,,,,,
260.798,0.17822,0.79065,10,,,,,,,,,,,,,,,,,,,,,,,,,,,,,,,,,,,,,
261.398,0.17822,0.77314,10,,,,,,,,,,,,,,,,,,,,,,,,,,,,,,,,,,,,,
261.998,0.17822,0.76205,10,,,,,,,,,,,,,,,,,,,,,,,,,,,,,,,,,,,,,
262.598,0.17822,0.7676,10,,,,,,,,,,,,,,,,,,,,,,,,,,,,,,,,,,,,,
263.198,0.1781,0.87263,10,,,,,,,,,,,,,,,,,,,,,,,,,,,,,,,,,,,,,
263.798,0.17822,0.79366,10,,,,,,,,,,,,,,,,,,,,,,,,,,,,,,,,,,,,,
264.398,0.17822,0.81287,10,,,,,,,,,,,,,,,,,,,,,,,,,,,,,,,,,,,,,
264.998,0.17822,0.75857,10,,,,,,,,,,,,,,,,,,,,,,,,,,,,,,,,,,,,,
265.598,0.17822,0.74299,10,,,,,,,,,,,,,,,,,,,,,,,,,,,,,,,,,,,,,
266.198,0.17822,0.75823,10,,,,,,,,,,,,,,,,,,,,,,,,,,,,,,,,,,,,,
266.798,0.17822,0.79739,10,,,,,,,,,,,,,,,,,,,,,,,,,,,,,,,,,,,,,
267.398,0.17822,0.78948,10,,,,,,,,,,,,,,,,,,,,,,,,,,,,,,,,,,,,,
267.998,0.17822,0.81286,10,,,,,,,,,,,,,,,,,,,,,,,,,,,,,,,,,,,,,
268.598,0.17822,0.76873,10,,,,,,,,,,,,,,,,,,,,,,,,,,,,,,,,,,,,,
269.198,0.17822,0.75083,10,,,,,,,,,,,,,,,,,,,,,,,,,,,,,,,,,,,,,
269.798,0.17822,0.7697,10,,,,,,,,,,,,,,,,,,,,,,,,,,,,,,,,,,,,,
270.398,0.17822,0.75658,10,,,,,,,,,,,,,,,,,,,,,,,,,,,,,,,,,,,,,
270.998,0.17822,0.76644,10,,,,,,,,,,,,,,,,,,,,,,,,,,,,,,,,,,,,,
271.598,0.17822,0.7769,10,,,,,,,,,,,,,,,,,,,,,,,,,,,,,,,,,,,,,
272.198,0.17822,0.74889,10,,,,,,,,,,,,,,,,,,,,,,,,,,,,,,,,,,,,,
272.798,0.17822,0.78077,10,,,,,,,,,,,,,,,,,,,,,,,,,,,,,,,,,,,,,
273.398,0.17822,0.80682,10,,,,,,,,,,,,,,,,,,,,,,,,,,,,,,,,,,,,,
273.998,0.1781,0.77192,10,,,,,,,,,,,,,,,,,,,,,,,,,,,,,,,,,,,,,
274.598,0.1781,0.77373,10,,,,,,,,,,,,,,,,,,,,,,,,,,,,,,,,,,,,,
275.198,0.1781,0.80489,10,,,,,,,,,,,,,,,,,,,,,,,,,,,,,,,,,,,,,
275.798,0.1781,0.75737,10,,,,,,,,,,,,,,,,,,,,,,,,,,,,,,,,,,,,,
276.398,0.17822,0.82505,10,,,,,,,,,,,,,,,,,,,,,,,,,,,,,,,,,,,,,
276.998,0.17822,0.80116,10,,,,,,,,,,,,,,,,,,,,,,,,,,,,,,,,,,,,,
277.598,0.17822,0.7523,10,,,,,,,,,,,,,,,,,,,,,,,,,,,,,,,,,,,,,
278.198,0.17822,0.74021,10,,,,,,,,,,,,,,,,,,,,,,,,,,,,,,,,,,,,,
278.798,0.17822,0.77097,10,,,,,,,,,,,,,,,,,,,,,,,,,,,,,,,,,,,,,
279.398,0.17822,0.77003,10,,,,,,,,,,,,,,,,,,,,,,,,,,,,,,,,,,,,,
279.998,0.17822,0.77119,10,,,,,,,,,,,,,,,,,,,,,,,,,,,,,,,,,,,,,
280.598,0.17822,0.7656,10,,,,,,,,,,,,,,,,,,,,,,,,,,,,,,,,,,,,,
281.198,0.17822,0.76577,10,,,,,,,,,,,,,,,,,,,,,,,,,,,,,,,,,,,,,
281.798,0.17822,0.71657,10,,,,,,,,,,,,,,,,,,,,,,,,,,,,,,,,,,,,,
282.398,0.17822,0.73795,10,,,,,,,,,,,,,,,,,,,,,,,,,,,,,,,,,,,,,
282.998,0.17827,0.81397,10,,,,,,,,,,,,,,,,,,,,,,,,,,,,,,,,,,,,,
283.598,0.17816,0.76484,10,,,,,,,,,,,,,,,,,,,,,,,,,,,,,,,,,,,,,
284.198,0.17816,0.74872,10,,,,,,,,,,,,,,,,,,,,,,,,,,,,,,,,,,,,,
284.798,0.17816,0.77846,10,,,,,,,,,,,,,,,,,,,,,,,,,,,,,,,,,,,,,
285.398,0.17816,0.82404,10,,,,,,,,,,,,,,,,,,,,,,,,,,,,,,,,,,,,,
285.998,0.17816,0.76274,10,,,,,,,,,,,,,,,,,,,,,,,,,,,,,,,,,,,,,
286.598,0.17816,0.74179,10,,,,,,,,,,,,,,,,,,,,,,,,,,,,,,,,,,,,,
287.198,0.17816,0.75482,10,,,,,,,,,,,,,,,,,,,,,,,,,,,,,,,,,,,,,
287.798,0.17816,0.80812,10,,,,,,,,,,,,,,,,,,,,,,,,,,,,,,,,,,,,,
288.398,0.17816,0.73624,10,,,,,,,,,,,,,,,,,,,,,,,,,,,,,,,,,,,,,
288.998,0.17816,0.77595,10,,,,,,,,,,,,,,,,,,,,,,,,,,,,,,,,,,,,,
289.598,0.17816,0.7518,10,,,,,,,,,,,,,,,,,,,,,,,,,,,,,,,,,,,,,
290.198,0.17816,0.74032,10,,,,,,,,,,,,,,,,,,,,,,,,,,,,,,,,,,,,,
290.798,0.17827,0.78914,10,,,,,,,,,,,,,,,,,,,,,,,,,,,,,,,,,,,,,
291.398,0.17827,0.69552,10,,,,,,,,,,,,,,,,,,,,,,,,,,,,,,,,,,,,,
291.998,0.17816,0.74892,10,,,,,,,,,,,,,,,,,,,,,,,,,,,,,,,,,,,,,
292.598,0.17827,0.73406,10,,,,,,,,,,,,,,,,,,,,,,,,,,,,,,,,,,,,,
293.198,0.17816,0.78561,10,,,,,,,,,,,,,,,,,,,,,,,,,,,,,,,,,,,,,
293.798,0.17816,0.72198,10,,,,,,,,,,,,,,,,,,,,,,,,,,,,,,,,,,,,,
294.398,0.17827,0.84552,10,,,,,,,,,,,,,,,,,,,,,,,,,,,,,,,,,,,,,
294.998,0.17827,0.76693,10,,,,,,,,,,,,,,,,,,,,,,,,,,,,,,,,,,,,,
295.598,0.17827,0.77554,10,,,,,,,,,,,,,,,,,,,,,,,,,,,,,,,,,,,,,
296.198,0.17827,0.75901,10,,,,,,,,,,,,,,,,,,,,,,,,,,,,,,,,,,,,,
296.798,0.17816,0.77572,10,,,,,,,,,,,,,,,,,,,,,,,,,,,,,,,,,,,,,
297.398,0.17827,0.75143,10,,,,,,,,,,,,,,,,,,,,,,,,,,,,,,,,,,,,,
297.998,0.17827,0.76467,10,,,,,,,,,,,,,,,,,,,,,,,,,,,,,,,,,,,,,
298.598,0.17827,0.79539,10,,,,,,,,,,,,,,,,,,,,,,,,,,,,,,,,,,,,,
299.198,0.17827,0.73461,10,,,,,,,,,,,,,,,,,,,,,,,,,,,,,,,,,,,,,
299.798,0.17827,0.76284,10,,,,,,,,,,,,,,,,,,,,,,,,,,,,,,,,,,,,,
300.398,0.17827,0.78552,10,,,,,,,,,,,,,,,,,,,,,,,,,,,,,,,,,,,,,
300.998,0.17827,0.78342,10,,,,,,,,,,,,,,,,,,,,,,,,,,,,,,,,,,,,,
301.598,0.17827,0.74569,10,,,,,,,,,,,,,,,,,,,,,,,,,,,,,,,,,,,,,
302.198,0.17827,0.77818,10,,,,,,,,,,,,,,,,,,,,,,,,,,,,,,,,,,,,,
302.798,0.17833,0.72784,10,,,,,,,,,,,,,,,,,,,,,,,,,,,,,,,,,,,,,
303.398,0.17839,0.8025,10,,,,,,,,,,,,,,,,,,,,,,,,,,,,,,,,,,,,,
303.998,0.17839,0.70903,10,,,,,,,,,,,,,,,,,,,,,,,,,,,,,,,,,,,,,
304.598,0.17844,0.69873,10,,,,,,,,,,,,,,,,,,,,,,,,,,,,,,,,,,,,,
305.198,0.17861,0.72758,10,,,,,,,,,,,,,,,,,,,,,,,,,,,,,,,,,,,,,
305.798,0.17901,0.74855,10,,,,,,,,,,,,,,,,,,,,,,,,,,,,,,,,,,,,,
306.398,0.17946,0.76907,10,,,,,,,,,,,,,,,,,,,,,,,,,,,,,,,,,,,,,
306.998,0.17975,0.75503,10,,,,,,,,,,,,,,,,,,,,,,,,,,,,,,,,,,,,,
307.598,0.17997,0.81191,10,,,,,,,,,,,,,,,,,,,,,,,,,,,,,,,,,,,,,
308.198,0.18014,0.78146,10,,,,,,,,,,,,,,,,,,,,,,,,,,,,,,,,,,,,,
308.798,0.18014,0.79992,10,,,,,,,,,,,,,,,,,,,,,,,,,,,,,,,,,,,,,
309.398,0.18003,0.77922,10,,,,,,,,,,,,,,,,,,,,,,,,,,,,,,,,,,,,,
309.998,0.17997,0.82755,10,,,,,,,,,,,,,,,,,,,,,,,,,,,,,,,,,,,,,
310.598,0.17997,0.79318,10,,,,,,,,,,,,,,,,,,,,,,,,,,,,,,,,,,,,,
311.198,0.17997,0.82776,10,,,,,,,,,,,,,,,,,,,,,,,,,,,,,,,,,,,,,
311.798,0.17986,0.76094,10,,,,,,,,,,,,,,,,,,,,,,,,,,,,,,,,,,,,,
312.398,0.1798,0.81405,10,,,,,,,,,,,,,,,,,,,,,,,,,,,,,,,,,,,,,
312.998,0.17975,0.78028,10,,,,,,,,,,,,,,,,,,,,,,,,,,,,,,,,,,,,,
313.598,0.17969,0.8357,10,,,,,,,,,,,,,,,,,,,,,,,,,,,,,,,,,,,,,
314.198,0.17969,0.73585,10,,,,,,,,,,,,,,,,,,,,,,,,,,,,,,,,,,,,,
314.798,0.17963,0.79341,10,,,,,,,,,,,,,,,,,,,,,,,,,,,,,,,,,,,,,
315.398,0.17952,0.77312,10,,,,,,,,,,,,,,,,,,,,,,,,,,,,,,,,,,,,,
315.998,0.17941,0.77476,10,,,,,,,,,,,,,,,,,,,,,,,,,,,,,,,,,,,,,
316.598,0.17929,0.7347,10,,,,,,,,,,,,,,,,,,,,,,,,,,,,,,,,,,,,,
317.198,0.17918,0.75549,10,,,,,,,,,,,,,,,,,,,,,,,,,,,,,,,,,,,,,
317.798,0.17907,0.76283,10,,,,,,,,,,,,,,,,,,,,,,,,,,,,,,,,,,,,,
318.398,0.17901,0.76267,10,,,,,,,,,,,,,,,,,,,,,,,,,,,,,,,,,,,,,
318.998,0.17907,0.70794,10,,,,,,,,,,,,,,,,,,,,,,,,,,,,,,,,,,,,,
319.598,0.17907,0.77041,10,,,,,,,,,,,,,,,,,,,,,,,,,,,,,,,,,,,,,
320.198,0.17901,0.73834,10,,,,,,,,,,,,,,,,,,,,,,,,,,,,,,,,,,,,,
320.798,0.17912,0.72129,10,,,,,,,,,,,,,,,,,,,,,,,,,,,,,,,,,,,,,
321.398,0.17912,0.74414,10,,,,,,,,,,,,,,,,,,,,,,,,,,,,,,,,,,,,,
321.998,0.17912,0.72572,10,,,,,,,,,,,,,,,,,,,,,,,,,,,,,,,,,,,,,
322.598,0.17912,0.7326,10,,,,,,,,,,,,,,,,,,,,,,,,,,,,,,,,,,,,,
323.198,0.17912,0.76826,10,,,,,,,,,,,,,,,,,,,,,,,,,,,,,,,,,,,,,
323.798,0.17912,0.72571,10,,,,,,,,,,,,,,,,,,,,,,,,,,,,,,,,,,,,,
324.398,0.17918,0.75459,10,,,,,,,,,,,,,,,,,,,,,,,,,,,,,,,,,,,,,
324.998,0.17918,0.74984,10,,,,,,,,,,,,,,,,,,,,,,,,,,,,,,,,,,,,,
325.598,0.17918,0.76127,10,,,,,,,,,,,,,,,,,,,,,,,,,,,,,,,,,,,,,
326.198,0.17918,0.74983,10,,,,,,,,,,,,,,,,,,,,,,,,,,,,,,,,,,,,,
326.798,0.17924,0.73959,10,,,,,,,,,,,,,,,,,,,,,,,,,,,,,,,,,,,,,
327.398,0.17924,0.75897,10,,,,,,,,,,,,,,,,,,,,,,,,,,,,,,,,,,,,,
327.998,0.17929,0.72474,10,,,,,,,,,,,,,,,,,,,,,,,,,,,,,,,,,,,,,
328.598,0.17935,0.76096,10,,,,,,,,,,,,,,,,,,,,,,,,,,,,,,,,,,,,,
329.198,0.17935,0.78917,10,,,,,,,,,,,,,,,,,,,,,,,,,,,,,,,,,,,,,
329.798,0.17941,0.77758,10,,,,,,,,,,,,,,,,,,,,,,,,,,,,,,,,,,,,,
330.398,0.17941,0.73642,10,,,,,,,,,,,,,,,,,,,,,,,,,,,,,,,,,,,,,
330.998,0.17952,0.72534,10,,,,,,,,,,,,,,,,,,,,,,,,,,,,,,,,,,,,,
331.598,0.17958,0.72313,10,,,,,,,,,,,,,,,,,,,,,,,,,,,,,,,,,,,,,
332.198,0.17963,0.76927,10,,,,,,,,,,,,,,,,,,,,,,,,,,,,,,,,,,,,,
332.798,0.17975,0.75871,10,,,,,,,,,,,,,,,,,,,,,,,,,,,,,,,,,,,,,
333.398,0.17986,0.75851,10,,,,,,,,,,,,,,,,,,,,,,,,,,,,,,,,,,,,,
333.998,0.17992,0.80357,10,,,,,,,,,,,,,,,,,,,,,,,,,,,,,,,,,,,,,
334.598,0.17997,0.77009,10,,,,,,,,,,,,,,,,,,,,,,,,,,,,,,,,,,,,,
335.198,0.17986,0.74253,10,,,,,,,,,,,,,,,,,,,,,,,,,,,,,,,,,,,,,
335.798,0.17986,0.78287,10,,,,,,,,,,,,,,,,,,,,,,,,,,,,,,,,,,,,,
336.398,0.17986,0.75282,10,,,,,,,,,,,,,,,,,,,,,,,,,,,,,,,,,,,,,
336.998,0.17986,0.77972,10,,,,,,,,,,,,,,,,,,,,,,,,,,,,,,,,,,,,,
337.598,0.17986,0.76897,10,,,,,,,,,,,,,,,,,,,,,,,,,,,,,,,,,,,,,
338.198,0.17992,0.83164,10,,,,,,,,,,,,,,,,,,,,,,,,,,,,,,,,,,,,,
338.798,0.1798,0.76432,10,,,,,,,,,,,,,,,,,,,,,,,,,,,,,,,,,,,,,
339.398,0.1798,0.76413,10,,,,,,,,,,,,,,,,,,,,,,,,,,,,,,,,,,,,,
339.998,0.1798,0.73806,10,,,,,,,,,,,,,,,,,,,,,,,,,,,,,,,,,,,,,
340.598,0.1798,0.77909,10,,,,,,,,,,,,,,,,,,,,,,,,,,,,,,,,,,,,,
341.198,0.17986,0.76823,10,,,,,,,,,,,,,,,,,,,,,,,,,,,,,,,,,,,,,
341.798,0.17986,0.71629,10,,,,,,,,,,,,,,,,,,,,,,,,,,,,,,,,,,,,,
342.398,0.1798,0.77028,10,,,,,,,,,,,,,,,,,,,,,,,,,,,,,,,,,,,,,
342.998,0.17992,0.75263,10,,,,,,,,,,,,,,,,,,,,,,,,,,,,,,,,,,,,,
343.598,0.1798,0.73218,10,,,,,,,,,,,,,,,,,,,,,,,,,,,,,,,,,,,,,
344.198,0.17992,0.7668,10,,,,,,,,,,,,,,,,,,,,,,,,,,,,,,,,,,,,,
344.798,0.17992,0.74457,10,,,,,,,,,,,,,,,,,,,,,,,,,,,,,,,,,,,,,
345.398,0.17992,0.70859,10,,,,,,,,,,,,,,,,,,,,,,,,,,,,,,,,,,,,,
345.998,0.17992,0.72982,10,,,,,,,,,,,,,,,,,,,,,,,,,,,,,,,,,,,,,
346.598,0.17997,0.80174,10,,,,,,,,,,,,,,,,,,,,,,,,,,,,,,,,,,,,,
347.198,0.17997,0.80845,10,,,,,,,,,,,,,,,,,,,,,,,,,,,,,,,,,,,,,
347.798,0.17997,0.7781,10,,,,,,,,,,,,,,,,,,,,,,,,,,,,,,,,,,,,,
348.398,0.17997,0.77395,10,,,,,,,,,,,,,,,,,,,,,,,,,,,,,,,,,,,,,
348.998,0.17997,0.76968,10,,,,,,,,,,,,,,,,,,,,,,,,,,,,,,,,,,,,,
349.598,0.17997,0.76306,10,,,,,,,,,,,,,,,,,,,,,,,,,,,,,,,,,,,,,
350.198,0.17997,0.82493,10,,,,,,,,,,,,,,,,,,,,,,,,,,,,,,,,,,,,,
350.798,0.17997,0.77637,10,,,,,,,,,,,,,,,,,,,,,,,,,,,,,,,,,,,,,
351.398,0.17997,0.77727,10,,,,,,,,,,,,,,,,,,,,,,,,,,,,,,,,,,,,,
351.998,0.17986,0.73638,10,,,,,,,,,,,,,,,,,,,,,,,,,,,,,,,,,,,,,
352.598,0.17986,0.73298,10,,,,,,,,,,,,,,,,,,,,,,,,,,,,,,,,,,,,,
353.198,0.17992,0.87844,10,,,,,,,,,,,,,,,,,,,,,,,,,,,,,,,,,,,,,
353.798,0.17986,0.72829,10,,,,,,,,,,,,,,,,,,,,,,,,,,,,,,,,,,,,,
354.398,0.17997,0.79688,10,,,,,,,,,,,,,,,,,,,,,,,,,,,,,,,,,,,,,
354.998,0.17986,0.73013,10,,,,,,,,,,,,,,,,,,,,,,,,,,,,,,,,,,,,,
355.598,0.17997,0.7273,10,,,,,,,,,,,,,,,,,,,,,,,,,,,,,,,,,,,,,
356.198,0.17986,0.80141,10,,,,,,,,,,,,,,,,,,,,,,,,,,,,,,,,,,,,,
356.798,0.17986,0.74032,10,,,,,,,,,,,,,,,,,,,,,,,,,,,,,,,,,,,,,
357.398,0.17986,0.75235,10,,,,,,,,,,,,,,,,,,,,,,,,,,,,,,,,,,,,,
357.998,0.17997,0.75143,10,,,,,,,,,,,,,,,,,,,,,,,,,,,,,,,,,,,,,
358.598,0.17997,0.76491,10,,,,,,,,,,,,,,,,,,,,,,,,,,,,,,,,,,,,,
359.198,0.17997,0.78379,10,,,,,,,,,,,,,,,,,,,,,,,,,,,,,,,,,,,,,
359.798,0.17997,0.74624,10,,,,,,,,,,,,,,,,,,,,,,,,,,,,,,,,,,,,,
360.398,0.17986,0.76258,10,,,,,,,,,,,,,,,,,,,,,,,,,,,,,,,,,,,,,
360.998,0.17997,0.7753,10,,,,,,,,,,,,,,,,,,,,,,,,,,,,,,,,,,,,,
361.598,0.17997,0.74262,10,,,,,,,,,,,,,,,,,,,,,,,,,,,,,,,,,,,,,
362.198,0.17997,0.7394,10,,,,,,,,,,,,,,,,,,,,,,,,,,,,,,,,,,,,,
362.798,0.17997,0.77291,10,,,,,,,,,,,,,,,,,,,,,,,,,,,,,,,,,,,,,
363.398,0.17997,0.73435,10,,,,,,,,,,,,,,,,,,,,,,,,,,,,,,,,,,,,,
363.998,0.17997,0.78593,10,,,,,,,,,,,,,,,,,,,,,,,,,,,,,,,,,,,,,
364.598,0.17997,0.7555,10,,,,,,,,,,,,,,,,,,,,,,,,,,,,,,,,,,,,,
365.198,0.17997,0.78986,10,,,,,,,,,,,,,,,,,,,,,,,,,,,,,,,,,,,,,
365.798,0.17997,0.7334,10,,,,,,,,,,,,,,,,,,,,,,,,,,,,,,,,,,,,,
366.398,0.17997,0.71979,10,,,,,,,,,,,,,,,,,,,,,,,,,,,,,,,,,,,,,
366.998,0.17997,0.7415,10,,,,,,,,,,,,,,,,,,,,,,,,,,,,,,,,,,,,,
367.598,0.17986,0.77161,10,,,,,,,,,,,,,,,,,,,,,,,,,,,,,,,,,,,,,
368.198,0.17997,0.76962,10,,,,,,,,,,,,,,,,,,,,,,,,,,,,,,,,,,,,,
368.798,0.17997,0.72361,10,,,,,,,,,,,,,,,,,,,,,,,,,,,,,,,,,,,,,
369.398,0.17997,0.74142,10,,,,,,,,,,,,,,,,,,,,,,,,,,,,,,,,,,,,,
369.998,0.18003,0.71802,10,,,,,,,,,,,,,,,,,,,,,,,,,,,,,,,,,,,,,
370.598,0.18003,0.70692,10,,,,,,,,,,,,,,,,,,,,,,,,,,,,,,,,,,,,,
371.198,0.18037,0.72604,10,,,,,,,,,,,,,,,,,,,,,,,,,,,,,,,,,,,,,
371.798,0.18133,0.8048,10,,,,,,,,,,,,,,,,,,,,,,,,,,,,,,,,,,,,,
372.398,0.18264,0.8109,10,,,,,,,,,,,,,,,,,,,,,,,,,,,,,,,,,,,,,
372.998,0.18292,0.76596,10,,,,,,,,,,,,,,,,,,,,,,,,,,,,,,,,,,,,,
373.598,0.18298,0.7934,10,,,,,,,,,,,,,,,,,,,,,,,,,,,,,,,,,,,,,
374.198,0.18286,0.79708,10,,,,,,,,,,,,,,,,,,,,,,,,,,,,,,,,,,,,,
374.798,0.18281,0.81787,10,,,,,,,,,,,,,,,,,,,,,,,,,,,,,,,,,,,,,
375.398,0.18275,0.80211,10,,,,,,,,,,,,,,,,,,,,,,,,,,,,,,,,,,,,,
375.998,0.18269,0.82705,10,,,,,,,,,,,,,,,,,,,,,,,,,,,,,,,,,,,,,
376.598,0.18264,0.81367,10,,,,,,,,,,,,,,,,,,,,,,,,,,,,,,,,,,,,,
377.198,0.18258,0.78801,10,,,,,,,,,,,,,,,,,,,,,,,,,,,,,,,,,,,,,
377.798,0.18247,0.79329,10,,,,,,,,,,,,,,,,,,,,,,,,,,,,,,,,,,,,,
378.398,0.18213,0.79082,10,,,,,,,,,,,,,,,,,,,,,,,,,,,,,,,,,,,,,
378.998,0.18179,0.80999,10,,,,,,,,,,,,,,,,,,,,,,,,,,,,,,,,,,,,,
379.598,0.18139,0.80789,10,,,,,,,,,,,,,,,,,,,,,,,,,,,,,,,,,,,,,
380.198,0.18111,0.7775,10,,,,,,,,,,,,,,,,,,,,,,,,,,,,,,,,,,,,,
380.7,1.69139,120.44488,10,,,,,,,,,,,,,,,,,,,,,,,,,,,,,,,,,,,,,
381.3,6.69743,1432.70374,10,,,,,,,,,,,,,,,,,,,,,,,,,,,,,,,,,,,,,
381.9,11.6977,689.98657,10,,,,,,,,,,,,,,,,,,,,,,,,,,,,,,,,,,,,,
382.5,16.69757,130.31709,10,,,,,,,,,,,,,,,,,,,,,,,,,,,,,,,,,,,,,
383.1,21.69749,77.62585,10,,,,,,,,,,,,,,,,,,,,,,,,,,,,,,,,,,,,,
383.7,26.69753,46.00977,10,,,,,,,,,,,,,,,,,,,,,,,,,,,,,,,,,,,,,
384.3,31.69763,26.28013,10,,,,,,,,,,,,,,,,,,,,,,,,,,,,,,,,,,,,,
384.9,36.69756,10.20069,10,,,,,,,,,,,,,,,,,,,,,,,,,,,,,,,,,,,,,
385.5,41.6976,6.64017,10,,,,,,,,,,,,,,,,,,,,,,,,,,,,,,,,,,,,,
386.1,46.69758,3.55278,10,,,,,,,,,,,,,,,,,,,,,,,,,,,,,,,,,,,,,
386.7,51.69757,1.32371,10,,,,,,,,,,,,,,,,,,,,,,,,,,,,,,,,,,,,,
387.3,56.69754,1.50219,10,,,,,,,,,,,,,,,,,,,,,,,,,,,,,,,,,,,,,
387.9,61.69759,0.5726,10,,,,,,,,,,,,,,,,,,,,,,,,,,,,,,,,,,,,,
388.5,66.69757,-3.30665,10,,,,,,,,,,,,,,,,,,,,,,,,,,,,,,,,,,,,,
389.1,71.69755,2.23242,10,,,,,,,,,,,,,,,,,,,,,,,,,,,,,,,,,,,,,
389.7,76.69753,7.72995,10,,,,,,,,,,,,,,,,,,,,,,,,,,,,,,,,,,,,,
390.3,81.69757,6.14046,10,,,,,,,,,,,,,,,,,,,,,,,,,,,,,,,,,,,,,
390.9,86.69749,-6.23744,10,,,,,,,,,,,,,,,,,,,,,,,,,,,,,,,,,,,,,
391.5,91.6976,-7.78799,10,,,,,,,,,,,,,,,,,,,,,,,,,,,,,,,,,,,,,
392.1,96.69752,-8.12897,10,,,,,,,,,,,,,,,,,,,,,,,,,,,,,,,,,,,,,
392.7,101.69756,-8.49705,10,,,,,,,,,,,,,,,,,,,,,,,,,,,,,,,,,,,,,
393.3,106.69749,-8.54527,10,,,,,,,,,,,,,,,,,,,,,,,,,,,,,,,,,,,,,
393.9,111.69759,-8.82417,10,,,,,,,,,,,,,,,,,,,,,,,,,,,,,,,,,,,,,
394.5,116.69756,-8.83481,10,,,,,,,,,,,,,,,,,,,,,,,,,,,,,,,,,,,,,
395.1,121.69756,-8.84936,10,,,,,,,,,,,,,,,,,,,,,,,,,,,,,,,,,,,,,
395.684,126.56425,-8.98685,10,,,,,,,,,,,,,,,,,,,,,,,,,,,,,,,,,,,,,