File: combined_ligament_solver/data/processed/Data Sheet 3_S160798_LCL.csv
Specimen properties : Length,58,mm,Unnamed: 3,Unnamed: 4,Unnamed: 5,Unnamed: 6,Unnamed: 7,Unnamed: 8,Unnamed: 9,Unnamed: 10,Unnamed: 11,Stress-Strain,Unnamed: 13,Unnamed: 14,Unnamed: 15,Unnamed: 16,Unnamed: 17,Unnamed: 18,Unnamed: 19,Unnamed: 20,Unnamed: 21,Unnamed: 22,Unnamed: 23,Unnamed: 24,Unnamed: 25,Unnamed: 26,Unnamed: 27,Linear,Unnamed: 29,Unnamed: 30,Unnamed: 31,Unnamed: 32,Unnamed: 33,Modulus,Unnamed: 35,Failure,Unnamed: 37,Unnamed: 38,Unnamed: 39,Unnamed: 40
Cross Section Average,36.032,mm2,,,,,,,,,,Polynomial Coefficients,,,,,,,,,,,,,,,,Force,,Stress,Extension,Strain,,Secant,Tangent,Load,Stress,Extension,Strain,Stiffness
Time,Extension,Load,Total cycle count,,,Extension,Load,Strain,Stress,E-tan,,X6,7778724.654533073,,,,,,,,,Strain,Stress,E-tan,,,,(N),,(MPa),(mm),(%),,(MPa),(MPa),(N),(MPa),(mm),(%),(N/mm)
(s),(mm),(N),,,,(mm),(N),(mm/mm),(MPa),(MPa),,X5,-3209405.590695168,,,,,,,,,(mm/mm),(MPa),(MPa),,,,340.3672760099518,,9.446249889263761,5.045999999999999,8.7,,108.57758493406624,162.80082301417468,629.38702,17.438894316163413,8.83337,15.229948275862071,67.45288862662542
0.5,0.12824,2.52687,0,,,4.21515,221.60245,0.06609189655172415,6.121604962255773,147.61913534668716,,,,,,,,,,,,0.005,0.07838222363140833,24.37123667183921,,,,,,,,,,,,,,,,
1.1,0.22837,4.45273,0,,,9.21519,629.38702,0.1522994827586207,17.438894316163413,,,,,,,,,,,,,0.011,0.3029005115406607,46.01033925137391,,,,,,,,,,,,,,,,
1.7,0.3281,6.67117,0,,,14.21517,37.91063,,,,,,,,,,,,,,,0.017,0.6410534526209297,63.250651178864246,,,,,,,,,,,,,,,,
2.3,0.42823,9.15427,0,,,19.21515,13.66638,,,,,,,,,,,,,,,0.023,1.071721422937291,77.54306465801889,,,,,,,,,,,,,,,,
2.9,0.52825,11.82939,0,,,,,,,,,,,,,,,,,,,0.029,1.5811412149739166,89.95911011365001,,,,,,,,,,,,,,,,
3.5,0.62838,14.48594,0,,,,,,,,,,,,,,,,,,,0.035,2.1607822951152427,101.23450709297312,,,,,,,,,,,,,,,,
4.1,0.72822,17.47648,0,,,,,,,,,,,,,,,,,,,0.041,2.8054843665349214,111.81271516690249,,,,,,,,,,,,,,,,
4.7,0.82818,20.57178,0,,,,,,,,,,,,,,,,,,,0.047,3.5118562374925664,121.88848483135028,,,,,,,,,,,,,,,,
5.3,0.92831,23.9521,0,,,,,,,,,,,,,,,,,,,0.053,4.276935995038274,131.45140840852397,,,,,,,,,,,,,,,,
5.9,1.02833,27.19279,0,,,,,,,,,,,,,,,,,,,0.059,5.097112484124943,140.32947094822208,,,,,,,,,,,,,,,,
6.5,1.12823,30.31692,0,,,,,,,,,,,,,,,,,,,0.065,5.967308092128379,148.232601129142,,,,,,,,,,,,,,,,
7.1,1.22825,33.94597,0,,,,,,,,,,,,,,,,,,,0.071,6.880422838775172,154.79622216015824,,,,,,,,,,,,,,,,
7.7,1.32827,36.28836,0,,,,,,,,,,,,,,,,,,,0.077,7.82703977147839,159.6248026816401,,,,,,,,,,,,,,,,
8.222,1.41542,40.00386,0.5,,,,,,,,,,,,,,,,,,,0.083,8.79539166608102,162.33540766673812,,,,,,,,,,,,,,,,
8.724,1.33201,34.81222,0.5,,,,,,,,,,,,,,,,,,,0.089,9.771589033007242,162.6012493226961,,,,,,,,,,,,,,,,
9.324,1.23188,29.21708,0.5,,,,,,,,,,,,,,,,,,,0.095,10.740109428821437,160.19523799210216,,,,,,,,,,,,,,,,
9.924,1.13197,24.39621,0.5,,,,,,,,,,,,,,,,,,,0.101,11.684548073195069,155.03353305429343,,,,,,,,,,,,,,,,
10.524,1.03196,20.21066,0.5,,,,,,,,,,,,,,,,,,,0.107,12.588629771281164,147.21909382648752,,,,,,,,,,,,,,,,
11.124,0.932,16.56152,0.5,,,,,,,,,,,,,,,,,,,0.113,13.437482141496911,137.0852304652671,,,,,,,,,,,,,,,,
11.724,0.83181,13.36096,0.5,,,,,,,,,,,,,,,,,,,0.119,14.219170148713635,125.2391548677315,,,,,,,,,,,,,,,,
12.324,0.73191,10.53908,0.5,,,,,,,,,,,,,,,,,,,0.125,14.926491942854948,112.60553157287835,,,,,,,,,,,,,,,,
12.924,0.632,7.99573,0.5,,,,,,,,,,,,,,,,,,,0.131,15.559036002902355,100.47002866281564,,,,,,,,,,,,,,,,
13.524,0.53199,5.59501,0.5,,,,,,,,,,,,,,,,,,,0.137,16.125499586308905,90.52286866419115,,,,,,,,,,,,,,,,
14.124,0.43186,3.58247,0.5,,,,,,,,,,,,,,,,,,,0.143,16.64626848382048,84.9023794493781,,,,,,,,,,,,,,,,
14.724,0.3319,1.90128,0.5,,,,,,,,,,,,,,,,,,,0.149,17.15625807970495,86.23854513788478,,,,,,,,,,,,,,,,
15.126,0.26486,0.98022,1,,,,,,,,,,,,,,,,,,,0.155,,,,,,,,,,,,,,,,,,
15.726,0.36595,3.29178,1,,,,,,,,,,,,,,,,,,,0.161,,,,,,,,,,,,,,,,,,
16.326,0.46591,5.77022,1,,,,,,,,,,,,,,,,,,,0.167,,,,,,,,,,,,,,,,,,
16.926,0.56599,8.23468,1,,,,,,,,,,,,,,,,,,,0.173,,,,,,,,,,,,,,,,,,
17.526,0.66578,10.94976,1,,,,,,,,,,,,,,,,,,,0.179,,,,,,,,,,,,,,,,,,
18.126,0.76591,13.71284,1,,,,,,,,,,,,,,,,,,,0.185,,,,,,,,,,,,,,,,,,
18.726,0.86598,16.81089,1,,,,,,,,,,,,,,,,,,,0.191,,,,,,,,,,,,,,,,,,
19.326,0.96594,20.2894,1,,,,,,,,,,,,,,,,,,,0.197,,,,,,,,,,,,,,,,,,
19.926,1.06584,24.0701,1,,,,,,,,,,,,,,,,,,,,,,,,,,,,,,,,,,,,,
20.526,1.16597,28.08574,1,,,,,,,,,,,,,,,,,,,,,,,,,,,,,,,,,,,,,
21.126,1.26588,32.43119,1,,,,,,,,,,,,,,,,,,,,,,,,,,,,,,,,,,,,,
21.726,1.36595,36.94046,1,,,,,,,,,,,,,,,,,,,,,,,,,,,,,,,,,,,,,
22.164,1.43888,40.02054,1.5,,,,,,,,,,,,,,,,,,,,,,,,,,,,,,,,,,,,,
22.764,1.33852,33.88433,1.5,,,,,,,,,,,,,,,,,,,,,,,,,,,,,,,,,,,,,
23.364,1.23862,28.51125,1.5,,,,,,,,,,,,,,,,,,,,,,,,,,,,,,,,,,,,,
23.964,1.13872,23.82933,1.5,,,,,,,,,,,,,,,,,,,,,,,,,,,,,,,,,,,,,
24.564,1.03864,19.79491,1.5,,,,,,,,,,,,,,,,,,,,,,,,,,,,,,,,,,,,,
25.164,0.93857,16.25127,1.5,,,,,,,,,,,,,,,,,,,,,,,,,,,,,,,,,,,,,
25.764,0.83844,13.04747,1.5,,,,,,,,,,,,,,,,,,,,,,,,,,,,,,,,,,,,,
26.364,0.73865,10.2724,1.5,,,,,,,,,,,,,,,,,,,,,,,,,,,,,,,,,,,,,
26.964,0.63863,7.63732,1.5,,,,,,,,,,,,,,,,,,,,,,,,,,,,,,,,,,,,,
27.564,0.53856,5.28409,1.5,,,,,,,,,,,,,,,,,,,,,,,,,,,,,,,,,,,,,
28.164,0.43849,3.24841,1.5,,,,,,,,,,,,,,,,,,,,,,,,,,,,,,,,,,,,,
28.764,0.3387,1.61518,1.5,,,,,,,,,,,,,,,,,,,,,,,,,,,,,,,,,,,,,
29.142,0.30492,1.00365,2,,,,,,,,,,,,,,,,,,,,,,,,,,,,,,,,,,,,,
29.742,0.40998,3.61007,2,,,,,,,,,,,,,,,,,,,,,,,,,,,,,,,,,,,,,
30.342,0.51,6.06925,2,,,,,,,,,,,,,,,,,,,,,,,,,,,,,,,,,,,,,
30.942,0.60979,8.63701,2,,,,,,,,,,,,,,,,,,,,,,,,,,,,,,,,,,,,,
31.542,0.70986,11.21248,2,,,,,,,,,,,,,,,,,,,,,,,,,,,,,,,,,,,,,
32.142,0.80994,13.95175,2,,,,,,,,,,,,,,,,,,,,,,,,,,,,,,,,,,,,,
32.742,0.91001,17.16369,2,,,,,,,,,,,,,,,,,,,,,,,,,,,,,,,,,,,,,
33.342,1.00986,20.66697,2,,,,,,,,,,,,,,,,,,,,,,,,,,,,,,,,,,,,,
33.942,1.10987,24.4995,2,,,,,,,,,,,,,,,,,,,,,,,,,,,,,,,,,,,,,
34.542,1.20995,28.63065,2,,,,,,,,,,,,,,,,,,,,,,,,,,,,,,,,,,,,,
35.142,1.30996,33.04681,2,,,,,,,,,,,,,,,,,,,,,,,,,,,,,,,,,,,,,
35.742,1.40992,37.71389,2,,,,,,,,,,,,,,,,,,,,,,,,,,,,,,,,,,,,,
36.244,1.42721,38.14904,2.5,,,,,,,,,,,,,,,,,,,,,,,,,,,,,,,,,,,,,
36.844,1.32662,32.0613,2.5,,,,,,,,,,,,,,,,,,,,,,,,,,,,,,,,,,,,,
37.444,1.22655,26.92562,2.5,,,,,,,,,,,,,,,,,,,,,,,,,,,,,,,,,,,,,
38.044,1.12659,22.46479,2.5,,,,,,,,,,,,,,,,,,,,,,,,,,,,,,,,,,,,,
38.644,1.02663,18.59397,2.5,,,,,,,,,,,,,,,,,,,,,,,,,,,,,,,,,,,,,
39.244,0.92667,15.20926,2.5,,,,,,,,,,,,,,,,,,,,,,,,,,,,,,,,,,,,,
39.844,0.8266,12.08489,2.5,,,,,,,,,,,,,,,,,,,,,,,,,,,,,,,,,,,,,
40.444,0.72658,9.46057,2.5,,,,,,,,,,,,,,,,,,,,,,,,,,,,,,,,,,,,,
41.044,0.62668,6.86745,2.5,,,,,,,,,,,,,,,,,,,,,,,,,,,,,,,,,,,,,
41.644,0.5266,4.61379,2.5,,,,,,,,,,,,,,,,,,,,,,,,,,,,,,,,,,,,,
42.244,0.42664,2.76244,2.5,,,,,,,,,,,,,,,,,,,,,,,,,,,,,,,,,,,,,
42.844,0.32651,1.14894,2.5,,,,,,,,,,,,,,,,,,,,,,,,,,,,,,,,,,,,,
43.238,0.36176,1.99276,3,,,,,,,,,,,,,,,,,,,,,,,,,,,,,,,,,,,,,
43.838,0.46195,4.41699,3,,,,,,,,,,,,,,,,,,,,,,,,,,,,,,,,,,,,,
44.438,0.56196,6.8343,3,,,,,,,,,,,,,,,,,,,,,,,,,,,,,,,,,,,,,
45.038,0.66181,9.40083,3,,,,,,,,,,,,,,,,,,,,,,,,,,,,,,,,,,,,,
45.638,0.76183,12.13633,3,,,,,,,,,,,,,,,,,,,,,,,,,,,,,,,,,,,,,
46.238,0.86201,15.03875,3,,,,,,,,,,,,,,,,,,,,,,,,,,,,,,,,,,,,,
46.838,0.96197,18.33907,3,,,,,,,,,,,,,,,,,,,,,,,,,,,,,,,,,,,,,
47.438,1.06182,21.85965,3,,,,,,,,,,,,,,,,,,,,,,,,,,,,,,,,,,,,,
48.038,1.16189,25.82828,3,,,,,,,,,,,,,,,,,,,,,,,,,,,,,,,,,,,,,
48.638,1.26191,30.03855,3,,,,,,,,,,,,,,,,,,,,,,,,,,,,,,,,,,,,,
49.238,1.36204,34.60712,3,,,,,,,,,,,,,,,,,,,,,,,,,,,,,,,,,,,,,
49.838,1.46183,39.4157,3,,,,,,,,,,,,,,,,,,,,,,,,,,,,,,,,,,,,,
50.31,1.40692,35.99305,3.5,,,,,,,,,,,,,,,,,,,,,,,,,,,,,,,,,,,,,
50.91,1.30707,30.28539,3.5,,,,,,,,,,,,,,,,,,,,,,,,,,,,,,,,,,,,,
51.51,1.207,25.40954,3.5,,,,,,,,,,,,,,,,,,,,,,,,,,,,,,,,,,,,,
52.11,1.10693,21.24143,3.5,,,,,,,,,,,,,,,,,,,,,,,,,,,,,,,,,,,,,
52.71,1.00691,17.47379,3.5,,,,,,,,,,,,,,,,,,,,,,,,,,,,,,,,,,,,,
53.31,0.90695,14.2228,3.5,,,,,,,,,,,,,,,,,,,,,,,,,,,,,,,,,,,,,
53.91,0.80693,11.15564,3.5,,,,,,,,,,,,,,,,,,,,,,,,,,,,,,,,,,,,,
54.51,0.70697,8.53446,3.5,,,,,,,,,,,,,,,,,,,,,,,,,,,,,,,,,,,,,
55.11,0.60679,6.07638,3.5,,,,,,,,,,,,,,,,,,,,,,,,,,,,,,,,,,,,,
55.71,0.50694,3.96808,3.5,,,,,,,,,,,,,,,,,,,,,,,,,,,,,,,,,,,,,
56.31,0.40692,2.20313,3.5,,,,,,,,,,,,,,,,,,,,,,,,,,,,,,,,,,,,,
56.728,0.33728,0.99,4,,,,,,,,,,,,,,,,,,,,,,,,,,,,,,,,,,,,,
57.23,0.42126,2.86016,4,,,,,,,,,,,,,,,,,,,,,,,,,,,,,,,,,,,,,
57.83,0.52128,5.38941,4,,,,,,,,,,,,,,,,,,,,,,,,,,,,,,,,,,,,,
58.43,0.62135,7.90487,4,,,,,,,,,,,,,,,,,,,,,,,,,,,,,,,,,,,,,
59.03,0.7212,10.62775,4,,,,,,,,,,,,,,,,,,,,,,,,,,,,,,,,,,,,,
59.63,0.82127,13.33231,4,,,,,,,,,,,,,,,,,,,,,,,,,,,,,,,,,,,,,
60.23,0.92129,16.47596,4,,,,,,,,,,,,,,,,,,,,,,,,,,,,,,,,,,,,,
60.83,1.0213,19.87894,4,,,,,,,,,,,,,,,,,,,,,,,,,,,,,,,,,,,,,
61.43,1.12126,23.5642,4,,,,,,,,,,,,,,,,,,,,,,,,,,,,,,,,,,,,,
62.03,1.22122,27.70942,4,,,,,,,,,,,,,,,,,,,,,,,,,,,,,,,,,,,,,
62.63,1.32118,32.03989,4,,,,,,,,,,,,,,,,,,,,,,,,,,,,,,,,,,,,,
63.23,1.42137,36.67583,4,,,,,,,,,,,,,,,,,,,,,,,,,,,,,,,,,,,,,
63.778,1.51255,40.0139,4.5,,,,,,,,,,,,,,,,,,,,,,,,,,,,,,,,,,,,,
64.28,1.42942,34.97034,4.5,,,,,,,,,,,,,,,,,,,,,,,,,,,,,,,,,,,,,
64.88,1.32934,29.46494,4.5,,,,,,,,,,,,,,,,,,,,,,,,,,,,,,,,,,,,,
65.48,1.22916,24.64128,4.5,,,,,,,,,,,,,,,,,,,,,,,,,,,,,,,,,,,,,
66.08,1.12925,20.46134,4.5,,,,,,,,,,,,,,,,,,,,,,,,,,,,,,,,,,,,,
66.68,1.02935,16.78878,4.5,,,,,,,,,,,,,,,,,,,,,,,,,,,,,,,,,,,,,
67.28,0.92933,13.50099,4.5,,,,,,,,,,,,,,,,,,,,,,,,,,,,,,,,,,,,,
67.88,0.82915,10.71098,4.5,,,,,,,,,,,,,,,,,,,,,,,,,,,,,,,,,,,,,
68.48,0.72924,8.11118,4.5,,,,,,,,,,,,,,,,,,,,,,,,,,,,,,,,,,,,,
69.08,0.62934,5.65648,4.5,,,,,,,,,,,,,,,,,,,,,,,,,,,,,,,,,,,,,
69.68,0.52927,3.56439,4.5,,,,,,,,,,,,,,,,,,,,,,,,,,,,,,,,,,,,,
70.28,0.42919,1.87623,4.5,,,,,,,,,,,,,,,,,,,,,,,,,,,,,,,,,,,,,
70.684,0.36199,0.98775,5,,,,,,,,,,,,,,,,,,,,,,,,,,,,,,,,,,,,,
71.186,0.44591,2.82365,5,,,,,,,,,,,,,,,,,,,,,,,,,,,,,,,,,,,,,
71.786,0.54581,5.32349,5,,,,,,,,,,,,,,,,,,,,,,,,,,,,,,,,,,,,,
72.386,0.64589,7.82569,5,,,,,,,,,,,,,,,,,,,,,,,,,,,,,,,,,,,,,
72.986,0.74602,10.57807,5,,,,,,,,,,,,,,,,,,,,,,,,,,,,,,,,,,,,,
73.586,0.84598,13.3401,5,,,,,,,,,,,,,,,,,,,,,,,,,,,,,,,,,,,,,
74.186,0.94582,16.54108,5,,,,,,,,,,,,,,,,,,,,,,,,,,,,,,,,,,,,,
74.786,1.04595,19.85731,5,,,,,,,,,,,,,,,,,,,,,,,,,,,,,,,,,,,,,
75.386,1.14597,23.59095,5,,,,,,,,,,,,,,,,,,,,,,,,,,,,,,,,,,,,,
75.986,1.24599,27.73967,5,,,,,,,,,,,,,,,,,,,,,,,,,,,,,,,,,,,,,
76.586,1.34583,32.18678,5,,,,,,,,,,,,,,,,,,,,,,,,,,,,,,,,,,,,,
77.186,1.44591,36.92788,5,,,,,,,,,,,,,,,,,,,,,,,,,,,,,,,,,,,,,
77.662,1.49623,39.73157,5.5,,,,,,,,,,,,,,,,,,,,,,,,,,,,,,,,,,,,,
78.262,1.39156,33.03327,5.5,,,,,,,,,,,,,,,,,,,,,,,,,,,,,,,,,,,,,
78.862,1.29149,27.79709,5.5,,,,,,,,,,,,,,,,,,,,,,,,,,,,,,,,,,,,,
79.462,1.1917,23.21638,5.5,,,,,,,,,,,,,,,,,,,,,,,,,,,,,,,,,,,,,
80.062,1.09163,19.2762,5.5,,,,,,,,,,,,,,,,,,,,,,,,,,,,,,,,,,,,,
80.662,0.99161,15.81254,5.5,,,,,,,,,,,,,,,,,,,,,,,,,,,,,,,,,,,,,
81.262,0.89154,12.5906,5.5,,,,,,,,,,,,,,,,,,,,,,,,,,,,,,,,,,,,,
81.862,0.79169,9.90463,5.5,,,,,,,,,,,,,,,,,,,,,,,,,,,,,,,,,,,,,
82.462,0.69162,7.23647,5.5,,,,,,,,,,,,,,,,,,,,,,,,,,,,,,,,,,,,,
83.062,0.5916,4.94015,5.5,,,,,,,,,,,,,,,,,,,,,,,,,,,,,,,,,,,,,
83.662,0.49153,2.99932,5.5,,,,,,,,,,,,,,,,,,,,,,,,,,,,,,,,,,,,,
84.262,0.39162,1.39393,5.5,,,,,,,,,,,,,,,,,,,,,,,,,,,,,,,,,,,,,
84.634,0.39695,1.60692,6,,,,,,,,,,,,,,,,,,,,,,,,,,,,,,,,,,,,,
85.234,0.49719,4.04308,6,,,,,,,,,,,,,,,,,,,,,,,,,,,,,,,,,,,,,
85.834,0.59715,6.51129,6,,,,,,,,,,,,,,,,,,,,,,,,,,,,,,,,,,,,,
86.434,0.69717,9.02707,6,,,,,,,,,,,,,,,,,,,,,,,,,,,,,,,,,,,,,
87.034,0.79741,11.73375,6,,,,,,,,,,,,,,,,,,,,,,,,,,,,,,,,,,,,,
87.634,0.89726,14.61839,6,,,,,,,,,,,,,,,,,,,,,,,,,,,,,,,,,,,,,
88.234,0.99722,17.84337,6,,,,,,,,,,,,,,,,,,,,,,,,,,,,,,,,,,,,,
88.834,1.09718,21.37132,6,,,,,,,,,,,,,,,,,,,,,,,,,,,,,,,,,,,,,
89.434,1.19737,25.32829,6,,,,,,,,,,,,,,,,,,,,,,,,,,,,,,,,,,,,,
90.034,1.29727,29.62341,6,,,,,,,,,,,,,,,,,,,,,,,,,,,,,,,,,,,,,
90.634,1.39712,34.1556,6,,,,,,,,,,,,,,,,,,,,,,,,,,,,,,,,,,,,,
91.234,1.49719,39.03141,6,,,,,,,,,,,,,,,,,,,,,,,,,,,,,,,,,,,,,
91.654,1.46699,37.07368,6.5,,,,,,,,,,,,,,,,,,,,,,,,,,,,,,,,,,,,,
92.254,1.36708,31.23701,6.5,,,,,,,,,,,,,,,,,,,,,,,,,,,,,,,,,,,,,
92.854,1.26707,26.2294,6.5,,,,,,,,,,,,,,,,,,,,,,,,,,,,,,,,,,,,,
93.454,1.16688,21.8559,6.5,,,,,,,,,,,,,,,,,,,,,,,,,,,,,,,,,,,,,
94.054,1.06681,18.11034,6.5,,,,,,,,,,,,,,,,,,,,,,,,,,,,,,,,,,,,,
94.654,0.96696,14.72424,6.5,,,,,,,,,,,,,,,,,,,,,,,,,,,,,,,,,,,,,
95.254,0.867,11.65199,6.5,,,,,,,,,,,,,,,,,,,,,,,,,,,,,,,,,,,,,
95.854,0.76693,8.95838,6.5,,,,,,,,,,,,,,,,,,,,,,,,,,,,,,,,,,,,,
96.454,0.66685,6.47468,6.5,,,,,,,,,,,,,,,,,,,,,,,,,,,,,,,,,,,,,
97.054,0.56701,4.31026,6.5,,,,,,,,,,,,,,,,,,,,,,,,,,,,,,,,,,,,,
97.654,0.46699,2.50902,6.5,,,,,,,,,,,,,,,,,,,,,,,,,,,,,,,,,,,,,
98.194,0.37678,0.99959,7,,,,,,,,,,,,,,,,,,,,,,,,,,,,,,,,,,,,,
98.598,0.44393,2.42068,7,,,,,,,,,,,,,,,,,,,,,,,,,,,,,,,,,,,,,
99.198,0.54383,4.88091,7,,,,,,,,,,,,,,,,,,,,,,,,,,,,,,,,,,,,,
99.798,0.64385,7.3128,7,,,,,,,,,,,,,,,,,,,,,,,,,,,,,,,,,,,,,
100.398,0.74403,10.02027,7,,,,,,,,,,,,,,,,,,,,,,,,,,,,,,,,,,,,,
100.998,0.84394,12.75096,7,,,,,,,,,,,,,,,,,,,,,,,,,,,,,,,,,,,,,
101.598,0.94384,15.77053,7,,,,,,,,,,,,,,,,,,,,,,,,,,,,,,,,,,,,,
102.198,1.04391,19.14642,7,,,,,,,,,,,,,,,,,,,,,,,,,,,,,,,,,,,,,
102.798,1.14404,22.84108,7,,,,,,,,,,,,,,,,,,,,,,,,,,,,,,,,,,,,,
103.398,1.244,26.89181,7,,,,,,,,,,,,,,,,,,,,,,,,,,,,,,,,,,,,,
103.998,1.34385,31.34603,7,,,,,,,,,,,,,,,,,,,,,,,,,,,,,,,,,,,,,
104.598,1.44387,35.99866,7,,,,,,,,,,,,,,,,,,,,,,,,,,,,,,,,,,,,,
105.198,1.54405,39.82521,7,,,,,,,,,,,,,,,,,,,,,,,,,,,,,,,,,,,,,
105.616,1.48002,36.11154,7.5,,,,,,,,,,,,,,,,,,,,,,,,,,,,,,,,,,,,,
106.216,1.38,30.37983,7.5,,,,,,,,,,,,,,,,,,,,,,,,,,,,,,,,,,,,,
106.816,1.27987,25.46384,7.5,,,,,,,,,,,,,,,,,,,,,,,,,,,,,,,,,,,,,
107.416,1.17997,21.16481,7.5,,,,,,,,,,,,,,,,,,,,,,,,,,,,,,,,,,,,,
108.016,1.07995,17.43108,7.5,,,,,,,,,,,,,,,,,,,,,,,,,,,,,,,,,,,,,
108.616,0.97994,14.06364,7.5,,,,,,,,,,,,,,,,,,,,,,,,,,,,,,,,,,,,,
109.216,0.87998,11.18151,7.5,,,,,,,,,,,,,,,,,,,,,,,,,,,,,,,,,,,,,
109.816,0.7799,8.56417,7.5,,,,,,,,,,,,,,,,,,,,,,,,,,,,,,,,,,,,,
110.416,0.67989,6.11531,7.5,,,,,,,,,,,,,,,,,,,,,,,,,,,,,,,,,,,,,
111.016,0.57993,3.90146,7.5,,,,,,,,,,,,,,,,,,,,,,,,,,,,,,,,,,,,,
111.616,0.47997,2.17896,7.5,,,,,,,,,,,,,,,,,,,,,,,,,,,,,,,,,,,,,
112.138,0.39298,0.98653,8,,,,,,,,,,,,,,,,,,,,,,,,,,,,,,,,,,,,,
112.542,0.45991,2.42336,8,,,,,,,,,,,,,,,,,,,,,,,,,,,,,,,,,,,,,
113.142,0.55992,4.90752,8,,,,,,,,,,,,,,,,,,,,,,,,,,,,,,,,,,,,,
113.742,0.65988,7.34874,8,,,,,,,,,,,,,,,,,,,,,,,,,,,,,,,,,,,,,
114.342,0.75979,10.04356,8,,,,,,,,,,,,,,,,,,,,,,,,,,,,,,,,,,,,,
114.942,0.85997,12.81764,8,,,,,,,,,,,,,,,,,,,,,,,,,,,,,,,,,,,,,
115.542,0.95999,15.89771,8,,,,,,,,,,,,,,,,,,,,,,,,,,,,,,,,,,,,,
116.142,1.05989,19.23095,8,,,,,,,,,,,,,,,,,,,,,,,,,,,,,,,,,,,,,
116.742,1.15991,22.84311,8,,,,,,,,,,,,,,,,,,,,,,,,,,,,,,,,,,,,,
117.342,1.25987,26.97231,8,,,,,,,,,,,,,,,,,,,,,,,,,,,,,,,,,,,,,
117.942,1.36006,31.39502,8,,,,,,,,,,,,,,,,,,,,,,,,,,,,,,,,,,,,,
118.542,1.45985,36.14326,8,,,,,,,,,,,,,,,,,,,,,,,,,,,,,,,,,,,,,
119.012,1.53833,40.02588,8.5,,,,,,,,,,,,,,,,,,,,,,,,,,,,,,,,,,,,,
119.612,1.43809,34.03133,8.5,,,,,,,,,,,,,,,,,,,,,,,,,,,,,,,,,,,,,
120.212,1.3379,28.67754,8.5,,,,,,,,,,,,,,,,,,,,,,,,,,,,,,,,,,,,,
120.812,1.23794,23.96529,8.5,,,,,,,,,,,,,,,,,,,,,,,,,,,,,,,,,,,,,
121.412,1.13804,19.88705,8.5,,,,,,,,,,,,,,,,,,,,,,,,,,,,,,,,,,,,,
122.012,1.03802,16.33435,8.5,,,,,,,,,,,,,,,,,,,,,,,,,,,,,,,,,,,,,
122.612,0.93789,13.1259,8.5,,,,,,,,,,,,,,,,,,,,,,,,,,,,,,,,,,,,,
123.212,0.83787,10.27548,8.5,,,,,,,,,,,,,,,,,,,,,,,,,,,,,,,,,,,,,
123.812,0.73803,7.67964,8.5,,,,,,,,,,,,,,,,,,,,,,,,,,,,,,,,,,,,,
124.412,0.63795,5.29378,8.5,,,,,,,,,,,,,,,,,,,,,,,,,,,,,,,,,,,,,
125.012,0.53788,3.29704,8.5,,,,,,,,,,,,,,,,,,,,,,,,,,,,,,,,,,,,,
125.612,0.43786,1.64886,8.5,,,,,,,,,,,,,,,,,,,,,,,,,,,,,,,,,,,,,
125.962,0.40874,0.98097,9,,,,,,,,,,,,,,,,,,,,,,,,,,,,,,,,,,,,,
126.562,0.51397,3.67117,9,,,,,,,,,,,,,,,,,,,,,,,,,,,,,,,,,,,,,
127.162,0.61393,6.12945,9,,,,,,,,,,,,,,,,,,,,,,,,,,,,,,,,,,,,,
127.762,0.71389,8.53356,9,,,,,,,,,,,,,,,,,,,,,,,,,,,,,,,,,,,,,
128.362,0.81385,11.30711,9,,,,,,,,,,,,,,,,,,,,,,,,,,,,,,,,,,,,,
128.962,0.91398,14.14044,9,,,,,,,,,,,,,,,,,,,,,,,,,,,,,,,,,,,,,
129.562,1.01394,17.37252,9,,,,,,,,,,,,,,,,,,,,,,,,,,,,,,,,,,,,,
130.162,1.1139,20.84033,9,,,,,,,,,,,,,,,,,,,,,,,,,,,,,,,,,,,,,
130.762,1.21386,24.78474,9,,,,,,,,,,,,,,,,,,,,,,,,,,,,,,,,,,,,,
131.362,1.31393,29.00714,9,,,,,,,,,,,,,,,,,,,,,,,,,,,,,,,,,,,,,
131.962,1.41406,33.58809,9,,,,,,,,,,,,,,,,,,,,,,,,,,,,,,,,,,,,,
132.562,1.51385,38.30429,9,,,,,,,,,,,,,,,,,,,,,,,,,,,,,,,,,,,,,
132.98,1.55459,39.76516,9.5,,,,,,,,,,,,,,,,,,,,,,,,,,,,,,,,,,,,,
133.58,1.44999,33.0786,9.5,,,,,,,,,,,,,,,,,,,,,,,,,,,,,,,,,,,,,
134.18,1.34991,27.83907,9.5,,,,,,,,,,,,,,,,,,,,,,,,,,,,,,,,,,,,,
134.78,1.25001,23.23509,9.5,,,,,,,,,,,,,,,,,,,,,,,,,,,,,,,,,,,,,
135.38,1.15005,19.23276,9.5,,,,,,,,,,,,,,,,,,,,,,,,,,,,,,,,,,,,,
135.98,1.04998,15.63489,9.5,,,,,,,,,,,,,,,,,,,,,,,,,,,,,,,,,,,,,
136.58,0.94979,12.53154,9.5,,,,,,,,,,,,,,,,,,,,,,,,,,,,,,,,,,,,,
137.18,0.84994,9.84725,9.5,,,,,,,,,,,,,,,,,,,,,,,,,,,,,,,,,,,,,
137.78,0.75004,7.33355,9.5,,,,,,,,,,,,,,,,,,,,,,,,,,,,,,,,,,,,,
138.38,0.64997,4.9135,9.5,,,,,,,,,,,,,,,,,,,,,,,,,,,,,,,,,,,,,
138.98,0.54984,2.92621,9.5,,,,,,,,,,,,,,,,,,,,,,,,,,,,,,,,,,,,,
139.58,0.44993,1.43146,9.5,,,,,,,,,,,,,,,,,,,,,,,,,,,,,,,,,,,,,
139.986,0.38771,0.5529,10,,,,,,,,,,,,,,,,,,,,,,,,,,,,,,,,,,,,,
140.586,0.37564,0.48461,10,,,,,,,,,,,,,,,,,,,,,,,,,,,,,,,,,,,,,
141.186,0.3821,0.61929,10,,,,,,,,,,,,,,,,,,,,,,,,,,,,,,,,,,,,,
141.786,0.41979,1.53728,10,,,,,,,,,,,,,,,,,,,,,,,,,,,,,,,,,,,,,
142.386,0.41871,1.50805,10,,,,,,,,,,,,,,,,,,,,,,,,,,,,,,,,,,,,,
142.986,0.39593,1.01204,10,,,,,,,,,,,,,,,,,,,,,,,,,,,,,,,,,,,,,
143.586,0.38703,0.81741,10,,,,,,,,,,,,,,,,,,,,,,,,,,,,,,,,,,,,,
144.186,0.38732,0.90505,10,,,,,,,,,,,,,,,,,,,,,,,,,,,,,,,,,,,,,
144.786,0.38777,0.84022,10,,,,,,,,,,,,,,,,,,,,,,,,,,,,,,,,,,,,,
145.386,0.38913,0.87081,10,,,,,,,,,,,,,,,,,,,,,,,,,,,,,,,,,,,,,
145.986,0.39429,1.01772,10,,,,,,,,,,,,,,,,,,,,,,,,,,,,,,,,,,,,,
146.586,0.39956,1.16028,10,,,,,,,,,,,,,,,,,,,,,,,,,,,,,,,,,,,,,
147.186,0.39944,1.23502,10,,,,,,,,,,,,,,,,,,,,,,,,,,,,,,,,,,,,,
147.786,0.39922,1.17547,10,,,,,,,,,,,,,,,,,,,,,,,,,,,,,,,,,,,,,
148.386,0.39786,1.22885,10,,,,,,,,,,,,,,,,,,,,,,,,,,,,,,,,,,,,,
148.986,0.39242,1.18266,10,,,,,,,,,,,,,,,,,,,,,,,,,,,,,,,,,,,,,
149.586,0.3876,1.0053,10,,,,,,,,,,,,,,,,,,,,,,,,,,,,,,,,,,,,,
150.186,0.38709,1.03984,10,,,,,,,,,,,,,,,,,,,,,,,,,,,,,,,,,,,,,
150.786,0.38698,1.03265,10,,,,,,,,,,,,,,,,,,,,,,,,,,,,,,,,,,,,,
151.386,0.38703,0.98369,10,,,,,,,,,,,,,,,,,,,,,,,,,,,,,,,,,,,,,
151.986,0.38698,0.98647,10,,,,,,,,,,,,,,,,,,,,,,,,,,,,,,,,,,,,,
152.586,0.38715,0.9792,10,,,,,,,,,,,,,,,,,,,,,,,,,,,,,,,,,,,,,
153.186,0.38715,1.08845,10,,,,,,,,,,,,,,,,,,,,,,,,,,,,,,,,,,,,,
153.786,0.38715,1.05522,10,,,,,,,,,,,,,,,,,,,,,,,,,,,,,,,,,,,,,
154.386,0.38715,1.01776,10,,,,,,,,,,,,,,,,,,,,,,,,,,,,,,,,,,,,,
154.986,0.38715,1.085,10,,,,,,,,,,,,,,,,,,,,,,,,,,,,,,,,,,,,,
155.586,0.38715,1.06433,10,,,,,,,,,,,,,,,,,,,,,,,,,,,,,,,,,,,,,
156.186,0.38715,1.04925,10,,,,,,,,,,,,,,,,,,,,,,,,,,,,,,,,,,,,,
156.786,0.38715,1.04763,10,,,,,,,,,,,,,,,,,,,,,,,,,,,,,,,,,,,,,
157.386,0.38715,1.02466,10,,,,,,,,,,,,,,,,,,,,,,,,,,,,,,,,,,,,,
157.986,0.38715,1.042,10,,,,,,,,,,,,,,,,,,,,,,,,,,,,,,,,,,,,,
158.586,0.38703,1.05973,10,,,,,,,,,,,,,,,,,,,,,,,,,,,,,,,,,,,,,
159.186,0.38698,1.2624,10,,,,,,,,,,,,,,,,,,,,,,,,,,,,,,,,,,,,,
159.786,0.38698,1.00372,10,,,,,,,,,,,,,,,,,,,,,,,,,,,,,,,,,,,,,
160.386,0.38698,1.13264,10,,,,,,,,,,,,,,,,,,,,,,,,,,,,,,,,,,,,,
160.986,0.38692,1.0848,10,,,,,,,,,,,,,,,,,,,,,,,,,,,,,,,,,,,,,
161.586,0.38647,1.08265,10,,,,,,,,,,,,,,,,,,,,,,,,,,,,,,,,,,,,,
162.186,0.38403,1.1243,10,,,,,,,,,,,,,,,,,,,,,,,,,,,,,,,,,,,,,
162.786,0.38142,1.03443,10,,,,,,,,,,,,,,,,,,,,,,,,,,,,,,,,,,,,,
163.386,0.38091,0.98163,10,,,,,,,,,,,,,,,,,,,,,,,,,,,,,,,,,,,,,
163.986,0.3808,1.04044,10,,,,,,,,,,,,,,,,,,,,,,,,,,,,,,,,,,,,,
164.586,0.38086,0.93514,10,,,,,,,,,,,,,,,,,,,,,,,,,,,,,,,,,,,,,
165.186,0.38086,1.09025,10,,,,,,,,,,,,,,,,,,,,,,,,,,,,,,,,,,,,,
165.786,0.38097,0.99734,10,,,,,,,,,,,,,,,,,,,,,,,,,,,,,,,,,,,,,
166.386,0.38103,1.00208,10,,,,,,,,,,,,,,,,,,,,,,,,,,,,,,,,,,,,,
166.986,0.38114,1.00447,10,,,,,,,,,,,,,,,,,,,,,,,,,,,,,,,,,,,,,
167.586,0.38125,1.01714,10,,,,,,,,,,,,,,,,,,,,,,,,,,,,,,,,,,,,,
168.186,0.38142,1.02074,10,,,,,,,,,,,,,,,,,,,,,,,,,,,,,,,,,,,,,
168.786,0.38165,0.96431,10,,,,,,,,,,,,,,,,,,,,,,,,,,,,,,,,,,,,,
169.386,0.38199,1.03282,10,,,,,,,,,,,,,,,,,,,,,,,,,,,,,,,,,,,,,
169.986,0.38256,0.94076,10,,,,,,,,,,,,,,,,,,,,,,,,,,,,,,,,,,,,,
170.586,0.38363,1.0329,10,,,,,,,,,,,,,,,,,,,,,,,,,,,,,,,,,,,,,
171.186,0.38494,1.06632,10,,,,,,,,,,,,,,,,,,,,,,,,,,,,,,,,,,,,,
171.786,0.38556,1.04774,10,,,,,,,,,,,,,,,,,,,,,,,,,,,,,,,,,,,,,
172.386,0.38579,1.1222,10,,,,,,,,,,,,,,,,,,,,,,,,,,,,,,,,,,,,,
172.986,0.38573,1.07987,10,,,,,,,,,,,,,,,,,,,,,,,,,,,,,,,,,,,,,
173.586,0.38567,1.08013,10,,,,,,,,,,,,,,,,,,,,,,,,,,,,,,,,,,,,,
174.186,0.38556,1.08094,10,,,,,,,,,,,,,,,,,,,,,,,,,,,,,,,,,,,,,
174.786,0.3855,1.07543,10,,,,,,,,,,,,,,,,,,,,,,,,,,,,,,,,,,,,,
175.386,0.38533,1.16411,10,,,,,,,,,,,,,,,,,,,,,,,,,,,,,,,,,,,,,
175.986,0.38488,1.1103,10,,,,,,,,,,,,,,,,,,,,,,,,,,,,,,,,,,,,,
176.586,0.38397,1.15785,10,,,,,,,,,,,,,,,,,,,,,,,,,,,,,,,,,,,,,
177.186,0.38227,1.10864,10,,,,,,,,,,,,,,,,,,,,,,,,,,,,,,,,,,,,,
177.786,0.38001,1.03824,10,,,,,,,,,,,,,,,,,,,,,,,,,,,,,,,,,,,,,
178.386,0.37831,0.97988,10,,,,,,,,,,,,,,,,,,,,,,,,,,,,,,,,,,,,,
178.986,0.37774,1.06465,10,,,,,,,,,,,,,,,,,,,,,,,,,,,,,,,,,,,,,
179.586,0.37757,1.01881,10,,,,,,,,,,,,,,,,,,,,,,,,,,,,,,,,,,,,,
180.186,0.37774,0.96948,10,,,,,,,,,,,,,,,,,,,,,,,,,,,,,,,,,,,,,
180.786,0.3778,1.01144,10,,,,,,,,,,,,,,,,,,,,,,,,,,,,,,,,,,,,,
181.386,0.37791,1.00209,10,,,,,,,,,,,,,,,,,,,,,,,,,,,,,,,,,,,,,
181.986,0.37802,0.97079,10,,,,,,,,,,,,,,,,,,,,,,,,,,,,,,,,,,,,,
182.586,0.37819,0.95626,10,,,,,,,,,,,,,,,,,,,,,,,,,,,,,,,,,,,,,
183.186,0.37859,0.97803,10,,,,,,,,,,,,,,,,,,,,,,,,,,,,,,,,,,,,,
183.786,0.37904,0.9924,10,,,,,,,,,,,,,,,,,,,,,,,,,,,,,,,,,,,,,
184.386,0.37972,0.9955,10,,,,,,,,,,,,,,,,,,,,,,,,,,,,,,,,,,,,,
184.986,0.38063,1.01612,10,,,,,,,,,,,,,,,,,,,,,,,,,,,,,,,,,,,,,
185.586,0.38154,1.00008,10,,,,,,,,,,,,,,,,,,,,,,,,,,,,,,,,,,,,,
186.186,0.38244,1.03271,10,,,,,,,,,,,,,,,,,,,,,,,,,,,,,,,,,,,,,
186.786,0.38335,1.00914,10,,,,,,,,,,,,,,,,,,,,,,,,,,,,,,,,,,,,,
187.386,0.38375,1.07105,10,,,,,,,,,,,,,,,,,,,,,,,,,,,,,,,,,,,,,
187.986,0.38369,1.09758,10,,,,,,,,,,,,,,,,,,,,,,,,,,,,,,,,,,,,,
188.586,0.38363,1.09936,10,,,,,,,,,,,,,,,,,,,,,,,,,,,,,,,,,,,,,
189.186,0.38358,1.07701,10,,,,,,,,,,,,,,,,,,,,,,,,,,,,,,,,,,,,,
189.786,0.38346,1.1434,10,,,,,,,,,,,,,,,,,,,,,,,,,,,,,,,,,,,,,
190.386,0.38335,1.101,10,,,,,,,,,,,,,,,,,,,,,,,,,,,,,,,,,,,,,
190.986,0.38318,1.11268,10,,,,,,,,,,,,,,,,,,,,,,,,,,,,,,,,,,,,,
191.586,0.38278,1.11283,10,,,,,,,,,,,,,,,,,,,,,,,,,,,,,,,,,,,,,
192.186,0.38216,1.10626,10,,,,,,,,,,,,,,,,,,,,,,,,,,,,,,,,,,,,,
192.786,0.38108,1.12264,10,,,,,,,,,,,,,,,,,,,,,,,,,,,,,,,,,,,,,
193.386,0.3795,1.09074,10,,,,,,,,,,,,,,,,,,,,,,,,,,,,,,,,,,,,,
193.986,0.37859,1.03713,10,,,,,,,,,,,,,,,,,,,,,,,,,,,,,,,,,,,,,
194.586,0.37808,1.04632,10,,,,,,,,,,,,,,,,,,,,,,,,,,,,,,,,,,,,,
195.186,0.37774,1.05418,10,,,,,,,,,,,,,,,,,,,,,,,,,,,,,,,,,,,,,
195.786,0.37757,1.02581,10,,,,,,,,,,,,,,,,,,,,,,,,,,,,,,,,,,,,,
196.386,0.37751,0.96263,10,,,,,,,,,,,,,,,,,,,,,,,,,,,,,,,,,,,,,
196.986,0.37763,1.0247,10,,,,,,,,,,,,,,,,,,,,,,,,,,,,,,,,,,,,,
197.586,0.37768,0.99505,10,,,,,,,,,,,,,,,,,,,,,,,,,,,,,,,,,,,,,
198.186,0.37768,1.05677,10,,,,,,,,,,,,,,,,,,,,,,,,,,,,,,,,,,,,,
198.786,0.37774,1.02918,10,,,,,,,,,,,,,,,,,,,,,,,,,,,,,,,,,,,,,
199.386,0.3778,0.9869,10,,,,,,,,,,,,,,,,,,,,,,,,,,,,,,,,,,,,,
199.986,0.3778,1.10957,10,,,,,,,,,,,,,,,,,,,,,,,,,,,,,,,,,,,,,
200.586,0.37785,0.99522,10,,,,,,,,,,,,,,,,,,,,,,,,,,,,,,,,,,,,,
201.186,0.37785,1.06007,10,,,,,,,,,,,,,,,,,,,,,,,,,,,,,,,,,,,,,
201.786,0.37791,1.02094,10,,,,,,,,,,,,,,,,,,,,,,,,,,,,,,,,,,,,,
202.386,0.37791,1.0842,10,,,,,,,,,,,,,,,,,,,,,,,,,,,,,,,,,,,,,
202.986,0.37791,1.05768,10,,,,,,,,,,,,,,,,,,,,,,,,,,,,,,,,,,,,,
203.586,0.37797,1.05821,10,,,,,,,,,,,,,,,,,,,,,,,,,,,,,,,,,,,,,
204.186,0.37797,1.04751,10,,,,,,,,,,,,,,,,,,,,,,,,,,,,,,,,,,,,,
204.786,0.37797,1.03697,10,,,,,,,,,,,,,,,,,,,,,,,,,,,,,,,,,,,,,
205.386,0.37797,1.05908,10,,,,,,,,,,,,,,,,,,,,,,,,,,,,,,,,,,,,,
205.986,0.37797,1.04451,10,,,,,,,,,,,,,,,,,,,,,,,,,,,,,,,,,,,,,
206.586,0.37797,1.00222,10,,,,,,,,,,,,,,,,,,,,,,,,,,,,,,,,,,,,,
207.186,0.37797,1.03565,10,,,,,,,,,,,,,,,,,,,,,,,,,,,,,,,,,,,,,
207.786,0.37791,1.0452,10,,,,,,,,,,,,,,,,,,,,,,,,,,,,,,,,,,,,,
208.386,0.37802,1.02503,10,,,,,,,,,,,,,,,,,,,,,,,,,,,,,,,,,,,,,
208.986,0.37802,0.98962,10,,,,,,,,,,,,,,,,,,,,,,,,,,,,,,,,,,,,,
209.586,0.37802,1.00371,10,,,,,,,,,,,,,,,,,,,,,,,,,,,,,,,,,,,,,
210.186,0.37808,1.01569,10,,,,,,,,,,,,,,,,,,,,,,,,,,,,,,,,,,,,,
210.786,0.37808,1.08442,10,,,,,,,,,,,,,,,,,,,,,,,,,,,,,,,,,,,,,
211.386,0.37808,1.02337,10,,,,,,,,,,,,,,,,,,,,,,,,,,,,,,,,,,,,,
211.986,0.37808,1.00524,10,,,,,,,,,,,,,,,,,,,,,,,,,,,,,,,,,,,,,
212.586,0.37814,1.06087,10,,,,,,,,,,,,,,,,,,,,,,,,,,,,,,,,,,,,,
213.186,0.37814,1.05304,10,,,,,,,,,,,,,,,,,,,,,,,,,,,,,,,,,,,,,
213.786,0.37814,0.96556,10,,,,,,,,,,,,,,,,,,,,,,,,,,,,,,,,,,,,,
214.386,0.37814,1.04441,10,,,,,,,,,,,,,,,,,,,,,,,,,,,,,,,,,,,,,
214.986,0.37814,1.05062,10,,,,,,,,,,,,,,,,,,,,,,,,,,,,,,,,,,,,,
215.586,0.37814,1.02006,10,,,,,,,,,,,,,,,,,,,,,,,,,,,,,,,,,,,,,
216.186,0.37814,1.01494,10,,,,,,,,,,,,,,,,,,,,,,,,,,,,,,,,,,,,,
216.786,0.37814,1.04029,10,,,,,,,,,,,,,,,,,,,,,,,,,,,,,,,,,,,,,
217.386,0.37814,1.0154,10,,,,,,,,,,,,,,,,,,,,,,,,,,,,,,,,,,,,,
217.986,0.37819,1.01796,10,,,,,,,,,,,,,,,,,,,,,,,,,,,,,,,,,,,,,
218.586,0.37831,1.08074,10,,,,,,,,,,,,,,,,,,,,,,,,,,,,,,,,,,,,,
219.186,0.37831,1.06887,10,,,,,,,,,,,,,,,,,,,,,,,,,,,,,,,,,,,,,
219.786,0.37831,1.09734,10,,,,,,,,,,,,,,,,,,,,,,,,,,,,,,,,,,,,,
220.386,0.37819,1.06193,10,,,,,,,,,,,,,,,,,,,,,,,,,,,,,,,,,,,,,
220.986,0.37819,1.01067,10,,,,,,,,,,,,,,,,,,,,,,,,,,,,,,,,,,,,,
221.586,0.37819,1.05902,10,,,,,,,,,,,,,,,,,,,,,,,,,,,,,,,,,,,,,
222.186,0.37819,1.03936,10,,,,,,,,,,,,,,,,,,,,,,,,,,,,,,,,,,,,,
222.786,0.37819,1.03615,10,,,,,,,,,,,,,,,,,,,,,,,,,,,,,,,,,,,,,
223.386,0.37819,1.03588,10,,,,,,,,,,,,,,,,,,,,,,,,,,,,,,,,,,,,,
223.986,0.37819,1.08738,10,,,,,,,,,,,,,,,,,,,,,,,,,,,,,,,,,,,,,
224.586,0.37825,1.0832,10,,,,,,,,,,,,,,,,,,,,,,,,,,,,,,,,,,,,,
225.186,0.37825,1.02279,10,,,,,,,,,,,,,,,,,,,,,,,,,,,,,,,,,,,,,
225.786,0.37814,1.05666,10,,,,,,,,,,,,,,,,,,,,,,,,,,,,,,,,,,,,,
226.386,0.37814,1.03658,10,,,,,,,,,,,,,,,,,,,,,,,,,,,,,,,,,,,,,
226.986,0.37814,1.05129,10,,,,,,,,,,,,,,,,,,,,,,,,,,,,,,,,,,,,,
227.586,0.37819,1.00741,10,,,,,,,,,,,,,,,,,,,,,,,,,,,,,,,,,,,,,
228.186,0.37808,1.01495,10,,,,,,,,,,,,,,,,,,,,,,,,,,,,,,,,,,,,,
228.786,0.37808,1.03026,10,,,,,,,,,,,,,,,,,,,,,,,,,,,,,,,,,,,,,
229.386,0.37808,1.0603,10,,,,,,,,,,,,,,,,,,,,,,,,,,,,,,,,,,,,,
229.986,0.37808,1.07252,10,,,,,,,,,,,,,,,,,,,,,,,,,,,,,,,,,,,,,
230.586,0.37808,1.08832,10,,,,,,,,,,,,,,,,,,,,,,,,,,,,,,,,,,,,,
231.186,0.37808,1.09448,10,,,,,,,,,,,,,,,,,,,,,,,,,,,,,,,,,,,,,
231.786,0.37797,1.09512,10,,,,,,,,,,,,,,,,,,,,,,,,,,,,,,,,,,,,,
232.386,0.37785,1.06474,10,,,,,,,,,,,,,,,,,,,,,,,,,,,,,,,,,,,,,
232.986,0.37774,1.03626,10,,,,,,,,,,,,,,,,,,,,,,,,,,,,,,,,,,,,,
233.586,0.37763,1.06328,10,,,,,,,,,,,,,,,,,,,,,,,,,,,,,,,,,,,,,
234.186,0.37746,1.08413,10,,,,,,,,,,,,,,,,,,,,,,,,,,,,,,,,,,,,,
234.786,0.37712,1.06451,10,,,,,,,,,,,,,,,,,,,,,,,,,,,,,,,,,,,,,
235.386,0.37627,1.04445,10,,,,,,,,,,,,,,,,,,,,,,,,,,,,,,,,,,,,,
235.986,0.37502,1.04713,10,,,,,,,,,,,,,,,,,,,,,,,,,,,,,,,,,,,,,
236.586,0.37451,0.98574,10,,,,,,,,,,,,,,,,,,,,,,,,,,,,,,,,,,,,,
237.186,0.37434,1.05402,10,,,,,,,,,,,,,,,,,,,,,,,,,,,,,,,,,,,,,
237.786,0.37423,1.01266,10,,,,,,,,,,,,,,,,,,,,,,,,,,,,,,,,,,,,,
238.386,0.37423,1.00598,10,,,,,,,,,,,,,,,,,,,,,,,,,,,,,,,,,,,,,
238.986,0.3744,0.9729,10,,,,,,,,,,,,,,,,,,,,,,,,,,,,,,,,,,,,,
239.586,0.37445,0.96761,10,,,,,,,,,,,,,,,,,,,,,,,,,,,,,,,,,,,,,
240.186,0.37451,1.02452,10,,,,,,,,,,,,,,,,,,,,,,,,,,,,,,,,,,,,,
240.786,0.37462,1.0189,10,,,,,,,,,,,,,,,,,,,,,,,,,,,,,,,,,,,,,
241.386,0.37474,0.94256,10,,,,,,,,,,,,,,,,,,,,,,,,,,,,,,,,,,,,,
241.986,0.37491,0.95787,10,,,,,,,,,,,,,,,,,,,,,,,,,,,,,,,,,,,,,
242.586,0.37525,0.97259,10,,,,,,,,,,,,,,,,,,,,,,,,,,,,,,,,,,,,,
243.186,0.37559,0.94507,10,,,,,,,,,,,,,,,,,,,,,,,,,,,,,,,,,,,,,
243.786,0.37615,1.0066,10,,,,,,,,,,,,,,,,,,,,,,,,,,,,,,,,,,,,,
244.386,0.37678,1.05754,10,,,,,,,,,,,,,,,,,,,,,,,,,,,,,,,,,,,,,
244.986,0.37746,1.04328,10,,,,,,,,,,,,,,,,,,,,,,,,,,,,,,,,,,,,,
245.586,0.37819,1.02177,10,,,,,,,,,,,,,,,,,,,,,,,,,,,,,,,,,,,,,
246.186,0.37853,1.0301,10,,,,,,,,,,,,,,,,,,,,,,,,,,,,,,,,,,,,,
246.786,0.3787,1.03964,10,,,,,,,,,,,,,,,,,,,,,,,,,,,,,,,,,,,,,
247.386,0.37893,1.05445,10,,,,,,,,,,,,,,,,,,,,,,,,,,,,,,,,,,,,,
247.986,0.37899,1.02492,10,,,,,,,,,,,,,,,,,,,,,,,,,,,,,,,,,,,,,
248.586,0.37904,1.04871,10,,,,,,,,,,,,,,,,,,,,,,,,,,,,,,,,,,,,,
249.186,0.37893,1.08554,10,,,,,,,,,,,,,,,,,,,,,,,,,,,,,,,,,,,,,
249.786,0.37887,1.06979,10,,,,,,,,,,,,,,,,,,,,,,,,,,,,,,,,,,,,,
250.386,0.37887,1.06945,10,,,,,,,,,,,,,,,,,,,,,,,,,,,,,,,,,,,,,
250.986,0.37876,1.12277,10,,,,,,,,,,,,,,,,,,,,,,,,,,,,,,,,,,,,,
251.586,0.3787,1.07707,10,,,,,,,,,,,,,,,,,,,,,,,,,,,,,,,,,,,,,
252.186,0.37865,1.05481,10,,,,,,,,,,,,,,,,,,,,,,,,,,,,,,,,,,,,,
252.786,0.37865,1.05662,10,,,,,,,,,,,,,,,,,,,,,,,,,,,,,,,,,,,,,
253.386,0.37853,1.15985,10,,,,,,,,,,,,,,,,,,,,,,,,,,,,,,,,,,,,,
253.986,0.37836,1.08771,10,,,,,,,,,,,,,,,,,,,,,,,,,,,,,,,,,,,,,
254.586,0.37808,1.06505,10,,,,,,,,,,,,,,,,,,,,,,,,,,,,,,,,,,,,,
255.186,0.37774,1.11129,10,,,,,,,,,,,,,,,,,,,,,,,,,,,,,,,,,,,,,
255.786,0.37734,1.10703,10,,,,,,,,,,,,,,,,,,,,,,,,,,,,,,,,,,,,,
256.386,0.37655,1.10915,10,,,,,,,,,,,,,,,,,,,,,,,,,,,,,,,,,,,,,
256.986,0.37598,1.10835,10,,,,,,,,,,,,,,,,,,,,,,,,,,,,,,,,,,,,,
257.586,0.37513,1.0158,10,,,,,,,,,,,,,,,,,,,,,,,,,,,,,,,,,,,,,
258.186,0.37485,1.03752,10,,,,,,,,,,,,,,,,,,,,,,,,,,,,,,,,,,,,,
258.786,0.37468,1.02647,10,,,,,,,,,,,,,,,,,,,,,,,,,,,,,,,,,,,,,
259.386,0.37457,1.10535,10,,,,,,,,,,,,,,,,,,,,,,,,,,,,,,,,,,,,,
259.986,0.37457,1.04104,10,,,,,,,,,,,,,,,,,,,,,,,,,,,,,,,,,,,,,
260.586,0.37457,1.04417,10,,,,,,,,,,,,,,,,,,,,,,,,,,,,,,,,,,,,,
261.186,0.37462,1.07944,10,,,,,,,,,,,,,,,,,,,,,,,,,,,,,,,,,,,,,
261.786,0.37468,0.98462,10,,,,,,,,,,,,,,,,,,,,,,,,,,,,,,,,,,,,,
262.386,0.37468,1.122,10,,,,,,,,,,,,,,,,,,,,,,,,,,,,,,,,,,,,,
262.986,0.37474,0.97989,10,,,,,,,,,,,,,,,,,,,,,,,,,,,,,,,,,,,,,
263.586,0.37479,0.99432,10,,,,,,,,,,,,,,,,,,,,,,,,,,,,,,,,,,,,,
264.186,0.37491,0.94711,10,,,,,,,,,,,,,,,,,,,,,,,,,,,,,,,,,,,,,
264.786,0.37496,1.02189,10,,,,,,,,,,,,,,,,,,,,,,,,,,,,,,,,,,,,,
265.386,0.37508,0.9961,10,,,,,,,,,,,,,,,,,,,,,,,,,,,,,,,,,,,,,
265.986,0.37525,1.00107,10,,,,,,,,,,,,,,,,,,,,,,,,,,,,,,,,,,,,,
266.586,0.37553,0.97605,10,,,,,,,,,,,,,,,,,,,,,,,,,,,,,,,,,,,,,
267.186,0.37587,0.97838,10,,,,,,,,,,,,,,,,,,,,,,,,,,,,,,,,,,,,,
267.786,0.37627,0.95184,10,,,,,,,,,,,,,,,,,,,,,,,,,,,,,,,,,,,,,
268.386,0.377,0.99947,10,,,,,,,,,,,,,,,,,,,,,,,,,,,,,,,,,,,,,
268.986,0.37768,1.0104,10,,,,,,,,,,,,,,,,,,,,,,,,,,,,,,,,,,,,,
269.586,0.37842,1.03557,10,,,,,,,,,,,,,,,,,,,,,,,,,,,,,,,,,,,,,
270.186,0.37893,1.04921,10,,,,,,,,,,,,,,,,,,,,,,,,,,,,,,,,,,,,,
270.786,0.37921,1.10546,10,,,,,,,,,,,,,,,,,,,,,,,,,,,,,,,,,,,,,
271.386,0.3791,1.09681,10,,,,,,,,,,,,,,,,,,,,,,,,,,,,,,,,,,,,,
271.986,0.3791,1.08872,10,,,,,,,,,,,,,,,,,,,,,,,,,,,,,,,,,,,,,
272.586,0.37904,1.11993,10,,,,,,,,,,,,,,,,,,,,,,,,,,,,,,,,,,,,,
273.186,0.37899,1.08715,10,,,,,,,,,,,,,,,,,,,,,,,,,,,,,,,,,,,,,
273.786,0.37893,1.09115,10,,,,,,,,,,,,,,,,,,,,,,,,,,,,,,,,,,,,,
274.386,0.37887,1.0562,10,,,,,,,,,,,,,,,,,,,,,,,,,,,,,,,,,,,,,
274.986,0.37882,1.04946,10,,,,,,,,,,,,,,,,,,,,,,,,,,,,,,,,,,,,,
275.586,0.37876,1.0733,10,,,,,,,,,,,,,,,,,,,,,,,,,,,,,,,,,,,,,
276.186,0.37876,1.06701,10,,,,,,,,,,,,,,,,,,,,,,,,,,,,,,,,,,,,,
276.786,0.37859,1.11031,10,,,,,,,,,,,,,,,,,,,,,,,,,,,,,,,,,,,,,
277.386,0.37836,1.1317,10,,,,,,,,,,,,,,,,,,,,,,,,,,,,,,,,,,,,,
277.986,0.37808,1.07722,10,,,,,,,,,,,,,,,,,,,,,,,,,,,,,,,,,,,,,
278.586,0.37757,1.06607,10,,,,,,,,,,,,,,,,,,,,,,,,,,,,,,,,,,,,,
279.186,0.37706,1.07018,10,,,,,,,,,,,,,,,,,,,,,,,,,,,,,,,,,,,,,
279.786,0.37615,1.06524,10,,,,,,,,,,,,,,,,,,,,,,,,,,,,,,,,,,,,,
280.386,0.37564,1.03189,10,,,,,,,,,,,,,,,,,,,,,,,,,,,,,,,,,,,,,
280.986,0.37536,1.05508,10,,,,,,,,,,,,,,,,,,,,,,,,,,,,,,,,,,,,,
281.586,0.37513,1.00419,10,,,,,,,,,,,,,,,,,,,,,,,,,,,,,,,,,,,,,
282.186,0.37502,1.02577,10,,,,,,,,,,,,,,,,,,,,,,,,,,,,,,,,,,,,,
282.786,0.37502,1.06723,10,,,,,,,,,,,,,,,,,,,,,,,,,,,,,,,,,,,,,
283.386,0.37513,0.96121,10,,,,,,,,,,,,,,,,,,,,,,,,,,,,,,,,,,,,,
283.986,0.37513,1.04861,10,,,,,,,,,,,,,,,,,,,,,,,,,,,,,,,,,,,,,
284.586,0.37519,1.00971,10,,,,,,,,,,,,,,,,,,,,,,,,,,,,,,,,,,,,,
285.186,0.37525,0.99098,10,,,,,,,,,,,,,,,,,,,,,,,,,,,,,,,,,,,,,
285.786,0.3753,1.00759,10,,,,,,,,,,,,,,,,,,,,,,,,,,,,,,,,,,,,,
286.386,0.37536,1.02577,10,,,,,,,,,,,,,,,,,,,,,,,,,,,,,,,,,,,,,
286.986,0.37542,0.98968,10,,,,,,,,,,,,,,,,,,,,,,,,,,,,,,,,,,,,,
287.586,0.37553,0.99942,10,,,,,,,,,,,,,,,,,,,,,,,,,,,,,,,,,,,,,
288.186,0.3757,0.97613,10,,,,,,,,,,,,,,,,,,,,,,,,,,,,,,,,,,,,,
288.786,0.37593,1.01549,10,,,,,,,,,,,,,,,,,,,,,,,,,,,,,,,,,,,,,
289.386,0.37621,1.00973,10,,,,,,,,,,,,,,,,,,,,,,,,,,,,,,,,,,,,,
289.986,0.37644,0.99638,10,,,,,,,,,,,,,,,,,,,,,,,,,,,,,,,,,,,,,
290.586,0.37683,0.99497,10,,,,,,,,,,,,,,,,,,,,,,,,,,,,,,,,,,,,,
291.186,0.3774,1.00468,10,,,,,,,,,,,,,,,,,,,,,,,,,,,,,,,,,,,,,
291.786,0.37819,1.03763,10,,,,,,,,,,,,,,,,,,,,,,,,,,,,,,,,,,,,,
292.386,0.37887,1.01891,10,,,,,,,,,,,,,,,,,,,,,,,,,,,,,,,,,,,,,
292.986,0.37916,1.07331,10,,,,,,,,,,,,,,,,,,,,,,,,,,,,,,,,,,,,,
293.586,0.37927,1.10493,10,,,,,,,,,,,,,,,,,,,,,,,,,,,,,,,,,,,,,
294.186,0.37916,1.06992,10,,,,,,,,,,,,,,,,,,,,,,,,,,,,,,,,,,,,,
294.786,0.3791,1.12932,10,,,,,,,,,,,,,,,,,,,,,,,,,,,,,,,,,,,,,
295.386,0.37904,1.09205,10,,,,,,,,,,,,,,,,,,,,,,,,,,,,,,,,,,,,,
295.986,0.37899,1.02391,10,,,,,,,,,,,,,,,,,,,,,,,,,,,,,,,,,,,,,
296.586,0.37899,1.06132,10,,,,,,,,,,,,,,,,,,,,,,,,,,,,,,,,,,,,,
297.186,0.37899,1.05057,10,,,,,,,,,,,,,,,,,,,,,,,,,,,,,,,,,,,,,
297.786,0.37893,1.05448,10,,,,,,,,,,,,,,,,,,,,,,,,,,,,,,,,,,,,,
298.386,0.37893,1.05544,10,,,,,,,,,,,,,,,,,,,,,,,,,,,,,,,,,,,,,
298.986,0.37887,1.0814,10,,,,,,,,,,,,,,,,,,,,,,,,,,,,,,,,,,,,,
299.586,0.37882,1.0483,10,,,,,,,,,,,,,,,,,,,,,,,,,,,,,,,,,,,,,
300.186,0.37876,1.07543,10,,,,,,,,,,,,,,,,,,,,,,,,,,,,,,,,,,,,,
300.786,0.37865,1.10125,10,,,,,,,,,,,,,,,,,,,,,,,,,,,,,,,,,,,,,
301.386,0.37848,1.13388,10,,,,,,,,,,,,,,,,,,,,,,,,,,,,,,,,,,,,,
301.986,0.37819,1.08223,10,,,,,,,,,,,,,,,,,,,,,,,,,,,,,,,,,,,,,
302.586,0.37785,1.10653,10,,,,,,,,,,,,,,,,,,,,,,,,,,,,,,,,,,,,,
303.186,0.37751,1.10381,10,,,,,,,,,,,,,,,,,,,,,,,,,,,,,,,,,,,,,
303.786,0.37723,1.04724,10,,,,,,,,,,,,,,,,,,,,,,,,,,,,,,,,,,,,,
304.386,0.37672,1.06102,10,,,,,,,,,,,,,,,,,,,,,,,,,,,,,,,,,,,,,
304.986,0.37627,1.03117,10,,,,,,,,,,,,,,,,,,,,,,,,,,,,,,,,,,,,,
305.586,0.37587,1.03842,10,,,,,,,,,,,,,,,,,,,,,,,,,,,,,,,,,,,,,
306.186,0.37559,1.03558,10,,,,,,,,,,,,,,,,,,,,,,,,,,,,,,,,,,,,,
306.786,0.37536,1.06968,10,,,,,,,,,,,,,,,,,,,,,,,,,,,,,,,,,,,,,
307.386,0.37519,1.01579,10,,,,,,,,,,,,,,,,,,,,,,,,,,,,,,,,,,,,,
307.986,0.37513,1.03509,10,,,,,,,,,,,,,,,,,,,,,,,,,,,,,,,,,,,,,
308.586,0.37525,0.93492,10,,,,,,,,,,,,,,,,,,,,,,,,,,,,,,,,,,,,,
309.186,0.37525,1.05033,10,,,,,,,,,,,,,,,,,,,,,,,,,,,,,,,,,,,,,
309.786,0.3753,1.01774,10,,,,,,,,,,,,,,,,,,,,,,,,,,,,,,,,,,,,,
310.386,0.37536,1.0362,10,,,,,,,,,,,,,,,,,,,,,,,,,,,,,,,,,,,,,
310.986,0.37542,1.05295,10,,,,,,,,,,,,,,,,,,,,,,,,,,,,,,,,,,,,,
311.586,0.37547,1.01691,10,,,,,,,,,,,,,,,,,,,,,,,,,,,,,,,,,,,,,
312.186,0.37553,0.97466,10,,,,,,,,,,,,,,,,,,,,,,,,,,,,,,,,,,,,,
312.786,0.37564,0.96733,10,,,,,,,,,,,,,,,,,,,,,,,,,,,,,,,,,,,,,
313.386,0.37581,0.97539,10,,,,,,,,,,,,,,,,,,,,,,,,,,,,,,,,,,,,,
313.986,0.37604,0.99011,10,,,,,,,,,,,,,,,,,,,,,,,,,,,,,,,,,,,,,
314.586,0.37632,0.97524,10,,,,,,,,,,,,,,,,,,,,,,,,,,,,,,,,,,,,,
315.186,0.37672,1.01323,10,,,,,,,,,,,,,,,,,,,,,,,,,,,,,,,,,,,,,
315.786,0.37729,0.97629,10,,,,,,,,,,,,,,,,,,,,,,,,,,,,,,,,,,,,,
316.386,0.37814,1.00257,10,,,,,,,,,,,,,,,,,,,,,,,,,,,,,,,,,,,,,
316.986,0.3791,1.01612,10,,,,,,,,,,,,,,,,,,,,,,,,,,,,,,,,,,,,,
317.586,0.37967,1.06186,10,,,,,,,,,,,,,,,,,,,,,,,,,,,,,,,,,,,,,
318.186,0.37984,1.11758,10,,,,,,,,,,,,,,,,,,,,,,,,,,,,,,,,,,,,,
318.786,0.37984,1.10022,10,,,,,,,,,,,,,,,,,,,,,,,,,,,,,,,,,,,,,
319.386,0.37972,1.04585,10,,,,,,,,,,,,,,,,,,,,,,,,,,,,,,,,,,,,,
319.986,0.37961,1.0636,10,,,,,,,,,,,,,,,,,,,,,,,,,,,,,,,,,,,,,
320.586,0.37955,1.14023,10,,,,,,,,,,,,,,,,,,,,,,,,,,,,,,,,,,,,,
321.186,0.3795,1.04901,10,,,,,,,,,,,,,,,,,,,,,,,,,,,,,,,,,,,,,
321.786,0.37944,1.06636,10,,,,,,,,,,,,,,,,,,,,,,,,,,,,,,,,,,,,,
322.386,0.37933,1.14517,10,,,,,,,,,,,,,,,,,,,,,,,,,,,,,,,,,,,,,
322.986,0.37921,1.0661,10,,,,,,,,,,,,,,,,,,,,,,,,,,,,,,,,,,,,,
323.586,0.37899,1.06661,10,,,,,,,,,,,,,,,,,,,,,,,,,,,,,,,,,,,,,
324.186,0.37876,1.10087,10,,,,,,,,,,,,,,,,,,,,,,,,,,,,,,,,,,,,,
324.786,0.37831,1.07383,10,,,,,,,,,,,,,,,,,,,,,,,,,,,,,,,,,,,,,
325.386,0.37774,1.05676,10,,,,,,,,,,,,,,,,,,,,,,,,,,,,,,,,,,,,,
325.986,0.37706,1.03471,10,,,,,,,,,,,,,,,,,,,,,,,,,,,,,,,,,,,,,
326.586,0.37666,1.06566,10,,,,,,,,,,,,,,,,,,,,,,,,,,,,,,,,,,,,,
327.186,0.37627,1.06066,10,,,,,,,,,,,,,,,,,,,,,,,,,,,,,,,,,,,,,
327.786,0.37587,1.04511,10,,,,,,,,,,,,,,,,,,,,,,,,,,,,,,,,,,,,,
328.386,0.3757,1.05661,10,,,,,,,,,,,,,,,,,,,,,,,,,,,,,,,,,,,,,
328.986,0.37576,0.99525,10,,,,,,,,,,,,,,,,,,,,,,,,,,,,,,,,,,,,,
329.586,0.37576,1.03285,10,,,,,,,,,,,,,,,,,,,,,,,,,,,,,,,,,,,,,
330.186,0.37581,0.99355,10,,,,,,,,,,,,,,,,,,,,,,,,,,,,,,,,,,,,,
330.786,0.37576,0.99238,10,,,,,,,,,,,,,,,,,,,,,,,,,,,,,,,,,,,,,
331.386,0.37587,0.99818,10,,,,,,,,,,,,,,,,,,,,,,,,,,,,,,,,,,,,,
331.986,0.37593,1.01441,10,,,,,,,,,,,,,,,,,,,,,,,,,,,,,,,,,,,,,
332.586,0.37598,1.05505,10,,,,,,,,,,,,,,,,,,,,,,,,,,,,,,,,,,,,,
333.186,0.37604,1.01129,10,,,,,,,,,,,,,,,,,,,,,,,,,,,,,,,,,,,,,
333.786,0.3761,1.0395,10,,,,,,,,,,,,,,,,,,,,,,,,,,,,,,,,,,,,,
334.386,0.37621,0.97983,10,,,,,,,,,,,,,,,,,,,,,,,,,,,,,,,,,,,,,
334.986,0.37638,0.97013,10,,,,,,,,,,,,,,,,,,,,,,,,,,,,,,,,,,,,,
335.586,0.37672,1.00412,10,,,,,,,,,,,,,,,,,,,,,,,,,,,,,,,,,,,,,
336.186,0.37712,1.00545,10,,,,,,,,,,,,,,,,,,,,,,,,,,,,,,,,,,,,,
336.786,0.37757,0.97117,10,,,,,,,,,,,,,,,,,,,,,,,,,,,,,,,,,,,,,
337.386,0.37836,1.02125,10,,,,,,,,,,,,,,,,,,,,,,,,,,,,,,,,,,,,,
337.986,0.37904,1.05328,10,,,,,,,,,,,,,,,,,,,,,,,,,,,,,,,,,,,,,
338.586,0.3795,1.0458,10,,,,,,,,,,,,,,,,,,,,,,,,,,,,,,,,,,,,,
339.186,0.37972,1.05756,10,,,,,,,,,,,,,,,,,,,,,,,,,,,,,,,,,,,,,
339.786,0.37978,1.03559,10,,,,,,,,,,,,,,,,,,,,,,,,,,,,,,,,,,,,,
340.386,0.37978,1.09127,10,,,,,,,,,,,,,,,,,,,,,,,,,,,,,,,,,,,,,
340.986,0.37961,1.10704,10,,,,,,,,,,,,,,,,,,,,,,,,,,,,,,,,,,,,,
341.586,0.37955,1.12199,10,,,,,,,,,,,,,,,,,,,,,,,,,,,,,,,,,,,,,
342.186,0.3795,1.1113,10,,,,,,,,,,,,,,,,,,,,,,,,,,,,,,,,,,,,,
342.786,0.37938,1.15319,10,,,,,,,,,,,,,,,,,,,,,,,,,,,,,,,,,,,,,
343.386,0.37933,1.0977,10,,,,,,,,,,,,,,,,,,,,,,,,,,,,,,,,,,,,,
343.986,0.3791,1.17978,10,,,,,,,,,,,,,,,,,,,,,,,,,,,,,,,,,,,,,
344.586,0.37893,1.08076,10,,,,,,,,,,,,,,,,,,,,,,,,,,,,,,,,,,,,,
345.186,0.37859,1.06476,10,,,,,,,,,,,,,,,,,,,,,,,,,,,,,,,,,,,,,
345.786,0.37814,1.07509,10,,,,,,,,,,,,,,,,,,,,,,,,,,,,,,,,,,,,,
346.386,0.37751,1.06629,10,,,,,,,,,,,,,,,,,,,,,,,,,,,,,,,,,,,,,
346.986,0.37712,1.0697,10,,,,,,,,,,,,,,,,,,,,,,,,,,,,,,,,,,,,,
347.586,0.37666,1.10165,10,,,,,,,,,,,,,,,,,,,,,,,,,,,,,,,,,,,,,
348.186,0.37627,1.03442,10,,,,,,,,,,,,,,,,,,,,,,,,,,,,,,,,,,,,,
348.786,0.37598,1.02754,10,,,,,,,,,,,,,,,,,,,,,,,,,,,,,,,,,,,,,
349.386,0.37587,1.04791,10,,,,,,,,,,,,,,,,,,,,,,,,,,,,,,,,,,,,,
349.986,0.3757,1.04004,10,,,,,,,,,,,,,,,,,,,,,,,,,,,,,,,,,,,,,
350.586,0.37581,1.03137,10,,,,,,,,,,,,,,,,,,,,,,,,,,,,,,,,,,,,,
351.186,0.37587,0.99984,10,,,,,,,,,,,,,,,,,,,,,,,,,,,,,,,,,,,,,
351.786,0.37587,0.99905,10,,,,,,,,,,,,,,,,,,,,,,,,,,,,,,,,,,,,,
352.386,0.37593,1.01589,10,,,,,,,,,,,,,,,,,,,,,,,,,,,,,,,,,,,,,
352.986,0.37598,1.04339,10,,,,,,,,,,,,,,,,,,,,,,,,,,,,,,,,,,,,,
353.586,0.37604,1.11157,10,,,,,,,,,,,,,,,,,,,,,,,,,,,,,,,,,,,,,
354.186,0.3761,1.02777,10,,,,,,,,,,,,,,,,,,,,,,,,,,,,,,,,,,,,,
354.786,0.37621,0.96125,10,,,,,,,,,,,,,,,,,,,,,,,,,,,,,,,,,,,,,
355.386,0.37644,0.98751,10,,,,,,,,,,,,,,,,,,,,,,,,,,,,,,,,,,,,,
355.986,0.37666,1.00883,10,,,,,,,,,,,,,,,,,,,,,,,,,,,,,,,,,,,,,
356.586,0.37706,1.00715,10,,,,,,,,,,,,,,,,,,,,,,,,,,,,,,,,,,,,,
357.186,0.37757,1.0305,10,,,,,,,,,,,,,,,,,,,,,,,,,,,,,,,,,,,,,
357.786,0.37836,0.98133,10,,,,,,,,,,,,,,,,,,,,,,,,,,,,,,,,,,,,,
358.386,0.37927,1.03902,10,,,,,,,,,,,,,,,,,,,,,,,,,,,,,,,,,,,,,
358.986,0.37978,1.05051,10,,,,,,,,,,,,,,,,,,,,,,,,,,,,,,,,,,,,,
359.586,0.38018,1.18316,10,,,,,,,,,,,,,,,,,,,,,,,,,,,,,,,,,,,,,
360.186,0.38035,1.07113,10,,,,,,,,,,,,,,,,,,,,,,,,,,,,,,,,,,,,,
360.786,0.38023,1.12611,10,,,,,,,,,,,,,,,,,,,,,,,,,,,,,,,,,,,,,
361.386,0.38023,1.0268,10,,,,,,,,,,,,,,,,,,,,,,,,,,,,,,,,,,,,,
361.986,0.38018,1.09647,10,,,,,,,,,,,,,,,,,,,,,,,,,,,,,,,,,,,,,
362.586,0.38006,1.11486,10,,,,,,,,,,,,,,,,,,,,,,,,,,,,,,,,,,,,,
363.186,0.38001,1.10342,10,,,,,,,,,,,,,,,,,,,,,,,,,,,,,,,,,,,,,
363.786,0.38006,1.0927,10,,,,,,,,,,,,,,,,,,,,,,,,,,,,,,,,,,,,,
364.386,0.37989,1.12623,10,,,,,,,,,,,,,,,,,,,,,,,,,,,,,,,,,,,,,
364.986,0.37989,1.03377,10,,,,,,,,,,,,,,,,,,,,,,,,,,,,,,,,,,,,,
365.586,0.37984,1.08183,10,,,,,,,,,,,,,,,,,,,,,,,,,,,,,,,,,,,,,
366.186,0.37972,1.05053,10,,,,,,,,,,,,,,,,,,,,,,,,,,,,,,,,,,,,,
366.786,0.37961,1.06874,10,,,,,,,,,,,,,,,,,,,,,,,,,,,,,,,,,,,,,
367.386,0.37955,1.08333,10,,,,,,,,,,,,,,,,,,,,,,,,,,,,,,,,,,,,,
367.986,0.37933,1.14772,10,,,,,,,,,,,,,,,,,,,,,,,,,,,,,,,,,,,,,
368.586,0.3791,1.05692,10,,,,,,,,,,,,,,,,,,,,,,,,,,,,,,,,,,,,,
369.186,0.37882,1.06233,10,,,,,,,,,,,,,,,,,,,,,,,,,,,,,,,,,,,,,
369.786,0.37848,1.00959,10,,,,,,,,,,,,,,,,,,,,,,,,,,,,,,,,,,,,,
370.386,0.37819,1.07148,10,,,,,,,,,,,,,,,,,,,,,,,,,,,,,,,,,,,,,
370.986,0.37791,1.07015,10,,,,,,,,,,,,,,,,,,,,,,,,,,,,,,,,,,,,,
371.586,0.37763,1.06431,10,,,,,,,,,,,,,,,,,,,,,,,,,,,,,,,,,,,,,
372.186,0.3774,1.04945,10,,,,,,,,,,,,,,,,,,,,,,,,,,,,,,,,,,,,,
372.786,0.37734,1.02912,10,,,,,,,,,,,,,,,,,,,,,,,,,,,,,,,,,,,,,
373.386,0.37729,1.07761,10,,,,,,,,,,,,,,,,,,,,,,,,,,,,,,,,,,,,,
373.986,0.37734,1.0172,10,,,,,,,,,,,,,,,,,,,,,,,,,,,,,,,,,,,,,
374.586,0.37734,1.05766,10,,,,,,,,,,,,,,,,,,,,,,,,,,,,,,,,,,,,,
375.186,0.37734,1.05674,10,,,,,,,,,,,,,,,,,,,,,,,,,,,,,,,,,,,,,
375.786,0.3774,1.02288,10,,,,,,,,,,,,,,,,,,,,,,,,,,,,,,,,,,,,,
376.386,0.37746,1.02899,10,,,,,,,,,,,,,,,,,,,,,,,,,,,,,,,,,,,,,
376.986,0.37751,0.9936,10,,,,,,,,,,,,,,,,,,,,,,,,,,,,,,,,,,,,,
377.586,0.37757,0.97221,10,,,,,,,,,,,,,,,,,,,,,,,,,,,,,,,,,,,,,
378.186,0.37763,0.96422,10,,,,,,,,,,,,,,,,,,,,,,,,,,,,,,,,,,,,,
378.786,0.37774,1.00041,10,,,,,,,,,,,,,,,,,,,,,,,,,,,,,,,,,,,,,
379.386,0.37797,0.97206,10,,,,,,,,,,,,,,,,,,,,,,,,,,,,,,,,,,,,,
379.986,0.37808,0.98886,10,,,,,,,,,,,,,,,,,,,,,,,,,,,,,,,,,,,,,
380.586,0.37848,0.98413,10,,,,,,,,,,,,,,,,,,,,,,,,,,,,,,,,,,,,,
381.186,0.37899,0.99865,10,,,,,,,,,,,,,,,,,,,,,,,,,,,,,,,,,,,,,
381.786,0.37955,1.01359,10,,,,,,,,,,,,,,,,,,,,,,,,,,,,,,,,,,,,,
382.386,0.38006,1.01814,10,,,,,,,,,,,,,,,,,,,,,,,,,,,,,,,,,,,,,
382.986,0.38046,1.0389,10,,,,,,,,,,,,,,,,,,,,,,,,,,,,,,,,,,,,,
383.586,0.38086,1.04775,10,,,,,,,,,,,,,,,,,,,,,,,,,,,,,,,,,,,,,
384.186,0.38108,1.09549,10,,,,,,,,,,,,,,,,,,,,,,,,,,,,,,,,,,,,,
384.786,0.38114,1.07849,10,,,,,,,,,,,,,,,,,,,,,,,,,,,,,,,,,,,,,
385.386,0.3812,1.06648,10,,,,,,,,,,,,,,,,,,,,,,,,,,,,,,,,,,,,,
385.986,0.38108,1.09163,10,,,,,,,,,,,,,,,,,,,,,,,,,,,,,,,,,,,,,
386.586,0.38108,1.05706,10,,,,,,,,,,,,,,,,,,,,,,,,,,,,,,,,,,,,,
387.186,0.38103,1.07308,10,,,,,,,,,,,,,,,,,,,,,,,,,,,,,,,,,,,,,
387.786,0.38097,1.05188,10,,,,,,,,,,,,,,,,,,,,,,,,,,,,,,,,,,,,,
388.386,0.38091,1.05839,10,,,,,,,,,,,,,,,,,,,,,,,,,,,,,,,,,,,,,
388.986,0.38086,1.09599,10,,,,,,,,,,,,,,,,,,,,,,,,,,,,,,,,,,,,,
389.586,0.38074,1.04522,10,,,,,,,,,,,,,,,,,,,,,,,,,,,,,,,,,,,,,
390.186,0.38063,1.0703,10,,,,,,,,,,,,,,,,,,,,,,,,,,,,,,,,,,,,,
390.786,0.38046,1.07714,10,,,,,,,,,,,,,,,,,,,,,,,,,,,,,,,,,,,,,
391.386,0.38035,1.05412,10,,,,,,,,,,,,,,,,,,,,,,,,,,,,,,,,,,,,,
391.986,0.38001,1.12015,10,,,,,,,,,,,,,,,,,,,,,,,,,,,,,,,,,,,,,
392.586,0.37978,1.07152,10,,,,,,,,,,,,,,,,,,,,,,,,,,,,,,,,,,,,,
393.186,0.37933,1.08597,10,,,,,,,,,,,,,,,,,,,,,,,,,,,,,,,,,,,,,
393.786,0.3787,1.07954,10,,,,,,,,,,,,,,,,,,,,,,,,,,,,,,,,,,,,,
394.386,0.37831,1.02575,10,,,,,,,,,,,,,,,,,,,,,,,,,,,,,,,,,,,,,
394.986,0.37814,1.08863,10,,,,,,,,,,,,,,,,,,,,,,,,,,,,,,,,,,,,,
395.586,0.37802,1.05603,10,,,,,,,,,,,,,,,,,,,,,,,,,,,,,,,,,,,,,
396.186,0.37791,1.00839,10,,,,,,,,,,,,,,,,,,,,,,,,,,,,,,,,,,,,,
396.786,0.37785,1.01486,10,,,,,,,,,,,,,,,,,,,,,,,,,,,,,,,,,,,,,
397.386,0.3778,1.01938,10,,,,,,,,,,,,,,,,,,,,,,,,,,,,,,,,,,,,,
397.986,0.37791,1.03253,10,,,,,,,,,,,,,,,,,,,,,,,,,,,,,,,,,,,,,
398.586,0.37797,1.00017,10,,,,,,,,,,,,,,,,,,,,,,,,,,,,,,,,,,,,,
399.186,0.37802,0.99601,10,,,,,,,,,,,,,,,,,,,,,,,,,,,,,,,,,,,,,
399.786,0.37808,0.97084,10,,,,,,,,,,,,,,,,,,,,,,,,,,,,,,,,,,,,,
400.386,0.37808,0.96795,10,,,,,,,,,,,,,,,,,,,,,,,,,,,,,,,,,,,,,
400.986,0.37819,0.97414,10,,,,,,,,,,,,,,,,,,,,,,,,,,,,,,,,,,,,,
401.586,0.37831,0.98225,10,,,,,,,,,,,,,,,,,,,,,,,,,,,,,,,,,,,,,
402.186,0.37848,1.01612,10,,,,,,,,,,,,,,,,,,,,,,,,,,,,,,,,,,,,,
402.786,0.37865,1.00632,10,,,,,,,,,,,,,,,,,,,,,,,,,,,,,,,,,,,,,
403.386,0.37887,0.94939,10,,,,,,,,,,,,,,,,,,,,,,,,,,,,,,,,,,,,,
403.986,0.37927,1.06934,10,,,,,,,,,,,,,,,,,,,,,,,,,,,,,,,,,,,,,
404.586,0.37967,0.98685,10,,,,,,,,,,,,,,,,,,,,,,,,,,,,,,,,,,,,,
405.186,0.38001,1.02811,10,,,,,,,,,,,,,,,,,,,,,,,,,,,,,,,,,,,,,
405.786,0.3804,1.06119,10,,,,,,,,,,,,,,,,,,,,,,,,,,,,,,,,,,,,,
406.386,0.38069,1.02563,10,,,,,,,,,,,,,,,,,,,,,,,,,,,,,,,,,,,,,
406.986,0.38086,1.0611,10,,,,,,,,,,,,,,,,,,,,,,,,,,,,,,,,,,,,,
407.586,0.38097,1.05296,10,,,,,,,,,,,,,,,,,,,,,,,,,,,,,,,,,,,,,
408.186,0.38108,1.07556,10,,,,,,,,,,,,,,,,,,,,,,,,,,,,,,,,,,,,,
408.786,0.38108,1.04223,10,,,,,,,,,,,,,,,,,,,,,,,,,,,,,,,,,,,,,
409.386,0.38097,1.08,10,,,,,,,,,,,,,,,,,,,,,,,,,,,,,,,,,,,,,
409.986,0.38097,1.11552,10,,,,,,,,,,,,,,,,,,,,,,,,,,,,,,,,,,,,,
410.586,0.3808,1.06219,10,,,,,,,,,,,,,,,,,,,,,,,,,,,,,,,,,,,,,
411.186,0.38074,1.03931,10,,,,,,,,,,,,,,,,,,,,,,,,,,,,,,,,,,,,,
411.786,0.38069,1.08235,10,,,,,,,,,,,,,,,,,,,,,,,,,,,,,,,,,,,,,
412.386,0.38063,1.03712,10,,,,,,,,,,,,,,,,,,,,,,,,,,,,,,,,,,,,,
412.986,0.38063,1.05909,10,,,,,,,,,,,,,,,,,,,,,,,,,,,,,,,,,,,,,
413.586,0.38052,1.06426,10,,,,,,,,,,,,,,,,,,,,,,,,,,,,,,,,,,,,,
414.186,0.38046,1.09413,10,,,,,,,,,,,,,,,,,,,,,,,,,,,,,,,,,,,,,
414.786,0.38035,1.04991,10,,,,,,,,,,,,,,,,,,,,,,,,,,,,,,,,,,,,,
415.386,0.38023,1.09477,10,,,,,,,,,,,,,,,,,,,,,,,,,,,,,,,,,,,,,
415.986,0.38001,1.07407,10,,,,,,,,,,,,,,,,,,,,,,,,,,,,,,,,,,,,,
416.586,0.37972,1.04721,10,,,,,,,,,,,,,,,,,,,,,,,,,,,,,,,,,,,,,
417.186,0.37955,1.08829,10,,,,,,,,,,,,,,,,,,,,,,,,,,,,,,,,,,,,,
417.786,0.37927,1.04842,10,,,,,,,,,,,,,,,,,,,,,,,,,,,,,,,,,,,,,
418.386,0.37899,1.07211,10,,,,,,,,,,,,,,,,,,,,,,,,,,,,,,,,,,,,,
418.986,0.37876,1.04562,10,,,,,,,,,,,,,,,,,,,,,,,,,,,,,,,,,,,,,
419.586,0.37865,1.08922,10,,,,,,,,,,,,,,,,,,,,,,,,,,,,,,,,,,,,,
420.186,0.37853,1.02327,10,,,,,,,,,,,,,,,,,,,,,,,,,,,,,,,,,,,,,
420.786,0.37848,1.03647,10,,,,,,,,,,,,,,,,,,,,,,,,,,,,,,,,,,,,,
421.386,0.37842,0.99206,10,,,,,,,,,,,,,,,,,,,,,,,,,,,,,,,,,,,,,
421.986,0.37853,1.01546,10,,,,,,,,,,,,,,,,,,,,,,,,,,,,,,,,,,,,,
422.586,0.37853,1.01066,10,,,,,,,,,,,,,,,,,,,,,,,,,,,,,,,,,,,,,
423.186,0.37853,1.04753,10,,,,,,,,,,,,,,,,,,,,,,,,,,,,,,,,,,,,,
423.786,0.37859,1.03103,10,,,,,,,,,,,,,,,,,,,,,,,,,,,,,,,,,,,,,
424.386,0.37865,1.01634,10,,,,,,,,,,,,,,,,,,,,,,,,,,,,,,,,,,,,,
424.986,0.3787,0.96472,10,,,,,,,,,,,,,,,,,,,,,,,,,,,,,,,,,,,,,
425.586,0.37876,0.95307,10,,,,,,,,,,,,,,,,,,,,,,,,,,,,,,,,,,,,,
426.186,0.37882,0.96779,10,,,,,,,,,,,,,,,,,,,,,,,,,,,,,,,,,,,,,
426.786,0.37887,0.97737,10,,,,,,,,,,,,,,,,,,,,,,,,,,,,,,,,,,,,,
427.386,0.37899,0.99638,10,,,,,,,,,,,,,,,,,,,,,,,,,,,,,,,,,,,,,
427.986,0.37916,1.01526,10,,,,,,,,,,,,,,,,,,,,,,,,,,,,,,,,,,,,,
428.586,0.37927,1.03195,10,,,,,,,,,,,,,,,,,,,,,,,,,,,,,,,,,,,,,
429.186,0.37927,1.07945,10,,,,,,,,,,,,,,,,,,,,,,,,,,,,,,,,,,,,,
429.786,0.37927,1.01232,10,,,,,,,,,,,,,,,,,,,,,,,,,,,,,,,,,,,,,
430.386,0.37933,1.09939,10,,,,,,,,,,,,,,,,,,,,,,,,,,,,,,,,,,,,,
430.986,0.37933,1.05652,10,,,,,,,,,,,,,,,,,,,,,,,,,,,,,,,,,,,,,
431.586,0.37933,1.01991,10,,,,,,,,,,,,,,,,,,,,,,,,,,,,,,,,,,,,,
432.186,0.37938,1.05512,10,,,,,,,,,,,,,,,,,,,,,,,,,,,,,,,,,,,,,
432.786,0.37938,1.0184,10,,,,,,,,,,,,,,,,,,,,,,,,,,,,,,,,,,,,,
433.386,0.37944,1.06782,10,,,,,,,,,,,,,,,,,,,,,,,,,,,,,,,,,,,,,
433.986,0.37944,1.01842,10,,,,,,,,,,,,,,,,,,,,,,,,,,,,,,,,,,,,,
434.586,0.3795,1.02543,10,,,,,,,,,,,,,,,,,,,,,,,,,,,,,,,,,,,,,
435.186,0.37955,1.01896,10,,,,,,,,,,,,,,,,,,,,,,,,,,,,,,,,,,,,,
435.786,0.37967,1.06878,10,,,,,,,,,,,,,,,,,,,,,,,,,,,,,,,,,,,,,
436.386,0.37978,1.02852,10,,,,,,,,,,,,,,,,,,,,,,,,,,,,,,,,,,,,,
436.986,0.37989,1.02845,10,,,,,,,,,,,,,,,,,,,,,,,,,,,,,,,,,,,,,
437.586,0.38023,1.00342,10,,,,,,,,,,,,,,,,,,,,,,,,,,,,,,,,,,,,,
438.186,0.38069,1.02895,10,,,,,,,,,,,,,,,,,,,,,,,,,,,,,,,,,,,,,
438.786,0.3812,1.01579,10,,,,,,,,,,,,,,,,,,,,,,,,,,,,,,,,,,,,,
439.386,0.38159,0.99781,10,,,,,,,,,,,,,,,,,,,,,,,,,,,,,,,,,,,,,
439.888,0.7765,4.97804,10,,,,,,,,,,,,,,,,,,,,,,,,,,,,,,,,,,,,,
440.488,5.88183,388.09738,10,,,,,,,,,,,,,,,,,,,,,,,,,,,,,,,,,,,,,
441.088,10.88198,53.00174,10,,,,,,,,,,,,,,,,,,,,,,,,,,,,,,,,,,,,,
441.688,15.88185,27.00052,10,,,,,,,,,,,,,,,,,,,,,,,,,,,,,,,,,,,,,
442.288,20.88184,8.38571,10,,,,,,,,,,,,,,,,,,,,,,,,,,,,,,,,,,,,,
442.888,25.88187,-1.28156,10,,,,,,,,,,,,,,,,,,,,,,,,,,,,,,,,,,,,,
443.488,30.88174,-3.6464,10,,,,,,,,,,,,,,,,,,,,,,,,,,,,,,,,,,,,,
444.088,35.88178,-7.63266,10,,,,,,,,,,,,,,,,,,,,,,,,,,,,,,,,,,,,,
444.688,40.88182,-7.8831,10,,,,,,,,,,,,,,,,,,,,,,,,,,,,,,,,,,,,,
445.288,45.88181,-7.88477,10,,,,,,,,,,,,,,,,,,,,,,,,,,,,,,,,,,,,,
445.888,50.88184,-7.85716,10,,,,,,,,,,,,,,,,,,,,,,,,,,,,,,,,,,,,,
445.992,51.74857,-7.90924,10,,,,,,,,,,,,,,,,,,,,,,,,,,,,,,,,,,,,,