File: combined_ligament_solver/data/processed/Data Sheet 3_S152678_LCL.csv
Specimen properties : Length,60,mm,Unnamed: 3,Unnamed: 4,Unnamed: 5,Unnamed: 6,Unnamed: 7,Unnamed: 8,Unnamed: 9,Unnamed: 10,Unnamed: 11,Stress-Strain,Unnamed: 13,Unnamed: 14,Unnamed: 15,Unnamed: 16,Unnamed: 17,Unnamed: 18,Unnamed: 19,Unnamed: 20,Unnamed: 21,Unnamed: 22,Unnamed: 23,Unnamed: 24,Unnamed: 25,Unnamed: 26,Unnamed: 27,Linear,Unnamed: 29,Unnamed: 30,Unnamed: 31,Unnamed: 32,Unnamed: 33,Modulus,Unnamed: 35,Failure,Unnamed: 37,Unnamed: 38,Unnamed: 39,Unnamed: 40
Cross Section Average,66.071,mm2,,,,,,,,,,Polynomial Coefficients,,,,,,,,,,,,,,,,Force,,Stress,Extension,Strain,,Secant,Tangent,Load,Stress,Extension,Strain,Stiffness
Time,Extension,Load,Total cycle count,,,Extension,Load,Strain,Stress,E-tan,,X6,-2683130.4194159415,,,,,,,,,Strain,Stress,E-tan,,,,(N),,(MPa),(mm),(%),,(MPa),(MPa),(N),(MPa),(mm),(%),(N/mm)
(s),(mm),(N),,,,(mm),(N),(mm/mm),(MPa),(MPa),,X5,1496471.9062352981,,,,,,,,,(mm/mm),(MPa),(MPa),,,,299.4916976694874,,4.532876718522308,9.24,15.4,,29.434264405989012,46.50369543080575,371.20886,5.60089207065127,10.5987,17.6645,32.412521392801665
0.9,0.99535,1.46591,0,,,9.03981,208.94885,0.12108816666666665,3.1450489624797564,46.084719569712185,,,,,,,,,,,,0.009,0.0744287979907286,3.801006095854628,,,,,,,,,,,,,,,,
1.9,1.16212,1.95644,0,,,17.37326,202.45399,,,,,,,,,,,,,,,0.019,0.0927165933762806,1.6234900409807502,,,,,,,,,,,,,,,,
2.9,1.32878,2.59325,0,,,25.70649,19.36771,,,,,,,,,,,,,,,0.029,0.13149871763662135,6.442197464862292,,,,,,,,,,,,,,,,
3.9,1.49549,3.14376,0,,,,,,,,,,,,,,,,,,,0.039,0.2381225888744425,14.346610608783381,,,,,,,,,,,,,,,,
4.9,1.66209,3.76469,0,,,,,,,,,,,,,,,,,,,0.049,0.4278383591419943,22.67139963944773,,,,,,,,,,,,,,,,
5.9,1.82869,4.40151,0,,,,,,,,,,,,,,,,,,,0.059,0.6951882740491779,29.80323725877572,,,,,,,,,,,,,,,,
6.9,1.99529,5.13858,0,,,,,,,,,,,,,,,,,,,0.069,1.0234641784696639,34.987613313716544,,,,,,,,,,,,,,,,
7.9,2.16189,5.84443,0,,,,,,,,,,,,,,,,,,,0.079,1.3922331683450162,38.13564940603694,,,,,,,,,,,,,,,,
8.9,2.3286,6.80009,0,,,,,,,,,,,,,,,,,,,0.089,1.7829313885868618,39.63091350213684,,,,,,,,,,,,,,,,
9.9,2.49532,7.83867,0,,,,,,,,,,,,,,,,,,,0.099,2.1825259770770495,40.13623454283085,,,,,,,,,,,,,,,,
10.9,2.66203,8.9382,0,,,,,,,,,,,,,,,,,,,0.109,2.5852451547658664,40.40051705318866,,,,,,,,,,,,,,,,
11.9,2.82863,9.99779,0,,,,,,,,,,,,,,,,,,,0.119,2.9923764618682194,41.065555752292724,,,,,,,,,,,,,,,,
12.9,2.99534,11.36184,0,,,,,,,,,,,,,,,,,,,0.129,3.4101331401579476,42.47285016304132,,,,,,,,,,,,,,,,
13.9,3.162,12.93613,0,,,,,,,,,,,,,,,,,,,0.139,3.8455886613599417,44.4704192220486,,,,,,,,,,,,,,,,
14.9,3.32866,15.12738,0,,,,,,,,,,,,,,,,,,,0.149,4.300679401640561,46.21961588919716,,,,,,,,,,,,,,,,
15.9,3.49543,17.47307,0,,,,,,,,,,,,,,,,,,,0.159,4.764275462195929,46.0019417579058,,,,,,,,,,,,,,,,
16.9,3.66197,20.00618,0,,,,,,,,,,,,,,,,,,,0.169,5.202319635938116,41.025861664298404,,,,,,,,,,,,,,,,
17.9,3.8288,22.68991,0,,,,,,,,,,,,,,,,,,,0.179,5.546034520279563,27.233618297576506,,,,,,,,,,,,,,,,
18.9,3.9954,25.69914,0,,,,,,,,,,,,,,,,,,,0.189,,,,,,,,,,,,,,,,,,
19.9,4.16211,28.84818,0,,,,,,,,,,,,,,,,,,,0.199,,,,,,,,,,,,,,,,,,
20.9,4.32877,32.3055,0,,,,,,,,,,,,,,,,,,,,,,,,,,,,,,,,,,,,,
21.9,4.49542,35.98666,0,,,,,,,,,,,,,,,,,,,,,,,,,,,,,,,,,,,,,
22.9,4.66202,39.79504,0,,,,,,,,,,,,,,,,,,,,,,,,,,,,,,,,,,,,,
23.772,4.5403,35.21656,0.5,,,,,,,,,,,,,,,,,,,,,,,,,,,,,,,,,,,,,
24.772,4.37365,30.07325,0.5,,,,,,,,,,,,,,,,,,,,,,,,,,,,,,,,,,,,,
25.772,4.20693,25.7131,0.5,,,,,,,,,,,,,,,,,,,,,,,,,,,,,,,,,,,,,
26.772,4.04039,21.8817,0.5,,,,,,,,,,,,,,,,,,,,,,,,,,,,,,,,,,,,,
27.772,3.87373,18.57494,0.5,,,,,,,,,,,,,,,,,,,,,,,,,,,,,,,,,,,,,
28.772,3.70708,15.70475,0.5,,,,,,,,,,,,,,,,,,,,,,,,,,,,,,,,,,,,,
29.772,3.54042,13.25195,0.5,,,,,,,,,,,,,,,,,,,,,,,,,,,,,,,,,,,,,
30.772,3.37376,10.98446,0.5,,,,,,,,,,,,,,,,,,,,,,,,,,,,,,,,,,,,,
31.772,3.20711,9.12998,0.5,,,,,,,,,,,,,,,,,,,,,,,,,,,,,,,,,,,,,
32.772,3.04034,7.72509,0.5,,,,,,,,,,,,,,,,,,,,,,,,,,,,,,,,,,,,,
33.772,2.87379,6.38924,0.5,,,,,,,,,,,,,,,,,,,,,,,,,,,,,,,,,,,,,
34.772,2.70708,5.34403,0.5,,,,,,,,,,,,,,,,,,,,,,,,,,,,,,,,,,,,,
35.772,2.54037,4.45966,0.5,,,,,,,,,,,,,,,,,,,,,,,,,,,,,,,,,,,,,
36.772,2.37371,3.94611,0.5,,,,,,,,,,,,,,,,,,,,,,,,,,,,,,,,,,,,,
37.772,2.207,3.31965,0.5,,,,,,,,,,,,,,,,,,,,,,,,,,,,,,,,,,,,,
38.772,2.04028,2.76188,0.5,,,,,,,,,,,,,,,,,,,,,,,,,,,,,,,,,,,,,
39.772,1.87357,2.13664,0.5,,,,,,,,,,,,,,,,,,,,,,,,,,,,,,,,,,,,,
40.772,1.70686,1.58605,0.5,,,,,,,,,,,,,,,,,,,,,,,,,,,,,,,,,,,,,
41.772,1.5402,1.17714,0.5,,,,,,,,,,,,,,,,,,,,,,,,,,,,,,,,,,,,,
42.562,1.54298,1.23218,1,,,,,,,,,,,,,,,,,,,,,,,,,,,,,,,,,,,,,
43.562,1.70958,1.94372,1,,,,,,,,,,,,,,,,,,,,,,,,,,,,,,,,,,,,,
44.562,1.87629,2.62231,1,,,,,,,,,,,,,,,,,,,,,,,,,,,,,,,,,,,,,
45.562,2.04289,3.37659,1,,,,,,,,,,,,,,,,,,,,,,,,,,,,,,,,,,,,,
46.562,2.20966,4.20334,1,,,,,,,,,,,,,,,,,,,,,,,,,,,,,,,,,,,,,
47.562,2.37626,4.98456,1,,,,,,,,,,,,,,,,,,,,,,,,,,,,,,,,,,,,,
48.562,2.54303,5.82685,1,,,,,,,,,,,,,,,,,,,,,,,,,,,,,,,,,,,,,
49.562,2.70963,6.88022,1,,,,,,,,,,,,,,,,,,,,,,,,,,,,,,,,,,,,,
50.562,2.87629,8.06178,1,,,,,,,,,,,,,,,,,,,,,,,,,,,,,,,,,,,,,
51.562,3.04306,9.4365,1,,,,,,,,,,,,,,,,,,,,,,,,,,,,,,,,,,,,,
52.562,3.20966,10.85225,1,,,,,,,,,,,,,,,,,,,,,,,,,,,,,,,,,,,,,
53.562,3.37643,12.6113,1,,,,,,,,,,,,,,,,,,,,,,,,,,,,,,,,,,,,,
54.562,3.54303,14.87391,1,,,,,,,,,,,,,,,,,,,,,,,,,,,,,,,,,,,,,
55.562,3.7098,17.37991,1,,,,,,,,,,,,,,,,,,,,,,,,,,,,,,,,,,,,,
56.562,3.8764,20.25076,1,,,,,,,,,,,,,,,,,,,,,,,,,,,,,,,,,,,,,
57.562,4.04311,23.4611,1,,,,,,,,,,,,,,,,,,,,,,,,,,,,,,,,,,,,,
58.562,4.20971,26.87644,1,,,,,,,,,,,,,,,,,,,,,,,,,,,,,,,,,,,,,
59.562,4.37631,30.62238,1,,,,,,,,,,,,,,,,,,,,,,,,,,,,,,,,,,,,,
60.562,4.54297,34.6878,1,,,,,,,,,,,,,,,,,,,,,,,,,,,,,,,,,,,,,
61.562,4.70951,38.84186,1,,,,,,,,,,,,,,,,,,,,,,,,,,,,,,,,,,,,,
62.412,4.65092,36.46618,1.5,,,,,,,,,,,,,,,,,,,,,,,,,,,,,,,,,,,,,
63.412,4.48426,31.18519,1.5,,,,,,,,,,,,,,,,,,,,,,,,,,,,,,,,,,,,,
64.412,4.31766,26.74754,1.5,,,,,,,,,,,,,,,,,,,,,,,,,,,,,,,,,,,,,
65.412,4.151,22.83425,1.5,,,,,,,,,,,,,,,,,,,,,,,,,,,,,,,,,,,,,
66.412,3.9844,19.33347,1.5,,,,,,,,,,,,,,,,,,,,,,,,,,,,,,,,,,,,,
67.412,3.81769,16.33723,1.5,,,,,,,,,,,,,,,,,,,,,,,,,,,,,,,,,,,,,
68.412,3.65109,13.7406,1.5,,,,,,,,,,,,,,,,,,,,,,,,,,,,,,,,,,,,,
69.412,3.48438,11.37985,1.5,,,,,,,,,,,,,,,,,,,,,,,,,,,,,,,,,,,,,
70.412,3.31772,9.50761,1.5,,,,,,,,,,,,,,,,,,,,,,,,,,,,,,,,,,,,,
71.412,3.15101,7.99781,1.5,,,,,,,,,,,,,,,,,,,,,,,,,,,,,,,,,,,,,
72.412,2.98441,6.65265,1.5,,,,,,,,,,,,,,,,,,,,,,,,,,,,,,,,,,,,,
73.412,2.81781,5.52329,1.5,,,,,,,,,,,,,,,,,,,,,,,,,,,,,,,,,,,,,
74.412,2.65104,4.62983,1.5,,,,,,,,,,,,,,,,,,,,,,,,,,,,,,,,,,,,,
75.412,2.48438,4.09218,1.5,,,,,,,,,,,,,,,,,,,,,,,,,,,,,,,,,,,,,
76.412,2.31767,3.51272,1.5,,,,,,,,,,,,,,,,,,,,,,,,,,,,,,,,,,,,,
77.412,2.15101,2.86414,1.5,,,,,,,,,,,,,,,,,,,,,,,,,,,,,,,,,,,,,
78.412,1.98424,2.21152,1.5,,,,,,,,,,,,,,,,,,,,,,,,,,,,,,,,,,,,,
79.412,1.81764,1.73384,1.5,,,,,,,,,,,,,,,,,,,,,,,,,,,,,,,,,,,,,
80.412,1.65098,1.23273,1.5,,,,,,,,,,,,,,,,,,,,,,,,,,,,,,,,,,,,,
81.172,1.59143,1.04018,2,,,,,,,,,,,,,,,,,,,,,,,,,,,,,,,,,,,,,
82.172,1.75859,1.69975,2,,,,,,,,,,,,,,,,,,,,,,,,,,,,,,,,,,,,,
83.172,1.92525,2.4177,2,,,,,,,,,,,,,,,,,,,,,,,,,,,,,,,,,,,,,
84.172,2.09196,3.15745,2,,,,,,,,,,,,,,,,,,,,,,,,,,,,,,,,,,,,,
85.172,2.25856,3.90165,2,,,,,,,,,,,,,,,,,,,,,,,,,,,,,,,,,,,,,
86.172,2.42533,4.73928,2,,,,,,,,,,,,,,,,,,,,,,,,,,,,,,,,,,,,,
87.172,2.59193,5.66176,2,,,,,,,,,,,,,,,,,,,,,,,,,,,,,,,,,,,,,
88.172,2.75865,6.65124,2,,,,,,,,,,,,,,,,,,,,,,,,,,,,,,,,,,,,,
89.172,2.92536,7.87001,2,,,,,,,,,,,,,,,,,,,,,,,,,,,,,,,,,,,,,
90.172,3.09202,9.1588,2,,,,,,,,,,,,,,,,,,,,,,,,,,,,,,,,,,,,,
91.172,3.25879,10.51781,2,,,,,,,,,,,,,,,,,,,,,,,,,,,,,,,,,,,,,
92.172,3.42544,12.33427,2,,,,,,,,,,,,,,,,,,,,,,,,,,,,,,,,,,,,,
93.172,3.59216,14.49956,2,,,,,,,,,,,,,,,,,,,,,,,,,,,,,,,,,,,,,
94.172,3.75876,16.99612,2,,,,,,,,,,,,,,,,,,,,,,,,,,,,,,,,,,,,,
95.172,3.92541,19.92392,2,,,,,,,,,,,,,,,,,,,,,,,,,,,,,,,,,,,,,
96.172,4.09196,23.08714,2,,,,,,,,,,,,,,,,,,,,,,,,,,,,,,,,,,,,,
97.172,4.25867,26.58669,2,,,,,,,,,,,,,,,,,,,,,,,,,,,,,,,,,,,,,
98.172,4.42533,30.37134,2,,,,,,,,,,,,,,,,,,,,,,,,,,,,,,,,,,,,,
99.172,4.59187,34.55405,2,,,,,,,,,,,,,,,,,,,,,,,,,,,,,,,,,,,,,
100.172,4.75875,38.89215,2,,,,,,,,,,,,,,,,,,,,,,,,,,,,,,,,,,,,,
101.002,4.69676,36.51856,2.5,,,,,,,,,,,,,,,,,,,,,,,,,,,,,,,,,,,,,
102.002,4.52999,31.30235,2.5,,,,,,,,,,,,,,,,,,,,,,,,,,,,,,,,,,,,,
103.002,4.36328,26.68139,2.5,,,,,,,,,,,,,,,,,,,,,,,,,,,,,,,,,,,,,
104.002,4.19656,22.78297,2.5,,,,,,,,,,,,,,,,,,,,,,,,,,,,,,,,,,,,,
105.002,4.02991,19.42183,2.5,,,,,,,,,,,,,,,,,,,,,,,,,,,,,,,,,,,,,
106.002,3.86325,16.30417,2.5,,,,,,,,,,,,,,,,,,,,,,,,,,,,,,,,,,,,,
107.002,3.69659,13.72084,2.5,,,,,,,,,,,,,,,,,,,,,,,,,,,,,,,,,,,,,
108.002,3.52999,11.4046,2.5,,,,,,,,,,,,,,,,,,,,,,,,,,,,,,,,,,,,,
109.002,3.36334,9.5401,2.5,,,,,,,,,,,,,,,,,,,,,,,,,,,,,,,,,,,,,
110.002,3.19674,7.99324,2.5,,,,,,,,,,,,,,,,,,,,,,,,,,,,,,,,,,,,,
111.002,3.03002,6.70125,2.5,,,,,,,,,,,,,,,,,,,,,,,,,,,,,,,,,,,,,
112.002,2.86337,5.49832,2.5,,,,,,,,,,,,,,,,,,,,,,,,,,,,,,,,,,,,,
113.002,2.69671,4.62583,2.5,,,,,,,,,,,,,,,,,,,,,,,,,,,,,,,,,,,,,
114.002,2.53005,4.06786,2.5,,,,,,,,,,,,,,,,,,,,,,,,,,,,,,,,,,,,,
115.002,2.36351,3.39329,2.5,,,,,,,,,,,,,,,,,,,,,,,,,,,,,,,,,,,,,
116.002,2.19674,2.84634,2.5,,,,,,,,,,,,,,,,,,,,,,,,,,,,,,,,,,,,,
117.002,2.03008,2.22431,2.5,,,,,,,,,,,,,,,,,,,,,,,,,,,,,,,,,,,,,
118.002,1.86337,1.6261,2.5,,,,,,,,,,,,,,,,,,,,,,,,,,,,,,,,,,,,,
119.002,1.69666,1.21556,2.5,,,,,,,,,,,,,,,,,,,,,,,,,,,,,,,,,,,,,
119.79,1.6996,1.2206,3,,,,,,,,,,,,,,,,,,,,,,,,,,,,,,,,,,,,,
120.79,1.86632,1.8419,3,,,,,,,,,,,,,,,,,,,,,,,,,,,,,,,,,,,,,
121.79,2.03297,2.60836,3,,,,,,,,,,,,,,,,,,,,,,,,,,,,,,,,,,,,,
122.79,2.19969,3.40007,3,,,,,,,,,,,,,,,,,,,,,,,,,,,,,,,,,,,,,
123.79,2.36629,4.16322,3,,,,,,,,,,,,,,,,,,,,,,,,,,,,,,,,,,,,,
124.79,2.533,5.00757,3,,,,,,,,,,,,,,,,,,,,,,,,,,,,,,,,,,,,,
125.79,2.69966,5.93175,3,,,,,,,,,,,,,,,,,,,,,,,,,,,,,,,,,,,,,
126.79,2.86643,7.04869,3,,,,,,,,,,,,,,,,,,,,,,,,,,,,,,,,,,,,,
127.79,3.03308,8.27783,3,,,,,,,,,,,,,,,,,,,,,,,,,,,,,,,,,,,,,
128.79,3.19974,9.66956,3,,,,,,,,,,,,,,,,,,,,,,,,,,,,,,,,,,,,,
129.79,3.36651,11.24287,3,,,,,,,,,,,,,,,,,,,,,,,,,,,,,,,,,,,,,
130.79,3.533,13.12187,3,,,,,,,,,,,,,,,,,,,,,,,,,,,,,,,,,,,,,
131.79,3.69977,15.46539,3,,,,,,,,,,,,,,,,,,,,,,,,,,,,,,,,,,,,,
132.79,3.86631,18.12908,3,,,,,,,,,,,,,,,,,,,,,,,,,,,,,,,,,,,,,
133.79,4.03297,21.08179,3,,,,,,,,,,,,,,,,,,,,,,,,,,,,,,,,,,,,,
134.79,4.19957,24.43845,3,,,,,,,,,,,,,,,,,,,,,,,,,,,,,,,,,,,,,
135.79,4.36622,28.06646,3,,,,,,,,,,,,,,,,,,,,,,,,,,,,,,,,,,,,,
136.79,4.53299,32.16391,3,,,,,,,,,,,,,,,,,,,,,,,,,,,,,,,,,,,,,
137.79,4.69959,36.40847,3,,,,,,,,,,,,,,,,,,,,,,,,,,,,,,,,,,,,,
138.606,4.83571,40.01624,3.5,,,,,,,,,,,,,,,,,,,,,,,,,,,,,,,,,,,,,
139.606,4.66882,34.27946,3.5,,,,,,,,,,,,,,,,,,,,,,,,,,,,,,,,,,,,,
140.606,4.50217,29.39261,3.5,,,,,,,,,,,,,,,,,,,,,,,,,,,,,,,,,,,,,
141.606,4.3354,25.10723,3.5,,,,,,,,,,,,,,,,,,,,,,,,,,,,,,,,,,,,,
142.606,4.1688,21.34262,3.5,,,,,,,,,,,,,,,,,,,,,,,,,,,,,,,,,,,,,
143.606,4.00203,18.09844,3.5,,,,,,,,,,,,,,,,,,,,,,,,,,,,,,,,,,,,,
144.606,3.83543,15.20937,3.5,,,,,,,,,,,,,,,,,,,,,,,,,,,,,,,,,,,,,
145.606,3.66877,12.72824,3.5,,,,,,,,,,,,,,,,,,,,,,,,,,,,,,,,,,,,,
146.606,3.50206,10.57893,3.5,,,,,,,,,,,,,,,,,,,,,,,,,,,,,,,,,,,,,
147.606,3.33534,8.86373,3.5,,,,,,,,,,,,,,,,,,,,,,,,,,,,,,,,,,,,,
148.606,3.16874,7.42137,3.5,,,,,,,,,,,,,,,,,,,,,,,,,,,,,,,,,,,,,
149.606,3.00203,6.2063,3.5,,,,,,,,,,,,,,,,,,,,,,,,,,,,,,,,,,,,,
150.606,2.8352,5.09087,3.5,,,,,,,,,,,,,,,,,,,,,,,,,,,,,,,,,,,,,
151.606,2.6686,4.39489,3.5,,,,,,,,,,,,,,,,,,,,,,,,,,,,,,,,,,,,,
152.606,2.50195,3.80797,3.5,,,,,,,,,,,,,,,,,,,,,,,,,,,,,,,,,,,,,
153.606,2.33529,3.17468,3.5,,,,,,,,,,,,,,,,,,,,,,,,,,,,,,,,,,,,,
154.606,2.16869,2.50705,3.5,,,,,,,,,,,,,,,,,,,,,,,,,,,,,,,,,,,,,
155.606,2.00203,1.92662,3.5,,,,,,,,,,,,,,,,,,,,,,,,,,,,,,,,,,,,,
156.606,1.83543,1.46023,3.5,,,,,,,,,,,,,,,,,,,,,,,,,,,,,,,,,,,,,
157.474,1.69065,0.99397,4,,,,,,,,,,,,,,,,,,,,,,,,,,,,,,,,,,,,,
158.376,1.84144,1.52348,4,,,,,,,,,,,,,,,,,,,,,,,,,,,,,,,,,,,,,
159.376,2.0081,2.26716,4,,,,,,,,,,,,,,,,,,,,,,,,,,,,,,,,,,,,,
160.376,2.17481,3.03235,4,,,,,,,,,,,,,,,,,,,,,,,,,,,,,,,,,,,,,
161.376,2.34141,3.82869,4,,,,,,,,,,,,,,,,,,,,,,,,,,,,,,,,,,,,,
162.376,2.50795,4.61867,4,,,,,,,,,,,,,,,,,,,,,,,,,,,,,,,,,,,,,
163.376,2.67472,5.60094,4,,,,,,,,,,,,,,,,,,,,,,,,,,,,,,,,,,,,,
164.376,2.84121,6.57055,4,,,,,,,,,,,,,,,,,,,,,,,,,,,,,,,,,,,,,
165.376,3.00792,7.73928,4,,,,,,,,,,,,,,,,,,,,,,,,,,,,,,,,,,,,,
166.376,3.17458,9.06645,4,,,,,,,,,,,,,,,,,,,,,,,,,,,,,,,,,,,,,
167.376,3.34129,10.48375,4,,,,,,,,,,,,,,,,,,,,,,,,,,,,,,,,,,,,,
168.376,3.50801,12.28517,4,,,,,,,,,,,,,,,,,,,,,,,,,,,,,,,,,,,,,
169.376,3.67461,14.48522,4,,,,,,,,,,,,,,,,,,,,,,,,,,,,,,,,,,,,,
170.376,3.84132,16.94282,4,,,,,,,,,,,,,,,,,,,,,,,,,,,,,,,,,,,,,
171.376,4.00798,19.91339,4,,,,,,,,,,,,,,,,,,,,,,,,,,,,,,,,,,,,,
172.376,4.17469,23.16003,4,,,,,,,,,,,,,,,,,,,,,,,,,,,,,,,,,,,,,
173.376,4.34135,26.7682,4,,,,,,,,,,,,,,,,,,,,,,,,,,,,,,,,,,,,,
174.376,4.50812,30.58514,4,,,,,,,,,,,,,,,,,,,,,,,,,,,,,,,,,,,,,
175.376,4.67477,34.85144,4,,,,,,,,,,,,,,,,,,,,,,,,,,,,,,,,,,,,,
176.376,4.84143,39.37627,4,,,,,,,,,,,,,,,,,,,,,,,,,,,,,,,,,,,,,
177.208,4.7464,35.95713,4.5,,,,,,,,,,,,,,,,,,,,,,,,,,,,,,,,,,,,,
178.208,4.5798,30.83198,4.5,,,,,,,,,,,,,,,,,,,,,,,,,,,,,,,,,,,,,
179.208,4.41303,26.3457,4.5,,,,,,,,,,,,,,,,,,,,,,,,,,,,,,,,,,,,,
180.208,4.24632,22.45971,4.5,,,,,,,,,,,,,,,,,,,,,,,,,,,,,,,,,,,,,
181.208,4.0796,19.07686,4.5,,,,,,,,,,,,,,,,,,,,,,,,,,,,,,,,,,,,,
182.208,3.91289,16.00866,4.5,,,,,,,,,,,,,,,,,,,,,,,,,,,,,,,,,,,,,
183.208,3.74629,13.45344,4.5,,,,,,,,,,,,,,,,,,,,,,,,,,,,,,,,,,,,,
184.208,3.57958,11.19075,4.5,,,,,,,,,,,,,,,,,,,,,,,,,,,,,,,,,,,,,
185.208,3.41298,9.36984,4.5,,,,,,,,,,,,,,,,,,,,,,,,,,,,,,,,,,,,,
186.208,3.24632,7.81736,4.5,,,,,,,,,,,,,,,,,,,,,,,,,,,,,,,,,,,,,
187.208,3.07966,6.56994,4.5,,,,,,,,,,,,,,,,,,,,,,,,,,,,,,,,,,,,,
188.208,2.91312,5.37882,4.5,,,,,,,,,,,,,,,,,,,,,,,,,,,,,,,,,,,,,
189.208,2.74635,4.60225,4.5,,,,,,,,,,,,,,,,,,,,,,,,,,,,,,,,,,,,,
190.208,2.57969,4.01025,4.5,,,,,,,,,,,,,,,,,,,,,,,,,,,,,,,,,,,,,
191.208,2.41298,3.3417,4.5,,,,,,,,,,,,,,,,,,,,,,,,,,,,,,,,,,,,,
192.208,2.24644,2.74824,4.5,,,,,,,,,,,,,,,,,,,,,,,,,,,,,,,,,,,,,
193.208,2.07972,2.07304,4.5,,,,,,,,,,,,,,,,,,,,,,,,,,,,,,,,,,,,,
194.208,1.91307,1.56694,4.5,,,,,,,,,,,,,,,,,,,,,,,,,,,,,,,,,,,,,
195.208,1.74635,1.13277,4.5,,,,,,,,,,,,,,,,,,,,,,,,,,,,,,,,,,,,,
195.966,1.78772,1.14995,5,,,,,,,,,,,,,,,,,,,,,,,,,,,,,,,,,,,,,
196.966,1.95443,1.8751,5,,,,,,,,,,,,,,,,,,,,,,,,,,,,,,,,,,,,,
197.966,2.12109,2.65831,5,,,,,,,,,,,,,,,,,,,,,,,,,,,,,,,,,,,,,
198.966,2.2878,3.44681,5,,,,,,,,,,,,,,,,,,,,,,,,,,,,,,,,,,,,,
199.966,2.4544,4.24697,5,,,,,,,,,,,,,,,,,,,,,,,,,,,,,,,,,,,,,
200.966,2.62106,5.08851,5,,,,,,,,,,,,,,,,,,,,,,,,,,,,,,,,,,,,,
201.966,2.7876,6.04676,5,,,,,,,,,,,,,,,,,,,,,,,,,,,,,,,,,,,,,
202.966,2.95432,7.05993,5,,,,,,,,,,,,,,,,,,,,,,,,,,,,,,,,,,,,,
203.966,3.12092,8.35151,5,,,,,,,,,,,,,,,,,,,,,,,,,,,,,,,,,,,,,
204.966,3.28763,9.76093,5,,,,,,,,,,,,,,,,,,,,,,,,,,,,,,,,,,,,,
205.966,3.45429,11.45368,5,,,,,,,,,,,,,,,,,,,,,,,,,,,,,,,,,,,,,
206.966,3.621,13.30592,5,,,,,,,,,,,,,,,,,,,,,,,,,,,,,,,,,,,,,
207.966,3.78771,15.75783,5,,,,,,,,,,,,,,,,,,,,,,,,,,,,,,,,,,,,,
208.966,3.95426,18.43204,5,,,,,,,,,,,,,,,,,,,,,,,,,,,,,,,,,,,,,
209.966,4.12108,21.55026,5,,,,,,,,,,,,,,,,,,,,,,,,,,,,,,,,,,,,,
210.966,4.28763,24.94384,5,,,,,,,,,,,,,,,,,,,,,,,,,,,,,,,,,,,,,
211.966,4.4544,28.67221,5,,,,,,,,,,,,,,,,,,,,,,,,,,,,,,,,,,,,,
212.966,4.62105,32.80301,5,,,,,,,,,,,,,,,,,,,,,,,,,,,,,,,,,,,,,
213.966,4.78777,37.24011,5,,,,,,,,,,,,,,,,,,,,,,,,,,,,,,,,,,,,,
214.858,4.83616,38.3256,5.5,,,,,,,,,,,,,,,,,,,,,,,,,,,,,,,,,,,,,
215.858,4.66945,32.77689,5.5,,,,,,,,,,,,,,,,,,,,,,,,,,,,,,,,,,,,,
216.858,4.50285,28.09887,5.5,,,,,,,,,,,,,,,,,,,,,,,,,,,,,,,,,,,,,
217.858,4.33608,23.96614,5.5,,,,,,,,,,,,,,,,,,,,,,,,,,,,,,,,,,,,,
218.858,4.16942,20.31345,5.5,,,,,,,,,,,,,,,,,,,,,,,,,,,,,,,,,,,,,
219.858,4.00271,17.16641,5.5,,,,,,,,,,,,,,,,,,,,,,,,,,,,,,,,,,,,,
220.858,3.83605,14.42695,5.5,,,,,,,,,,,,,,,,,,,,,,,,,,,,,,,,,,,,,
221.858,3.66945,12.03181,5.5,,,,,,,,,,,,,,,,,,,,,,,,,,,,,,,,,,,,,
222.858,3.50268,10.03375,5.5,,,,,,,,,,,,,,,,,,,,,,,,,,,,,,,,,,,,,
223.858,3.33602,8.3768,5.5,,,,,,,,,,,,,,,,,,,,,,,,,,,,,,,,,,,,,
224.858,3.16931,6.94871,5.5,,,,,,,,,,,,,,,,,,,,,,,,,,,,,,,,,,,,,
225.858,3.00265,5.78681,5.5,,,,,,,,,,,,,,,,,,,,,,,,,,,,,,,,,,,,,
226.858,2.83583,4.76462,5.5,,,,,,,,,,,,,,,,,,,,,,,,,,,,,,,,,,,,,
227.858,2.66928,4.21793,5.5,,,,,,,,,,,,,,,,,,,,,,,,,,,,,,,,,,,,,
228.858,2.50257,3.50362,5.5,,,,,,,,,,,,,,,,,,,,,,,,,,,,,,,,,,,,,
229.858,2.33597,2.96305,5.5,,,,,,,,,,,,,,,,,,,,,,,,,,,,,,,,,,,,,
230.858,2.16937,2.28426,5.5,,,,,,,,,,,,,,,,,,,,,,,,,,,,,,,,,,,,,
231.858,2.00266,1.70107,5.5,,,,,,,,,,,,,,,,,,,,,,,,,,,,,,,,,,,,,
232.858,1.83606,1.20407,5.5,,,,,,,,,,,,,,,,,,,,,,,,,,,,,,,,,,,,,
233.65,1.83832,1.21162,6,,,,,,,,,,,,,,,,,,,,,,,,,,,,,,,,,,,,,
234.65,2.00515,1.88691,6,,,,,,,,,,,,,,,,,,,,,,,,,,,,,,,,,,,,,
235.65,2.17169,2.72813,6,,,,,,,,,,,,,,,,,,,,,,,,,,,,,,,,,,,,,
236.65,2.33835,3.55646,6,,,,,,,,,,,,,,,,,,,,,,,,,,,,,,,,,,,,,
237.65,2.50495,4.35998,6,,,,,,,,,,,,,,,,,,,,,,,,,,,,,,,,,,,,,
238.65,2.67161,5.19901,6,,,,,,,,,,,,,,,,,,,,,,,,,,,,,,,,,,,,,
239.65,2.83826,6.14777,6,,,,,,,,,,,,,,,,,,,,,,,,,,,,,,,,,,,,,
240.65,3.00492,7.20768,6,,,,,,,,,,,,,,,,,,,,,,,,,,,,,,,,,,,,,
241.65,3.17169,8.56971,6,,,,,,,,,,,,,,,,,,,,,,,,,,,,,,,,,,,,,
242.65,3.33823,9.89523,6,,,,,,,,,,,,,,,,,,,,,,,,,,,,,,,,,,,,,
243.65,3.505,11.668,6,,,,,,,,,,,,,,,,,,,,,,,,,,,,,,,,,,,,,
244.65,3.6716,13.72389,6,,,,,,,,,,,,,,,,,,,,,,,,,,,,,,,,,,,,,
245.65,3.83832,16.15105,6,,,,,,,,,,,,,,,,,,,,,,,,,,,,,,,,,,,,,
246.65,4.00497,18.90634,6,,,,,,,,,,,,,,,,,,,,,,,,,,,,,,,,,,,,,
247.65,4.17169,22.10812,6,,,,,,,,,,,,,,,,,,,,,,,,,,,,,,,,,,,,,
248.65,4.3384,25.56967,6,,,,,,,,,,,,,,,,,,,,,,,,,,,,,,,,,,,,,
249.65,4.50506,29.38736,6,,,,,,,,,,,,,,,,,,,,,,,,,,,,,,,,,,,,,
250.65,4.67183,33.61306,6,,,,,,,,,,,,,,,,,,,,,,,,,,,,,,,,,,,,,
251.65,4.83837,38.13797,6,,,,,,,,,,,,,,,,,,,,,,,,,,,,,,,,,,,,,
252.52,4.81638,37.04235,6.5,,,,,,,,,,,,,,,,,,,,,,,,,,,,,,,,,,,,,
253.52,4.64956,31.69586,6.5,,,,,,,,,,,,,,,,,,,,,,,,,,,,,,,,,,,,,
254.52,4.4829,27.09607,6.5,,,,,,,,,,,,,,,,,,,,,,,,,,,,,,,,,,,,,
255.52,4.31624,23.08179,6.5,,,,,,,,,,,,,,,,,,,,,,,,,,,,,,,,,,,,,
256.52,4.14964,19.62375,6.5,,,,,,,,,,,,,,,,,,,,,,,,,,,,,,,,,,,,,
257.52,3.98304,16.48893,6.5,,,,,,,,,,,,,,,,,,,,,,,,,,,,,,,,,,,,,
258.52,3.81639,13.82765,6.5,,,,,,,,,,,,,,,,,,,,,,,,,,,,,,,,,,,,,
259.52,3.64973,11.56442,6.5,,,,,,,,,,,,,,,,,,,,,,,,,,,,,,,,,,,,,
260.52,3.48307,9.62749,6.5,,,,,,,,,,,,,,,,,,,,,,,,,,,,,,,,,,,,,
261.52,3.31642,7.99502,6.5,,,,,,,,,,,,,,,,,,,,,,,,,,,,,,,,,,,,,
262.52,3.14976,6.70564,6.5,,,,,,,,,,,,,,,,,,,,,,,,,,,,,,,,,,,,,
263.52,2.98305,5.51825,6.5,,,,,,,,,,,,,,,,,,,,,,,,,,,,,,,,,,,,,
264.52,2.81645,4.66421,6.5,,,,,,,,,,,,,,,,,,,,,,,,,,,,,,,,,,,,,
265.52,2.64973,4.01611,6.5,,,,,,,,,,,,,,,,,,,,,,,,,,,,,,,,,,,,,
266.52,2.48308,3.34408,6.5,,,,,,,,,,,,,,,,,,,,,,,,,,,,,,,,,,,,,
267.52,2.31642,2.75621,6.5,,,,,,,,,,,,,,,,,,,,,,,,,,,,,,,,,,,,,
268.52,2.14971,2.1021,6.5,,,,,,,,,,,,,,,,,,,,,,,,,,,,,,,,,,,,,
269.52,1.98294,1.54599,6.5,,,,,,,,,,,,,,,,,,,,,,,,,,,,,,,,,,,,,
270.52,1.81628,1.12077,6.5,,,,,,,,,,,,,,,,,,,,,,,,,,,,,,,,,,,,,
271.254,1.86161,1.24728,7,,,,,,,,,,,,,,,,,,,,,,,,,,,,,,,,,,,,,
272.254,2.02833,1.86974,7,,,,,,,,,,,,,,,,,,,,,,,,,,,,,,,,,,,,,
273.254,2.19493,2.66891,7,,,,,,,,,,,,,,,,,,,,,,,,,,,,,,,,,,,,,
274.254,2.3617,3.43694,7,,,,,,,,,,,,,,,,,,,,,,,,,,,,,,,,,,,,,
275.254,2.52835,4.28055,7,,,,,,,,,,,,,,,,,,,,,,,,,,,,,,,,,,,,,
276.254,2.69507,5.20128,7,,,,,,,,,,,,,,,,,,,,,,,,,,,,,,,,,,,,,
277.254,2.86178,6.14233,7,,,,,,,,,,,,,,,,,,,,,,,,,,,,,,,,,,,,,
278.254,3.02844,7.19599,7,,,,,,,,,,,,,,,,,,,,,,,,,,,,,,,,,,,,,
279.254,3.19509,8.58437,7,,,,,,,,,,,,,,,,,,,,,,,,,,,,,,,,,,,,,
280.254,3.36169,9.98936,7,,,,,,,,,,,,,,,,,,,,,,,,,,,,,,,,,,,,,
281.254,3.52835,11.76293,7,,,,,,,,,,,,,,,,,,,,,,,,,,,,,,,,,,,,,
282.254,3.69489,13.83626,7,,,,,,,,,,,,,,,,,,,,,,,,,,,,,,,,,,,,,
283.254,3.86166,16.22978,7,,,,,,,,,,,,,,,,,,,,,,,,,,,,,,,,,,,,,
284.254,4.02821,18.97651,7,,,,,,,,,,,,,,,,,,,,,,,,,,,,,,,,,,,,,
285.254,4.19498,22.19932,7,,,,,,,,,,,,,,,,,,,,,,,,,,,,,,,,,,,,,
286.254,4.36158,25.67941,7,,,,,,,,,,,,,,,,,,,,,,,,,,,,,,,,,,,,,
287.254,4.52829,29.54461,7,,,,,,,,,,,,,,,,,,,,,,,,,,,,,,,,,,,,,
288.254,4.695,33.73077,7,,,,,,,,,,,,,,,,,,,,,,,,,,,,,,,,,,,,,
289.254,4.8616,38.31876,7,,,,,,,,,,,,,,,,,,,,,,,,,,,,,,,,,,,,,
290.102,4.8361,37.17031,7.5,,,,,,,,,,,,,,,,,,,,,,,,,,,,,,,,,,,,,
291.102,4.66939,31.84005,7.5,,,,,,,,,,,,,,,,,,,,,,,,,,,,,,,,,,,,,
292.102,4.50279,27.24991,7.5,,,,,,,,,,,,,,,,,,,,,,,,,,,,,,,,,,,,,
293.102,4.33608,23.19324,7.5,,,,,,,,,,,,,,,,,,,,,,,,,,,,,,,,,,,,,
294.102,4.16942,19.64384,7.5,,,,,,,,,,,,,,,,,,,,,,,,,,,,,,,,,,,,,
295.102,4.00271,16.56703,7.5,,,,,,,,,,,,,,,,,,,,,,,,,,,,,,,,,,,,,
296.102,3.83605,13.95747,7.5,,,,,,,,,,,,,,,,,,,,,,,,,,,,,,,,,,,,,
297.102,3.66939,11.68089,7.5,,,,,,,,,,,,,,,,,,,,,,,,,,,,,,,,,,,,,
298.102,3.50274,9.6601,7.5,,,,,,,,,,,,,,,,,,,,,,,,,,,,,,,,,,,,,
299.102,3.33602,8.12973,7.5,,,,,,,,,,,,,,,,,,,,,,,,,,,,,,,,,,,,,
300.102,3.16931,6.68802,7.5,,,,,,,,,,,,,,,,,,,,,,,,,,,,,,,,,,,,,
301.102,3.00265,5.56304,7.5,,,,,,,,,,,,,,,,,,,,,,,,,,,,,,,,,,,,,
302.102,2.83588,4.66388,7.5,,,,,,,,,,,,,,,,,,,,,,,,,,,,,,,,,,,,,
303.102,2.66923,4.03464,7.5,,,,,,,,,,,,,,,,,,,,,,,,,,,,,,,,,,,,,
304.102,2.50263,3.32267,7.5,,,,,,,,,,,,,,,,,,,,,,,,,,,,,,,,,,,,,
305.102,2.33597,2.75832,7.5,,,,,,,,,,,,,,,,,,,,,,,,,,,,,,,,,,,,,
306.102,2.16931,2.07971,7.5,,,,,,,,,,,,,,,,,,,,,,,,,,,,,,,,,,,,,
307.102,2.00266,1.57408,7.5,,,,,,,,,,,,,,,,,,,,,,,,,,,,,,,,,,,,,
308.102,1.83606,1.11858,7.5,,,,,,,,,,,,,,,,,,,,,,,,,,,,,,,,,,,,,
308.818,1.88434,1.25577,8,,,,,,,,,,,,,,,,,,,,,,,,,,,,,,,,,,,,,
309.818,2.05094,1.97701,8,,,,,,,,,,,,,,,,,,,,,,,,,,,,,,,,,,,,,
310.818,2.21759,2.76729,8,,,,,,,,,,,,,,,,,,,,,,,,,,,,,,,,,,,,,
311.818,2.38431,3.57256,8,,,,,,,,,,,,,,,,,,,,,,,,,,,,,,,,,,,,,
312.818,2.55085,4.32346,8,,,,,,,,,,,,,,,,,,,,,,,,,,,,,,,,,,,,,
313.818,2.71768,5.28398,8,,,,,,,,,,,,,,,,,,,,,,,,,,,,,,,,,,,,,
314.818,2.88428,6.17463,8,,,,,,,,,,,,,,,,,,,,,,,,,,,,,,,,,,,,,
315.818,3.05105,7.27096,8,,,,,,,,,,,,,,,,,,,,,,,,,,,,,,,,,,,,,
316.818,3.21759,8.6179,8,,,,,,,,,,,,,,,,,,,,,,,,,,,,,,,,,,,,,
317.818,3.3843,10.04233,8,,,,,,,,,,,,,,,,,,,,,,,,,,,,,,,,,,,,,
318.818,3.55102,11.82117,8,,,,,,,,,,,,,,,,,,,,,,,,,,,,,,,,,,,,,
319.818,3.71767,13.90097,8,,,,,,,,,,,,,,,,,,,,,,,,,,,,,,,,,,,,,
320.818,3.88444,16.33521,8,,,,,,,,,,,,,,,,,,,,,,,,,,,,,,,,,,,,,
321.818,4.05104,19.1197,8,,,,,,,,,,,,,,,,,,,,,,,,,,,,,,,,,,,,,
322.818,4.21781,22.34827,8,,,,,,,,,,,,,,,,,,,,,,,,,,,,,,,,,,,,,
323.818,4.38441,25.91454,8,,,,,,,,,,,,,,,,,,,,,,,,,,,,,,,,,,,,,
324.818,4.55107,29.73028,8,,,,,,,,,,,,,,,,,,,,,,,,,,,,,,,,,,,,,
325.818,4.71767,34.0098,8,,,,,,,,,,,,,,,,,,,,,,,,,,,,,,,,,,,,,
326.818,4.88433,38.65613,8,,,,,,,,,,,,,,,,,,,,,,,,,,,,,,,,,,,,,
327.712,4.83299,36.53098,8.5,,,,,,,,,,,,,,,,,,,,,,,,,,,,,,,,,,,,,
328.712,4.66644,31.25034,8.5,,,,,,,,,,,,,,,,,,,,,,,,,,,,,,,,,,,,,
329.712,4.49979,26.79325,8.5,,,,,,,,,,,,,,,,,,,,,,,,,,,,,,,,,,,,,
330.712,4.33307,22.75958,8.5,,,,,,,,,,,,,,,,,,,,,,,,,,,,,,,,,,,,,
331.712,4.16642,19.32612,8.5,,,,,,,,,,,,,,,,,,,,,,,,,,,,,,,,,,,,,
332.712,3.9997,16.25834,8.5,,,,,,,,,,,,,,,,,,,,,,,,,,,,,,,,,,,,,
333.712,3.83305,13.56965,8.5,,,,,,,,,,,,,,,,,,,,,,,,,,,,,,,,,,,,,
334.712,3.66639,11.28865,8.5,,,,,,,,,,,,,,,,,,,,,,,,,,,,,,,,,,,,,
335.712,3.49979,9.47173,8.5,,,,,,,,,,,,,,,,,,,,,,,,,,,,,,,,,,,,,
336.712,3.33302,7.9088,8.5,,,,,,,,,,,,,,,,,,,,,,,,,,,,,,,,,,,,,
337.712,3.16636,6.56719,8.5,,,,,,,,,,,,,,,,,,,,,,,,,,,,,,,,,,,,,
338.712,2.99971,5.39155,8.5,,,,,,,,,,,,,,,,,,,,,,,,,,,,,,,,,,,,,
339.712,2.83294,4.56923,8.5,,,,,,,,,,,,,,,,,,,,,,,,,,,,,,,,,,,,,
340.712,2.66622,3.95602,8.5,,,,,,,,,,,,,,,,,,,,,,,,,,,,,,,,,,,,,
341.712,2.49957,3.36869,8.5,,,,,,,,,,,,,,,,,,,,,,,,,,,,,,,,,,,,,
342.712,2.33297,2.64851,8.5,,,,,,,,,,,,,,,,,,,,,,,,,,,,,,,,,,,,,
343.712,2.16625,2.02455,8.5,,,,,,,,,,,,,,,,,,,,,,,,,,,,,,,,,,,,,
344.712,1.99977,1.58338,8.5,,,,,,,,,,,,,,,,,,,,,,,,,,,,,,,,,,,,,
345.688,1.83708,0.99778,9,,,,,,,,,,,,,,,,,,,,,,,,,,,,,,,,,,,,,
346.492,1.97064,1.47747,9,,,,,,,,,,,,,,,,,,,,,,,,,,,,,,,,,,,,,
347.492,2.1373,2.21814,9,,,,,,,,,,,,,,,,,,,,,,,,,,,,,,,,,,,,,
348.492,2.30395,3.00772,9,,,,,,,,,,,,,,,,,,,,,,,,,,,,,,,,,,,,,
349.492,2.47072,3.81577,9,,,,,,,,,,,,,,,,,,,,,,,,,,,,,,,,,,,,,
350.492,2.63744,4.64097,9,,,,,,,,,,,,,,,,,,,,,,,,,,,,,,,,,,,,,
351.492,2.80415,5.66424,9,,,,,,,,,,,,,,,,,,,,,,,,,,,,,,,,,,,,,
352.492,2.97075,6.69285,9,,,,,,,,,,,,,,,,,,,,,,,,,,,,,,,,,,,,,
353.492,3.13746,7.83604,9,,,,,,,,,,,,,,,,,,,,,,,,,,,,,,,,,,,,,
354.492,3.30406,9.17847,9,,,,,,,,,,,,,,,,,,,,,,,,,,,,,,,,,,,,,
355.492,3.47066,10.78063,9,,,,,,,,,,,,,,,,,,,,,,,,,,,,,,,,,,,,,
356.492,3.63732,12.57719,9,,,,,,,,,,,,,,,,,,,,,,,,,,,,,,,,,,,,,
357.492,3.80392,14.825,9,,,,,,,,,,,,,,,,,,,,,,,,,,,,,,,,,,,,,
358.492,3.97063,17.42841,9,,,,,,,,,,,,,,,,,,,,,,,,,,,,,,,,,,,,,
359.492,4.13723,20.43865,9,,,,,,,,,,,,,,,,,,,,,,,,,,,,,,,,,,,,,
360.492,4.304,23.83469,9,,,,,,,,,,,,,,,,,,,,,,,,,,,,,,,,,,,,,
361.492,4.47055,27.47454,9,,,,,,,,,,,,,,,,,,,,,,,,,,,,,,,,,,,,,
362.492,4.63732,31.54841,9,,,,,,,,,,,,,,,,,,,,,,,,,,,,,,,,,,,,,
363.492,4.80397,35.97555,9,,,,,,,,,,,,,,,,,,,,,,,,,,,,,,,,,,,,,
364.35,4.947,40.01048,9.5,,,,,,,,,,,,,,,,,,,,,,,,,,,,,,,,,,,,,
365.35,4.78012,34.40405,9.5,,,,,,,,,,,,,,,,,,,,,,,,,,,,,,,,,,,,,
366.35,4.6134,29.40154,9.5,,,,,,,,,,,,,,,,,,,,,,,,,,,,,,,,,,,,,
367.35,4.44686,25.07319,9.5,,,,,,,,,,,,,,,,,,,,,,,,,,,,,,,,,,,,,
368.35,4.28009,21.35081,9.5,,,,,,,,,,,,,,,,,,,,,,,,,,,,,,,,,,,,,
369.35,4.11343,17.98477,9.5,,,,,,,,,,,,,,,,,,,,,,,,,,,,,,,,,,,,,
370.35,3.94666,15.12562,9.5,,,,,,,,,,,,,,,,,,,,,,,,,,,,,,,,,,,,,
371.35,3.78012,12.64034,9.5,,,,,,,,,,,,,,,,,,,,,,,,,,,,,,,,,,,,,
372.35,3.61335,10.46571,9.5,,,,,,,,,,,,,,,,,,,,,,,,,,,,,,,,,,,,,
373.35,3.44675,8.7422,9.5,,,,,,,,,,,,,,,,,,,,,,,,,,,,,,,,,,,,,
374.35,3.27998,7.35583,9.5,,,,,,,,,,,,,,,,,,,,,,,,,,,,,,,,,,,,,
375.35,3.11332,5.99851,9.5,,,,,,,,,,,,,,,,,,,,,,,,,,,,,,,,,,,,,
376.35,2.94661,4.98946,9.5,,,,,,,,,,,,,,,,,,,,,,,,,,,,,,,,,,,,,
377.35,2.77984,4.44188,9.5,,,,,,,,,,,,,,,,,,,,,,,,,,,,,,,,,,,,,
378.35,2.61318,3.67718,9.5,,,,,,,,,,,,,,,,,,,,,,,,,,,,,,,,,,,,,
379.35,2.4467,3.06156,9.5,,,,,,,,,,,,,,,,,,,,,,,,,,,,,,,,,,,,,
380.35,2.27993,2.37133,9.5,,,,,,,,,,,,,,,,,,,,,,,,,,,,,,,,,,,,,
381.35,2.11338,1.70551,9.5,,,,,,,,,,,,,,,,,,,,,,,,,,,,,,,,,,,,,
382.35,1.94678,1.25853,9.5,,,,,,,,,,,,,,,,,,,,,,,,,,,,,,,,,,,,,
383.246,1.79809,0.93812,10,,,,,,,,,,,,,,,,,,,,,,,,,,,,,,,,,,,,,
384.246,1.70476,0.80965,10,,,,,,,,,,,,,,,,,,,,,,,,,,,,,,,,,,,,,
385.246,1.70227,0.78003,10,,,,,,,,,,,,,,,,,,,,,,,,,,,,,,,,,,,,,
386.246,1.70368,0.83484,10,,,,,,,,,,,,,,,,,,,,,,,,,,,,,,,,,,,,,
387.246,1.72136,0.91017,10,,,,,,,,,,,,,,,,,,,,,,,,,,,,,,,,,,,,,
388.246,1.80704,1.07593,10,,,,,,,,,,,,,,,,,,,,,,,,,,,,,,,,,,,,,
389.246,1.84246,1.13366,10,,,,,,,,,,,,,,,,,,,,,,,,,,,,,,,,,,,,,
390.246,1.84223,1.12439,10,,,,,,,,,,,,,,,,,,,,,,,,,,,,,,,,,,,,,
391.246,1.83997,1.17399,10,,,,,,,,,,,,,,,,,,,,,,,,,,,,,,,,,,,,,
392.246,1.79792,1.06373,10,,,,,,,,,,,,,,,,,,,,,,,,,,,,,,,,,,,,,
393.246,1.71955,0.97579,10,,,,,,,,,,,,,,,,,,,,,,,,,,,,,,,,,,,,,
394.246,1.69943,0.89854,10,,,,,,,,,,,,,,,,,,,,,,,,,,,,,,,,,,,,,
395.246,1.6996,0.85453,10,,,,,,,,,,,,,,,,,,,,,,,,,,,,,,,,,,,,,
396.246,1.69989,0.88436,10,,,,,,,,,,,,,,,,,,,,,,,,,,,,,,,,,,,,,
397.246,1.70062,0.85269,10,,,,,,,,,,,,,,,,,,,,,,,,,,,,,,,,,,,,,
398.246,1.703,0.86796,10,,,,,,,,,,,,,,,,,,,,,,,,,,,,,,,,,,,,,
399.246,1.74346,0.96974,10,,,,,,,,,,,,,,,,,,,,,,,,,,,,,,,,,,,,,
400.246,1.80166,1.09631,10,,,,,,,,,,,,,,,,,,,,,,,,,,,,,,,,,,,,,
401.246,1.80602,1.11455,10,,,,,,,,,,,,,,,,,,,,,,,,,,,,,,,,,,,,,
402.246,1.80563,1.16359,10,,,,,,,,,,,,,,,,,,,,,,,,,,,,,,,,,,,,,
403.246,1.80325,1.1461,10,,,,,,,,,,,,,,,,,,,,,,,,,,,,,,,,,,,,,
404.246,1.77701,1.04769,10,,,,,,,,,,,,,,,,,,,,,,,,,,,,,,,,,,,,,
405.246,1.72471,0.98111,10,,,,,,,,,,,,,,,,,,,,,,,,,,,,,,,,,,,,,
406.246,1.71037,0.93196,10,,,,,,,,,,,,,,,,,,,,,,,,,,,,,,,,,,,,,
407.246,1.70952,0.92025,10,,,,,,,,,,,,,,,,,,,,,,,,,,,,,,,,,,,,,
408.246,1.70963,0.96811,10,,,,,,,,,,,,,,,,,,,,,,,,,,,,,,,,,,,,,
409.246,1.70986,0.88221,10,,,,,,,,,,,,,,,,,,,,,,,,,,,,,,,,,,,,,
410.246,1.71026,0.88614,10,,,,,,,,,,,,,,,,,,,,,,,,,,,,,,,,,,,,,
411.246,1.71162,0.95458,10,,,,,,,,,,,,,,,,,,,,,,,,,,,,,,,,,,,,,
412.246,1.71915,0.88924,10,,,,,,,,,,,,,,,,,,,,,,,,,,,,,,,,,,,,,
413.246,1.76942,1.02416,10,,,,,,,,,,,,,,,,,,,,,,,,,,,,,,,,,,,,,
414.246,1.79038,1.11193,10,,,,,,,,,,,,,,,,,,,,,,,,,,,,,,,,,,,,,
415.246,1.79033,1.06459,10,,,,,,,,,,,,,,,,,,,,,,,,,,,,,,,,,,,,,
416.246,1.79004,1.09669,10,,,,,,,,,,,,,,,,,,,,,,,,,,,,,,,,,,,,,
417.246,1.78829,1.09669,10,,,,,,,,,,,,,,,,,,,,,,,,,,,,,,,,,,,,,
418.246,1.77095,1.04829,10,,,,,,,,,,,,,,,,,,,,,,,,,,,,,,,,,,,,,
419.246,1.73032,0.96483,10,,,,,,,,,,,,,,,,,,,,,,,,,,,,,,,,,,,,,
420.246,1.71932,0.99431,10,,,,,,,,,,,,,,,,,,,,,,,,,,,,,,,,,,,,,
421.246,1.71672,0.98003,10,,,,,,,,,,,,,,,,,,,,,,,,,,,,,,,,,,,,,
422.246,1.71632,0.92452,10,,,,,,,,,,,,,,,,,,,,,,,,,,,,,,,,,,,,,
423.246,1.71643,1.0246,10,,,,,,,,,,,,,,,,,,,,,,,,,,,,,,,,,,,,,
424.246,1.71655,0.95616,10,,,,,,,,,,,,,,,,,,,,,,,,,,,,,,,,,,,,,
425.246,1.71666,0.92746,10,,,,,,,,,,,,,,,,,,,,,,,,,,,,,,,,,,,,,
426.246,1.71694,0.9076,10,,,,,,,,,,,,,,,,,,,,,,,,,,,,,,,,,,,,,
427.246,1.71734,0.93908,10,,,,,,,,,,,,,,,,,,,,,,,,,,,,,,,,,,,,,
428.246,1.71802,0.98592,10,,,,,,,,,,,,,,,,,,,,,,,,,,,,,,,,,,,,,
429.246,1.72131,0.90378,10,,,,,,,,,,,,,,,,,,,,,,,,,,,,,,,,,,,,,
430.246,1.74477,0.95511,10,,,,,,,,,,,,,,,,,,,,,,,,,,,,,,,,,,,,,
431.246,1.76369,1.0341,10,,,,,,,,,,,,,,,,,,,,,,,,,,,,,,,,,,,,,
432.246,1.76534,1.07249,10,,,,,,,,,,,,,,,,,,,,,,,,,,,,,,,,,,,,,
433.246,1.76522,1.04005,10,,,,,,,,,,,,,,,,,,,,,,,,,,,,,,,,,,,,,
434.246,1.76517,1.01619,10,,,,,,,,,,,,,,,,,,,,,,,,,,,,,,,,,,,,,
435.246,1.76505,1.04331,10,,,,,,,,,,,,,,,,,,,,,,,,,,,,,,,,,,,,,
436.246,1.76466,1.03239,10,,,,,,,,,,,,,,,,,,,,,,,,,,,,,,,,,,,,,
437.246,1.76126,1.07534,10,,,,,,,,,,,,,,,,,,,,,,,,,,,,,,,,,,,,,
438.246,1.75066,1.06894,10,,,,,,,,,,,,,,,,,,,,,,,,,,,,,,,,,,,,,
439.246,1.73026,0.98344,10,,,,,,,,,,,,,,,,,,,,,,,,,,,,,,,,,,,,,
440.246,1.72244,0.98952,10,,,,,,,,,,,,,,,,,,,,,,,,,,,,,,,,,,,,,
441.246,1.72097,0.99199,10,,,,,,,,,,,,,,,,,,,,,,,,,,,,,,,,,,,,,
442.246,1.72057,0.95812,10,,,,,,,,,,,,,,,,,,,,,,,,,,,,,,,,,,,,,
443.246,1.72051,0.94904,10,,,,,,,,,,,,,,,,,,,,,,,,,,,,,,,,,,,,,
444.246,1.72068,0.95989,10,,,,,,,,,,,,,,,,,,,,,,,,,,,,,,,,,,,,,
445.246,1.72074,0.92788,10,,,,,,,,,,,,,,,,,,,,,,,,,,,,,,,,,,,,,
446.246,1.72085,0.93115,10,,,,,,,,,,,,,,,,,,,,,,,,,,,,,,,,,,,,,
447.246,1.72097,0.96981,10,,,,,,,,,,,,,,,,,,,,,,,,,,,,,,,,,,,,,
448.246,1.72108,0.94885,10,,,,,,,,,,,,,,,,,,,,,,,,,,,,,,,,,,,,,
449.246,1.72142,0.96607,10,,,,,,,,,,,,,,,,,,,,,,,,,,,,,,,,,,,,,
450.246,1.72187,0.95341,10,,,,,,,,,,,,,,,,,,,,,,,,,,,,,,,,,,,,,
451.246,1.72329,0.91584,10,,,,,,,,,,,,,,,,,,,,,,,,,,,,,,,,,,,,,
452.246,1.72607,0.96424,10,,,,,,,,,,,,,,,,,,,,,,,,,,,,,,,,,,,,,
453.246,1.7395,1.02117,10,,,,,,,,,,,,,,,,,,,,,,,,,,,,,,,,,,,,,
454.246,1.75638,1.0223,10,,,,,,,,,,,,,,,,,,,,,,,,,,,,,,,,,,,,,
455.246,1.75752,1.05826,10,,,,,,,,,,,,,,,,,,,,,,,,,,,,,,,,,,,,,
456.246,1.75735,1.09545,10,,,,,,,,,,,,,,,,,,,,,,,,,,,,,,,,,,,,,
457.246,1.75723,1.07361,10,,,,,,,,,,,,,,,,,,,,,,,,,,,,,,,,,,,,,
458.246,1.75723,0.97306,10,,,,,,,,,,,,,,,,,,,,,,,,,,,,,,,,,,,,,
459.246,1.75723,1.00955,10,,,,,,,,,,,,,,,,,,,,,,,,,,,,,,,,,,,,,
460.246,1.75718,0.96891,10,,,,,,,,,,,,,,,,,,,,,,,,,,,,,,,,,,,,,
461.246,1.75718,1.00829,10,,,,,,,,,,,,,,,,,,,,,,,,,,,,,,,,,,,,,
462.246,1.75718,1.02821,10,,,,,,,,,,,,,,,,,,,,,,,,,,,,,,,,,,,,,
463.246,1.75712,0.95276,10,,,,,,,,,,,,,,,,,,,,,,,,,,,,,,,,,,,,,
464.246,1.75706,0.99831,10,,,,,,,,,,,,,,,,,,,,,,,,,,,,,,,,,,,,,
465.246,1.75701,1.0641,10,,,,,,,,,,,,,,,,,,,,,,,,,,,,,,,,,,,,,
466.246,1.75678,1.03155,10,,,,,,,,,,,,,,,,,,,,,,,,,,,,,,,,,,,,,
467.246,1.75621,1.0018,10,,,,,,,,,,,,,,,,,,,,,,,,,,,,,,,,,,,,,
468.246,1.75531,1.05021,10,,,,,,,,,,,,,,,,,,,,,,,,,,,,,,,,,,,,,
469.246,1.75395,1.01385,10,,,,,,,,,,,,,,,,,,,,,,,,,,,,,,,,,,,,,
470.246,1.74992,1.00772,10,,,,,,,,,,,,,,,,,,,,,,,,,,,,,,,,,,,,,
471.246,1.7446,1.04787,10,,,,,,,,,,,,,,,,,,,,,,,,,,,,,,,,,,,,,
472.246,1.73808,0.93866,10,,,,,,,,,,,,,,,,,,,,,,,,,,,,,,,,,,,,,
473.246,1.73451,1.00338,10,,,,,,,,,,,,,,,,,,,,,,,,,,,,,,,,,,,,,
474.246,1.73377,0.99491,10,,,,,,,,,,,,,,,,,,,,,,,,,,,,,,,,,,,,,
475.246,1.7336,0.98518,10,,,,,,,,,,,,,,,,,,,,,,,,,,,,,,,,,,,,,
476.246,1.7336,0.97162,10,,,,,,,,,,,,,,,,,,,,,,,,,,,,,,,,,,,,,
477.246,1.73372,0.98189,10,,,,,,,,,,,,,,,,,,,,,,,,,,,,,,,,,,,,,
478.246,1.73377,0.9275,10,,,,,,,,,,,,,,,,,,,,,,,,,,,,,,,,,,,,,
479.246,1.73377,0.99858,10,,,,,,,,,,,,,,,,,,,,,,,,,,,,,,,,,,,,,
480.246,1.73383,0.92182,10,,,,,,,,,,,,,,,,,,,,,,,,,,,,,,,,,,,,,
481.246,1.73406,0.91702,10,,,,,,,,,,,,,,,,,,,,,,,,,,,,,,,,,,,,,
482.246,1.73434,0.99816,10,,,,,,,,,,,,,,,,,,,,,,,,,,,,,,,,,,,,,
483.246,1.73519,0.95045,10,,,,,,,,,,,,,,,,,,,,,,,,,,,,,,,,,,,,,
484.246,1.73717,0.93726,10,,,,,,,,,,,,,,,,,,,,,,,,,,,,,,,,,,,,,
485.246,1.74664,0.95218,10,,,,,,,,,,,,,,,,,,,,,,,,,,,,,,,,,,,,,
486.246,1.75735,1.0473,10,,,,,,,,,,,,,,,,,,,,,,,,,,,,,,,,,,,,,
487.246,1.75803,0.99033,10,,,,,,,,,,,,,,,,,,,,,,,,,,,,,,,,,,,,,
488.246,1.75825,1.07989,10,,,,,,,,,,,,,,,,,,,,,,,,,,,,,,,,,,,,,
489.246,1.75814,1.0633,10,,,,,,,,,,,,,,,,,,,,,,,,,,,,,,,,,,,,,
490.246,1.75808,1.00639,10,,,,,,,,,,,,,,,,,,,,,,,,,,,,,,,,,,,,,
491.246,1.75803,1.03135,10,,,,,,,,,,,,,,,,,,,,,,,,,,,,,,,,,,,,,
492.246,1.75797,1.01526,10,,,,,,,,,,,,,,,,,,,,,,,,,,,,,,,,,,,,,
493.246,1.7578,1.08103,10,,,,,,,,,,,,,,,,,,,,,,,,,,,,,,,,,,,,,
494.246,1.7574,1.00651,10,,,,,,,,,,,,,,,,,,,,,,,,,,,,,,,,,,,,,
495.246,1.7565,1.07132,10,,,,,,,,,,,,,,,,,,,,,,,,,,,,,,,,,,,,,
496.246,1.75514,1.00488,10,,,,,,,,,,,,,,,,,,,,,,,,,,,,,,,,,,,,,
497.246,1.75247,1.01679,10,,,,,,,,,,,,,,,,,,,,,,,,,,,,,,,,,,,,,
498.246,1.7442,1.06483,10,,,,,,,,,,,,,,,,,,,,,,,,,,,,,,,,,,,,,
499.246,1.73247,0.95642,10,,,,,,,,,,,,,,,,,,,,,,,,,,,,,,,,,,,,,
500.246,1.73066,0.99921,10,,,,,,,,,,,,,,,,,,,,,,,,,,,,,,,,,,,,,
501.246,1.73015,1.01597,10,,,,,,,,,,,,,,,,,,,,,,,,,,,,,,,,,,,,,
502.246,1.72992,1.0003,10,,,,,,,,,,,,,,,,,,,,,,,,,,,,,,,,,,,,,
503.246,1.72998,0.96591,10,,,,,,,,,,,,,,,,,,,,,,,,,,,,,,,,,,,,,
504.246,1.73009,0.97725,10,,,,,,,,,,,,,,,,,,,,,,,,,,,,,,,,,,,,,
505.246,1.73015,0.96307,10,,,,,,,,,,,,,,,,,,,,,,,,,,,,,,,,,,,,,
506.246,1.73037,0.94692,10,,,,,,,,,,,,,,,,,,,,,,,,,,,,,,,,,,,,,
507.246,1.73066,0.98687,10,,,,,,,,,,,,,,,,,,,,,,,,,,,,,,,,,,,,,
508.246,1.73151,0.93756,10,,,,,,,,,,,,,,,,,,,,,,,,,,,,,,,,,,,,,
509.246,1.73547,0.93722,10,,,,,,,,,,,,,,,,,,,,,,,,,,,,,,,,,,,,,
510.246,1.75327,0.98794,10,,,,,,,,,,,,,,,,,,,,,,,,,,,,,,,,,,,,,
511.246,1.76494,1.02621,10,,,,,,,,,,,,,,,,,,,,,,,,,,,,,,,,,,,,,
512.246,1.76607,1.04316,10,,,,,,,,,,,,,,,,,,,,,,,,,,,,,,,,,,,,,
513.246,1.76602,1.07551,10,,,,,,,,,,,,,,,,,,,,,,,,,,,,,,,,,,,,,
514.246,1.7659,1.07369,10,,,,,,,,,,,,,,,,,,,,,,,,,,,,,,,,,,,,,
515.246,1.76579,1.03838,10,,,,,,,,,,,,,,,,,,,,,,,,,,,,,,,,,,,,,
516.246,1.76539,1.06856,10,,,,,,,,,,,,,,,,,,,,,,,,,,,,,,,,,,,,,
517.246,1.76313,1.07701,10,,,,,,,,,,,,,,,,,,,,,,,,,,,,,,,,,,,,,
518.246,1.7557,0.99726,10,,,,,,,,,,,,,,,,,,,,,,,,,,,,,,,,,,,,,
519.246,1.74159,1.01419,10,,,,,,,,,,,,,,,,,,,,,,,,,,,,,,,,,,,,,
520.246,1.73015,0.99877,10,,,,,,,,,,,,,,,,,,,,,,,,,,,,,,,,,,,,,
521.246,1.72448,0.90845,10,,,,,,,,,,,,,,,,,,,,,,,,,,,,,,,,,,,,,
522.246,1.72352,1.02156,10,,,,,,,,,,,,,,,,,,,,,,,,,,,,,,,,,,,,,
523.246,1.72335,1.00025,10,,,,,,,,,,,,,,,,,,,,,,,,,,,,,,,,,,,,,
524.246,1.72352,0.9543,10,,,,,,,,,,,,,,,,,,,,,,,,,,,,,,,,,,,,,
525.246,1.72363,1.01102,10,,,,,,,,,,,,,,,,,,,,,,,,,,,,,,,,,,,,,
526.246,1.72374,1.00136,10,,,,,,,,,,,,,,,,,,,,,,,,,,,,,,,,,,,,,
527.246,1.72391,0.90137,10,,,,,,,,,,,,,,,,,,,,,,,,,,,,,,,,,,,,,
528.246,1.72442,0.93069,10,,,,,,,,,,,,,,,,,,,,,,,,,,,,,,,,,,,,,
529.246,1.72573,0.92684,10,,,,,,,,,,,,,,,,,,,,,,,,,,,,,,,,,,,,,
530.246,1.73615,0.97221,10,,,,,,,,,,,,,,,,,,,,,,,,,,,,,,,,,,,,,
531.246,1.77027,1.05544,10,,,,,,,,,,,,,,,,,,,,,,,,,,,,,,,,,,,,,
532.246,1.77395,1.03812,10,,,,,,,,,,,,,,,,,,,,,,,,,,,,,,,,,,,,,
533.246,1.77378,1.07293,10,,,,,,,,,,,,,,,,,,,,,,,,,,,,,,,,,,,,,
534.246,1.77355,1.10151,10,,,,,,,,,,,,,,,,,,,,,,,,,,,,,,,,,,,,,
535.246,1.77168,1.07641,10,,,,,,,,,,,,,,,,,,,,,,,,,,,,,,,,,,,,,
536.246,1.76126,1.06085,10,,,,,,,,,,,,,,,,,,,,,,,,,,,,,,,,,,,,,
537.246,1.74199,1.03485,10,,,,,,,,,,,,,,,,,,,,,,,,,,,,,,,,,,,,,
538.246,1.72743,1.03907,10,,,,,,,,,,,,,,,,,,,,,,,,,,,,,,,,,,,,,
539.246,1.72567,0.97569,10,,,,,,,,,,,,,,,,,,,,,,,,,,,,,,,,,,,,,
540.246,1.72556,0.97338,10,,,,,,,,,,,,,,,,,,,,,,,,,,,,,,,,,,,,,
541.246,1.72567,0.92385,10,,,,,,,,,,,,,,,,,,,,,,,,,,,,,,,,,,,,,
542.246,1.72584,0.93814,10,,,,,,,,,,,,,,,,,,,,,,,,,,,,,,,,,,,,,
543.246,1.72607,0.92803,10,,,,,,,,,,,,,,,,,,,,,,,,,,,,,,,,,,,,,
544.246,1.72663,0.88262,10,,,,,,,,,,,,,,,,,,,,,,,,,,,,,,,,,,,,,
545.246,1.72862,0.94045,10,,,,,,,,,,,,,,,,,,,,,,,,,,,,,,,,,,,,,
546.246,1.7455,0.93488,10,,,,,,,,,,,,,,,,,,,,,,,,,,,,,,,,,,,,,
547.246,1.77922,1.05627,10,,,,,,,,,,,,,,,,,,,,,,,,,,,,,,,,,,,,,
548.246,1.78047,1.09233,10,,,,,,,,,,,,,,,,,,,,,,,,,,,,,,,,,,,,,
549.246,1.78018,1.06793,10,,,,,,,,,,,,,,,,,,,,,,,,,,,,,,,,,,,,,
550.246,1.77973,1.1205,10,,,,,,,,,,,,,,,,,,,,,,,,,,,,,,,,,,,,,
551.246,1.77576,1.0651,10,,,,,,,,,,,,,,,,,,,,,,,,,,,,,,,,,,,,,
552.246,1.7548,1.04198,10,,,,,,,,,,,,,,,,,,,,,,,,,,,,,,,,,,,,,
553.246,1.73508,0.96253,10,,,,,,,,,,,,,,,,,,,,,,,,,,,,,,,,,,,,,
554.246,1.72867,0.87966,10,,,,,,,,,,,,,,,,,,,,,,,,,,,,,,,,,,,,,
555.246,1.7285,0.92012,10,,,,,,,,,,,,,,,,,,,,,,,,,,,,,,,,,,,,,
556.246,1.72873,0.94841,10,,,,,,,,,,,,,,,,,,,,,,,,,,,,,,,,,,,,,
557.246,1.72901,0.91969,10,,,,,,,,,,,,,,,,,,,,,,,,,,,,,,,,,,,,,
558.246,1.72958,0.92945,10,,,,,,,,,,,,,,,,,,,,,,,,,,,,,,,,,,,,,
559.246,1.73088,1.00901,10,,,,,,,,,,,,,,,,,,,,,,,,,,,,,,,,,,,,,
560.246,1.73298,0.99542,10,,,,,,,,,,,,,,,,,,,,,,,,,,,,,,,,,,,,,
561.246,1.73496,0.97733,10,,,,,,,,,,,,,,,,,,,,,,,,,,,,,,,,,,,,,
562.246,1.73751,0.99521,10,,,,,,,,,,,,,,,,,,,,,,,,,,,,,,,,,,,,,
563.246,1.74783,1.02476,10,,,,,,,,,,,,,,,,,,,,,,,,,,,,,,,,,,,,,
564.246,1.75735,1.05896,10,,,,,,,,,,,,,,,,,,,,,,,,,,,,,,,,,,,,,
565.246,1.75723,1.04842,10,,,,,,,,,,,,,,,,,,,,,,,,,,,,,,,,,,,,,
566.246,1.75718,1.00604,10,,,,,,,,,,,,,,,,,,,,,,,,,,,,,,,,,,,,,
567.246,1.75706,1.06156,10,,,,,,,,,,,,,,,,,,,,,,,,,,,,,,,,,,,,,
568.246,1.75684,1.05096,10,,,,,,,,,,,,,,,,,,,,,,,,,,,,,,,,,,,,,
569.246,1.75604,1.0372,10,,,,,,,,,,,,,,,,,,,,,,,,,,,,,,,,,,,,,
570.246,1.75389,1.04525,10,,,,,,,,,,,,,,,,,,,,,,,,,,,,,,,,,,,,,
571.246,1.74732,1.04187,10,,,,,,,,,,,,,,,,,,,,,,,,,,,,,,,,,,,,,
572.246,1.73043,0.96127,10,,,,,,,,,,,,,,,,,,,,,,,,,,,,,,,,,,,,,
573.246,1.72777,1.01219,10,,,,,,,,,,,,,,,,,,,,,,,,,,,,,,,,,,,,,
574.246,1.72709,0.9785,10,,,,,,,,,,,,,,,,,,,,,,,,,,,,,,,,,,,,,
575.246,1.7268,0.91687,10,,,,,,,,,,,,,,,,,,,,,,,,,,,,,,,,,,,,,
576.246,1.72692,0.99545,10,,,,,,,,,,,,,,,,,,,,,,,,,,,,,,,,,,,,,
577.246,1.72697,1.04657,10,,,,,,,,,,,,,,,,,,,,,,,,,,,,,,,,,,,,,
578.246,1.72709,0.92964,10,,,,,,,,,,,,,,,,,,,,,,,,,,,,,,,,,,,,,
579.246,1.72726,0.97145,10,,,,,,,,,,,,,,,,,,,,,,,,,,,,,,,,,,,,,
580.246,1.72754,0.95808,10,,,,,,,,,,,,,,,,,,,,,,,,,,,,,,,,,,,,,
581.246,1.72811,0.9521,10,,,,,,,,,,,,,,,,,,,,,,,,,,,,,,,,,,,,,
582.246,1.72981,0.96559,10,,,,,,,,,,,,,,,,,,,,,,,,,,,,,,,,,,,,,
583.246,1.73451,0.96124,10,,,,,,,,,,,,,,,,,,,,,,,,,,,,,,,,,,,,,
584.246,1.74193,1.00253,10,,,,,,,,,,,,,,,,,,,,,,,,,,,,,,,,,,,,,
585.246,1.76896,1.06743,10,,,,,,,,,,,,,,,,,,,,,,,,,,,,,,,,,,,,,
586.246,1.77021,1.07495,10,,,,,,,,,,,,,,,,,,,,,,,,,,,,,,,,,,,,,
587.246,1.76998,1.06503,10,,,,,,,,,,,,,,,,,,,,,,,,,,,,,,,,,,,,,
588.246,1.7693,1.14748,10,,,,,,,,,,,,,,,,,,,,,,,,,,,,,,,,,,,,,
589.246,1.76103,1.09969,10,,,,,,,,,,,,,,,,,,,,,,,,,,,,,,,,,,,,,
590.246,1.7276,0.98142,10,,,,,,,,,,,,,,,,,,,,,,,,,,,,,,,,,,,,,
591.246,1.71626,0.9925,10,,,,,,,,,,,,,,,,,,,,,,,,,,,,,,,,,,,,,
592.246,1.71247,0.94094,10,,,,,,,,,,,,,,,,,,,,,,,,,,,,,,,,,,,,,
593.246,1.71207,0.96724,10,,,,,,,,,,,,,,,,,,,,,,,,,,,,,,,,,,,,,
594.246,1.71218,0.95835,10,,,,,,,,,,,,,,,,,,,,,,,,,,,,,,,,,,,,,
595.246,1.7123,1.00174,10,,,,,,,,,,,,,,,,,,,,,,,,,,,,,,,,,,,,,
596.246,1.71252,0.95074,10,,,,,,,,,,,,,,,,,,,,,,,,,,,,,,,,,,,,,
597.246,1.71286,0.9101,10,,,,,,,,,,,,,,,,,,,,,,,,,,,,,,,,,,,,,
598.246,1.71377,0.88353,10,,,,,,,,,,,,,,,,,,,,,,,,,,,,,,,,,,,,,
599.246,1.71887,0.91603,10,,,,,,,,,,,,,,,,,,,,,,,,,,,,,,,,,,,,,
600.246,1.75298,1.04578,10,,,,,,,,,,,,,,,,,,,,,,,,,,,,,,,,,,,,,
601.246,1.77763,1.08167,10,,,,,,,,,,,,,,,,,,,,,,,,,,,,,,,,,,,,,
602.246,1.77752,1.10081,10,,,,,,,,,,,,,,,,,,,,,,,,,,,,,,,,,,,,,
603.246,1.77712,1.15485,10,,,,,,,,,,,,,,,,,,,,,,,,,,,,,,,,,,,,,
604.246,1.77106,1.12443,10,,,,,,,,,,,,,,,,,,,,,,,,,,,,,,,,,,,,,
605.246,1.73411,0.98226,10,,,,,,,,,,,,,,,,,,,,,,,,,,,,,,,,,,,,,
606.246,1.71111,0.99806,10,,,,,,,,,,,,,,,,,,,,,,,,,,,,,,,,,,,,,
607.246,1.71065,0.9539,10,,,,,,,,,,,,,,,,,,,,,,,,,,,,,,,,,,,,,
608.246,1.71077,0.95647,10,,,,,,,,,,,,,,,,,,,,,,,,,,,,,,,,,,,,,
609.246,1.71099,0.93312,10,,,,,,,,,,,,,,,,,,,,,,,,,,,,,,,,,,,,,
610.246,1.71139,0.92391,10,,,,,,,,,,,,,,,,,,,,,,,,,,,,,,,,,,,,,
611.246,1.71235,0.93228,10,,,,,,,,,,,,,,,,,,,,,,,,,,,,,,,,,,,,,
612.246,1.71717,0.96002,10,,,,,,,,,,,,,,,,,,,,,,,,,,,,,,,,,,,,,
613.246,1.75689,0.99482,10,,,,,,,,,,,,,,,,,,,,,,,,,,,,,,,,,,,,,
614.246,1.78313,1.11487,10,,,,,,,,,,,,,,,,,,,,,,,,,,,,,,,,,,,,,
615.246,1.7829,1.15033,10,,,,,,,,,,,,,,,,,,,,,,,,,,,,,,,,,,,,,
616.246,1.78143,1.12583,10,,,,,,,,,,,,,,,,,,,,,,,,,,,,,,,,,,,,,
617.246,1.76341,1.07047,10,,,,,,,,,,,,,,,,,,,,,,,,,,,,,,,,,,,,,
618.246,1.71292,0.94403,10,,,,,,,,,,,,,,,,,,,,,,,,,,,,,,,,,,,,,
619.246,1.70289,0.93513,10,,,,,,,,,,,,,,,,,,,,,,,,,,,,,,,,,,,,,
620.246,1.70295,0.92832,10,,,,,,,,,,,,,,,,,,,,,,,,,,,,,,,,,,,,,
621.246,1.70317,0.98221,10,,,,,,,,,,,,,,,,,,,,,,,,,,,,,,,,,,,,,
622.246,1.70357,0.91137,10,,,,,,,,,,,,,,,,,,,,,,,,,,,,,,,,,,,,,
623.246,1.70448,0.89019,10,,,,,,,,,,,,,,,,,,,,,,,,,,,,,,,,,,,,,
624.246,1.70952,0.92248,10,,,,,,,,,,,,,,,,,,,,,,,,,,,,,,,,,,,,,
625.246,1.751,1.01907,10,,,,,,,,,,,,,,,,,,,,,,,,,,,,,,,,,,,,,
626.246,1.78279,1.11293,10,,,,,,,,,,,,,,,,,,,,,,,,,,,,,,,,,,,,,
627.246,1.78262,1.15869,10,,,,,,,,,,,,,,,,,,,,,,,,,,,,,,,,,,,,,
628.246,1.78171,1.18909,10,,,,,,,,,,,,,,,,,,,,,,,,,,,,,,,,,,,,,
629.246,1.7697,1.1117,10,,,,,,,,,,,,,,,,,,,,,,,,,,,,,,,,,,,,,
630.246,1.71626,0.93123,10,,,,,,,,,,,,,,,,,,,,,,,,,,,,,,,,,,,,,
631.246,1.70198,0.9212,10,,,,,,,,,,,,,,,,,,,,,,,,,,,,,,,,,,,,,
632.246,1.70204,0.93043,10,,,,,,,,,,,,,,,,,,,,,,,,,,,,,,,,,,,,,
633.246,1.70227,1.01484,10,,,,,,,,,,,,,,,,,,,,,,,,,,,,,,,,,,,,,
634.246,1.70266,0.89246,10,,,,,,,,,,,,,,,,,,,,,,,,,,,,,,,,,,,,,
635.246,1.70408,0.88351,10,,,,,,,,,,,,,,,,,,,,,,,,,,,,,,,,,,,,,
636.246,1.71428,0.92151,10,,,,,,,,,,,,,,,,,,,,,,,,,,,,,,,,,,,,,
637.246,1.77576,1.09725,10,,,,,,,,,,,,,,,,,,,,,,,,,,,,,,,,,,,,,
638.246,1.7871,1.12047,10,,,,,,,,,,,,,,,,,,,,,,,,,,,,,,,,,,,,,
639.246,1.78659,1.18888,10,,,,,,,,,,,,,,,,,,,,,,,,,,,,,,,,,,,,,
640.246,1.77735,1.14616,10,,,,,,,,,,,,,,,,,,,,,,,,,,,,,,,,,,,,,
641.246,1.72386,0.99421,10,,,,,,,,,,,,,,,,,,,,,,,,,,,,,,,,,,,,,
642.246,1.69898,0.9555,10,,,,,,,,,,,,,,,,,,,,,,,,,,,,,,,,,,,,,
643.246,1.69909,0.86882,10,,,,,,,,,,,,,,,,,,,,,,,,,,,,,,,,,,,,,
644.246,1.69932,0.94514,10,,,,,,,,,,,,,,,,,,,,,,,,,,,,,,,,,,,,,
645.246,1.69994,0.9359,10,,,,,,,,,,,,,,,,,,,,,,,,,,,,,,,,,,,,,
646.246,1.70221,0.8689,10,,,,,,,,,,,,,,,,,,,,,,,,,,,,,,,,,,,,,
647.246,1.71978,0.94182,10,,,,,,,,,,,,,,,,,,,,,,,,,,,,,,,,,,,,,
648.246,1.78676,1.1453,10,,,,,,,,,,,,,,,,,,,,,,,,,,,,,,,,,,,,,
649.246,1.78942,1.15957,10,,,,,,,,,,,,,,,,,,,,,,,,,,,,,,,,,,,,,
650.246,1.78795,1.19305,10,,,,,,,,,,,,,,,,,,,,,,,,,,,,,,,,,,,,,
651.246,1.76364,1.11976,10,,,,,,,,,,,,,,,,,,,,,,,,,,,,,,,,,,,,,
652.246,1.69904,0.91207,10,,,,,,,,,,,,,,,,,,,,,,,,,,,,,,,,,,,,,
653.246,1.69405,0.90827,10,,,,,,,,,,,,,,,,,,,,,,,,,,,,,,,,,,,,,
654.246,1.69428,0.93866,10,,,,,,,,,,,,,,,,,,,,,,,,,,,,,,,,,,,,,
655.246,1.69462,0.90872,10,,,,,,,,,,,,,,,,,,,,,,,,,,,,,,,,,,,,,
656.246,1.69575,0.86801,10,,,,,,,,,,,,,,,,,,,,,,,,,,,,,,,,,,,,,
657.246,1.70544,0.93367,10,,,,,,,,,,,,,,,,,,,,,,,,,,,,,,,,,,,,,
658.246,1.75412,1.04431,10,,,,,,,,,,,,,,,,,,,,,,,,,,,,,,,,,,,,,
659.246,1.7833,1.1443,10,,,,,,,,,,,,,,,,,,,,,,,,,,,,,,,,,,,,,
660.246,1.78302,1.17231,10,,,,,,,,,,,,,,,,,,,,,,,,,,,,,,,,,,,,,
661.246,1.78075,1.12878,10,,,,,,,,,,,,,,,,,,,,,,,,,,,,,,,,,,,,,
662.246,1.74199,1.03139,10,,,,,,,,,,,,,,,,,,,,,,,,,,,,,,,,,,,,,
663.246,1.69575,0.95976,10,,,,,,,,,,,,,,,,,,,,,,,,,,,,,,,,,,,,,
664.246,1.69439,0.87421,10,,,,,,,,,,,,,,,,,,,,,,,,,,,,,,,,,,,,,
665.246,1.69462,0.87638,10,,,,,,,,,,,,,,,,,,,,,,,,,,,,,,,,,,,,,
666.246,1.69507,0.85924,10,,,,,,,,,,,,,,,,,,,,,,,,,,,,,,,,,,,,,
667.246,1.69722,0.87154,10,,,,,,,,,,,,,,,,,,,,,,,,,,,,,,,,,,,,,
668.246,1.7119,0.94324,10,,,,,,,,,,,,,,,,,,,,,,,,,,,,,,,,,,,,,
669.246,1.78472,1.16839,10,,,,,,,,,,,,,,,,,,,,,,,,,,,,,,,,,,,,,
670.246,1.79135,1.19336,10,,,,,,,,,,,,,,,,,,,,,,,,,,,,,,,,,,,,,
671.246,1.79061,1.19204,10,,,,,,,,,,,,,,,,,,,,,,,,,,,,,,,,,,,,,
672.246,1.77548,1.15433,10,,,,,,,,,,,,,,,,,,,,,,,,,,,,,,,,,,,,,
673.246,1.70878,0.96321,10,,,,,,,,,,,,,,,,,,,,,,,,,,,,,,,,,,,,,
674.246,1.68974,0.95675,10,,,,,,,,,,,,,,,,,,,,,,,,,,,,,,,,,,,,,
675.246,1.68986,0.89775,10,,,,,,,,,,,,,,,,,,,,,,,,,,,,,,,,,,,,,
676.246,1.69008,0.93003,10,,,,,,,,,,,,,,,,,,,,,,,,,,,,,,,,,,,,,
677.246,1.69071,0.85861,10,,,,,,,,,,,,,,,,,,,,,,,,,,,,,,,,,,,,,
678.246,1.69399,0.90849,10,,,,,,,,,,,,,,,,,,,,,,,,,,,,,,,,,,,,,
679.246,1.71983,0.94824,10,,,,,,,,,,,,,,,,,,,,,,,,,,,,,,,,,,,,,
680.246,1.78738,1.12774,10,,,,,,,,,,,,,,,,,,,,,,,,,,,,,,,,,,,,,
681.246,1.78965,1.20797,10,,,,,,,,,,,,,,,,,,,,,,,,,,,,,,,,,,,,,
682.246,1.78766,1.13209,10,,,,,,,,,,,,,,,,,,,,,,,,,,,,,,,,,,,,,
683.148,3.19883,8.70527,10,,,,,,,,,,,,,,,,,,,,,,,,,,,,,,,,,,,,,
684.148,11.53983,322.93854,10,,,,,,,,,,,,,,,,,,,,,,,,,,,,,,,,,,,,,
685.148,19.87322,102.76348,10,,,,,,,,,,,,,,,,,,,,,,,,,,,,,,,,,,,,,
686.148,28.20646,11.27445,10,,,,,,,,,,,,,,,,,,,,,,,,,,,,,,,,,,,,,
687.148,36.53979,-0.32407,10,,,,,,,,,,,,,,,,,,,,,,,,,,,,,,,,,,,,,
688.148,44.87308,-0.44275,10,,,,,,,,,,,,,,,,,,,,,,,,,,,,,,,,,,,,,
688.902,51.15645,-0.44729,10,,,,,,,,,,,,,,,,,,,,,,,,,,,,,,,,,,,,,