File: combined_ligament_solver/data/processed/Data Sheet 3_S152678_PCL.csv
Specimen properties : Length,41,mm,Unnamed: 3,Unnamed: 4,Unnamed: 5,Unnamed: 6,Unnamed: 7,Unnamed: 8,Unnamed: 9,Unnamed: 10,Unnamed: 11,Stress-Strain,Unnamed: 13,Unnamed: 14,Unnamed: 15,Unnamed: 16,Unnamed: 17,Unnamed: 18,Unnamed: 19,Unnamed: 20,Unnamed: 21,Unnamed: 22,Unnamed: 23,Unnamed: 24,Unnamed: 25,Unnamed: 26,Unnamed: 27,Linear,Unnamed: 29,Unnamed: 30,Unnamed: 31,Unnamed: 32,Unnamed: 33,Modulus,Unnamed: 35,Failure,Unnamed: 37,Unnamed: 38,Unnamed: 39,Unnamed: 40
Cross Section Average,62.5115,mm2,,,,,,,,,,Polynomial Coefficients,,,,,,,,,,,,,,,,Force,,Stress,Extension,Strain,,Secant,Tangent,Load,Stress,Extension,Strain,Stiffness
Time,Extension,Load,Total cycle count,,,Extension,Load,Strain,Stress,E-tan,,X6,-485295.7056152318,,,,,,,,,Strain,Stress,E-tan,,,,(N),,(MPa),(mm),(%),,(MPa),(MPa),(N),(MPa),(mm),(%),(N/mm)
(s),(mm),(N),,,,(mm),(N),(mm/mm),(MPa),(MPa),,X5,296242.00991801673,,,,,,,,,(mm/mm),(MPa),(MPa),,,,327.81517461112844,,5.244077883447501,6.232,15.2,,34.50051239110198,52.601892286018476,497.58783,7.9460611247530455,8.91695,21.748658536585367,52.601921471618816
0.6,0.2597,1.60269,0,,,6.00593,211.74179,0.11585975609756098,3.373365860681635,51.247490474946204,,,,,,,,,,,,0.006,0.02167887818888998,3.9186586208028964,,,,,,,,,,,,,,,,
1.3,0.37627,2.36116,0,,,11.83925,524.82947,,,,,,,,,,,,,,,0.013,0.05634477237870754,5.917743880288481,,,,,,,,,,,,,,,,
2,0.49294,3.11421,0,,,17.67263,76.68029,,,,,,,,,,,,,,,0.02,0.10970082783962658,9.029872917194153,,,,,,,,,,,,,,,,
2.7,0.60962,3.95365,0,,,23.50601,13.56675,,,,,,,,,,,,,,,0.027,0.1879319410614788,12.86371898658155,,,,,,,,,,,,,,,,
3.4,0.7263,4.85158,0,,,,,,,,,,,,,,,,,,,0.034,0.29476305272209474,17.09694925376197,,,,,,,,,,,,,,,,
4.1,0.84303,5.76969,0,,,,,,,,,,,,,,,,,,,0.041,0.4319186147280676,21.470352211550395,,,,,,,,,,,,,,,,
4.8,0.95959,6.77172,0,,,,,,,,,,,,,,,,,,,0.048,0.5995409491762996,25.781965097520597,,,,,,,,,,,,,,,,
5.5,1.07627,7.83948,0,,,,,,,,,,,,,,,,,,,0.055,0.7965674992363296,29.88120131125935,,,,,,,,,,,,,,,,
6.2,1.193,9.03222,0,,,,,,,,,,,,,,,,,,,0.062,1.021066971953442,33.662977831620275,,,,,,,,,,,,,,,,
6.9,1.30968,10.31193,0,,,,,,,,,,,,,,,,,,,0.069,1.2705343729725584,37.06184263398012,,,,,,,,,,,,,,,,
7.6,1.42636,11.59575,0,,,,,,,,,,,,,,,,,,,0.076,1.5421449331829098,40.04610210749267,,,,,,,,,,,,,,,,
8.3,1.54303,13.14022,0,,,,,,,,,,,,,,,,,,,0.083,1.8329669272834894,42.611948472340806,,,,,,,,,,,,,,,,
9,1.65971,14.72522,0,,,,,,,,,,,,,,,,,,,0.09,2.1401333842692907,44.77758719699394,,,,,,,,,,,,,,,,
9.7,1.77644,16.39108,0,,,,,,,,,,,,,,,,,,,0.097,2.460972689838327,46.57736441546319,,,,,,,,,,,,,,,,
10.4,1.89318,18.28673,0,,,,,,,,,,,,,,,,,,,0.104,2.793098080719421,48.05589434455189,,,,,,,,,,,,,,,,
11.1,2.00974,20.27963,0,,,,,,,,,,,,,,,,,,,0.111,3.134456030920797,49.262186701112434,,,,,,,,,,,,,,,,
11.8,2.12642,22.50702,0,,,,,,,,,,,,,,,,,,,0.118,3.4833335298994426,50.243774119306245,,,,,,,,,,,,,,,,
12.5,2.24298,24.90085,0,,,,,,,,,,,,,,,,,,,0.125,3.8383242526512418,51.040839567846724,,,,,,,,,,,,,,,,
13.2,2.35966,27.46156,0,,,,,,,,,,,,,,,,,,,0.132,4.198253621721911,51.680343767261,,,,,,,,,,,,,,,,
13.9,2.47628,30.24134,0,,,,,,,,,,,,,,,,,,,0.139,4.562062761138704,52.170152607149355,,,,,,,,,,,,,,,,
14.6,2.59307,33.2244,0,,,,,,,,,,,,,,,,,,,0.146,4.928651342262898,52.49316456341541,,,,,,,,,,,,,,,,
15.3,2.70963,36.39363,0,,,,,,,,,,,,,,,,,,,0.153,5.296679321563066,52.60143811556523,,,,,,,,,,,,,,,,
16,2.82631,39.73729,0,,,,,,,,,,,,,,,,,,,0.16,5.66432757030915,52.41031916393796,,,,,,,,,,,,,,,,
16.57,2.7544,35.52769,0.5,,,,,,,,,,,,,,,,,,,0.167,6.029017396187239,51.792568446910664,,,,,,,,,,,,,,,,
17.27,2.63778,30.16004,0.5,,,,,,,,,,,,,,,,,,,0.174,6.387088956835257,50.57248895826211,,,,,,,,,,,,,,,,
17.97,2.52116,25.68999,0.5,,,,,,,,,,,,,,,,,,,0.181,6.733438565299291,48.52005336431903,,,,,,,,,,,,,,,,
18.67,2.40442,21.94822,0.5,,,,,,,,,,,,,,,,,,,0.188,7.061114887410835,45.34503142126484,,,,,,,,,,,,,,,,
19.37,2.28769,18.61578,0.5,,,,,,,,,,,,,,,,,,,0.195,7.360874031084705,40.69111739243776,,,,,,,,,,,,,,,,
20.07,2.17101,15.69828,0.5,,,,,,,,,,,,,,,,,,,,,,,,,,,,,,,,,,,,,
20.77,2.05434,13.24428,0.5,,,,,,,,,,,,,,,,,,,,,,,,,,,,,,,,,,,,,
21.47,1.93766,11.06215,0.5,,,,,,,,,,,,,,,,,,,,,,,,,,,,,,,,,,,,,
22.17,1.82093,9.21869,0.5,,,,,,,,,,,,,,,,,,,,,,,,,,,,,,,,,,,,,
22.87,1.70425,7.49983,0.5,,,,,,,,,,,,,,,,,,,,,,,,,,,,,,,,,,,,,
23.57,1.58757,6.0107,0.5,,,,,,,,,,,,,,,,,,,,,,,,,,,,,,,,,,,,,
24.27,1.47095,4.76833,0.5,,,,,,,,,,,,,,,,,,,,,,,,,,,,,,,,,,,,,
24.97,1.35433,3.65858,0.5,,,,,,,,,,,,,,,,,,,,,,,,,,,,,,,,,,,,,
25.67,1.23771,2.68101,0.5,,,,,,,,,,,,,,,,,,,,,,,,,,,,,,,,,,,,,
26.37,1.12104,1.90291,0.5,,,,,,,,,,,,,,,,,,,,,,,,,,,,,,,,,,,,,
27.07,1.00436,1.1928,0.5,,,,,,,,,,,,,,,,,,,,,,,,,,,,,,,,,,,,,
27.542,0.99297,1.17086,1,,,,,,,,,,,,,,,,,,,,,,,,,,,,,,,,,,,,,
28.242,1.10993,2.18065,1,,,,,,,,,,,,,,,,,,,,,,,,,,,,,,,,,,,,,
28.942,1.22655,3.2516,1,,,,,,,,,,,,,,,,,,,,,,,,,,,,,,,,,,,,,
29.642,1.34334,4.38439,1,,,,,,,,,,,,,,,,,,,,,,,,,,,,,,,,,,,,,
30.342,1.46002,5.64036,1,,,,,,,,,,,,,,,,,,,,,,,,,,,,,,,,,,,,,
31.042,1.57669,7.084,1,,,,,,,,,,,,,,,,,,,,,,,,,,,,,,,,,,,,,
31.742,1.69326,8.66011,1,,,,,,,,,,,,,,,,,,,,,,,,,,,,,,,,,,,,,
32.442,1.80988,10.42871,1,,,,,,,,,,,,,,,,,,,,,,,,,,,,,,,,,,,,,
33.142,1.92661,12.41626,1,,,,,,,,,,,,,,,,,,,,,,,,,,,,,,,,,,,,,
33.842,2.04329,14.63388,1,,,,,,,,,,,,,,,,,,,,,,,,,,,,,,,,,,,,,
34.542,2.15996,17.10021,1,,,,,,,,,,,,,,,,,,,,,,,,,,,,,,,,,,,,,
35.242,2.27664,19.92532,1,,,,,,,,,,,,,,,,,,,,,,,,,,,,,,,,,,,,,
35.942,2.39332,22.88898,1,,,,,,,,,,,,,,,,,,,,,,,,,,,,,,,,,,,,,
36.642,2.51011,26.13741,1,,,,,,,,,,,,,,,,,,,,,,,,,,,,,,,,,,,,,
37.342,2.62678,29.71706,1,,,,,,,,,,,,,,,,,,,,,,,,,,,,,,,,,,,,,
38.042,2.74346,33.5831,1,,,,,,,,,,,,,,,,,,,,,,,,,,,,,,,,,,,,,
38.742,2.86002,37.61223,1,,,,,,,,,,,,,,,,,,,,,,,,,,,,,,,,,,,,,
39.268,2.91862,39.75906,1.5,,,,,,,,,,,,,,,,,,,,,,,,,,,,,,,,,,,,,
39.968,2.79746,33.21305,1.5,,,,,,,,,,,,,,,,,,,,,,,,,,,,,,,,,,,,,
40.668,2.68079,28.2503,1.5,,,,,,,,,,,,,,,,,,,,,,,,,,,,,,,,,,,,,
41.368,2.564,24.10899,1.5,,,,,,,,,,,,,,,,,,,,,,,,,,,,,,,,,,,,,
42.068,2.44732,20.44936,1.5,,,,,,,,,,,,,,,,,,,,,,,,,,,,,,,,,,,,,
42.768,2.33059,17.37525,1.5,,,,,,,,,,,,,,,,,,,,,,,,,,,,,,,,,,,,,
43.468,2.21391,14.60723,1.5,,,,,,,,,,,,,,,,,,,,,,,,,,,,,,,,,,,,,
44.168,2.09723,12.20094,1.5,,,,,,,,,,,,,,,,,,,,,,,,,,,,,,,,,,,,,
44.868,1.98061,10.13621,1.5,,,,,,,,,,,,,,,,,,,,,,,,,,,,,,,,,,,,,
45.568,1.86405,8.3073,1.5,,,,,,,,,,,,,,,,,,,,,,,,,,,,,,,,,,,,,
46.268,1.74737,6.7472,1.5,,,,,,,,,,,,,,,,,,,,,,,,,,,,,,,,,,,,,
46.968,1.6307,5.31572,1.5,,,,,,,,,,,,,,,,,,,,,,,,,,,,,,,,,,,,,
47.668,1.51402,4.14021,1.5,,,,,,,,,,,,,,,,,,,,,,,,,,,,,,,,,,,,,
48.368,1.3974,3.04855,1.5,,,,,,,,,,,,,,,,,,,,,,,,,,,,,,,,,,,,,
49.068,1.28078,2.16933,1.5,,,,,,,,,,,,,,,,,,,,,,,,,,,,,,,,,,,,,
49.768,1.16399,1.38779,1.5,,,,,,,,,,,,,,,,,,,,,,,,,,,,,,,,,,,,,
50.242,1.085,0.99301,2,,,,,,,,,,,,,,,,,,,,,,,,,,,,,,,,,,,,,
50.942,1.20269,1.96567,2,,,,,,,,,,,,,,,,,,,,,,,,,,,,,,,,,,,,,
51.642,1.31943,2.98154,2,,,,,,,,,,,,,,,,,,,,,,,,,,,,,,,,,,,,,
52.342,1.4361,4.13333,2,,,,,,,,,,,,,,,,,,,,,,,,,,,,,,,,,,,,,
53.042,1.55278,5.44459,2,,,,,,,,,,,,,,,,,,,,,,,,,,,,,,,,,,,,,
53.742,1.6694,6.87248,2,,,,,,,,,,,,,,,,,,,,,,,,,,,,,,,,,,,,,
54.442,1.78608,8.48773,2,,,,,,,,,,,,,,,,,,,,,,,,,,,,,,,,,,,,,
55.142,1.90275,10.29638,2,,,,,,,,,,,,,,,,,,,,,,,,,,,,,,,,,,,,,
55.842,2.01932,12.28009,2,,,,,,,,,,,,,,,,,,,,,,,,,,,,,,,,,,,,,
56.542,2.13599,14.63174,2,,,,,,,,,,,,,,,,,,,,,,,,,,,,,,,,,,,,,
57.242,2.25261,17.15122,2,,,,,,,,,,,,,,,,,,,,,,,,,,,,,,,,,,,,,
57.942,2.36929,19.99007,2,,,,,,,,,,,,,,,,,,,,,,,,,,,,,,,,,,,,,
58.642,2.48597,23.1585,2,,,,,,,,,,,,,,,,,,,,,,,,,,,,,,,,,,,,,
59.342,2.60264,26.58968,2,,,,,,,,,,,,,,,,,,,,,,,,,,,,,,,,,,,,,
60.042,2.71921,30.40784,2,,,,,,,,,,,,,,,,,,,,,,,,,,,,,,,,,,,,,
60.742,2.83588,34.53609,2,,,,,,,,,,,,,,,,,,,,,,,,,,,,,,,,,,,,,
61.442,2.95256,38.78859,2,,,,,,,,,,,,,,,,,,,,,,,,,,,,,,,,,,,,,
62.034,2.91777,36.50233,2.5,,,,,,,,,,,,,,,,,,,,,,,,,,,,,,,,,,,,,
62.734,2.80115,31.01206,2.5,,,,,,,,,,,,,,,,,,,,,,,,,,,,,,,,,,,,,
63.434,2.68441,26.43423,2.5,,,,,,,,,,,,,,,,,,,,,,,,,,,,,,,,,,,,,
64.134,2.56774,22.51593,2.5,,,,,,,,,,,,,,,,,,,,,,,,,,,,,,,,,,,,,
64.834,2.45106,19.08035,2.5,,,,,,,,,,,,,,,,,,,,,,,,,,,,,,,,,,,,,
65.534,2.33427,16.05419,2.5,,,,,,,,,,,,,,,,,,,,,,,,,,,,,,,,,,,,,
66.234,2.21765,13.47899,2.5,,,,,,,,,,,,,,,,,,,,,,,,,,,,,,,,,,,,,
66.934,2.10092,11.15606,2.5,,,,,,,,,,,,,,,,,,,,,,,,,,,,,,,,,,,,,
67.634,1.98424,9.18446,2.5,,,,,,,,,,,,,,,,,,,,,,,,,,,,,,,,,,,,,
68.334,1.86756,7.46803,2.5,,,,,,,,,,,,,,,,,,,,,,,,,,,,,,,,,,,,,
69.034,1.751,5.94855,2.5,,,,,,,,,,,,,,,,,,,,,,,,,,,,,,,,,,,,,
69.734,1.63432,4.6389,2.5,,,,,,,,,,,,,,,,,,,,,,,,,,,,,,,,,,,,,
70.434,1.5177,3.53135,2.5,,,,,,,,,,,,,,,,,,,,,,,,,,,,,,,,,,,,,
71.134,1.40108,2.5159,2.5,,,,,,,,,,,,,,,,,,,,,,,,,,,,,,,,,,,,,
71.834,1.28441,1.70397,2.5,,,,,,,,,,,,,,,,,,,,,,,,,,,,,,,,,,,,,
72.51,1.17175,0.99974,3,,,,,,,,,,,,,,,,,,,,,,,,,,,,,,,,,,,,,
73.014,1.25539,1.68212,3,,,,,,,,,,,,,,,,,,,,,,,,,,,,,,,,,,,,,
73.714,1.37201,2.77039,3,,,,,,,,,,,,,,,,,,,,,,,,,,,,,,,,,,,,,
74.414,1.48869,3.86898,3,,,,,,,,,,,,,,,,,,,,,,,,,,,,,,,,,,,,,
75.114,1.60537,5.2274,3,,,,,,,,,,,,,,,,,,,,,,,,,,,,,,,,,,,,,
75.814,1.72204,6.67009,3,,,,,,,,,,,,,,,,,,,,,,,,,,,,,,,,,,,,,
76.514,1.83883,8.32146,3,,,,,,,,,,,,,,,,,,,,,,,,,,,,,,,,,,,,,
77.214,1.9554,10.11696,3,,,,,,,,,,,,,,,,,,,,,,,,,,,,,,,,,,,,,
77.914,2.07202,12.12545,3,,,,,,,,,,,,,,,,,,,,,,,,,,,,,,,,,,,,,
78.614,2.18864,14.49902,3,,,,,,,,,,,,,,,,,,,,,,,,,,,,,,,,,,,,,
79.314,2.30531,17.04905,3,,,,,,,,,,,,,,,,,,,,,,,,,,,,,,,,,,,,,
80.014,2.42199,19.96523,3,,,,,,,,,,,,,,,,,,,,,,,,,,,,,,,,,,,,,
80.714,2.53867,23.18392,3,,,,,,,,,,,,,,,,,,,,,,,,,,,,,,,,,,,,,
81.414,2.65534,26.71028,3,,,,,,,,,,,,,,,,,,,,,,,,,,,,,,,,,,,,,
82.114,2.77191,30.58386,3,,,,,,,,,,,,,,,,,,,,,,,,,,,,,,,,,,,,,
82.814,2.88858,34.87498,3,,,,,,,,,,,,,,,,,,,,,,,,,,,,,,,,,,,,,
83.514,3.00532,39.37933,3,,,,,,,,,,,,,,,,,,,,,,,,,,,,,,,,,,,,,
84.102,2.93641,35.73846,3.5,,,,,,,,,,,,,,,,,,,,,,,,,,,,,,,,,,,,,
84.802,2.81973,30.40188,3.5,,,,,,,,,,,,,,,,,,,,,,,,,,,,,,,,,,,,,
85.502,2.70311,25.8212,3.5,,,,,,,,,,,,,,,,,,,,,,,,,,,,,,,,,,,,,
86.202,2.58649,21.98746,3.5,,,,,,,,,,,,,,,,,,,,,,,,,,,,,,,,,,,,,
86.902,2.46976,18.56982,3.5,,,,,,,,,,,,,,,,,,,,,,,,,,,,,,,,,,,,,
87.602,2.35303,15.62803,3.5,,,,,,,,,,,,,,,,,,,,,,,,,,,,,,,,,,,,,
88.302,2.23641,13.0587,3.5,,,,,,,,,,,,,,,,,,,,,,,,,,,,,,,,,,,,,
89.002,2.11973,10.84654,3.5,,,,,,,,,,,,,,,,,,,,,,,,,,,,,,,,,,,,,
89.702,2.00311,8.89362,3.5,,,,,,,,,,,,,,,,,,,,,,,,,,,,,,,,,,,,,
90.402,1.88643,7.18432,3.5,,,,,,,,,,,,,,,,,,,,,,,,,,,,,,,,,,,,,
91.102,1.76964,5.67228,3.5,,,,,,,,,,,,,,,,,,,,,,,,,,,,,,,,,,,,,
91.802,1.65291,4.39434,3.5,,,,,,,,,,,,,,,,,,,,,,,,,,,,,,,,,,,,,
92.502,1.53623,3.32115,3.5,,,,,,,,,,,,,,,,,,,,,,,,,,,,,,,,,,,,,
93.202,1.41956,2.3484,3.5,,,,,,,,,,,,,,,,,,,,,,,,,,,,,,,,,,,,,
93.902,1.30294,1.53519,3.5,,,,,,,,,,,,,,,,,,,,,,,,,,,,,,,,,,,,,
94.4,1.22003,0.99042,4,,,,,,,,,,,,,,,,,,,,,,,,,,,,,,,,,,,,,
95.1,1.33762,1.99037,4,,,,,,,,,,,,,,,,,,,,,,,,,,,,,,,,,,,,,
95.8,1.45429,3.07994,4,,,,,,,,,,,,,,,,,,,,,,,,,,,,,,,,,,,,,
96.5,1.57097,4.22901,4,,,,,,,,,,,,,,,,,,,,,,,,,,,,,,,,,,,,,
97.2,1.6877,5.67742,4,,,,,,,,,,,,,,,,,,,,,,,,,,,,,,,,,,,,,
97.9,1.80427,7.17705,4,,,,,,,,,,,,,,,,,,,,,,,,,,,,,,,,,,,,,
98.6,1.921,8.85779,4,,,,,,,,,,,,,,,,,,,,,,,,,,,,,,,,,,,,,
99.3,2.03751,10.75122,4,,,,,,,,,,,,,,,,,,,,,,,,,,,,,,,,,,,,,
100,2.15424,12.94216,4,,,,,,,,,,,,,,,,,,,,,,,,,,,,,,,,,,,,,
100.7,2.27097,15.43783,4,,,,,,,,,,,,,,,,,,,,,,,,,,,,,,,,,,,,,
101.4,2.38771,18.12766,4,,,,,,,,,,,,,,,,,,,,,,,,,,,,,,,,,,,,,
102.1,2.50438,21.21417,4,,,,,,,,,,,,,,,,,,,,,,,,,,,,,,,,,,,,,
102.8,2.62106,24.55836,4,,,,,,,,,,,,,,,,,,,,,,,,,,,,,,,,,,,,,
103.5,2.73774,28.30181,4,,,,,,,,,,,,,,,,,,,,,,,,,,,,,,,,,,,,,
104.2,2.85441,32.48227,4,,,,,,,,,,,,,,,,,,,,,,,,,,,,,,,,,,,,,
104.9,2.97109,36.95173,4,,,,,,,,,,,,,,,,,,,,,,,,,,,,,,,,,,,,,
105.464,3.03586,39.79541,4.5,,,,,,,,,,,,,,,,,,,,,,,,,,,,,,,,,,,,,
106.164,2.91471,33.2924,4.5,,,,,,,,,,,,,,,,,,,,,,,,,,,,,,,,,,,,,
106.864,2.79809,28.35177,4.5,,,,,,,,,,,,,,,,,,,,,,,,,,,,,,,,,,,,,
107.564,2.68141,24.12205,4.5,,,,,,,,,,,,,,,,,,,,,,,,,,,,,,,,,,,,,
108.264,2.56473,20.42609,4.5,,,,,,,,,,,,,,,,,,,,,,,,,,,,,,,,,,,,,
108.964,2.448,17.18262,4.5,,,,,,,,,,,,,,,,,,,,,,,,,,,,,,,,,,,,,
109.664,2.33121,14.41558,4.5,,,,,,,,,,,,,,,,,,,,,,,,,,,,,,,,,,,,,
110.364,2.21459,12.04898,4.5,,,,,,,,,,,,,,,,,,,,,,,,,,,,,,,,,,,,,
111.064,2.09791,9.87328,4.5,,,,,,,,,,,,,,,,,,,,,,,,,,,,,,,,,,,,,
111.764,1.98129,8.03409,4.5,,,,,,,,,,,,,,,,,,,,,,,,,,,,,,,,,,,,,
112.464,1.86467,6.43949,4.5,,,,,,,,,,,,,,,,,,,,,,,,,,,,,,,,,,,,,
113.164,1.748,5.05758,4.5,,,,,,,,,,,,,,,,,,,,,,,,,,,,,,,,,,,,,
113.864,1.63132,3.82754,4.5,,,,,,,,,,,,,,,,,,,,,,,,,,,,,,,,,,,,,
114.564,1.5147,2.812,4.5,,,,,,,,,,,,,,,,,,,,,,,,,,,,,,,,,,,,,
115.264,1.39814,1.86496,4.5,,,,,,,,,,,,,,,,,,,,,,,,,,,,,,,,,,,,,
115.964,1.28146,1.16449,4.5,,,,,,,,,,,,,,,,,,,,,,,,,,,,,,,,,,,,,
116.456,1.33365,1.57005,5,,,,,,,,,,,,,,,,,,,,,,,,,,,,,,,,,,,,,
117.156,1.45038,2.63377,5,,,,,,,,,,,,,,,,,,,,,,,,,,,,,,,,,,,,,
117.856,1.567,3.82472,5,,,,,,,,,,,,,,,,,,,,,,,,,,,,,,,,,,,,,
118.556,1.68368,5.09516,5,,,,,,,,,,,,,,,,,,,,,,,,,,,,,,,,,,,,,
119.256,1.80019,6.63263,5,,,,,,,,,,,,,,,,,,,,,,,,,,,,,,,,,,,,,
119.956,1.91692,8.25862,5,,,,,,,,,,,,,,,,,,,,,,,,,,,,,,,,,,,,,
120.656,2.03365,10.15683,5,,,,,,,,,,,,,,,,,,,,,,,,,,,,,,,,,,,,,
121.356,2.15033,12.26161,5,,,,,,,,,,,,,,,,,,,,,,,,,,,,,,,,,,,,,
122.056,2.26695,14.60195,5,,,,,,,,,,,,,,,,,,,,,,,,,,,,,,,,,,,,,
122.756,2.38357,17.27431,5,,,,,,,,,,,,,,,,,,,,,,,,,,,,,,,,,,,,,
123.456,2.50025,20.2522,5,,,,,,,,,,,,,,,,,,,,,,,,,,,,,,,,,,,,,
124.156,2.61704,23.60258,5,,,,,,,,,,,,,,,,,,,,,,,,,,,,,,,,,,,,,
124.856,2.73371,27.29391,5,,,,,,,,,,,,,,,,,,,,,,,,,,,,,,,,,,,,,
125.556,2.85039,31.38024,5,,,,,,,,,,,,,,,,,,,,,,,,,,,,,,,,,,,,,
126.256,2.96707,35.83983,5,,,,,,,,,,,,,,,,,,,,,,,,,,,,,,,,,,,,,
126.872,3.06969,40.0076,5.5,,,,,,,,,,,,,,,,,,,,,,,,,,,,,,,,,,,,,
127.474,2.96973,34.91283,5.5,,,,,,,,,,,,,,,,,,,,,,,,,,,,,,,,,,,,,
128.174,2.85305,29.68092,5.5,,,,,,,,,,,,,,,,,,,,,,,,,,,,,,,,,,,,,
128.874,2.73638,25.22041,5.5,,,,,,,,,,,,,,,,,,,,,,,,,,,,,,,,,,,,,
129.574,2.6197,21.40183,5.5,,,,,,,,,,,,,,,,,,,,,,,,,,,,,,,,,,,,,
130.274,2.50291,18.0845,5.5,,,,,,,,,,,,,,,,,,,,,,,,,,,,,,,,,,,,,
130.974,2.38623,15.18187,5.5,,,,,,,,,,,,,,,,,,,,,,,,,,,,,,,,,,,,,
131.674,2.26961,12.62819,5.5,,,,,,,,,,,,,,,,,,,,,,,,,,,,,,,,,,,,,
132.374,2.15294,10.39782,5.5,,,,,,,,,,,,,,,,,,,,,,,,,,,,,,,,,,,,,
133.074,2.03632,8.47586,5.5,,,,,,,,,,,,,,,,,,,,,,,,,,,,,,,,,,,,,
133.774,1.9197,6.85444,5.5,,,,,,,,,,,,,,,,,,,,,,,,,,,,,,,,,,,,,
134.474,1.80296,5.31458,5.5,,,,,,,,,,,,,,,,,,,,,,,,,,,,,,,,,,,,,
135.174,1.68634,4.0876,5.5,,,,,,,,,,,,,,,,,,,,,,,,,,,,,,,,,,,,,
135.874,1.56978,2.97983,5.5,,,,,,,,,,,,,,,,,,,,,,,,,,,,,,,,,,,,,
136.574,1.4531,2.03305,5.5,,,,,,,,,,,,,,,,,,,,,,,,,,,,,,,,,,,,,
137.274,1.33643,1.2374,5.5,,,,,,,,,,,,,,,,,,,,,,,,,,,,,,,,,,,,,
137.728,1.32798,1.25841,6,,,,,,,,,,,,,,,,,,,,,,,,,,,,,,,,,,,,,
138.428,1.44506,2.31181,6,,,,,,,,,,,,,,,,,,,,,,,,,,,,,,,,,,,,,
139.128,1.56168,3.50901,6,,,,,,,,,,,,,,,,,,,,,,,,,,,,,,,,,,,,,
139.828,1.6783,4.76843,6,,,,,,,,,,,,,,,,,,,,,,,,,,,,,,,,,,,,,
140.528,1.79503,6.17064,6,,,,,,,,,,,,,,,,,,,,,,,,,,,,,,,,,,,,,
141.228,1.91165,7.82048,6,,,,,,,,,,,,,,,,,,,,,,,,,,,,,,,,,,,,,
141.928,2.02827,9.64733,6,,,,,,,,,,,,,,,,,,,,,,,,,,,,,,,,,,,,,
142.628,2.14495,11.64653,6,,,,,,,,,,,,,,,,,,,,,,,,,,,,,,,,,,,,,
143.328,2.26162,13.97987,6,,,,,,,,,,,,,,,,,,,,,,,,,,,,,,,,,,,,,
144.028,2.3783,16.65533,6,,,,,,,,,,,,,,,,,,,,,,,,,,,,,,,,,,,,,
144.728,2.49498,19.63642,6,,,,,,,,,,,,,,,,,,,,,,,,,,,,,,,,,,,,,
145.428,2.6116,22.8314,6,,,,,,,,,,,,,,,,,,,,,,,,,,,,,,,,,,,,,
146.128,2.72822,26.45167,6,,,,,,,,,,,,,,,,,,,,,,,,,,,,,,,,,,,,,
146.828,2.84501,30.45025,6,,,,,,,,,,,,,,,,,,,,,,,,,,,,,,,,,,,,,
147.528,2.96174,34.86889,6,,,,,,,,,,,,,,,,,,,,,,,,,,,,,,,,,,,,,
148.228,3.07842,39.59702,6,,,,,,,,,,,,,,,,,,,,,,,,,,,,,,,,,,,,,
148.792,3.00526,35.76879,6.5,,,,,,,,,,,,,,,,,,,,,,,,,,,,,,,,,,,,,
149.492,2.8887,30.47436,6.5,,,,,,,,,,,,,,,,,,,,,,,,,,,,,,,,,,,,,
150.192,2.77202,25.86182,6.5,,,,,,,,,,,,,,,,,,,,,,,,,,,,,,,,,,,,,
150.892,2.65534,21.91484,6.5,,,,,,,,,,,,,,,,,,,,,,,,,,,,,,,,,,,,,
151.592,2.53867,18.50343,6.5,,,,,,,,,,,,,,,,,,,,,,,,,,,,,,,,,,,,,
152.292,2.42205,15.5151,6.5,,,,,,,,,,,,,,,,,,,,,,,,,,,,,,,,,,,,,
152.992,2.30543,12.94125,6.5,,,,,,,,,,,,,,,,,,,,,,,,,,,,,,,,,,,,,
153.692,2.18875,10.67979,6.5,,,,,,,,,,,,,,,,,,,,,,,,,,,,,,,,,,,,,
154.392,2.07202,8.72104,6.5,,,,,,,,,,,,,,,,,,,,,,,,,,,,,,,,,,,,,
155.092,1.9554,7.01103,6.5,,,,,,,,,,,,,,,,,,,,,,,,,,,,,,,,,,,,,
155.792,1.83872,5.50175,6.5,,,,,,,,,,,,,,,,,,,,,,,,,,,,,,,,,,,,,
156.492,1.7221,4.19251,6.5,,,,,,,,,,,,,,,,,,,,,,,,,,,,,,,,,,,,,
157.192,1.60537,3.09212,6.5,,,,,,,,,,,,,,,,,,,,,,,,,,,,,,,,,,,,,
157.892,1.48869,2.14551,6.5,,,,,,,,,,,,,,,,,,,,,,,,,,,,,,,,,,,,,
158.592,1.37196,1.36102,6.5,,,,,,,,,,,,,,,,,,,,,,,,,,,,,,,,,,,,,
159.094,1.35547,1.22965,7,,,,,,,,,,,,,,,,,,,,,,,,,,,,,,,,,,,,,
159.794,1.4726,2.31014,7,,,,,,,,,,,,,,,,,,,,,,,,,,,,,,,,,,,,,
160.494,1.58927,3.53974,7,,,,,,,,,,,,,,,,,,,,,,,,,,,,,,,,,,,,,
161.194,1.70595,4.77029,7,,,,,,,,,,,,,,,,,,,,,,,,,,,,,,,,,,,,,
161.894,1.82263,6.22496,7,,,,,,,,,,,,,,,,,,,,,,,,,,,,,,,,,,,,,
162.594,1.9393,7.85645,7,,,,,,,,,,,,,,,,,,,,,,,,,,,,,,,,,,,,,
163.294,2.05609,9.70901,7,,,,,,,,,,,,,,,,,,,,,,,,,,,,,,,,,,,,,
163.994,2.17283,11.76016,7,,,,,,,,,,,,,,,,,,,,,,,,,,,,,,,,,,,,,
164.694,2.28945,14.17991,7,,,,,,,,,,,,,,,,,,,,,,,,,,,,,,,,,,,,,
165.394,2.40607,16.79353,7,,,,,,,,,,,,,,,,,,,,,,,,,,,,,,,,,,,,,
166.094,2.52269,19.78714,7,,,,,,,,,,,,,,,,,,,,,,,,,,,,,,,,,,,,,
166.794,2.63936,23.04408,7,,,,,,,,,,,,,,,,,,,,,,,,,,,,,,,,,,,,,
167.494,2.75604,26.7519,7,,,,,,,,,,,,,,,,,,,,,,,,,,,,,,,,,,,,,
168.194,2.87272,30.78815,7,,,,,,,,,,,,,,,,,,,,,,,,,,,,,,,,,,,,,
168.894,2.98934,35.25183,7,,,,,,,,,,,,,,,,,,,,,,,,,,,,,,,,,,,,,
169.588,3.10494,40.00944,7.5,,,,,,,,,,,,,,,,,,,,,,,,,,,,,,,,,,,,,
170.19,3.00492,34.95812,7.5,,,,,,,,,,,,,,,,,,,,,,,,,,,,,,,,,,,,,
170.89,2.88836,29.7387,7.5,,,,,,,,,,,,,,,,,,,,,,,,,,,,,,,,,,,,,
171.59,2.77168,25.17829,7.5,,,,,,,,,,,,,,,,,,,,,,,,,,,,,,,,,,,,,
172.29,2.655,21.39627,7.5,,,,,,,,,,,,,,,,,,,,,,,,,,,,,,,,,,,,,
172.99,2.53833,18.02386,7.5,,,,,,,,,,,,,,,,,,,,,,,,,,,,,,,,,,,,,
173.69,2.42171,15.13166,7.5,,,,,,,,,,,,,,,,,,,,,,,,,,,,,,,,,,,,,
174.39,2.30509,12.54171,7.5,,,,,,,,,,,,,,,,,,,,,,,,,,,,,,,,,,,,,
175.09,2.18841,10.28475,7.5,,,,,,,,,,,,,,,,,,,,,,,,,,,,,,,,,,,,,
175.79,2.07168,8.39548,7.5,,,,,,,,,,,,,,,,,,,,,,,,,,,,,,,,,,,,,
176.49,1.95506,6.74598,7.5,,,,,,,,,,,,,,,,,,,,,,,,,,,,,,,,,,,,,
177.19,1.83838,5.30386,7.5,,,,,,,,,,,,,,,,,,,,,,,,,,,,,,,,,,,,,
177.89,1.72182,3.98771,7.5,,,,,,,,,,,,,,,,,,,,,,,,,,,,,,,,,,,,,
178.59,1.60508,2.90277,7.5,,,,,,,,,,,,,,,,,,,,,,,,,,,,,,,,,,,,,
179.29,1.48835,2.00075,7.5,,,,,,,,,,,,,,,,,,,,,,,,,,,,,,,,,,,,,
179.99,1.37167,1.17674,7.5,,,,,,,,,,,,,,,,,,,,,,,,,,,,,,,,,,,,,
180.406,1.36952,1.20353,8,,,,,,,,,,,,,,,,,,,,,,,,,,,,,,,,,,,,,
181.106,1.48665,2.25223,8,,,,,,,,,,,,,,,,,,,,,,,,,,,,,,,,,,,,,
181.806,1.60338,3.43903,8,,,,,,,,,,,,,,,,,,,,,,,,,,,,,,,,,,,,,
182.506,1.72012,4.73006,8,,,,,,,,,,,,,,,,,,,,,,,,,,,,,,,,,,,,,
183.206,1.83679,6.1902,8,,,,,,,,,,,,,,,,,,,,,,,,,,,,,,,,,,,,,
183.906,1.95341,7.79339,8,,,,,,,,,,,,,,,,,,,,,,,,,,,,,,,,,,,,,
184.606,2.06998,9.63858,8,,,,,,,,,,,,,,,,,,,,,,,,,,,,,,,,,,,,,
185.306,2.18671,11.684,8,,,,,,,,,,,,,,,,,,,,,,,,,,,,,,,,,,,,,
186.006,2.30327,13.99843,8,,,,,,,,,,,,,,,,,,,,,,,,,,,,,,,,,,,,,
186.706,2.42001,16.72755,8,,,,,,,,,,,,,,,,,,,,,,,,,,,,,,,,,,,,,
187.406,2.53657,19.69751,8,,,,,,,,,,,,,,,,,,,,,,,,,,,,,,,,,,,,,
188.106,2.65325,22.94283,8,,,,,,,,,,,,,,,,,,,,,,,,,,,,,,,,,,,,,
188.806,2.76992,26.60818,8,,,,,,,,,,,,,,,,,,,,,,,,,,,,,,,,,,,,,
189.506,2.88671,30.75095,8,,,,,,,,,,,,,,,,,,,,,,,,,,,,,,,,,,,,,
190.206,3.00328,35.19145,8,,,,,,,,,,,,,,,,,,,,,,,,,,,,,,,,,,,,,
190.9,3.11893,40.0044,8.5,,,,,,,,,,,,,,,,,,,,,,,,,,,,,,,,,,,,,
191.502,3.01914,34.90261,8.5,,,,,,,,,,,,,,,,,,,,,,,,,,,,,,,,,,,,,
192.202,2.90235,29.66163,8.5,,,,,,,,,,,,,,,,,,,,,,,,,,,,,,,,,,,,,
192.902,2.78556,25.18004,8.5,,,,,,,,,,,,,,,,,,,,,,,,,,,,,,,,,,,,,
193.602,2.66894,21.34028,8.5,,,,,,,,,,,,,,,,,,,,,,,,,,,,,,,,,,,,,
194.302,2.55227,17.93366,8.5,,,,,,,,,,,,,,,,,,,,,,,,,,,,,,,,,,,,,
195.002,2.43565,15.07649,8.5,,,,,,,,,,,,,,,,,,,,,,,,,,,,,,,,,,,,,
195.702,2.31897,12.5058,8.5,,,,,,,,,,,,,,,,,,,,,,,,,,,,,,,,,,,,,
196.402,2.20235,10.30003,8.5,,,,,,,,,,,,,,,,,,,,,,,,,,,,,,,,,,,,,
197.102,2.08567,8.35816,8.5,,,,,,,,,,,,,,,,,,,,,,,,,,,,,,,,,,,,,
197.802,1.96905,6.66891,8.5,,,,,,,,,,,,,,,,,,,,,,,,,,,,,,,,,,,,,
198.502,1.85238,5.22792,8.5,,,,,,,,,,,,,,,,,,,,,,,,,,,,,,,,,,,,,
199.202,1.73576,3.98569,8.5,,,,,,,,,,,,,,,,,,,,,,,,,,,,,,,,,,,,,
199.902,1.61902,2.83982,8.5,,,,,,,,,,,,,,,,,,,,,,,,,,,,,,,,,,,,,
200.602,1.50235,1.91458,8.5,,,,,,,,,,,,,,,,,,,,,,,,,,,,,,,,,,,,,
201.302,1.38578,1.13318,8.5,,,,,,,,,,,,,,,,,,,,,,,,,,,,,,,,,,,,,
201.762,1.40987,1.37201,9,,,,,,,,,,,,,,,,,,,,,,,,,,,,,,,,,,,,,
202.462,1.52666,2.436,9,,,,,,,,,,,,,,,,,,,,,,,,,,,,,,,,,,,,,
203.162,1.64333,3.64588,9,,,,,,,,,,,,,,,,,,,,,,,,,,,,,,,,,,,,,
203.862,1.75995,5.05271,9,,,,,,,,,,,,,,,,,,,,,,,,,,,,,,,,,,,,,
204.562,1.87663,6.44972,9,,,,,,,,,,,,,,,,,,,,,,,,,,,,,,,,,,,,,
205.262,1.99331,8.08841,9,,,,,,,,,,,,,,,,,,,,,,,,,,,,,,,,,,,,,
205.962,2.11004,9.97609,9,,,,,,,,,,,,,,,,,,,,,,,,,,,,,,,,,,,,,
206.662,2.22672,12.22373,9,,,,,,,,,,,,,,,,,,,,,,,,,,,,,,,,,,,,,
207.362,2.34345,14.56337,9,,,,,,,,,,,,,,,,,,,,,,,,,,,,,,,,,,,,,
208.062,2.46007,17.30764,9,,,,,,,,,,,,,,,,,,,,,,,,,,,,,,,,,,,,,
208.762,2.57675,20.36686,9,,,,,,,,,,,,,,,,,,,,,,,,,,,,,,,,,,,,,
209.462,2.69342,23.78659,9,,,,,,,,,,,,,,,,,,,,,,,,,,,,,,,,,,,,,
210.162,2.8101,27.51551,9,,,,,,,,,,,,,,,,,,,,,,,,,,,,,,,,,,,,,
210.862,2.92666,31.66573,9,,,,,,,,,,,,,,,,,,,,,,,,,,,,,,,,,,,,,
211.562,3.04328,36.31995,9,,,,,,,,,,,,,,,,,,,,,,,,,,,,,,,,,,,,,
212.096,3.13242,40.03185,9.5,,,,,,,,,,,,,,,,,,,,,,,,,,,,,,,,,,,,,
212.796,3.0154,34.13613,9.5,,,,,,,,,,,,,,,,,,,,,,,,,,,,,,,,,,,,,
213.496,2.89873,28.98888,9.5,,,,,,,,,,,,,,,,,,,,,,,,,,,,,,,,,,,,,
214.196,2.78194,24.56081,9.5,,,,,,,,,,,,,,,,,,,,,,,,,,,,,,,,,,,,,
214.896,2.6652,20.85135,9.5,,,,,,,,,,,,,,,,,,,,,,,,,,,,,,,,,,,,,
215.596,2.54853,17.54849,9.5,,,,,,,,,,,,,,,,,,,,,,,,,,,,,,,,,,,,,
216.296,2.43196,14.63817,9.5,,,,,,,,,,,,,,,,,,,,,,,,,,,,,,,,,,,,,
216.996,2.3154,12.1306,9.5,,,,,,,,,,,,,,,,,,,,,,,,,,,,,,,,,,,,,
217.696,2.19872,9.94441,9.5,,,,,,,,,,,,,,,,,,,,,,,,,,,,,,,,,,,,,
218.396,2.08205,8.08191,9.5,,,,,,,,,,,,,,,,,,,,,,,,,,,,,,,,,,,,,
219.096,1.96537,6.46263,9.5,,,,,,,,,,,,,,,,,,,,,,,,,,,,,,,,,,,,,
219.796,1.84869,5.00983,9.5,,,,,,,,,,,,,,,,,,,,,,,,,,,,,,,,,,,,,
220.496,1.73202,3.77919,9.5,,,,,,,,,,,,,,,,,,,,,,,,,,,,,,,,,,,,,
221.196,1.6154,2.73027,9.5,,,,,,,,,,,,,,,,,,,,,,,,,,,,,,,,,,,,,
221.896,1.49878,1.76168,9.5,,,,,,,,,,,,,,,,,,,,,,,,,,,,,,,,,,,,,
222.596,1.38199,1.01865,9.5,,,,,,,,,,,,,,,,,,,,,,,,,,,,,,,,,,,,,
223.154,1.29438,0.5674,10,,,,,,,,,,,,,,,,,,,,,,,,,,,,,,,,,,,,,
223.854,1.2703,0.48149,10,,,,,,,,,,,,,,,,,,,,,,,,,,,,,,,,,,,,,
224.554,1.27092,0.54998,10,,,,,,,,,,,,,,,,,,,,,,,,,,,,,,,,,,,,,
225.254,1.27313,0.65556,10,,,,,,,,,,,,,,,,,,,,,,,,,,,,,,,,,,,,,
225.954,1.30163,0.81435,10,,,,,,,,,,,,,,,,,,,,,,,,,,,,,,,,,,,,,
226.654,1.33048,1.10423,10,,,,,,,,,,,,,,,,,,,,,,,,,,,,,,,,,,,,,
227.354,1.33025,1.03907,10,,,,,,,,,,,,,,,,,,,,,,,,,,,,,,,,,,,,,
228.054,1.32878,1.11783,10,,,,,,,,,,,,,,,,,,,,,,,,,,,,,,,,,,,,,
228.754,1.30798,0.88395,10,,,,,,,,,,,,,,,,,,,,,,,,,,,,,,,,,,,,,
229.454,1.28378,0.72601,10,,,,,,,,,,,,,,,,,,,,,,,,,,,,,,,,,,,,,
230.154,1.2831,0.81852,10,,,,,,,,,,,,,,,,,,,,,,,,,,,,,,,,,,,,,
230.854,1.28327,0.73234,10,,,,,,,,,,,,,,,,,,,,,,,,,,,,,,,,,,,,,
231.554,1.28339,0.76786,10,,,,,,,,,,,,,,,,,,,,,,,,,,,,,,,,,,,,,
232.254,1.2835,0.78084,10,,,,,,,,,,,,,,,,,,,,,,,,,,,,,,,,,,,,,
232.954,1.28373,0.71629,10,,,,,,,,,,,,,,,,,,,,,,,,,,,,,,,,,,,,,
233.654,1.28418,0.81281,10,,,,,,,,,,,,,,,,,,,,,,,,,,,,,,,,,,,,,
234.354,1.2848,0.74344,10,,,,,,,,,,,,,,,,,,,,,,,,,,,,,,,,,,,,,
235.054,1.28594,0.78003,10,,,,,,,,,,,,,,,,,,,,,,,,,,,,,,,,,,,,,
235.754,1.28786,0.79624,10,,,,,,,,,,,,,,,,,,,,,,,,,,,,,,,,,,,,,
236.454,1.28996,0.83818,10,,,,,,,,,,,,,,,,,,,,,,,,,,,,,,,,,,,,,
237.154,1.29228,0.8502,10,,,,,,,,,,,,,,,,,,,,,,,,,,,,,,,,,,,,,
237.854,1.29404,0.84818,10,,,,,,,,,,,,,,,,,,,,,,,,,,,,,,,,,,,,,
238.554,1.29461,0.90189,10,,,,,,,,,,,,,,,,,,,,,,,,,,,,,,,,,,,,,
239.254,1.29449,0.86498,10,,,,,,,,,,,,,,,,,,,,,,,,,,,,,,,,,,,,,
239.954,1.29444,0.88134,10,,,,,,,,,,,,,,,,,,,,,,,,,,,,,,,,,,,,,
240.654,1.29427,0.94138,10,,,,,,,,,,,,,,,,,,,,,,,,,,,,,,,,,,,,,
241.354,1.29415,0.86748,10,,,,,,,,,,,,,,,,,,,,,,,,,,,,,,,,,,,,,
242.054,1.29364,0.90212,10,,,,,,,,,,,,,,,,,,,,,,,,,,,,,,,,,,,,,
242.754,1.29172,0.93289,10,,,,,,,,,,,,,,,,,,,,,,,,,,,,,,,,,,,,,
243.454,1.28752,0.86116,10,,,,,,,,,,,,,,,,,,,,,,,,,,,,,,,,,,,,,
244.154,1.28458,0.83503,10,,,,,,,,,,,,,,,,,,,,,,,,,,,,,,,,,,,,,
244.854,1.2814,0.86761,10,,,,,,,,,,,,,,,,,,,,,,,,,,,,,,,,,,,,,
245.554,1.27783,0.81403,10,,,,,,,,,,,,,,,,,,,,,,,,,,,,,,,,,,,,,
246.254,1.27653,0.78844,10,,,,,,,,,,,,,,,,,,,,,,,,,,,,,,,,,,,,,
246.954,1.27579,0.83053,10,,,,,,,,,,,,,,,,,,,,,,,,,,,,,,,,,,,,,
247.654,1.2754,0.84211,10,,,,,,,,,,,,,,,,,,,,,,,,,,,,,,,,,,,,,
248.354,1.27494,0.78867,10,,,,,,,,,,,,,,,,,,,,,,,,,,,,,,,,,,,,,
249.054,1.27455,0.82394,10,,,,,,,,,,,,,,,,,,,,,,,,,,,,,,,,,,,,,
249.754,1.27438,0.77878,10,,,,,,,,,,,,,,,,,,,,,,,,,,,,,,,,,,,,,
250.454,1.27426,0.76185,10,,,,,,,,,,,,,,,,,,,,,,,,,,,,,,,,,,,,,
251.154,1.27409,0.77976,10,,,,,,,,,,,,,,,,,,,,,,,,,,,,,,,,,,,,,
251.854,1.27404,0.85898,10,,,,,,,,,,,,,,,,,,,,,,,,,,,,,,,,,,,,,
252.554,1.27398,0.77553,10,,,,,,,,,,,,,,,,,,,,,,,,,,,,,,,,,,,,,
253.254,1.27398,0.86008,10,,,,,,,,,,,,,,,,,,,,,,,,,,,,,,,,,,,,,
253.954,1.27392,0.79406,10,,,,,,,,,,,,,,,,,,,,,,,,,,,,,,,,,,,,,
254.654,1.27392,0.81325,10,,,,,,,,,,,,,,,,,,,,,,,,,,,,,,,,,,,,,
255.354,1.27392,0.80361,10,,,,,,,,,,,,,,,,,,,,,,,,,,,,,,,,,,,,,
256.054,1.27392,0.81984,10,,,,,,,,,,,,,,,,,,,,,,,,,,,,,,,,,,,,,
256.754,1.27392,0.8332,10,,,,,,,,,,,,,,,,,,,,,,,,,,,,,,,,,,,,,
257.454,1.27392,0.87292,10,,,,,,,,,,,,,,,,,,,,,,,,,,,,,,,,,,,,,
258.154,1.27404,0.81981,10,,,,,,,,,,,,,,,,,,,,,,,,,,,,,,,,,,,,,
258.854,1.27404,0.86377,10,,,,,,,,,,,,,,,,,,,,,,,,,,,,,,,,,,,,,
259.554,1.27404,0.80565,10,,,,,,,,,,,,,,,,,,,,,,,,,,,,,,,,,,,,,
260.254,1.27404,0.8376,10,,,,,,,,,,,,,,,,,,,,,,,,,,,,,,,,,,,,,
260.954,1.27392,0.84004,10,,,,,,,,,,,,,,,,,,,,,,,,,,,,,,,,,,,,,
261.654,1.27404,0.8232,10,,,,,,,,,,,,,,,,,,,,,,,,,,,,,,,,,,,,,
262.354,1.27392,0.81132,10,,,,,,,,,,,,,,,,,,,,,,,,,,,,,,,,,,,,,
263.054,1.27398,0.8297,10,,,,,,,,,,,,,,,,,,,,,,,,,,,,,,,,,,,,,
263.754,1.27387,0.8992,10,,,,,,,,,,,,,,,,,,,,,,,,,,,,,,,,,,,,,
264.454,1.27375,0.81227,10,,,,,,,,,,,,,,,,,,,,,,,,,,,,,,,,,,,,,
265.154,1.2733,0.84333,10,,,,,,,,,,,,,,,,,,,,,,,,,,,,,,,,,,,,,
265.854,1.27177,0.87913,10,,,,,,,,,,,,,,,,,,,,,,,,,,,,,,,,,,,,,
266.554,1.26854,0.78318,10,,,,,,,,,,,,,,,,,,,,,,,,,,,,,,,,,,,,,
267.254,1.2661,0.79422,10,,,,,,,,,,,,,,,,,,,,,,,,,,,,,,,,,,,,,
267.954,1.26497,0.81331,10,,,,,,,,,,,,,,,,,,,,,,,,,,,,,,,,,,,,,
268.654,1.26469,0.82556,10,,,,,,,,,,,,,,,,,,,,,,,,,,,,,,,,,,,,,
269.354,1.26457,0.75825,10,,,,,,,,,,,,,,,,,,,,,,,,,,,,,,,,,,,,,
270.054,1.26469,0.78416,10,,,,,,,,,,,,,,,,,,,,,,,,,,,,,,,,,,,,,
270.754,1.2648,0.7326,10,,,,,,,,,,,,,,,,,,,,,,,,,,,,,,,,,,,,,
271.454,1.2648,0.82645,10,,,,,,,,,,,,,,,,,,,,,,,,,,,,,,,,,,,,,
272.154,1.26491,0.75492,10,,,,,,,,,,,,,,,,,,,,,,,,,,,,,,,,,,,,,
272.854,1.26503,0.75115,10,,,,,,,,,,,,,,,,,,,,,,,,,,,,,,,,,,,,,
273.554,1.26514,0.80572,10,,,,,,,,,,,,,,,,,,,,,,,,,,,,,,,,,,,,,
274.254,1.26525,0.85783,10,,,,,,,,,,,,,,,,,,,,,,,,,,,,,,,,,,,,,
274.954,1.26542,0.80882,10,,,,,,,,,,,,,,,,,,,,,,,,,,,,,,,,,,,,,
275.654,1.26554,0.79916,10,,,,,,,,,,,,,,,,,,,,,,,,,,,,,,,,,,,,,
276.354,1.26582,0.74557,10,,,,,,,,,,,,,,,,,,,,,,,,,,,,,,,,,,,,,
277.054,1.2661,0.79715,10,,,,,,,,,,,,,,,,,,,,,,,,,,,,,,,,,,,,,
277.754,1.26644,0.76139,10,,,,,,,,,,,,,,,,,,,,,,,,,,,,,,,,,,,,,
278.454,1.26712,0.78472,10,,,,,,,,,,,,,,,,,,,,,,,,,,,,,,,,,,,,,
279.154,1.26831,0.80924,10,,,,,,,,,,,,,,,,,,,,,,,,,,,,,,,,,,,,,
279.854,1.26962,0.84795,10,,,,,,,,,,,,,,,,,,,,,,,,,,,,,,,,,,,,,
280.554,1.27069,0.807,10,,,,,,,,,,,,,,,,,,,,,,,,,,,,,,,,,,,,,
281.254,1.27109,0.84899,10,,,,,,,,,,,,,,,,,,,,,,,,,,,,,,,,,,,,,
281.954,1.27143,0.83798,10,,,,,,,,,,,,,,,,,,,,,,,,,,,,,,,,,,,,,
282.654,1.27166,0.835,10,,,,,,,,,,,,,,,,,,,,,,,,,,,,,,,,,,,,,
283.354,1.27177,0.86091,10,,,,,,,,,,,,,,,,,,,,,,,,,,,,,,,,,,,,,
284.054,1.27183,0.85172,10,,,,,,,,,,,,,,,,,,,,,,,,,,,,,,,,,,,,,
284.754,1.27177,0.91653,10,,,,,,,,,,,,,,,,,,,,,,,,,,,,,,,,,,,,,
285.454,1.27166,0.91322,10,,,,,,,,,,,,,,,,,,,,,,,,,,,,,,,,,,,,,
286.154,1.27166,0.84435,10,,,,,,,,,,,,,,,,,,,,,,,,,,,,,,,,,,,,,
286.854,1.2716,0.85572,10,,,,,,,,,,,,,,,,,,,,,,,,,,,,,,,,,,,,,
287.554,1.27154,0.87224,10,,,,,,,,,,,,,,,,,,,,,,,,,,,,,,,,,,,,,
288.254,1.27149,0.85241,10,,,,,,,,,,,,,,,,,,,,,,,,,,,,,,,,,,,,,
288.954,1.27143,0.82614,10,,,,,,,,,,,,,,,,,,,,,,,,,,,,,,,,,,,,,
289.654,1.27132,0.85972,10,,,,,,,,,,,,,,,,,,,,,,,,,,,,,,,,,,,,,
290.354,1.27115,0.84256,10,,,,,,,,,,,,,,,,,,,,,,,,,,,,,,,,,,,,,
291.054,1.27098,0.89495,10,,,,,,,,,,,,,,,,,,,,,,,,,,,,,,,,,,,,,
291.754,1.27052,0.97032,10,,,,,,,,,,,,,,,,,,,,,,,,,,,,,,,,,,,,,
292.454,1.26996,0.87925,10,,,,,,,,,,,,,,,,,,,,,,,,,,,,,,,,,,,,,
293.154,1.26865,0.88377,10,,,,,,,,,,,,,,,,,,,,,,,,,,,,,,,,,,,,,
293.854,1.26718,0.84486,10,,,,,,,,,,,,,,,,,,,,,,,,,,,,,,,,,,,,,
294.554,1.26559,0.84386,10,,,,,,,,,,,,,,,,,,,,,,,,,,,,,,,,,,,,,
295.254,1.26418,0.81777,10,,,,,,,,,,,,,,,,,,,,,,,,,,,,,,,,,,,,,
295.954,1.26248,0.80429,10,,,,,,,,,,,,,,,,,,,,,,,,,,,,,,,,,,,,,
296.654,1.2614,0.82807,10,,,,,,,,,,,,,,,,,,,,,,,,,,,,,,,,,,,,,
297.354,1.26078,0.82755,10,,,,,,,,,,,,,,,,,,,,,,,,,,,,,,,,,,,,,
298.054,1.26027,0.84217,10,,,,,,,,,,,,,,,,,,,,,,,,,,,,,,,,,,,,,
298.754,1.25976,0.78795,10,,,,,,,,,,,,,,,,,,,,,,,,,,,,,,,,,,,,,
299.454,1.2593,0.8127,10,,,,,,,,,,,,,,,,,,,,,,,,,,,,,,,,,,,,,
300.154,1.25862,0.83131,10,,,,,,,,,,,,,,,,,,,,,,,,,,,,,,,,,,,,,
300.854,1.25783,0.80077,10,,,,,,,,,,,,,,,,,,,,,,,,,,,,,,,,,,,,,
301.554,1.25698,0.76887,10,,,,,,,,,,,,,,,,,,,,,,,,,,,,,,,,,,,,,
302.254,1.2567,0.80585,10,,,,,,,,,,,,,,,,,,,,,,,,,,,,,,,,,,,,,
302.954,1.25658,0.7865,10,,,,,,,,,,,,,,,,,,,,,,,,,,,,,,,,,,,,,
303.654,1.2567,0.7876,10,,,,,,,,,,,,,,,,,,,,,,,,,,,,,,,,,,,,,
304.354,1.25675,0.74533,10,,,,,,,,,,,,,,,,,,,,,,,,,,,,,,,,,,,,,
305.054,1.25681,0.78822,10,,,,,,,,,,,,,,,,,,,,,,,,,,,,,,,,,,,,,
305.754,1.25687,0.81364,10,,,,,,,,,,,,,,,,,,,,,,,,,,,,,,,,,,,,,
306.454,1.25698,0.78797,10,,,,,,,,,,,,,,,,,,,,,,,,,,,,,,,,,,,,,
307.154,1.25704,0.80755,10,,,,,,,,,,,,,,,,,,,,,,,,,,,,,,,,,,,,,
307.854,1.25709,0.79429,10,,,,,,,,,,,,,,,,,,,,,,,,,,,,,,,,,,,,,
308.554,1.25715,0.78399,10,,,,,,,,,,,,,,,,,,,,,,,,,,,,,,,,,,,,,
309.254,1.25738,0.77947,10,,,,,,,,,,,,,,,,,,,,,,,,,,,,,,,,,,,,,
309.954,1.25749,0.77838,10,,,,,,,,,,,,,,,,,,,,,,,,,,,,,,,,,,,,,
310.654,1.25766,0.81267,10,,,,,,,,,,,,,,,,,,,,,,,,,,,,,,,,,,,,,
311.354,1.25783,0.84062,10,,,,,,,,,,,,,,,,,,,,,,,,,,,,,,,,,,,,,
312.054,1.25783,0.81424,10,,,,,,,,,,,,,,,,,,,,,,,,,,,,,,,,,,,,,
312.754,1.25772,0.85218,10,,,,,,,,,,,,,,,,,,,,,,,,,,,,,,,,,,,,,
313.454,1.25772,0.8419,10,,,,,,,,,,,,,,,,,,,,,,,,,,,,,,,,,,,,,
314.154,1.25772,0.79844,10,,,,,,,,,,,,,,,,,,,,,,,,,,,,,,,,,,,,,
314.854,1.25772,0.78081,10,,,,,,,,,,,,,,,,,,,,,,,,,,,,,,,,,,,,,
315.554,1.25772,0.80104,10,,,,,,,,,,,,,,,,,,,,,,,,,,,,,,,,,,,,,
316.254,1.25772,0.84481,10,,,,,,,,,,,,,,,,,,,,,,,,,,,,,,,,,,,,,
316.954,1.25772,0.80364,10,,,,,,,,,,,,,,,,,,,,,,,,,,,,,,,,,,,,,
317.654,1.25772,0.78493,10,,,,,,,,,,,,,,,,,,,,,,,,,,,,,,,,,,,,,
318.354,1.25783,0.8236,10,,,,,,,,,,,,,,,,,,,,,,,,,,,,,,,,,,,,,
319.054,1.25783,0.84359,10,,,,,,,,,,,,,,,,,,,,,,,,,,,,,,,,,,,,,
319.754,1.25783,0.80456,10,,,,,,,,,,,,,,,,,,,,,,,,,,,,,,,,,,,,,
320.454,1.25783,0.86762,10,,,,,,,,,,,,,,,,,,,,,,,,,,,,,,,,,,,,,
321.154,1.25783,0.83051,10,,,,,,,,,,,,,,,,,,,,,,,,,,,,,,,,,,,,,
321.854,1.25783,0.82852,10,,,,,,,,,,,,,,,,,,,,,,,,,,,,,,,,,,,,,
322.554,1.25772,0.81603,10,,,,,,,,,,,,,,,,,,,,,,,,,,,,,,,,,,,,,
323.254,1.25772,0.8462,10,,,,,,,,,,,,,,,,,,,,,,,,,,,,,,,,,,,,,
323.954,1.25772,0.83914,10,,,,,,,,,,,,,,,,,,,,,,,,,,,,,,,,,,,,,
324.654,1.25772,0.79821,10,,,,,,,,,,,,,,,,,,,,,,,,,,,,,,,,,,,,,
325.354,1.25772,0.84946,10,,,,,,,,,,,,,,,,,,,,,,,,,,,,,,,,,,,,,
326.054,1.25772,0.82753,10,,,,,,,,,,,,,,,,,,,,,,,,,,,,,,,,,,,,,
326.754,1.25772,0.83221,10,,,,,,,,,,,,,,,,,,,,,,,,,,,,,,,,,,,,,
327.454,1.25777,0.82034,10,,,,,,,,,,,,,,,,,,,,,,,,,,,,,,,,,,,,,
328.154,1.25766,0.76613,10,,,,,,,,,,,,,,,,,,,,,,,,,,,,,,,,,,,,,
328.854,1.25766,0.84659,10,,,,,,,,,,,,,,,,,,,,,,,,,,,,,,,,,,,,,
329.554,1.25766,0.84201,10,,,,,,,,,,,,,,,,,,,,,,,,,,,,,,,,,,,,,
330.254,1.25772,0.87316,10,,,,,,,,,,,,,,,,,,,,,,,,,,,,,,,,,,,,,
330.954,1.25772,0.80261,10,,,,,,,,,,,,,,,,,,,,,,,,,,,,,,,,,,,,,
331.654,1.25772,0.84224,10,,,,,,,,,,,,,,,,,,,,,,,,,,,,,,,,,,,,,
332.354,1.25772,0.87729,10,,,,,,,,,,,,,,,,,,,,,,,,,,,,,,,,,,,,,
333.054,1.25772,0.83978,10,,,,,,,,,,,,,,,,,,,,,,,,,,,,,,,,,,,,,
333.754,1.25777,0.77648,10,,,,,,,,,,,,,,,,,,,,,,,,,,,,,,,,,,,,,
334.454,1.25777,0.83029,10,,,,,,,,,,,,,,,,,,,,,,,,,,,,,,,,,,,,,
335.154,1.25772,0.76653,10,,,,,,,,,,,,,,,,,,,,,,,,,,,,,,,,,,,,,
335.854,1.25777,0.83501,10,,,,,,,,,,,,,,,,,,,,,,,,,,,,,,,,,,,,,
336.554,1.25766,0.82034,10,,,,,,,,,,,,,,,,,,,,,,,,,,,,,,,,,,,,,
337.254,1.25766,0.84278,10,,,,,,,,,,,,,,,,,,,,,,,,,,,,,,,,,,,,,
337.954,1.25766,0.84821,10,,,,,,,,,,,,,,,,,,,,,,,,,,,,,,,,,,,,,
338.654,1.2576,0.78624,10,,,,,,,,,,,,,,,,,,,,,,,,,,,,,,,,,,,,,
339.354,1.2576,0.79835,10,,,,,,,,,,,,,,,,,,,,,,,,,,,,,,,,,,,,,
340.054,1.2576,0.823,10,,,,,,,,,,,,,,,,,,,,,,,,,,,,,,,,,,,,,
340.754,1.2576,0.76604,10,,,,,,,,,,,,,,,,,,,,,,,,,,,,,,,,,,,,,
341.454,1.2576,0.8387,10,,,,,,,,,,,,,,,,,,,,,,,,,,,,,,,,,,,,,
342.154,1.25772,0.79759,10,,,,,,,,,,,,,,,,,,,,,,,,,,,,,,,,,,,,,
342.854,1.25772,0.80922,10,,,,,,,,,,,,,,,,,,,,,,,,,,,,,,,,,,,,,
343.554,1.25772,0.8736,10,,,,,,,,,,,,,,,,,,,,,,,,,,,,,,,,,,,,,
344.254,1.2576,0.8456,10,,,,,,,,,,,,,,,,,,,,,,,,,,,,,,,,,,,,,
344.954,1.2576,0.86598,10,,,,,,,,,,,,,,,,,,,,,,,,,,,,,,,,,,,,,
345.654,1.25755,0.8289,10,,,,,,,,,,,,,,,,,,,,,,,,,,,,,,,,,,,,,
346.354,1.25755,0.83258,10,,,,,,,,,,,,,,,,,,,,,,,,,,,,,,,,,,,,,
347.054,1.25755,0.81794,10,,,,,,,,,,,,,,,,,,,,,,,,,,,,,,,,,,,,,
347.754,1.25755,0.8175,10,,,,,,,,,,,,,,,,,,,,,,,,,,,,,,,,,,,,,
348.454,1.25766,0.83262,10,,,,,,,,,,,,,,,,,,,,,,,,,,,,,,,,,,,,,
349.154,1.25766,0.814,10,,,,,,,,,,,,,,,,,,,,,,,,,,,,,,,,,,,,,
349.854,1.25766,0.87748,10,,,,,,,,,,,,,,,,,,,,,,,,,,,,,,,,,,,,,
350.554,1.25766,0.83061,10,,,,,,,,,,,,,,,,,,,,,,,,,,,,,,,,,,,,,
351.254,1.25766,0.83636,10,,,,,,,,,,,,,,,,,,,,,,,,,,,,,,,,,,,,,
351.954,1.25766,0.78,10,,,,,,,,,,,,,,,,,,,,,,,,,,,,,,,,,,,,,
352.654,1.25755,0.81478,10,,,,,,,,,,,,,,,,,,,,,,,,,,,,,,,,,,,,,
353.354,1.25755,0.76609,10,,,,,,,,,,,,,,,,,,,,,,,,,,,,,,,,,,,,,
354.054,1.25755,0.82187,10,,,,,,,,,,,,,,,,,,,,,,,,,,,,,,,,,,,,,
354.754,1.25766,0.78808,10,,,,,,,,,,,,,,,,,,,,,,,,,,,,,,,,,,,,,
355.454,1.25766,0.82084,10,,,,,,,,,,,,,,,,,,,,,,,,,,,,,,,,,,,,,
356.154,1.25755,0.82736,10,,,,,,,,,,,,,,,,,,,,,,,,,,,,,,,,,,,,,
356.854,1.2576,0.82298,10,,,,,,,,,,,,,,,,,,,,,,,,,,,,,,,,,,,,,
357.554,1.2576,0.84242,10,,,,,,,,,,,,,,,,,,,,,,,,,,,,,,,,,,,,,
358.254,1.2576,0.85407,10,,,,,,,,,,,,,,,,,,,,,,,,,,,,,,,,,,,,,
358.954,1.2576,0.84985,10,,,,,,,,,,,,,,,,,,,,,,,,,,,,,,,,,,,,,
359.654,1.2576,0.81504,10,,,,,,,,,,,,,,,,,,,,,,,,,,,,,,,,,,,,,
360.354,1.2576,0.7738,10,,,,,,,,,,,,,,,,,,,,,,,,,,,,,,,,,,,,,
361.054,1.2576,0.843,10,,,,,,,,,,,,,,,,,,,,,,,,,,,,,,,,,,,,,
361.754,1.2576,0.85089,10,,,,,,,,,,,,,,,,,,,,,,,,,,,,,,,,,,,,,
362.454,1.2576,0.82329,10,,,,,,,,,,,,,,,,,,,,,,,,,,,,,,,,,,,,,
363.154,1.2576,0.79682,10,,,,,,,,,,,,,,,,,,,,,,,,,,,,,,,,,,,,,
363.854,1.2576,0.83048,10,,,,,,,,,,,,,,,,,,,,,,,,,,,,,,,,,,,,,
364.554,1.2576,0.77623,10,,,,,,,,,,,,,,,,,,,,,,,,,,,,,,,,,,,,,
365.254,1.2576,0.81364,10,,,,,,,,,,,,,,,,,,,,,,,,,,,,,,,,,,,,,
365.954,1.2576,0.79413,10,,,,,,,,,,,,,,,,,,,,,,,,,,,,,,,,,,,,,
366.654,1.2576,0.82231,10,,,,,,,,,,,,,,,,,,,,,,,,,,,,,,,,,,,,,
367.354,1.2576,0.82712,10,,,,,,,,,,,,,,,,,,,,,,,,,,,,,,,,,,,,,
368.054,1.2576,0.89146,10,,,,,,,,,,,,,,,,,,,,,,,,,,,,,,,,,,,,,
368.754,1.2576,0.81854,10,,,,,,,,,,,,,,,,,,,,,,,,,,,,,,,,,,,,,
369.454,1.2576,0.88336,10,,,,,,,,,,,,,,,,,,,,,,,,,,,,,,,,,,,,,
370.154,1.25755,0.80508,10,,,,,,,,,,,,,,,,,,,,,,,,,,,,,,,,,,,,,
370.854,1.25755,0.86109,10,,,,,,,,,,,,,,,,,,,,,,,,,,,,,,,,,,,,,
371.554,1.2576,0.85504,10,,,,,,,,,,,,,,,,,,,,,,,,,,,,,,,,,,,,,
372.254,1.25749,0.84715,10,,,,,,,,,,,,,,,,,,,,,,,,,,,,,,,,,,,,,
372.954,1.25743,0.81319,10,,,,,,,,,,,,,,,,,,,,,,,,,,,,,,,,,,,,,
373.654,1.25743,0.89642,10,,,,,,,,,,,,,,,,,,,,,,,,,,,,,,,,,,,,,
374.354,1.25738,0.78545,10,,,,,,,,,,,,,,,,,,,,,,,,,,,,,,,,,,,,,
375.054,1.25732,0.82472,10,,,,,,,,,,,,,,,,,,,,,,,,,,,,,,,,,,,,,
375.754,1.25732,0.8441,10,,,,,,,,,,,,,,,,,,,,,,,,,,,,,,,,,,,,,
376.454,1.25732,0.8357,10,,,,,,,,,,,,,,,,,,,,,,,,,,,,,,,,,,,,,
377.154,1.25726,0.79495,10,,,,,,,,,,,,,,,,,,,,,,,,,,,,,,,,,,,,,
377.854,1.25738,0.79899,10,,,,,,,,,,,,,,,,,,,,,,,,,,,,,,,,,,,,,
378.554,1.25738,0.82707,10,,,,,,,,,,,,,,,,,,,,,,,,,,,,,,,,,,,,,
379.254,1.25738,0.83293,10,,,,,,,,,,,,,,,,,,,,,,,,,,,,,,,,,,,,,
379.954,1.25738,0.91643,10,,,,,,,,,,,,,,,,,,,,,,,,,,,,,,,,,,,,,
380.654,1.25738,0.80708,10,,,,,,,,,,,,,,,,,,,,,,,,,,,,,,,,,,,,,
381.354,1.25738,0.77696,10,,,,,,,,,,,,,,,,,,,,,,,,,,,,,,,,,,,,,
382.054,1.25738,0.81506,10,,,,,,,,,,,,,,,,,,,,,,,,,,,,,,,,,,,,,
382.754,1.25738,0.81848,10,,,,,,,,,,,,,,,,,,,,,,,,,,,,,,,,,,,,,
383.454,1.25738,0.81688,10,,,,,,,,,,,,,,,,,,,,,,,,,,,,,,,,,,,,,
384.154,1.25732,0.82279,10,,,,,,,,,,,,,,,,,,,,,,,,,,,,,,,,,,,,,
384.854,1.25738,0.82765,10,,,,,,,,,,,,,,,,,,,,,,,,,,,,,,,,,,,,,
385.554,1.25738,0.82992,10,,,,,,,,,,,,,,,,,,,,,,,,,,,,,,,,,,,,,
386.254,1.25738,0.7855,10,,,,,,,,,,,,,,,,,,,,,,,,,,,,,,,,,,,,,
386.954,1.25732,0.87238,10,,,,,,,,,,,,,,,,,,,,,,,,,,,,,,,,,,,,,
387.654,1.25738,0.83665,10,,,,,,,,,,,,,,,,,,,,,,,,,,,,,,,,,,,,,
388.354,1.25726,0.88471,10,,,,,,,,,,,,,,,,,,,,,,,,,,,,,,,,,,,,,
389.054,1.25726,0.83286,10,,,,,,,,,,,,,,,,,,,,,,,,,,,,,,,,,,,,,
389.754,1.25732,0.81841,10,,,,,,,,,,,,,,,,,,,,,,,,,,,,,,,,,,,,,
390.454,1.25721,0.8958,10,,,,,,,,,,,,,,,,,,,,,,,,,,,,,,,,,,,,,
391.154,1.25709,0.83821,10,,,,,,,,,,,,,,,,,,,,,,,,,,,,,,,,,,,,,
391.854,1.25692,0.84586,10,,,,,,,,,,,,,,,,,,,,,,,,,,,,,,,,,,,,,
392.554,1.25681,0.83415,10,,,,,,,,,,,,,,,,,,,,,,,,,,,,,,,,,,,,,
393.254,1.25658,0.81989,10,,,,,,,,,,,,,,,,,,,,,,,,,,,,,,,,,,,,,
393.954,1.2563,0.87267,10,,,,,,,,,,,,,,,,,,,,,,,,,,,,,,,,,,,,,
394.654,1.25562,0.8401,10,,,,,,,,,,,,,,,,,,,,,,,,,,,,,,,,,,,,,
395.354,1.25369,0.78919,10,,,,,,,,,,,,,,,,,,,,,,,,,,,,,,,,,,,,,
396.054,1.25205,0.82545,10,,,,,,,,,,,,,,,,,,,,,,,,,,,,,,,,,,,,,
396.754,1.2512,0.78056,10,,,,,,,,,,,,,,,,,,,,,,,,,,,,,,,,,,,,,
397.454,1.25086,0.77164,10,,,,,,,,,,,,,,,,,,,,,,,,,,,,,,,,,,,,,
398.154,1.25063,0.83781,10,,,,,,,,,,,,,,,,,,,,,,,,,,,,,,,,,,,,,
398.854,1.25052,0.81193,10,,,,,,,,,,,,,,,,,,,,,,,,,,,,,,,,,,,,,
399.554,1.25058,0.83785,10,,,,,,,,,,,,,,,,,,,,,,,,,,,,,,,,,,,,,
400.254,1.25052,0.77262,10,,,,,,,,,,,,,,,,,,,,,,,,,,,,,,,,,,,,,
400.954,1.25069,0.76554,10,,,,,,,,,,,,,,,,,,,,,,,,,,,,,,,,,,,,,
401.654,1.25075,0.77278,10,,,,,,,,,,,,,,,,,,,,,,,,,,,,,,,,,,,,,
402.354,1.2508,0.79726,10,,,,,,,,,,,,,,,,,,,,,,,,,,,,,,,,,,,,,
403.054,1.25075,0.83348,10,,,,,,,,,,,,,,,,,,,,,,,,,,,,,,,,,,,,,
403.754,1.25092,0.78805,10,,,,,,,,,,,,,,,,,,,,,,,,,,,,,,,,,,,,,
404.454,1.25092,0.83332,10,,,,,,,,,,,,,,,,,,,,,,,,,,,,,,,,,,,,,
405.154,1.25103,0.7448,10,,,,,,,,,,,,,,,,,,,,,,,,,,,,,,,,,,,,,
405.854,1.25131,0.81104,10,,,,,,,,,,,,,,,,,,,,,,,,,,,,,,,,,,,,,
406.554,1.2516,0.72323,10,,,,,,,,,,,,,,,,,,,,,,,,,,,,,,,,,,,,,
407.254,1.25199,0.79178,10,,,,,,,,,,,,,,,,,,,,,,,,,,,,,,,,,,,,,
407.954,1.25267,0.79303,10,,,,,,,,,,,,,,,,,,,,,,,,,,,,,,,,,,,,,
408.654,1.25369,0.78474,10,,,,,,,,,,,,,,,,,,,,,,,,,,,,,,,,,,,,,
409.354,1.25596,0.7933,10,,,,,,,,,,,,,,,,,,,,,,,,,,,,,,,,,,,,,
410.054,1.25879,0.86503,10,,,,,,,,,,,,,,,,,,,,,,,,,,,,,,,,,,,,,
410.754,1.26027,0.80738,10,,,,,,,,,,,,,,,,,,,,,,,,,,,,,,,,,,,,,
411.454,1.26174,0.86826,10,,,,,,,,,,,,,,,,,,,,,,,,,,,,,,,,,,,,,
412.154,1.26225,0.86072,10,,,,,,,,,,,,,,,,,,,,,,,,,,,,,,,,,,,,,
412.854,1.26231,0.89671,10,,,,,,,,,,,,,,,,,,,,,,,,,,,,,,,,,,,,,
413.554,1.26231,0.84393,10,,,,,,,,,,,,,,,,,,,,,,,,,,,,,,,,,,,,,
414.254,1.26231,0.87653,10,,,,,,,,,,,,,,,,,,,,,,,,,,,,,,,,,,,,,
414.954,1.26219,0.87317,10,,,,,,,,,,,,,,,,,,,,,,,,,,,,,,,,,,,,,
415.654,1.26214,0.86754,10,,,,,,,,,,,,,,,,,,,,,,,,,,,,,,,,,,,,,
416.354,1.26202,0.8537,10,,,,,,,,,,,,,,,,,,,,,,,,,,,,,,,,,,,,,
417.054,1.26197,0.88138,10,,,,,,,,,,,,,,,,,,,,,,,,,,,,,,,,,,,,,
417.754,1.26191,0.81436,10,,,,,,,,,,,,,,,,,,,,,,,,,,,,,,,,,,,,,
418.454,1.26174,0.87398,10,,,,,,,,,,,,,,,,,,,,,,,,,,,,,,,,,,,,,
419.154,1.26146,0.89497,10,,,,,,,,,,,,,,,,,,,,,,,,,,,,,,,,,,,,,
419.854,1.26066,0.92768,10,,,,,,,,,,,,,,,,,,,,,,,,,,,,,,,,,,,,,
420.554,1.25919,0.89636,10,,,,,,,,,,,,,,,,,,,,,,,,,,,,,,,,,,,,,
421.254,1.25681,0.89589,10,,,,,,,,,,,,,,,,,,,,,,,,,,,,,,,,,,,,,
421.954,1.25505,0.81483,10,,,,,,,,,,,,,,,,,,,,,,,,,,,,,,,,,,,,,
422.654,1.25375,0.81459,10,,,,,,,,,,,,,,,,,,,,,,,,,,,,,,,,,,,,,
423.354,1.25313,0.82242,10,,,,,,,,,,,,,,,,,,,,,,,,,,,,,,,,,,,,,
424.054,1.25279,0.8321,10,,,,,,,,,,,,,,,,,,,,,,,,,,,,,,,,,,,,,
424.754,1.25262,0.79714,10,,,,,,,,,,,,,,,,,,,,,,,,,,,,,,,,,,,,,
425.454,1.2525,0.84416,10,,,,,,,,,,,,,,,,,,,,,,,,,,,,,,,,,,,,,
426.154,1.25245,0.79142,10,,,,,,,,,,,,,,,,,,,,,,,,,,,,,,,,,,,,,
426.854,1.25256,0.82311,10,,,,,,,,,,,,,,,,,,,,,,,,,,,,,,,,,,,,,
427.554,1.25262,0.75798,10,,,,,,,,,,,,,,,,,,,,,,,,,,,,,,,,,,,,,
428.254,1.25267,0.8024,10,,,,,,,,,,,,,,,,,,,,,,,,,,,,,,,,,,,,,
428.954,1.25267,0.7759,10,,,,,,,,,,,,,,,,,,,,,,,,,,,,,,,,,,,,,
429.654,1.25273,0.83183,10,,,,,,,,,,,,,,,,,,,,,,,,,,,,,,,,,,,,,
430.354,1.25279,0.77675,10,,,,,,,,,,,,,,,,,,,,,,,,,,,,,,,,,,,,,
431.054,1.25279,0.82611,10,,,,,,,,,,,,,,,,,,,,,,,,,,,,,,,,,,,,,
431.754,1.25284,0.80045,10,,,,,,,,,,,,,,,,,,,,,,,,,,,,,,,,,,,,,
432.454,1.25296,0.81611,10,,,,,,,,,,,,,,,,,,,,,,,,,,,,,,,,,,,,,
433.154,1.25307,0.77801,10,,,,,,,,,,,,,,,,,,,,,,,,,,,,,,,,,,,,,
433.854,1.25324,0.79302,10,,,,,,,,,,,,,,,,,,,,,,,,,,,,,,,,,,,,,
434.554,1.25347,0.84647,10,,,,,,,,,,,,,,,,,,,,,,,,,,,,,,,,,,,,,
435.254,1.25364,0.79177,10,,,,,,,,,,,,,,,,,,,,,,,,,,,,,,,,,,,,,
435.954,1.25386,0.80041,10,,,,,,,,,,,,,,,,,,,,,,,,,,,,,,,,,,,,,
436.654,1.2542,0.80716,10,,,,,,,,,,,,,,,,,,,,,,,,,,,,,,,,,,,,,
437.354,1.25466,0.80225,10,,,,,,,,,,,,,,,,,,,,,,,,,,,,,,,,,,,,,
438.054,1.25528,0.81417,10,,,,,,,,,,,,,,,,,,,,,,,,,,,,,,,,,,,,,
438.754,1.25619,0.7967,10,,,,,,,,,,,,,,,,,,,,,,,,,,,,,,,,,,,,,
439.454,1.25721,0.81377,10,,,,,,,,,,,,,,,,,,,,,,,,,,,,,,,,,,,,,
440.154,1.25806,0.81549,10,,,,,,,,,,,,,,,,,,,,,,,,,,,,,,,,,,,,,
440.854,1.2584,0.84019,10,,,,,,,,,,,,,,,,,,,,,,,,,,,,,,,,,,,,,
441.554,1.25851,0.87636,10,,,,,,,,,,,,,,,,,,,,,,,,,,,,,,,,,,,,,
442.254,1.25845,0.85812,10,,,,,,,,,,,,,,,,,,,,,,,,,,,,,,,,,,,,,
442.954,1.2584,0.80334,10,,,,,,,,,,,,,,,,,,,,,,,,,,,,,,,,,,,,,
443.654,1.25834,0.84093,10,,,,,,,,,,,,,,,,,,,,,,,,,,,,,,,,,,,,,
444.354,1.25823,0.85185,10,,,,,,,,,,,,,,,,,,,,,,,,,,,,,,,,,,,,,
445.054,1.25811,0.95301,10,,,,,,,,,,,,,,,,,,,,,,,,,,,,,,,,,,,,,
445.754,1.258,0.84969,10,,,,,,,,,,,,,,,,,,,,,,,,,,,,,,,,,,,,,
446.454,1.25783,0.89533,10,,,,,,,,,,,,,,,,,,,,,,,,,,,,,,,,,,,,,
447.154,1.25755,0.8135,10,,,,,,,,,,,,,,,,,,,,,,,,,,,,,,,,,,,,,
447.854,1.25709,0.86353,10,,,,,,,,,,,,,,,,,,,,,,,,,,,,,,,,,,,,,
448.554,1.25658,0.87271,10,,,,,,,,,,,,,,,,,,,,,,,,,,,,,,,,,,,,,
449.254,1.25573,0.82611,10,,,,,,,,,,,,,,,,,,,,,,,,,,,,,,,,,,,,,
449.954,1.25477,0.79803,10,,,,,,,,,,,,,,,,,,,,,,,,,,,,,,,,,,,,,
450.654,1.25381,0.84216,10,,,,,,,,,,,,,,,,,,,,,,,,,,,,,,,,,,,,,
451.354,1.2529,0.79889,10,,,,,,,,,,,,,,,,,,,,,,,,,,,,,,,,,,,,,
452.054,1.25222,0.86545,10,,,,,,,,,,,,,,,,,,,,,,,,,,,,,,,,,,,,,
452.754,1.25188,0.82642,10,,,,,,,,,,,,,,,,,,,,,,,,,,,,,,,,,,,,,
453.454,1.25143,0.81777,10,,,,,,,,,,,,,,,,,,,,,,,,,,,,,,,,,,,,,
454.154,1.25109,0.82257,10,,,,,,,,,,,,,,,,,,,,,,,,,,,,,,,,,,,,,
454.854,1.25086,0.83919,10,,,,,,,,,,,,,,,,,,,,,,,,,,,,,,,,,,,,,
455.554,1.25052,0.80531,10,,,,,,,,,,,,,,,,,,,,,,,,,,,,,,,,,,,,,
456.254,1.25041,0.80104,10,,,,,,,,,,,,,,,,,,,,,,,,,,,,,,,,,,,,,
456.954,1.25035,0.80207,10,,,,,,,,,,,,,,,,,,,,,,,,,,,,,,,,,,,,,
457.654,1.25029,0.80351,10,,,,,,,,,,,,,,,,,,,,,,,,,,,,,,,,,,,,,
458.354,1.25024,0.77325,10,,,,,,,,,,,,,,,,,,,,,,,,,,,,,,,,,,,,,
459.054,1.25035,0.8045,10,,,,,,,,,,,,,,,,,,,,,,,,,,,,,,,,,,,,,
459.754,1.25041,0.78732,10,,,,,,,,,,,,,,,,,,,,,,,,,,,,,,,,,,,,,
460.454,1.25046,0.79054,10,,,,,,,,,,,,,,,,,,,,,,,,,,,,,,,,,,,,,
461.154,1.25046,0.77248,10,,,,,,,,,,,,,,,,,,,,,,,,,,,,,,,,,,,,,
461.854,1.25041,0.84628,10,,,,,,,,,,,,,,,,,,,,,,,,,,,,,,,,,,,,,
462.554,1.25041,0.84268,10,,,,,,,,,,,,,,,,,,,,,,,,,,,,,,,,,,,,,
463.254,1.25052,0.81387,10,,,,,,,,,,,,,,,,,,,,,,,,,,,,,,,,,,,,,
463.954,1.25058,0.88021,10,,,,,,,,,,,,,,,,,,,,,,,,,,,,,,,,,,,,,
464.654,1.25058,0.83576,10,,,,,,,,,,,,,,,,,,,,,,,,,,,,,,,,,,,,,
465.354,1.25058,0.83386,10,,,,,,,,,,,,,,,,,,,,,,,,,,,,,,,,,,,,,
466.054,1.25052,0.87108,10,,,,,,,,,,,,,,,,,,,,,,,,,,,,,,,,,,,,,
466.754,1.25052,0.81507,10,,,,,,,,,,,,,,,,,,,,,,,,,,,,,,,,,,,,,
467.454,1.25052,0.81631,10,,,,,,,,,,,,,,,,,,,,,,,,,,,,,,,,,,,,,
468.154,1.25052,0.82358,10,,,,,,,,,,,,,,,,,,,,,,,,,,,,,,,,,,,,,
468.854,1.25052,0.84669,10,,,,,,,,,,,,,,,,,,,,,,,,,,,,,,,,,,,,,
469.554,1.25063,0.77677,10,,,,,,,,,,,,,,,,,,,,,,,,,,,,,,,,,,,,,
470.254,1.25063,0.83064,10,,,,,,,,,,,,,,,,,,,,,,,,,,,,,,,,,,,,,
470.954,1.25063,0.76906,10,,,,,,,,,,,,,,,,,,,,,,,,,,,,,,,,,,,,,
471.654,1.25063,0.83673,10,,,,,,,,,,,,,,,,,,,,,,,,,,,,,,,,,,,,,
472.354,1.25063,0.7968,10,,,,,,,,,,,,,,,,,,,,,,,,,,,,,,,,,,,,,
473.054,1.25063,0.8614,10,,,,,,,,,,,,,,,,,,,,,,,,,,,,,,,,,,,,,
473.754,1.25063,0.83427,10,,,,,,,,,,,,,,,,,,,,,,,,,,,,,,,,,,,,,
474.454,1.25058,0.86575,10,,,,,,,,,,,,,,,,,,,,,,,,,,,,,,,,,,,,,
475.154,1.25052,0.88008,10,,,,,,,,,,,,,,,,,,,,,,,,,,,,,,,,,,,,,
475.854,1.25052,0.87039,10,,,,,,,,,,,,,,,,,,,,,,,,,,,,,,,,,,,,,
476.554,1.25052,0.85473,10,,,,,,,,,,,,,,,,,,,,,,,,,,,,,,,,,,,,,
477.254,1.25052,0.87457,10,,,,,,,,,,,,,,,,,,,,,,,,,,,,,,,,,,,,,
477.954,1.25046,0.8249,10,,,,,,,,,,,,,,,,,,,,,,,,,,,,,,,,,,,,,
478.654,1.25046,0.84453,10,,,,,,,,,,,,,,,,,,,,,,,,,,,,,,,,,,,,,
479.354,1.25041,0.84458,10,,,,,,,,,,,,,,,,,,,,,,,,,,,,,,,,,,,,,
480.054,1.25041,0.86224,10,,,,,,,,,,,,,,,,,,,,,,,,,,,,,,,,,,,,,
480.754,1.25041,0.85596,10,,,,,,,,,,,,,,,,,,,,,,,,,,,,,,,,,,,,,
481.454,1.25035,0.81641,10,,,,,,,,,,,,,,,,,,,,,,,,,,,,,,,,,,,,,
482.154,1.25035,0.86237,10,,,,,,,,,,,,,,,,,,,,,,,,,,,,,,,,,,,,,
482.854,1.25029,0.82702,10,,,,,,,,,,,,,,,,,,,,,,,,,,,,,,,,,,,,,
483.554,1.25029,0.81753,10,,,,,,,,,,,,,,,,,,,,,,,,,,,,,,,,,,,,,
484.254,1.25029,0.83611,10,,,,,,,,,,,,,,,,,,,,,,,,,,,,,,,,,,,,,
484.954,1.25029,0.84121,10,,,,,,,,,,,,,,,,,,,,,,,,,,,,,,,,,,,,,
485.654,1.25024,0.82822,10,,,,,,,,,,,,,,,,,,,,,,,,,,,,,,,,,,,,,
486.354,1.25024,0.81346,10,,,,,,,,,,,,,,,,,,,,,,,,,,,,,,,,,,,,,
487.054,1.25024,0.86363,10,,,,,,,,,,,,,,,,,,,,,,,,,,,,,,,,,,,,,
487.754,1.25035,0.82001,10,,,,,,,,,,,,,,,,,,,,,,,,,,,,,,,,,,,,,
488.454,1.25035,0.81463,10,,,,,,,,,,,,,,,,,,,,,,,,,,,,,,,,,,,,,
489.154,1.25035,0.80948,10,,,,,,,,,,,,,,,,,,,,,,,,,,,,,,,,,,,,,
489.854,1.25035,0.78846,10,,,,,,,,,,,,,,,,,,,,,,,,,,,,,,,,,,,,,
490.554,1.25035,0.81563,10,,,,,,,,,,,,,,,,,,,,,,,,,,,,,,,,,,,,,
491.254,1.25035,0.80396,10,,,,,,,,,,,,,,,,,,,,,,,,,,,,,,,,,,,,,
491.954,1.25035,0.82098,10,,,,,,,,,,,,,,,,,,,,,,,,,,,,,,,,,,,,,
492.654,1.25035,0.84987,10,,,,,,,,,,,,,,,,,,,,,,,,,,,,,,,,,,,,,
493.354,1.25035,0.81966,10,,,,,,,,,,,,,,,,,,,,,,,,,,,,,,,,,,,,,
494.054,1.25035,0.87462,10,,,,,,,,,,,,,,,,,,,,,,,,,,,,,,,,,,,,,
494.754,1.25035,0.79758,10,,,,,,,,,,,,,,,,,,,,,,,,,,,,,,,,,,,,,
495.454,1.25035,0.82795,10,,,,,,,,,,,,,,,,,,,,,,,,,,,,,,,,,,,,,
496.154,1.25035,0.88157,10,,,,,,,,,,,,,,,,,,,,,,,,,,,,,,,,,,,,,
496.854,1.25035,0.7846,10,,,,,,,,,,,,,,,,,,,,,,,,,,,,,,,,,,,,,
497.554,1.25035,0.81019,10,,,,,,,,,,,,,,,,,,,,,,,,,,,,,,,,,,,,,
498.254,1.25035,0.79585,10,,,,,,,,,,,,,,,,,,,,,,,,,,,,,,,,,,,,,
498.954,1.25035,0.78498,10,,,,,,,,,,,,,,,,,,,,,,,,,,,,,,,,,,,,,
499.654,1.25035,0.83091,10,,,,,,,,,,,,,,,,,,,,,,,,,,,,,,,,,,,,,
500.354,1.25035,0.82049,10,,,,,,,,,,,,,,,,,,,,,,,,,,,,,,,,,,,,,
501.054,1.25035,0.82,10,,,,,,,,,,,,,,,,,,,,,,,,,,,,,,,,,,,,,
501.754,1.25035,0.80789,10,,,,,,,,,,,,,,,,,,,,,,,,,,,,,,,,,,,,,
502.454,1.25035,0.83123,10,,,,,,,,,,,,,,,,,,,,,,,,,,,,,,,,,,,,,
503.154,1.25035,0.78298,10,,,,,,,,,,,,,,,,,,,,,,,,,,,,,,,,,,,,,
503.854,1.25035,0.81835,10,,,,,,,,,,,,,,,,,,,,,,,,,,,,,,,,,,,,,
504.554,1.25035,0.86258,10,,,,,,,,,,,,,,,,,,,,,,,,,,,,,,,,,,,,,
505.254,1.25035,0.81893,10,,,,,,,,,,,,,,,,,,,,,,,,,,,,,,,,,,,,,
505.954,1.25035,0.79949,10,,,,,,,,,,,,,,,,,,,,,,,,,,,,,,,,,,,,,
506.654,1.25035,0.82955,10,,,,,,,,,,,,,,,,,,,,,,,,,,,,,,,,,,,,,
507.354,1.25029,0.84403,10,,,,,,,,,,,,,,,,,,,,,,,,,,,,,,,,,,,,,
508.054,1.25024,0.84847,10,,,,,,,,,,,,,,,,,,,,,,,,,,,,,,,,,,,,,
508.754,1.25024,0.79649,10,,,,,,,,,,,,,,,,,,,,,,,,,,,,,,,,,,,,,
509.454,1.25012,0.90768,10,,,,,,,,,,,,,,,,,,,,,,,,,,,,,,,,,,,,,
510.154,1.2499,0.84054,10,,,,,,,,,,,,,,,,,,,,,,,,,,,,,,,,,,,,,
510.854,1.24729,0.83599,10,,,,,,,,,,,,,,,,,,,,,,,,,,,,,,,,,,,,,
511.554,1.24213,0.78039,10,,,,,,,,,,,,,,,,,,,,,,,,,,,,,,,,,,,,,
512.254,1.24038,0.78087,10,,,,,,,,,,,,,,,,,,,,,,,,,,,,,,,,,,,,,
512.954,1.23987,0.83318,10,,,,,,,,,,,,,,,,,,,,,,,,,,,,,,,,,,,,,
513.654,1.23975,0.81721,10,,,,,,,,,,,,,,,,,,,,,,,,,,,,,,,,,,,,,
514.354,1.2397,0.79423,10,,,,,,,,,,,,,,,,,,,,,,,,,,,,,,,,,,,,,
515.054,1.23975,0.80292,10,,,,,,,,,,,,,,,,,,,,,,,,,,,,,,,,,,,,,
515.754,1.23992,0.74777,10,,,,,,,,,,,,,,,,,,,,,,,,,,,,,,,,,,,,,
516.454,1.24004,0.73647,10,,,,,,,,,,,,,,,,,,,,,,,,,,,,,,,,,,,,,
517.154,1.24009,0.78562,10,,,,,,,,,,,,,,,,,,,,,,,,,,,,,,,,,,,,,
517.854,1.24026,0.76597,10,,,,,,,,,,,,,,,,,,,,,,,,,,,,,,,,,,,,,
518.554,1.24055,0.7453,10,,,,,,,,,,,,,,,,,,,,,,,,,,,,,,,,,,,,,
519.254,1.24089,0.74616,10,,,,,,,,,,,,,,,,,,,,,,,,,,,,,,,,,,,,,
519.954,1.2414,0.72396,10,,,,,,,,,,,,,,,,,,,,,,,,,,,,,,,,,,,,,
520.654,1.24213,0.78701,10,,,,,,,,,,,,,,,,,,,,,,,,,,,,,,,,,,,,,
521.354,1.24361,0.76217,10,,,,,,,,,,,,,,,,,,,,,,,,,,,,,,,,,,,,,
522.054,1.24786,0.84522,10,,,,,,,,,,,,,,,,,,,,,,,,,,,,,,,,,,,,,
522.656,1.25568,0.86763,10,,,,,,,,,,,,,,,,,,,,,,,,,,,,,,,,,,,,,
523.356,6.83921,279.00296,10,,,,,,,,,,,,,,,,,,,,,,,,,,,,,,,,,,,,,
524.056,12.67276,355.22141,10,,,,,,,,,,,,,,,,,,,,,,,,,,,,,,,,,,,,,
524.756,18.50603,37.44626,10,,,,,,,,,,,,,,,,,,,,,,,,,,,,,,,,,,,,,
525.456,24.33935,12.24585,10,,,,,,,,,,,,,,,,,,,,,,,,,,,,,,,,,,,,,
526.156,30.17262,-1.43798,10,,,,,,,,,,,,,,,,,,,,,,,,,,,,,,,,,,,,,
526.856,36.00589,-2.95281,10,,,,,,,,,,,,,,,,,,,,,,,,,,,,,,,,,,,,,
527.556,41.83926,-3.44107,10,,,,,,,,,,,,,,,,,,,,,,,,,,,,,,,,,,,,,
528.256,47.67258,-3.51439,10,,,,,,,,,,,,,,,,,,,,,,,,,,,,,,,,,,,,,
528.956,53.50602,-3.4454,10,,,,,,,,,,,,,,,,,,,,,,,,,,,,,,,,,,,,,
529.124,54.90592,-3.48574,10,,,,,,,,,,,,,,,,,,,,,,,,,,,,,,,,,,,,,