File: combined_ligament_solver/data/processed/Data Sheet 3_S152635_ACL.csv
Specimen properties : Length,32,mm,Unnamed: 3,Unnamed: 4,Unnamed: 5,Unnamed: 6,Unnamed: 7,Unnamed: 8,Unnamed: 9,Unnamed: 10,Unnamed: 11,Stress-Strain,Unnamed: 13,Unnamed: 14,Unnamed: 15,Unnamed: 16,Unnamed: 17,Unnamed: 18,Unnamed: 19,Unnamed: 20,Unnamed: 21,Unnamed: 22,Unnamed: 23,Unnamed: 24,Unnamed: 25,Unnamed: 26,Unnamed: 27,Linear,Unnamed: 29,Unnamed: 30,Unnamed: 31,Unnamed: 32,Unnamed: 33,Modulus,Unnamed: 35,Failure,Unnamed: 37,Unnamed: 38,Unnamed: 39,Unnamed: 40
Cross Section Average,37.7755,mm2,,,,,,,,,,Polynomial Coefficients,,,,,,,,,,,,,,,,Force,,Stress,Extension,Strain,,Secant,Tangent,Load,Stress,Extension,Strain,Stiffness
Time,Extension,Load,Total cycle count,,,Extension,Load,Strain,Stress,E-tan,,X6,0.0,,,,,,,,,Strain,Stress,E-tan,,,,(N),,(MPa),(mm),(%),,(MPa),(MPa),(N),(MPa),(mm),(%),(N/mm)
(s),(mm),(N),,,,(mm),(N),(mm/mm),(MPa),(MPa),,X5,-531638.8003270214,,,,,,,,,(mm/mm),(MPa),(MPa),,,,72.02999824930392,,1.906791392550831,3.168,9.9,,19.26051911667506,46.46885317748412,161.69922,2.793921192307183,3.96666,12.3958125,22.73674187162371
0.7,2.09922,1.08038,0,,,8.26109,161.69922,0.176041875,,,,,,,,,,,,,,0.007,0.003756342858337828,1.6918922251672721,,,,,,,,,,,,,,,,
1.5,2.23238,1.30259,0,,,14.92776,146.31274,,,,,,,,,,,,,,,0.015,0.026592334160112974,3.598137336146073,,,,,,,,,,,,,,,,
2.3,2.36595,1.67736,0,,,,,,,,,,,,,,,,,,,0.023,0.06138021804293262,4.916039635853605,,,,,,,,,,,,,,,,
3.1,2.49911,1.95236,0,,,,,,,,,,,,,,,,,,,0.031,0.10745753480187788,6.506220762915995,,,,,,,,,,,,,,,,
3.9,2.63234,2.55474,0,,,,,,,,,,,,,,,,,,,0.039,0.1698708978769239,8.96799125282279,,,,,,,,,,,,,,,,
4.7,2.76596,3.23133,0,,,,,,,,,,,,,,,,,,,0.047,0.257285505027846,12.639350537926685,,,,,,,,,,,,,,,,
5.5,2.89912,4.08575,0,,,,,,,,,,,,,,,,,,,0.055,0.37989464950912594,17.596986947443646,,,,,,,,,,,,,,,,
6.3,3.03235,4.97749,0,,,,,,,,,,,,,,,,,,,0.063,0.5473292312448571,23.656277707452464,,,,,,,,,,,,,,,,
7.1,3.16591,6.13364,0,,,,,,,,,,,,,,,,,,,0.071,0.7665672680036524,30.37128894089598,,,,,,,,,,,,,,,,
7.9,3.29913,7.61607,0,,,,,,,,,,,,,,,,,,,0.079,1.0398434065735505,37.03477566758126,,,,,,,,,,,,,,,,
8.7,3.43241,9.14851,0,,,,,,,,,,,,,,,,,,,0.087,1.362558433936917,42.678181804175225,,,,,,,,,,,,,,,,
9.5,3.56592,10.96311,0,,,,,,,,,,,,,,,,,,,0.095,1.7211887884453556,46.07164016420934,,,,,,,,,,,,,,,,
10.3,3.69909,12.96691,0,,,,,,,,,,,,,,,,,,,0.103,2.0911960709946165,45.723972458081754,,,,,,,,,,,,,,,,
11.1,3.83242,15.03928,0,,,,,,,,,,,,,,,,,,,0.111,2.4349365561994967,39.88268929305057,,,,,,,,,,,,,,,,
11.9,3.96593,17.16555,0,,,,,,,,,,,,,,,,,,,0.119,2.6995707035687424,26.533990173235964,,,,,,,,,,,,,,,,
12.7,4.0991,19.35681,0,,,,,,,,,,,,,,,,,,,0.127,2.8149726686799728,3.4027634996309755,,,,,,,,,,,,,,,,
13.5,4.23249,22.38057,0,,,,,,,,,,,,,,,,,,,0.135,,,,,,,,,,,,,,,,,,
14.3,4.36588,25.71543,0,,,,,,,,,,,,,,,,,,,0.143,,,,,,,,,,,,,,,,,,
15.1,4.49905,29.09292,0,,,,,,,,,,,,,,,,,,,0.151,,,,,,,,,,,,,,,,,,
15.9,4.6325,32.81432,0,,,,,,,,,,,,,,,,,,,0.159,,,,,,,,,,,,,,,,,,
16.7,4.76584,36.81961,0,,,,,,,,,,,,,,,,,,,0.167,,,,,,,,,,,,,,,,,,
17.38,4.84999,39.70446,0.5,,,,,,,,,,,,,,,,,,,0.175,,,,,,,,,,,,,,,,,,
18.18,4.71229,32.19031,0.5,,,,,,,,,,,,,,,,,,,0.183,,,,,,,,,,,,,,,,,,
18.98,4.57889,26.73636,0.5,,,,,,,,,,,,,,,,,,,0.191,,,,,,,,,,,,,,,,,,
19.78,4.44544,22.30833,0.5,,,,,,,,,,,,,,,,,,,0.199,,,,,,,,,,,,,,,,,,
20.58,4.31222,18.5245,0.5,,,,,,,,,,,,,,,,,,,,,,,,,,,,,,,,,,,,,
21.38,4.17883,15.36619,0.5,,,,,,,,,,,,,,,,,,,,,,,,,,,,,,,,,,,,,
22.18,4.04543,12.7206,0.5,,,,,,,,,,,,,,,,,,,,,,,,,,,,,,,,,,,,,
22.98,3.91215,10.38272,0.5,,,,,,,,,,,,,,,,,,,,,,,,,,,,,,,,,,,,,
23.78,3.77882,8.44654,0.5,,,,,,,,,,,,,,,,,,,,,,,,,,,,,,,,,,,,,
24.58,3.64554,6.83379,0.5,,,,,,,,,,,,,,,,,,,,,,,,,,,,,,,,,,,,,
25.38,3.51214,5.46351,0.5,,,,,,,,,,,,,,,,,,,,,,,,,,,,,,,,,,,,,
26.18,3.37881,4.28788,0.5,,,,,,,,,,,,,,,,,,,,,,,,,,,,,,,,,,,,,
26.98,3.24553,3.36976,0.5,,,,,,,,,,,,,,,,,,,,,,,,,,,,,,,,,,,,,
27.78,3.11213,2.69933,0.5,,,,,,,,,,,,,,,,,,,,,,,,,,,,,,,,,,,,,
28.58,2.97874,2.19732,0.5,,,,,,,,,,,,,,,,,,,,,,,,,,,,,,,,,,,,,
29.38,2.84552,1.73168,0.5,,,,,,,,,,,,,,,,,,,,,,,,,,,,,,,,,,,,,
30.18,2.71218,1.40739,0.5,,,,,,,,,,,,,,,,,,,,,,,,,,,,,,,,,,,,,
30.98,2.57873,1.06535,0.5,,,,,,,,,,,,,,,,,,,,,,,,,,,,,,,,,,,,,
31.488,2.52342,1.02543,1,,,,,,,,,,,,,,,,,,,,,,,,,,,,,,,,,,,,,
32.288,2.66186,1.40134,1,,,,,,,,,,,,,,,,,,,,,,,,,,,,,,,,,,,,,
33.088,2.79508,1.75068,1,,,,,,,,,,,,,,,,,,,,,,,,,,,,,,,,,,,,,
33.888,2.92848,2.22107,1,,,,,,,,,,,,,,,,,,,,,,,,,,,,,,,,,,,,,
34.688,3.06181,2.90393,1,,,,,,,,,,,,,,,,,,,,,,,,,,,,,,,,,,,,,
35.488,3.19504,3.80257,1,,,,,,,,,,,,,,,,,,,,,,,,,,,,,,,,,,,,,
36.288,3.32854,4.77485,1,,,,,,,,,,,,,,,,,,,,,,,,,,,,,,,,,,,,,
37.088,3.46177,6.06628,1,,,,,,,,,,,,,,,,,,,,,,,,,,,,,,,,,,,,,
37.888,3.59505,7.6098,1,,,,,,,,,,,,,,,,,,,,,,,,,,,,,,,,,,,,,
38.688,3.72861,9.35496,1,,,,,,,,,,,,,,,,,,,,,,,,,,,,,,,,,,,,,
39.488,3.86178,11.42005,1,,,,,,,,,,,,,,,,,,,,,,,,,,,,,,,,,,,,,
40.288,3.99506,13.83099,1,,,,,,,,,,,,,,,,,,,,,,,,,,,,,,,,,,,,,
41.088,4.12862,16.48143,1,,,,,,,,,,,,,,,,,,,,,,,,,,,,,,,,,,,,,
41.888,4.26173,19.29129,1,,,,,,,,,,,,,,,,,,,,,,,,,,,,,,,,,,,,,
42.688,4.39501,22.63492,1,,,,,,,,,,,,,,,,,,,,,,,,,,,,,,,,,,,,,
43.488,4.52857,26.42136,1,,,,,,,,,,,,,,,,,,,,,,,,,,,,,,,,,,,,,
44.288,4.66174,30.61477,1,,,,,,,,,,,,,,,,,,,,,,,,,,,,,,,,,,,,,
45.088,4.79513,35.20631,1,,,,,,,,,,,,,,,,,,,,,,,,,,,,,,,,,,,,,
45.888,4.92858,40.01163,1,,,,,,,,,,,,,,,,,,,,,,,,,,,,,,,,,,,,,
46.59,4.81196,33.88208,1.5,,,,,,,,,,,,,,,,,,,,,,,,,,,,,,,,,,,,,
47.39,4.67846,28.3228,1.5,,,,,,,,,,,,,,,,,,,,,,,,,,,,,,,,,,,,,
48.19,4.54506,23.51563,1.5,,,,,,,,,,,,,,,,,,,,,,,,,,,,,,,,,,,,,
48.99,4.4119,19.63208,1.5,,,,,,,,,,,,,,,,,,,,,,,,,,,,,,,,,,,,,
49.79,4.27839,16.23302,1.5,,,,,,,,,,,,,,,,,,,,,,,,,,,,,,,,,,,,,
50.59,4.14522,13.39445,1.5,,,,,,,,,,,,,,,,,,,,,,,,,,,,,,,,,,,,,
51.39,4.01189,10.97452,1.5,,,,,,,,,,,,,,,,,,,,,,,,,,,,,,,,,,,,,
52.19,3.87838,8.9845,1.5,,,,,,,,,,,,,,,,,,,,,,,,,,,,,,,,,,,,,
52.99,3.74521,7.27192,1.5,,,,,,,,,,,,,,,,,,,,,,,,,,,,,,,,,,,,,
53.79,3.61182,5.82076,1.5,,,,,,,,,,,,,,,,,,,,,,,,,,,,,,,,,,,,,
54.59,3.47837,4.61359,1.5,,,,,,,,,,,,,,,,,,,,,,,,,,,,,,,,,,,,,
55.39,3.3452,3.67637,1.5,,,,,,,,,,,,,,,,,,,,,,,,,,,,,,,,,,,,,
56.19,3.21181,2.86668,1.5,,,,,,,,,,,,,,,,,,,,,,,,,,,,,,,,,,,,,
56.99,3.07847,2.36198,1.5,,,,,,,,,,,,,,,,,,,,,,,,,,,,,,,,,,,,,
57.79,2.94525,1.89747,1.5,,,,,,,,,,,,,,,,,,,,,,,,,,,,,,,,,,,,,
58.59,2.81169,1.49889,1.5,,,,,,,,,,,,,,,,,,,,,,,,,,,,,,,,,,,,,
59.39,2.67846,1.26521,1.5,,,,,,,,,,,,,,,,,,,,,,,,,,,,,,,,,,,,,
60.168,2.54881,0.99995,2,,,,,,,,,,,,,,,,,,,,,,,,,,,,,,,,,,,,,
60.772,2.64917,1.25075,2,,,,,,,,,,,,,,,,,,,,,,,,,,,,,,,,,,,,,
61.572,2.78239,1.58579,2,,,,,,,,,,,,,,,,,,,,,,,,,,,,,,,,,,,,,
62.372,2.91567,2.01049,2,,,,,,,,,,,,,,,,,,,,,,,,,,,,,,,,,,,,,
63.172,3.04929,2.60205,2,,,,,,,,,,,,,,,,,,,,,,,,,,,,,,,,,,,,,
63.972,3.18246,3.30118,2,,,,,,,,,,,,,,,,,,,,,,,,,,,,,,,,,,,,,
64.772,3.31574,4.24595,2,,,,,,,,,,,,,,,,,,,,,,,,,,,,,,,,,,,,,
65.572,3.4493,5.36676,2,,,,,,,,,,,,,,,,,,,,,,,,,,,,,,,,,,,,,
66.372,3.58241,6.70313,2,,,,,,,,,,,,,,,,,,,,,,,,,,,,,,,,,,,,,
67.172,3.71575,8.38776,2,,,,,,,,,,,,,,,,,,,,,,,,,,,,,,,,,,,,,
67.972,3.8492,10.31846,2,,,,,,,,,,,,,,,,,,,,,,,,,,,,,,,,,,,,,
68.772,3.98236,12.53625,2,,,,,,,,,,,,,,,,,,,,,,,,,,,,,,,,,,,,,
69.572,4.11581,15.07014,2,,,,,,,,,,,,,,,,,,,,,,,,,,,,,,,,,,,,,
70.372,4.24921,17.72295,2,,,,,,,,,,,,,,,,,,,,,,,,,,,,,,,,,,,,,
71.172,4.38243,20.83838,2,,,,,,,,,,,,,,,,,,,,,,,,,,,,,,,,,,,,,
71.972,4.51582,24.55618,2,,,,,,,,,,,,,,,,,,,,,,,,,,,,,,,,,,,,,
72.772,4.64916,28.63107,2,,,,,,,,,,,,,,,,,,,,,,,,,,,,,,,,,,,,,
73.572,4.78238,33.22366,2,,,,,,,,,,,,,,,,,,,,,,,,,,,,,,,,,,,,,
74.372,4.91595,38.19453,2,,,,,,,,,,,,,,,,,,,,,,,,,,,,,,,,,,,,,
75.054,4.89577,36.44949,2.5,,,,,,,,,,,,,,,,,,,,,,,,,,,,,,,,,,,,,
75.854,4.76255,30.22025,2.5,,,,,,,,,,,,,,,,,,,,,,,,,,,,,,,,,,,,,
76.654,4.62921,25.19545,2.5,,,,,,,,,,,,,,,,,,,,,,,,,,,,,,,,,,,,,
77.454,4.49582,20.99719,2.5,,,,,,,,,,,,,,,,,,,,,,,,,,,,,,,,,,,,,
78.254,4.36248,17.3915,2.5,,,,,,,,,,,,,,,,,,,,,,,,,,,,,,,,,,,,,
79.054,4.22909,14.37141,2.5,,,,,,,,,,,,,,,,,,,,,,,,,,,,,,,,,,,,,
79.854,4.09581,11.86305,2.5,,,,,,,,,,,,,,,,,,,,,,,,,,,,,,,,,,,,,
80.654,3.96253,9.68642,2.5,,,,,,,,,,,,,,,,,,,,,,,,,,,,,,,,,,,,,
81.454,3.82914,7.86386,2.5,,,,,,,,,,,,,,,,,,,,,,,,,,,,,,,,,,,,,
82.254,3.6958,6.32117,2.5,,,,,,,,,,,,,,,,,,,,,,,,,,,,,,,,,,,,,
83.054,3.56252,5.05583,2.5,,,,,,,,,,,,,,,,,,,,,,,,,,,,,,,,,,,,,
83.854,3.42901,4.03671,2.5,,,,,,,,,,,,,,,,,,,,,,,,,,,,,,,,,,,,,
84.654,3.29585,3.1736,2.5,,,,,,,,,,,,,,,,,,,,,,,,,,,,,,,,,,,,,
85.454,3.16251,2.56106,2.5,,,,,,,,,,,,,,,,,,,,,,,,,,,,,,,,,,,,,
86.254,3.02906,2.10144,2.5,,,,,,,,,,,,,,,,,,,,,,,,,,,,,,,,,,,,,
87.054,2.89584,1.6783,2.5,,,,,,,,,,,,,,,,,,,,,,,,,,,,,,,,,,,,,
87.854,2.76256,1.33509,2.5,,,,,,,,,,,,,,,,,,,,,,,,,,,,,,,,,,,,,
88.654,2.62911,1.09489,2.5,,,,,,,,,,,,,,,,,,,,,,,,,,,,,,,,,,,,,
89.188,2.64106,1.10469,3,,,,,,,,,,,,,,,,,,,,,,,,,,,,,,,,,,,,,
89.988,2.77451,1.47741,3,,,,,,,,,,,,,,,,,,,,,,,,,,,,,,,,,,,,,
90.788,2.90779,1.88231,3,,,,,,,,,,,,,,,,,,,,,,,,,,,,,,,,,,,,,
91.588,3.04113,2.34766,3,,,,,,,,,,,,,,,,,,,,,,,,,,,,,,,,,,,,,
92.388,3.17452,2.98692,3,,,,,,,,,,,,,,,,,,,,,,,,,,,,,,,,,,,,,
93.188,3.3078,3.81427,3,,,,,,,,,,,,,,,,,,,,,,,,,,,,,,,,,,,,,
93.988,3.4412,4.91713,3,,,,,,,,,,,,,,,,,,,,,,,,,,,,,,,,,,,,,
94.788,3.57448,6.17452,3,,,,,,,,,,,,,,,,,,,,,,,,,,,,,,,,,,,,,
95.588,3.70781,7.76044,3,,,,,,,,,,,,,,,,,,,,,,,,,,,,,,,,,,,,,
96.388,3.84115,9.57506,3,,,,,,,,,,,,,,,,,,,,,,,,,,,,,,,,,,,,,
97.188,3.97449,11.74477,3,,,,,,,,,,,,,,,,,,,,,,,,,,,,,,,,,,,,,
97.988,4.10777,14.17661,3,,,,,,,,,,,,,,,,,,,,,,,,,,,,,,,,,,,,,
98.788,4.24122,16.75712,3,,,,,,,,,,,,,,,,,,,,,,,,,,,,,,,,,,,,,
99.588,4.3745,19.74104,3,,,,,,,,,,,,,,,,,,,,,,,,,,,,,,,,,,,,,
100.388,4.50772,23.34471,3,,,,,,,,,,,,,,,,,,,,,,,,,,,,,,,,,,,,,
101.188,4.64111,27.39986,3,,,,,,,,,,,,,,,,,,,,,,,,,,,,,,,,,,,,,
101.988,4.77445,31.90345,3,,,,,,,,,,,,,,,,,,,,,,,,,,,,,,,,,,,,,
102.788,4.90779,36.868,3,,,,,,,,,,,,,,,,,,,,,,,,,,,,,,,,,,,,,
103.48,4.95652,38.38712,3.5,,,,,,,,,,,,,,,,,,,,,,,,,,,,,,,,,,,,,
104.28,4.82296,31.65805,3.5,,,,,,,,,,,,,,,,,,,,,,,,,,,,,,,,,,,,,
105.08,4.68956,26.32565,3.5,,,,,,,,,,,,,,,,,,,,,,,,,,,,,,,,,,,,,
105.88,4.55606,21.8989,3.5,,,,,,,,,,,,,,,,,,,,,,,,,,,,,,,,,,,,,
106.68,4.42289,18.17461,3.5,,,,,,,,,,,,,,,,,,,,,,,,,,,,,,,,,,,,,
107.48,4.28944,15.08155,3.5,,,,,,,,,,,,,,,,,,,,,,,,,,,,,,,,,,,,,
108.28,4.15616,12.30974,3.5,,,,,,,,,,,,,,,,,,,,,,,,,,,,,,,,,,,,,
109.08,4.02288,10.08567,3.5,,,,,,,,,,,,,,,,,,,,,,,,,,,,,,,,,,,,,
109.88,3.88937,8.20909,3.5,,,,,,,,,,,,,,,,,,,,,,,,,,,,,,,,,,,,,
110.68,3.75621,6.58881,3.5,,,,,,,,,,,,,,,,,,,,,,,,,,,,,,,,,,,,,
111.48,3.62293,5.30665,3.5,,,,,,,,,,,,,,,,,,,,,,,,,,,,,,,,,,,,,
112.28,3.48936,4.19397,3.5,,,,,,,,,,,,,,,,,,,,,,,,,,,,,,,,,,,,,
113.08,3.3562,3.32619,3.5,,,,,,,,,,,,,,,,,,,,,,,,,,,,,,,,,,,,,
113.88,3.22286,2.62223,3.5,,,,,,,,,,,,,,,,,,,,,,,,,,,,,,,,,,,,,
114.68,3.08935,2.16599,3.5,,,,,,,,,,,,,,,,,,,,,,,,,,,,,,,,,,,,,
115.48,2.95624,1.7322,3.5,,,,,,,,,,,,,,,,,,,,,,,,,,,,,,,,,,,,,
116.28,2.82285,1.41631,3.5,,,,,,,,,,,,,,,,,,,,,,,,,,,,,,,,,,,,,
117.08,2.68934,1.06604,3.5,,,,,,,,,,,,,,,,,,,,,,,,,,,,,,,,,,,,,
117.65,2.62367,0.97307,4,,,,,,,,,,,,,,,,,,,,,,,,,,,,,,,,,,,,,
118.45,2.76216,1.32678,4,,,,,,,,,,,,,,,,,,,,,,,,,,,,,,,,,,,,,
119.25,2.89544,1.74503,4,,,,,,,,,,,,,,,,,,,,,,,,,,,,,,,,,,,,,
120.05,3.02872,2.1933,4,,,,,,,,,,,,,,,,,,,,,,,,,,,,,,,,,,,,,
120.85,3.16228,2.81205,4,,,,,,,,,,,,,,,,,,,,,,,,,,,,,,,,,,,,,
121.65,3.29551,3.6164,4,,,,,,,,,,,,,,,,,,,,,,,,,,,,,,,,,,,,,
122.45,3.42879,4.5436,4,,,,,,,,,,,,,,,,,,,,,,,,,,,,,,,,,,,,,
123.25,3.56218,5.81441,4,,,,,,,,,,,,,,,,,,,,,,,,,,,,,,,,,,,,,
124.05,3.69552,7.26442,4,,,,,,,,,,,,,,,,,,,,,,,,,,,,,,,,,,,,,
124.85,3.82868,9.00892,4,,,,,,,,,,,,,,,,,,,,,,,,,,,,,,,,,,,,,
125.65,3.96219,11.01415,4,,,,,,,,,,,,,,,,,,,,,,,,,,,,,,,,,,,,,
126.45,4.09541,13.32654,4,,,,,,,,,,,,,,,,,,,,,,,,,,,,,,,,,,,,,
127.25,4.22875,15.98363,4,,,,,,,,,,,,,,,,,,,,,,,,,,,,,,,,,,,,,
128.05,4.3622,18.8071,4,,,,,,,,,,,,,,,,,,,,,,,,,,,,,,,,,,,,,
128.85,4.49548,22.28016,4,,,,,,,,,,,,,,,,,,,,,,,,,,,,,,,,,,,,,
129.65,4.62882,26.19411,4,,,,,,,,,,,,,,,,,,,,,,,,,,,,,,,,,,,,,
130.45,4.7621,30.55904,4,,,,,,,,,,,,,,,,,,,,,,,,,,,,,,,,,,,,,
131.25,4.89543,35.54699,4,,,,,,,,,,,,,,,,,,,,,,,,,,,,,,,,,,,,,
131.932,5.00905,40.02369,4.5,,,,,,,,,,,,,,,,,,,,,,,,,,,,,,,,,,,,,
132.732,4.8756,33.17998,4.5,,,,,,,,,,,,,,,,,,,,,,,,,,,,,,,,,,,,,
133.532,4.74215,27.58755,4.5,,,,,,,,,,,,,,,,,,,,,,,,,,,,,,,,,,,,,
134.332,4.60881,22.90636,4.5,,,,,,,,,,,,,,,,,,,,,,,,,,,,,,,,,,,,,
135.132,4.47553,19.08858,4.5,,,,,,,,,,,,,,,,,,,,,,,,,,,,,,,,,,,,,
135.932,4.34208,15.73516,4.5,,,,,,,,,,,,,,,,,,,,,,,,,,,,,,,,,,,,,
136.732,4.20892,12.94834,4.5,,,,,,,,,,,,,,,,,,,,,,,,,,,,,,,,,,,,,
137.532,4.07558,10.6376,4.5,,,,,,,,,,,,,,,,,,,,,,,,,,,,,,,,,,,,,
138.332,3.94207,8.61579,4.5,,,,,,,,,,,,,,,,,,,,,,,,,,,,,,,,,,,,,
139.132,3.80891,7.01148,4.5,,,,,,,,,,,,,,,,,,,,,,,,,,,,,,,,,,,,,
139.932,3.67551,5.62421,4.5,,,,,,,,,,,,,,,,,,,,,,,,,,,,,,,,,,,,,
140.732,3.54201,4.49137,4.5,,,,,,,,,,,,,,,,,,,,,,,,,,,,,,,,,,,,,
141.532,3.4089,3.51319,4.5,,,,,,,,,,,,,,,,,,,,,,,,,,,,,,,,,,,,,
142.332,3.2755,2.79476,4.5,,,,,,,,,,,,,,,,,,,,,,,,,,,,,,,,,,,,,
143.132,3.142,2.36294,4.5,,,,,,,,,,,,,,,,,,,,,,,,,,,,,,,,,,,,,
143.932,3.00889,1.80558,4.5,,,,,,,,,,,,,,,,,,,,,,,,,,,,,,,,,,,,,
144.732,2.87549,1.4692,4.5,,,,,,,,,,,,,,,,,,,,,,,,,,,,,,,,,,,,,
145.532,2.7421,1.19953,4.5,,,,,,,,,,,,,,,,,,,,,,,,,,,,,,,,,,,,,
146.08,2.65087,1.00045,5,,,,,,,,,,,,,,,,,,,,,,,,,,,,,,,,,,,,,
146.88,2.78505,1.29929,5,,,,,,,,,,,,,,,,,,,,,,,,,,,,,,,,,,,,,
147.68,2.91839,1.72392,5,,,,,,,,,,,,,,,,,,,,,,,,,,,,,,,,,,,,,
148.48,3.0519,2.17765,5,,,,,,,,,,,,,,,,,,,,,,,,,,,,,,,,,,,,,
149.28,3.18512,2.74786,5,,,,,,,,,,,,,,,,,,,,,,,,,,,,,,,,,,,,,
150.08,3.31846,3.51004,5,,,,,,,,,,,,,,,,,,,,,,,,,,,,,,,,,,,,,
150.88,3.45185,4.4906,5,,,,,,,,,,,,,,,,,,,,,,,,,,,,,,,,,,,,,
151.68,3.58507,5.76283,5,,,,,,,,,,,,,,,,,,,,,,,,,,,,,,,,,,,,,
152.48,3.71847,7.21302,5,,,,,,,,,,,,,,,,,,,,,,,,,,,,,,,,,,,,,
153.28,3.8518,8.9598,5,,,,,,,,,,,,,,,,,,,,,,,,,,,,,,,,,,,,,
154.08,3.98514,10.93139,5,,,,,,,,,,,,,,,,,,,,,,,,,,,,,,,,,,,,,
154.88,4.11848,13.32289,5,,,,,,,,,,,,,,,,,,,,,,,,,,,,,,,,,,,,,
155.68,4.25181,15.88646,5,,,,,,,,,,,,,,,,,,,,,,,,,,,,,,,,,,,,,
156.48,4.38509,18.79394,5,,,,,,,,,,,,,,,,,,,,,,,,,,,,,,,,,,,,,
157.28,4.51854,22.32143,5,,,,,,,,,,,,,,,,,,,,,,,,,,,,,,,,,,,,,
158.08,4.65177,26.30608,5,,,,,,,,,,,,,,,,,,,,,,,,,,,,,,,,,,,,,
158.88,4.7851,30.75412,5,,,,,,,,,,,,,,,,,,,,,,,,,,,,,,,,,,,,,
159.68,4.91861,35.7126,5,,,,,,,,,,,,,,,,,,,,,,,,,,,,,,,,,,,,,
160.316,5.02446,40.01932,5.5,,,,,,,,,,,,,,,,,,,,,,,,,,,,,,,,,,,,,
161.116,4.8909,33.03527,5.5,,,,,,,,,,,,,,,,,,,,,,,,,,,,,,,,,,,,,
161.916,4.75762,27.45856,5.5,,,,,,,,,,,,,,,,,,,,,,,,,,,,,,,,,,,,,
162.716,4.62406,22.83766,5.5,,,,,,,,,,,,,,,,,,,,,,,,,,,,,,,,,,,,,
163.516,4.49083,19.01541,5.5,,,,,,,,,,,,,,,,,,,,,,,,,,,,,,,,,,,,,
164.316,4.35755,15.6539,5.5,,,,,,,,,,,,,,,,,,,,,,,,,,,,,,,,,,,,,
165.116,4.22399,12.87319,5.5,,,,,,,,,,,,,,,,,,,,,,,,,,,,,,,,,,,,,
165.916,4.09088,10.51853,5.5,,,,,,,,,,,,,,,,,,,,,,,,,,,,,,,,,,,,,
166.716,3.95754,8.56332,5.5,,,,,,,,,,,,,,,,,,,,,,,,,,,,,,,,,,,,,
167.516,3.82404,6.91598,5.5,,,,,,,,,,,,,,,,,,,,,,,,,,,,,,,,,,,,,
168.316,3.69087,5.51263,5.5,,,,,,,,,,,,,,,,,,,,,,,,,,,,,,,,,,,,,
169.116,3.55753,4.35118,5.5,,,,,,,,,,,,,,,,,,,,,,,,,,,,,,,,,,,,,
169.916,3.42397,3.41315,5.5,,,,,,,,,,,,,,,,,,,,,,,,,,,,,,,,,,,,,
170.716,3.29092,2.73481,5.5,,,,,,,,,,,,,,,,,,,,,,,,,,,,,,,,,,,,,
171.516,3.15747,2.32135,5.5,,,,,,,,,,,,,,,,,,,,,,,,,,,,,,,,,,,,,
172.316,3.02407,1.81819,5.5,,,,,,,,,,,,,,,,,,,,,,,,,,,,,,,,,,,,,
173.116,2.89085,1.47026,5.5,,,,,,,,,,,,,,,,,,,,,,,,,,,,,,,,,,,,,
173.916,2.75746,1.16004,5.5,,,,,,,,,,,,,,,,,,,,,,,,,,,,,,,,,,,,,
174.502,2.72703,1.12206,6,,,,,,,,,,,,,,,,,,,,,,,,,,,,,,,,,,,,,
175.302,2.8607,1.42587,6,,,,,,,,,,,,,,,,,,,,,,,,,,,,,,,,,,,,,
176.102,2.99427,1.89939,6,,,,,,,,,,,,,,,,,,,,,,,,,,,,,,,,,,,,,
176.902,3.12738,2.36257,6,,,,,,,,,,,,,,,,,,,,,,,,,,,,,,,,,,,,,
177.702,3.26071,3.0656,6,,,,,,,,,,,,,,,,,,,,,,,,,,,,,,,,,,,,,
178.502,3.39428,3.88988,6,,,,,,,,,,,,,,,,,,,,,,,,,,,,,,,,,,,,,
179.302,3.52739,4.98078,6,,,,,,,,,,,,,,,,,,,,,,,,,,,,,,,,,,,,,
180.102,3.66072,6.28654,6,,,,,,,,,,,,,,,,,,,,,,,,,,,,,,,,,,,,,
180.902,3.79429,7.8531,6,,,,,,,,,,,,,,,,,,,,,,,,,,,,,,,,,,,,,
181.702,3.92745,9.72657,6,,,,,,,,,,,,,,,,,,,,,,,,,,,,,,,,,,,,,
182.502,4.06085,11.87436,6,,,,,,,,,,,,,,,,,,,,,,,,,,,,,,,,,,,,,
183.302,4.19418,14.36639,6,,,,,,,,,,,,,,,,,,,,,,,,,,,,,,,,,,,,,
184.102,4.32735,17.08435,6,,,,,,,,,,,,,,,,,,,,,,,,,,,,,,,,,,,,,
184.902,4.46086,20.1888,6,,,,,,,,,,,,,,,,,,,,,,,,,,,,,,,,,,,,,
185.702,4.59414,23.98538,6,,,,,,,,,,,,,,,,,,,,,,,,,,,,,,,,,,,,,
186.502,4.72736,28.2163,6,,,,,,,,,,,,,,,,,,,,,,,,,,,,,,,,,,,,,
187.302,4.86098,32.89005,6,,,,,,,,,,,,,,,,,,,,,,,,,,,,,,,,,,,,,
188.102,4.99415,38.12543,6,,,,,,,,,,,,,,,,,,,,,,,,,,,,,,,,,,,,,
188.774,4.97256,36.4368,6.5,,,,,,,,,,,,,,,,,,,,,,,,,,,,,,,,,,,,,
189.574,4.83905,30.18088,6.5,,,,,,,,,,,,,,,,,,,,,,,,,,,,,,,,,,,,,
190.374,4.70588,25.03554,6.5,,,,,,,,,,,,,,,,,,,,,,,,,,,,,,,,,,,,,
191.174,4.57249,20.79977,6.5,,,,,,,,,,,,,,,,,,,,,,,,,,,,,,,,,,,,,
191.974,4.4391,17.23018,6.5,,,,,,,,,,,,,,,,,,,,,,,,,,,,,,,,,,,,,
192.774,4.30587,14.20353,6.5,,,,,,,,,,,,,,,,,,,,,,,,,,,,,,,,,,,,,
193.574,4.17242,11.59424,6.5,,,,,,,,,,,,,,,,,,,,,,,,,,,,,,,,,,,,,
194.374,4.03909,9.50923,6.5,,,,,,,,,,,,,,,,,,,,,,,,,,,,,,,,,,,,,
195.174,3.90586,7.68865,6.5,,,,,,,,,,,,,,,,,,,,,,,,,,,,,,,,,,,,,
195.974,3.77236,6.15693,6.5,,,,,,,,,,,,,,,,,,,,,,,,,,,,,,,,,,,,,
196.774,3.63913,4.91152,6.5,,,,,,,,,,,,,,,,,,,,,,,,,,,,,,,,,,,,,
197.574,3.50591,3.91401,6.5,,,,,,,,,,,,,,,,,,,,,,,,,,,,,,,,,,,,,
198.374,3.37235,3.01201,6.5,,,,,,,,,,,,,,,,,,,,,,,,,,,,,,,,,,,,,
199.174,3.23918,2.49191,6.5,,,,,,,,,,,,,,,,,,,,,,,,,,,,,,,,,,,,,
199.974,3.10584,1.99084,6.5,,,,,,,,,,,,,,,,,,,,,,,,,,,,,,,,,,,,,
200.774,2.97234,1.55646,6.5,,,,,,,,,,,,,,,,,,,,,,,,,,,,,,,,,,,,,
201.574,2.83923,1.29602,6.5,,,,,,,,,,,,,,,,,,,,,,,,,,,,,,,,,,,,,
202.374,2.70583,1.05725,6.5,,,,,,,,,,,,,,,,,,,,,,,,,,,,,,,,,,,,,
202.912,2.78375,1.18314,7,,,,,,,,,,,,,,,,,,,,,,,,,,,,,,,,,,,,,
203.712,2.91703,1.56531,7,,,,,,,,,,,,,,,,,,,,,,,,,,,,,,,,,,,,,
204.512,3.05059,2.03182,7,,,,,,,,,,,,,,,,,,,,,,,,,,,,,,,,,,,,,
205.312,3.18376,2.55816,7,,,,,,,,,,,,,,,,,,,,,,,,,,,,,,,,,,,,,
206.112,3.3171,3.26623,7,,,,,,,,,,,,,,,,,,,,,,,,,,,,,,,,,,,,,
206.912,3.45055,4.19345,7,,,,,,,,,,,,,,,,,,,,,,,,,,,,,,,,,,,,,
207.712,3.58371,5.41344,7,,,,,,,,,,,,,,,,,,,,,,,,,,,,,,,,,,,,,
208.512,3.71711,6.7552,7,,,,,,,,,,,,,,,,,,,,,,,,,,,,,,,,,,,,,
209.312,3.85056,8.39992,7,,,,,,,,,,,,,,,,,,,,,,,,,,,,,,,,,,,,,
210.112,3.98378,10.30215,7,,,,,,,,,,,,,,,,,,,,,,,,,,,,,,,,,,,,,
210.912,4.11717,12.60208,7,,,,,,,,,,,,,,,,,,,,,,,,,,,,,,,,,,,,,
211.712,4.25051,15.16073,7,,,,,,,,,,,,,,,,,,,,,,,,,,,,,,,,,,,,,
212.512,4.38373,17.94773,7,,,,,,,,,,,,,,,,,,,,,,,,,,,,,,,,,,,,,
213.312,4.51718,21.34163,7,,,,,,,,,,,,,,,,,,,,,,,,,,,,,,,,,,,,,
214.112,4.65041,25.23923,7,,,,,,,,,,,,,,,,,,,,,,,,,,,,,,,,,,,,,
214.912,4.78374,29.66259,7,,,,,,,,,,,,,,,,,,,,,,,,,,,,,,,,,,,,,
215.712,4.91725,34.55609,7,,,,,,,,,,,,,,,,,,,,,,,,,,,,,,,,,,,,,
216.512,5.05047,39.9161,7,,,,,,,,,,,,,,,,,,,,,,,,,,,,,,,,,,,,,
217.124,4.95216,34.76699,7.5,,,,,,,,,,,,,,,,,,,,,,,,,,,,,,,,,,,,,
217.924,4.81888,28.85007,7.5,,,,,,,,,,,,,,,,,,,,,,,,,,,,,,,,,,,,,
218.724,4.68543,23.99031,7.5,,,,,,,,,,,,,,,,,,,,,,,,,,,,,,,,,,,,,
219.524,4.55215,19.83182,7.5,,,,,,,,,,,,,,,,,,,,,,,,,,,,,,,,,,,,,
220.324,4.41881,16.38644,7.5,,,,,,,,,,,,,,,,,,,,,,,,,,,,,,,,,,,,,
221.124,4.28542,13.4739,7.5,,,,,,,,,,,,,,,,,,,,,,,,,,,,,,,,,,,,,
221.924,4.15219,11.05232,7.5,,,,,,,,,,,,,,,,,,,,,,,,,,,,,,,,,,,,,
222.724,4.01886,9.04993,7.5,,,,,,,,,,,,,,,,,,,,,,,,,,,,,,,,,,,,,
223.524,3.88535,7.24416,7.5,,,,,,,,,,,,,,,,,,,,,,,,,,,,,,,,,,,,,
224.324,3.75224,5.80513,7.5,,,,,,,,,,,,,,,,,,,,,,,,,,,,,,,,,,,,,
225.124,3.61885,4.6342,7.5,,,,,,,,,,,,,,,,,,,,,,,,,,,,,,,,,,,,,
225.924,3.4854,3.65006,7.5,,,,,,,,,,,,,,,,,,,,,,,,,,,,,,,,,,,,,
226.724,3.35217,2.89597,7.5,,,,,,,,,,,,,,,,,,,,,,,,,,,,,,,,,,,,,
227.524,3.21889,2.39332,7.5,,,,,,,,,,,,,,,,,,,,,,,,,,,,,,,,,,,,,
228.324,3.08544,1.90884,7.5,,,,,,,,,,,,,,,,,,,,,,,,,,,,,,,,,,,,,
229.124,2.95216,1.5554,7.5,,,,,,,,,,,,,,,,,,,,,,,,,,,,,,,,,,,,,
229.924,2.81883,1.28319,7.5,,,,,,,,,,,,,,,,,,,,,,,,,,,,,,,,,,,,,
230.524,2.71887,1.00147,8,,,,,,,,,,,,,,,,,,,,,,,,,,,,,,,,,,,,,
231.324,2.85311,1.38264,8,,,,,,,,,,,,,,,,,,,,,,,,,,,,,,,,,,,,,
232.124,2.9865,1.7289,8,,,,,,,,,,,,,,,,,,,,,,,,,,,,,,,,,,,,,
232.924,3.11973,2.26,8,,,,,,,,,,,,,,,,,,,,,,,,,,,,,,,,,,,,,
233.724,3.25312,2.84038,8,,,,,,,,,,,,,,,,,,,,,,,,,,,,,,,,,,,,,
234.524,3.38657,3.65572,8,,,,,,,,,,,,,,,,,,,,,,,,,,,,,,,,,,,,,
235.324,3.51974,4.66415,8,,,,,,,,,,,,,,,,,,,,,,,,,,,,,,,,,,,,,
236.124,3.65307,5.89962,8,,,,,,,,,,,,,,,,,,,,,,,,,,,,,,,,,,,,,
236.924,3.78647,7.42144,8,,,,,,,,,,,,,,,,,,,,,,,,,,,,,,,,,,,,,
237.724,3.9198,9.1059,8,,,,,,,,,,,,,,,,,,,,,,,,,,,,,,,,,,,,,
238.524,4.05308,11.22948,8,,,,,,,,,,,,,,,,,,,,,,,,,,,,,,,,,,,,,
239.324,4.18653,13.63061,8,,,,,,,,,,,,,,,,,,,,,,,,,,,,,,,,,,,,,
240.124,4.31981,16.279,8,,,,,,,,,,,,,,,,,,,,,,,,,,,,,,,,,,,,,
240.924,4.45309,19.3582,8,,,,,,,,,,,,,,,,,,,,,,,,,,,,,,,,,,,,,
241.724,4.58649,22.96136,8,,,,,,,,,,,,,,,,,,,,,,,,,,,,,,,,,,,,,
242.524,4.71977,27.08994,8,,,,,,,,,,,,,,,,,,,,,,,,,,,,,,,,,,,,,
243.324,4.85316,31.73935,8,,,,,,,,,,,,,,,,,,,,,,,,,,,,,,,,,,,,,
244.124,4.98644,36.88649,8,,,,,,,,,,,,,,,,,,,,,,,,,,,,,,,,,,,,,
244.782,5.02973,38.4071,8.5,,,,,,,,,,,,,,,,,,,,,,,,,,,,,,,,,,,,,
245.582,4.89589,31.64152,8.5,,,,,,,,,,,,,,,,,,,,,,,,,,,,,,,,,,,,,
246.382,4.76255,26.21999,8.5,,,,,,,,,,,,,,,,,,,,,,,,,,,,,,,,,,,,,
247.182,4.62916,21.83813,8.5,,,,,,,,,,,,,,,,,,,,,,,,,,,,,,,,,,,,,
247.982,4.49582,18.04513,8.5,,,,,,,,,,,,,,,,,,,,,,,,,,,,,,,,,,,,,
248.782,4.36248,14.87512,8.5,,,,,,,,,,,,,,,,,,,,,,,,,,,,,,,,,,,,,
249.582,4.22909,12.23135,8.5,,,,,,,,,,,,,,,,,,,,,,,,,,,,,,,,,,,,,
250.382,4.09575,9.93103,8.5,,,,,,,,,,,,,,,,,,,,,,,,,,,,,,,,,,,,,
251.182,3.96253,8.03835,8.5,,,,,,,,,,,,,,,,,,,,,,,,,,,,,,,,,,,,,
251.982,3.82914,6.41729,8.5,,,,,,,,,,,,,,,,,,,,,,,,,,,,,,,,,,,,,
252.782,3.6958,5.24887,8.5,,,,,,,,,,,,,,,,,,,,,,,,,,,,,,,,,,,,,
253.582,3.56252,4.06193,8.5,,,,,,,,,,,,,,,,,,,,,,,,,,,,,,,,,,,,,
254.382,3.42907,3.20114,8.5,,,,,,,,,,,,,,,,,,,,,,,,,,,,,,,,,,,,,
255.182,3.29585,2.54886,8.5,,,,,,,,,,,,,,,,,,,,,,,,,,,,,,,,,,,,,
255.982,3.16251,2.1289,8.5,,,,,,,,,,,,,,,,,,,,,,,,,,,,,,,,,,,,,
256.782,3.02906,1.77588,8.5,,,,,,,,,,,,,,,,,,,,,,,,,,,,,,,,,,,,,
257.582,2.89578,1.32998,8.5,,,,,,,,,,,,,,,,,,,,,,,,,,,,,,,,,,,,,
258.382,2.76256,1.10889,8.5,,,,,,,,,,,,,,,,,,,,,,,,,,,,,,,,,,,,,
258.976,2.79775,1.18023,9,,,,,,,,,,,,,,,,,,,,,,,,,,,,,,,,,,,,,
259.776,2.9312,1.51186,9,,,,,,,,,,,,,,,,,,,,,,,,,,,,,,,,,,,,,
260.576,3.06442,2.03638,9,,,,,,,,,,,,,,,,,,,,,,,,,,,,,,,,,,,,,
261.376,3.19781,2.49643,9,,,,,,,,,,,,,,,,,,,,,,,,,,,,,,,,,,,,,
262.176,3.33121,3.1959,9,,,,,,,,,,,,,,,,,,,,,,,,,,,,,,,,,,,,,
262.976,3.46443,4.06906,9,,,,,,,,,,,,,,,,,,,,,,,,,,,,,,,,,,,,,
263.776,3.59771,5.2188,9,,,,,,,,,,,,,,,,,,,,,,,,,,,,,,,,,,,,,
264.576,3.73122,6.60337,9,,,,,,,,,,,,,,,,,,,,,,,,,,,,,,,,,,,,,
265.376,3.86438,8.22768,9,,,,,,,,,,,,,,,,,,,,,,,,,,,,,,,,,,,,,
266.176,3.99778,10.12976,9,,,,,,,,,,,,,,,,,,,,,,,,,,,,,,,,,,,,,
266.976,4.13123,12.41442,9,,,,,,,,,,,,,,,,,,,,,,,,,,,,,,,,,,,,,
267.776,4.26439,14.95866,9,,,,,,,,,,,,,,,,,,,,,,,,,,,,,,,,,,,,,
268.576,4.39779,17.75286,9,,,,,,,,,,,,,,,,,,,,,,,,,,,,,,,,,,,,,
269.376,4.53118,21.02491,9,,,,,,,,,,,,,,,,,,,,,,,,,,,,,,,,,,,,,
270.176,4.66446,25.02129,9,,,,,,,,,,,,,,,,,,,,,,,,,,,,,,,,,,,,,
270.976,4.79785,29.3838,9,,,,,,,,,,,,,,,,,,,,,,,,,,,,,,,,,,,,,
271.776,4.93113,34.22905,9,,,,,,,,,,,,,,,,,,,,,,,,,,,,,,,,,,,,,
272.576,5.06447,39.73847,9,,,,,,,,,,,,,,,,,,,,,,,,,,,,,,,,,,,,,
273.22,4.97154,34.74839,9.5,,,,,,,,,,,,,,,,,,,,,,,,,,,,,,,,,,,,,
274.02,4.83809,28.8228,9.5,,,,,,,,,,,,,,,,,,,,,,,,,,,,,,,,,,,,,
274.82,4.70486,23.90965,9.5,,,,,,,,,,,,,,,,,,,,,,,,,,,,,,,,,,,,,
275.62,4.57147,19.80287,9.5,,,,,,,,,,,,,,,,,,,,,,,,,,,,,,,,,,,,,
276.42,4.43813,16.34011,9.5,,,,,,,,,,,,,,,,,,,,,,,,,,,,,,,,,,,,,
277.22,4.30491,13.4049,9.5,,,,,,,,,,,,,,,,,,,,,,,,,,,,,,,,,,,,,
278.02,4.1714,10.94357,9.5,,,,,,,,,,,,,,,,,,,,,,,,,,,,,,,,,,,,,
278.82,4.03812,8.91868,9.5,,,,,,,,,,,,,,,,,,,,,,,,,,,,,,,,,,,,,
279.62,3.9049,7.17477,9.5,,,,,,,,,,,,,,,,,,,,,,,,,,,,,,,,,,,,,
280.42,3.77139,5.76748,9.5,,,,,,,,,,,,,,,,,,,,,,,,,,,,,,,,,,,,,
281.22,3.63823,4.58495,9.5,,,,,,,,,,,,,,,,,,,,,,,,,,,,,,,,,,,,,
282.02,3.50489,3.62355,9.5,,,,,,,,,,,,,,,,,,,,,,,,,,,,,,,,,,,,,
282.82,3.37133,2.8724,9.5,,,,,,,,,,,,,,,,,,,,,,,,,,,,,,,,,,,,,
283.62,3.23822,2.35189,9.5,,,,,,,,,,,,,,,,,,,,,,,,,,,,,,,,,,,,,
284.42,3.10488,1.85336,9.5,,,,,,,,,,,,,,,,,,,,,,,,,,,,,,,,,,,,,
285.22,2.97143,1.52341,9.5,,,,,,,,,,,,,,,,,,,,,,,,,,,,,,,,,,,,,
286.02,2.83821,1.20152,9.5,,,,,,,,,,,,,,,,,,,,,,,,,,,,,,,,,,,,,
286.692,2.72419,0.95766,10,,,,,,,,,,,,,,,,,,,,,,,,,,,,,,,,,,,,,
287.492,2.57822,0.78229,10,,,,,,,,,,,,,,,,,,,,,,,,,,,,,,,,,,,,,
288.292,2.49679,0.68295,10,,,,,,,,,,,,,,,,,,,,,,,,,,,,,,,,,,,,,
289.092,2.49033,0.67513,10,,,,,,,,,,,,,,,,,,,,,,,,,,,,,,,,,,,,,
289.892,2.49084,0.64125,10,,,,,,,,,,,,,,,,,,,,,,,,,,,,,,,,,,,,,
290.692,2.49328,0.65418,10,,,,,,,,,,,,,,,,,,,,,,,,,,,,,,,,,,,,,
291.492,2.54229,0.72855,10,,,,,,,,,,,,,,,,,,,,,,,,,,,,,,,,,,,,,
292.292,2.64333,0.93894,10,,,,,,,,,,,,,,,,,,,,,,,,,,,,,,,,,,,,,
293.092,2.68895,1.05063,10,,,,,,,,,,,,,,,,,,,,,,,,,,,,,,,,,,,,,
293.892,2.68895,1.14015,10,,,,,,,,,,,,,,,,,,,,,,,,,,,,,,,,,,,,,
294.692,2.68713,1.11961,10,,,,,,,,,,,,,,,,,,,,,,,,,,,,,,,,,,,,,
295.492,2.66328,1.04216,10,,,,,,,,,,,,,,,,,,,,,,,,,,,,,,,,,,,,,
296.292,2.59482,0.8578,10,,,,,,,,,,,,,,,,,,,,,,,,,,,,,,,,,,,,,
297.092,2.55476,0.82576,10,,,,,,,,,,,,,,,,,,,,,,,,,,,,,,,,,,,,,
297.892,2.55062,0.87638,10,,,,,,,,,,,,,,,,,,,,,,,,,,,,,,,,,,,,,
298.692,2.55085,0.76871,10,,,,,,,,,,,,,,,,,,,,,,,,,,,,,,,,,,,,,
299.492,2.55108,0.79974,10,,,,,,,,,,,,,,,,,,,,,,,,,,,,,,,,,,,,,
300.292,2.55159,0.76236,10,,,,,,,,,,,,,,,,,,,,,,,,,,,,,,,,,,,,,
301.092,2.55408,0.71649,10,,,,,,,,,,,,,,,,,,,,,,,,,,,,,,,,,,,,,
301.892,2.57357,0.85532,10,,,,,,,,,,,,,,,,,,,,,,,,,,,,,,,,,,,,,
302.692,2.621,0.92431,10,,,,,,,,,,,,,,,,,,,,,,,,,,,,,,,,,,,,,
303.492,2.63449,0.95376,10,,,,,,,,,,,,,,,,,,,,,,,,,,,,,,,,,,,,,
304.292,2.63472,0.97572,10,,,,,,,,,,,,,,,,,,,,,,,,,,,,,,,,,,,,,
305.092,2.63443,0.98587,10,,,,,,,,,,,,,,,,,,,,,,,,,,,,,,,,,,,,,
305.892,2.63381,1.00455,10,,,,,,,,,,,,,,,,,,,,,,,,,,,,,,,,,,,,,
306.692,2.62905,1.00523,10,,,,,,,,,,,,,,,,,,,,,,,,,,,,,,,,,,,,,
307.492,2.60706,0.94411,10,,,,,,,,,,,,,,,,,,,,,,,,,,,,,,,,,,,,,
308.292,2.57584,0.83002,10,,,,,,,,,,,,,,,,,,,,,,,,,,,,,,,,,,,,,
309.092,2.56281,0.83655,10,,,,,,,,,,,,,,,,,,,,,,,,,,,,,,,,,,,,,
309.892,2.56145,0.87804,10,,,,,,,,,,,,,,,,,,,,,,,,,,,,,,,,,,,,,
310.692,2.56145,0.78421,10,,,,,,,,,,,,,,,,,,,,,,,,,,,,,,,,,,,,,
311.492,2.56156,0.80789,10,,,,,,,,,,,,,,,,,,,,,,,,,,,,,,,,,,,,,
312.292,2.56173,0.87969,10,,,,,,,,,,,,,,,,,,,,,,,,,,,,,,,,,,,,,
313.092,2.56207,0.76279,10,,,,,,,,,,,,,,,,,,,,,,,,,,,,,,,,,,,,,
313.892,2.56275,0.7791,10,,,,,,,,,,,,,,,,,,,,,,,,,,,,,,,,,,,,,
314.692,2.56451,0.79854,10,,,,,,,,,,,,,,,,,,,,,,,,,,,,,,,,,,,,,
315.492,2.5738,0.83448,10,,,,,,,,,,,,,,,,,,,,,,,,,,,,,,,,,,,,,
316.292,2.6112,0.95666,10,,,,,,,,,,,,,,,,,,,,,,,,,,,,,,,,,,,,,
317.092,2.62287,0.94831,10,,,,,,,,,,,,,,,,,,,,,,,,,,,,,,,,,,,,,
317.892,2.62293,0.99177,10,,,,,,,,,,,,,,,,,,,,,,,,,,,,,,,,,,,,,
318.692,2.62276,0.98255,10,,,,,,,,,,,,,,,,,,,,,,,,,,,,,,,,,,,,,
319.492,2.62197,1.01946,10,,,,,,,,,,,,,,,,,,,,,,,,,,,,,,,,,,,,,
320.292,2.61698,0.96592,10,,,,,,,,,,,,,,,,,,,,,,,,,,,,,,,,,,,,,
321.092,2.59477,0.94329,10,,,,,,,,,,,,,,,,,,,,,,,,,,,,,,,,,,,,,
321.892,2.57029,0.8377,10,,,,,,,,,,,,,,,,,,,,,,,,,,,,,,,,,,,,,
322.692,2.56054,0.84792,10,,,,,,,,,,,,,,,,,,,,,,,,,,,,,,,,,,,,,
323.492,2.55969,0.85065,10,,,,,,,,,,,,,,,,,,,,,,,,,,,,,,,,,,,,,
324.292,2.55963,0.82008,10,,,,,,,,,,,,,,,,,,,,,,,,,,,,,,,,,,,,,
325.092,2.5598,0.88097,10,,,,,,,,,,,,,,,,,,,,,,,,,,,,,,,,,,,,,
325.892,2.55992,0.79033,10,,,,,,,,,,,,,,,,,,,,,,,,,,,,,,,,,,,,,
326.692,2.56009,0.83755,10,,,,,,,,,,,,,,,,,,,,,,,,,,,,,,,,,,,,,
327.492,2.56037,0.82864,10,,,,,,,,,,,,,,,,,,,,,,,,,,,,,,,,,,,,,
328.292,2.56088,0.79498,10,,,,,,,,,,,,,,,,,,,,,,,,,,,,,,,,,,,,,
329.092,2.56224,0.79201,10,,,,,,,,,,,,,,,,,,,,,,,,,,,,,,,,,,,,,
329.892,2.56626,0.77332,10,,,,,,,,,,,,,,,,,,,,,,,,,,,,,,,,,,,,,
330.692,2.59131,0.90864,10,,,,,,,,,,,,,,,,,,,,,,,,,,,,,,,,,,,,,
331.492,2.62293,0.99059,10,,,,,,,,,,,,,,,,,,,,,,,,,,,,,,,,,,,,,
332.292,2.62565,0.9712,10,,,,,,,,,,,,,,,,,,,,,,,,,,,,,,,,,,,,,
333.092,2.62548,1.01253,10,,,,,,,,,,,,,,,,,,,,,,,,,,,,,,,,,,,,,
333.892,2.62503,1.0417,10,,,,,,,,,,,,,,,,,,,,,,,,,,,,,,,,,,,,,
334.692,2.62123,0.98185,10,,,,,,,,,,,,,,,,,,,,,,,,,,,,,,,,,,,,,
335.492,2.59839,0.92979,10,,,,,,,,,,,,,,,,,,,,,,,,,,,,,,,,,,,,,
336.292,2.56235,0.84018,10,,,,,,,,,,,,,,,,,,,,,,,,,,,,,,,,,,,,,
337.092,2.55368,0.7758,10,,,,,,,,,,,,,,,,,,,,,,,,,,,,,,,,,,,,,
337.892,2.55334,0.81036,10,,,,,,,,,,,,,,,,,,,,,,,,,,,,,,,,,,,,,
338.692,2.55351,0.80671,10,,,,,,,,,,,,,,,,,,,,,,,,,,,,,,,,,,,,,
339.492,2.55357,0.79443,10,,,,,,,,,,,,,,,,,,,,,,,,,,,,,,,,,,,,,
340.292,2.5538,0.79056,10,,,,,,,,,,,,,,,,,,,,,,,,,,,,,,,,,,,,,
341.092,2.55419,0.79403,10,,,,,,,,,,,,,,,,,,,,,,,,,,,,,,,,,,,,,
341.892,2.55516,0.85217,10,,,,,,,,,,,,,,,,,,,,,,,,,,,,,,,,,,,,,
342.692,2.55839,0.79769,10,,,,,,,,,,,,,,,,,,,,,,,,,,,,,,,,,,,,,
343.492,2.57414,0.85494,10,,,,,,,,,,,,,,,,,,,,,,,,,,,,,,,,,,,,,
344.292,2.6099,0.92932,10,,,,,,,,,,,,,,,,,,,,,,,,,,,,,,,,,,,,,
345.092,2.61993,0.96422,10,,,,,,,,,,,,,,,,,,,,,,,,,,,,,,,,,,,,,
345.892,2.61998,1.00279,10,,,,,,,,,,,,,,,,,,,,,,,,,,,,,,,,,,,,,
346.692,2.61976,0.94872,10,,,,,,,,,,,,,,,,,,,,,,,,,,,,,,,,,,,,,
347.492,2.61902,0.98832,10,,,,,,,,,,,,,,,,,,,,,,,,,,,,,,,,,,,,,
348.292,2.61432,0.99114,10,,,,,,,,,,,,,,,,,,,,,,,,,,,,,,,,,,,,,
349.092,2.58406,0.88594,10,,,,,,,,,,,,,,,,,,,,,,,,,,,,,,,,,,,,,
349.892,2.55555,0.84043,10,,,,,,,,,,,,,,,,,,,,,,,,,,,,,,,,,,,,,
350.692,2.55289,0.80184,10,,,,,,,,,,,,,,,,,,,,,,,,,,,,,,,,,,,,,
351.492,2.55283,0.79395,10,,,,,,,,,,,,,,,,,,,,,,,,,,,,,,,,,,,,,
352.292,2.55306,0.83349,10,,,,,,,,,,,,,,,,,,,,,,,,,,,,,,,,,,,,,
353.092,2.55329,0.82713,10,,,,,,,,,,,,,,,,,,,,,,,,,,,,,,,,,,,,,
353.892,2.55385,0.75057,10,,,,,,,,,,,,,,,,,,,,,,,,,,,,,,,,,,,,,
354.692,2.5555,0.78634,10,,,,,,,,,,,,,,,,,,,,,,,,,,,,,,,,,,,,,
355.492,2.56099,0.79716,10,,,,,,,,,,,,,,,,,,,,,,,,,,,,,,,,,,,,,
356.292,2.59579,0.86757,10,,,,,,,,,,,,,,,,,,,,,,,,,,,,,,,,,,,,,
357.092,2.6282,1.0045,10,,,,,,,,,,,,,,,,,,,,,,,,,,,,,,,,,,,,,
357.892,2.62865,1.03804,10,,,,,,,,,,,,,,,,,,,,,,,,,,,,,,,,,,,,,
358.692,2.62831,1.00068,10,,,,,,,,,,,,,,,,,,,,,,,,,,,,,,,,,,,,,
359.492,2.62656,1.01744,10,,,,,,,,,,,,,,,,,,,,,,,,,,,,,,,,,,,,,
360.292,2.61358,1.02515,10,,,,,,,,,,,,,,,,,,,,,,,,,,,,,,,,,,,,,
361.092,2.57216,0.87726,10,,,,,,,,,,,,,,,,,,,,,,,,,,,,,,,,,,,,,
361.892,2.55153,0.80892,10,,,,,,,,,,,,,,,,,,,,,,,,,,,,,,,,,,,,,
362.692,2.55096,0.86213,10,,,,,,,,,,,,,,,,,,,,,,,,,,,,,,,,,,,,,
363.492,2.55102,0.82139,10,,,,,,,,,,,,,,,,,,,,,,,,,,,,,,,,,,,,,
364.292,2.55113,0.82343,10,,,,,,,,,,,,,,,,,,,,,,,,,,,,,,,,,,,,,
365.092,2.55136,0.79456,10,,,,,,,,,,,,,,,,,,,,,,,,,,,,,,,,,,,,,
365.892,2.55176,0.75671,10,,,,,,,,,,,,,,,,,,,,,,,,,,,,,,,,,,,,,
366.692,2.55266,0.76683,10,,,,,,,,,,,,,,,,,,,,,,,,,,,,,,,,,,,,,
367.492,2.55669,0.79406,10,,,,,,,,,,,,,,,,,,,,,,,,,,,,,,,,,,,,,
368.292,2.57391,0.87813,10,,,,,,,,,,,,,,,,,,,,,,,,,,,,,,,,,,,,,
369.092,2.61879,0.95312,10,,,,,,,,,,,,,,,,,,,,,,,,,,,,,,,,,,,,,
369.892,2.62848,0.99933,10,,,,,,,,,,,,,,,,,,,,,,,,,,,,,,,,,,,,,
370.692,2.62826,0.97528,10,,,,,,,,,,,,,,,,,,,,,,,,,,,,,,,,,,,,,
371.492,2.62786,1.01878,10,,,,,,,,,,,,,,,,,,,,,,,,,,,,,,,,,,,,,
372.292,2.6248,0.99852,10,,,,,,,,,,,,,,,,,,,,,,,,,,,,,,,,,,,,,
373.092,2.60599,0.90787,10,,,,,,,,,,,,,,,,,,,,,,,,,,,,,,,,,,,,,
373.892,2.56207,0.87438,10,,,,,,,,,,,,,,,,,,,,,,,,,,,,,,,,,,,,,
374.692,2.54745,0.82405,10,,,,,,,,,,,,,,,,,,,,,,,,,,,,,,,,,,,,,
375.492,2.54705,0.81944,10,,,,,,,,,,,,,,,,,,,,,,,,,,,,,,,,,,,,,
376.292,2.54717,0.82322,10,,,,,,,,,,,,,,,,,,,,,,,,,,,,,,,,,,,,,
377.092,2.54734,0.79907,10,,,,,,,,,,,,,,,,,,,,,,,,,,,,,,,,,,,,,
377.892,2.54756,0.76472,10,,,,,,,,,,,,,,,,,,,,,,,,,,,,,,,,,,,,,
378.692,2.54824,0.79661,10,,,,,,,,,,,,,,,,,,,,,,,,,,,,,,,,,,,,,
379.492,2.54994,0.76015,10,,,,,,,,,,,,,,,,,,,,,,,,,,,,,,,,,,,,,
380.292,2.55691,0.75926,10,,,,,,,,,,,,,,,,,,,,,,,,,,,,,,,,,,,,,
381.092,2.59165,0.92859,10,,,,,,,,,,,,,,,,,,,,,,,,,,,,,,,,,,,,,
381.892,2.62803,1.03646,10,,,,,,,,,,,,,,,,,,,,,,,,,,,,,,,,,,,,,
382.692,2.62882,1.03706,10,,,,,,,,,,,,,,,,,,,,,,,,,,,,,,,,,,,,,
383.492,2.62848,1.00448,10,,,,,,,,,,,,,,,,,,,,,,,,,,,,,,,,,,,,,
384.292,2.62656,1.05364,10,,,,,,,,,,,,,,,,,,,,,,,,,,,,,,,,,,,,,
385.092,2.61556,0.9615,10,,,,,,,,,,,,,,,,,,,,,,,,,,,,,,,,,,,,,
385.892,2.56768,0.89832,10,,,,,,,,,,,,,,,,,,,,,,,,,,,,,,,,,,,,,
386.692,2.54416,0.8064,10,,,,,,,,,,,,,,,,,,,,,,,,,,,,,,,,,,,,,
387.492,2.54354,0.78546,10,,,,,,,,,,,,,,,,,,,,,,,,,,,,,,,,,,,,,
388.292,2.54365,0.79487,10,,,,,,,,,,,,,,,,,,,,,,,,,,,,,,,,,,,,,
389.092,2.54382,0.82133,10,,,,,,,,,,,,,,,,,,,,,,,,,,,,,,,,,,,,,
389.892,2.54411,0.75589,10,,,,,,,,,,,,,,,,,,,,,,,,,,,,,,,,,,,,,
390.692,2.54484,0.7563,10,,,,,,,,,,,,,,,,,,,,,,,,,,,,,,,,,,,,,
391.492,2.54739,0.79703,10,,,,,,,,,,,,,,,,,,,,,,,,,,,,,,,,,,,,,
392.292,2.55584,0.82473,10,,,,,,,,,,,,,,,,,,,,,,,,,,,,,,,,,,,,,
393.092,2.58825,1.00019,10,,,,,,,,,,,,,,,,,,,,,,,,,,,,,,,,,,,,,
393.892,2.60916,0.9994,10,,,,,,,,,,,,,,,,,,,,,,,,,,,,,,,,,,,,,
394.692,2.60978,1.02066,10,,,,,,,,,,,,,,,,,,,,,,,,,,,,,,,,,,,,,
395.492,2.6095,0.96019,10,,,,,,,,,,,,,,,,,,,,,,,,,,,,,,,,,,,,,
396.292,2.60905,1.02367,10,,,,,,,,,,,,,,,,,,,,,,,,,,,,,,,,,,,,,
397.092,2.60491,1.03166,10,,,,,,,,,,,,,,,,,,,,,,,,,,,,,,,,,,,,,
397.892,2.58321,0.89636,10,,,,,,,,,,,,,,,,,,,,,,,,,,,,,,,,,,,,,
398.692,2.55646,0.88332,10,,,,,,,,,,,,,,,,,,,,,,,,,,,,,,,,,,,,,
399.492,2.54722,0.78194,10,,,,,,,,,,,,,,,,,,,,,,,,,,,,,,,,,,,,,
400.292,2.54694,0.8475,10,,,,,,,,,,,,,,,,,,,,,,,,,,,,,,,,,,,,,
401.092,2.547,0.84143,10,,,,,,,,,,,,,,,,,,,,,,,,,,,,,,,,,,,,,
401.892,2.54717,0.79962,10,,,,,,,,,,,,,,,,,,,,,,,,,,,,,,,,,,,,,
402.692,2.54734,0.8403,10,,,,,,,,,,,,,,,,,,,,,,,,,,,,,,,,,,,,,
403.492,2.54756,0.81353,10,,,,,,,,,,,,,,,,,,,,,,,,,,,,,,,,,,,,,
404.292,2.54819,0.77434,10,,,,,,,,,,,,,,,,,,,,,,,,,,,,,,,,,,,,,
405.092,2.54977,0.86894,10,,,,,,,,,,,,,,,,,,,,,,,,,,,,,,,,,,,,,
405.892,2.55306,0.8245,10,,,,,,,,,,,,,,,,,,,,,,,,,,,,,,,,,,,,,
406.692,2.56575,0.8217,10,,,,,,,,,,,,,,,,,,,,,,,,,,,,,,,,,,,,,
407.492,2.60519,0.95965,10,,,,,,,,,,,,,,,,,,,,,,,,,,,,,,,,,,,,,
408.292,2.60825,1.04914,10,,,,,,,,,,,,,,,,,,,,,,,,,,,,,,,,,,,,,
409.092,2.60803,1.04738,10,,,,,,,,,,,,,,,,,,,,,,,,,,,,,,,,,,,,,
409.892,2.60774,0.95896,10,,,,,,,,,,,,,,,,,,,,,,,,,,,,,,,,,,,,,
410.692,2.60497,0.99801,10,,,,,,,,,,,,,,,,,,,,,,,,,,,,,,,,,,,,,
411.492,2.59074,0.98149,10,,,,,,,,,,,,,,,,,,,,,,,,,,,,,,,,,,,,,
412.292,2.5615,0.86917,10,,,,,,,,,,,,,,,,,,,,,,,,,,,,,,,,,,,,,
413.092,2.54558,0.87234,10,,,,,,,,,,,,,,,,,,,,,,,,,,,,,,,,,,,,,
413.892,2.54501,0.74335,10,,,,,,,,,,,,,,,,,,,,,,,,,,,,,,,,,,,,,
414.692,2.54518,0.81534,10,,,,,,,,,,,,,,,,,,,,,,,,,,,,,,,,,,,,,
415.492,2.54524,0.84687,10,,,,,,,,,,,,,,,,,,,,,,,,,,,,,,,,,,,,,
416.292,2.54541,0.86128,10,,,,,,,,,,,,,,,,,,,,,,,,,,,,,,,,,,,,,
417.092,2.54575,0.84559,10,,,,,,,,,,,,,,,,,,,,,,,,,,,,,,,,,,,,,
417.892,2.54626,0.80236,10,,,,,,,,,,,,,,,,,,,,,,,,,,,,,,,,,,,,,
418.692,2.54768,0.80438,10,,,,,,,,,,,,,,,,,,,,,,,,,,,,,,,,,,,,,
419.492,2.55153,0.80227,10,,,,,,,,,,,,,,,,,,,,,,,,,,,,,,,,,,,,,
420.292,2.55963,0.83147,10,,,,,,,,,,,,,,,,,,,,,,,,,,,,,,,,,,,,,
421.092,2.60599,0.96916,10,,,,,,,,,,,,,,,,,,,,,,,,,,,,,,,,,,,,,
421.892,2.6231,0.98262,10,,,,,,,,,,,,,,,,,,,,,,,,,,,,,,,,,,,,,
422.692,2.62321,1.03127,10,,,,,,,,,,,,,,,,,,,,,,,,,,,,,,,,,,,,,
423.492,2.62299,1.01233,10,,,,,,,,,,,,,,,,,,,,,,,,,,,,,,,,,,,,,
424.292,2.62095,1.00169,10,,,,,,,,,,,,,,,,,,,,,,,,,,,,,,,,,,,,,
425.092,2.60259,0.94575,10,,,,,,,,,,,,,,,,,,,,,,,,,,,,,,,,,,,,,
425.892,2.56048,0.86508,10,,,,,,,,,,,,,,,,,,,,,,,,,,,,,,,,,,,,,
426.692,2.54093,0.79065,10,,,,,,,,,,,,,,,,,,,,,,,,,,,,,,,,,,,,,
427.492,2.54042,0.773,10,,,,,,,,,,,,,,,,,,,,,,,,,,,,,,,,,,,,,
428.292,2.54065,0.83933,10,,,,,,,,,,,,,,,,,,,,,,,,,,,,,,,,,,,,,
429.092,2.54082,0.82646,10,,,,,,,,,,,,,,,,,,,,,,,,,,,,,,,,,,,,,
429.892,2.54116,0.79848,10,,,,,,,,,,,,,,,,,,,,,,,,,,,,,,,,,,,,,
430.692,2.54201,0.74751,10,,,,,,,,,,,,,,,,,,,,,,,,,,,,,,,,,,,,,
431.492,2.54575,0.79473,10,,,,,,,,,,,,,,,,,,,,,,,,,,,,,,,,,,,,,
432.292,2.55618,0.83957,10,,,,,,,,,,,,,,,,,,,,,,,,,,,,,,,,,,,,,
433.092,2.60321,0.95552,10,,,,,,,,,,,,,,,,,,,,,,,,,,,,,,,,,,,,,
433.892,2.62786,0.95828,10,,,,,,,,,,,,,,,,,,,,,,,,,,,,,,,,,,,,,
434.692,2.62786,1.04431,10,,,,,,,,,,,,,,,,,,,,,,,,,,,,,,,,,,,,,
435.492,2.62758,0.99036,10,,,,,,,,,,,,,,,,,,,,,,,,,,,,,,,,,,,,,
436.292,2.62548,1.01946,10,,,,,,,,,,,,,,,,,,,,,,,,,,,,,,,,,,,,,
437.092,2.61528,0.9938,10,,,,,,,,,,,,,,,,,,,,,,,,,,,,,,,,,,,,,
437.892,2.5717,0.88033,10,,,,,,,,,,,,,,,,,,,,,,,,,,,,,,,,,,,,,
438.692,2.54082,0.8539,10,,,,,,,,,,,,,,,,,,,,,,,,,,,,,,,,,,,,,
439.492,2.5398,0.78712,10,,,,,,,,,,,,,,,,,,,,,,,,,,,,,,,,,,,,,
440.292,2.54003,0.8053,10,,,,,,,,,,,,,,,,,,,,,,,,,,,,,,,,,,,,,
441.092,2.54031,0.79285,10,,,,,,,,,,,,,,,,,,,,,,,,,,,,,,,,,,,,,
441.892,2.54076,0.73882,10,,,,,,,,,,,,,,,,,,,,,,,,,,,,,,,,,,,,,
442.692,2.54201,0.75156,10,,,,,,,,,,,,,,,,,,,,,,,,,,,,,,,,,,,,,
443.492,2.54745,0.82808,10,,,,,,,,,,,,,,,,,,,,,,,,,,,,,,,,,,,,,
444.292,2.57431,0.87018,10,,,,,,,,,,,,,,,,,,,,,,,,,,,,,,,,,,,,,
445.092,2.62525,0.98922,10,,,,,,,,,,,,,,,,,,,,,,,,,,,,,,,,,,,,,
445.892,2.63132,1.03345,10,,,,,,,,,,,,,,,,,,,,,,,,,,,,,,,,,,,,,
446.692,2.63103,1.01278,10,,,,,,,,,,,,,,,,,,,,,,,,,,,,,,,,,,,,,
447.492,2.62911,1.04651,10,,,,,,,,,,,,,,,,,,,,,,,,,,,,,,,,,,,,,
448.292,2.62072,0.9685,10,,,,,,,,,,,,,,,,,,,,,,,,,,,,,,,,,,,,,
449.092,2.57471,0.88628,10,,,,,,,,,,,,,,,,,,,,,,,,,,,,,,,,,,,,,
449.892,2.5377,0.77703,10,,,,,,,,,,,,,,,,,,,,,,,,,,,,,,,,,,,,,
450.692,2.5364,0.82469,10,,,,,,,,,,,,,,,,,,,,,,,,,,,,,,,,,,,,,
451.492,2.5364,0.82503,10,,,,,,,,,,,,,,,,,,,,,,,,,,,,,,,,,,,,,
452.292,2.53657,0.77851,10,,,,,,,,,,,,,,,,,,,,,,,,,,,,,,,,,,,,,
453.092,2.5368,0.81779,10,,,,,,,,,,,,,,,,,,,,,,,,,,,,,,,,,,,,,
453.892,2.53731,0.74899,10,,,,,,,,,,,,,,,,,,,,,,,,,,,,,,,,,,,,,
454.692,2.53935,0.73974,10,,,,,,,,,,,,,,,,,,,,,,,,,,,,,,,,,,,,,
455.492,2.54802,0.7682,10,,,,,,,,,,,,,,,,,,,,,,,,,,,,,,,,,,,,,
456.292,2.59454,0.93428,10,,,,,,,,,,,,,,,,,,,,,,,,,,,,,,,,,,,,,
457.092,2.63103,0.98378,10,,,,,,,,,,,,,,,,,,,,,,,,,,,,,,,,,,,,,
457.892,2.63132,1.03635,10,,,,,,,,,,,,,,,,,,,,,,,,,,,,,,,,,,,,,
458.692,2.63092,1.03044,10,,,,,,,,,,,,,,,,,,,,,,,,,,,,,,,,,,,,,
459.492,2.62803,1.00295,10,,,,,,,,,,,,,,,,,,,,,,,,,,,,,,,,,,,,,
460.292,2.61976,0.97609,10,,,,,,,,,,,,,,,,,,,,,,,,,,,,,,,,,,,,,
461.092,2.57289,0.89313,10,,,,,,,,,,,,,,,,,,,,,,,,,,,,,,,,,,,,,
461.892,2.54365,0.78153,10,,,,,,,,,,,,,,,,,,,,,,,,,,,,,,,,,,,,,
462.692,2.54122,0.74532,10,,,,,,,,,,,,,,,,,,,,,,,,,,,,,,,,,,,,,
463.492,2.54144,0.79873,10,,,,,,,,,,,,,,,,,,,,,,,,,,,,,,,,,,,,,
464.292,2.54167,0.81638,10,,,,,,,,,,,,,,,,,,,,,,,,,,,,,,,,,,,,,
465.092,2.54229,0.73177,10,,,,,,,,,,,,,,,,,,,,,,,,,,,,,,,,,,,,,
465.892,2.54467,0.77691,10,,,,,,,,,,,,,,,,,,,,,,,,,,,,,,,,,,,,,
466.692,2.5589,0.80877,10,,,,,,,,,,,,,,,,,,,,,,,,,,,,,,,,,,,,,
467.492,2.61766,0.92417,10,,,,,,,,,,,,,,,,,,,,,,,,,,,,,,,,,,,,,
468.292,2.63948,0.99,10,,,,,,,,,,,,,,,,,,,,,,,,,,,,,,,,,,,,,
469.092,2.63936,0.98942,10,,,,,,,,,,,,,,,,,,,,,,,,,,,,,,,,,,,,,
469.892,2.63897,1.05359,10,,,,,,,,,,,,,,,,,,,,,,,,,,,,,,,,,,,,,
470.692,2.63562,1.0593,10,,,,,,,,,,,,,,,,,,,,,,,,,,,,,,,,,,,,,
471.492,2.62129,0.93492,10,,,,,,,,,,,,,,,,,,,,,,,,,,,,,,,,,,,,,
472.292,2.57799,0.84873,10,,,,,,,,,,,,,,,,,,,,,,,,,,,,,,,,,,,,,
473.092,2.56315,0.84622,10,,,,,,,,,,,,,,,,,,,,,,,,,,,,,,,,,,,,,
473.892,2.55805,0.86159,10,,,,,,,,,,,,,,,,,,,,,,,,,,,,,,,,,,,,,
474.692,2.55657,0.84882,10,,,,,,,,,,,,,,,,,,,,,,,,,,,,,,,,,,,,,
475.492,2.55635,0.77834,10,,,,,,,,,,,,,,,,,,,,,,,,,,,,,,,,,,,,,
476.292,2.55657,0.79232,10,,,,,,,,,,,,,,,,,,,,,,,,,,,,,,,,,,,,,
477.092,2.55663,0.81869,10,,,,,,,,,,,,,,,,,,,,,,,,,,,,,,,,,,,,,
477.892,2.55691,0.81348,10,,,,,,,,,,,,,,,,,,,,,,,,,,,,,,,,,,,,,
478.692,2.55748,0.78261,10,,,,,,,,,,,,,,,,,,,,,,,,,,,,,,,,,,,,,
479.492,2.56009,0.76347,10,,,,,,,,,,,,,,,,,,,,,,,,,,,,,,,,,,,,,
480.292,2.57947,0.87401,10,,,,,,,,,,,,,,,,,,,,,,,,,,,,,,,,,,,,,
481.092,2.60185,0.9,10,,,,,,,,,,,,,,,,,,,,,,,,,,,,,,,,,,,,,
481.892,2.60672,0.94072,10,,,,,,,,,,,,,,,,,,,,,,,,,,,,,,,,,,,,,
482.692,2.60706,0.98328,10,,,,,,,,,,,,,,,,,,,,,,,,,,,,,,,,,,,,,
483.492,2.60701,0.91734,10,,,,,,,,,,,,,,,,,,,,,,,,,,,,,,,,,,,,,
484.292,2.60678,0.94583,10,,,,,,,,,,,,,,,,,,,,,,,,,,,,,,,,,,,,,
485.092,2.60667,0.9652,10,,,,,,,,,,,,,,,,,,,,,,,,,,,,,,,,,,,,,
485.892,2.60627,0.94857,10,,,,,,,,,,,,,,,,,,,,,,,,,,,,,,,,,,,,,
486.692,2.60463,0.94353,10,,,,,,,,,,,,,,,,,,,,,,,,,,,,,,,,,,,,,
487.492,2.60009,0.93815,10,,,,,,,,,,,,,,,,,,,,,,,,,,,,,,,,,,,,,
488.292,2.58927,0.92096,10,,,,,,,,,,,,,,,,,,,,,,,,,,,,,,,,,,,,,
489.092,2.57901,0.88677,10,,,,,,,,,,,,,,,,,,,,,,,,,,,,,,,,,,,,,
489.892,2.57522,0.88773,10,,,,,,,,,,,,,,,,,,,,,,,,,,,,,,,,,,,,,
490.692,2.57272,0.8552,10,,,,,,,,,,,,,,,,,,,,,,,,,,,,,,,,,,,,,
491.492,2.57097,0.83457,10,,,,,,,,,,,,,,,,,,,,,,,,,,,,,,,,,,,,,
492.292,2.57029,0.88518,10,,,,,,,,,,,,,,,,,,,,,,,,,,,,,,,,,,,,,
493.092,2.57,0.79976,10,,,,,,,,,,,,,,,,,,,,,,,,,,,,,,,,,,,,,
493.892,2.56995,0.82422,10,,,,,,,,,,,,,,,,,,,,,,,,,,,,,,,,,,,,,
494.692,2.57006,0.88106,10,,,,,,,,,,,,,,,,,,,,,,,,,,,,,,,,,,,,,
495.492,2.57012,0.85693,10,,,,,,,,,,,,,,,,,,,,,,,,,,,,,,,,,,,,,
496.292,2.57023,0.83533,10,,,,,,,,,,,,,,,,,,,,,,,,,,,,,,,,,,,,,
497.092,2.57029,0.86738,10,,,,,,,,,,,,,,,,,,,,,,,,,,,,,,,,,,,,,
497.892,2.57046,0.81785,10,,,,,,,,,,,,,,,,,,,,,,,,,,,,,,,,,,,,,
498.692,2.57074,0.82961,10,,,,,,,,,,,,,,,,,,,,,,,,,,,,,,,,,,,,,
499.492,2.57119,0.84302,10,,,,,,,,,,,,,,,,,,,,,,,,,,,,,,,,,,,,,
500.292,2.57221,0.87208,10,,,,,,,,,,,,,,,,,,,,,,,,,,,,,,,,,,,,,
501.092,2.57612,0.81646,10,,,,,,,,,,,,,,,,,,,,,,,,,,,,,,,,,,,,,
501.892,2.58763,0.88174,10,,,,,,,,,,,,,,,,,,,,,,,,,,,,,,,,,,,,,
502.692,2.60157,0.89812,10,,,,,,,,,,,,,,,,,,,,,,,,,,,,,,,,,,,,,
503.492,2.60525,0.92758,10,,,,,,,,,,,,,,,,,,,,,,,,,,,,,,,,,,,,,
504.292,2.60542,1.02542,10,,,,,,,,,,,,,,,,,,,,,,,,,,,,,,,,,,,,,
505.092,2.60531,0.93937,10,,,,,,,,,,,,,,,,,,,,,,,,,,,,,,,,,,,,,
505.892,2.60519,0.95315,10,,,,,,,,,,,,,,,,,,,,,,,,,,,,,,,,,,,,,
506.692,2.60508,0.91883,10,,,,,,,,,,,,,,,,,,,,,,,,,,,,,,,,,,,,,
507.492,2.6048,0.96966,10,,,,,,,,,,,,,,,,,,,,,,,,,,,,,,,,,,,,,
508.292,2.60315,1.03215,10,,,,,,,,,,,,,,,,,,,,,,,,,,,,,,,,,,,,,
509.092,2.60015,0.92978,10,,,,,,,,,,,,,,,,,,,,,,,,,,,,,,,,,,,,,
509.892,2.59352,0.92108,10,,,,,,,,,,,,,,,,,,,,,,,,,,,,,,,,,,,,,
510.692,2.57737,0.82713,10,,,,,,,,,,,,,,,,,,,,,,,,,,,,,,,,,,,,,
511.492,2.57352,0.87238,10,,,,,,,,,,,,,,,,,,,,,,,,,,,,,,,,,,,,,
512.292,2.57301,0.84222,10,,,,,,,,,,,,,,,,,,,,,,,,,,,,,,,,,,,,,
513.092,2.57301,0.84068,10,,,,,,,,,,,,,,,,,,,,,,,,,,,,,,,,,,,,,
513.892,2.57306,0.84083,10,,,,,,,,,,,,,,,,,,,,,,,,,,,,,,,,,,,,,
514.692,2.57312,0.86877,10,,,,,,,,,,,,,,,,,,,,,,,,,,,,,,,,,,,,,
515.492,2.57306,0.88303,10,,,,,,,,,,,,,,,,,,,,,,,,,,,,,,,,,,,,,
516.292,2.57323,0.93828,10,,,,,,,,,,,,,,,,,,,,,,,,,,,,,,,,,,,,,
517.092,2.57335,0.84428,10,,,,,,,,,,,,,,,,,,,,,,,,,,,,,,,,,,,,,
517.892,2.5734,0.76604,10,,,,,,,,,,,,,,,,,,,,,,,,,,,,,,,,,,,,,
518.692,2.57369,0.85512,10,,,,,,,,,,,,,,,,,,,,,,,,,,,,,,,,,,,,,
519.492,2.57431,0.82808,10,,,,,,,,,,,,,,,,,,,,,,,,,,,,,,,,,,,,,
520.292,2.57601,0.83169,10,,,,,,,,,,,,,,,,,,,,,,,,,,,,,,,,,,,,,
521.092,2.58043,0.85125,10,,,,,,,,,,,,,,,,,,,,,,,,,,,,,,,,,,,,,
521.892,2.59919,0.86436,10,,,,,,,,,,,,,,,,,,,,,,,,,,,,,,,,,,,,,
522.692,2.60842,0.9809,10,,,,,,,,,,,,,,,,,,,,,,,,,,,,,,,,,,,,,
523.492,2.60848,0.9513,10,,,,,,,,,,,,,,,,,,,,,,,,,,,,,,,,,,,,,
524.292,2.60831,0.95982,10,,,,,,,,,,,,,,,,,,,,,,,,,,,,,,,,,,,,,
525.092,2.60814,0.90337,10,,,,,,,,,,,,,,,,,,,,,,,,,,,,,,,,,,,,,
525.892,2.60723,0.96148,10,,,,,,,,,,,,,,,,,,,,,,,,,,,,,,,,,,,,,
526.692,2.60417,0.94114,10,,,,,,,,,,,,,,,,,,,,,,,,,,,,,,,,,,,,,
527.492,2.59828,0.91979,10,,,,,,,,,,,,,,,,,,,,,,,,,,,,,,,,,,,,,
528.292,2.58037,0.8856,10,,,,,,,,,,,,,,,,,,,,,,,,,,,,,,,,,,,,,
529.092,2.57199,0.8116,10,,,,,,,,,,,,,,,,,,,,,,,,,,,,,,,,,,,,,
529.892,2.57091,0.81442,10,,,,,,,,,,,,,,,,,,,,,,,,,,,,,,,,,,,,,
530.692,2.57057,0.86149,10,,,,,,,,,,,,,,,,,,,,,,,,,,,,,,,,,,,,,
531.492,2.57068,0.78002,10,,,,,,,,,,,,,,,,,,,,,,,,,,,,,,,,,,,,,
532.292,2.57074,0.87703,10,,,,,,,,,,,,,,,,,,,,,,,,,,,,,,,,,,,,,
533.092,2.5708,0.86176,10,,,,,,,,,,,,,,,,,,,,,,,,,,,,,,,,,,,,,
533.892,2.57091,0.84143,10,,,,,,,,,,,,,,,,,,,,,,,,,,,,,,,,,,,,,
534.692,2.57108,0.81465,10,,,,,,,,,,,,,,,,,,,,,,,,,,,,,,,,,,,,,
535.492,2.57136,0.79519,10,,,,,,,,,,,,,,,,,,,,,,,,,,,,,,,,,,,,,
536.292,2.57204,0.8261,10,,,,,,,,,,,,,,,,,,,,,,,,,,,,,,,,,,,,,
537.092,2.57374,0.78116,10,,,,,,,,,,,,,,,,,,,,,,,,,,,,,,,,,,,,,
537.892,2.5776,0.84228,10,,,,,,,,,,,,,,,,,,,,,,,,,,,,,,,,,,,,,
538.692,2.59216,0.86978,10,,,,,,,,,,,,,,,,,,,,,,,,,,,,,,,,,,,,,
539.492,2.61143,0.92029,10,,,,,,,,,,,,,,,,,,,,,,,,,,,,,,,,,,,,,
540.292,2.61273,0.97482,10,,,,,,,,,,,,,,,,,,,,,,,,,,,,,,,,,,,,,
541.092,2.61256,0.92207,10,,,,,,,,,,,,,,,,,,,,,,,,,,,,,,,,,,,,,
541.892,2.61245,0.92424,10,,,,,,,,,,,,,,,,,,,,,,,,,,,,,,,,,,,,,
542.692,2.61228,0.95716,10,,,,,,,,,,,,,,,,,,,,,,,,,,,,,,,,,,,,,
543.492,2.6112,0.95603,10,,,,,,,,,,,,,,,,,,,,,,,,,,,,,,,,,,,,,
544.292,2.60735,0.95192,10,,,,,,,,,,,,,,,,,,,,,,,,,,,,,,,,,,,,,
545.092,2.59981,0.95806,10,,,,,,,,,,,,,,,,,,,,,,,,,,,,,,,,,,,,,
545.892,2.58417,0.90769,10,,,,,,,,,,,,,,,,,,,,,,,,,,,,,,,,,,,,,
546.692,2.57238,0.891,10,,,,,,,,,,,,,,,,,,,,,,,,,,,,,,,,,,,,,
547.492,2.57176,0.86116,10,,,,,,,,,,,,,,,,,,,,,,,,,,,,,,,,,,,,,
548.292,2.57165,0.79015,10,,,,,,,,,,,,,,,,,,,,,,,,,,,,,,,,,,,,,
549.092,2.57182,0.78479,10,,,,,,,,,,,,,,,,,,,,,,,,,,,,,,,,,,,,,
549.892,2.57187,0.85193,10,,,,,,,,,,,,,,,,,,,,,,,,,,,,,,,,,,,,,
550.692,2.57199,0.86608,10,,,,,,,,,,,,,,,,,,,,,,,,,,,,,,,,,,,,,
551.492,2.57221,0.81945,10,,,,,,,,,,,,,,,,,,,,,,,,,,,,,,,,,,,,,
552.292,2.57261,0.85161,10,,,,,,,,,,,,,,,,,,,,,,,,,,,,,,,,,,,,,
553.092,2.57329,0.78748,10,,,,,,,,,,,,,,,,,,,,,,,,,,,,,,,,,,,,,
553.892,2.57505,0.80343,10,,,,,,,,,,,,,,,,,,,,,,,,,,,,,,,,,,,,,
554.692,2.57958,0.79351,10,,,,,,,,,,,,,,,,,,,,,,,,,,,,,,,,,,,,,
555.492,2.60769,0.90366,10,,,,,,,,,,,,,,,,,,,,,,,,,,,,,,,,,,,,,
556.292,2.62769,0.96473,10,,,,,,,,,,,,,,,,,,,,,,,,,,,,,,,,,,,,,
557.092,2.62814,1.04695,10,,,,,,,,,,,,,,,,,,,,,,,,,,,,,,,,,,,,,
557.892,2.62786,0.98016,10,,,,,,,,,,,,,,,,,,,,,,,,,,,,,,,,,,,,,
558.692,2.62673,0.98247,10,,,,,,,,,,,,,,,,,,,,,,,,,,,,,,,,,,,,,
559.492,2.61857,1.00781,10,,,,,,,,,,,,,,,,,,,,,,,,,,,,,,,,,,,,,
560.292,2.58496,0.86069,10,,,,,,,,,,,,,,,,,,,,,,,,,,,,,,,,,,,,,
561.092,2.56439,0.85404,10,,,,,,,,,,,,,,,,,,,,,,,,,,,,,,,,,,,,,
561.892,2.56128,0.86828,10,,,,,,,,,,,,,,,,,,,,,,,,,,,,,,,,,,,,,
562.692,2.56105,0.76324,10,,,,,,,,,,,,,,,,,,,,,,,,,,,,,,,,,,,,,
563.492,2.56116,0.8505,10,,,,,,,,,,,,,,,,,,,,,,,,,,,,,,,,,,,,,
564.292,2.56133,0.81961,10,,,,,,,,,,,,,,,,,,,,,,,,,,,,,,,,,,,,,
565.092,2.56145,0.81438,10,,,,,,,,,,,,,,,,,,,,,,,,,,,,,,,,,,,,,
565.892,2.56167,0.776,10,,,,,,,,,,,,,,,,,,,,,,,,,,,,,,,,,,,,,
566.692,2.56235,0.80852,10,,,,,,,,,,,,,,,,,,,,,,,,,,,,,,,,,,,,,
567.492,2.56439,0.79906,10,,,,,,,,,,,,,,,,,,,,,,,,,,,,,,,,,,,,,
568.292,2.57357,0.8553,10,,,,,,,,,,,,,,,,,,,,,,,,,,,,,,,,,,,,,
569.092,2.59006,0.90072,10,,,,,,,,,,,,,,,,,,,,,,,,,,,,,,,,,,,,,
569.892,2.60939,0.90584,10,,,,,,,,,,,,,,,,,,,,,,,,,,,,,,,,,,,,,
570.692,2.61041,0.96022,10,,,,,,,,,,,,,,,,,,,,,,,,,,,,,,,,,,,,,
571.492,2.61035,1.01179,10,,,,,,,,,,,,,,,,,,,,,,,,,,,,,,,,,,,,,
572.292,2.61024,0.94727,10,,,,,,,,,,,,,,,,,,,,,,,,,,,,,,,,,,,,,
573.092,2.61001,0.91608,10,,,,,,,,,,,,,,,,,,,,,,,,,,,,,,,,,,,,,
573.892,2.60888,0.9489,10,,,,,,,,,,,,,,,,,,,,,,,,,,,,,,,,,,,,,
574.692,2.60502,0.9859,10,,,,,,,,,,,,,,,,,,,,,,,,,,,,,,,,,,,,,
575.492,2.59295,0.92711,10,,,,,,,,,,,,,,,,,,,,,,,,,,,,,,,,,,,,,
576.292,2.56808,0.84765,10,,,,,,,,,,,,,,,,,,,,,,,,,,,,,,,,,,,,,
577.092,2.56411,0.84457,10,,,,,,,,,,,,,,,,,,,,,,,,,,,,,,,,,,,,,
577.892,2.56349,0.85284,10,,,,,,,,,,,,,,,,,,,,,,,,,,,,,,,,,,,,,
578.692,2.5636,0.84877,10,,,,,,,,,,,,,,,,,,,,,,,,,,,,,,,,,,,,,
579.492,2.56377,0.7961,10,,,,,,,,,,,,,,,,,,,,,,,,,,,,,,,,,,,,,
580.292,2.56388,0.77968,10,,,,,,,,,,,,,,,,,,,,,,,,,,,,,,,,,,,,,
581.092,2.56422,0.79406,10,,,,,,,,,,,,,,,,,,,,,,,,,,,,,,,,,,,,,
581.892,2.5649,0.74937,10,,,,,,,,,,,,,,,,,,,,,,,,,,,,,,,,,,,,,
582.692,2.56728,0.79453,10,,,,,,,,,,,,,,,,,,,,,,,,,,,,,,,,,,,,,
583.492,2.57799,0.8442,10,,,,,,,,,,,,,,,,,,,,,,,,,,,,,,,,,,,,,
584.292,2.60927,0.88981,10,,,,,,,,,,,,,,,,,,,,,,,,,,,,,,,,,,,,,
585.092,2.62752,0.95524,10,,,,,,,,,,,,,,,,,,,,,,,,,,,,,,,,,,,,,
585.892,2.62792,0.96973,10,,,,,,,,,,,,,,,,,,,,,,,,,,,,,,,,,,,,,
586.594,2.62775,0.95005,10,,,,,,,,,,,,,,,,,,,,,,,,,,,,,,,,,,,,,
587.394,9.09438,140.06454,10,,,,,,,,,,,,,,,,,,,,,,,,,,,,,,,,,,,,,
588.194,15.76104,105.12473,10,,,,,,,,,,,,,,,,,,,,,,,,,,,,,,,,,,,,,
588.994,22.42776,4.45896,10,,,,,,,,,,,,,,,,,,,,,,,,,,,,,,,,,,,,,
589.794,29.09437,1.18246,10,,,,,,,,,,,,,,,,,,,,,,,,,,,,,,,,,,,,,
590.594,35.76103,0.29081,10,,,,,,,,,,,,,,,,,,,,,,,,,,,,,,,,,,,,,
591.164,40.511,0.39346,10,,,,,,,,,,,,,,,,,,,,,,,,,,,,,,,,,,,,,