File: combined_ligament_solver/data/processed/Data Sheet 3_S151624_PCL.csv
Specimen properties : Length,36,mm,Unnamed: 3,Unnamed: 4,Unnamed: 5,Unnamed: 6,Unnamed: 7,Unnamed: 8,Unnamed: 9,Unnamed: 10,Unnamed: 11,Stress-Strain,Unnamed: 13,Unnamed: 14,Unnamed: 15,Unnamed: 16,Unnamed: 17,Unnamed: 18,Unnamed: 19,Unnamed: 20,Unnamed: 21,Unnamed: 22,Unnamed: 23,Unnamed: 24,Unnamed: 25,Unnamed: 26,Unnamed: 27,Linear,Unnamed: 29,Unnamed: 30,Unnamed: 31,Unnamed: 32,Unnamed: 33,Modulus,Unnamed: 35,Failure,Unnamed: 37,Unnamed: 38,Unnamed: 39,Unnamed: 40
Cross Section Average,86.52600000000001,mm2,,,,,,,,,,Polynomial Coefficients,,,,,,,,,,,,,,,,Force,,Stress,Extension,Strain,,Secant,Tangent,Load,Stress,Extension,Strain,Stiffness
Time,Extension,Load,Total cycle count,,,Extension,Load,Strain,Stress,E-tan,,X6,-263693.7821239411,,,,,,,,,Strain,Stress,E-tan,,,,(N),,(MPa),(mm),(%),,(MPa),(MPa),(N),(MPa),(mm),(%),(N/mm)
(s),(mm),(N),,,,(mm),(N),(mm/mm),(MPa),(MPa),,X5,407693.83902849234,,,,,,,,,(mm/mm),(MPa),(MPa),,,,446.36381187019913,,5.1587246824099005,3.276,9.1,,56.68928222428462,101.4019364034854,907.23096,10.4850676097358,7.36667,20.462972222222223,136.2526898260681
0.5,0.14359,2.27739,0,,,4.33772,624.66284,0.11203472222222222,7.219365739777638,90.01178197538393,,,,,,,,,,,,0.005,0.03016092152612373,6.393230696783594,,,,,,,,,,,,,,,,
1.1,0.2435,4.21832,0,,,9.33821,635.90137,,,,,,,,,,,,,,,0.011,0.07892578942139444,9.754416990583485,,,,,,,,,,,,,,,,
1.7,0.34346,6.22315,0,,,14.33786,260.25705,,,,,,,,,,,,,,,0.017,0.15678174851787677,15.572524769993503,,,,,,,,,,,,,,,,
2.3,0.44336,8.55162,0,,,,,,,,,,,,,,,,,,,0.023,0.276208420436292,23.209639636741365,,,,,,,,,,,,,,,,
2.9,0.54355,11.47025,0,,,,,,,,,,,,,,,,,,,0.029,0.44606636414103645,32.087191782357884,,,,,,,,,,,,,,,,
3.5,0.64356,14.94798,0,,,,,,,,,,,,,,,,,,,0.035,0.6719479762622178,41.68447964052509,,,,,,,,,,,,,,,,
4.1,0.74341,18.25405,0,,,,,,,,,,,,,,,,,,,0.041,0.9565195333317822,51.53719353942483,,,,,,,,,,,,,,,,
4.7,0.84343,22.88534,0,,,,,,,,,,,,,,,,,,,0.047,1.2998543759337278,61.23593935408573,,,,,,,,,,,,,,,,
5.3,0.94356,28.24182,0,,,,,,,,,,,,,,,,,,,0.053,1.6997572347684107,70.42476215873232,,,,,,,,,,,,,,,,
5.9,1.04357,34.46042,0,,,,,,,,,,,,,,,,,,,0.059,2.152079698630936,78.79966987913492,,,,,,,,,,,,,,,,
6.38,1.12342,40.02563,0.5,,,,,,,,,,,,,,,,,,,0.065,2.6510268243036395,86.10715694495089,,,,,,,,,,,,,,,,
6.98,1.02317,31.42832,0.5,,,,,,,,,,,,,,,,,,,0.071,3.1894548883626586,92.1427279420851,,,,,,,,,,,,,,,,
7.58,0.9231,24.04467,0.5,,,,,,,,,,,,,,,,,,,0.077,3.7591602808985933,96.7494212650223,,,,,,,,,,,,,,,,
8.18,0.82325,18.24935,0.5,,,,,,,,,,,,,,,,,,,0.083,4.351159541151253,99.81633276919223,,,,,,,,,,,,,,,,
8.78,0.72329,13.63125,0.5,,,,,,,,,,,,,,,,,,,0.089,4.955960535058487,101.27713942329999,,,,,,,,,,,,,,,,
9.38,0.62316,9.70011,0.5,,,,,,,,,,,,,,,,,,,0.095,5.563824774719128,101.10862296169633,,,,,,,,,,,,,,,,
9.98,0.52309,6.65069,0.5,,,,,,,,,,,,,,,,,,,0.101,6.165020879769987,99.32919353669858,,,,,,,,,,,,,,,,
10.58,0.42324,4.24942,0.5,,,,,,,,,,,,,,,,,,,0.107,6.750069180676969,95.99741337096015,,,,,,,,,,,,,,,,
11.18,0.32328,2.31333,0.5,,,,,,,,,,,,,,,,,,,0.113,7.309977463940265,91.21052040980874,,,,,,,,,,,,,,,,
11.752,0.2278,0.99573,1,,,,,,,,,,,,,,,,,,,0.119,7.836467859213628,85.10295197359855,,,,,,,,,,,,,,,,
12.156,0.29472,2.05868,1,,,,,,,,,,,,,,,,,,,0.125,8.322194868337755,77.84486841007691,,,,,,,,,,,,,,,,
12.756,0.3948,4.55038,1,,,,,,,,,,,,,,,,,,,0.131,8.760954536287711,69.64067674665657,,,,,,,,,,,,,,,,
13.356,0.49481,7.03961,1,,,,,,,,,,,,,,,,,,,0.137,9.147884764034554,60.727554342893285,,,,,,,,,,,,,,,,
13.956,0.59489,10.23659,1,,,,,,,,,,,,,,,,,,,0.143,9.479656763320893,51.3739725427324,,,,,,,,,,,,,,,,
14.556,0.69479,14.11253,1,,,,,,,,,,,,,,,,,,,0.149,9.754657653350627,41.87822032682038,,,,,,,,,,,,,,,,
15.156,0.79486,18.12107,1,,,,,,,,,,,,,,,,,,,0.155,9.973164199392778,32.566927965046204,,,,,,,,,,,,,,,,
15.756,0.89482,23.47547,1,,,,,,,,,,,,,,,,,,,0.161,10.137507693299431,23.79359066860862,,,,,,,,,,,,,,,,
16.356,0.9949,29.57898,1,,,,,,,,,,,,,,,,,,,0.167,10.252229975937674,15.937092242710436,,,,,,,,,,,,,,,,
16.956,1.09486,36.66627,1,,,,,,,,,,,,,,,,,,,0.173,10.324230601535671,9.400228738474672,,,,,,,,,,,,,,,,
17.424,1.10642,37.44114,1.5,,,,,,,,,,,,,,,,,,,0.179,10.362905143942845,4.608232105745453,,,,,,,,,,,,,,,,
18.024,1.006,28.78325,1.5,,,,,,,,,,,,,,,,,,,0.185,10.380274644804278,2.007293845135647,,,,,,,,,,,,,,,,
18.624,0.90587,21.9874,1.5,,,,,,,,,,,,,,,,,,,0.191,10.391106203648711,2.0630886604351395,,,,,,,,,,,,,,,,
19.224,0.8058,16.56069,1.5,,,,,,,,,,,,,,,,,,,0.197,10.41302470989133,5.2592981109729156,,,,,,,,,,,,,,,,
19.824,0.70584,12.16155,1.5,,,,,,,,,,,,,,,,,,,,,,,,,,,,,,,,,,,,,
20.424,0.60594,8.47933,1.5,,,,,,,,,,,,,,,,,,,,,,,,,,,,,,,,,,,,,
21.024,0.50586,5.63648,1.5,,,,,,,,,,,,,,,,,,,,,,,,,,,,,,,,,,,,,
21.624,0.40573,3.35257,1.5,,,,,,,,,,,,,,,,,,,,,,,,,,,,,,,,,,,,,
22.224,0.30589,1.6243,1.5,,,,,,,,,,,,,,,,,,,,,,,,,,,,,,,,,,,,,
22.544,0.25256,0.96961,2,,,,,,,,,,,,,,,,,,,,,,,,,,,,,,,,,,,,,
23.144,0.35349,2.89494,2,,,,,,,,,,,,,,,,,,,,,,,,,,,,,,,,,,,,,
23.744,0.45339,5.34881,2,,,,,,,,,,,,,,,,,,,,,,,,,,,,,,,,,,,,,
24.344,0.55341,8.16719,2,,,,,,,,,,,,,,,,,,,,,,,,,,,,,,,,,,,,,
24.944,0.65359,11.73297,2,,,,,,,,,,,,,,,,,,,,,,,,,,,,,,,,,,,,,
25.544,0.7535,15.99472,2,,,,,,,,,,,,,,,,,,,,,,,,,,,,,,,,,,,,,
26.144,0.85334,20.37207,2,,,,,,,,,,,,,,,,,,,,,,,,,,,,,,,,,,,,,
26.744,0.95347,26.03268,2,,,,,,,,,,,,,,,,,,,,,,,,,,,,,,,,,,,,,
27.344,1.0536,32.75579,2,,,,,,,,,,,,,,,,,,,,,,,,,,,,,,,,,,,,,
27.914,1.14846,40.02677,2.5,,,,,,,,,,,,,,,,,,,,,,,,,,,,,,,,,,,,,
28.416,1.06533,32.81655,2.5,,,,,,,,,,,,,,,,,,,,,,,,,,,,,,,,,,,,,
29.016,0.96515,25.12452,2.5,,,,,,,,,,,,,,,,,,,,,,,,,,,,,,,,,,,,,
29.616,0.86513,19.06863,2.5,,,,,,,,,,,,,,,,,,,,,,,,,,,,,,,,,,,,,
30.216,0.76528,14.19531,2.5,,,,,,,,,,,,,,,,,,,,,,,,,,,,,,,,,,,,,
30.816,0.66521,10.14507,2.5,,,,,,,,,,,,,,,,,,,,,,,,,,,,,,,,,,,,,
31.416,0.56519,6.85434,2.5,,,,,,,,,,,,,,,,,,,,,,,,,,,,,,,,,,,,,
32.016,0.46506,4.32446,2.5,,,,,,,,,,,,,,,,,,,,,,,,,,,,,,,,,,,,,
32.616,0.36527,2.37885,2.5,,,,,,,,,,,,,,,,,,,,,,,,,,,,,,,,,,,,,
33.17,0.27291,0.99786,3,,,,,,,,,,,,,,,,,,,,,,,,,,,,,,,,,,,,,
33.574,0.33983,2.09736,3,,,,,,,,,,,,,,,,,,,,,,,,,,,,,,,,,,,,,
34.174,0.43985,4.59079,3,,,,,,,,,,,,,,,,,,,,,,,,,,,,,,,,,,,,,
34.774,0.53986,7.29302,3,,,,,,,,,,,,,,,,,,,,,,,,,,,,,,,,,,,,,
35.374,0.63977,10.71393,3,,,,,,,,,,,,,,,,,,,,,,,,,,,,,,,,,,,,,
35.974,0.73978,14.85772,3,,,,,,,,,,,,,,,,,,,,,,,,,,,,,,,,,,,,,
36.574,0.8398,19.07133,3,,,,,,,,,,,,,,,,,,,,,,,,,,,,,,,,,,,,,
37.174,0.93987,24.66057,3,,,,,,,,,,,,,,,,,,,,,,,,,,,,,,,,,,,,,
37.774,1.03983,31.19376,3,,,,,,,,,,,,,,,,,,,,,,,,,,,,,,,,,,,,,
38.374,1.13979,38.72336,3,,,,,,,,,,,,,,,,,,,,,,,,,,,,,,,,,,,,,
38.87,1.08885,34.23423,3.5,,,,,,,,,,,,,,,,,,,,,,,,,,,,,,,,,,,,,
39.47,0.98895,26.27496,3.5,,,,,,,,,,,,,,,,,,,,,,,,,,,,,,,,,,,,,
40.07,0.88882,19.97914,3.5,,,,,,,,,,,,,,,,,,,,,,,,,,,,,,,,,,,,,
40.67,0.78891,14.86897,3.5,,,,,,,,,,,,,,,,,,,,,,,,,,,,,,,,,,,,,
41.27,0.68878,10.7501,3.5,,,,,,,,,,,,,,,,,,,,,,,,,,,,,,,,,,,,,
41.87,0.58888,7.37761,3.5,,,,,,,,,,,,,,,,,,,,,,,,,,,,,,,,,,,,,
42.47,0.48886,4.63334,3.5,,,,,,,,,,,,,,,,,,,,,,,,,,,,,,,,,,,,,
43.07,0.38896,2.55119,3.5,,,,,,,,,,,,,,,,,,,,,,,,,,,,,,,,,,,,,
43.67,0.28872,1.05054,3.5,,,,,,,,,,,,,,,,,,,,,,,,,,,,,,,,,,,,,
44.01,0.33303,1.69917,4,,,,,,,,,,,,,,,,,,,,,,,,,,,,,,,,,,,,,
44.61,0.43316,4.12878,4,,,,,,,,,,,,,,,,,,,,,,,,,,,,,,,,,,,,,
45.21,0.53323,6.84724,4,,,,,,,,,,,,,,,,,,,,,,,,,,,,,,,,,,,,,
45.81,0.63314,10.16317,4,,,,,,,,,,,,,,,,,,,,,,,,,,,,,,,,,,,,,
46.41,0.7331,14.15114,4,,,,,,,,,,,,,,,,,,,,,,,,,,,,,,,,,,,,,
47.01,0.83311,18.32374,4,,,,,,,,,,,,,,,,,,,,,,,,,,,,,,,,,,,,,
47.61,0.9333,23.81903,4,,,,,,,,,,,,,,,,,,,,,,,,,,,,,,,,,,,,,
48.21,1.03315,30.25637,4,,,,,,,,,,,,,,,,,,,,,,,,,,,,,,,,,,,,,
48.81,1.13305,37.71283,4,,,,,,,,,,,,,,,,,,,,,,,,,,,,,,,,,,,,,
49.276,1.11072,35.7458,4.5,,,,,,,,,,,,,,,,,,,,,,,,,,,,,,,,,,,,,
49.876,1.01059,27.44067,4.5,,,,,,,,,,,,,,,,,,,,,,,,,,,,,,,,,,,,,
50.476,0.91041,20.79681,4.5,,,,,,,,,,,,,,,,,,,,,,,,,,,,,,,,,,,,,
51.076,0.8105,15.59372,4.5,,,,,,,,,,,,,,,,,,,,,,,,,,,,,,,,,,,,,
51.676,0.7106,11.36402,4.5,,,,,,,,,,,,,,,,,,,,,,,,,,,,,,,,,,,,,
52.276,0.61053,7.79849,4.5,,,,,,,,,,,,,,,,,,,,,,,,,,,,,,,,,,,,,
52.876,0.51045,5.02913,4.5,,,,,,,,,,,,,,,,,,,,,,,,,,,,,,,,,,,,,
53.476,0.41049,2.85112,4.5,,,,,,,,,,,,,,,,,,,,,,,,,,,,,,,,,,,,,
54.076,0.31059,1.24683,4.5,,,,,,,,,,,,,,,,,,,,,,,,,,,,,,,,,,,,,
54.392,0.32504,1.37912,5,,,,,,,,,,,,,,,,,,,,,,,,,,,,,,,,,,,,,
54.992,0.42562,3.77066,5,,,,,,,,,,,,,,,,,,,,,,,,,,,,,,,,,,,,,
55.592,0.52547,6.38249,5,,,,,,,,,,,,,,,,,,,,,,,,,,,,,,,,,,,,,
56.192,0.62543,9.62177,5,,,,,,,,,,,,,,,,,,,,,,,,,,,,,,,,,,,,,
56.792,0.72545,13.58152,5,,,,,,,,,,,,,,,,,,,,,,,,,,,,,,,,,,,,,
57.392,0.82563,17.52547,5,,,,,,,,,,,,,,,,,,,,,,,,,,,,,,,,,,,,,
57.992,0.92559,23.08514,5,,,,,,,,,,,,,,,,,,,,,,,,,,,,,,,,,,,,,
58.592,1.02538,29.36407,5,,,,,,,,,,,,,,,,,,,,,,,,,,,,,,,,,,,,,
59.192,1.12546,36.69489,5,,,,,,,,,,,,,,,,,,,,,,,,,,,,,,,,,,,,,
59.636,1.13299,37.45647,5.5,,,,,,,,,,,,,,,,,,,,,,,,,,,,,,,,,,,,,
60.236,1.03247,28.7606,5.5,,,,,,,,,,,,,,,,,,,,,,,,,,,,,,,,,,,,,
60.836,0.93262,21.88444,5.5,,,,,,,,,,,,,,,,,,,,,,,,,,,,,,,,,,,,,
61.436,0.8326,16.43056,5.5,,,,,,,,,,,,,,,,,,,,,,,,,,,,,,,,,,,,,
62.036,0.73253,12.14016,5.5,,,,,,,,,,,,,,,,,,,,,,,,,,,,,,,,,,,,,
62.636,0.6324,8.34916,5.5,,,,,,,,,,,,,,,,,,,,,,,,,,,,,,,,,,,,,
63.236,0.53255,5.49372,5.5,,,,,,,,,,,,,,,,,,,,,,,,,,,,,,,,,,,,,
63.836,0.43259,3.1055,5.5,,,,,,,,,,,,,,,,,,,,,,,,,,,,,,,,,,,,,
64.436,0.33258,1.40552,5.5,,,,,,,,,,,,,,,,,,,,,,,,,,,,,,,,,,,,,
64.82,0.33569,1.38415,6,,,,,,,,,,,,,,,,,,,,,,,,,,,,,,,,,,,,,
65.42,0.43616,3.84332,6,,,,,,,,,,,,,,,,,,,,,,,,,,,,,,,,,,,,,
66.02,0.53629,6.56303,6,,,,,,,,,,,,,,,,,,,,,,,,,,,,,,,,,,,,,
66.62,0.63608,9.81126,6,,,,,,,,,,,,,,,,,,,,,,,,,,,,,,,,,,,,,
67.22,0.7361,13.82238,6,,,,,,,,,,,,,,,,,,,,,,,,,,,,,,,,,,,,,
67.82,0.83617,17.83061,6,,,,,,,,,,,,,,,,,,,,,,,,,,,,,,,,,,,,,
68.42,0.9363,23.41029,6,,,,,,,,,,,,,,,,,,,,,,,,,,,,,,,,,,,,,
69.02,1.03615,29.83467,6,,,,,,,,,,,,,,,,,,,,,,,,,,,,,,,,,,,,,
69.62,1.13611,37.2555,6,,,,,,,,,,,,,,,,,,,,,,,,,,,,,,,,,,,,,
70.028,1.13753,37.49684,6.5,,,,,,,,,,,,,,,,,,,,,,,,,,,,,,,,,,,,,
70.628,1.03717,28.7944,6.5,,,,,,,,,,,,,,,,,,,,,,,,,,,,,,,,,,,,,
71.228,0.93727,21.87574,6.5,,,,,,,,,,,,,,,,,,,,,,,,,,,,,,,,,,,,,
71.828,0.83725,16.40304,6.5,,,,,,,,,,,,,,,,,,,,,,,,,,,,,,,,,,,,,
72.428,0.73712,12.05862,6.5,,,,,,,,,,,,,,,,,,,,,,,,,,,,,,,,,,,,,
73.028,0.63716,8.39908,6.5,,,,,,,,,,,,,,,,,,,,,,,,,,,,,,,,,,,,,
73.628,0.53726,5.48496,6.5,,,,,,,,,,,,,,,,,,,,,,,,,,,,,,,,,,,,,
74.228,0.43718,3.11036,6.5,,,,,,,,,,,,,,,,,,,,,,,,,,,,,,,,,,,,,
74.828,0.33722,1.30836,6.5,,,,,,,,,,,,,,,,,,,,,,,,,,,,,,,,,,,,,
75.146,0.31337,0.92581,7,,,,,,,,,,,,,,,,,,,,,,,,,,,,,,,,,,,,,
75.746,0.41854,3.22018,7,,,,,,,,,,,,,,,,,,,,,,,,,,,,,,,,,,,,,
76.346,0.51839,5.85835,7,,,,,,,,,,,,,,,,,,,,,,,,,,,,,,,,,,,,,
76.946,0.61846,9.04405,7,,,,,,,,,,,,,,,,,,,,,,,,,,,,,,,,,,,,,
77.546,0.71853,12.89055,7,,,,,,,,,,,,,,,,,,,,,,,,,,,,,,,,,,,,,
78.146,0.81861,16.99057,7,,,,,,,,,,,,,,,,,,,,,,,,,,,,,,,,,,,,,
78.746,0.9184,22.13226,7,,,,,,,,,,,,,,,,,,,,,,,,,,,,,,,,,,,,,
79.346,1.01841,28.28374,7,,,,,,,,,,,,,,,,,,,,,,,,,,,,,,,,,,,,,
79.946,1.11854,35.57856,7,,,,,,,,,,,,,,,,,,,,,,,,,,,,,,,,,,,,,
80.378,1.16144,39.80445,7.5,,,,,,,,,,,,,,,,,,,,,,,,,,,,,,,,,,,,,
80.978,1.05695,30.10367,7.5,,,,,,,,,,,,,,,,,,,,,,,,,,,,,,,,,,,,,
81.578,0.95687,22.89713,7.5,,,,,,,,,,,,,,,,,,,,,,,,,,,,,,,,,,,,,
82.178,0.85674,17.19384,7.5,,,,,,,,,,,,,,,,,,,,,,,,,,,,,,,,,,,,,
82.778,0.75684,12.7333,7.5,,,,,,,,,,,,,,,,,,,,,,,,,,,,,,,,,,,,,
83.378,0.65694,8.91464,7.5,,,,,,,,,,,,,,,,,,,,,,,,,,,,,,,,,,,,,
83.978,0.55686,5.93452,7.5,,,,,,,,,,,,,,,,,,,,,,,,,,,,,,,,,,,,,
84.578,0.45673,3.4066,7.5,,,,,,,,,,,,,,,,,,,,,,,,,,,,,,,,,,,,,
85.178,0.35683,1.52563,7.5,,,,,,,,,,,,,,,,,,,,,,,,,,,,,,,,,,,,,
85.532,0.32685,1.09244,8,,,,,,,,,,,,,,,,,,,,,,,,,,,,,,,,,,,,,
86.132,0.43214,3.44162,8,,,,,,,,,,,,,,,,,,,,,,,,,,,,,,,,,,,,,
86.732,0.53221,6.10348,8,,,,,,,,,,,,,,,,,,,,,,,,,,,,,,,,,,,,,
87.332,0.63212,9.32212,8,,,,,,,,,,,,,,,,,,,,,,,,,,,,,,,,,,,,,
87.932,0.73213,13.33876,8,,,,,,,,,,,,,,,,,,,,,,,,,,,,,,,,,,,,,
88.532,0.83215,17.23035,8,,,,,,,,,,,,,,,,,,,,,,,,,,,,,,,,,,,,,
89.132,0.93228,22.70971,8,,,,,,,,,,,,,,,,,,,,,,,,,,,,,,,,,,,,,
89.732,1.03213,29.04292,8,,,,,,,,,,,,,,,,,,,,,,,,,,,,,,,,,,,,,
90.332,1.13209,36.42436,8,,,,,,,,,,,,,,,,,,,,,,,,,,,,,,,,,,,,,
90.8,1.14359,37.46152,8.5,,,,,,,,,,,,,,,,,,,,,,,,,,,,,,,,,,,,,
91.4,1.04318,28.75665,8.5,,,,,,,,,,,,,,,,,,,,,,,,,,,,,,,,,,,,,
92,0.94322,21.86179,8.5,,,,,,,,,,,,,,,,,,,,,,,,,,,,,,,,,,,,,
92.6,0.84326,16.36109,8.5,,,,,,,,,,,,,,,,,,,,,,,,,,,,,,,,,,,,,
93.2,0.74307,12.0554,8.5,,,,,,,,,,,,,,,,,,,,,,,,,,,,,,,,,,,,,
93.8,0.64317,8.36365,8.5,,,,,,,,,,,,,,,,,,,,,,,,,,,,,,,,,,,,,
94.4,0.54326,5.49066,8.5,,,,,,,,,,,,,,,,,,,,,,,,,,,,,,,,,,,,,
95,0.44325,3.06058,8.5,,,,,,,,,,,,,,,,,,,,,,,,,,,,,,,,,,,,,
95.6,0.34317,1.31709,8.5,,,,,,,,,,,,,,,,,,,,,,,,,,,,,,,,,,,,,
95.954,0.35145,1.44366,9,,,,,,,,,,,,,,,,,,,,,,,,,,,,,,,,,,,,,
96.554,0.4518,3.82401,9,,,,,,,,,,,,,,,,,,,,,,,,,,,,,,,,,,,,,
97.154,0.55176,6.53539,9,,,,,,,,,,,,,,,,,,,,,,,,,,,,,,,,,,,,,
97.754,0.65189,9.94601,9,,,,,,,,,,,,,,,,,,,,,,,,,,,,,,,,,,,,,
98.354,0.75185,14.01395,9,,,,,,,,,,,,,,,,,,,,,,,,,,,,,,,,,,,,,
98.954,0.85176,18.1589,9,,,,,,,,,,,,,,,,,,,,,,,,,,,,,,,,,,,,,
99.554,0.95177,23.65249,9,,,,,,,,,,,,,,,,,,,,,,,,,,,,,,,,,,,,,
100.154,1.0519,30.18192,9,,,,,,,,,,,,,,,,,,,,,,,,,,,,,,,,,,,,,
100.754,1.15186,37.79588,9,,,,,,,,,,,,,,,,,,,,,,,,,,,,,,,,,,,,,
101.224,1.12993,35.89874,9.5,,,,,,,,,,,,,,,,,,,,,,,,,,,,,,,,,,,,,
101.824,1.0298,27.53964,9.5,,,,,,,,,,,,,,,,,,,,,,,,,,,,,,,,,,,,,
102.424,0.92996,20.83841,9.5,,,,,,,,,,,,,,,,,,,,,,,,,,,,,,,,,,,,,
103.024,0.82994,15.58323,9.5,,,,,,,,,,,,,,,,,,,,,,,,,,,,,,,,,,,,,
103.624,0.72987,11.40004,9.5,,,,,,,,,,,,,,,,,,,,,,,,,,,,,,,,,,,,,
104.224,0.62974,7.78892,9.5,,,,,,,,,,,,,,,,,,,,,,,,,,,,,,,,,,,,,
104.824,0.52989,5.0059,9.5,,,,,,,,,,,,,,,,,,,,,,,,,,,,,,,,,,,,,
105.424,0.42993,2.67449,9.5,,,,,,,,,,,,,,,,,,,,,,,,,,,,,,,,,,,,,
106.024,0.3298,1.10513,9.5,,,,,,,,,,,,,,,,,,,,,,,,,,,,,,,,,,,,,
106.46,0.29676,0.60246,10,,,,,,,,,,,,,,,,,,,,,,,,,,,,,,,,,,,,,
107.06,0.29875,0.69852,10,,,,,,,,,,,,,,,,,,,,,,,,,,,,,,,,,,,,,
107.66,0.3332,1.32386,10,,,,,,,,,,,,,,,,,,,,,,,,,,,,,,,,,,,,,
108.26,0.34963,1.56882,10,,,,,,,,,,,,,,,,,,,,,,,,,,,,,,,,,,,,,
108.86,0.34901,1.48452,10,,,,,,,,,,,,,,,,,,,,,,,,,,,,,,,,,,,,,
109.46,0.34136,1.40833,10,,,,,,,,,,,,,,,,,,,,,,,,,,,,,,,,,,,,,
110.06,0.32459,1.13988,10,,,,,,,,,,,,,,,,,,,,,,,,,,,,,,,,,,,,,
110.66,0.32107,1.14707,10,,,,,,,,,,,,,,,,,,,,,,,,,,,,,,,,,,,,,
111.26,0.32113,1.15784,10,,,,,,,,,,,,,,,,,,,,,,,,,,,,,,,,,,,,,
111.86,0.32124,1.15785,10,,,,,,,,,,,,,,,,,,,,,,,,,,,,,,,,,,,,,
112.46,0.32136,1.13489,10,,,,,,,,,,,,,,,,,,,,,,,,,,,,,,,,,,,,,
113.06,0.32141,1.29862,10,,,,,,,,,,,,,,,,,,,,,,,,,,,,,,,,,,,,,
113.66,0.32147,1.26012,10,,,,,,,,,,,,,,,,,,,,,,,,,,,,,,,,,,,,,
114.26,0.32153,1.24886,10,,,,,,,,,,,,,,,,,,,,,,,,,,,,,,,,,,,,,
114.86,0.32158,1.14892,10,,,,,,,,,,,,,,,,,,,,,,,,,,,,,,,,,,,,,
115.46,0.32164,1.21599,10,,,,,,,,,,,,,,,,,,,,,,,,,,,,,,,,,,,,,
116.06,0.32164,1.27423,10,,,,,,,,,,,,,,,,,,,,,,,,,,,,,,,,,,,,,
116.66,0.32164,1.22159,10,,,,,,,,,,,,,,,,,,,,,,,,,,,,,,,,,,,,,
117.26,0.32164,1.22928,10,,,,,,,,,,,,,,,,,,,,,,,,,,,,,,,,,,,,,
117.86,0.32164,1.23432,10,,,,,,,,,,,,,,,,,,,,,,,,,,,,,,,,,,,,,
118.46,0.32164,1.20885,10,,,,,,,,,,,,,,,,,,,,,,,,,,,,,,,,,,,,,
119.06,0.32164,1.22413,10,,,,,,,,,,,,,,,,,,,,,,,,,,,,,,,,,,,,,
119.66,0.32153,1.27,10,,,,,,,,,,,,,,,,,,,,,,,,,,,,,,,,,,,,,
120.26,0.32164,1.259,10,,,,,,,,,,,,,,,,,,,,,,,,,,,,,,,,,,,,,
120.86,0.32153,1.2247,10,,,,,,,,,,,,,,,,,,,,,,,,,,,,,,,,,,,,,
121.46,0.32153,1.24309,10,,,,,,,,,,,,,,,,,,,,,,,,,,,,,,,,,,,,,
122.06,0.32147,1.2946,10,,,,,,,,,,,,,,,,,,,,,,,,,,,,,,,,,,,,,
122.66,0.32158,1.22327,10,,,,,,,,,,,,,,,,,,,,,,,,,,,,,,,,,,,,,
123.26,0.32147,1.20941,10,,,,,,,,,,,,,,,,,,,,,,,,,,,,,,,,,,,,,
123.86,0.32147,1.2259,10,,,,,,,,,,,,,,,,,,,,,,,,,,,,,,,,,,,,,
124.46,0.32147,1.31731,10,,,,,,,,,,,,,,,,,,,,,,,,,,,,,,,,,,,,,
125.06,0.32147,1.25811,10,,,,,,,,,,,,,,,,,,,,,,,,,,,,,,,,,,,,,
125.66,0.32153,1.21709,10,,,,,,,,,,,,,,,,,,,,,,,,,,,,,,,,,,,,,
126.26,0.32141,1.24301,10,,,,,,,,,,,,,,,,,,,,,,,,,,,,,,,,,,,,,
126.86,0.32147,1.2238,10,,,,,,,,,,,,,,,,,,,,,,,,,,,,,,,,,,,,,
127.46,0.32136,1.28295,10,,,,,,,,,,,,,,,,,,,,,,,,,,,,,,,,,,,,,
128.06,0.3213,1.24887,10,,,,,,,,,,,,,,,,,,,,,,,,,,,,,,,,,,,,,
128.66,0.32124,1.26464,10,,,,,,,,,,,,,,,,,,,,,,,,,,,,,,,,,,,,,
129.26,0.32119,1.22052,10,,,,,,,,,,,,,,,,,,,,,,,,,,,,,,,,,,,,,
129.86,0.32113,1.24071,10,,,,,,,,,,,,,,,,,,,,,,,,,,,,,,,,,,,,,
130.46,0.32096,1.2598,10,,,,,,,,,,,,,,,,,,,,,,,,,,,,,,,,,,,,,
131.06,0.32062,1.27974,10,,,,,,,,,,,,,,,,,,,,,,,,,,,,,,,,,,,,,
131.66,0.31892,1.25132,10,,,,,,,,,,,,,,,,,,,,,,,,,,,,,,,,,,,,,
132.26,0.31773,1.2324,10,,,,,,,,,,,,,,,,,,,,,,,,,,,,,,,,,,,,,
132.86,0.31665,1.1974,10,,,,,,,,,,,,,,,,,,,,,,,,,,,,,,,,,,,,,
133.46,0.31626,1.21785,10,,,,,,,,,,,,,,,,,,,,,,,,,,,,,,,,,,,,,
134.06,0.31609,1.11247,10,,,,,,,,,,,,,,,,,,,,,,,,,,,,,,,,,,,,,
134.66,0.31603,1.216,10,,,,,,,,,,,,,,,,,,,,,,,,,,,,,,,,,,,,,
135.26,0.31614,1.2353,10,,,,,,,,,,,,,,,,,,,,,,,,,,,,,,,,,,,,,
135.86,0.3162,1.18833,10,,,,,,,,,,,,,,,,,,,,,,,,,,,,,,,,,,,,,
136.46,0.3162,1.27001,10,,,,,,,,,,,,,,,,,,,,,,,,,,,,,,,,,,,,,
137.06,0.31626,1.20371,10,,,,,,,,,,,,,,,,,,,,,,,,,,,,,,,,,,,,,
137.66,0.31626,1.22848,10,,,,,,,,,,,,,,,,,,,,,,,,,,,,,,,,,,,,,
138.26,0.31631,1.20284,10,,,,,,,,,,,,,,,,,,,,,,,,,,,,,,,,,,,,,
138.86,0.31631,1.23829,10,,,,,,,,,,,,,,,,,,,,,,,,,,,,,,,,,,,,,
139.46,0.31637,1.20745,10,,,,,,,,,,,,,,,,,,,,,,,,,,,,,,,,,,,,,
140.06,0.31637,1.26333,10,,,,,,,,,,,,,,,,,,,,,,,,,,,,,,,,,,,,,
140.66,0.31637,1.27351,10,,,,,,,,,,,,,,,,,,,,,,,,,,,,,,,,,,,,,
141.26,0.31637,1.20843,10,,,,,,,,,,,,,,,,,,,,,,,,,,,,,,,,,,,,,
141.86,0.31631,1.26521,10,,,,,,,,,,,,,,,,,,,,,,,,,,,,,,,,,,,,,
142.46,0.31631,1.2504,10,,,,,,,,,,,,,,,,,,,,,,,,,,,,,,,,,,,,,
143.06,0.31643,1.21107,10,,,,,,,,,,,,,,,,,,,,,,,,,,,,,,,,,,,,,
143.66,0.31637,1.24993,10,,,,,,,,,,,,,,,,,,,,,,,,,,,,,,,,,,,,,
144.26,0.31631,1.24104,10,,,,,,,,,,,,,,,,,,,,,,,,,,,,,,,,,,,,,
144.86,0.31643,1.23271,10,,,,,,,,,,,,,,,,,,,,,,,,,,,,,,,,,,,,,
145.46,0.31637,1.25203,10,,,,,,,,,,,,,,,,,,,,,,,,,,,,,,,,,,,,,
146.06,0.31637,1.25348,10,,,,,,,,,,,,,,,,,,,,,,,,,,,,,,,,,,,,,
146.66,0.31637,1.18972,10,,,,,,,,,,,,,,,,,,,,,,,,,,,,,,,,,,,,,
147.26,0.31643,1.21502,10,,,,,,,,,,,,,,,,,,,,,,,,,,,,,,,,,,,,,
147.86,0.31643,1.21116,10,,,,,,,,,,,,,,,,,,,,,,,,,,,,,,,,,,,,,
148.46,0.31637,1.27488,10,,,,,,,,,,,,,,,,,,,,,,,,,,,,,,,,,,,,,
149.06,0.31643,1.20965,10,,,,,,,,,,,,,,,,,,,,,,,,,,,,,,,,,,,,,
149.66,0.31631,1.24282,10,,,,,,,,,,,,,,,,,,,,,,,,,,,,,,,,,,,,,
150.26,0.31631,1.23963,10,,,,,,,,,,,,,,,,,,,,,,,,,,,,,,,,,,,,,
150.86,0.31637,1.23336,10,,,,,,,,,,,,,,,,,,,,,,,,,,,,,,,,,,,,,
151.46,0.31637,1.22673,10,,,,,,,,,,,,,,,,,,,,,,,,,,,,,,,,,,,,,
152.06,0.31637,1.22463,10,,,,,,,,,,,,,,,,,,,,,,,,,,,,,,,,,,,,,
152.66,0.31626,1.22584,10,,,,,,,,,,,,,,,,,,,,,,,,,,,,,,,,,,,,,
153.26,0.31626,1.18033,10,,,,,,,,,,,,,,,,,,,,,,,,,,,,,,,,,,,,,
153.86,0.31626,1.20129,10,,,,,,,,,,,,,,,,,,,,,,,,,,,,,,,,,,,,,
154.46,0.31631,1.27851,10,,,,,,,,,,,,,,,,,,,,,,,,,,,,,,,,,,,,,
155.06,0.3162,1.19597,10,,,,,,,,,,,,,,,,,,,,,,,,,,,,,,,,,,,,,
155.66,0.3162,1.24657,10,,,,,,,,,,,,,,,,,,,,,,,,,,,,,,,,,,,,,
156.26,0.31614,1.27003,10,,,,,,,,,,,,,,,,,,,,,,,,,,,,,,,,,,,,,
156.86,0.31609,1.19024,10,,,,,,,,,,,,,,,,,,,,,,,,,,,,,,,,,,,,,
157.46,0.31609,1.28556,10,,,,,,,,,,,,,,,,,,,,,,,,,,,,,,,,,,,,,
158.06,0.31597,1.2984,10,,,,,,,,,,,,,,,,,,,,,,,,,,,,,,,,,,,,,
158.66,0.31541,1.27174,10,,,,,,,,,,,,,,,,,,,,,,,,,,,,,,,,,,,,,
159.26,0.31376,1.23735,10,,,,,,,,,,,,,,,,,,,,,,,,,,,,,,,,,,,,,
159.86,0.31184,1.24076,10,,,,,,,,,,,,,,,,,,,,,,,,,,,,,,,,,,,,,
160.46,0.31076,1.20877,10,,,,,,,,,,,,,,,,,,,,,,,,,,,,,,,,,,,,,
161.06,0.31059,1.09954,10,,,,,,,,,,,,,,,,,,,,,,,,,,,,,,,,,,,,,
161.66,0.3107,1.18528,10,,,,,,,,,,,,,,,,,,,,,,,,,,,,,,,,,,,,,
162.26,0.31082,1.2005,10,,,,,,,,,,,,,,,,,,,,,,,,,,,,,,,,,,,,,
162.86,0.31087,1.15196,10,,,,,,,,,,,,,,,,,,,,,,,,,,,,,,,,,,,,,
163.46,0.31099,1.20934,10,,,,,,,,,,,,,,,,,,,,,,,,,,,,,,,,,,,,,
164.06,0.31104,1.22783,10,,,,,,,,,,,,,,,,,,,,,,,,,,,,,,,,,,,,,
164.66,0.3111,1.2443,10,,,,,,,,,,,,,,,,,,,,,,,,,,,,,,,,,,,,,
165.26,0.3111,1.21003,10,,,,,,,,,,,,,,,,,,,,,,,,,,,,,,,,,,,,,
165.86,0.31116,1.19475,10,,,,,,,,,,,,,,,,,,,,,,,,,,,,,,,,,,,,,
166.46,0.31121,1.23165,10,,,,,,,,,,,,,,,,,,,,,,,,,,,,,,,,,,,,,
167.06,0.31127,1.19737,10,,,,,,,,,,,,,,,,,,,,,,,,,,,,,,,,,,,,,
167.66,0.31133,1.26411,10,,,,,,,,,,,,,,,,,,,,,,,,,,,,,,,,,,,,,
168.26,0.31133,1.26175,10,,,,,,,,,,,,,,,,,,,,,,,,,,,,,,,,,,,,,
168.86,0.31138,1.23463,10,,,,,,,,,,,,,,,,,,,,,,,,,,,,,,,,,,,,,
169.46,0.31138,1.21054,10,,,,,,,,,,,,,,,,,,,,,,,,,,,,,,,,,,,,,
170.06,0.31138,1.28328,10,,,,,,,,,,,,,,,,,,,,,,,,,,,,,,,,,,,,,
170.66,0.31133,1.25121,10,,,,,,,,,,,,,,,,,,,,,,,,,,,,,,,,,,,,,
171.26,0.31133,1.21712,10,,,,,,,,,,,,,,,,,,,,,,,,,,,,,,,,,,,,,
171.86,0.31144,1.19958,10,,,,,,,,,,,,,,,,,,,,,,,,,,,,,,,,,,,,,
172.46,0.31144,1.24581,10,,,,,,,,,,,,,,,,,,,,,,,,,,,,,,,,,,,,,
173.06,0.31144,1.27348,10,,,,,,,,,,,,,,,,,,,,,,,,,,,,,,,,,,,,,
173.66,0.31144,1.2744,10,,,,,,,,,,,,,,,,,,,,,,,,,,,,,,,,,,,,,
174.26,0.31144,1.20472,10,,,,,,,,,,,,,,,,,,,,,,,,,,,,,,,,,,,,,
174.86,0.31144,1.26463,10,,,,,,,,,,,,,,,,,,,,,,,,,,,,,,,,,,,,,
175.46,0.31133,1.25971,10,,,,,,,,,,,,,,,,,,,,,,,,,,,,,,,,,,,,,
176.06,0.31144,1.22684,10,,,,,,,,,,,,,,,,,,,,,,,,,,,,,,,,,,,,,
176.66,0.31133,1.27197,10,,,,,,,,,,,,,,,,,,,,,,,,,,,,,,,,,,,,,
177.26,0.31133,1.24317,10,,,,,,,,,,,,,,,,,,,,,,,,,,,,,,,,,,,,,
177.86,0.31133,1.20014,10,,,,,,,,,,,,,,,,,,,,,,,,,,,,,,,,,,,,,
178.46,0.31133,1.23616,10,,,,,,,,,,,,,,,,,,,,,,,,,,,,,,,,,,,,,
179.06,0.31133,1.24966,10,,,,,,,,,,,,,,,,,,,,,,,,,,,,,,,,,,,,,
179.66,0.31133,1.25237,10,,,,,,,,,,,,,,,,,,,,,,,,,,,,,,,,,,,,,
180.26,0.31133,1.24515,10,,,,,,,,,,,,,,,,,,,,,,,,,,,,,,,,,,,,,
180.86,0.31133,1.19972,10,,,,,,,,,,,,,,,,,,,,,,,,,,,,,,,,,,,,,
181.46,0.31138,1.24942,10,,,,,,,,,,,,,,,,,,,,,,,,,,,,,,,,,,,,,
182.06,0.31138,1.20805,10,,,,,,,,,,,,,,,,,,,,,,,,,,,,,,,,,,,,,
182.66,0.31138,1.21878,10,,,,,,,,,,,,,,,,,,,,,,,,,,,,,,,,,,,,,
183.26,0.31138,1.25981,10,,,,,,,,,,,,,,,,,,,,,,,,,,,,,,,,,,,,,
183.86,0.31138,1.24581,10,,,,,,,,,,,,,,,,,,,,,,,,,,,,,,,,,,,,,
184.46,0.31138,1.225,10,,,,,,,,,,,,,,,,,,,,,,,,,,,,,,,,,,,,,
185.06,0.31138,1.21231,10,,,,,,,,,,,,,,,,,,,,,,,,,,,,,,,,,,,,,
185.66,0.31138,1.20759,10,,,,,,,,,,,,,,,,,,,,,,,,,,,,,,,,,,,,,
186.26,0.31138,1.27687,10,,,,,,,,,,,,,,,,,,,,,,,,,,,,,,,,,,,,,
186.86,0.31138,1.23615,10,,,,,,,,,,,,,,,,,,,,,,,,,,,,,,,,,,,,,
187.46,0.31138,1.25722,10,,,,,,,,,,,,,,,,,,,,,,,,,,,,,,,,,,,,,
188.06,0.31138,1.23295,10,,,,,,,,,,,,,,,,,,,,,,,,,,,,,,,,,,,,,
188.66,0.31138,1.23928,10,,,,,,,,,,,,,,,,,,,,,,,,,,,,,,,,,,,,,
189.26,0.31138,1.24706,10,,,,,,,,,,,,,,,,,,,,,,,,,,,,,,,,,,,,,
189.86,0.31138,1.23813,10,,,,,,,,,,,,,,,,,,,,,,,,,,,,,,,,,,,,,
190.46,0.31138,1.24742,10,,,,,,,,,,,,,,,,,,,,,,,,,,,,,,,,,,,,,
191.06,0.31138,1.23628,10,,,,,,,,,,,,,,,,,,,,,,,,,,,,,,,,,,,,,
191.66,0.31138,1.22991,10,,,,,,,,,,,,,,,,,,,,,,,,,,,,,,,,,,,,,
192.26,0.31138,1.27163,10,,,,,,,,,,,,,,,,,,,,,,,,,,,,,,,,,,,,,
192.86,0.31138,1.21012,10,,,,,,,,,,,,,,,,,,,,,,,,,,,,,,,,,,,,,
193.46,0.31138,1.22891,10,,,,,,,,,,,,,,,,,,,,,,,,,,,,,,,,,,,,,
194.06,0.31138,1.21982,10,,,,,,,,,,,,,,,,,,,,,,,,,,,,,,,,,,,,,
194.66,0.31138,1.25711,10,,,,,,,,,,,,,,,,,,,,,,,,,,,,,,,,,,,,,
195.26,0.31138,1.2995,10,,,,,,,,,,,,,,,,,,,,,,,,,,,,,,,,,,,,,
195.86,0.31138,1.24333,10,,,,,,,,,,,,,,,,,,,,,,,,,,,,,,,,,,,,,
196.46,0.31138,1.2306,10,,,,,,,,,,,,,,,,,,,,,,,,,,,,,,,,,,,,,
197.06,0.31138,1.22228,10,,,,,,,,,,,,,,,,,,,,,,,,,,,,,,,,,,,,,
197.66,0.31138,1.21049,10,,,,,,,,,,,,,,,,,,,,,,,,,,,,,,,,,,,,,
198.26,0.31138,1.2595,10,,,,,,,,,,,,,,,,,,,,,,,,,,,,,,,,,,,,,
198.86,0.31133,1.25248,10,,,,,,,,,,,,,,,,,,,,,,,,,,,,,,,,,,,,,
199.46,0.31138,1.272,10,,,,,,,,,,,,,,,,,,,,,,,,,,,,,,,,,,,,,
200.06,0.31138,1.2324,10,,,,,,,,,,,,,,,,,,,,,,,,,,,,,,,,,,,,,
200.66,0.31138,1.22293,10,,,,,,,,,,,,,,,,,,,,,,,,,,,,,,,,,,,,,
201.26,0.31138,1.28847,10,,,,,,,,,,,,,,,,,,,,,,,,,,,,,,,,,,,,,
201.86,0.31138,1.23291,10,,,,,,,,,,,,,,,,,,,,,,,,,,,,,,,,,,,,,
202.46,0.31138,1.22503,10,,,,,,,,,,,,,,,,,,,,,,,,,,,,,,,,,,,,,
203.06,0.31138,1.24207,10,,,,,,,,,,,,,,,,,,,,,,,,,,,,,,,,,,,,,
203.66,0.31138,1.20892,10,,,,,,,,,,,,,,,,,,,,,,,,,,,,,,,,,,,,,
204.26,0.31138,1.20013,10,,,,,,,,,,,,,,,,,,,,,,,,,,,,,,,,,,,,,
204.86,0.31138,1.24354,10,,,,,,,,,,,,,,,,,,,,,,,,,,,,,,,,,,,,,
205.46,0.31138,1.24421,10,,,,,,,,,,,,,,,,,,,,,,,,,,,,,,,,,,,,,
206.06,0.31138,1.22857,10,,,,,,,,,,,,,,,,,,,,,,,,,,,,,,,,,,,,,
206.66,0.31138,1.23441,10,,,,,,,,,,,,,,,,,,,,,,,,,,,,,,,,,,,,,
207.26,0.31138,1.22083,10,,,,,,,,,,,,,,,,,,,,,,,,,,,,,,,,,,,,,
207.86,0.31138,1.22124,10,,,,,,,,,,,,,,,,,,,,,,,,,,,,,,,,,,,,,
208.46,0.31138,1.26917,10,,,,,,,,,,,,,,,,,,,,,,,,,,,,,,,,,,,,,
209.06,0.31138,1.22954,10,,,,,,,,,,,,,,,,,,,,,,,,,,,,,,,,,,,,,
209.66,0.31138,1.22891,10,,,,,,,,,,,,,,,,,,,,,,,,,,,,,,,,,,,,,
210.26,0.31138,1.23513,10,,,,,,,,,,,,,,,,,,,,,,,,,,,,,,,,,,,,,
210.86,0.31138,1.22703,10,,,,,,,,,,,,,,,,,,,,,,,,,,,,,,,,,,,,,
211.46,0.31138,1.26126,10,,,,,,,,,,,,,,,,,,,,,,,,,,,,,,,,,,,,,
212.06,0.31138,1.21545,10,,,,,,,,,,,,,,,,,,,,,,,,,,,,,,,,,,,,,
212.66,0.31138,1.22605,10,,,,,,,,,,,,,,,,,,,,,,,,,,,,,,,,,,,,,
213.26,0.31138,1.24472,10,,,,,,,,,,,,,,,,,,,,,,,,,,,,,,,,,,,,,
213.86,0.31138,1.22932,10,,,,,,,,,,,,,,,,,,,,,,,,,,,,,,,,,,,,,
214.46,0.31138,1.2462,10,,,,,,,,,,,,,,,,,,,,,,,,,,,,,,,,,,,,,
215.06,0.31138,1.25306,10,,,,,,,,,,,,,,,,,,,,,,,,,,,,,,,,,,,,,
215.66,0.31127,1.22321,10,,,,,,,,,,,,,,,,,,,,,,,,,,,,,,,,,,,,,
216.26,0.31127,1.17563,10,,,,,,,,,,,,,,,,,,,,,,,,,,,,,,,,,,,,,
216.86,0.31127,1.21801,10,,,,,,,,,,,,,,,,,,,,,,,,,,,,,,,,,,,,,
217.46,0.31127,1.22677,10,,,,,,,,,,,,,,,,,,,,,,,,,,,,,,,,,,,,,
218.06,0.31127,1.26471,10,,,,,,,,,,,,,,,,,,,,,,,,,,,,,,,,,,,,,
218.66,0.31127,1.24075,10,,,,,,,,,,,,,,,,,,,,,,,,,,,,,,,,,,,,,
219.26,0.31127,1.21032,10,,,,,,,,,,,,,,,,,,,,,,,,,,,,,,,,,,,,,
219.86,0.31127,1.23855,10,,,,,,,,,,,,,,,,,,,,,,,,,,,,,,,,,,,,,
220.46,0.31127,1.23421,10,,,,,,,,,,,,,,,,,,,,,,,,,,,,,,,,,,,,,
221.06,0.31127,1.20844,10,,,,,,,,,,,,,,,,,,,,,,,,,,,,,,,,,,,,,
221.66,0.31127,1.22749,10,,,,,,,,,,,,,,,,,,,,,,,,,,,,,,,,,,,,,
222.26,0.31127,1.24931,10,,,,,,,,,,,,,,,,,,,,,,,,,,,,,,,,,,,,,
222.86,0.31116,1.23638,10,,,,,,,,,,,,,,,,,,,,,,,,,,,,,,,,,,,,,
223.46,0.31121,1.25232,10,,,,,,,,,,,,,,,,,,,,,,,,,,,,,,,,,,,,,
224.06,0.31121,1.25533,10,,,,,,,,,,,,,,,,,,,,,,,,,,,,,,,,,,,,,
224.66,0.31104,1.22988,10,,,,,,,,,,,,,,,,,,,,,,,,,,,,,,,,,,,,,
225.26,0.31104,1.2448,10,,,,,,,,,,,,,,,,,,,,,,,,,,,,,,,,,,,,,
225.86,0.31104,1.27428,10,,,,,,,,,,,,,,,,,,,,,,,,,,,,,,,,,,,,,
226.46,0.31093,1.2017,10,,,,,,,,,,,,,,,,,,,,,,,,,,,,,,,,,,,,,
227.06,0.31087,1.23844,10,,,,,,,,,,,,,,,,,,,,,,,,,,,,,,,,,,,,,
227.66,0.31082,1.21206,10,,,,,,,,,,,,,,,,,,,,,,,,,,,,,,,,,,,,,
228.26,0.31082,1.18588,10,,,,,,,,,,,,,,,,,,,,,,,,,,,,,,,,,,,,,
228.86,0.31076,1.29246,10,,,,,,,,,,,,,,,,,,,,,,,,,,,,,,,,,,,,,
229.46,0.3107,1.24418,10,,,,,,,,,,,,,,,,,,,,,,,,,,,,,,,,,,,,,
230.06,0.31065,1.24211,10,,,,,,,,,,,,,,,,,,,,,,,,,,,,,,,,,,,,,
230.66,0.31053,1.22818,10,,,,,,,,,,,,,,,,,,,,,,,,,,,,,,,,,,,,,
231.26,0.31042,1.25378,10,,,,,,,,,,,,,,,,,,,,,,,,,,,,,,,,,,,,,
231.86,0.30985,1.2823,10,,,,,,,,,,,,,,,,,,,,,,,,,,,,,,,,,,,,,
232.46,0.30866,1.27326,10,,,,,,,,,,,,,,,,,,,,,,,,,,,,,,,,,,,,,
233.06,0.30776,1.17584,10,,,,,,,,,,,,,,,,,,,,,,,,,,,,,,,,,,,,,
233.66,0.3073,1.21053,10,,,,,,,,,,,,,,,,,,,,,,,,,,,,,,,,,,,,,
234.26,0.30713,1.19569,10,,,,,,,,,,,,,,,,,,,,,,,,,,,,,,,,,,,,,
234.86,0.30696,1.1799,10,,,,,,,,,,,,,,,,,,,,,,,,,,,,,,,,,,,,,
235.46,0.30696,1.19948,10,,,,,,,,,,,,,,,,,,,,,,,,,,,,,,,,,,,,,
236.06,0.30708,1.21031,10,,,,,,,,,,,,,,,,,,,,,,,,,,,,,,,,,,,,,
236.66,0.30713,1.20069,10,,,,,,,,,,,,,,,,,,,,,,,,,,,,,,,,,,,,,
237.26,0.30713,1.184,10,,,,,,,,,,,,,,,,,,,,,,,,,,,,,,,,,,,,,
237.86,0.30719,1.19344,10,,,,,,,,,,,,,,,,,,,,,,,,,,,,,,,,,,,,,
238.46,0.3073,1.22322,10,,,,,,,,,,,,,,,,,,,,,,,,,,,,,,,,,,,,,
239.06,0.30736,1.15488,10,,,,,,,,,,,,,,,,,,,,,,,,,,,,,,,,,,,,,
239.66,0.30742,1.24117,10,,,,,,,,,,,,,,,,,,,,,,,,,,,,,,,,,,,,,
240.26,0.30747,1.24124,10,,,,,,,,,,,,,,,,,,,,,,,,,,,,,,,,,,,,,
240.86,0.30753,1.24824,10,,,,,,,,,,,,,,,,,,,,,,,,,,,,,,,,,,,,,
241.46,0.30759,1.22492,10,,,,,,,,,,,,,,,,,,,,,,,,,,,,,,,,,,,,,
242.06,0.30759,1.24383,10,,,,,,,,,,,,,,,,,,,,,,,,,,,,,,,,,,,,,
242.66,0.30759,1.24332,10,,,,,,,,,,,,,,,,,,,,,,,,,,,,,,,,,,,,,
243.26,0.30759,1.23046,10,,,,,,,,,,,,,,,,,,,,,,,,,,,,,,,,,,,,,
243.86,0.30764,1.21032,10,,,,,,,,,,,,,,,,,,,,,,,,,,,,,,,,,,,,,
244.46,0.30759,1.21907,10,,,,,,,,,,,,,,,,,,,,,,,,,,,,,,,,,,,,,
245.06,0.30764,1.21318,10,,,,,,,,,,,,,,,,,,,,,,,,,,,,,,,,,,,,,
245.66,0.30776,1.23728,10,,,,,,,,,,,,,,,,,,,,,,,,,,,,,,,,,,,,,
246.26,0.30781,1.24534,10,,,,,,,,,,,,,,,,,,,,,,,,,,,,,,,,,,,,,
246.86,0.30787,1.26293,10,,,,,,,,,,,,,,,,,,,,,,,,,,,,,,,,,,,,,
247.46,0.30781,1.20426,10,,,,,,,,,,,,,,,,,,,,,,,,,,,,,,,,,,,,,
248.06,0.30793,1.22854,10,,,,,,,,,,,,,,,,,,,,,,,,,,,,,,,,,,,,,
248.66,0.30793,1.27885,10,,,,,,,,,,,,,,,,,,,,,,,,,,,,,,,,,,,,,
249.26,0.30787,1.23026,10,,,,,,,,,,,,,,,,,,,,,,,,,,,,,,,,,,,,,
249.86,0.30798,1.2365,10,,,,,,,,,,,,,,,,,,,,,,,,,,,,,,,,,,,,,
250.46,0.30798,1.22673,10,,,,,,,,,,,,,,,,,,,,,,,,,,,,,,,,,,,,,
251.06,0.30798,1.1814,10,,,,,,,,,,,,,,,,,,,,,,,,,,,,,,,,,,,,,
251.66,0.30798,1.19893,10,,,,,,,,,,,,,,,,,,,,,,,,,,,,,,,,,,,,,
252.26,0.30798,1.24142,10,,,,,,,,,,,,,,,,,,,,,,,,,,,,,,,,,,,,,
252.86,0.30798,1.24457,10,,,,,,,,,,,,,,,,,,,,,,,,,,,,,,,,,,,,,
253.46,0.30798,1.24921,10,,,,,,,,,,,,,,,,,,,,,,,,,,,,,,,,,,,,,
254.06,0.30798,1.2466,10,,,,,,,,,,,,,,,,,,,,,,,,,,,,,,,,,,,,,
254.66,0.30798,1.22267,10,,,,,,,,,,,,,,,,,,,,,,,,,,,,,,,,,,,,,
255.26,0.30798,1.22927,10,,,,,,,,,,,,,,,,,,,,,,,,,,,,,,,,,,,,,
255.86,0.30793,1.21302,10,,,,,,,,,,,,,,,,,,,,,,,,,,,,,,,,,,,,,
256.46,0.30798,1.22877,10,,,,,,,,,,,,,,,,,,,,,,,,,,,,,,,,,,,,,
257.06,0.30798,1.20542,10,,,,,,,,,,,,,,,,,,,,,,,,,,,,,,,,,,,,,
257.66,0.30798,1.23212,10,,,,,,,,,,,,,,,,,,,,,,,,,,,,,,,,,,,,,
258.26,0.30798,1.25005,10,,,,,,,,,,,,,,,,,,,,,,,,,,,,,,,,,,,,,
258.86,0.30798,1.2285,10,,,,,,,,,,,,,,,,,,,,,,,,,,,,,,,,,,,,,
259.46,0.30793,1.28297,10,,,,,,,,,,,,,,,,,,,,,,,,,,,,,,,,,,,,,
260.06,0.30793,1.28119,10,,,,,,,,,,,,,,,,,,,,,,,,,,,,,,,,,,,,,
260.66,0.30798,1.25031,10,,,,,,,,,,,,,,,,,,,,,,,,,,,,,,,,,,,,,
261.26,0.30798,1.2433,10,,,,,,,,,,,,,,,,,,,,,,,,,,,,,,,,,,,,,
261.86,0.30798,1.24242,10,,,,,,,,,,,,,,,,,,,,,,,,,,,,,,,,,,,,,
262.46,0.30798,1.26288,10,,,,,,,,,,,,,,,,,,,,,,,,,,,,,,,,,,,,,
263.06,0.30798,1.25218,10,,,,,,,,,,,,,,,,,,,,,,,,,,,,,,,,,,,,,
263.66,0.30798,1.22712,10,,,,,,,,,,,,,,,,,,,,,,,,,,,,,,,,,,,,,
264.26,0.30798,1.22685,10,,,,,,,,,,,,,,,,,,,,,,,,,,,,,,,,,,,,,
264.86,0.30798,1.2348,10,,,,,,,,,,,,,,,,,,,,,,,,,,,,,,,,,,,,,
265.46,0.30798,1.25494,10,,,,,,,,,,,,,,,,,,,,,,,,,,,,,,,,,,,,,
266.06,0.30798,1.25394,10,,,,,,,,,,,,,,,,,,,,,,,,,,,,,,,,,,,,,
266.66,0.30798,1.19207,10,,,,,,,,,,,,,,,,,,,,,,,,,,,,,,,,,,,,,
267.26,0.30798,1.24325,10,,,,,,,,,,,,,,,,,,,,,,,,,,,,,,,,,,,,,
267.86,0.30798,1.22967,10,,,,,,,,,,,,,,,,,,,,,,,,,,,,,,,,,,,,,
268.46,0.30798,1.23957,10,,,,,,,,,,,,,,,,,,,,,,,,,,,,,,,,,,,,,
269.06,0.30798,1.20887,10,,,,,,,,,,,,,,,,,,,,,,,,,,,,,,,,,,,,,
269.66,0.30787,1.23243,10,,,,,,,,,,,,,,,,,,,,,,,,,,,,,,,,,,,,,
270.26,0.30787,1.25835,10,,,,,,,,,,,,,,,,,,,,,,,,,,,,,,,,,,,,,
270.86,0.30787,1.27322,10,,,,,,,,,,,,,,,,,,,,,,,,,,,,,,,,,,,,,
271.46,0.30793,1.23335,10,,,,,,,,,,,,,,,,,,,,,,,,,,,,,,,,,,,,,
272.06,0.30793,1.21788,10,,,,,,,,,,,,,,,,,,,,,,,,,,,,,,,,,,,,,
272.66,0.30793,1.25197,10,,,,,,,,,,,,,,,,,,,,,,,,,,,,,,,,,,,,,
273.26,0.30793,1.25733,10,,,,,,,,,,,,,,,,,,,,,,,,,,,,,,,,,,,,,
273.86,0.30793,1.20851,10,,,,,,,,,,,,,,,,,,,,,,,,,,,,,,,,,,,,,
274.46,0.30793,1.31919,10,,,,,,,,,,,,,,,,,,,,,,,,,,,,,,,,,,,,,
275.06,0.30793,1.23874,10,,,,,,,,,,,,,,,,,,,,,,,,,,,,,,,,,,,,,
275.66,0.30793,1.22033,10,,,,,,,,,,,,,,,,,,,,,,,,,,,,,,,,,,,,,
276.26,0.30793,1.21187,10,,,,,,,,,,,,,,,,,,,,,,,,,,,,,,,,,,,,,
276.86,0.30793,1.25022,10,,,,,,,,,,,,,,,,,,,,,,,,,,,,,,,,,,,,,
277.46,0.30781,1.24369,10,,,,,,,,,,,,,,,,,,,,,,,,,,,,,,,,,,,,,
278.06,0.30793,1.23111,10,,,,,,,,,,,,,,,,,,,,,,,,,,,,,,,,,,,,,
278.66,0.30793,1.18986,10,,,,,,,,,,,,,,,,,,,,,,,,,,,,,,,,,,,,,
279.26,0.30793,1.23982,10,,,,,,,,,,,,,,,,,,,,,,,,,,,,,,,,,,,,,
279.86,0.30793,1.21375,10,,,,,,,,,,,,,,,,,,,,,,,,,,,,,,,,,,,,,
280.46,0.30793,1.26942,10,,,,,,,,,,,,,,,,,,,,,,,,,,,,,,,,,,,,,
281.06,0.30793,1.23046,10,,,,,,,,,,,,,,,,,,,,,,,,,,,,,,,,,,,,,
281.66,0.30793,1.21059,10,,,,,,,,,,,,,,,,,,,,,,,,,,,,,,,,,,,,,
282.26,0.30793,1.20427,10,,,,,,,,,,,,,,,,,,,,,,,,,,,,,,,,,,,,,
282.86,0.30793,1.21316,10,,,,,,,,,,,,,,,,,,,,,,,,,,,,,,,,,,,,,
283.46,0.30793,1.26605,10,,,,,,,,,,,,,,,,,,,,,,,,,,,,,,,,,,,,,
284.06,0.30793,1.21857,10,,,,,,,,,,,,,,,,,,,,,,,,,,,,,,,,,,,,,
284.66,0.30793,1.20786,10,,,,,,,,,,,,,,,,,,,,,,,,,,,,,,,,,,,,,
285.26,0.30781,1.23273,10,,,,,,,,,,,,,,,,,,,,,,,,,,,,,,,,,,,,,
285.86,0.30781,1.24736,10,,,,,,,,,,,,,,,,,,,,,,,,,,,,,,,,,,,,,
286.46,0.30781,1.30158,10,,,,,,,,,,,,,,,,,,,,,,,,,,,,,,,,,,,,,
287.06,0.30781,1.24094,10,,,,,,,,,,,,,,,,,,,,,,,,,,,,,,,,,,,,,
287.66,0.30781,1.21417,10,,,,,,,,,,,,,,,,,,,,,,,,,,,,,,,,,,,,,
288.26,0.30793,1.22814,10,,,,,,,,,,,,,,,,,,,,,,,,,,,,,,,,,,,,,
288.86,0.30793,1.23049,10,,,,,,,,,,,,,,,,,,,,,,,,,,,,,,,,,,,,,
289.46,0.30781,1.35274,10,,,,,,,,,,,,,,,,,,,,,,,,,,,,,,,,,,,,,
290.06,0.30781,1.19825,10,,,,,,,,,,,,,,,,,,,,,,,,,,,,,,,,,,,,,
290.66,0.30781,1.23153,10,,,,,,,,,,,,,,,,,,,,,,,,,,,,,,,,,,,,,
291.26,0.30787,1.26539,10,,,,,,,,,,,,,,,,,,,,,,,,,,,,,,,,,,,,,
291.86,0.30787,1.21281,10,,,,,,,,,,,,,,,,,,,,,,,,,,,,,,,,,,,,,
292.46,0.30787,1.24679,10,,,,,,,,,,,,,,,,,,,,,,,,,,,,,,,,,,,,,
293.06,0.30787,1.23308,10,,,,,,,,,,,,,,,,,,,,,,,,,,,,,,,,,,,,,
293.66,0.30787,1.24099,10,,,,,,,,,,,,,,,,,,,,,,,,,,,,,,,,,,,,,
294.26,0.30787,1.24752,10,,,,,,,,,,,,,,,,,,,,,,,,,,,,,,,,,,,,,
294.86,0.30787,1.19783,10,,,,,,,,,,,,,,,,,,,,,,,,,,,,,,,,,,,,,
295.46,0.30787,1.32606,10,,,,,,,,,,,,,,,,,,,,,,,,,,,,,,,,,,,,,
296.06,0.30787,1.2086,10,,,,,,,,,,,,,,,,,,,,,,,,,,,,,,,,,,,,,
296.66,0.30787,1.25692,10,,,,,,,,,,,,,,,,,,,,,,,,,,,,,,,,,,,,,
297.26,0.30787,1.21203,10,,,,,,,,,,,,,,,,,,,,,,,,,,,,,,,,,,,,,
297.86,0.30776,1.23711,10,,,,,,,,,,,,,,,,,,,,,,,,,,,,,,,,,,,,,
298.46,0.30776,1.29937,10,,,,,,,,,,,,,,,,,,,,,,,,,,,,,,,,,,,,,
299.06,0.30776,1.22763,10,,,,,,,,,,,,,,,,,,,,,,,,,,,,,,,,,,,,,
299.66,0.30776,1.24652,10,,,,,,,,,,,,,,,,,,,,,,,,,,,,,,,,,,,,,
300.26,0.30776,1.21181,10,,,,,,,,,,,,,,,,,,,,,,,,,,,,,,,,,,,,,
300.86,0.30776,1.22072,10,,,,,,,,,,,,,,,,,,,,,,,,,,,,,,,,,,,,,
301.46,0.3077,1.31962,10,,,,,,,,,,,,,,,,,,,,,,,,,,,,,,,,,,,,,
302.06,0.30781,1.23666,10,,,,,,,,,,,,,,,,,,,,,,,,,,,,,,,,,,,,,
302.66,0.3077,1.22871,10,,,,,,,,,,,,,,,,,,,,,,,,,,,,,,,,,,,,,
303.26,0.30781,1.27222,10,,,,,,,,,,,,,,,,,,,,,,,,,,,,,,,,,,,,,
303.86,0.3077,1.28441,10,,,,,,,,,,,,,,,,,,,,,,,,,,,,,,,,,,,,,
304.46,0.30764,1.18405,10,,,,,,,,,,,,,,,,,,,,,,,,,,,,,,,,,,,,,
305.06,0.30759,1.24975,10,,,,,,,,,,,,,,,,,,,,,,,,,,,,,,,,,,,,,
305.66,0.30759,1.26441,10,,,,,,,,,,,,,,,,,,,,,,,,,,,,,,,,,,,,,
306.26,0.30753,1.22519,10,,,,,,,,,,,,,,,,,,,,,,,,,,,,,,,,,,,,,
306.86,0.30753,1.23247,10,,,,,,,,,,,,,,,,,,,,,,,,,,,,,,,,,,,,,
307.46,0.30747,1.24992,10,,,,,,,,,,,,,,,,,,,,,,,,,,,,,,,,,,,,,
308.06,0.30742,1.27345,10,,,,,,,,,,,,,,,,,,,,,,,,,,,,,,,,,,,,,
308.66,0.3073,1.24951,10,,,,,,,,,,,,,,,,,,,,,,,,,,,,,,,,,,,,,
309.26,0.30725,1.25289,10,,,,,,,,,,,,,,,,,,,,,,,,,,,,,,,,,,,,,
309.86,0.30719,1.22281,10,,,,,,,,,,,,,,,,,,,,,,,,,,,,,,,,,,,,,
310.46,0.30713,1.23238,10,,,,,,,,,,,,,,,,,,,,,,,,,,,,,,,,,,,,,
311.06,0.30708,1.22618,10,,,,,,,,,,,,,,,,,,,,,,,,,,,,,,,,,,,,,
311.66,0.30696,1.22561,10,,,,,,,,,,,,,,,,,,,,,,,,,,,,,,,,,,,,,
312.26,0.30679,1.26124,10,,,,,,,,,,,,,,,,,,,,,,,,,,,,,,,,,,,,,
312.86,0.30645,1.23775,10,,,,,,,,,,,,,,,,,,,,,,,,,,,,,,,,,,,,,
313.46,0.30611,1.3031,10,,,,,,,,,,,,,,,,,,,,,,,,,,,,,,,,,,,,,
314.06,0.30572,1.21975,10,,,,,,,,,,,,,,,,,,,,,,,,,,,,,,,,,,,,,
314.66,0.30526,1.22589,10,,,,,,,,,,,,,,,,,,,,,,,,,,,,,,,,,,,,,
315.26,0.3047,1.2611,10,,,,,,,,,,,,,,,,,,,,,,,,,,,,,,,,,,,,,
315.86,0.30407,1.22149,10,,,,,,,,,,,,,,,,,,,,,,,,,,,,,,,,,,,,,
316.46,0.30351,1.25896,10,,,,,,,,,,,,,,,,,,,,,,,,,,,,,,,,,,,,,
317.06,0.30305,1.20599,10,,,,,,,,,,,,,,,,,,,,,,,,,,,,,,,,,,,,,
317.66,0.30271,1.19961,10,,,,,,,,,,,,,,,,,,,,,,,,,,,,,,,,,,,,,
318.26,0.3026,1.14745,10,,,,,,,,,,,,,,,,,,,,,,,,,,,,,,,,,,,,,
318.86,0.3026,1.18314,10,,,,,,,,,,,,,,,,,,,,,,,,,,,,,,,,,,,,,
319.46,0.30271,1.16064,10,,,,,,,,,,,,,,,,,,,,,,,,,,,,,,,,,,,,,
320.06,0.30277,1.19726,10,,,,,,,,,,,,,,,,,,,,,,,,,,,,,,,,,,,,,
320.66,0.30283,1.16719,10,,,,,,,,,,,,,,,,,,,,,,,,,,,,,,,,,,,,,
321.26,0.30288,1.1889,10,,,,,,,,,,,,,,,,,,,,,,,,,,,,,,,,,,,,,
321.86,0.30294,1.18834,10,,,,,,,,,,,,,,,,,,,,,,,,,,,,,,,,,,,,,
322.46,0.303,1.22255,10,,,,,,,,,,,,,,,,,,,,,,,,,,,,,,,,,,,,,
323.06,0.30305,1.13623,10,,,,,,,,,,,,,,,,,,,,,,,,,,,,,,,,,,,,,
323.66,0.30311,1.21027,10,,,,,,,,,,,,,,,,,,,,,,,,,,,,,,,,,,,,,
324.26,0.30317,1.25525,10,,,,,,,,,,,,,,,,,,,,,,,,,,,,,,,,,,,,,
324.86,0.30322,1.19392,10,,,,,,,,,,,,,,,,,,,,,,,,,,,,,,,,,,,,,
325.46,0.30328,1.22,10,,,,,,,,,,,,,,,,,,,,,,,,,,,,,,,,,,,,,
326.06,0.30334,1.20986,10,,,,,,,,,,,,,,,,,,,,,,,,,,,,,,,,,,,,,
326.66,0.30334,1.234,10,,,,,,,,,,,,,,,,,,,,,,,,,,,,,,,,,,,,,
327.26,0.30339,1.26393,10,,,,,,,,,,,,,,,,,,,,,,,,,,,,,,,,,,,,,
327.86,0.30345,1.20341,10,,,,,,,,,,,,,,,,,,,,,,,,,,,,,,,,,,,,,
328.46,0.30345,1.24975,10,,,,,,,,,,,,,,,,,,,,,,,,,,,,,,,,,,,,,
329.06,0.30351,1.2107,10,,,,,,,,,,,,,,,,,,,,,,,,,,,,,,,,,,,,,
329.66,0.30351,1.22032,10,,,,,,,,,,,,,,,,,,,,,,,,,,,,,,,,,,,,,
330.26,0.30368,1.29812,10,,,,,,,,,,,,,,,,,,,,,,,,,,,,,,,,,,,,,
330.86,0.30356,1.23059,10,,,,,,,,,,,,,,,,,,,,,,,,,,,,,,,,,,,,,
331.46,0.30368,1.20959,10,,,,,,,,,,,,,,,,,,,,,,,,,,,,,,,,,,,,,
332.06,0.30368,1.20575,10,,,,,,,,,,,,,,,,,,,,,,,,,,,,,,,,,,,,,
332.66,0.30368,1.22039,10,,,,,,,,,,,,,,,,,,,,,,,,,,,,,,,,,,,,,
333.26,0.30368,1.25649,10,,,,,,,,,,,,,,,,,,,,,,,,,,,,,,,,,,,,,
333.86,0.30368,1.21857,10,,,,,,,,,,,,,,,,,,,,,,,,,,,,,,,,,,,,,
334.46,0.30368,1.27604,10,,,,,,,,,,,,,,,,,,,,,,,,,,,,,,,,,,,,,
335.06,0.30368,1.20064,10,,,,,,,,,,,,,,,,,,,,,,,,,,,,,,,,,,,,,
335.66,0.30368,1.24855,10,,,,,,,,,,,,,,,,,,,,,,,,,,,,,,,,,,,,,
336.26,0.30368,1.22789,10,,,,,,,,,,,,,,,,,,,,,,,,,,,,,,,,,,,,,
336.86,0.30356,1.24122,10,,,,,,,,,,,,,,,,,,,,,,,,,,,,,,,,,,,,,
337.46,0.30356,1.22877,10,,,,,,,,,,,,,,,,,,,,,,,,,,,,,,,,,,,,,
338.06,0.30368,1.23585,10,,,,,,,,,,,,,,,,,,,,,,,,,,,,,,,,,,,,,
338.66,0.30368,1.24117,10,,,,,,,,,,,,,,,,,,,,,,,,,,,,,,,,,,,,,
339.26,0.30368,1.22539,10,,,,,,,,,,,,,,,,,,,,,,,,,,,,,,,,,,,,,
339.86,0.30368,1.25048,10,,,,,,,,,,,,,,,,,,,,,,,,,,,,,,,,,,,,,
340.46,0.30368,1.27707,10,,,,,,,,,,,,,,,,,,,,,,,,,,,,,,,,,,,,,
341.06,0.30356,1.24746,10,,,,,,,,,,,,,,,,,,,,,,,,,,,,,,,,,,,,,
341.66,0.30356,1.26105,10,,,,,,,,,,,,,,,,,,,,,,,,,,,,,,,,,,,,,
342.26,0.30356,1.24007,10,,,,,,,,,,,,,,,,,,,,,,,,,,,,,,,,,,,,,
342.86,0.30356,1.24306,10,,,,,,,,,,,,,,,,,,,,,,,,,,,,,,,,,,,,,
343.46,0.30356,1.2644,10,,,,,,,,,,,,,,,,,,,,,,,,,,,,,,,,,,,,,
344.06,0.30362,1.19988,10,,,,,,,,,,,,,,,,,,,,,,,,,,,,,,,,,,,,,
344.66,0.30351,1.21651,10,,,,,,,,,,,,,,,,,,,,,,,,,,,,,,,,,,,,,
345.26,0.30362,1.20907,10,,,,,,,,,,,,,,,,,,,,,,,,,,,,,,,,,,,,,
345.86,0.30362,1.22587,10,,,,,,,,,,,,,,,,,,,,,,,,,,,,,,,,,,,,,
346.46,0.30362,1.2303,10,,,,,,,,,,,,,,,,,,,,,,,,,,,,,,,,,,,,,
347.06,0.30362,1.21678,10,,,,,,,,,,,,,,,,,,,,,,,,,,,,,,,,,,,,,
347.66,0.30362,1.24756,10,,,,,,,,,,,,,,,,,,,,,,,,,,,,,,,,,,,,,
348.26,0.30362,1.224,10,,,,,,,,,,,,,,,,,,,,,,,,,,,,,,,,,,,,,
348.86,0.30362,1.21311,10,,,,,,,,,,,,,,,,,,,,,,,,,,,,,,,,,,,,,
349.46,0.30362,1.25947,10,,,,,,,,,,,,,,,,,,,,,,,,,,,,,,,,,,,,,
350.06,0.30362,1.20191,10,,,,,,,,,,,,,,,,,,,,,,,,,,,,,,,,,,,,,
350.66,0.30362,1.21695,10,,,,,,,,,,,,,,,,,,,,,,,,,,,,,,,,,,,,,
351.26,0.30362,1.18466,10,,,,,,,,,,,,,,,,,,,,,,,,,,,,,,,,,,,,,
351.86,0.30362,1.20918,10,,,,,,,,,,,,,,,,,,,,,,,,,,,,,,,,,,,,,
352.46,0.30362,1.24499,10,,,,,,,,,,,,,,,,,,,,,,,,,,,,,,,,,,,,,
353.06,0.30362,1.25387,10,,,,,,,,,,,,,,,,,,,,,,,,,,,,,,,,,,,,,
353.66,0.30362,1.23122,10,,,,,,,,,,,,,,,,,,,,,,,,,,,,,,,,,,,,,
354.26,0.30362,1.24882,10,,,,,,,,,,,,,,,,,,,,,,,,,,,,,,,,,,,,,
354.86,0.30362,1.24194,10,,,,,,,,,,,,,,,,,,,,,,,,,,,,,,,,,,,,,
355.46,0.30362,1.18582,10,,,,,,,,,,,,,,,,,,,,,,,,,,,,,,,,,,,,,
356.06,0.30362,1.22367,10,,,,,,,,,,,,,,,,,,,,,,,,,,,,,,,,,,,,,
356.66,0.30362,1.22158,10,,,,,,,,,,,,,,,,,,,,,,,,,,,,,,,,,,,,,
357.26,0.30362,1.24021,10,,,,,,,,,,,,,,,,,,,,,,,,,,,,,,,,,,,,,
357.86,0.30362,1.18727,10,,,,,,,,,,,,,,,,,,,,,,,,,,,,,,,,,,,,,
358.46,0.30356,1.24656,10,,,,,,,,,,,,,,,,,,,,,,,,,,,,,,,,,,,,,
359.06,0.30368,1.22071,10,,,,,,,,,,,,,,,,,,,,,,,,,,,,,,,,,,,,,
359.66,0.30368,1.19094,10,,,,,,,,,,,,,,,,,,,,,,,,,,,,,,,,,,,,,
360.26,0.30368,1.20962,10,,,,,,,,,,,,,,,,,,,,,,,,,,,,,,,,,,,,,
360.86,0.30373,1.20792,10,,,,,,,,,,,,,,,,,,,,,,,,,,,,,,,,,,,,,
361.46,0.30368,1.25867,10,,,,,,,,,,,,,,,,,,,,,,,,,,,,,,,,,,,,,
362.06,0.30379,1.21594,10,,,,,,,,,,,,,,,,,,,,,,,,,,,,,,,,,,,,,
362.66,0.30385,1.23323,10,,,,,,,,,,,,,,,,,,,,,,,,,,,,,,,,,,,,,
363.26,0.3039,1.23284,10,,,,,,,,,,,,,,,,,,,,,,,,,,,,,,,,,,,,,
363.86,0.30396,1.26403,10,,,,,,,,,,,,,,,,,,,,,,,,,,,,,,,,,,,,,
364.46,0.30396,1.22901,10,,,,,,,,,,,,,,,,,,,,,,,,,,,,,,,,,,,,,
365.06,0.30402,1.2062,10,,,,,,,,,,,,,,,,,,,,,,,,,,,,,,,,,,,,,
365.66,0.30402,1.18083,10,,,,,,,,,,,,,,,,,,,,,,,,,,,,,,,,,,,,,
366.26,0.30402,1.20463,10,,,,,,,,,,,,,,,,,,,,,,,,,,,,,,,,,,,,,
366.86,0.30396,1.18026,10,,,,,,,,,,,,,,,,,,,,,,,,,,,,,,,,,,,,,
367.46,0.30407,1.22391,10,,,,,,,,,,,,,,,,,,,,,,,,,,,,,,,,,,,,,
368.06,0.30407,1.18662,10,,,,,,,,,,,,,,,,,,,,,,,,,,,,,,,,,,,,,
368.66,0.30402,1.23277,10,,,,,,,,,,,,,,,,,,,,,,,,,,,,,,,,,,,,,
369.26,0.30413,1.2363,10,,,,,,,,,,,,,,,,,,,,,,,,,,,,,,,,,,,,,
369.86,0.30413,1.20649,10,,,,,,,,,,,,,,,,,,,,,,,,,,,,,,,,,,,,,
370.46,0.30413,1.26007,10,,,,,,,,,,,,,,,,,,,,,,,,,,,,,,,,,,,,,
371.06,0.30413,1.25667,10,,,,,,,,,,,,,,,,,,,,,,,,,,,,,,,,,,,,,
371.66,0.30402,1.19214,10,,,,,,,,,,,,,,,,,,,,,,,,,,,,,,,,,,,,,
372.26,0.30413,1.22673,10,,,,,,,,,,,,,,,,,,,,,,,,,,,,,,,,,,,,,
372.86,0.30413,1.26495,10,,,,,,,,,,,,,,,,,,,,,,,,,,,,,,,,,,,,,
373.46,0.30413,1.22384,10,,,,,,,,,,,,,,,,,,,,,,,,,,,,,,,,,,,,,
374.06,0.30413,1.20802,10,,,,,,,,,,,,,,,,,,,,,,,,,,,,,,,,,,,,,
374.66,0.30413,1.21836,10,,,,,,,,,,,,,,,,,,,,,,,,,,,,,,,,,,,,,
375.26,0.30413,1.20233,10,,,,,,,,,,,,,,,,,,,,,,,,,,,,,,,,,,,,,
375.86,0.30413,1.23548,10,,,,,,,,,,,,,,,,,,,,,,,,,,,,,,,,,,,,,
376.46,0.30402,1.23083,10,,,,,,,,,,,,,,,,,,,,,,,,,,,,,,,,,,,,,
377.06,0.30413,1.24993,10,,,,,,,,,,,,,,,,,,,,,,,,,,,,,,,,,,,,,
377.66,0.30413,1.24465,10,,,,,,,,,,,,,,,,,,,,,,,,,,,,,,,,,,,,,
378.26,0.30413,1.21341,10,,,,,,,,,,,,,,,,,,,,,,,,,,,,,,,,,,,,,
378.86,0.30413,1.22195,10,,,,,,,,,,,,,,,,,,,,,,,,,,,,,,,,,,,,,
379.46,0.30413,1.25005,10,,,,,,,,,,,,,,,,,,,,,,,,,,,,,,,,,,,,,
380.06,0.30413,1.25694,10,,,,,,,,,,,,,,,,,,,,,,,,,,,,,,,,,,,,,
380.66,0.30402,1.21022,10,,,,,,,,,,,,,,,,,,,,,,,,,,,,,,,,,,,,,
381.26,0.30413,1.26659,10,,,,,,,,,,,,,,,,,,,,,,,,,,,,,,,,,,,,,
381.86,0.30402,1.21149,10,,,,,,,,,,,,,,,,,,,,,,,,,,,,,,,,,,,,,
382.46,0.30413,1.2649,10,,,,,,,,,,,,,,,,,,,,,,,,,,,,,,,,,,,,,
383.06,0.30413,1.19863,10,,,,,,,,,,,,,,,,,,,,,,,,,,,,,,,,,,,,,
383.66,0.30413,1.28646,10,,,,,,,,,,,,,,,,,,,,,,,,,,,,,,,,,,,,,
384.26,0.30413,1.22071,10,,,,,,,,,,,,,,,,,,,,,,,,,,,,,,,,,,,,,
384.86,0.30413,1.22743,10,,,,,,,,,,,,,,,,,,,,,,,,,,,,,,,,,,,,,
385.46,0.30413,1.30154,10,,,,,,,,,,,,,,,,,,,,,,,,,,,,,,,,,,,,,
386.06,0.30413,1.20288,10,,,,,,,,,,,,,,,,,,,,,,,,,,,,,,,,,,,,,
386.66,0.30413,1.28646,10,,,,,,,,,,,,,,,,,,,,,,,,,,,,,,,,,,,,,
387.26,0.30413,1.20631,10,,,,,,,,,,,,,,,,,,,,,,,,,,,,,,,,,,,,,
387.86,0.30413,1.22712,10,,,,,,,,,,,,,,,,,,,,,,,,,,,,,,,,,,,,,
388.46,0.30413,1.26635,10,,,,,,,,,,,,,,,,,,,,,,,,,,,,,,,,,,,,,
389.06,0.30402,1.22872,10,,,,,,,,,,,,,,,,,,,,,,,,,,,,,,,,,,,,,
389.66,0.30407,1.30441,10,,,,,,,,,,,,,,,,,,,,,,,,,,,,,,,,,,,,,
390.26,0.30402,1.22743,10,,,,,,,,,,,,,,,,,,,,,,,,,,,,,,,,,,,,,
390.86,0.30402,1.17416,10,,,,,,,,,,,,,,,,,,,,,,,,,,,,,,,,,,,,,
391.46,0.30413,1.26631,10,,,,,,,,,,,,,,,,,,,,,,,,,,,,,,,,,,,,,
392.06,0.30413,1.21958,10,,,,,,,,,,,,,,,,,,,,,,,,,,,,,,,,,,,,,
392.66,0.30413,1.23782,10,,,,,,,,,,,,,,,,,,,,,,,,,,,,,,,,,,,,,
393.26,0.30413,1.21438,10,,,,,,,,,,,,,,,,,,,,,,,,,,,,,,,,,,,,,
393.86,0.30407,1.22619,10,,,,,,,,,,,,,,,,,,,,,,,,,,,,,,,,,,,,,
394.46,0.30407,1.24924,10,,,,,,,,,,,,,,,,,,,,,,,,,,,,,,,,,,,,,
395.06,0.30419,1.20709,10,,,,,,,,,,,,,,,,,,,,,,,,,,,,,,,,,,,,,
395.66,0.30419,1.16471,10,,,,,,,,,,,,,,,,,,,,,,,,,,,,,,,,,,,,,
396.26,0.30424,1.20026,10,,,,,,,,,,,,,,,,,,,,,,,,,,,,,,,,,,,,,
396.86,0.30424,1.24878,10,,,,,,,,,,,,,,,,,,,,,,,,,,,,,,,,,,,,,
397.46,0.30424,1.22813,10,,,,,,,,,,,,,,,,,,,,,,,,,,,,,,,,,,,,,
398.06,0.30424,1.16321,10,,,,,,,,,,,,,,,,,,,,,,,,,,,,,,,,,,,,,
398.66,0.30424,1.26519,10,,,,,,,,,,,,,,,,,,,,,,,,,,,,,,,,,,,,,
399.26,0.30424,1.21088,10,,,,,,,,,,,,,,,,,,,,,,,,,,,,,,,,,,,,,
399.86,0.30424,1.21468,10,,,,,,,,,,,,,,,,,,,,,,,,,,,,,,,,,,,,,
400.46,0.30424,1.22988,10,,,,,,,,,,,,,,,,,,,,,,,,,,,,,,,,,,,,,
401.06,0.30424,1.26647,10,,,,,,,,,,,,,,,,,,,,,,,,,,,,,,,,,,,,,
401.66,0.30424,1.26604,10,,,,,,,,,,,,,,,,,,,,,,,,,,,,,,,,,,,,,
402.26,0.30424,1.20272,10,,,,,,,,,,,,,,,,,,,,,,,,,,,,,,,,,,,,,
402.86,0.30424,1.26188,10,,,,,,,,,,,,,,,,,,,,,,,,,,,,,,,,,,,,,
403.46,0.30424,1.18585,10,,,,,,,,,,,,,,,,,,,,,,,,,,,,,,,,,,,,,
404.06,0.30424,1.22802,10,,,,,,,,,,,,,,,,,,,,,,,,,,,,,,,,,,,,,
404.66,0.3043,1.20755,10,,,,,,,,,,,,,,,,,,,,,,,,,,,,,,,,,,,,,
405.26,0.30436,1.16267,10,,,,,,,,,,,,,,,,,,,,,,,,,,,,,,,,,,,,,
405.86,0.30447,1.24586,10,,,,,,,,,,,,,,,,,,,,,,,,,,,,,,,,,,,,,
406.362,2.67047,235.04558,10,,,,,,,,,,,,,,,,,,,,,,,,,,,,,,,,,,,,,
406.962,7.67114,907.23096,10,,,,,,,,,,,,,,,,,,,,,,,,,,,,,,,,,,,,,
407.562,12.67112,376.14117,10,,,,,,,,,,,,,,,,,,,,,,,,,,,,,,,,,,,,,
408.162,17.67116,128.35391,10,,,,,,,,,,,,,,,,,,,,,,,,,,,,,,,,,,,,,
408.762,22.67114,41.87766,10,,,,,,,,,,,,,,,,,,,,,,,,,,,,,,,,,,,,,
409.362,27.67113,21.11723,10,,,,,,,,,,,,,,,,,,,,,,,,,,,,,,,,,,,,,
409.962,32.67105,11.23814,10,,,,,,,,,,,,,,,,,,,,,,,,,,,,,,,,,,,,,
410.562,37.67109,1.45029,10,,,,,,,,,,,,,,,,,,,,,,,,,,,,,,,,,,,,,
411.162,42.67119,0.66944,10,,,,,,,,,,,,,,,,,,,,,,,,,,,,,,,,,,,,,
411.762,47.67117,0.32606,10,,,,,,,,,,,,,,,,,,,,,,,,,,,,,,,,,,,,,
412.362,52.67115,-0.08697,10,,,,,,,,,,,,,,,,,,,,,,,,,,,,,,,,,,,,,
412.962,57.67114,-0.2054,10,,,,,,,,,,,,,,,,,,,,,,,,,,,,,,,,,,,,,
413.562,62.67112,-1.75714,10,,,,,,,,,,,,,,,,,,,,,,,,,,,,,,,,,,,,,
414.162,67.67116,-3.8172,10,,,,,,,,,,,,,,,,,,,,,,,,,,,,,,,,,,,,,
414.762,72.67109,-3.84837,10,,,,,,,,,,,,,,,,,,,,,,,,,,,,,,,,,,,,,
415.362,77.67113,-3.77694,10,,,,,,,,,,,,,,,,,,,,,,,,,,,,,,,,,,,,,
415.604,79.68777,-3.78201,10,,,,,,,,,,,,,,,,,,,,,,,,,,,,,,,,,,,,,