File: combined_ligament_solver/data/processed/Data Sheet 3_S151568_ACL.csv
Specimen properties : Length,40,mm,Unnamed: 3,Unnamed: 4,Unnamed: 5,Unnamed: 6,Unnamed: 7,Unnamed: 8,Unnamed: 9,Unnamed: 10,Unnamed: 11,Stress-Strain,Unnamed: 13,Unnamed: 14,Unnamed: 15,Unnamed: 16,Unnamed: 17,Unnamed: 18,Unnamed: 19,Unnamed: 20,Unnamed: 21,Unnamed: 22,Unnamed: 23,Unnamed: 24,Unnamed: 25,Unnamed: 26,Unnamed: 27,Linear,Unnamed: 29,Unnamed: 30,Unnamed: 31,Unnamed: 32,Unnamed: 33,Modulus,Unnamed: 35,Failure,Unnamed: 37,Unnamed: 38,Unnamed: 39,Unnamed: 40
Cross Section Average,34.679500000000004,mm2,,,,,,,,,,Polynomial Coefficients,,,,,,,,,,,,,,,,Force,,Stress,Extension,Strain,,Secant,Tangent,Load,Stress,Extension,Strain,Stiffness
Time,Extension,Load,Total cycle count,,,Extension,Load,Strain,Stress,E-tan,,X6,42029986.47112255,,,,,,,,,Strain,Stress,E-tan,,,,(N),,(MPa),(mm),(%),,(MPa),(MPa),(N),(MPa),(mm),(%),(N/mm)
(s),(mm),(N),,,,(mm),(N),(mm/mm),(MPa),(MPa),,X5,-16328499.852662655,,,,,,,,,(mm/mm),(MPa),(MPa),,,,169.61058714988965,,4.8908025533784985,3.4399999999999995,8.6,,56.86979713230812,144.99042985452806,280.96265,8.06936980060266,4.766629999999999,11.916574999999998,49.30540324124699
0.7,1.95829,1.01892,0,,,8.53411,339.93616,,,,,,,,,,,,,,,0.007,-0.0237748311557385,6.676456278261327,,,,,,,,,,,,,,,,
1.5,2.09157,1.31784,0,,,15.20089,75.80988,,,,,,,,,,,,,,,0.015,0.08087454671577704,15.655420955895405,,,,,,,,,,,,,,,,
2.3,2.22496,1.57152,0,,,21.86749,9.98045,,,,,,,,,,,,,,,0.023,0.20701727760428185,15.468438959442762,,,,,,,,,,,,,,,,
3.1,2.35835,1.91023,0,,,,,,,,,,,,,,,,,,,0.031,0.334235434683554,17.03719340321595,,,,,,,,,,,,,,,,
3.9,2.49152,2.42296,0,,,,,,,,,,,,,,,,,,,0.039,0.5052678684031381,26.04649131223888,,,,,,,,,,,,,,,,
4.7,2.62491,2.97775,0,,,,,,,,,,,,,,,,,,,0.047,0.7885774508272683,43.93587541185025,,,,,,,,,,,,,,,,
5.5,2.75836,3.69898,0,,,,,,,,,,,,,,,,,,,0.055,1.2488512142907051,68.89123591734452,,,,,,,,,,,,,,,,
6.3,2.89159,4.27988,0,,,,,,,,,,,,,,,,,,,0.063,1.9254333843714717,96.83642232352997,,,,,,,,,,,,,,,,
7.1,3.02492,5.03228,0,,,,,,,,,,,,,,,,,,,0.071,2.8186913071805186,122.42485519440984,,,,,,,,,,,,,,,,
7.9,3.15837,5.93277,0,,,,,,,,,,,,,,,,,,,0.079,3.8843142709682814,140.03113795273134,,,,,,,,,,,,,,,,
8.7,3.2916,7.04924,0,,,,,,,,,,,,,,,,,,,0.087,5.035545222048202,144.7426686697034,,,,,,,,,,,,,,,,
9.5,3.42493,8.32666,0,,,,,,,,,,,,,,,,,,,0.095,6.153345375036926,133.35125185438542,,,,,,,,,,,,,,,,
10.3,3.55833,9.78544,0,,,,,,,,,,,,,,,,,,,0.103,7.104491717412012,105.34471024373094,,,,,,,,,,,,,,,,
11.1,3.69149,11.29212,0,,,,,,,,,,,,,,,,,,,0.111,7.767607408385584,63.89849659157225,,,,,,,,,,,,,,,,
11.9,3.82494,13.12208,0,,,,,,,,,,,,,,,,,,,0.119,8.067125072095735,16.867305458791986,,,,,,,,,,,,,,,,
12.7,3.95828,14.89222,0,,,,,,,,,,,,,,,,,,,0.127,,,,,,,,,,,,,,,,,,
13.5,4.09162,16.8549,0,,,,,,,,,,,,,,,,,,,0.135,,,,,,,,,,,,,,,,,,
14.3,4.22495,19.76808,0,,,,,,,,,,,,,,,,,,,0.143,,,,,,,,,,,,,,,,,,
15.1,4.35823,23.39631,0,,,,,,,,,,,,,,,,,,,0.151,,,,,,,,,,,,,,,,,,
15.9,4.49151,27.88642,0,,,,,,,,,,,,,,,,,,,0.159,,,,,,,,,,,,,,,,,,
16.7,4.62496,32.9415,0,,,,,,,,,,,,,,,,,,,0.167,,,,,,,,,,,,,,,,,,
17.5,4.75824,38.85114,0,,,,,,,,,,,,,,,,,,,0.175,,,,,,,,,,,,,,,,,,
18.146,4.69931,34.09216,0.5,,,,,,,,,,,,,,,,,,,0.183,,,,,,,,,,,,,,,,,,
18.946,4.56597,26.45783,0.5,,,,,,,,,,,,,,,,,,,0.191,,,,,,,,,,,,,,,,,,
19.746,4.43264,20.45024,0.5,,,,,,,,,,,,,,,,,,,0.199,,,,,,,,,,,,,,,,,,
20.546,4.2993,15.77637,0.5,,,,,,,,,,,,,,,,,,,,,,,,,,,,,,,,,,,,,
21.346,4.16591,12.48099,0.5,,,,,,,,,,,,,,,,,,,,,,,,,,,,,,,,,,,,,
22.146,4.03263,9.78997,0.5,,,,,,,,,,,,,,,,,,,,,,,,,,,,,,,,,,,,,
22.946,3.89929,7.88703,0.5,,,,,,,,,,,,,,,,,,,,,,,,,,,,,,,,,,,,,
23.746,3.76578,6.32184,0.5,,,,,,,,,,,,,,,,,,,,,,,,,,,,,,,,,,,,,
24.546,3.63262,5.06093,0.5,,,,,,,,,,,,,,,,,,,,,,,,,,,,,,,,,,,,,
25.346,3.49928,4.30024,0.5,,,,,,,,,,,,,,,,,,,,,,,,,,,,,,,,,,,,,
26.146,3.36589,3.32333,0.5,,,,,,,,,,,,,,,,,,,,,,,,,,,,,,,,,,,,,
26.946,3.23266,2.57605,0.5,,,,,,,,,,,,,,,,,,,,,,,,,,,,,,,,,,,,,
27.746,3.09933,2.05548,0.5,,,,,,,,,,,,,,,,,,,,,,,,,,,,,,,,,,,,,
28.546,2.96588,1.61864,0.5,,,,,,,,,,,,,,,,,,,,,,,,,,,,,,,,,,,,,
29.346,2.83265,1.21384,0.5,,,,,,,,,,,,,,,,,,,,,,,,,,,,,,,,,,,,,
30.07,2.71195,0.99925,1,,,,,,,,,,,,,,,,,,,,,,,,,,,,,,,,,,,,,
30.674,2.81197,1.28171,1,,,,,,,,,,,,,,,,,,,,,,,,,,,,,,,,,,,,,
31.474,2.94519,1.7768,1,,,,,,,,,,,,,,,,,,,,,,,,,,,,,,,,,,,,,
32.274,3.07859,2.49966,1,,,,,,,,,,,,,,,,,,,,,,,,,,,,,,,,,,,,,
33.074,3.21198,3.28132,1,,,,,,,,,,,,,,,,,,,,,,,,,,,,,,,,,,,,,
33.874,3.3452,4.17064,1,,,,,,,,,,,,,,,,,,,,,,,,,,,,,,,,,,,,,
34.674,3.4786,5.22317,1,,,,,,,,,,,,,,,,,,,,,,,,,,,,,,,,,,,,,
35.474,3.61199,6.34679,1,,,,,,,,,,,,,,,,,,,,,,,,,,,,,,,,,,,,,
36.274,3.74521,7.91449,1,,,,,,,,,,,,,,,,,,,,,,,,,,,,,,,,,,,,,
37.074,3.87855,9.89517,1,,,,,,,,,,,,,,,,,,,,,,,,,,,,,,,,,,,,,
37.874,4.012,12.01924,1,,,,,,,,,,,,,,,,,,,,,,,,,,,,,,,,,,,,,
38.674,4.14528,14.39645,1,,,,,,,,,,,,,,,,,,,,,,,,,,,,,,,,,,,,,
39.474,4.27862,16.75942,1,,,,,,,,,,,,,,,,,,,,,,,,,,,,,,,,,,,,,
40.274,4.41195,20.8736,1,,,,,,,,,,,,,,,,,,,,,,,,,,,,,,,,,,,,,
41.074,4.54518,26.123,1,,,,,,,,,,,,,,,,,,,,,,,,,,,,,,,,,,,,,
41.874,4.67857,32.17757,1,,,,,,,,,,,,,,,,,,,,,,,,,,,,,,,,,,,,,
42.674,4.81191,38.9652,1,,,,,,,,,,,,,,,,,,,,,,,,,,,,,,,,,,,,,
43.286,4.74742,34.21552,1.5,,,,,,,,,,,,,,,,,,,,,,,,,,,,,,,,,,,,,
44.086,4.61386,26.4954,1.5,,,,,,,,,,,,,,,,,,,,,,,,,,,,,,,,,,,,,
44.886,4.48063,20.4715,1.5,,,,,,,,,,,,,,,,,,,,,,,,,,,,,,,,,,,,,
45.686,4.34735,15.73036,1.5,,,,,,,,,,,,,,,,,,,,,,,,,,,,,,,,,,,,,
46.486,4.21379,12.34473,1.5,,,,,,,,,,,,,,,,,,,,,,,,,,,,,,,,,,,,,
47.286,4.08062,9.6673,1.5,,,,,,,,,,,,,,,,,,,,,,,,,,,,,,,,,,,,,
48.086,3.94729,7.77498,1.5,,,,,,,,,,,,,,,,,,,,,,,,,,,,,,,,,,,,,
48.886,3.81384,6.16999,1.5,,,,,,,,,,,,,,,,,,,,,,,,,,,,,,,,,,,,,
49.686,3.68067,5.21294,1.5,,,,,,,,,,,,,,,,,,,,,,,,,,,,,,,,,,,,,
50.486,3.54733,4.09878,1.5,,,,,,,,,,,,,,,,,,,,,,,,,,,,,,,,,,,,,
51.286,3.41388,3.25487,1.5,,,,,,,,,,,,,,,,,,,,,,,,,,,,,,,,,,,,,
52.086,3.2806,2.56259,1.5,,,,,,,,,,,,,,,,,,,,,,,,,,,,,,,,,,,,,
52.886,3.14727,1.93195,1.5,,,,,,,,,,,,,,,,,,,,,,,,,,,,,,,,,,,,,
53.686,3.01393,1.5558,1.5,,,,,,,,,,,,,,,,,,,,,,,,,,,,,,,,,,,,,
54.486,2.88065,1.14223,1.5,,,,,,,,,,,,,,,,,,,,,,,,,,,,,,,,,,,,,
55.04,2.78828,0.98091,2,,,,,,,,,,,,,,,,,,,,,,,,,,,,,,,,,,,,,
55.84,2.92224,1.36743,2,,,,,,,,,,,,,,,,,,,,,,,,,,,,,,,,,,,,,
56.64,3.05552,1.96616,2,,,,,,,,,,,,,,,,,,,,,,,,,,,,,,,,,,,,,
57.44,3.18886,2.62683,2,,,,,,,,,,,,,,,,,,,,,,,,,,,,,,,,,,,,,
58.24,3.32231,3.47528,2,,,,,,,,,,,,,,,,,,,,,,,,,,,,,,,,,,,,,
59.04,3.45565,4.49931,2,,,,,,,,,,,,,,,,,,,,,,,,,,,,,,,,,,,,,
59.84,3.58887,5.56355,2,,,,,,,,,,,,,,,,,,,,,,,,,,,,,,,,,,,,,
60.64,3.72238,6.86395,2,,,,,,,,,,,,,,,,,,,,,,,,,,,,,,,,,,,,,
61.44,3.8556,8.72532,2,,,,,,,,,,,,,,,,,,,,,,,,,,,,,,,,,,,,,
62.24,3.98888,10.7617,2,,,,,,,,,,,,,,,,,,,,,,,,,,,,,,,,,,,,,
63.04,4.12233,13.08053,2,,,,,,,,,,,,,,,,,,,,,,,,,,,,,,,,,,,,,
63.84,4.25561,15.20069,2,,,,,,,,,,,,,,,,,,,,,,,,,,,,,,,,,,,,,
64.64,4.38883,18.5799,2,,,,,,,,,,,,,,,,,,,,,,,,,,,,,,,,,,,,,
65.44,4.52234,23.48193,2,,,,,,,,,,,,,,,,,,,,,,,,,,,,,,,,,,,,,
66.24,4.65568,29.36422,2,,,,,,,,,,,,,,,,,,,,,,,,,,,,,,,,,,,,,
67.04,4.7889,36.08833,2,,,,,,,,,,,,,,,,,,,,,,,,,,,,,,,,,,,,,
67.66,4.82613,37.90377,2.5,,,,,,,,,,,,,,,,,,,,,,,,,,,,,,,,,,,,,
68.46,4.6924,29.18536,2.5,,,,,,,,,,,,,,,,,,,,,,,,,,,,,,,,,,,,,
69.26,4.55889,22.58254,2.5,,,,,,,,,,,,,,,,,,,,,,,,,,,,,,,,,,,,,
70.06,4.42561,17.39154,2.5,,,,,,,,,,,,,,,,,,,,,,,,,,,,,,,,,,,,,
70.86,4.29239,13.40785,2.5,,,,,,,,,,,,,,,,,,,,,,,,,,,,,,,,,,,,,
71.66,4.15888,10.54717,2.5,,,,,,,,,,,,,,,,,,,,,,,,,,,,,,,,,,,,,
72.46,4.02566,8.32417,2.5,,,,,,,,,,,,,,,,,,,,,,,,,,,,,,,,,,,,,
73.26,3.89232,6.66556,2.5,,,,,,,,,,,,,,,,,,,,,,,,,,,,,,,,,,,,,
74.06,3.75881,5.35437,2.5,,,,,,,,,,,,,,,,,,,,,,,,,,,,,,,,,,,,,
74.86,3.6257,4.41018,2.5,,,,,,,,,,,,,,,,,,,,,,,,,,,,,,,,,,,,,
75.66,3.49231,3.4827,2.5,,,,,,,,,,,,,,,,,,,,,,,,,,,,,,,,,,,,,
76.46,3.35886,2.76739,2.5,,,,,,,,,,,,,,,,,,,,,,,,,,,,,,,,,,,,,
77.26,3.22569,2.12631,2.5,,,,,,,,,,,,,,,,,,,,,,,,,,,,,,,,,,,,,
78.06,3.09224,1.65472,2.5,,,,,,,,,,,,,,,,,,,,,,,,,,,,,,,,,,,,,
78.86,2.95891,1.24852,2.5,,,,,,,,,,,,,,,,,,,,,,,,,,,,,,,,,,,,,
79.552,2.84365,0.99734,3,,,,,,,,,,,,,,,,,,,,,,,,,,,,,,,,,,,,,
80.254,2.96061,1.33809,3,,,,,,,,,,,,,,,,,,,,,,,,,,,,,,,,,,,,,
81.054,3.09394,1.85409,3,,,,,,,,,,,,,,,,,,,,,,,,,,,,,,,,,,,,,
81.854,3.22728,2.61299,3,,,,,,,,,,,,,,,,,,,,,,,,,,,,,,,,,,,,,
82.654,3.36062,3.52007,3,,,,,,,,,,,,,,,,,,,,,,,,,,,,,,,,,,,,,
83.454,3.49395,4.4855,3,,,,,,,,,,,,,,,,,,,,,,,,,,,,,,,,,,,,,
84.254,3.62729,5.59769,3,,,,,,,,,,,,,,,,,,,,,,,,,,,,,,,,,,,,,
85.054,3.76057,6.89786,3,,,,,,,,,,,,,,,,,,,,,,,,,,,,,,,,,,,,,
85.854,3.89402,8.83528,3,,,,,,,,,,,,,,,,,,,,,,,,,,,,,,,,,,,,,
86.654,4.02724,10.90332,3,,,,,,,,,,,,,,,,,,,,,,,,,,,,,,,,,,,,,
87.454,4.16058,13.19226,3,,,,,,,,,,,,,,,,,,,,,,,,,,,,,,,,,,,,,
88.254,4.29397,15.52266,3,,,,,,,,,,,,,,,,,,,,,,,,,,,,,,,,,,,,,
89.054,4.42725,18.95485,3,,,,,,,,,,,,,,,,,,,,,,,,,,,,,,,,,,,,,
89.854,4.56059,24.02317,3,,,,,,,,,,,,,,,,,,,,,,,,,,,,,,,,,,,,,
90.654,4.69398,30.06918,3,,,,,,,,,,,,,,,,,,,,,,,,,,,,,,,,,,,,,
91.454,4.82732,37.02585,3,,,,,,,,,,,,,,,,,,,,,,,,,,,,,,,,,,,,,
92.064,4.82908,36.68953,3.5,,,,,,,,,,,,,,,,,,,,,,,,,,,,,,,,,,,,,
92.864,4.69563,28.2555,3.5,,,,,,,,,,,,,,,,,,,,,,,,,,,,,,,,,,,,,
93.664,4.56229,21.87713,3.5,,,,,,,,,,,,,,,,,,,,,,,,,,,,,,,,,,,,,
94.464,4.42895,16.75723,3.5,,,,,,,,,,,,,,,,,,,,,,,,,,,,,,,,,,,,,
95.264,4.29567,12.98836,3.5,,,,,,,,,,,,,,,,,,,,,,,,,,,,,,,,,,,,,
96.064,4.16222,10.11172,3.5,,,,,,,,,,,,,,,,,,,,,,,,,,,,,,,,,,,,,
96.864,4.029,8.05013,3.5,,,,,,,,,,,,,,,,,,,,,,,,,,,,,,,,,,,,,
97.664,3.89561,6.4602,3.5,,,,,,,,,,,,,,,,,,,,,,,,,,,,,,,,,,,,,
98.464,3.76216,5.49598,3.5,,,,,,,,,,,,,,,,,,,,,,,,,,,,,,,,,,,,,
99.264,3.62899,4.33077,3.5,,,,,,,,,,,,,,,,,,,,,,,,,,,,,,,,,,,,,
100.064,3.49565,3.32458,3.5,,,,,,,,,,,,,,,,,,,,,,,,,,,,,,,,,,,,,
100.864,3.3622,2.59281,3.5,,,,,,,,,,,,,,,,,,,,,,,,,,,,,,,,,,,,,
101.664,3.22898,1.97433,3.5,,,,,,,,,,,,,,,,,,,,,,,,,,,,,,,,,,,,,
102.464,3.0957,1.54603,3.5,,,,,,,,,,,,,,,,,,,,,,,,,,,,,,,,,,,,,
103.264,2.96225,1.18625,3.5,,,,,,,,,,,,,,,,,,,,,,,,,,,,,,,,,,,,,
103.878,2.8598,0.99551,4,,,,,,,,,,,,,,,,,,,,,,,,,,,,,,,,,,,,,
104.58,2.97687,1.30609,4,,,,,,,,,,,,,,,,,,,,,,,,,,,,,,,,,,,,,
105.38,3.11032,1.87883,4,,,,,,,,,,,,,,,,,,,,,,,,,,,,,,,,,,,,,
106.18,3.24349,2.59076,4,,,,,,,,,,,,,,,,,,,,,,,,,,,,,,,,,,,,,
106.98,3.37694,3.40918,4,,,,,,,,,,,,,,,,,,,,,,,,,,,,,,,,,,,,,
107.78,3.51027,4.42671,4,,,,,,,,,,,,,,,,,,,,,,,,,,,,,,,,,,,,,
108.58,3.6435,5.57543,4,,,,,,,,,,,,,,,,,,,,,,,,,,,,,,,,,,,,,
109.38,3.777,6.85555,4,,,,,,,,,,,,,,,,,,,,,,,,,,,,,,,,,,,,,
110.18,3.91028,8.7388,4,,,,,,,,,,,,,,,,,,,,,,,,,,,,,,,,,,,,,
110.98,4.04351,10.82326,4,,,,,,,,,,,,,,,,,,,,,,,,,,,,,,,,,,,,,
111.78,4.17696,13.20297,4,,,,,,,,,,,,,,,,,,,,,,,,,,,,,,,,,,,,,
112.58,4.31029,15.41948,4,,,,,,,,,,,,,,,,,,,,,,,,,,,,,,,,,,,,,
113.38,4.44352,18.88716,4,,,,,,,,,,,,,,,,,,,,,,,,,,,,,,,,,,,,,
114.18,4.57697,24.09137,4,,,,,,,,,,,,,,,,,,,,,,,,,,,,,,,,,,,,,
114.98,4.7103,30.0584,4,,,,,,,,,,,,,,,,,,,,,,,,,,,,,,,,,,,,,
115.78,4.84353,37.14746,4,,,,,,,,,,,,,,,,,,,,,,,,,,,,,,,,,,,,,
116.474,4.82602,35.54314,4.5,,,,,,,,,,,,,,,,,,,,,,,,,,,,,,,,,,,,,
117.274,4.69268,27.3638,4.5,,,,,,,,,,,,,,,,,,,,,,,,,,,,,,,,,,,,,
118.074,4.55917,21.13273,4.5,,,,,,,,,,,,,,,,,,,,,,,,,,,,,,,,,,,,,
118.874,4.42595,16.19137,4.5,,,,,,,,,,,,,,,,,,,,,,,,,,,,,,,,,,,,,
119.674,4.29267,12.49595,4.5,,,,,,,,,,,,,,,,,,,,,,,,,,,,,,,,,,,,,
120.474,4.15916,9.78622,4.5,,,,,,,,,,,,,,,,,,,,,,,,,,,,,,,,,,,,,
121.274,4.026,7.875,4.5,,,,,,,,,,,,,,,,,,,,,,,,,,,,,,,,,,,,,
122.074,3.89266,6.20587,4.5,,,,,,,,,,,,,,,,,,,,,,,,,,,,,,,,,,,,,
122.874,3.75915,5.3438,4.5,,,,,,,,,,,,,,,,,,,,,,,,,,,,,,,,,,,,,
123.674,3.62599,4.11579,4.5,,,,,,,,,,,,,,,,,,,,,,,,,,,,,,,,,,,,,
124.474,3.49271,3.24334,4.5,,,,,,,,,,,,,,,,,,,,,,,,,,,,,,,,,,,,,
125.274,3.3592,2.50992,4.5,,,,,,,,,,,,,,,,,,,,,,,,,,,,,,,,,,,,,
126.074,3.22603,1.87382,4.5,,,,,,,,,,,,,,,,,,,,,,,,,,,,,,,,,,,,,
126.874,3.09264,1.56774,4.5,,,,,,,,,,,,,,,,,,,,,,,,,,,,,,,,,,,,,
127.674,2.95925,1.1263,4.5,,,,,,,,,,,,,,,,,,,,,,,,,,,,,,,,,,,,,
128.21,2.93686,1.02485,5,,,,,,,,,,,,,,,,,,,,,,,,,,,,,,,,,,,,,
129.01,3.07054,1.54247,5,,,,,,,,,,,,,,,,,,,,,,,,,,,,,,,,,,,,,
129.81,3.20388,2.14093,5,,,,,,,,,,,,,,,,,,,,,,,,,,,,,,,,,,,,,
130.61,3.33733,2.92433,5,,,,,,,,,,,,,,,,,,,,,,,,,,,,,,,,,,,,,
131.41,3.47055,3.98572,5,,,,,,,,,,,,,,,,,,,,,,,,,,,,,,,,,,,,,
132.21,3.60406,4.96232,5,,,,,,,,,,,,,,,,,,,,,,,,,,,,,,,,,,,,,
133.01,3.73728,6.15589,5,,,,,,,,,,,,,,,,,,,,,,,,,,,,,,,,,,,,,
133.81,3.87045,7.7685,5,,,,,,,,,,,,,,,,,,,,,,,,,,,,,,,,,,,,,
134.61,4.00401,9.9119,5,,,,,,,,,,,,,,,,,,,,,,,,,,,,,,,,,,,,,
135.41,4.13735,12.16691,5,,,,,,,,,,,,,,,,,,,,,,,,,,,,,,,,,,,,,
136.21,4.27051,14.30486,5,,,,,,,,,,,,,,,,,,,,,,,,,,,,,,,,,,,,,
137.01,4.40402,17.0282,5,,,,,,,,,,,,,,,,,,,,,,,,,,,,,,,,,,,,,
137.81,4.53724,21.73784,5,,,,,,,,,,,,,,,,,,,,,,,,,,,,,,,,,,,,,
138.61,4.67047,27.50158,5,,,,,,,,,,,,,,,,,,,,,,,,,,,,,,,,,,,,,
139.41,4.80397,34.28535,5,,,,,,,,,,,,,,,,,,,,,,,,,,,,,,,,,,,,,
140.016,4.90495,40.02666,5.5,,,,,,,,,,,,,,,,,,,,,,,,,,,,,,,,,,,,,
140.816,4.77162,31.09455,5.5,,,,,,,,,,,,,,,,,,,,,,,,,,,,,,,,,,,,,
141.616,4.63834,24.04165,5.5,,,,,,,,,,,,,,,,,,,,,,,,,,,,,,,,,,,,,
142.416,4.50489,18.46134,5.5,,,,,,,,,,,,,,,,,,,,,,,,,,,,,,,,,,,,,
143.216,4.37155,14.09948,5.5,,,,,,,,,,,,,,,,,,,,,,,,,,,,,,,,,,,,,
144.016,4.23838,10.97177,5.5,,,,,,,,,,,,,,,,,,,,,,,,,,,,,,,,,,,,,
144.816,4.10482,8.67468,5.5,,,,,,,,,,,,,,,,,,,,,,,,,,,,,,,,,,,,,
145.616,3.97165,6.88071,5.5,,,,,,,,,,,,,,,,,,,,,,,,,,,,,,,,,,,,,
146.416,3.83837,5.52826,5.5,,,,,,,,,,,,,,,,,,,,,,,,,,,,,,,,,,,,,
147.216,3.70481,4.54684,5.5,,,,,,,,,,,,,,,,,,,,,,,,,,,,,,,,,,,,,
148.016,3.57164,3.59965,5.5,,,,,,,,,,,,,,,,,,,,,,,,,,,,,,,,,,,,,
148.816,3.43836,2.82032,5.5,,,,,,,,,,,,,,,,,,,,,,,,,,,,,,,,,,,,,
149.616,3.3048,2.15092,5.5,,,,,,,,,,,,,,,,,,,,,,,,,,,,,,,,,,,,,
150.416,3.17169,1.61012,5.5,,,,,,,,,,,,,,,,,,,,,,,,,,,,,,,,,,,,,
151.216,3.0383,1.24555,5.5,,,,,,,,,,,,,,,,,,,,,,,,,,,,,,,,,,,,,
151.838,2.93465,0.99745,6,,,,,,,,,,,,,,,,,,,,,,,,,,,,,,,,,,,,,
152.54,3.05156,1.36387,6,,,,,,,,,,,,,,,,,,,,,,,,,,,,,,,,,,,,,
153.34,3.18489,1.95578,6,,,,,,,,,,,,,,,,,,,,,,,,,,,,,,,,,,,,,
154.14,3.31823,2.70827,6,,,,,,,,,,,,,,,,,,,,,,,,,,,,,,,,,,,,,
154.94,3.45157,3.69811,6,,,,,,,,,,,,,,,,,,,,,,,,,,,,,,,,,,,,,
155.74,3.5849,4.64048,6,,,,,,,,,,,,,,,,,,,,,,,,,,,,,,,,,,,,,
156.54,3.71835,5.84394,6,,,,,,,,,,,,,,,,,,,,,,,,,,,,,,,,,,,,,
157.34,3.85158,7.33217,6,,,,,,,,,,,,,,,,,,,,,,,,,,,,,,,,,,,,,
158.14,3.98491,9.43453,6,,,,,,,,,,,,,,,,,,,,,,,,,,,,,,,,,,,,,
158.94,4.11831,11.52802,6,,,,,,,,,,,,,,,,,,,,,,,,,,,,,,,,,,,,,
159.74,4.25159,13.76694,6,,,,,,,,,,,,,,,,,,,,,,,,,,,,,,,,,,,,,
160.54,4.38492,16.34431,6,,,,,,,,,,,,,,,,,,,,,,,,,,,,,,,,,,,,,
161.34,4.51837,20.54708,6,,,,,,,,,,,,,,,,,,,,,,,,,,,,,,,,,,,,,
162.14,4.65154,26.16736,6,,,,,,,,,,,,,,,,,,,,,,,,,,,,,,,,,,,,,
162.94,4.78488,32.7498,6,,,,,,,,,,,,,,,,,,,,,,,,,,,,,,,,,,,,,
163.726,4.91606,40.01659,6.5,,,,,,,,,,,,,,,,,,,,,,,,,,,,,,,,,,,,,
164.428,4.79972,32.24659,6.5,,,,,,,,,,,,,,,,,,,,,,,,,,,,,,,,,,,,,
165.228,4.66616,24.85603,6.5,,,,,,,,,,,,,,,,,,,,,,,,,,,,,,,,,,,,,
166.028,4.53294,19.13236,6.5,,,,,,,,,,,,,,,,,,,,,,,,,,,,,,,,,,,,,
166.828,4.39966,14.60632,6.5,,,,,,,,,,,,,,,,,,,,,,,,,,,,,,,,,,,,,
167.628,4.26621,11.33506,6.5,,,,,,,,,,,,,,,,,,,,,,,,,,,,,,,,,,,,,
168.428,4.13298,8.95889,6.5,,,,,,,,,,,,,,,,,,,,,,,,,,,,,,,,,,,,,
169.228,3.99965,7.15226,6.5,,,,,,,,,,,,,,,,,,,,,,,,,,,,,,,,,,,,,
170.028,3.8662,5.63608,6.5,,,,,,,,,,,,,,,,,,,,,,,,,,,,,,,,,,,,,
170.828,3.73297,4.67005,6.5,,,,,,,,,,,,,,,,,,,,,,,,,,,,,,,,,,,,,
171.628,3.59958,3.672,6.5,,,,,,,,,,,,,,,,,,,,,,,,,,,,,,,,,,,,,
172.428,3.46624,2.885,6.5,,,,,,,,,,,,,,,,,,,,,,,,,,,,,,,,,,,,,
173.228,3.33296,2.1994,6.5,,,,,,,,,,,,,,,,,,,,,,,,,,,,,,,,,,,,,
174.028,3.19951,1.69555,6.5,,,,,,,,,,,,,,,,,,,,,,,,,,,,,,,,,,,,,
174.828,3.06623,1.29341,6.5,,,,,,,,,,,,,,,,,,,,,,,,,,,,,,,,,,,,,
175.468,2.95953,0.99433,7,,,,,,,,,,,,,,,,,,,,,,,,,,,,,,,,,,,,,
176.17,3.07649,1.37109,7,,,,,,,,,,,,,,,,,,,,,,,,,,,,,,,,,,,,,
176.97,3.21,2.08159,7,,,,,,,,,,,,,,,,,,,,,,,,,,,,,,,,,,,,,
177.77,3.34322,2.74999,7,,,,,,,,,,,,,,,,,,,,,,,,,,,,,,,,,,,,,
178.57,3.47656,3.71091,7,,,,,,,,,,,,,,,,,,,,,,,,,,,,,,,,,,,,,
179.37,3.61001,4.76765,7,,,,,,,,,,,,,,,,,,,,,,,,,,,,,,,,,,,,,
180.17,3.74317,5.91244,7,,,,,,,,,,,,,,,,,,,,,,,,,,,,,,,,,,,,,
180.97,3.87651,7.48668,7,,,,,,,,,,,,,,,,,,,,,,,,,,,,,,,,,,,,,
181.77,4.01002,9.65777,7,,,,,,,,,,,,,,,,,,,,,,,,,,,,,,,,,,,,,
182.57,4.14318,11.77138,7,,,,,,,,,,,,,,,,,,,,,,,,,,,,,,,,,,,,,
183.37,4.27658,13.80126,7,,,,,,,,,,,,,,,,,,,,,,,,,,,,,,,,,,,,,
184.17,4.40997,16.7278,7,,,,,,,,,,,,,,,,,,,,,,,,,,,,,,,,,,,,,
184.97,4.54319,21.13561,7,,,,,,,,,,,,,,,,,,,,,,,,,,,,,,,,,,,,,
185.77,4.67659,26.8021,7,,,,,,,,,,,,,,,,,,,,,,,,,,,,,,,,,,,,,
186.57,4.80992,33.54385,7,,,,,,,,,,,,,,,,,,,,,,,,,,,,,,,,,,,,,
187.252,4.9236,40.02517,7.5,,,,,,,,,,,,,,,,,,,,,,,,,,,,,,,,,,,,,
188.052,4.79032,31.101,7.5,,,,,,,,,,,,,,,,,,,,,,,,,,,,,,,,,,,,,
188.852,4.65698,24.01379,7.5,,,,,,,,,,,,,,,,,,,,,,,,,,,,,,,,,,,,,
189.652,4.52364,18.41812,7.5,,,,,,,,,,,,,,,,,,,,,,,,,,,,,,,,,,,,,
190.452,4.39019,14.03152,7.5,,,,,,,,,,,,,,,,,,,,,,,,,,,,,,,,,,,,,
191.252,4.25697,10.93125,7.5,,,,,,,,,,,,,,,,,,,,,,,,,,,,,,,,,,,,,
192.052,4.12363,8.54644,7.5,,,,,,,,,,,,,,,,,,,,,,,,,,,,,,,,,,,,,
192.852,3.99018,6.83273,7.5,,,,,,,,,,,,,,,,,,,,,,,,,,,,,,,,,,,,,
193.652,3.85702,5.62899,7.5,,,,,,,,,,,,,,,,,,,,,,,,,,,,,,,,,,,,,
194.452,3.72362,4.50391,7.5,,,,,,,,,,,,,,,,,,,,,,,,,,,,,,,,,,,,,
195.252,3.59017,3.51626,7.5,,,,,,,,,,,,,,,,,,,,,,,,,,,,,,,,,,,,,
196.052,3.45701,2.71754,7.5,,,,,,,,,,,,,,,,,,,,,,,,,,,,,,,,,,,,,
196.852,3.32361,2.07978,7.5,,,,,,,,,,,,,,,,,,,,,,,,,,,,,,,,,,,,,
197.652,3.19022,1.57321,7.5,,,,,,,,,,,,,,,,,,,,,,,,,,,,,,,,,,,,,
198.452,3.05694,1.20988,7.5,,,,,,,,,,,,,,,,,,,,,,,,,,,,,,,,,,,,,
199.05,2.98565,1.06832,8,,,,,,,,,,,,,,,,,,,,,,,,,,,,,,,,,,,,,
199.85,3.12454,1.56106,8,,,,,,,,,,,,,,,,,,,,,,,,,,,,,,,,,,,,,
200.65,3.25788,2.17453,8,,,,,,,,,,,,,,,,,,,,,,,,,,,,,,,,,,,,,
201.45,3.39139,3.0148,8,,,,,,,,,,,,,,,,,,,,,,,,,,,,,,,,,,,,,
202.25,3.52455,3.97619,8,,,,,,,,,,,,,,,,,,,,,,,,,,,,,,,,,,,,,
203.05,3.65795,5.07762,8,,,,,,,,,,,,,,,,,,,,,,,,,,,,,,,,,,,,,
203.85,3.79134,6.26366,8,,,,,,,,,,,,,,,,,,,,,,,,,,,,,,,,,,,,,
204.65,3.92451,7.96947,8,,,,,,,,,,,,,,,,,,,,,,,,,,,,,,,,,,,,,
205.45,4.05796,10.16177,8,,,,,,,,,,,,,,,,,,,,,,,,,,,,,,,,,,,,,
206.25,4.19129,12.48307,8,,,,,,,,,,,,,,,,,,,,,,,,,,,,,,,,,,,,,
207.05,4.32457,14.84805,8,,,,,,,,,,,,,,,,,,,,,,,,,,,,,,,,,,,,,
207.85,4.45802,17.62342,8,,,,,,,,,,,,,,,,,,,,,,,,,,,,,,,,,,,,,
208.65,4.5913,22.58592,8,,,,,,,,,,,,,,,,,,,,,,,,,,,,,,,,,,,,,
209.45,4.72447,28.63496,8,,,,,,,,,,,,,,,,,,,,,,,,,,,,,,,,,,,,,
210.25,4.85809,35.67262,8,,,,,,,,,,,,,,,,,,,,,,,,,,,,,,,,,,,,,
210.882,4.89708,37.90926,8.5,,,,,,,,,,,,,,,,,,,,,,,,,,,,,,,,,,,,,
211.682,4.7634,29.15521,8.5,,,,,,,,,,,,,,,,,,,,,,,,,,,,,,,,,,,,,
212.482,4.63001,22.45629,8.5,,,,,,,,,,,,,,,,,,,,,,,,,,,,,,,,,,,,,
213.282,4.49656,17.13934,8.5,,,,,,,,,,,,,,,,,,,,,,,,,,,,,,,,,,,,,
214.082,4.36328,13.21287,8.5,,,,,,,,,,,,,,,,,,,,,,,,,,,,,,,,,,,,,
214.882,4.23,10.20275,8.5,,,,,,,,,,,,,,,,,,,,,,,,,,,,,,,,,,,,,
215.682,4.09655,8.08973,8.5,,,,,,,,,,,,,,,,,,,,,,,,,,,,,,,,,,,,,
216.482,3.96327,6.40051,8.5,,,,,,,,,,,,,,,,,,,,,,,,,,,,,,,,,,,,,
217.282,3.82993,5.52346,8.5,,,,,,,,,,,,,,,,,,,,,,,,,,,,,,,,,,,,,
218.082,3.69659,4.28024,8.5,,,,,,,,,,,,,,,,,,,,,,,,,,,,,,,,,,,,,
218.882,3.5632,3.30724,8.5,,,,,,,,,,,,,,,,,,,,,,,,,,,,,,,,,,,,,
219.682,3.42992,2.60652,8.5,,,,,,,,,,,,,,,,,,,,,,,,,,,,,,,,,,,,,
220.482,3.29664,1.95673,8.5,,,,,,,,,,,,,,,,,,,,,,,,,,,,,,,,,,,,,
221.282,3.16319,1.53092,8.5,,,,,,,,,,,,,,,,,,,,,,,,,,,,,,,,,,,,,
222.082,3.02997,1.21154,8.5,,,,,,,,,,,,,,,,,,,,,,,,,,,,,,,,,,,,,
222.608,2.97064,0.95816,9,,,,,,,,,,,,,,,,,,,,,,,,,,,,,,,,,,,,,
223.408,3.10964,1.44356,9,,,,,,,,,,,,,,,,,,,,,,,,,,,,,,,,,,,,,
224.208,3.24286,2.05468,9,,,,,,,,,,,,,,,,,,,,,,,,,,,,,,,,,,,,,
225.008,3.37626,2.83847,9,,,,,,,,,,,,,,,,,,,,,,,,,,,,,,,,,,,,,
225.808,3.50959,3.78236,9,,,,,,,,,,,,,,,,,,,,,,,,,,,,,,,,,,,,,
226.608,3.64293,4.8602,9,,,,,,,,,,,,,,,,,,,,,,,,,,,,,,,,,,,,,
227.408,3.77632,6.12207,9,,,,,,,,,,,,,,,,,,,,,,,,,,,,,,,,,,,,,
228.208,3.9096,7.62919,9,,,,,,,,,,,,,,,,,,,,,,,,,,,,,,,,,,,,,
229.008,4.04283,9.80319,9,,,,,,,,,,,,,,,,,,,,,,,,,,,,,,,,,,,,,
229.808,4.17633,12.08465,9,,,,,,,,,,,,,,,,,,,,,,,,,,,,,,,,,,,,,
230.608,4.30967,14.01022,9,,,,,,,,,,,,,,,,,,,,,,,,,,,,,,,,,,,,,
231.408,4.44284,17.06138,9,,,,,,,,,,,,,,,,,,,,,,,,,,,,,,,,,,,,,
232.208,4.57634,21.71548,9,,,,,,,,,,,,,,,,,,,,,,,,,,,,,,,,,,,,,
233.008,4.70962,27.57546,9,,,,,,,,,,,,,,,,,,,,,,,,,,,,,,,,,,,,,
233.808,4.84279,34.45687,9,,,,,,,,,,,,,,,,,,,,,,,,,,,,,,,,,,,,,
234.474,4.92524,39.87981,9.5,,,,,,,,,,,,,,,,,,,,,,,,,,,,,,,,,,,,,
235.274,4.78731,30.1069,9.5,,,,,,,,,,,,,,,,,,,,,,,,,,,,,,,,,,,,,
236.074,4.65392,23.19225,9.5,,,,,,,,,,,,,,,,,,,,,,,,,,,,,,,,,,,,,
236.874,4.5207,17.74676,9.5,,,,,,,,,,,,,,,,,,,,,,,,,,,,,,,,,,,,,
237.674,4.38719,13.55508,9.5,,,,,,,,,,,,,,,,,,,,,,,,,,,,,,,,,,,,,
238.474,4.25391,10.58459,9.5,,,,,,,,,,,,,,,,,,,,,,,,,,,,,,,,,,,,,
239.274,4.12069,8.32461,9.5,,,,,,,,,,,,,,,,,,,,,,,,,,,,,,,,,,,,,
240.074,3.98718,6.6555,9.5,,,,,,,,,,,,,,,,,,,,,,,,,,,,,,,,,,,,,
240.874,3.85396,5.77885,9.5,,,,,,,,,,,,,,,,,,,,,,,,,,,,,,,,,,,,,
241.674,3.72068,4.47191,9.5,,,,,,,,,,,,,,,,,,,,,,,,,,,,,,,,,,,,,
242.474,3.58717,3.40592,9.5,,,,,,,,,,,,,,,,,,,,,,,,,,,,,,,,,,,,,
243.274,3.45395,2.61485,9.5,,,,,,,,,,,,,,,,,,,,,,,,,,,,,,,,,,,,,
244.074,3.32067,2.04384,9.5,,,,,,,,,,,,,,,,,,,,,,,,,,,,,,,,,,,,,
244.874,3.18722,1.56013,9.5,,,,,,,,,,,,,,,,,,,,,,,,,,,,,,,,,,,,,
245.674,3.05394,1.13604,9.5,,,,,,,,,,,,,,,,,,,,,,,,,,,,,,,,,,,,,
246.35,2.94621,0.92806,10,,,,,,,,,,,,,,,,,,,,,,,,,,,,,,,,,,,,,
247.15,2.9104,0.81951,10,,,,,,,,,,,,,,,,,,,,,,,,,,,,,,,,,,,,,
247.95,2.91114,0.8282,10,,,,,,,,,,,,,,,,,,,,,,,,,,,,,,,,,,,,,
248.75,2.91624,0.87204,10,,,,,,,,,,,,,,,,,,,,,,,,,,,,,,,,,,,,,
249.55,2.99965,1.0413,10,,,,,,,,,,,,,,,,,,,,,,,,,,,,,,,,,,,,,
250.35,3.09332,1.38571,10,,,,,,,,,,,,,,,,,,,,,,,,,,,,,,,,,,,,,
251.15,3.10318,1.42413,10,,,,,,,,,,,,,,,,,,,,,,,,,,,,,,,,,,,,,
251.95,3.09938,1.44932,10,,,,,,,,,,,,,,,,,,,,,,,,,,,,,,,,,,,,,
252.75,3.03716,1.22258,10,,,,,,,,,,,,,,,,,,,,,,,,,,,,,,,,,,,,,
253.55,2.96916,1.0283,10,,,,,,,,,,,,,,,,,,,,,,,,,,,,,,,,,,,,,
254.35,2.96072,0.96798,10,,,,,,,,,,,,,,,,,,,,,,,,,,,,,,,,,,,,,
255.15,2.961,1.04887,10,,,,,,,,,,,,,,,,,,,,,,,,,,,,,,,,,,,,,
255.95,2.96146,1.00928,10,,,,,,,,,,,,,,,,,,,,,,,,,,,,,,,,,,,,,
256.75,2.96361,0.99397,10,,,,,,,,,,,,,,,,,,,,,,,,,,,,,,,,,,,,,
257.55,2.9856,1.06756,10,,,,,,,,,,,,,,,,,,,,,,,,,,,,,,,,,,,,,
258.35,3.03852,1.22281,10,,,,,,,,,,,,,,,,,,,,,,,,,,,,,,,,,,,,,
259.15,3.0502,1.31052,10,,,,,,,,,,,,,,,,,,,,,,,,,,,,,,,,,,,,,
259.95,3.04997,1.29215,10,,,,,,,,,,,,,,,,,,,,,,,,,,,,,,,,,,,,,
260.75,3.04884,1.31371,10,,,,,,,,,,,,,,,,,,,,,,,,,,,,,,,,,,,,,
261.55,3.03818,1.26872,10,,,,,,,,,,,,,,,,,,,,,,,,,,,,,,,,,,,,,
262.35,2.99489,1.11297,10,,,,,,,,,,,,,,,,,,,,,,,,,,,,,,,,,,,,,
263.15,2.97987,1.18913,10,,,,,,,,,,,,,,,,,,,,,,,,,,,,,,,,,,,,,
263.95,2.97823,1.0481,10,,,,,,,,,,,,,,,,,,,,,,,,,,,,,,,,,,,,,
264.75,2.97823,1.07985,10,,,,,,,,,,,,,,,,,,,,,,,,,,,,,,,,,,,,,
265.55,2.9784,1.10724,10,,,,,,,,,,,,,,,,,,,,,,,,,,,,,,,,,,,,,
266.35,2.97851,1.08595,10,,,,,,,,,,,,,,,,,,,,,,,,,,,,,,,,,,,,,
267.15,2.97874,1.21542,10,,,,,,,,,,,,,,,,,,,,,,,,,,,,,,,,,,,,,
267.95,2.97902,1.08757,10,,,,,,,,,,,,,,,,,,,,,,,,,,,,,,,,,,,,,
268.75,2.97959,1.06075,10,,,,,,,,,,,,,,,,,,,,,,,,,,,,,,,,,,,,,
269.55,2.98157,1.04399,10,,,,,,,,,,,,,,,,,,,,,,,,,,,,,,,,,,,,,
270.35,2.9865,1.07615,10,,,,,,,,,,,,,,,,,,,,,,,,,,,,,,,,,,,,,
271.15,3.00849,1.1973,10,,,,,,,,,,,,,,,,,,,,,,,,,,,,,,,,,,,,,
271.95,3.01778,1.15703,10,,,,,,,,,,,,,,,,,,,,,,,,,,,,,,,,,,,,,
272.75,3.01818,1.19088,10,,,,,,,,,,,,,,,,,,,,,,,,,,,,,,,,,,,,,
273.55,3.01801,1.22484,10,,,,,,,,,,,,,,,,,,,,,,,,,,,,,,,,,,,,,
274.35,3.01784,1.20438,10,,,,,,,,,,,,,,,,,,,,,,,,,,,,,,,,,,,,,
275.15,3.0175,1.25371,10,,,,,,,,,,,,,,,,,,,,,,,,,,,,,,,,,,,,,
275.95,3.01512,1.24658,10,,,,,,,,,,,,,,,,,,,,,,,,,,,,,,,,,,,,,
276.75,3.00809,1.16933,10,,,,,,,,,,,,,,,,,,,,,,,,,,,,,,,,,,,,,
277.55,2.98769,1.11582,10,,,,,,,,,,,,,,,,,,,,,,,,,,,,,,,,,,,,,
278.35,2.97647,1.13521,10,,,,,,,,,,,,,,,,,,,,,,,,,,,,,,,,,,,,,
279.15,2.97024,1.13246,10,,,,,,,,,,,,,,,,,,,,,,,,,,,,,,,,,,,,,
279.95,2.96916,1.09317,10,,,,,,,,,,,,,,,,,,,,,,,,,,,,,,,,,,,,,
280.75,2.96922,1.08119,10,,,,,,,,,,,,,,,,,,,,,,,,,,,,,,,,,,,,,
281.55,2.96933,1.08497,10,,,,,,,,,,,,,,,,,,,,,,,,,,,,,,,,,,,,,
282.35,2.96945,1.10737,10,,,,,,,,,,,,,,,,,,,,,,,,,,,,,,,,,,,,,
283.15,2.9695,1.06183,10,,,,,,,,,,,,,,,,,,,,,,,,,,,,,,,,,,,,,
283.95,2.96967,1.06858,10,,,,,,,,,,,,,,,,,,,,,,,,,,,,,,,,,,,,,
284.75,2.97013,1.0941,10,,,,,,,,,,,,,,,,,,,,,,,,,,,,,,,,,,,,,
285.55,2.97086,1.07113,10,,,,,,,,,,,,,,,,,,,,,,,,,,,,,,,,,,,,,
286.35,2.97296,1.06628,10,,,,,,,,,,,,,,,,,,,,,,,,,,,,,,,,,,,,,
287.15,2.98282,1.14474,10,,,,,,,,,,,,,,,,,,,,,,,,,,,,,,,,,,,,,
287.95,3.00957,1.18822,10,,,,,,,,,,,,,,,,,,,,,,,,,,,,,,,,,,,,,
288.75,3.01597,1.2116,10,,,,,,,,,,,,,,,,,,,,,,,,,,,,,,,,,,,,,
289.55,3.0158,1.21933,10,,,,,,,,,,,,,,,,,,,,,,,,,,,,,,,,,,,,,
290.35,3.01552,1.21461,10,,,,,,,,,,,,,,,,,,,,,,,,,,,,,,,,,,,,,
291.15,3.01421,1.2399,10,,,,,,,,,,,,,,,,,,,,,,,,,,,,,,,,,,,,,
291.95,3.009,1.25892,10,,,,,,,,,,,,,,,,,,,,,,,,,,,,,,,,,,,,,
292.75,2.98288,1.14741,10,,,,,,,,,,,,,,,,,,,,,,,,,,,,,,,,,,,,,
293.55,2.96537,1.10397,10,,,,,,,,,,,,,,,,,,,,,,,,,,,,,,,,,,,,,
294.35,2.96372,1.11054,10,,,,,,,,,,,,,,,,,,,,,,,,,,,,,,,,,,,,,
295.15,2.96378,1.06487,10,,,,,,,,,,,,,,,,,,,,,,,,,,,,,,,,,,,,,
295.95,2.96389,1.11396,10,,,,,,,,,,,,,,,,,,,,,,,,,,,,,,,,,,,,,
296.75,2.96395,1.11947,10,,,,,,,,,,,,,,,,,,,,,,,,,,,,,,,,,,,,,
297.55,2.96412,1.09124,10,,,,,,,,,,,,,,,,,,,,,,,,,,,,,,,,,,,,,
298.35,2.96412,1.11877,10,,,,,,,,,,,,,,,,,,,,,,,,,,,,,,,,,,,,,
299.15,2.96435,1.06201,10,,,,,,,,,,,,,,,,,,,,,,,,,,,,,,,,,,,,,
299.95,2.96469,1.061,10,,,,,,,,,,,,,,,,,,,,,,,,,,,,,,,,,,,,,
300.75,2.96508,1.06567,10,,,,,,,,,,,,,,,,,,,,,,,,,,,,,,,,,,,,,
301.55,2.96571,1.13332,10,,,,,,,,,,,,,,,,,,,,,,,,,,,,,,,,,,,,,
302.35,2.96735,1.10945,10,,,,,,,,,,,,,,,,,,,,,,,,,,,,,,,,,,,,,
303.15,2.9703,1.10733,10,,,,,,,,,,,,,,,,,,,,,,,,,,,,,,,,,,,,,
303.95,2.97647,1.11642,10,,,,,,,,,,,,,,,,,,,,,,,,,,,,,,,,,,,,,
304.75,3.00231,1.1868,10,,,,,,,,,,,,,,,,,,,,,,,,,,,,,,,,,,,,,
305.55,3.01183,1.24855,10,,,,,,,,,,,,,,,,,,,,,,,,,,,,,,,,,,,,,
306.35,3.01172,1.22858,10,,,,,,,,,,,,,,,,,,,,,,,,,,,,,,,,,,,,,
307.15,3.01127,1.30481,10,,,,,,,,,,,,,,,,,,,,,,,,,,,,,,,,,,,,,
307.95,3.00809,1.28611,10,,,,,,,,,,,,,,,,,,,,,,,,,,,,,,,,,,,,,
308.75,2.98707,1.24026,10,,,,,,,,,,,,,,,,,,,,,,,,,,,,,,,,,,,,,
309.55,2.95942,1.15617,10,,,,,,,,,,,,,,,,,,,,,,,,,,,,,,,,,,,,,
310.35,2.95534,1.10055,10,,,,,,,,,,,,,,,,,,,,,,,,,,,,,,,,,,,,,
311.15,2.95477,1.11329,10,,,,,,,,,,,,,,,,,,,,,,,,,,,,,,,,,,,,,
311.95,2.95466,1.05626,10,,,,,,,,,,,,,,,,,,,,,,,,,,,,,,,,,,,,,
312.75,2.95483,1.0601,10,,,,,,,,,,,,,,,,,,,,,,,,,,,,,,,,,,,,,
313.55,2.95488,1.10298,10,,,,,,,,,,,,,,,,,,,,,,,,,,,,,,,,,,,,,
314.35,2.95505,1.11046,10,,,,,,,,,,,,,,,,,,,,,,,,,,,,,,,,,,,,,
315.15,2.95517,1.10812,10,,,,,,,,,,,,,,,,,,,,,,,,,,,,,,,,,,,,,
315.95,2.95551,1.09419,10,,,,,,,,,,,,,,,,,,,,,,,,,,,,,,,,,,,,,
316.75,2.95607,1.09543,10,,,,,,,,,,,,,,,,,,,,,,,,,,,,,,,,,,,,,
317.55,2.95687,1.07185,10,,,,,,,,,,,,,,,,,,,,,,,,,,,,,,,,,,,,,
318.35,2.9601,1.07451,10,,,,,,,,,,,,,,,,,,,,,,,,,,,,,,,,,,,,,
319.15,2.96724,1.10005,10,,,,,,,,,,,,,,,,,,,,,,,,,,,,,,,,,,,,,
319.95,2.9818,1.17844,10,,,,,,,,,,,,,,,,,,,,,,,,,,,,,,,,,,,,,
320.75,3.00084,1.22947,10,,,,,,,,,,,,,,,,,,,,,,,,,,,,,,,,,,,,,
321.55,3.00299,1.23332,10,,,,,,,,,,,,,,,,,,,,,,,,,,,,,,,,,,,,,
322.35,3.00277,1.21491,10,,,,,,,,,,,,,,,,,,,,,,,,,,,,,,,,,,,,,
323.15,3.00237,1.24252,10,,,,,,,,,,,,,,,,,,,,,,,,,,,,,,,,,,,,,
323.95,2.99931,1.23411,10,,,,,,,,,,,,,,,,,,,,,,,,,,,,,,,,,,,,,
324.75,2.98112,1.22328,10,,,,,,,,,,,,,,,,,,,,,,,,,,,,,,,,,,,,,
325.55,2.95704,1.15721,10,,,,,,,,,,,,,,,,,,,,,,,,,,,,,,,,,,,,,
326.35,2.95415,1.11907,10,,,,,,,,,,,,,,,,,,,,,,,,,,,,,,,,,,,,,
327.15,2.95352,1.08291,10,,,,,,,,,,,,,,,,,,,,,,,,,,,,,,,,,,,,,
327.95,2.95318,1.07072,10,,,,,,,,,,,,,,,,,,,,,,,,,,,,,,,,,,,,,
328.75,2.95318,1.07563,10,,,,,,,,,,,,,,,,,,,,,,,,,,,,,,,,,,,,,
329.55,2.9533,1.09365,10,,,,,,,,,,,,,,,,,,,,,,,,,,,,,,,,,,,,,
330.35,2.95335,1.07292,10,,,,,,,,,,,,,,,,,,,,,,,,,,,,,,,,,,,,,
331.15,2.95341,1.10346,10,,,,,,,,,,,,,,,,,,,,,,,,,,,,,,,,,,,,,
331.95,2.95341,1.12942,10,,,,,,,,,,,,,,,,,,,,,,,,,,,,,,,,,,,,,
332.75,2.95347,1.1114,10,,,,,,,,,,,,,,,,,,,,,,,,,,,,,,,,,,,,,
333.55,2.95352,1.17731,10,,,,,,,,,,,,,,,,,,,,,,,,,,,,,,,,,,,,,
334.35,2.95358,1.08562,10,,,,,,,,,,,,,,,,,,,,,,,,,,,,,,,,,,,,,
335.15,2.95375,1.11501,10,,,,,,,,,,,,,,,,,,,,,,,,,,,,,,,,,,,,,
335.95,2.95403,1.0575,10,,,,,,,,,,,,,,,,,,,,,,,,,,,,,,,,,,,,,
336.75,2.95449,1.08519,10,,,,,,,,,,,,,,,,,,,,,,,,,,,,,,,,,,,,,
337.55,2.95511,1.13355,10,,,,,,,,,,,,,,,,,,,,,,,,,,,,,,,,,,,,,
338.35,2.95658,1.12326,10,,,,,,,,,,,,,,,,,,,,,,,,,,,,,,,,,,,,,
339.15,2.95902,1.10832,10,,,,,,,,,,,,,,,,,,,,,,,,,,,,,,,,,,,,,
339.95,2.96157,1.13175,10,,,,,,,,,,,,,,,,,,,,,,,,,,,,,,,,,,,,,
340.75,2.96843,1.13838,10,,,,,,,,,,,,,,,,,,,,,,,,,,,,,,,,,,,,,
341.55,2.98078,1.18004,10,,,,,,,,,,,,,,,,,,,,,,,,,,,,,,,,,,,,,
342.35,2.98803,1.20484,10,,,,,,,,,,,,,,,,,,,,,,,,,,,,,,,,,,,,,
343.15,2.98826,1.26341,10,,,,,,,,,,,,,,,,,,,,,,,,,,,,,,,,,,,,,
343.95,2.98803,1.23238,10,,,,,,,,,,,,,,,,,,,,,,,,,,,,,,,,,,,,,
344.75,2.98775,1.21575,10,,,,,,,,,,,,,,,,,,,,,,,,,,,,,,,,,,,,,
345.55,2.98656,1.20454,10,,,,,,,,,,,,,,,,,,,,,,,,,,,,,,,,,,,,,
346.35,2.98072,1.20312,10,,,,,,,,,,,,,,,,,,,,,,,,,,,,,,,,,,,,,
347.15,2.95806,1.15241,10,,,,,,,,,,,,,,,,,,,,,,,,,,,,,,,,,,,,,
347.95,2.95369,1.13596,10,,,,,,,,,,,,,,,,,,,,,,,,,,,,,,,,,,,,,
348.75,2.95188,1.11487,10,,,,,,,,,,,,,,,,,,,,,,,,,,,,,,,,,,,,,
349.55,2.95131,1.14846,10,,,,,,,,,,,,,,,,,,,,,,,,,,,,,,,,,,,,,
350.35,2.95103,1.1534,10,,,,,,,,,,,,,,,,,,,,,,,,,,,,,,,,,,,,,
351.15,2.95086,1.12599,10,,,,,,,,,,,,,,,,,,,,,,,,,,,,,,,,,,,,,
351.95,2.95092,1.12083,10,,,,,,,,,,,,,,,,,,,,,,,,,,,,,,,,,,,,,
352.75,2.95092,1.12848,10,,,,,,,,,,,,,,,,,,,,,,,,,,,,,,,,,,,,,
353.55,2.95097,1.13754,10,,,,,,,,,,,,,,,,,,,,,,,,,,,,,,,,,,,,,
354.35,2.95103,1.13843,10,,,,,,,,,,,,,,,,,,,,,,,,,,,,,,,,,,,,,
355.15,2.95103,1.07889,10,,,,,,,,,,,,,,,,,,,,,,,,,,,,,,,,,,,,,
355.95,2.95109,1.10395,10,,,,,,,,,,,,,,,,,,,,,,,,,,,,,,,,,,,,,
356.75,2.95114,1.16136,10,,,,,,,,,,,,,,,,,,,,,,,,,,,,,,,,,,,,,
357.55,2.9512,1.0903,10,,,,,,,,,,,,,,,,,,,,,,,,,,,,,,,,,,,,,
358.35,2.95126,1.11776,10,,,,,,,,,,,,,,,,,,,,,,,,,,,,,,,,,,,,,
359.15,2.95137,1.1024,10,,,,,,,,,,,,,,,,,,,,,,,,,,,,,,,,,,,,,
359.95,2.9516,1.08944,10,,,,,,,,,,,,,,,,,,,,,,,,,,,,,,,,,,,,,
360.75,2.95188,1.06275,10,,,,,,,,,,,,,,,,,,,,,,,,,,,,,,,,,,,,,
361.55,2.95216,1.10405,10,,,,,,,,,,,,,,,,,,,,,,,,,,,,,,,,,,,,,
362.35,2.95279,1.19169,10,,,,,,,,,,,,,,,,,,,,,,,,,,,,,,,,,,,,,
363.15,2.95341,1.09243,10,,,,,,,,,,,,,,,,,,,,,,,,,,,,,,,,,,,,,
363.95,2.95556,1.10089,10,,,,,,,,,,,,,,,,,,,,,,,,,,,,,,,,,,,,,
364.75,2.95783,1.10896,10,,,,,,,,,,,,,,,,,,,,,,,,,,,,,,,,,,,,,
365.55,2.95987,1.16237,10,,,,,,,,,,,,,,,,,,,,,,,,,,,,,,,,,,,,,
366.35,2.96055,1.25606,10,,,,,,,,,,,,,,,,,,,,,,,,,,,,,,,,,,,,,
367.15,2.96083,1.09423,10,,,,,,,,,,,,,,,,,,,,,,,,,,,,,,,,,,,,,
367.95,2.961,1.13113,10,,,,,,,,,,,,,,,,,,,,,,,,,,,,,,,,,,,,,
368.75,2.96112,1.23518,10,,,,,,,,,,,,,,,,,,,,,,,,,,,,,,,,,,,,,
369.55,2.961,1.15196,10,,,,,,,,,,,,,,,,,,,,,,,,,,,,,,,,,,,,,
370.35,2.96095,1.22036,10,,,,,,,,,,,,,,,,,,,,,,,,,,,,,,,,,,,,,
371.15,2.961,1.18728,10,,,,,,,,,,,,,,,,,,,,,,,,,,,,,,,,,,,,,
371.95,2.96083,1.15935,10,,,,,,,,,,,,,,,,,,,,,,,,,,,,,,,,,,,,,
372.75,2.96078,1.12809,10,,,,,,,,,,,,,,,,,,,,,,,,,,,,,,,,,,,,,
373.55,2.96072,1.11411,10,,,,,,,,,,,,,,,,,,,,,,,,,,,,,,,,,,,,,
374.35,2.96061,1.18363,10,,,,,,,,,,,,,,,,,,,,,,,,,,,,,,,,,,,,,
375.15,2.96044,1.18902,10,,,,,,,,,,,,,,,,,,,,,,,,,,,,,,,,,,,,,
375.95,2.96021,1.17235,10,,,,,,,,,,,,,,,,,,,,,,,,,,,,,,,,,,,,,
376.75,2.95987,1.17769,10,,,,,,,,,,,,,,,,,,,,,,,,,,,,,,,,,,,,,
377.55,2.95908,1.1973,10,,,,,,,,,,,,,,,,,,,,,,,,,,,,,,,,,,,,,
378.35,2.95806,1.22556,10,,,,,,,,,,,,,,,,,,,,,,,,,,,,,,,,,,,,,
379.15,2.95664,1.1889,10,,,,,,,,,,,,,,,,,,,,,,,,,,,,,,,,,,,,,
379.95,2.95449,1.16568,10,,,,,,,,,,,,,,,,,,,,,,,,,,,,,,,,,,,,,
380.75,2.95256,1.19082,10,,,,,,,,,,,,,,,,,,,,,,,,,,,,,,,,,,,,,
381.55,2.95024,1.15842,10,,,,,,,,,,,,,,,,,,,,,,,,,,,,,,,,,,,,,
382.35,2.94797,1.16698,10,,,,,,,,,,,,,,,,,,,,,,,,,,,,,,,,,,,,,
383.15,2.94604,1.21734,10,,,,,,,,,,,,,,,,,,,,,,,,,,,,,,,,,,,,,
383.95,2.9431,1.17672,10,,,,,,,,,,,,,,,,,,,,,,,,,,,,,,,,,,,,,
384.75,2.94066,1.13783,10,,,,,,,,,,,,,,,,,,,,,,,,,,,,,,,,,,,,,
385.55,2.9397,1.10333,10,,,,,,,,,,,,,,,,,,,,,,,,,,,,,,,,,,,,,
386.35,2.9393,1.08441,10,,,,,,,,,,,,,,,,,,,,,,,,,,,,,,,,,,,,,
387.15,2.93902,1.13623,10,,,,,,,,,,,,,,,,,,,,,,,,,,,,,,,,,,,,,
387.95,2.93902,1.11214,10,,,,,,,,,,,,,,,,,,,,,,,,,,,,,,,,,,,,,
388.75,2.93907,1.09024,10,,,,,,,,,,,,,,,,,,,,,,,,,,,,,,,,,,,,,
389.55,2.93913,1.1445,10,,,,,,,,,,,,,,,,,,,,,,,,,,,,,,,,,,,,,
390.35,2.93919,1.06521,10,,,,,,,,,,,,,,,,,,,,,,,,,,,,,,,,,,,,,
391.15,2.9393,1.11503,10,,,,,,,,,,,,,,,,,,,,,,,,,,,,,,,,,,,,,
391.95,2.93936,1.12337,10,,,,,,,,,,,,,,,,,,,,,,,,,,,,,,,,,,,,,
392.75,2.93941,1.11162,10,,,,,,,,,,,,,,,,,,,,,,,,,,,,,,,,,,,,,
393.55,2.93964,1.07022,10,,,,,,,,,,,,,,,,,,,,,,,,,,,,,,,,,,,,,
394.35,2.93987,1.10544,10,,,,,,,,,,,,,,,,,,,,,,,,,,,,,,,,,,,,,
395.15,2.94021,1.1022,10,,,,,,,,,,,,,,,,,,,,,,,,,,,,,,,,,,,,,
395.95,2.94072,1.10174,10,,,,,,,,,,,,,,,,,,,,,,,,,,,,,,,,,,,,,
396.75,2.9423,1.07619,10,,,,,,,,,,,,,,,,,,,,,,,,,,,,,,,,,,,,,
397.55,2.94587,1.11693,10,,,,,,,,,,,,,,,,,,,,,,,,,,,,,,,,,,,,,
398.35,2.95687,1.13456,10,,,,,,,,,,,,,,,,,,,,,,,,,,,,,,,,,,,,,
399.15,2.96066,1.20497,10,,,,,,,,,,,,,,,,,,,,,,,,,,,,,,,,,,,,,
399.95,2.96083,1.17905,10,,,,,,,,,,,,,,,,,,,,,,,,,,,,,,,,,,,,,
400.75,2.96072,1.14133,10,,,,,,,,,,,,,,,,,,,,,,,,,,,,,,,,,,,,,
401.55,2.96066,1.14389,10,,,,,,,,,,,,,,,,,,,,,,,,,,,,,,,,,,,,,
402.35,2.96055,1.14435,10,,,,,,,,,,,,,,,,,,,,,,,,,,,,,,,,,,,,,
403.15,2.96038,1.16608,10,,,,,,,,,,,,,,,,,,,,,,,,,,,,,,,,,,,,,
403.95,2.9601,1.23712,10,,,,,,,,,,,,,,,,,,,,,,,,,,,,,,,,,,,,,
404.75,2.95913,1.22327,10,,,,,,,,,,,,,,,,,,,,,,,,,,,,,,,,,,,,,
405.55,2.95726,1.19186,10,,,,,,,,,,,,,,,,,,,,,,,,,,,,,,,,,,,,,
406.35,2.95454,1.19493,10,,,,,,,,,,,,,,,,,,,,,,,,,,,,,,,,,,,,,
407.15,2.94922,1.19219,10,,,,,,,,,,,,,,,,,,,,,,,,,,,,,,,,,,,,,
407.95,2.94446,1.1637,10,,,,,,,,,,,,,,,,,,,,,,,,,,,,,,,,,,,,,
408.75,2.941,1.14174,10,,,,,,,,,,,,,,,,,,,,,,,,,,,,,,,,,,,,,
409.55,2.93913,1.15157,10,,,,,,,,,,,,,,,,,,,,,,,,,,,,,,,,,,,,,
410.35,2.93777,1.1817,10,,,,,,,,,,,,,,,,,,,,,,,,,,,,,,,,,,,,,
411.15,2.93647,1.11462,10,,,,,,,,,,,,,,,,,,,,,,,,,,,,,,,,,,,,,
411.95,2.93573,1.15939,10,,,,,,,,,,,,,,,,,,,,,,,,,,,,,,,,,,,,,
412.75,2.93539,1.12731,10,,,,,,,,,,,,,,,,,,,,,,,,,,,,,,,,,,,,,
413.55,2.93522,1.16942,10,,,,,,,,,,,,,,,,,,,,,,,,,,,,,,,,,,,,,
414.35,2.93511,1.10118,10,,,,,,,,,,,,,,,,,,,,,,,,,,,,,,,,,,,,,
415.15,2.93511,1.08988,10,,,,,,,,,,,,,,,,,,,,,,,,,,,,,,,,,,,,,
415.95,2.93522,1.09963,10,,,,,,,,,,,,,,,,,,,,,,,,,,,,,,,,,,,,,
416.75,2.93522,1.13977,10,,,,,,,,,,,,,,,,,,,,,,,,,,,,,,,,,,,,,
417.55,2.93528,1.11831,10,,,,,,,,,,,,,,,,,,,,,,,,,,,,,,,,,,,,,
418.35,2.93528,1.13265,10,,,,,,,,,,,,,,,,,,,,,,,,,,,,,,,,,,,,,
419.15,2.93528,1.17882,10,,,,,,,,,,,,,,,,,,,,,,,,,,,,,,,,,,,,,
419.95,2.93533,1.12036,10,,,,,,,,,,,,,,,,,,,,,,,,,,,,,,,,,,,,,
420.75,2.93539,1.11953,10,,,,,,,,,,,,,,,,,,,,,,,,,,,,,,,,,,,,,
421.55,2.93545,1.15462,10,,,,,,,,,,,,,,,,,,,,,,,,,,,,,,,,,,,,,
422.35,2.93545,1.15589,10,,,,,,,,,,,,,,,,,,,,,,,,,,,,,,,,,,,,,
423.15,2.9355,1.16556,10,,,,,,,,,,,,,,,,,,,,,,,,,,,,,,,,,,,,,
423.95,2.9355,1.15786,10,,,,,,,,,,,,,,,,,,,,,,,,,,,,,,,,,,,,,
424.75,2.93556,1.17517,10,,,,,,,,,,,,,,,,,,,,,,,,,,,,,,,,,,,,,
425.55,2.93562,1.15763,10,,,,,,,,,,,,,,,,,,,,,,,,,,,,,,,,,,,,,
426.35,2.93562,1.18666,10,,,,,,,,,,,,,,,,,,,,,,,,,,,,,,,,,,,,,
427.15,2.93562,1.10518,10,,,,,,,,,,,,,,,,,,,,,,,,,,,,,,,,,,,,,
427.95,2.93567,1.14764,10,,,,,,,,,,,,,,,,,,,,,,,,,,,,,,,,,,,,,
428.75,2.93567,1.12864,10,,,,,,,,,,,,,,,,,,,,,,,,,,,,,,,,,,,,,
429.55,2.93567,1.12849,10,,,,,,,,,,,,,,,,,,,,,,,,,,,,,,,,,,,,,
430.35,2.93567,1.12851,10,,,,,,,,,,,,,,,,,,,,,,,,,,,,,,,,,,,,,
431.15,2.93567,1.1799,10,,,,,,,,,,,,,,,,,,,,,,,,,,,,,,,,,,,,,
431.95,2.93567,1.11155,10,,,,,,,,,,,,,,,,,,,,,,,,,,,,,,,,,,,,,
432.75,2.93567,1.13908,10,,,,,,,,,,,,,,,,,,,,,,,,,,,,,,,,,,,,,
433.55,2.93567,1.14271,10,,,,,,,,,,,,,,,,,,,,,,,,,,,,,,,,,,,,,
434.35,2.93573,1.14178,10,,,,,,,,,,,,,,,,,,,,,,,,,,,,,,,,,,,,,
435.15,2.93584,1.09341,10,,,,,,,,,,,,,,,,,,,,,,,,,,,,,,,,,,,,,
435.95,2.93607,1.12168,10,,,,,,,,,,,,,,,,,,,,,,,,,,,,,,,,,,,,,
436.75,2.93635,1.14513,10,,,,,,,,,,,,,,,,,,,,,,,,,,,,,,,,,,,,,
437.55,2.93669,1.10596,10,,,,,,,,,,,,,,,,,,,,,,,,,,,,,,,,,,,,,
438.35,2.9372,1.09178,10,,,,,,,,,,,,,,,,,,,,,,,,,,,,,,,,,,,,,
439.15,2.93822,1.08324,10,,,,,,,,,,,,,,,,,,,,,,,,,,,,,,,,,,,,,
439.95,2.94026,1.10153,10,,,,,,,,,,,,,,,,,,,,,,,,,,,,,,,,,,,,,
440.75,2.94406,1.15492,10,,,,,,,,,,,,,,,,,,,,,,,,,,,,,,,,,,,,,
441.55,2.9516,1.13831,10,,,,,,,,,,,,,,,,,,,,,,,,,,,,,,,,,,,,,
442.35,2.95709,1.20974,10,,,,,,,,,,,,,,,,,,,,,,,,,,,,,,,,,,,,,
443.15,2.9576,1.15605,10,,,,,,,,,,,,,,,,,,,,,,,,,,,,,,,,,,,,,
443.95,2.95772,1.15057,10,,,,,,,,,,,,,,,,,,,,,,,,,,,,,,,,,,,,,
444.75,2.95755,1.21714,10,,,,,,,,,,,,,,,,,,,,,,,,,,,,,,,,,,,,,
445.55,2.95749,1.19463,10,,,,,,,,,,,,,,,,,,,,,,,,,,,,,,,,,,,,,
446.35,2.95738,1.18799,10,,,,,,,,,,,,,,,,,,,,,,,,,,,,,,,,,,,,,
447.15,2.95721,1.21723,10,,,,,,,,,,,,,,,,,,,,,,,,,,,,,,,,,,,,,
447.95,2.95664,1.2059,10,,,,,,,,,,,,,,,,,,,,,,,,,,,,,,,,,,,,,
448.75,2.955,1.27205,10,,,,,,,,,,,,,,,,,,,,,,,,,,,,,,,,,,,,,
449.55,2.95199,1.18949,10,,,,,,,,,,,,,,,,,,,,,,,,,,,,,,,,,,,,,
450.35,2.94644,1.18475,10,,,,,,,,,,,,,,,,,,,,,,,,,,,,,,,,,,,,,
451.15,2.94094,1.14959,10,,,,,,,,,,,,,,,,,,,,,,,,,,,,,,,,,,,,,
451.95,2.93919,1.16424,10,,,,,,,,,,,,,,,,,,,,,,,,,,,,,,,,,,,,,
452.75,2.93817,1.1692,10,,,,,,,,,,,,,,,,,,,,,,,,,,,,,,,,,,,,,
453.55,2.93743,1.15884,10,,,,,,,,,,,,,,,,,,,,,,,,,,,,,,,,,,,,,
454.35,2.93658,1.14976,10,,,,,,,,,,,,,,,,,,,,,,,,,,,,,,,,,,,,,
455.15,2.93539,1.1314,10,,,,,,,,,,,,,,,,,,,,,,,,,,,,,,,,,,,,,
455.95,2.93499,1.15855,10,,,,,,,,,,,,,,,,,,,,,,,,,,,,,,,,,,,,,
456.75,2.9346,1.1675,10,,,,,,,,,,,,,,,,,,,,,,,,,,,,,,,,,,,,,
457.55,2.93437,1.15383,10,,,,,,,,,,,,,,,,,,,,,,,,,,,,,,,,,,,,,
458.35,2.93409,1.15859,10,,,,,,,,,,,,,,,,,,,,,,,,,,,,,,,,,,,,,
459.15,2.93392,1.17194,10,,,,,,,,,,,,,,,,,,,,,,,,,,,,,,,,,,,,,
459.95,2.9338,1.12234,10,,,,,,,,,,,,,,,,,,,,,,,,,,,,,,,,,,,,,
460.75,2.93392,1.09251,10,,,,,,,,,,,,,,,,,,,,,,,,,,,,,,,,,,,,,
461.55,2.93397,1.194,10,,,,,,,,,,,,,,,,,,,,,,,,,,,,,,,,,,,,,
462.35,2.93397,1.18772,10,,,,,,,,,,,,,,,,,,,,,,,,,,,,,,,,,,,,,
463.15,2.93403,1.16199,10,,,,,,,,,,,,,,,,,,,,,,,,,,,,,,,,,,,,,
463.95,2.93403,1.16721,10,,,,,,,,,,,,,,,,,,,,,,,,,,,,,,,,,,,,,
464.75,2.93403,1.14993,10,,,,,,,,,,,,,,,,,,,,,,,,,,,,,,,,,,,,,
465.55,2.93403,1.18502,10,,,,,,,,,,,,,,,,,,,,,,,,,,,,,,,,,,,,,
466.35,2.93403,1.14111,10,,,,,,,,,,,,,,,,,,,,,,,,,,,,,,,,,,,,,
467.15,2.93403,1.16663,10,,,,,,,,,,,,,,,,,,,,,,,,,,,,,,,,,,,,,
467.95,2.93403,1.12333,10,,,,,,,,,,,,,,,,,,,,,,,,,,,,,,,,,,,,,
468.75,2.93403,1.16662,10,,,,,,,,,,,,,,,,,,,,,,,,,,,,,,,,,,,,,
469.55,2.93403,1.18445,10,,,,,,,,,,,,,,,,,,,,,,,,,,,,,,,,,,,,,
470.35,2.93403,1.15312,10,,,,,,,,,,,,,,,,,,,,,,,,,,,,,,,,,,,,,
471.15,2.93403,1.18416,10,,,,,,,,,,,,,,,,,,,,,,,,,,,,,,,,,,,,,
471.95,2.93403,1.13682,10,,,,,,,,,,,,,,,,,,,,,,,,,,,,,,,,,,,,,
472.75,2.93403,1.12084,10,,,,,,,,,,,,,,,,,,,,,,,,,,,,,,,,,,,,,
473.55,2.93403,1.18354,10,,,,,,,,,,,,,,,,,,,,,,,,,,,,,,,,,,,,,
474.35,2.93403,1.16855,10,,,,,,,,,,,,,,,,,,,,,,,,,,,,,,,,,,,,,
475.15,2.93403,1.17936,10,,,,,,,,,,,,,,,,,,,,,,,,,,,,,,,,,,,,,
475.95,2.93403,1.14326,10,,,,,,,,,,,,,,,,,,,,,,,,,,,,,,,,,,,,,
476.75,2.93403,1.17138,10,,,,,,,,,,,,,,,,,,,,,,,,,,,,,,,,,,,,,
477.55,2.93403,1.13341,10,,,,,,,,,,,,,,,,,,,,,,,,,,,,,,,,,,,,,
478.35,2.93403,1.15132,10,,,,,,,,,,,,,,,,,,,,,,,,,,,,,,,,,,,,,
479.15,2.93403,1.18088,10,,,,,,,,,,,,,,,,,,,,,,,,,,,,,,,,,,,,,
479.95,2.93403,1.15928,10,,,,,,,,,,,,,,,,,,,,,,,,,,,,,,,,,,,,,
480.75,2.93403,1.11726,10,,,,,,,,,,,,,,,,,,,,,,,,,,,,,,,,,,,,,
481.55,2.93403,1.16159,10,,,,,,,,,,,,,,,,,,,,,,,,,,,,,,,,,,,,,
482.35,2.93403,1.12938,10,,,,,,,,,,,,,,,,,,,,,,,,,,,,,,,,,,,,,
483.15,2.93403,1.16027,10,,,,,,,,,,,,,,,,,,,,,,,,,,,,,,,,,,,,,
483.95,2.93403,1.17024,10,,,,,,,,,,,,,,,,,,,,,,,,,,,,,,,,,,,,,
484.75,2.93403,1.13985,10,,,,,,,,,,,,,,,,,,,,,,,,,,,,,,,,,,,,,
485.55,2.93403,1.13851,10,,,,,,,,,,,,,,,,,,,,,,,,,,,,,,,,,,,,,
486.35,2.93403,1.15242,10,,,,,,,,,,,,,,,,,,,,,,,,,,,,,,,,,,,,,
487.15,2.93403,1.16348,10,,,,,,,,,,,,,,,,,,,,,,,,,,,,,,,,,,,,,
487.95,2.93403,1.1306,10,,,,,,,,,,,,,,,,,,,,,,,,,,,,,,,,,,,,,
488.75,2.93403,1.15176,10,,,,,,,,,,,,,,,,,,,,,,,,,,,,,,,,,,,,,
489.55,2.93403,1.15046,10,,,,,,,,,,,,,,,,,,,,,,,,,,,,,,,,,,,,,
490.35,2.93403,1.1601,10,,,,,,,,,,,,,,,,,,,,,,,,,,,,,,,,,,,,,
491.15,2.93403,1.1483,10,,,,,,,,,,,,,,,,,,,,,,,,,,,,,,,,,,,,,
491.95,2.93403,1.13315,10,,,,,,,,,,,,,,,,,,,,,,,,,,,,,,,,,,,,,
492.75,2.93403,1.10519,10,,,,,,,,,,,,,,,,,,,,,,,,,,,,,,,,,,,,,
493.55,2.93403,1.12907,10,,,,,,,,,,,,,,,,,,,,,,,,,,,,,,,,,,,,,
494.35,2.93403,1.16858,10,,,,,,,,,,,,,,,,,,,,,,,,,,,,,,,,,,,,,
495.15,2.93403,1.16,10,,,,,,,,,,,,,,,,,,,,,,,,,,,,,,,,,,,,,
495.95,2.93403,1.13974,10,,,,,,,,,,,,,,,,,,,,,,,,,,,,,,,,,,,,,
496.75,2.93403,1.13593,10,,,,,,,,,,,,,,,,,,,,,,,,,,,,,,,,,,,,,
497.55,2.93403,1.14918,10,,,,,,,,,,,,,,,,,,,,,,,,,,,,,,,,,,,,,
498.35,2.93403,1.149,10,,,,,,,,,,,,,,,,,,,,,,,,,,,,,,,,,,,,,
499.15,2.93403,1.11623,10,,,,,,,,,,,,,,,,,,,,,,,,,,,,,,,,,,,,,
499.95,2.93403,1.15373,10,,,,,,,,,,,,,,,,,,,,,,,,,,,,,,,,,,,,,
500.75,2.93403,1.13596,10,,,,,,,,,,,,,,,,,,,,,,,,,,,,,,,,,,,,,
501.55,2.93403,1.10884,10,,,,,,,,,,,,,,,,,,,,,,,,,,,,,,,,,,,,,
502.35,2.93403,1.14358,10,,,,,,,,,,,,,,,,,,,,,,,,,,,,,,,,,,,,,
503.15,2.93403,1.15338,10,,,,,,,,,,,,,,,,,,,,,,,,,,,,,,,,,,,,,
503.95,2.93403,1.14963,10,,,,,,,,,,,,,,,,,,,,,,,,,,,,,,,,,,,,,
504.75,2.93403,1.17865,10,,,,,,,,,,,,,,,,,,,,,,,,,,,,,,,,,,,,,
505.55,2.93403,1.18376,10,,,,,,,,,,,,,,,,,,,,,,,,,,,,,,,,,,,,,
506.35,2.93403,1.12802,10,,,,,,,,,,,,,,,,,,,,,,,,,,,,,,,,,,,,,
507.15,2.93403,1.12081,10,,,,,,,,,,,,,,,,,,,,,,,,,,,,,,,,,,,,,
507.95,2.93403,1.126,10,,,,,,,,,,,,,,,,,,,,,,,,,,,,,,,,,,,,,
508.75,2.93403,1.17516,10,,,,,,,,,,,,,,,,,,,,,,,,,,,,,,,,,,,,,
509.55,2.93403,1.09766,10,,,,,,,,,,,,,,,,,,,,,,,,,,,,,,,,,,,,,
510.35,2.93403,1.13331,10,,,,,,,,,,,,,,,,,,,,,,,,,,,,,,,,,,,,,
511.15,2.93403,1.17007,10,,,,,,,,,,,,,,,,,,,,,,,,,,,,,,,,,,,,,
511.95,2.93403,1.18255,10,,,,,,,,,,,,,,,,,,,,,,,,,,,,,,,,,,,,,
512.75,2.93403,1.12615,10,,,,,,,,,,,,,,,,,,,,,,,,,,,,,,,,,,,,,
513.55,2.93403,1.18782,10,,,,,,,,,,,,,,,,,,,,,,,,,,,,,,,,,,,,,
514.35,2.93403,1.17333,10,,,,,,,,,,,,,,,,,,,,,,,,,,,,,,,,,,,,,
515.15,2.93403,1.14416,10,,,,,,,,,,,,,,,,,,,,,,,,,,,,,,,,,,,,,
515.95,2.93403,1.13926,10,,,,,,,,,,,,,,,,,,,,,,,,,,,,,,,,,,,,,
516.75,2.93403,1.12493,10,,,,,,,,,,,,,,,,,,,,,,,,,,,,,,,,,,,,,
517.55,2.93403,1.12982,10,,,,,,,,,,,,,,,,,,,,,,,,,,,,,,,,,,,,,
518.35,2.93403,1.15101,10,,,,,,,,,,,,,,,,,,,,,,,,,,,,,,,,,,,,,
519.15,2.93403,1.14318,10,,,,,,,,,,,,,,,,,,,,,,,,,,,,,,,,,,,,,
519.95,2.93403,1.16338,10,,,,,,,,,,,,,,,,,,,,,,,,,,,,,,,,,,,,,
520.75,2.93403,1.09961,10,,,,,,,,,,,,,,,,,,,,,,,,,,,,,,,,,,,,,
521.55,2.93403,1.1719,10,,,,,,,,,,,,,,,,,,,,,,,,,,,,,,,,,,,,,
522.35,2.93403,1.11767,10,,,,,,,,,,,,,,,,,,,,,,,,,,,,,,,,,,,,,
523.15,2.93403,1.13201,10,,,,,,,,,,,,,,,,,,,,,,,,,,,,,,,,,,,,,
523.95,2.93403,1.11488,10,,,,,,,,,,,,,,,,,,,,,,,,,,,,,,,,,,,,,
524.75,2.93403,1.18348,10,,,,,,,,,,,,,,,,,,,,,,,,,,,,,,,,,,,,,
525.55,2.93403,1.16119,10,,,,,,,,,,,,,,,,,,,,,,,,,,,,,,,,,,,,,
526.35,2.93403,1.15786,10,,,,,,,,,,,,,,,,,,,,,,,,,,,,,,,,,,,,,
527.15,2.93403,1.11897,10,,,,,,,,,,,,,,,,,,,,,,,,,,,,,,,,,,,,,
527.95,2.93403,1.1636,10,,,,,,,,,,,,,,,,,,,,,,,,,,,,,,,,,,,,,
528.75,2.93403,1.14351,10,,,,,,,,,,,,,,,,,,,,,,,,,,,,,,,,,,,,,
529.55,2.93403,1.16182,10,,,,,,,,,,,,,,,,,,,,,,,,,,,,,,,,,,,,,
530.35,2.93403,1.1619,10,,,,,,,,,,,,,,,,,,,,,,,,,,,,,,,,,,,,,
531.15,2.93403,1.15861,10,,,,,,,,,,,,,,,,,,,,,,,,,,,,,,,,,,,,,
531.95,2.93403,1.14156,10,,,,,,,,,,,,,,,,,,,,,,,,,,,,,,,,,,,,,
532.75,2.93403,1.1294,10,,,,,,,,,,,,,,,,,,,,,,,,,,,,,,,,,,,,,
533.55,2.93403,1.13596,10,,,,,,,,,,,,,,,,,,,,,,,,,,,,,,,,,,,,,
534.35,2.93403,1.13453,10,,,,,,,,,,,,,,,,,,,,,,,,,,,,,,,,,,,,,
535.15,2.93403,1.09844,10,,,,,,,,,,,,,,,,,,,,,,,,,,,,,,,,,,,,,
535.95,2.93403,1.16632,10,,,,,,,,,,,,,,,,,,,,,,,,,,,,,,,,,,,,,
536.75,2.93403,1.13767,10,,,,,,,,,,,,,,,,,,,,,,,,,,,,,,,,,,,,,
537.55,2.93403,1.15567,10,,,,,,,,,,,,,,,,,,,,,,,,,,,,,,,,,,,,,
538.35,2.93403,1.15581,10,,,,,,,,,,,,,,,,,,,,,,,,,,,,,,,,,,,,,
539.15,2.93403,1.16951,10,,,,,,,,,,,,,,,,,,,,,,,,,,,,,,,,,,,,,
539.95,2.93403,1.13509,10,,,,,,,,,,,,,,,,,,,,,,,,,,,,,,,,,,,,,
540.75,2.93403,1.14239,10,,,,,,,,,,,,,,,,,,,,,,,,,,,,,,,,,,,,,
541.55,2.93403,1.1172,10,,,,,,,,,,,,,,,,,,,,,,,,,,,,,,,,,,,,,
542.35,2.93403,1.10462,10,,,,,,,,,,,,,,,,,,,,,,,,,,,,,,,,,,,,,
543.15,2.93403,1.15522,10,,,,,,,,,,,,,,,,,,,,,,,,,,,,,,,,,,,,,
543.95,2.93403,1.19032,10,,,,,,,,,,,,,,,,,,,,,,,,,,,,,,,,,,,,,
544.75,2.93414,1.11901,10,,,,,,,,,,,,,,,,,,,,,,,,,,,,,,,,,,,,,
545.55,2.93414,1.11898,10,,,,,,,,,,,,,,,,,,,,,,,,,,,,,,,,,,,,,
546.252,4.35999,15.82543,10,,,,,,,,,,,,,,,,,,,,,,,,,,,,,,,,,,,,,
547.052,11.0343,289.90649,10,,,,,,,,,,,,,,,,,,,,,,,,,,,,,,,,,,,,,
547.852,17.70091,30.05066,10,,,,,,,,,,,,,,,,,,,,,,,,,,,,,,,,,,,,,
548.652,24.36752,5.17837,10,,,,,,,,,,,,,,,,,,,,,,,,,,,,,,,,,,,,,
549.452,31.03424,2.11244,10,,,,,,,,,,,,,,,,,,,,,,,,,,,,,,,,,,,,,
550.252,37.7009,0.32955,10,,,,,,,,,,,,,,,,,,,,,,,,,,,,,,,,,,,,,
551.052,44.3675,0.28512,10,,,,,,,,,,,,,,,,,,,,,,,,,,,,,,,,,,,,,
551.852,51.03422,0.152,10,,,,,,,,,,,,,,,,,,,,,,,,,,,,,,,,,,,,,
552.652,57.70083,0.12912,10,,,,,,,,,,,,,,,,,,,,,,,,,,,,,,,,,,,,,
552.906,59.81756,0.14867,10,,,,,,,,,,,,,,,,,,,,,,,,,,,,,,,,,,,,,