File: combined_ligament_solver/data/processed/Data Sheet 3_S152718_LCL.csv
Specimen properties : Length,68,mm,Unnamed: 3,Unnamed: 4,Unnamed: 5,Unnamed: 6,Unnamed: 7,Unnamed: 8,Unnamed: 9,Unnamed: 10,Unnamed: 11,Stress-Strain,Unnamed: 13,Unnamed: 14,Unnamed: 15,Unnamed: 16,Unnamed: 17,Unnamed: 18,Unnamed: 19,Unnamed: 20,Unnamed: 21,Unnamed: 22,Unnamed: 23,Unnamed: 24,Unnamed: 25,Unnamed: 26,Unnamed: 27,Linear,Unnamed: 29,Unnamed: 30,Unnamed: 31,Unnamed: 32,Unnamed: 33,Modulus,Unnamed: 35,Failure,Unnamed: 37,Unnamed: 38,Unnamed: 39,Unnamed: 40
Cross Section Average,44.4595,mm2,,,,,,,,,,Polynomial Coefficients,,,,,,,,,,,,,,,,Force,,Stress,Extension,Strain,,Secant,Tangent,Load,Stress,Extension,Strain,Stiffness
Time,Extension,Load,Total cycle count,,,Extension,Load,Strain,Stress,E-tan,,X6,-20564643.09421048,,,,,,,,,Strain,Stress,E-tan,,,,(N),,(MPa),(mm),(%),,(MPa),(MPa),(N),(MPa),(mm),(%),(N/mm)
(s),(mm),(N),,,,(mm),(N),(mm/mm),(MPa),(MPa),,X5,6271750.193964083,,,,,,,,,(mm/mm),(MPa),(MPa),,,,238.98225269035066,,5.375279809497423,5.712000000000001,8.4,,63.99142630354074,102.91232627359105,121.30937,2.7087108491998335,3.84982,5.6615,41.83862967268043
0.7,0.21953,1.80766,0,,,6.34281,226.80142,0.081125,5.081478199260001,101.16128169352844,,,,,,,,,,,,0.007,0.05926865843555013,10.903646349811813,,,,,,,,,,,,,,,,
1.5,0.35275,2.87773,0,,,13.00959,242.46396,,,,,,,,,,,,,,,0.015,0.1986793437044591,23.29161627837238,,,,,,,,,,,,,,,,
2.3,0.48609,3.87046,0,,,19.67619,14.87164,,,,,,,,,,,,,,,0.023,0.4539294505624538,38.753781486214685,,,,,,,,,,,,,,,,
3.1,0.61959,4.9573,0,,,,,,,,,,,,,,,,,,,0.031,0.8329844652161047,53.880950849604034,,,,,,,,,,,,,,,,
3.9,0.7527,6.22042,0,,,,,,,,,,,,,,,,,,,0.039,1.3245862832078903,66.98205289469799,,,,,,,,,,,,,,,,
4.7,0.8861,7.44488,0,,,,,,,,,,,,,,,,,,,0.047,1.9098148530066226,77.59895499561057,,,,,,,,,,,,,,,,
5.5,1.01949,8.58779,0,,,,,,,,,,,,,,,,,,,0.055,2.5697683731823875,86.02128257247479,,,,,,,,,,,,,,,,
6.3,1.15271,10.08484,0,,,,,,,,,,,,,,,,,,,0.063,3.289362043165991,92.8012382895104,,,,,,,,,,,,,,,,
7.1,1.28616,11.83912,0,,,,,,,,,,,,,,,,,,,0.071,4.057245367592928,98.26842125308261,,,,,,,,,,,,,,,,
7.9,1.4195,14.01105,0,,,,,,,,,,,,,,,,,,,0.079,4.861838014231855,102.04464620977117,,,,,,,,,,,,,,,,
8.7,1.55267,16.2546,0,,,,,,,,,,,,,,,,,,,0.087,5.683484225497564,102.55876274443388,,,,,,,,,,,,,,,,
9.5,1.68629,18.69822,0,,,,,,,,,,,,,,,,,,,0.095,,,,,,,,,,,,,,,,,,
10.3,1.81945,21.24629,0,,,,,,,,,,,,,,,,,,,0.103,,,,,,,,,,,,,,,,,,
11.1,1.95268,23.98026,0,,,,,,,,,,,,,,,,,,,0.111,,,,,,,,,,,,,,,,,,
11.9,2.08624,26.91337,0,,,,,,,,,,,,,,,,,,,0.119,,,,,,,,,,,,,,,,,,
12.7,2.21941,29.87627,0,,,,,,,,,,,,,,,,,,,0.127,,,,,,,,,,,,,,,,,,
13.5,2.35274,32.63803,0,,,,,,,,,,,,,,,,,,,0.135,,,,,,,,,,,,,,,,,,
14.3,2.48625,36.12913,0,,,,,,,,,,,,,,,,,,,0.143,,,,,,,,,,,,,,,,,,
15.1,2.61936,39.71416,0,,,,,,,,,,,,,,,,,,,0.151,,,,,,,,,,,,,,,,,,
15.776,2.53181,35.42828,0.5,,,,,,,,,,,,,,,,,,,0.159,,,,,,,,,,,,,,,,,,
16.576,2.39847,30.24558,0.5,,,,,,,,,,,,,,,,,,,0.167,,,,,,,,,,,,,,,,,,
17.376,2.26519,25.8392,0.5,,,,,,,,,,,,,,,,,,,0.175,,,,,,,,,,,,,,,,,,
18.176,2.13174,22.04854,0.5,,,,,,,,,,,,,,,,,,,0.183,,,,,,,,,,,,,,,,,,
18.976,1.99846,18.64663,0.5,,,,,,,,,,,,,,,,,,,0.191,,,,,,,,,,,,,,,,,,
19.776,1.86518,15.70311,0.5,,,,,,,,,,,,,,,,,,,0.199,,,,,,,,,,,,,,,,,,
20.576,1.73173,13.00196,0.5,,,,,,,,,,,,,,,,,,,,,,,,,,,,,,,,,,,,,
21.376,1.59851,10.77827,0.5,,,,,,,,,,,,,,,,,,,,,,,,,,,,,,,,,,,,,
22.176,1.46523,8.64987,0.5,,,,,,,,,,,,,,,,,,,,,,,,,,,,,,,,,,,,,
22.976,1.33167,6.93349,0.5,,,,,,,,,,,,,,,,,,,,,,,,,,,,,,,,,,,,,
23.776,1.1985,5.4867,0.5,,,,,,,,,,,,,,,,,,,,,,,,,,,,,,,,,,,,,
24.576,1.06522,4.18898,0.5,,,,,,,,,,,,,,,,,,,,,,,,,,,,,,,,,,,,,
25.376,0.93166,3.07091,0.5,,,,,,,,,,,,,,,,,,,,,,,,,,,,,,,,,,,,,
26.176,0.79849,2.07635,0.5,,,,,,,,,,,,,,,,,,,,,,,,,,,,,,,,,,,,,
26.976,0.66515,1.15562,0.5,,,,,,,,,,,,,,,,,,,,,,,,,,,,,,,,,,,,,
27.488,0.68068,1.44305,1,,,,,,,,,,,,,,,,,,,,,,,,,,,,,,,,,,,,,
28.288,0.81407,2.69315,1,,,,,,,,,,,,,,,,,,,,,,,,,,,,,,,,,,,,,
29.088,0.94741,3.99489,1,,,,,,,,,,,,,,,,,,,,,,,,,,,,,,,,,,,,,
29.888,1.0808,5.2481,1,,,,,,,,,,,,,,,,,,,,,,,,,,,,,,,,,,,,,
30.688,1.21408,6.69544,1,,,,,,,,,,,,,,,,,,,,,,,,,,,,,,,,,,,,,
31.488,1.34753,8.34619,1,,,,,,,,,,,,,,,,,,,,,,,,,,,,,,,,,,,,,
32.288,1.48081,10.25349,1,,,,,,,,,,,,,,,,,,,,,,,,,,,,,,,,,,,,,
33.088,1.61409,12.45621,1,,,,,,,,,,,,,,,,,,,,,,,,,,,,,,,,,,,,,
33.888,1.74749,14.86946,1,,,,,,,,,,,,,,,,,,,,,,,,,,,,,,,,,,,,,
34.688,1.88082,17.58851,1,,,,,,,,,,,,,,,,,,,,,,,,,,,,,,,,,,,,,
35.488,2.01405,20.55753,1,,,,,,,,,,,,,,,,,,,,,,,,,,,,,,,,,,,,,
36.288,2.1475,23.7443,1,,,,,,,,,,,,,,,,,,,,,,,,,,,,,,,,,,,,,
37.088,2.28078,27.3256,1,,,,,,,,,,,,,,,,,,,,,,,,,,,,,,,,,,,,,
37.888,2.41411,31.07234,1,,,,,,,,,,,,,,,,,,,,,,,,,,,,,,,,,,,,,
38.688,2.54751,34.76941,1,,,,,,,,,,,,,,,,,,,,,,,,,,,,,,,,,,,,,
39.488,2.68079,39.01123,1,,,,,,,,,,,,,,,,,,,,,,,,,,,,,,,,,,,,,
40.102,2.64951,36.91482,1.5,,,,,,,,,,,,,,,,,,,,,,,,,,,,,,,,,,,,,
40.902,2.51606,31.48121,1.5,,,,,,,,,,,,,,,,,,,,,,,,,,,,,,,,,,,,,
41.702,2.38289,26.90557,1.5,,,,,,,,,,,,,,,,,,,,,,,,,,,,,,,,,,,,,
42.502,2.24944,22.95505,1.5,,,,,,,,,,,,,,,,,,,,,,,,,,,,,,,,,,,,,
43.302,2.11605,19.44266,1.5,,,,,,,,,,,,,,,,,,,,,,,,,,,,,,,,,,,,,
44.102,1.98288,16.45566,1.5,,,,,,,,,,,,,,,,,,,,,,,,,,,,,,,,,,,,,
44.902,1.84937,13.65342,1.5,,,,,,,,,,,,,,,,,,,,,,,,,,,,,,,,,,,,,
45.702,1.71615,11.29828,1.5,,,,,,,,,,,,,,,,,,,,,,,,,,,,,,,,,,,,,
46.502,1.58287,9.12367,1.5,,,,,,,,,,,,,,,,,,,,,,,,,,,,,,,,,,,,,
47.302,1.44931,7.31179,1.5,,,,,,,,,,,,,,,,,,,,,,,,,,,,,,,,,,,,,
48.102,1.31614,5.73715,1.5,,,,,,,,,,,,,,,,,,,,,,,,,,,,,,,,,,,,,
48.902,1.18286,4.3996,1.5,,,,,,,,,,,,,,,,,,,,,,,,,,,,,,,,,,,,,
49.702,1.04935,3.31271,1.5,,,,,,,,,,,,,,,,,,,,,,,,,,,,,,,,,,,,,
50.502,0.91619,2.29626,1.5,,,,,,,,,,,,,,,,,,,,,,,,,,,,,,,,,,,,,
51.302,0.78285,1.36193,1.5,,,,,,,,,,,,,,,,,,,,,,,,,,,,,,,,,,,,,
51.86,0.75695,1.36058,2,,,,,,,,,,,,,,,,,,,,,,,,,,,,,,,,,,,,,
52.66,0.8908,2.5055,2,,,,,,,,,,,,,,,,,,,,,,,,,,,,,,,,,,,,,
53.46,1.02402,3.85463,2,,,,,,,,,,,,,,,,,,,,,,,,,,,,,,,,,,,,,
54.26,1.15742,5.15203,2,,,,,,,,,,,,,,,,,,,,,,,,,,,,,,,,,,,,,
55.06,1.29087,6.55107,2,,,,,,,,,,,,,,,,,,,,,,,,,,,,,,,,,,,,,
55.86,1.42403,8.2298,2,,,,,,,,,,,,,,,,,,,,,,,,,,,,,,,,,,,,,
56.66,1.55737,10.18188,2,,,,,,,,,,,,,,,,,,,,,,,,,,,,,,,,,,,,,
57.46,1.69088,12.3714,2,,,,,,,,,,,,,,,,,,,,,,,,,,,,,,,,,,,,,
58.26,1.82404,14.80794,2,,,,,,,,,,,,,,,,,,,,,,,,,,,,,,,,,,,,,
59.06,1.95744,17.53994,2,,,,,,,,,,,,,,,,,,,,,,,,,,,,,,,,,,,,,
59.86,2.09083,20.50015,2,,,,,,,,,,,,,,,,,,,,,,,,,,,,,,,,,,,,,
60.66,2.22405,23.76142,2,,,,,,,,,,,,,,,,,,,,,,,,,,,,,,,,,,,,,
61.46,2.3575,27.39099,2,,,,,,,,,,,,,,,,,,,,,,,,,,,,,,,,,,,,,
62.26,2.49078,31.24173,2,,,,,,,,,,,,,,,,,,,,,,,,,,,,,,,,,,,,,
63.06,2.62412,35.29065,2,,,,,,,,,,,,,,,,,,,,,,,,,,,,,,,,,,,,,
63.86,2.75746,39.48479,2,,,,,,,,,,,,,,,,,,,,,,,,,,,,,,,,,,,,,
64.548,2.67195,35.53355,2.5,,,,,,,,,,,,,,,,,,,,,,,,,,,,,,,,,,,,,
65.348,2.53855,30.39531,2.5,,,,,,,,,,,,,,,,,,,,,,,,,,,,,,,,,,,,,
66.148,2.40505,25.97609,2.5,,,,,,,,,,,,,,,,,,,,,,,,,,,,,,,,,,,,,
66.948,2.27182,22.09794,2.5,,,,,,,,,,,,,,,,,,,,,,,,,,,,,,,,,,,,,
67.748,2.13849,18.68127,2.5,,,,,,,,,,,,,,,,,,,,,,,,,,,,,,,,,,,,,
68.548,2.00509,15.6794,2.5,,,,,,,,,,,,,,,,,,,,,,,,,,,,,,,,,,,,,
69.348,1.87181,12.99922,2.5,,,,,,,,,,,,,,,,,,,,,,,,,,,,,,,,,,,,,
70.148,1.73842,10.73006,2.5,,,,,,,,,,,,,,,,,,,,,,,,,,,,,,,,,,,,,
70.948,1.60514,8.65135,2.5,,,,,,,,,,,,,,,,,,,,,,,,,,,,,,,,,,,,,
71.748,1.4718,6.80341,2.5,,,,,,,,,,,,,,,,,,,,,,,,,,,,,,,,,,,,,
72.548,1.33841,5.34712,2.5,,,,,,,,,,,,,,,,,,,,,,,,,,,,,,,,,,,,,
73.348,1.20513,4.10439,2.5,,,,,,,,,,,,,,,,,,,,,,,,,,,,,,,,,,,,,
74.148,1.07185,2.98498,2.5,,,,,,,,,,,,,,,,,,,,,,,,,,,,,,,,,,,,,
74.948,0.93834,2.00987,2.5,,,,,,,,,,,,,,,,,,,,,,,,,,,,,,,,,,,,,
75.748,0.80518,1.17915,2.5,,,,,,,,,,,,,,,,,,,,,,,,,,,,,,,,,,,,,
76.272,0.8521,1.58541,3,,,,,,,,,,,,,,,,,,,,,,,,,,,,,,,,,,,,,
77.072,0.98543,2.93205,3,,,,,,,,,,,,,,,,,,,,,,,,,,,,,,,,,,,,,
77.872,1.11883,4.17538,3,,,,,,,,,,,,,,,,,,,,,,,,,,,,,,,,,,,,,
78.672,1.25205,5.42786,3,,,,,,,,,,,,,,,,,,,,,,,,,,,,,,,,,,,,,
79.472,1.38544,6.9626,3,,,,,,,,,,,,,,,,,,,,,,,,,,,,,,,,,,,,,
80.272,1.51884,8.68063,3,,,,,,,,,,,,,,,,,,,,,,,,,,,,,,,,,,,,,
81.072,1.65206,10.69976,3,,,,,,,,,,,,,,,,,,,,,,,,,,,,,,,,,,,,,
81.872,1.7854,13.00641,3,,,,,,,,,,,,,,,,,,,,,,,,,,,,,,,,,,,,,
82.672,1.91885,15.48659,3,,,,,,,,,,,,,,,,,,,,,,,,,,,,,,,,,,,,,
83.472,2.05207,18.41235,3,,,,,,,,,,,,,,,,,,,,,,,,,,,,,,,,,,,,,
84.272,2.18546,21.44538,3,,,,,,,,,,,,,,,,,,,,,,,,,,,,,,,,,,,,,
85.072,2.3188,24.87548,3,,,,,,,,,,,,,,,,,,,,,,,,,,,,,,,,,,,,,
85.872,2.45214,28.65343,3,,,,,,,,,,,,,,,,,,,,,,,,,,,,,,,,,,,,,
86.672,2.58547,32.69289,3,,,,,,,,,,,,,,,,,,,,,,,,,,,,,,,,,,,,,
87.472,2.71881,37.05927,3,,,,,,,,,,,,,,,,,,,,,,,,,,,,,,,,,,,,,
88.098,2.79401,39.79001,3.5,,,,,,,,,,,,,,,,,,,,,,,,,,,,,,,,,,,,,
88.898,2.65619,33.53537,3.5,,,,,,,,,,,,,,,,,,,,,,,,,,,,,,,,,,,,,
89.698,2.52274,28.74053,3.5,,,,,,,,,,,,,,,,,,,,,,,,,,,,,,,,,,,,,
90.498,2.38952,24.48858,3.5,,,,,,,,,,,,,,,,,,,,,,,,,,,,,,,,,,,,,
91.298,2.25613,20.78689,3.5,,,,,,,,,,,,,,,,,,,,,,,,,,,,,,,,,,,,,
92.098,2.12273,17.52909,3.5,,,,,,,,,,,,,,,,,,,,,,,,,,,,,,,,,,,,,
92.898,1.98951,14.68958,3.5,,,,,,,,,,,,,,,,,,,,,,,,,,,,,,,,,,,,,
93.698,1.85617,12.10211,3.5,,,,,,,,,,,,,,,,,,,,,,,,,,,,,,,,,,,,,
94.498,1.72278,9.86762,3.5,,,,,,,,,,,,,,,,,,,,,,,,,,,,,,,,,,,,,
95.298,1.5895,7.90198,3.5,,,,,,,,,,,,,,,,,,,,,,,,,,,,,,,,,,,,,
96.098,1.45616,6.18925,3.5,,,,,,,,,,,,,,,,,,,,,,,,,,,,,,,,,,,,,
96.898,1.32277,4.82406,3.5,,,,,,,,,,,,,,,,,,,,,,,,,,,,,,,,,,,,,
97.698,1.18943,3.64325,3.5,,,,,,,,,,,,,,,,,,,,,,,,,,,,,,,,,,,,,
98.498,1.0561,2.54972,3.5,,,,,,,,,,,,,,,,,,,,,,,,,,,,,,,,,,,,,
99.298,0.92276,1.60241,3.5,,,,,,,,,,,,,,,,,,,,,,,,,,,,,,,,,,,,,
99.972,0.81045,0.98205,4,,,,,,,,,,,,,,,,,,,,,,,,,,,,,,,,,,,,,
100.674,0.92769,1.95856,4,,,,,,,,,,,,,,,,,,,,,,,,,,,,,,,,,,,,,
101.474,1.0612,3.32932,4,,,,,,,,,,,,,,,,,,,,,,,,,,,,,,,,,,,,,
102.274,1.19436,4.57769,4,,,,,,,,,,,,,,,,,,,,,,,,,,,,,,,,,,,,,
103.074,1.3277,5.94231,4,,,,,,,,,,,,,,,,,,,,,,,,,,,,,,,,,,,,,
103.874,1.46121,7.55024,4,,,,,,,,,,,,,,,,,,,,,,,,,,,,,,,,,,,,,
104.674,1.59437,9.24552,4,,,,,,,,,,,,,,,,,,,,,,,,,,,,,,,,,,,,,
105.474,1.72771,11.39426,4,,,,,,,,,,,,,,,,,,,,,,,,,,,,,,,,,,,,,
106.274,1.86127,13.8036,4,,,,,,,,,,,,,,,,,,,,,,,,,,,,,,,,,,,,,
107.074,1.99438,16.36096,4,,,,,,,,,,,,,,,,,,,,,,,,,,,,,,,,,,,,,
107.874,2.12772,19.32401,4,,,,,,,,,,,,,,,,,,,,,,,,,,,,,,,,,,,,,
108.674,2.26123,22.53425,4,,,,,,,,,,,,,,,,,,,,,,,,,,,,,,,,,,,,,
109.474,2.39434,26.13564,4,,,,,,,,,,,,,,,,,,,,,,,,,,,,,,,,,,,,,
110.274,2.52779,30.05587,4,,,,,,,,,,,,,,,,,,,,,,,,,,,,,,,,,,,,,
111.074,2.66118,34.23885,4,,,,,,,,,,,,,,,,,,,,,,,,,,,,,,,,,,,,,
111.874,2.7944,38.74475,4,,,,,,,,,,,,,,,,,,,,,,,,,,,,,,,,,,,,,
112.48,2.76193,37.04957,4.5,,,,,,,,,,,,,,,,,,,,,,,,,,,,,,,,,,,,,
113.28,2.62843,31.6372,4.5,,,,,,,,,,,,,,,,,,,,,,,,,,,,,,,,,,,,,
114.08,2.49515,27.0277,4.5,,,,,,,,,,,,,,,,,,,,,,,,,,,,,,,,,,,,,
114.88,2.36181,23.04267,4.5,,,,,,,,,,,,,,,,,,,,,,,,,,,,,,,,,,,,,
115.68,2.22847,19.50113,4.5,,,,,,,,,,,,,,,,,,,,,,,,,,,,,,,,,,,,,
116.48,2.09514,16.35583,4.5,,,,,,,,,,,,,,,,,,,,,,,,,,,,,,,,,,,,,
117.28,1.9618,13.59492,4.5,,,,,,,,,,,,,,,,,,,,,,,,,,,,,,,,,,,,,
118.08,1.82841,11.20068,4.5,,,,,,,,,,,,,,,,,,,,,,,,,,,,,,,,,,,,,
118.88,1.69518,9.05511,4.5,,,,,,,,,,,,,,,,,,,,,,,,,,,,,,,,,,,,,
119.68,1.56179,7.21796,4.5,,,,,,,,,,,,,,,,,,,,,,,,,,,,,,,,,,,,,
120.48,1.42845,5.70013,4.5,,,,,,,,,,,,,,,,,,,,,,,,,,,,,,,,,,,,,
121.28,1.29517,4.28083,4.5,,,,,,,,,,,,,,,,,,,,,,,,,,,,,,,,,,,,,
122.08,1.16167,3.16942,4.5,,,,,,,,,,,,,,,,,,,,,,,,,,,,,,,,,,,,,
122.88,1.02856,2.1862,4.5,,,,,,,,,,,,,,,,,,,,,,,,,,,,,,,,,,,,,
123.68,0.89516,1.32128,4.5,,,,,,,,,,,,,,,,,,,,,,,,,,,,,,,,,,,,,
124.21,0.87386,1.24324,5,,,,,,,,,,,,,,,,,,,,,,,,,,,,,,,,,,,,,
125.01,1.00787,2.53602,5,,,,,,,,,,,,,,,,,,,,,,,,,,,,,,,,,,,,,
125.81,1.14098,3.85481,5,,,,,,,,,,,,,,,,,,,,,,,,,,,,,,,,,,,,,
126.61,1.27438,5.07129,5,,,,,,,,,,,,,,,,,,,,,,,,,,,,,,,,,,,,,
127.41,1.40794,6.56486,5,,,,,,,,,,,,,,,,,,,,,,,,,,,,,,,,,,,,,
128.21,1.54105,8.19082,5,,,,,,,,,,,,,,,,,,,,,,,,,,,,,,,,,,,,,
129.01,1.6745,10.13072,5,,,,,,,,,,,,,,,,,,,,,,,,,,,,,,,,,,,,,
129.81,1.80778,12.32572,5,,,,,,,,,,,,,,,,,,,,,,,,,,,,,,,,,,,,,
130.61,1.941,14.80554,5,,,,,,,,,,,,,,,,,,,,,,,,,,,,,,,,,,,,,
131.41,2.07445,17.6013,5,,,,,,,,,,,,,,,,,,,,,,,,,,,,,,,,,,,,,
132.21,2.20785,20.67959,5,,,,,,,,,,,,,,,,,,,,,,,,,,,,,,,,,,,,,
133.01,2.34101,24.06294,5,,,,,,,,,,,,,,,,,,,,,,,,,,,,,,,,,,,,,
133.81,2.47446,27.82102,5,,,,,,,,,,,,,,,,,,,,,,,,,,,,,,,,,,,,,
134.61,2.6078,31.65734,5,,,,,,,,,,,,,,,,,,,,,,,,,,,,,,,,,,,,,
135.41,2.74102,35.99639,5,,,,,,,,,,,,,,,,,,,,,,,,,,,,,,,,,,,,,
136.074,2.85181,40.01451,5.5,,,,,,,,,,,,,,,,,,,,,,,,,,,,,,,,,,,,,
136.874,2.71824,34.29148,5.5,,,,,,,,,,,,,,,,,,,,,,,,,,,,,,,,,,,,,
137.674,2.58474,29.31223,5.5,,,,,,,,,,,,,,,,,,,,,,,,,,,,,,,,,,,,,
138.474,2.4514,25.04436,5.5,,,,,,,,,,,,,,,,,,,,,,,,,,,,,,,,,,,,,
139.274,2.31823,21.21024,5.5,,,,,,,,,,,,,,,,,,,,,,,,,,,,,,,,,,,,,
140.074,2.18473,17.94061,5.5,,,,,,,,,,,,,,,,,,,,,,,,,,,,,,,,,,,,,
140.874,2.05145,14.99262,5.5,,,,,,,,,,,,,,,,,,,,,,,,,,,,,,,,,,,,,
141.674,1.91822,12.36204,5.5,,,,,,,,,,,,,,,,,,,,,,,,,,,,,,,,,,,,,
142.474,1.78477,10.05916,5.5,,,,,,,,,,,,,,,,,,,,,,,,,,,,,,,,,,,,,
143.274,1.65149,8.13656,5.5,,,,,,,,,,,,,,,,,,,,,,,,,,,,,,,,,,,,,
144.074,1.51821,6.43762,5.5,,,,,,,,,,,,,,,,,,,,,,,,,,,,,,,,,,,,,
144.874,1.38465,4.99852,5.5,,,,,,,,,,,,,,,,,,,,,,,,,,,,,,,,,,,,,
145.674,1.25148,3.75252,5.5,,,,,,,,,,,,,,,,,,,,,,,,,,,,,,,,,,,,,
146.474,1.11815,2.73058,5.5,,,,,,,,,,,,,,,,,,,,,,,,,,,,,,,,,,,,,
147.274,0.98464,1.74368,5.5,,,,,,,,,,,,,,,,,,,,,,,,,,,,,,,,,,,,,
148.074,0.85159,1.02499,5.5,,,,,,,,,,,,,,,,,,,,,,,,,,,,,,,,,,,,,
148.596,0.93205,1.65437,6,,,,,,,,,,,,,,,,,,,,,,,,,,,,,,,,,,,,,
149.396,1.0655,2.96305,6,,,,,,,,,,,,,,,,,,,,,,,,,,,,,,,,,,,,,
150.196,1.19873,4.24462,6,,,,,,,,,,,,,,,,,,,,,,,,,,,,,,,,,,,,,
150.996,1.33206,5.54939,6,,,,,,,,,,,,,,,,,,,,,,,,,,,,,,,,,,,,,
151.796,1.46551,6.97148,6,,,,,,,,,,,,,,,,,,,,,,,,,,,,,,,,,,,,,
152.596,1.59874,8.71017,6,,,,,,,,,,,,,,,,,,,,,,,,,,,,,,,,,,,,,
153.396,1.73213,10.72982,6,,,,,,,,,,,,,,,,,,,,,,,,,,,,,,,,,,,,,
154.196,1.86547,13.04279,6,,,,,,,,,,,,,,,,,,,,,,,,,,,,,,,,,,,,,
154.996,1.99875,15.57383,6,,,,,,,,,,,,,,,,,,,,,,,,,,,,,,,,,,,,,
155.796,2.13208,18.49819,6,,,,,,,,,,,,,,,,,,,,,,,,,,,,,,,,,,,,,
156.596,2.26548,21.63724,6,,,,,,,,,,,,,,,,,,,,,,,,,,,,,,,,,,,,,
157.396,2.39881,25.15693,6,,,,,,,,,,,,,,,,,,,,,,,,,,,,,,,,,,,,,
158.196,2.53215,28.98948,6,,,,,,,,,,,,,,,,,,,,,,,,,,,,,,,,,,,,,
158.996,2.66543,32.93,6,,,,,,,,,,,,,,,,,,,,,,,,,,,,,,,,,,,,,
159.796,2.79877,37.49737,6,,,,,,,,,,,,,,,,,,,,,,,,,,,,,,,,,,,,,
160.424,2.83702,38.70423,6.5,,,,,,,,,,,,,,,,,,,,,,,,,,,,,,,,,,,,,
161.224,2.70317,32.9811,6.5,,,,,,,,,,,,,,,,,,,,,,,,,,,,,,,,,,,,,
162.024,2.56978,28.19598,6.5,,,,,,,,,,,,,,,,,,,,,,,,,,,,,,,,,,,,,
162.824,2.43655,23.99377,6.5,,,,,,,,,,,,,,,,,,,,,,,,,,,,,,,,,,,,,
163.624,2.30305,20.32606,6.5,,,,,,,,,,,,,,,,,,,,,,,,,,,,,,,,,,,,,
164.424,2.16977,17.14474,6.5,,,,,,,,,,,,,,,,,,,,,,,,,,,,,,,,,,,,,
165.224,2.03654,14.28446,6.5,,,,,,,,,,,,,,,,,,,,,,,,,,,,,,,,,,,,,
166.024,1.90304,11.77649,6.5,,,,,,,,,,,,,,,,,,,,,,,,,,,,,,,,,,,,,
166.824,1.76981,9.56251,6.5,,,,,,,,,,,,,,,,,,,,,,,,,,,,,,,,,,,,,
167.624,1.63648,7.64817,6.5,,,,,,,,,,,,,,,,,,,,,,,,,,,,,,,,,,,,,
168.424,1.50314,6.04474,6.5,,,,,,,,,,,,,,,,,,,,,,,,,,,,,,,,,,,,,
169.224,1.3698,4.67102,6.5,,,,,,,,,,,,,,,,,,,,,,,,,,,,,,,,,,,,,
170.024,1.23652,3.4463,6.5,,,,,,,,,,,,,,,,,,,,,,,,,,,,,,,,,,,,,
170.824,1.10296,2.35757,6.5,,,,,,,,,,,,,,,,,,,,,,,,,,,,,,,,,,,,,
171.624,0.96985,1.47089,6.5,,,,,,,,,,,,,,,,,,,,,,,,,,,,,,,,,,,,,
172.176,0.87765,0.98578,7,,,,,,,,,,,,,,,,,,,,,,,,,,,,,,,,,,,,,
172.976,1.01218,2.20654,7,,,,,,,,,,,,,,,,,,,,,,,,,,,,,,,,,,,,,
173.776,1.1454,3.53775,7,,,,,,,,,,,,,,,,,,,,,,,,,,,,,,,,,,,,,
174.576,1.27874,4.72133,7,,,,,,,,,,,,,,,,,,,,,,,,,,,,,,,,,,,,,
175.376,1.41219,6.1757,7,,,,,,,,,,,,,,,,,,,,,,,,,,,,,,,,,,,,,
176.176,1.54541,7.81228,7,,,,,,,,,,,,,,,,,,,,,,,,,,,,,,,,,,,,,
176.976,1.67881,9.60223,7,,,,,,,,,,,,,,,,,,,,,,,,,,,,,,,,,,,,,
177.776,1.81214,11.7987,7,,,,,,,,,,,,,,,,,,,,,,,,,,,,,,,,,,,,,
178.576,1.94542,14.16874,7,,,,,,,,,,,,,,,,,,,,,,,,,,,,,,,,,,,,,
179.376,2.07876,16.876,7,,,,,,,,,,,,,,,,,,,,,,,,,,,,,,,,,,,,,
180.176,2.2121,19.88435,7,,,,,,,,,,,,,,,,,,,,,,,,,,,,,,,,,,,,,
180.976,2.34543,23.26438,7,,,,,,,,,,,,,,,,,,,,,,,,,,,,,,,,,,,,,
181.776,2.47888,26.97046,7,,,,,,,,,,,,,,,,,,,,,,,,,,,,,,,,,,,,,
182.576,2.61205,30.74547,7,,,,,,,,,,,,,,,,,,,,,,,,,,,,,,,,,,,,,
183.376,2.74544,35.1013,7,,,,,,,,,,,,,,,,,,,,,,,,,,,,,,,,,,,,,
184.176,2.87884,39.89825,7,,,,,,,,,,,,,,,,,,,,,,,,,,,,,,,,,,,,,
184.8,2.78262,35.6484,7.5,,,,,,,,,,,,,,,,,,,,,,,,,,,,,,,,,,,,,
185.6,2.64917,30.45502,7.5,,,,,,,,,,,,,,,,,,,,,,,,,,,,,,,,,,,,,
186.4,2.51566,25.99376,7.5,,,,,,,,,,,,,,,,,,,,,,,,,,,,,,,,,,,,,
187.2,2.38249,22.11943,7.5,,,,,,,,,,,,,,,,,,,,,,,,,,,,,,,,,,,,,
188,2.24916,18.69339,7.5,,,,,,,,,,,,,,,,,,,,,,,,,,,,,,,,,,,,,
188.8,2.11576,15.60269,7.5,,,,,,,,,,,,,,,,,,,,,,,,,,,,,,,,,,,,,
189.6,1.98254,12.92574,7.5,,,,,,,,,,,,,,,,,,,,,,,,,,,,,,,,,,,,,
190.4,1.84903,10.54225,7.5,,,,,,,,,,,,,,,,,,,,,,,,,,,,,,,,,,,,,
191.2,1.71581,8.5063,7.5,,,,,,,,,,,,,,,,,,,,,,,,,,,,,,,,,,,,,
192,1.58253,6.81372,7.5,,,,,,,,,,,,,,,,,,,,,,,,,,,,,,,,,,,,,
192.8,1.44902,5.27427,7.5,,,,,,,,,,,,,,,,,,,,,,,,,,,,,,,,,,,,,
193.6,1.31586,3.95476,7.5,,,,,,,,,,,,,,,,,,,,,,,,,,,,,,,,,,,,,
194.4,1.18246,2.86445,7.5,,,,,,,,,,,,,,,,,,,,,,,,,,,,,,,,,,,,,
195.2,1.04884,1.89205,7.5,,,,,,,,,,,,,,,,,,,,,,,,,,,,,,,,,,,,,
196,0.9159,1.08742,7.5,,,,,,,,,,,,,,,,,,,,,,,,,,,,,,,,,,,,,
196.592,0.9847,1.73399,8,,,,,,,,,,,,,,,,,,,,,,,,,,,,,,,,,,,,,
197.392,1.11815,3.051,8,,,,,,,,,,,,,,,,,,,,,,,,,,,,,,,,,,,,,
198.192,1.25137,4.44975,8,,,,,,,,,,,,,,,,,,,,,,,,,,,,,,,,,,,,,
198.992,1.38471,5.69266,8,,,,,,,,,,,,,,,,,,,,,,,,,,,,,,,,,,,,,
199.792,1.51821,7.2018,8,,,,,,,,,,,,,,,,,,,,,,,,,,,,,,,,,,,,,
200.592,1.65138,9.0098,8,,,,,,,,,,,,,,,,,,,,,,,,,,,,,,,,,,,,,
201.392,1.78472,11.04465,8,,,,,,,,,,,,,,,,,,,,,,,,,,,,,,,,,,,,,
202.192,1.91817,13.41393,8,,,,,,,,,,,,,,,,,,,,,,,,,,,,,,,,,,,,,
202.992,2.05139,15.98133,8,,,,,,,,,,,,,,,,,,,,,,,,,,,,,,,,,,,,,
203.792,2.18478,18.89861,8,,,,,,,,,,,,,,,,,,,,,,,,,,,,,,,,,,,,,
204.592,2.31818,22.17492,8,,,,,,,,,,,,,,,,,,,,,,,,,,,,,,,,,,,,,
205.392,2.4514,25.7519,8,,,,,,,,,,,,,,,,,,,,,,,,,,,,,,,,,,,,,
206.192,2.58479,29.7296,8,,,,,,,,,,,,,,,,,,,,,,,,,,,,,,,,,,,,,
206.992,2.71813,33.72282,8,,,,,,,,,,,,,,,,,,,,,,,,,,,,,,,,,,,,,
207.792,2.85147,38.39605,8,,,,,,,,,,,,,,,,,,,,,,,,,,,,,,,,,,,,,
208.452,2.82789,37.17122,8.5,,,,,,,,,,,,,,,,,,,,,,,,,,,,,,,,,,,,,
209.252,2.69444,31.6914,8.5,,,,,,,,,,,,,,,,,,,,,,,,,,,,,,,,,,,,,
210.052,2.56116,27.02972,8.5,,,,,,,,,,,,,,,,,,,,,,,,,,,,,,,,,,,,,
210.852,2.42783,23.08736,8.5,,,,,,,,,,,,,,,,,,,,,,,,,,,,,,,,,,,,,
211.652,2.29432,19.44245,8.5,,,,,,,,,,,,,,,,,,,,,,,,,,,,,,,,,,,,,
212.452,2.16115,16.36538,8.5,,,,,,,,,,,,,,,,,,,,,,,,,,,,,,,,,,,,,
213.252,2.02787,13.56582,8.5,,,,,,,,,,,,,,,,,,,,,,,,,,,,,,,,,,,,,
214.052,1.89431,11.11907,8.5,,,,,,,,,,,,,,,,,,,,,,,,,,,,,,,,,,,,,
214.852,1.76114,8.91045,8.5,,,,,,,,,,,,,,,,,,,,,,,,,,,,,,,,,,,,,
215.652,1.62786,7.15843,8.5,,,,,,,,,,,,,,,,,,,,,,,,,,,,,,,,,,,,,
216.452,1.49441,5.6442,8.5,,,,,,,,,,,,,,,,,,,,,,,,,,,,,,,,,,,,,
217.252,1.36108,4.304,8.5,,,,,,,,,,,,,,,,,,,,,,,,,,,,,,,,,,,,,
218.052,1.2278,3.17903,8.5,,,,,,,,,,,,,,,,,,,,,,,,,,,,,,,,,,,,,
218.852,1.09457,2.09581,8.5,,,,,,,,,,,,,,,,,,,,,,,,,,,,,,,,,,,,,
219.652,0.96107,1.24588,8.5,,,,,,,,,,,,,,,,,,,,,,,,,,,,,,,,,,,,,
220.238,0.96441,1.40556,9,,,,,,,,,,,,,,,,,,,,,,,,,,,,,,,,,,,,,
221.038,1.09769,2.68672,9,,,,,,,,,,,,,,,,,,,,,,,,,,,,,,,,,,,,,
221.838,1.23114,4.02286,9,,,,,,,,,,,,,,,,,,,,,,,,,,,,,,,,,,,,,
222.638,1.36442,5.27201,9,,,,,,,,,,,,,,,,,,,,,,,,,,,,,,,,,,,,,
223.438,1.4977,6.7889,9,,,,,,,,,,,,,,,,,,,,,,,,,,,,,,,,,,,,,
224.238,1.63143,8.50822,9,,,,,,,,,,,,,,,,,,,,,,,,,,,,,,,,,,,,,
225.038,1.76443,10.46754,9,,,,,,,,,,,,,,,,,,,,,,,,,,,,,,,,,,,,,
225.838,1.89771,12.76764,9,,,,,,,,,,,,,,,,,,,,,,,,,,,,,,,,,,,,,
226.638,2.03127,15.2869,9,,,,,,,,,,,,,,,,,,,,,,,,,,,,,,,,,,,,,
227.438,2.16444,18.15222,9,,,,,,,,,,,,,,,,,,,,,,,,,,,,,,,,,,,,,
228.238,2.29772,21.38672,9,,,,,,,,,,,,,,,,,,,,,,,,,,,,,,,,,,,,,
229.038,2.43123,24.86164,9,,,,,,,,,,,,,,,,,,,,,,,,,,,,,,,,,,,,,
229.838,2.56439,28.69205,9,,,,,,,,,,,,,,,,,,,,,,,,,,,,,,,,,,,,,
230.638,2.69773,32.65971,9,,,,,,,,,,,,,,,,,,,,,,,,,,,,,,,,,,,,,
231.438,2.83124,37.22473,9,,,,,,,,,,,,,,,,,,,,,,,,,,,,,,,,,,,,,
232.098,2.8747,38.75957,9.5,,,,,,,,,,,,,,,,,,,,,,,,,,,,,,,,,,,,,
232.898,2.74074,32.95971,9.5,,,,,,,,,,,,,,,,,,,,,,,,,,,,,,,,,,,,,
233.698,2.60752,28.1611,9.5,,,,,,,,,,,,,,,,,,,,,,,,,,,,,,,,,,,,,
234.498,2.47412,24.00462,9.5,,,,,,,,,,,,,,,,,,,,,,,,,,,,,,,,,,,,,
235.298,2.34079,20.35208,9.5,,,,,,,,,,,,,,,,,,,,,,,,,,,,,,,,,,,,,
236.098,2.20756,17.1157,9.5,,,,,,,,,,,,,,,,,,,,,,,,,,,,,,,,,,,,,
236.898,2.074,14.2296,9.5,,,,,,,,,,,,,,,,,,,,,,,,,,,,,,,,,,,,,
237.698,1.94083,11.65525,9.5,,,,,,,,,,,,,,,,,,,,,,,,,,,,,,,,,,,,,
238.498,1.80755,9.54102,9.5,,,,,,,,,,,,,,,,,,,,,,,,,,,,,,,,,,,,,
239.298,1.67399,7.5779,9.5,,,,,,,,,,,,,,,,,,,,,,,,,,,,,,,,,,,,,
240.098,1.54099,5.99445,9.5,,,,,,,,,,,,,,,,,,,,,,,,,,,,,,,,,,,,,
240.898,1.40749,4.56141,9.5,,,,,,,,,,,,,,,,,,,,,,,,,,,,,,,,,,,,,
241.698,1.27404,3.40357,9.5,,,,,,,,,,,,,,,,,,,,,,,,,,,,,,,,,,,,,
242.498,1.14081,2.30811,9.5,,,,,,,,,,,,,,,,,,,,,,,,,,,,,,,,,,,,,
243.298,1.00742,1.40495,9.5,,,,,,,,,,,,,,,,,,,,,,,,,,,,,,,,,,,,,
244,0.89006,0.77941,10,,,,,,,,,,,,,,,,,,,,,,,,,,,,,,,,,,,,,
244.8,0.83334,0.5733,10,,,,,,,,,,,,,,,,,,,,,,,,,,,,,,,,,,,,,
245.6,0.83419,0.59577,10,,,,,,,,,,,,,,,,,,,,,,,,,,,,,,,,,,,,,
246.4,0.84207,0.64574,10,,,,,,,,,,,,,,,,,,,,,,,,,,,,,,,,,,,,,
247.2,0.88933,1.10747,10,,,,,,,,,,,,,,,,,,,,,,,,,,,,,,,,,,,,,
248,0.89278,1.16072,10,,,,,,,,,,,,,,,,,,,,,,,,,,,,,,,,,,,,,
248.8,0.88876,1.18019,10,,,,,,,,,,,,,,,,,,,,,,,,,,,,,,,,,,,,,
249.6,0.85408,0.8979,10,,,,,,,,,,,,,,,,,,,,,,,,,,,,,,,,,,,,,
250.4,0.84694,0.79313,10,,,,,,,,,,,,,,,,,,,,,,,,,,,,,,,,,,,,,
251.2,0.84705,0.80731,10,,,,,,,,,,,,,,,,,,,,,,,,,,,,,,,,,,,,,
252,0.84722,0.83916,10,,,,,,,,,,,,,,,,,,,,,,,,,,,,,,,,,,,,,
252.8,0.84745,0.82368,10,,,,,,,,,,,,,,,,,,,,,,,,,,,,,,,,,,,,,
253.6,0.8483,0.80958,10,,,,,,,,,,,,,,,,,,,,,,,,,,,,,,,,,,,,,
254.4,0.85079,0.80558,10,,,,,,,,,,,,,,,,,,,,,,,,,,,,,,,,,,,,,
255.2,0.8568,0.89542,10,,,,,,,,,,,,,,,,,,,,,,,,,,,,,,,,,,,,,
256,0.86128,0.95917,10,,,,,,,,,,,,,,,,,,,,,,,,,,,,,,,,,,,,,
256.8,0.86258,0.96894,10,,,,,,,,,,,,,,,,,,,,,,,,,,,,,,,,,,,,,
257.6,0.86247,1.04022,10,,,,,,,,,,,,,,,,,,,,,,,,,,,,,,,,,,,,,
258.4,0.8623,0.96387,10,,,,,,,,,,,,,,,,,,,,,,,,,,,,,,,,,,,,,
259.2,0.86196,1.01512,10,,,,,,,,,,,,,,,,,,,,,,,,,,,,,,,,,,,,,
260,0.85912,1.00392,10,,,,,,,,,,,,,,,,,,,,,,,,,,,,,,,,,,,,,
260.8,0.85215,0.92188,10,,,,,,,,,,,,,,,,,,,,,,,,,,,,,,,,,,,,,
261.6,0.84779,0.92937,10,,,,,,,,,,,,,,,,,,,,,,,,,,,,,,,,,,,,,
262.4,0.84552,0.88928,10,,,,,,,,,,,,,,,,,,,,,,,,,,,,,,,,,,,,,
263.2,0.8445,0.91212,10,,,,,,,,,,,,,,,,,,,,,,,,,,,,,,,,,,,,,
264,0.84405,0.92343,10,,,,,,,,,,,,,,,,,,,,,,,,,,,,,,,,,,,,,
264.8,0.84388,0.9208,10,,,,,,,,,,,,,,,,,,,,,,,,,,,,,,,,,,,,,
265.6,0.84382,0.87906,10,,,,,,,,,,,,,,,,,,,,,,,,,,,,,,,,,,,,,
266.4,0.84388,0.91082,10,,,,,,,,,,,,,,,,,,,,,,,,,,,,,,,,,,,,,
267.2,0.84399,0.88327,10,,,,,,,,,,,,,,,,,,,,,,,,,,,,,,,,,,,,,
268,0.84388,0.91401,10,,,,,,,,,,,,,,,,,,,,,,,,,,,,,,,,,,,,,
268.8,0.84399,0.88188,10,,,,,,,,,,,,,,,,,,,,,,,,,,,,,,,,,,,,,
269.6,0.84399,0.91711,10,,,,,,,,,,,,,,,,,,,,,,,,,,,,,,,,,,,,,
270.4,0.84399,0.91041,10,,,,,,,,,,,,,,,,,,,,,,,,,,,,,,,,,,,,,
271.2,0.84399,0.9358,10,,,,,,,,,,,,,,,,,,,,,,,,,,,,,,,,,,,,,
272,0.84399,0.94044,10,,,,,,,,,,,,,,,,,,,,,,,,,,,,,,,,,,,,,
272.8,0.84399,0.90786,10,,,,,,,,,,,,,,,,,,,,,,,,,,,,,,,,,,,,,
273.6,0.84388,0.98935,10,,,,,,,,,,,,,,,,,,,,,,,,,,,,,,,,,,,,,
274.4,0.84394,0.8879,10,,,,,,,,,,,,,,,,,,,,,,,,,,,,,,,,,,,,,
275.2,0.84394,0.91719,10,,,,,,,,,,,,,,,,,,,,,,,,,,,,,,,,,,,,,
276,0.84394,0.93601,10,,,,,,,,,,,,,,,,,,,,,,,,,,,,,,,,,,,,,
276.8,0.84388,0.91997,10,,,,,,,,,,,,,,,,,,,,,,,,,,,,,,,,,,,,,
277.6,0.84388,0.8851,10,,,,,,,,,,,,,,,,,,,,,,,,,,,,,,,,,,,,,
278.4,0.84377,0.87948,10,,,,,,,,,,,,,,,,,,,,,,,,,,,,,,,,,,,,,
279.2,0.84377,0.87119,10,,,,,,,,,,,,,,,,,,,,,,,,,,,,,,,,,,,,,
280,0.84377,0.93068,10,,,,,,,,,,,,,,,,,,,,,,,,,,,,,,,,,,,,,
280.8,0.84382,0.95558,10,,,,,,,,,,,,,,,,,,,,,,,,,,,,,,,,,,,,,
281.6,0.8436,0.93068,10,,,,,,,,,,,,,,,,,,,,,,,,,,,,,,,,,,,,,
282.4,0.84297,0.93283,10,,,,,,,,,,,,,,,,,,,,,,,,,,,,,,,,,,,,,
283.2,0.83963,0.95723,10,,,,,,,,,,,,,,,,,,,,,,,,,,,,,,,,,,,,,
284,0.83283,0.87953,10,,,,,,,,,,,,,,,,,,,,,,,,,,,,,,,,,,,,,
284.8,0.83147,0.85839,10,,,,,,,,,,,,,,,,,,,,,,,,,,,,,,,,,,,,,
285.6,0.83147,0.89173,10,,,,,,,,,,,,,,,,,,,,,,,,,,,,,,,,,,,,,
286.4,0.83164,0.80535,10,,,,,,,,,,,,,,,,,,,,,,,,,,,,,,,,,,,,,
287.2,0.83181,0.85885,10,,,,,,,,,,,,,,,,,,,,,,,,,,,,,,,,,,,,,
288,0.83198,0.82932,10,,,,,,,,,,,,,,,,,,,,,,,,,,,,,,,,,,,,,
288.8,0.83249,0.79398,10,,,,,,,,,,,,,,,,,,,,,,,,,,,,,,,,,,,,,
289.6,0.83362,0.86757,10,,,,,,,,,,,,,,,,,,,,,,,,,,,,,,,,,,,,,
290.4,0.83736,0.89923,10,,,,,,,,,,,,,,,,,,,,,,,,,,,,,,,,,,,,,
291.2,0.84632,0.94473,10,,,,,,,,,,,,,,,,,,,,,,,,,,,,,,,,,,,,,
292,0.8483,0.98359,10,,,,,,,,,,,,,,,,,,,,,,,,,,,,,,,,,,,,,
292.8,0.84824,0.9877,10,,,,,,,,,,,,,,,,,,,,,,,,,,,,,,,,,,,,,
293.6,0.84802,1.02968,10,,,,,,,,,,,,,,,,,,,,,,,,,,,,,,,,,,,,,
294.4,0.84768,0.98574,10,,,,,,,,,,,,,,,,,,,,,,,,,,,,,,,,,,,,,
295.2,0.84513,1.0065,10,,,,,,,,,,,,,,,,,,,,,,,,,,,,,,,,,,,,,
296,0.83918,0.97557,10,,,,,,,,,,,,,,,,,,,,,,,,,,,,,,,,,,,,,
296.8,0.83334,0.92751,10,,,,,,,,,,,,,,,,,,,,,,,,,,,,,,,,,,,,,
297.6,0.83175,0.93838,10,,,,,,,,,,,,,,,,,,,,,,,,,,,,,,,,,,,,,
298.4,0.83147,0.90455,10,,,,,,,,,,,,,,,,,,,,,,,,,,,,,,,,,,,,,
299.2,0.83141,0.88354,10,,,,,,,,,,,,,,,,,,,,,,,,,,,,,,,,,,,,,
300,0.83147,0.95448,10,,,,,,,,,,,,,,,,,,,,,,,,,,,,,,,,,,,,,
300.8,0.83153,0.87364,10,,,,,,,,,,,,,,,,,,,,,,,,,,,,,,,,,,,,,
301.6,0.83153,0.88895,10,,,,,,,,,,,,,,,,,,,,,,,,,,,,,,,,,,,,,
302.4,0.83175,0.93262,10,,,,,,,,,,,,,,,,,,,,,,,,,,,,,,,,,,,,,
303.2,0.83187,0.82852,10,,,,,,,,,,,,,,,,,,,,,,,,,,,,,,,,,,,,,
304,0.83192,0.88522,10,,,,,,,,,,,,,,,,,,,,,,,,,,,,,,,,,,,,,
304.8,0.83232,0.87091,10,,,,,,,,,,,,,,,,,,,,,,,,,,,,,,,,,,,,,
305.6,0.83289,0.83973,10,,,,,,,,,,,,,,,,,,,,,,,,,,,,,,,,,,,,,
306.4,0.83402,0.92204,10,,,,,,,,,,,,,,,,,,,,,,,,,,,,,,,,,,,,,
307.2,0.83572,0.86682,10,,,,,,,,,,,,,,,,,,,,,,,,,,,,,,,,,,,,,
308,0.83804,0.92676,10,,,,,,,,,,,,,,,,,,,,,,,,,,,,,,,,,,,,,
308.8,0.83901,0.94705,10,,,,,,,,,,,,,,,,,,,,,,,,,,,,,,,,,,,,,
309.6,0.83906,1.02766,10,,,,,,,,,,,,,,,,,,,,,,,,,,,,,,,,,,,,,
310.4,0.83906,1.02055,10,,,,,,,,,,,,,,,,,,,,,,,,,,,,,,,,,,,,,
311.2,0.83884,0.9608,10,,,,,,,,,,,,,,,,,,,,,,,,,,,,,,,,,,,,,
312,0.83872,0.98902,10,,,,,,,,,,,,,,,,,,,,,,,,,,,,,,,,,,,,,
312.8,0.8385,1.03346,10,,,,,,,,,,,,,,,,,,,,,,,,,,,,,,,,,,,,,
313.6,0.83793,0.92705,10,,,,,,,,,,,,,,,,,,,,,,,,,,,,,,,,,,,,,
314.4,0.83651,0.9904,10,,,,,,,,,,,,,,,,,,,,,,,,,,,,,,,,,,,,,
315.2,0.83504,0.94933,10,,,,,,,,,,,,,,,,,,,,,,,,,,,,,,,,,,,,,
316,0.83362,0.98479,10,,,,,,,,,,,,,,,,,,,,,,,,,,,,,,,,,,,,,
316.8,0.83141,0.94272,10,,,,,,,,,,,,,,,,,,,,,,,,,,,,,,,,,,,,,
317.6,0.8292,0.89146,10,,,,,,,,,,,,,,,,,,,,,,,,,,,,,,,,,,,,,
318.4,0.82835,0.97454,10,,,,,,,,,,,,,,,,,,,,,,,,,,,,,,,,,,,,,
319.2,0.82807,0.85977,10,,,,,,,,,,,,,,,,,,,,,,,,,,,,,,,,,,,,,
320,0.82818,0.92067,10,,,,,,,,,,,,,,,,,,,,,,,,,,,,,,,,,,,,,
320.8,0.8283,0.86738,10,,,,,,,,,,,,,,,,,,,,,,,,,,,,,,,,,,,,,
321.6,0.82841,0.87675,10,,,,,,,,,,,,,,,,,,,,,,,,,,,,,,,,,,,,,
322.4,0.82852,0.98442,10,,,,,,,,,,,,,,,,,,,,,,,,,,,,,,,,,,,,,
323.2,0.82864,0.83229,10,,,,,,,,,,,,,,,,,,,,,,,,,,,,,,,,,,,,,
324,0.82886,0.84904,10,,,,,,,,,,,,,,,,,,,,,,,,,,,,,,,,,,,,,
324.8,0.82949,0.81383,10,,,,,,,,,,,,,,,,,,,,,,,,,,,,,,,,,,,,,
325.6,0.83051,0.82177,10,,,,,,,,,,,,,,,,,,,,,,,,,,,,,,,,,,,,,
326.4,0.83487,0.92599,10,,,,,,,,,,,,,,,,,,,,,,,,,,,,,,,,,,,,,
327.2,0.83753,0.91442,10,,,,,,,,,,,,,,,,,,,,,,,,,,,,,,,,,,,,,
328,0.83827,0.9496,10,,,,,,,,,,,,,,,,,,,,,,,,,,,,,,,,,,,,,
328.8,0.83844,0.93012,10,,,,,,,,,,,,,,,,,,,,,,,,,,,,,,,,,,,,,
329.6,0.83838,0.92666,10,,,,,,,,,,,,,,,,,,,,,,,,,,,,,,,,,,,,,
330.4,0.83827,0.97104,10,,,,,,,,,,,,,,,,,,,,,,,,,,,,,,,,,,,,,
331.2,0.83821,0.97773,10,,,,,,,,,,,,,,,,,,,,,,,,,,,,,,,,,,,,,
332,0.83793,0.97642,10,,,,,,,,,,,,,,,,,,,,,,,,,,,,,,,,,,,,,
332.8,0.83731,0.95969,10,,,,,,,,,,,,,,,,,,,,,,,,,,,,,,,,,,,,,
333.6,0.83589,0.95724,10,,,,,,,,,,,,,,,,,,,,,,,,,,,,,,,,,,,,,
334.4,0.83419,0.93204,10,,,,,,,,,,,,,,,,,,,,,,,,,,,,,,,,,,,,,
335.2,0.83277,0.94121,10,,,,,,,,,,,,,,,,,,,,,,,,,,,,,,,,,,,,,
336,0.83124,0.93588,10,,,,,,,,,,,,,,,,,,,,,,,,,,,,,,,,,,,,,
336.8,0.83011,0.90433,10,,,,,,,,,,,,,,,,,,,,,,,,,,,,,,,,,,,,,
337.6,0.82898,0.88497,10,,,,,,,,,,,,,,,,,,,,,,,,,,,,,,,,,,,,,
338.4,0.82852,0.92001,10,,,,,,,,,,,,,,,,,,,,,,,,,,,,,,,,,,,,,
339.2,0.8283,0.84456,10,,,,,,,,,,,,,,,,,,,,,,,,,,,,,,,,,,,,,
340,0.82835,0.88734,10,,,,,,,,,,,,,,,,,,,,,,,,,,,,,,,,,,,,,
340.8,0.82841,0.83963,10,,,,,,,,,,,,,,,,,,,,,,,,,,,,,,,,,,,,,
341.6,0.82841,0.82409,10,,,,,,,,,,,,,,,,,,,,,,,,,,,,,,,,,,,,,
342.4,0.82858,0.8929,10,,,,,,,,,,,,,,,,,,,,,,,,,,,,,,,,,,,,,
343.2,0.82875,0.87223,10,,,,,,,,,,,,,,,,,,,,,,,,,,,,,,,,,,,,,
344,0.82898,0.85667,10,,,,,,,,,,,,,,,,,,,,,,,,,,,,,,,,,,,,,
344.8,0.82943,0.81292,10,,,,,,,,,,,,,,,,,,,,,,,,,,,,,,,,,,,,,
345.6,0.83,0.87084,10,,,,,,,,,,,,,,,,,,,,,,,,,,,,,,,,,,,,,
346.4,0.83198,0.84107,10,,,,,,,,,,,,,,,,,,,,,,,,,,,,,,,,,,,,,
347.2,0.83663,0.89549,10,,,,,,,,,,,,,,,,,,,,,,,,,,,,,,,,,,,,,
348,0.8385,0.99642,10,,,,,,,,,,,,,,,,,,,,,,,,,,,,,,,,,,,,,
348.8,0.83884,0.96861,10,,,,,,,,,,,,,,,,,,,,,,,,,,,,,,,,,,,,,
349.6,0.83872,1.01412,10,,,,,,,,,,,,,,,,,,,,,,,,,,,,,,,,,,,,,
350.4,0.8385,0.94139,10,,,,,,,,,,,,,,,,,,,,,,,,,,,,,,,,,,,,,
351.2,0.83833,1.02255,10,,,,,,,,,,,,,,,,,,,,,,,,,,,,,,,,,,,,,
352,0.83753,1.01887,10,,,,,,,,,,,,,,,,,,,,,,,,,,,,,,,,,,,,,
352.8,0.83572,0.95377,10,,,,,,,,,,,,,,,,,,,,,,,,,,,,,,,,,,,,,
353.6,0.83396,0.90955,10,,,,,,,,,,,,,,,,,,,,,,,,,,,,,,,,,,,,,
354.4,0.83192,0.91153,10,,,,,,,,,,,,,,,,,,,,,,,,,,,,,,,,,,,,,
355.2,0.83039,0.95065,10,,,,,,,,,,,,,,,,,,,,,,,,,,,,,,,,,,,,,
356,0.82898,0.95216,10,,,,,,,,,,,,,,,,,,,,,,,,,,,,,,,,,,,,,
356.8,0.82852,0.88095,10,,,,,,,,,,,,,,,,,,,,,,,,,,,,,,,,,,,,,
357.6,0.8283,0.87128,10,,,,,,,,,,,,,,,,,,,,,,,,,,,,,,,,,,,,,
358.4,0.8283,0.85047,10,,,,,,,,,,,,,,,,,,,,,,,,,,,,,,,,,,,,,
359.2,0.82835,0.89411,10,,,,,,,,,,,,,,,,,,,,,,,,,,,,,,,,,,,,,
360,0.82835,0.89829,10,,,,,,,,,,,,,,,,,,,,,,,,,,,,,,,,,,,,,
360.8,0.82852,0.87751,10,,,,,,,,,,,,,,,,,,,,,,,,,,,,,,,,,,,,,
361.6,0.82864,0.87324,10,,,,,,,,,,,,,,,,,,,,,,,,,,,,,,,,,,,,,
362.4,0.82875,0.84389,10,,,,,,,,,,,,,,,,,,,,,,,,,,,,,,,,,,,,,
363.2,0.82903,0.83032,10,,,,,,,,,,,,,,,,,,,,,,,,,,,,,,,,,,,,,
364,0.82954,0.90853,10,,,,,,,,,,,,,,,,,,,,,,,,,,,,,,,,,,,,,
364.8,0.83028,0.85713,10,,,,,,,,,,,,,,,,,,,,,,,,,,,,,,,,,,,,,
365.6,0.83362,0.86723,10,,,,,,,,,,,,,,,,,,,,,,,,,,,,,,,,,,,,,
366.4,0.83589,0.90654,10,,,,,,,,,,,,,,,,,,,,,,,,,,,,,,,,,,,,,
367.2,0.83714,0.94818,10,,,,,,,,,,,,,,,,,,,,,,,,,,,,,,,,,,,,,
368,0.8377,0.94877,10,,,,,,,,,,,,,,,,,,,,,,,,,,,,,,,,,,,,,
368.8,0.83776,0.96146,10,,,,,,,,,,,,,,,,,,,,,,,,,,,,,,,,,,,,,
369.6,0.83765,0.98627,10,,,,,,,,,,,,,,,,,,,,,,,,,,,,,,,,,,,,,
370.4,0.83736,1.02551,10,,,,,,,,,,,,,,,,,,,,,,,,,,,,,,,,,,,,,
371.2,0.83708,0.98605,10,,,,,,,,,,,,,,,,,,,,,,,,,,,,,,,,,,,,,
372,0.83617,0.98179,10,,,,,,,,,,,,,,,,,,,,,,,,,,,,,,,,,,,,,
372.8,0.83498,0.95028,10,,,,,,,,,,,,,,,,,,,,,,,,,,,,,,,,,,,,,
373.6,0.83317,0.94599,10,,,,,,,,,,,,,,,,,,,,,,,,,,,,,,,,,,,,,
374.4,0.83147,0.92619,10,,,,,,,,,,,,,,,,,,,,,,,,,,,,,,,,,,,,,
375.2,0.83039,0.90128,10,,,,,,,,,,,,,,,,,,,,,,,,,,,,,,,,,,,,,
376,0.82949,0.95699,10,,,,,,,,,,,,,,,,,,,,,,,,,,,,,,,,,,,,,
376.8,0.82881,0.88414,10,,,,,,,,,,,,,,,,,,,,,,,,,,,,,,,,,,,,,
377.6,0.82847,0.92178,10,,,,,,,,,,,,,,,,,,,,,,,,,,,,,,,,,,,,,
378.4,0.82818,0.88826,10,,,,,,,,,,,,,,,,,,,,,,,,,,,,,,,,,,,,,
379.2,0.8283,0.84849,10,,,,,,,,,,,,,,,,,,,,,,,,,,,,,,,,,,,,,
380,0.82835,0.91459,10,,,,,,,,,,,,,,,,,,,,,,,,,,,,,,,,,,,,,
380.8,0.82841,0.87455,10,,,,,,,,,,,,,,,,,,,,,,,,,,,,,,,,,,,,,
381.6,0.82841,0.88879,10,,,,,,,,,,,,,,,,,,,,,,,,,,,,,,,,,,,,,
382.4,0.82858,0.84691,10,,,,,,,,,,,,,,,,,,,,,,,,,,,,,,,,,,,,,
383.2,0.82864,0.83022,10,,,,,,,,,,,,,,,,,,,,,,,,,,,,,,,,,,,,,
384,0.82881,0.87886,10,,,,,,,,,,,,,,,,,,,,,,,,,,,,,,,,,,,,,
384.8,0.8292,0.80701,10,,,,,,,,,,,,,,,,,,,,,,,,,,,,,,,,,,,,,
385.6,0.82971,0.88902,10,,,,,,,,,,,,,,,,,,,,,,,,,,,,,,,,,,,,,
386.4,0.83102,0.86504,10,,,,,,,,,,,,,,,,,,,,,,,,,,,,,,,,,,,,,
387.2,0.83357,0.87992,10,,,,,,,,,,,,,,,,,,,,,,,,,,,,,,,,,,,,,
388,0.83538,0.91636,10,,,,,,,,,,,,,,,,,,,,,,,,,,,,,,,,,,,,,
388.8,0.83617,0.91891,10,,,,,,,,,,,,,,,,,,,,,,,,,,,,,,,,,,,,,
389.6,0.83685,0.92814,10,,,,,,,,,,,,,,,,,,,,,,,,,,,,,,,,,,,,,
390.4,0.83708,0.97651,10,,,,,,,,,,,,,,,,,,,,,,,,,,,,,,,,,,,,,
391.2,0.83685,0.96722,10,,,,,,,,,,,,,,,,,,,,,,,,,,,,,,,,,,,,,
392,0.83674,0.92924,10,,,,,,,,,,,,,,,,,,,,,,,,,,,,,,,,,,,,,
392.8,0.83657,0.95631,10,,,,,,,,,,,,,,,,,,,,,,,,,,,,,,,,,,,,,
393.6,0.83634,0.91422,10,,,,,,,,,,,,,,,,,,,,,,,,,,,,,,,,,,,,,
394.4,0.836,0.95487,10,,,,,,,,,,,,,,,,,,,,,,,,,,,,,,,,,,,,,
395.2,0.83538,0.90955,10,,,,,,,,,,,,,,,,,,,,,,,,,,,,,,,,,,,,,
396,0.8343,0.96367,10,,,,,,,,,,,,,,,,,,,,,,,,,,,,,,,,,,,,,
396.8,0.83311,0.95543,10,,,,,,,,,,,,,,,,,,,,,,,,,,,,,,,,,,,,,
397.6,0.8313,0.94814,10,,,,,,,,,,,,,,,,,,,,,,,,,,,,,,,,,,,,,
398.4,0.83022,0.9393,10,,,,,,,,,,,,,,,,,,,,,,,,,,,,,,,,,,,,,
399.2,0.82881,0.90135,10,,,,,,,,,,,,,,,,,,,,,,,,,,,,,,,,,,,,,
400,0.82813,0.92334,10,,,,,,,,,,,,,,,,,,,,,,,,,,,,,,,,,,,,,
400.8,0.82807,0.92238,10,,,,,,,,,,,,,,,,,,,,,,,,,,,,,,,,,,,,,
401.6,0.82813,0.87982,10,,,,,,,,,,,,,,,,,,,,,,,,,,,,,,,,,,,,,
402.4,0.82813,0.87564,10,,,,,,,,,,,,,,,,,,,,,,,,,,,,,,,,,,,,,
403.2,0.82824,0.90555,10,,,,,,,,,,,,,,,,,,,,,,,,,,,,,,,,,,,,,
404,0.82835,0.9408,10,,,,,,,,,,,,,,,,,,,,,,,,,,,,,,,,,,,,,
404.8,0.82847,0.88446,10,,,,,,,,,,,,,,,,,,,,,,,,,,,,,,,,,,,,,
405.6,0.82852,0.92027,10,,,,,,,,,,,,,,,,,,,,,,,,,,,,,,,,,,,,,
406.4,0.82864,0.83688,10,,,,,,,,,,,,,,,,,,,,,,,,,,,,,,,,,,,,,
407.2,0.82903,0.84335,10,,,,,,,,,,,,,,,,,,,,,,,,,,,,,,,,,,,,,
408,0.82949,0.87964,10,,,,,,,,,,,,,,,,,,,,,,,,,,,,,,,,,,,,,
408.8,0.83017,0.83628,10,,,,,,,,,,,,,,,,,,,,,,,,,,,,,,,,,,,,,
409.6,0.83306,0.92452,10,,,,,,,,,,,,,,,,,,,,,,,,,,,,,,,,,,,,,
410.4,0.83566,0.92203,10,,,,,,,,,,,,,,,,,,,,,,,,,,,,,,,,,,,,,
411.2,0.83651,0.95186,10,,,,,,,,,,,,,,,,,,,,,,,,,,,,,,,,,,,,,
412,0.83674,1.02756,10,,,,,,,,,,,,,,,,,,,,,,,,,,,,,,,,,,,,,
412.8,0.83657,0.97435,10,,,,,,,,,,,,,,,,,,,,,,,,,,,,,,,,,,,,,
413.6,0.83651,1.00661,10,,,,,,,,,,,,,,,,,,,,,,,,,,,,,,,,,,,,,
414.4,0.83634,0.93698,10,,,,,,,,,,,,,,,,,,,,,,,,,,,,,,,,,,,,,
415.2,0.83606,1.01211,10,,,,,,,,,,,,,,,,,,,,,,,,,,,,,,,,,,,,,
416,0.83572,0.94898,10,,,,,,,,,,,,,,,,,,,,,,,,,,,,,,,,,,,,,
416.8,0.83504,0.95,10,,,,,,,,,,,,,,,,,,,,,,,,,,,,,,,,,,,,,
417.6,0.83402,0.97868,10,,,,,,,,,,,,,,,,,,,,,,,,,,,,,,,,,,,,,
418.4,0.83294,0.91505,10,,,,,,,,,,,,,,,,,,,,,,,,,,,,,,,,,,,,,
419.2,0.83181,0.89982,10,,,,,,,,,,,,,,,,,,,,,,,,,,,,,,,,,,,,,
420,0.8309,0.95798,10,,,,,,,,,,,,,,,,,,,,,,,,,,,,,,,,,,,,,
420.8,0.83022,0.91532,10,,,,,,,,,,,,,,,,,,,,,,,,,,,,,,,,,,,,,
421.6,0.8296,1.00829,10,,,,,,,,,,,,,,,,,,,,,,,,,,,,,,,,,,,,,
422.4,0.82892,0.9187,10,,,,,,,,,,,,,,,,,,,,,,,,,,,,,,,,,,,,,
423.2,0.82858,0.84178,10,,,,,,,,,,,,,,,,,,,,,,,,,,,,,,,,,,,,,
424,0.82852,0.87947,10,,,,,,,,,,,,,,,,,,,,,,,,,,,,,,,,,,,,,
424.8,0.82869,0.90395,10,,,,,,,,,,,,,,,,,,,,,,,,,,,,,,,,,,,,,
425.6,0.82875,0.88179,10,,,,,,,,,,,,,,,,,,,,,,,,,,,,,,,,,,,,,
426.4,0.82892,0.83604,10,,,,,,,,,,,,,,,,,,,,,,,,,,,,,,,,,,,,,
427.2,0.82898,0.87162,10,,,,,,,,,,,,,,,,,,,,,,,,,,,,,,,,,,,,,
428,0.82926,0.85304,10,,,,,,,,,,,,,,,,,,,,,,,,,,,,,,,,,,,,,
428.8,0.82971,0.86745,10,,,,,,,,,,,,,,,,,,,,,,,,,,,,,,,,,,,,,
429.6,0.83068,0.85944,10,,,,,,,,,,,,,,,,,,,,,,,,,,,,,,,,,,,,,
430.4,0.83311,0.86211,10,,,,,,,,,,,,,,,,,,,,,,,,,,,,,,,,,,,,,
431.2,0.83561,0.88574,10,,,,,,,,,,,,,,,,,,,,,,,,,,,,,,,,,,,,,
432,0.83685,0.91359,10,,,,,,,,,,,,,,,,,,,,,,,,,,,,,,,,,,,,,
432.8,0.83748,0.90023,10,,,,,,,,,,,,,,,,,,,,,,,,,,,,,,,,,,,,,
433.6,0.83765,0.95643,10,,,,,,,,,,,,,,,,,,,,,,,,,,,,,,,,,,,,,
434.4,0.83742,0.97261,10,,,,,,,,,,,,,,,,,,,,,,,,,,,,,,,,,,,,,
435.2,0.83731,0.96133,10,,,,,,,,,,,,,,,,,,,,,,,,,,,,,,,,,,,,,
436,0.83725,0.94609,10,,,,,,,,,,,,,,,,,,,,,,,,,,,,,,,,,,,,,
436.8,0.83702,0.99995,10,,,,,,,,,,,,,,,,,,,,,,,,,,,,,,,,,,,,,
437.6,0.83668,0.94829,10,,,,,,,,,,,,,,,,,,,,,,,,,,,,,,,,,,,,,
438.4,0.83583,0.93028,10,,,,,,,,,,,,,,,,,,,,,,,,,,,,,,,,,,,,,
439.2,0.8347,0.92936,10,,,,,,,,,,,,,,,,,,,,,,,,,,,,,,,,,,,,,
440,0.83317,0.95277,10,,,,,,,,,,,,,,,,,,,,,,,,,,,,,,,,,,,,,
440.8,0.83164,0.91954,10,,,,,,,,,,,,,,,,,,,,,,,,,,,,,,,,,,,,,
441.6,0.83073,0.88542,10,,,,,,,,,,,,,,,,,,,,,,,,,,,,,,,,,,,,,
442.4,0.8296,0.93309,10,,,,,,,,,,,,,,,,,,,,,,,,,,,,,,,,,,,,,
443.2,0.82858,0.8968,10,,,,,,,,,,,,,,,,,,,,,,,,,,,,,,,,,,,,,
444,0.8283,0.93119,10,,,,,,,,,,,,,,,,,,,,,,,,,,,,,,,,,,,,,
444.8,0.82813,0.84516,10,,,,,,,,,,,,,,,,,,,,,,,,,,,,,,,,,,,,,
445.6,0.82824,0.86125,10,,,,,,,,,,,,,,,,,,,,,,,,,,,,,,,,,,,,,
446.4,0.82835,0.92234,10,,,,,,,,,,,,,,,,,,,,,,,,,,,,,,,,,,,,,
447.2,0.82841,0.86748,10,,,,,,,,,,,,,,,,,,,,,,,,,,,,,,,,,,,,,
448,0.82847,0.93957,10,,,,,,,,,,,,,,,,,,,,,,,,,,,,,,,,,,,,,
448.8,0.82858,0.91884,10,,,,,,,,,,,,,,,,,,,,,,,,,,,,,,,,,,,,,
449.6,0.82869,0.81999,10,,,,,,,,,,,,,,,,,,,,,,,,,,,,,,,,,,,,,
450.4,0.82898,0.82276,10,,,,,,,,,,,,,,,,,,,,,,,,,,,,,,,,,,,,,
451.2,0.82949,0.86939,10,,,,,,,,,,,,,,,,,,,,,,,,,,,,,,,,,,,,,
452,0.83017,0.85935,10,,,,,,,,,,,,,,,,,,,,,,,,,,,,,,,,,,,,,
452.8,0.83311,0.85799,10,,,,,,,,,,,,,,,,,,,,,,,,,,,,,,,,,,,,,
453.6,0.83606,0.90289,10,,,,,,,,,,,,,,,,,,,,,,,,,,,,,,,,,,,,,
454.4,0.83821,0.91939,10,,,,,,,,,,,,,,,,,,,,,,,,,,,,,,,,,,,,,
455.2,0.83878,0.91813,10,,,,,,,,,,,,,,,,,,,,,,,,,,,,,,,,,,,,,
456,0.83889,0.94848,10,,,,,,,,,,,,,,,,,,,,,,,,,,,,,,,,,,,,,
456.8,0.83878,1.03151,10,,,,,,,,,,,,,,,,,,,,,,,,,,,,,,,,,,,,,
457.6,0.83855,0.98275,10,,,,,,,,,,,,,,,,,,,,,,,,,,,,,,,,,,,,,
458.4,0.83838,1.00035,10,,,,,,,,,,,,,,,,,,,,,,,,,,,,,,,,,,,,,
459.2,0.83776,0.98173,10,,,,,,,,,,,,,,,,,,,,,,,,,,,,,,,,,,,,,
460,0.83629,0.99122,10,,,,,,,,,,,,,,,,,,,,,,,,,,,,,,,,,,,,,
460.8,0.83436,0.94287,10,,,,,,,,,,,,,,,,,,,,,,,,,,,,,,,,,,,,,
461.6,0.83272,0.84532,10,,,,,,,,,,,,,,,,,,,,,,,,,,,,,,,,,,,,,
462.4,0.83107,0.8903,10,,,,,,,,,,,,,,,,,,,,,,,,,,,,,,,,,,,,,
463.2,0.83005,0.88101,10,,,,,,,,,,,,,,,,,,,,,,,,,,,,,,,,,,,,,
464,0.8296,0.92097,10,,,,,,,,,,,,,,,,,,,,,,,,,,,,,,,,,,,,,
464.8,0.82909,0.90001,10,,,,,,,,,,,,,,,,,,,,,,,,,,,,,,,,,,,,,
465.6,0.82892,0.82546,10,,,,,,,,,,,,,,,,,,,,,,,,,,,,,,,,,,,,,
466.4,0.82903,0.87934,10,,,,,,,,,,,,,,,,,,,,,,,,,,,,,,,,,,,,,
467.2,0.82909,0.89022,10,,,,,,,,,,,,,,,,,,,,,,,,,,,,,,,,,,,,,
468,0.82915,0.9119,10,,,,,,,,,,,,,,,,,,,,,,,,,,,,,,,,,,,,,
468.8,0.82926,0.83074,10,,,,,,,,,,,,,,,,,,,,,,,,,,,,,,,,,,,,,
469.6,0.82932,0.85633,10,,,,,,,,,,,,,,,,,,,,,,,,,,,,,,,,,,,,,
470.4,0.82943,0.9066,10,,,,,,,,,,,,,,,,,,,,,,,,,,,,,,,,,,,,,
471.2,0.8296,0.92249,10,,,,,,,,,,,,,,,,,,,,,,,,,,,,,,,,,,,,,
472,0.82954,0.96726,10,,,,,,,,,,,,,,,,,,,,,,,,,,,,,,,,,,,,,
472.8,0.82966,0.93941,10,,,,,,,,,,,,,,,,,,,,,,,,,,,,,,,,,,,,,
473.6,0.82966,0.836,10,,,,,,,,,,,,,,,,,,,,,,,,,,,,,,,,,,,,,
474.4,0.82977,0.88448,10,,,,,,,,,,,,,,,,,,,,,,,,,,,,,,,,,,,,,
475.2,0.82988,0.85353,10,,,,,,,,,,,,,,,,,,,,,,,,,,,,,,,,,,,,,
476,0.83,0.91065,10,,,,,,,,,,,,,,,,,,,,,,,,,,,,,,,,,,,,,
476.8,0.83028,0.89996,10,,,,,,,,,,,,,,,,,,,,,,,,,,,,,,,,,,,,,
477.6,0.83096,0.84151,10,,,,,,,,,,,,,,,,,,,,,,,,,,,,,,,,,,,,,
478.4,0.83243,0.89032,10,,,,,,,,,,,,,,,,,,,,,,,,,,,,,,,,,,,,,
479.2,0.83391,0.95336,10,,,,,,,,,,,,,,,,,,,,,,,,,,,,,,,,,,,,,
480,0.83447,0.94596,10,,,,,,,,,,,,,,,,,,,,,,,,,,,,,,,,,,,,,
480.8,0.83464,0.93663,10,,,,,,,,,,,,,,,,,,,,,,,,,,,,,,,,,,,,,
481.6,0.8347,0.88525,10,,,,,,,,,,,,,,,,,,,,,,,,,,,,,,,,,,,,,
482.4,0.83476,0.93064,10,,,,,,,,,,,,,,,,,,,,,,,,,,,,,,,,,,,,,
483.2,0.83476,0.91253,10,,,,,,,,,,,,,,,,,,,,,,,,,,,,,,,,,,,,,
484,0.8347,0.96703,10,,,,,,,,,,,,,,,,,,,,,,,,,,,,,,,,,,,,,
484.8,0.83459,0.96907,10,,,,,,,,,,,,,,,,,,,,,,,,,,,,,,,,,,,,,
485.6,0.83464,0.94571,10,,,,,,,,,,,,,,,,,,,,,,,,,,,,,,,,,,,,,
486.4,0.83447,0.88761,10,,,,,,,,,,,,,,,,,,,,,,,,,,,,,,,,,,,,,
487.2,0.83442,0.92561,10,,,,,,,,,,,,,,,,,,,,,,,,,,,,,,,,,,,,,
488,0.8343,0.92614,10,,,,,,,,,,,,,,,,,,,,,,,,,,,,,,,,,,,,,
488.8,0.83419,0.99062,10,,,,,,,,,,,,,,,,,,,,,,,,,,,,,,,,,,,,,
489.6,0.83413,0.93107,10,,,,,,,,,,,,,,,,,,,,,,,,,,,,,,,,,,,,,
490.4,0.83402,0.84546,10,,,,,,,,,,,,,,,,,,,,,,,,,,,,,,,,,,,,,
491.2,0.83391,0.85923,10,,,,,,,,,,,,,,,,,,,,,,,,,,,,,,,,,,,,,
492,0.83379,0.95708,10,,,,,,,,,,,,,,,,,,,,,,,,,,,,,,,,,,,,,
492.8,0.83368,0.98756,10,,,,,,,,,,,,,,,,,,,,,,,,,,,,,,,,,,,,,
493.6,0.83351,0.9058,10,,,,,,,,,,,,,,,,,,,,,,,,,,,,,,,,,,,,,
494.4,0.83328,0.87941,10,,,,,,,,,,,,,,,,,,,,,,,,,,,,,,,,,,,,,
495.2,0.83306,0.91933,10,,,,,,,,,,,,,,,,,,,,,,,,,,,,,,,,,,,,,
496,0.83289,0.91896,10,,,,,,,,,,,,,,,,,,,,,,,,,,,,,,,,,,,,,
496.8,0.83272,0.94289,10,,,,,,,,,,,,,,,,,,,,,,,,,,,,,,,,,,,,,
497.6,0.83243,0.8656,10,,,,,,,,,,,,,,,,,,,,,,,,,,,,,,,,,,,,,
498.4,0.83209,0.9524,10,,,,,,,,,,,,,,,,,,,,,,,,,,,,,,,,,,,,,
499.2,0.83175,0.93064,10,,,,,,,,,,,,,,,,,,,,,,,,,,,,,,,,,,,,,
500,0.83141,0.83552,10,,,,,,,,,,,,,,,,,,,,,,,,,,,,,,,,,,,,,
500.8,0.83136,0.8852,10,,,,,,,,,,,,,,,,,,,,,,,,,,,,,,,,,,,,,
501.6,0.83147,0.8987,10,,,,,,,,,,,,,,,,,,,,,,,,,,,,,,,,,,,,,
502.4,0.83147,0.93758,10,,,,,,,,,,,,,,,,,,,,,,,,,,,,,,,,,,,,,
503.2,0.83153,0.87909,10,,,,,,,,,,,,,,,,,,,,,,,,,,,,,,,,,,,,,
504,0.83153,0.94407,10,,,,,,,,,,,,,,,,,,,,,,,,,,,,,,,,,,,,,
504.8,0.83153,0.95683,10,,,,,,,,,,,,,,,,,,,,,,,,,,,,,,,,,,,,,
505.6,0.83153,0.90186,10,,,,,,,,,,,,,,,,,,,,,,,,,,,,,,,,,,,,,
506.4,0.83153,0.89163,10,,,,,,,,,,,,,,,,,,,,,,,,,,,,,,,,,,,,,
507.2,0.83153,0.85049,10,,,,,,,,,,,,,,,,,,,,,,,,,,,,,,,,,,,,,
508,0.83147,0.89833,10,,,,,,,,,,,,,,,,,,,,,,,,,,,,,,,,,,,,,
508.8,0.83158,0.91372,10,,,,,,,,,,,,,,,,,,,,,,,,,,,,,,,,,,,,,
509.6,0.83164,0.86128,10,,,,,,,,,,,,,,,,,,,,,,,,,,,,,,,,,,,,,
510.4,0.8317,0.85326,10,,,,,,,,,,,,,,,,,,,,,,,,,,,,,,,,,,,,,
511.2,0.83175,0.91337,10,,,,,,,,,,,,,,,,,,,,,,,,,,,,,,,,,,,,,
512,0.8317,0.91252,10,,,,,,,,,,,,,,,,,,,,,,,,,,,,,,,,,,,,,
512.8,0.8317,0.97118,10,,,,,,,,,,,,,,,,,,,,,,,,,,,,,,,,,,,,,
513.6,0.8317,0.9617,10,,,,,,,,,,,,,,,,,,,,,,,,,,,,,,,,,,,,,
514.4,0.8317,0.92977,10,,,,,,,,,,,,,,,,,,,,,,,,,,,,,,,,,,,,,
515.2,0.8317,0.89346,10,,,,,,,,,,,,,,,,,,,,,,,,,,,,,,,,,,,,,
516,0.83181,0.91763,10,,,,,,,,,,,,,,,,,,,,,,,,,,,,,,,,,,,,,
516.8,0.83192,1.00353,10,,,,,,,,,,,,,,,,,,,,,,,,,,,,,,,,,,,,,
517.6,0.83204,0.9236,10,,,,,,,,,,,,,,,,,,,,,,,,,,,,,,,,,,,,,
518.4,0.83215,0.86301,10,,,,,,,,,,,,,,,,,,,,,,,,,,,,,,,,,,,,,
519.2,0.83238,0.84881,10,,,,,,,,,,,,,,,,,,,,,,,,,,,,,,,,,,,,,
520,0.83311,0.86405,10,,,,,,,,,,,,,,,,,,,,,,,,,,,,,,,,,,,,,
520.8,0.83413,0.91564,10,,,,,,,,,,,,,,,,,,,,,,,,,,,,,,,,,,,,,
521.6,0.83527,0.89453,10,,,,,,,,,,,,,,,,,,,,,,,,,,,,,,,,,,,,,
522.4,0.83634,0.8941,10,,,,,,,,,,,,,,,,,,,,,,,,,,,,,,,,,,,,,
523.2,0.83765,0.90317,10,,,,,,,,,,,,,,,,,,,,,,,,,,,,,,,,,,,,,
524,0.83821,0.90987,10,,,,,,,,,,,,,,,,,,,,,,,,,,,,,,,,,,,,,
524.8,0.83844,0.89016,10,,,,,,,,,,,,,,,,,,,,,,,,,,,,,,,,,,,,,
525.6,0.83844,0.97049,10,,,,,,,,,,,,,,,,,,,,,,,,,,,,,,,,,,,,,
526.4,0.83827,0.95168,10,,,,,,,,,,,,,,,,,,,,,,,,,,,,,,,,,,,,,
527.2,0.8381,0.93096,10,,,,,,,,,,,,,,,,,,,,,,,,,,,,,,,,,,,,,
528,0.83793,0.96572,10,,,,,,,,,,,,,,,,,,,,,,,,,,,,,,,,,,,,,
528.8,0.83736,0.93553,10,,,,,,,,,,,,,,,,,,,,,,,,,,,,,,,,,,,,,
529.6,0.83612,0.9596,10,,,,,,,,,,,,,,,,,,,,,,,,,,,,,,,,,,,,,
530.4,0.83385,0.938,10,,,,,,,,,,,,,,,,,,,,,,,,,,,,,,,,,,,,,
531.2,0.83232,0.95344,10,,,,,,,,,,,,,,,,,,,,,,,,,,,,,,,,,,,,,
532,0.83147,0.93239,10,,,,,,,,,,,,,,,,,,,,,,,,,,,,,,,,,,,,,
532.8,0.83079,0.9193,10,,,,,,,,,,,,,,,,,,,,,,,,,,,,,,,,,,,,,
533.6,0.83034,0.92676,10,,,,,,,,,,,,,,,,,,,,,,,,,,,,,,,,,,,,,
534.4,0.82983,0.95166,10,,,,,,,,,,,,,,,,,,,,,,,,,,,,,,,,,,,,,
535.2,0.82881,0.88874,10,,,,,,,,,,,,,,,,,,,,,,,,,,,,,,,,,,,,,
536,0.8279,0.92294,10,,,,,,,,,,,,,,,,,,,,,,,,,,,,,,,,,,,,,
536.8,0.82716,0.90901,10,,,,,,,,,,,,,,,,,,,,,,,,,,,,,,,,,,,,,
537.6,0.8266,0.91433,10,,,,,,,,,,,,,,,,,,,,,,,,,,,,,,,,,,,,,
538.4,0.8262,0.88557,10,,,,,,,,,,,,,,,,,,,,,,,,,,,,,,,,,,,,,
539.2,0.82597,0.90837,10,,,,,,,,,,,,,,,,,,,,,,,,,,,,,,,,,,,,,
540,0.82592,0.90394,10,,,,,,,,,,,,,,,,,,,,,,,,,,,,,,,,,,,,,
540.8,0.82609,0.91405,10,,,,,,,,,,,,,,,,,,,,,,,,,,,,,,,,,,,,,
541.6,0.82614,0.86187,10,,,,,,,,,,,,,,,,,,,,,,,,,,,,,,,,,,,,,
542.4,0.8262,0.86331,10,,,,,,,,,,,,,,,,,,,,,,,,,,,,,,,,,,,,,
543.2,0.82626,0.85797,10,,,,,,,,,,,,,,,,,,,,,,,,,,,,,,,,,,,,,
543.902,1.24077,2.77084,10,,,,,,,,,,,,,,,,,,,,,,,,,,,,,,,,,,,,,
544.702,8.00961,239.99881,10,,,,,,,,,,,,,,,,,,,,,,,,,,,,,,,,,,,,,
545.502,14.67621,17.67013,10,,,,,,,,,,,,,,,,,,,,,,,,,,,,,,,,,,,,,
546.302,21.34282,11.17169,10,,,,,,,,,,,,,,,,,,,,,,,,,,,,,,,,,,,,,
547.102,28.00954,3.38546,10,,,,,,,,,,,,,,,,,,,,,,,,,,,,,,,,,,,,,
547.902,34.6762,0.06874,10,,,,,,,,,,,,,,,,,,,,,,,,,,,,,,,,,,,,,
548.702,41.34292,-4.12703,10,,,,,,,,,,,,,,,,,,,,,,,,,,,,,,,,,,,,,
549.502,48.00953,-4.71135,10,,,,,,,,,,,,,,,,,,,,,,,,,,,,,,,,,,,,,
550.302,54.67619,-4.80677,10,,,,,,,,,,,,,,,,,,,,,,,,,,,,,,,,,,,,,
551.102,61.34286,-4.81358,10,,,,,,,,,,,,,,,,,,,,,,,,,,,,,,,,,,,,,
551.206,62.20963,-4.74567,10,,,,,,,,,,,,,,,,,,,,,,,,,,,,,,,,,,,,,