File: combined_ligament_solver/data/processed/Data Sheet 3_S152635_PCL.csv
Specimen properties : Length,32,mm,Unnamed: 3,Unnamed: 4,Unnamed: 5,Unnamed: 6,Unnamed: 7,Unnamed: 8,Unnamed: 9,Unnamed: 10,Unnamed: 11,Stress-Strain,Unnamed: 13,Unnamed: 14,Unnamed: 15,Unnamed: 16,Unnamed: 17,Unnamed: 18,Unnamed: 19,Unnamed: 20,Unnamed: 21,Unnamed: 22,Unnamed: 23,Unnamed: 24,Unnamed: 25,Unnamed: 26,Unnamed: 27,Linear,Unnamed: 29,Unnamed: 30,Unnamed: 31,Unnamed: 32,Unnamed: 33,Modulus,Unnamed: 35,Failure,Unnamed: 37,Unnamed: 38,Unnamed: 39,Unnamed: 40
Cross Section Average,70.33500000000001,mm2,,,,,,,,,,Polynomial Coefficients,,,,,,,,,,,,,,,,Force,,Stress,Extension,Strain,,Secant,Tangent,Load,Stress,Extension,Strain,Stiffness
Time,Extension,Load,Total cycle count,,,Extension,Load,Strain,Stress,E-tan,,X6,-81244.83024841835,,,,,,,,,Strain,Stress,E-tan,,,,(N),,(MPa),(mm),(%),,(MPa),(MPa),(N),(MPa),(mm),(%),(N/mm)
(s),(mm),(N),,,,(mm),(N),(mm/mm),(MPa),(MPa),,X5,-29908.72525906942,,,,,,,,,(mm/mm),(MPa),(MPa),,,,260.95376994447207,,3.710155256194953,3.84,12,,30.917960468291277,48.77438453053791,601.74115,8.53584758655008,8.09999,25.31246875,67.9567109230396
0.6,0.17436,2.57227,0,,,5.61329,356.24677,0.14895906250000002,5.045488874671216,36.557034747507345,,,,,,,,,,,,0.006,0.003984211715509781,2.905072942019117,,,,,,,,,,,,,,,,
1.3,0.29104,4.31892,0,,,11.44667,591.90143,,,,,,,,,,,,,,,0.013,0.04744973058422184,8.581516854323075,,,,,,,,,,,,,,,,
2,0.40777,6.16495,0,,,17.28005,346.46838,,,,,,,,,,,,,,,0.02,0.12784933627594786,13.574291207333847,,,,,,,,,,,,,,,,
2.7,0.52456,8.30161,0,,,,,,,,,,,,,,,,,,,0.027,0.24084647828508374,17.994128032709344,,,,,,,,,,,,,,,,
3.4,0.6413,10.43339,0,,,,,,,,,,,,,,,,,,,0.034,0.38283486785228693,21.940403293708645,,,,,,,,,,,,,,,,
4.1,0.75792,12.57928,0,,,,,,,,,,,,,,,,,,,0.041,0.5508550528979194,25.500153738250628,,,,,,,,,,,,,,,,
4.8,0.87448,14.98888,0,,,,,,,,,,,,,,,,,,,0.048,0.7425041109269076,28.747093751974123,,,,,,,,,,,,,,,,
5.5,0.9911,17.64893,0,,,,,,,,,,,,,,,,,,,0.055,0.9558384599050173,31.74063221129727,,,,,,,,,,,,,,,,
6.2,1.10772,20.22331,0,,,,,,,,,,,,,,,,,,,0.062,1.1892697871065434,34.524889336475546,,,,,,,,,,,,,,,,
6.9,1.22451,23.07345,0,,,,,,,,,,,,,,,,,,,0.069,1.4414540959334174,37.12771354466301,,,,,,,,,,,,,,,,
7.6,1.34119,26.32518,0,,,,,,,,,,,,,,,,,,,0.076,1.7111738707057274,39.559698302971086,,,,,,,,,,,,,,,,
8.3,1.45775,29.95015,0,,,,,,,,,,,,,,,,,,,0.083,1.9972133594236567,41.81319898152732,,,,,,,,,,,,,,,,
9,1.57437,33.66727,0,,,,,,,,,,,,,,,,,,,0.09,2.2982269745008352,43.86134970653495,,,,,,,,,,,,,,,,
9.7,1.69105,37.7157,0,,,,,,,,,,,,,,,,,,,0.097,2.61260081146911,45.65708021333043,,,,,,,,,,,,,,,,
10.282,1.72176,37.66007,0.5,,,,,,,,,,,,,,,,,,,0.104,2.9383072856547283,47.13213269944956,,,,,,,,,,,,,,,,
10.982,1.60457,30.17298,0.5,,,,,,,,,,,,,,,,,,,0.111,3.2727528868259377,48.196078677679786,,,,,,,,,,,,,,,,
11.682,1.48784,24.31034,0.5,,,,,,,,,,,,,,,,,,,0.118,3.6126190518119974,48.7353358291209,,,,,,,,,,,,,,,,
12.382,1.37111,19.48271,0.5,,,,,,,,,,,,,,,,,,,0.125,3.953696155093616,48.61218485624437,,,,,,,,,,,,,,,,
13.082,1.25432,15.42485,0.5,,,,,,,,,,,,,,,,,,,0.132,4.290710617364794,47.66378633595631,,,,,,,,,,,,,,,,
13.782,1.1377,12.13203,0.5,,,,,,,,,,,,,,,,,,,0.139,4.617145132066082,45.70119757265441,,,,,,,,,,,,,,,,
14.482,1.02102,9.11538,0.5,,,,,,,,,,,,,,,,,,,0.146,4.925052009889271,42.50838945128428,,,,,,,,,,,,,,,,
15.182,0.9044,6.59905,0.5,,,,,,,,,,,,,,,,,,,0.153,5.204859641253469,37.841263290407454,,,,,,,,,,,,,,,,
15.882,0.78772,4.38845,0.5,,,,,,,,,,,,,,,,,,,0.16,5.445172076752618,31.426667695241907,,,,,,,,,,,,,,,,
16.582,0.6711,2.57031,0.5,,,,,,,,,,,,,,,,,,,0.167,5.632561725574436,22.961415410763994,,,,,,,,,,,,,,,,
17.282,0.55443,1.11946,0.5,,,,,,,,,,,,,,,,,,,0.174,5.751355171890708,12.111300174697515,,,,,,,,,,,,,,,,
17.736,0.61302,2.0728,1,,,,,,,,,,,,,,,,,,,0.181,,,,,,,,,,,,,,,,,,
18.436,0.7297,4.18003,1,,,,,,,,,,,,,,,,,,,0.188,,,,,,,,,,,,,,,,,,
19.136,0.84637,6.52514,1,,,,,,,,,,,,,,,,,,,0.195,,,,,,,,,,,,,,,,,,
19.836,0.96305,9.17572,1,,,,,,,,,,,,,,,,,,,,,,,,,,,,,,,,,,,,,
20.536,1.07973,12.06337,1,,,,,,,,,,,,,,,,,,,,,,,,,,,,,,,,,,,,,
21.236,1.19635,15.27575,1,,,,,,,,,,,,,,,,,,,,,,,,,,,,,,,,,,,,,
21.936,1.31314,18.92335,1,,,,,,,,,,,,,,,,,,,,,,,,,,,,,,,,,,,,,
22.636,1.42987,22.82279,1,,,,,,,,,,,,,,,,,,,,,,,,,,,,,,,,,,,,,
23.336,1.54655,27.38365,1,,,,,,,,,,,,,,,,,,,,,,,,,,,,,,,,,,,,,
24.036,1.66322,32.30977,1,,,,,,,,,,,,,,,,,,,,,,,,,,,,,,,,,,,,,
24.736,1.77979,37.50396,1,,,,,,,,,,,,,,,,,,,,,,,,,,,,,,,,,,,,,
25.254,1.79968,37.78086,1.5,,,,,,,,,,,,,,,,,,,,,,,,,,,,,,,,,,,,,
25.954,1.68255,30.39588,1.5,,,,,,,,,,,,,,,,,,,,,,,,,,,,,,,,,,,,,
26.654,1.56587,24.50524,1.5,,,,,,,,,,,,,,,,,,,,,,,,,,,,,,,,,,,,,
27.354,1.44919,19.62399,1.5,,,,,,,,,,,,,,,,,,,,,,,,,,,,,,,,,,,,,
28.054,1.33252,15.46633,1.5,,,,,,,,,,,,,,,,,,,,,,,,,,,,,,,,,,,,,
28.754,1.2159,12.03521,1.5,,,,,,,,,,,,,,,,,,,,,,,,,,,,,,,,,,,,,
29.454,1.09922,9.21772,1.5,,,,,,,,,,,,,,,,,,,,,,,,,,,,,,,,,,,,,
30.154,0.98249,6.49905,1.5,,,,,,,,,,,,,,,,,,,,,,,,,,,,,,,,,,,,,
30.854,0.86575,4.27689,1.5,,,,,,,,,,,,,,,,,,,,,,,,,,,,,,,,,,,,,
31.554,0.74913,2.46564,1.5,,,,,,,,,,,,,,,,,,,,,,,,,,,,,,,,,,,,,
32.238,0.63518,0.99563,2,,,,,,,,,,,,,,,,,,,,,,,,,,,,,,,,,,,,,
32.742,0.7187,2.37778,2,,,,,,,,,,,,,,,,,,,,,,,,,,,,,,,,,,,,,
33.442,0.83544,4.58072,2,,,,,,,,,,,,,,,,,,,,,,,,,,,,,,,,,,,,,
34.142,0.95206,7.08956,2,,,,,,,,,,,,,,,,,,,,,,,,,,,,,,,,,,,,,
34.842,1.06873,9.87376,2,,,,,,,,,,,,,,,,,,,,,,,,,,,,,,,,,,,,,
35.542,1.18535,12.87455,2,,,,,,,,,,,,,,,,,,,,,,,,,,,,,,,,,,,,,
36.242,1.30203,16.22654,2,,,,,,,,,,,,,,,,,,,,,,,,,,,,,,,,,,,,,
36.942,1.41876,20.09873,2,,,,,,,,,,,,,,,,,,,,,,,,,,,,,,,,,,,,,
37.642,1.53544,24.42342,2,,,,,,,,,,,,,,,,,,,,,,,,,,,,,,,,,,,,,
38.342,1.65206,29.32078,2,,,,,,,,,,,,,,,,,,,,,,,,,,,,,,,,,,,,,
39.042,1.76879,34.63067,2,,,,,,,,,,,,,,,,,,,,,,,,,,,,,,,,,,,,,
39.696,1.87776,40.01089,2.5,,,,,,,,,,,,,,,,,,,,,,,,,,,,,,,,,,,,,
40.298,1.77797,33.45429,2.5,,,,,,,,,,,,,,,,,,,,,,,,,,,,,,,,,,,,,
40.998,1.66118,26.9879,2.5,,,,,,,,,,,,,,,,,,,,,,,,,,,,,,,,,,,,,
41.698,1.54451,21.73015,2.5,,,,,,,,,,,,,,,,,,,,,,,,,,,,,,,,,,,,,
42.398,1.42777,17.17101,2.5,,,,,,,,,,,,,,,,,,,,,,,,,,,,,,,,,,,,,
43.098,1.31104,13.36391,2.5,,,,,,,,,,,,,,,,,,,,,,,,,,,,,,,,,,,,,
43.798,1.19442,10.26031,2.5,,,,,,,,,,,,,,,,,,,,,,,,,,,,,,,,,,,,,
44.498,1.07774,7.58781,2.5,,,,,,,,,,,,,,,,,,,,,,,,,,,,,,,,,,,,,
45.198,0.96101,5.09723,2.5,,,,,,,,,,,,,,,,,,,,,,,,,,,,,,,,,,,,,
45.898,0.84433,3.04109,2.5,,,,,,,,,,,,,,,,,,,,,,,,,,,,,,,,,,,,,
46.598,0.72783,1.52101,2.5,,,,,,,,,,,,,,,,,,,,,,,,,,,,,,,,,,,,,
47.046,0.72029,1.43161,3,,,,,,,,,,,,,,,,,,,,,,,,,,,,,,,,,,,,,
47.746,0.83736,3.64806,3,,,,,,,,,,,,,,,,,,,,,,,,,,,,,,,,,,,,,
48.446,0.9541,6.00566,3,,,,,,,,,,,,,,,,,,,,,,,,,,,,,,,,,,,,,
49.146,1.07077,8.64798,3,,,,,,,,,,,,,,,,,,,,,,,,,,,,,,,,,,,,,
49.846,1.18734,11.6475,3,,,,,,,,,,,,,,,,,,,,,,,,,,,,,,,,,,,,,
50.546,1.30401,14.84894,3,,,,,,,,,,,,,,,,,,,,,,,,,,,,,,,,,,,,,
51.246,1.42063,18.61813,3,,,,,,,,,,,,,,,,,,,,,,,,,,,,,,,,,,,,,
51.946,1.53742,22.90089,3,,,,,,,,,,,,,,,,,,,,,,,,,,,,,,,,,,,,,
52.646,1.65416,27.69848,3,,,,,,,,,,,,,,,,,,,,,,,,,,,,,,,,,,,,,
53.346,1.77089,32.99272,3,,,,,,,,,,,,,,,,,,,,,,,,,,,,,,,,,,,,,
54.046,1.88751,38.76891,3,,,,,,,,,,,,,,,,,,,,,,,,,,,,,,,,,,,,,
54.588,1.84427,35.62328,3.5,,,,,,,,,,,,,,,,,,,,,,,,,,,,,,,,,,,,,
55.288,1.72748,28.77163,3.5,,,,,,,,,,,,,,,,,,,,,,,,,,,,,,,,,,,,,
55.988,1.61081,23.15924,3.5,,,,,,,,,,,,,,,,,,,,,,,,,,,,,,,,,,,,,
56.688,1.49424,18.37544,3.5,,,,,,,,,,,,,,,,,,,,,,,,,,,,,,,,,,,,,
57.388,1.37757,14.35595,3.5,,,,,,,,,,,,,,,,,,,,,,,,,,,,,,,,,,,,,
58.088,1.26089,11.05891,3.5,,,,,,,,,,,,,,,,,,,,,,,,,,,,,,,,,,,,,
58.788,1.1441,8.22476,3.5,,,,,,,,,,,,,,,,,,,,,,,,,,,,,,,,,,,,,
59.488,1.02731,5.73098,3.5,,,,,,,,,,,,,,,,,,,,,,,,,,,,,,,,,,,,,
60.188,0.91075,3.5585,3.5,,,,,,,,,,,,,,,,,,,,,,,,,,,,,,,,,,,,,
60.888,0.79401,1.81241,3.5,,,,,,,,,,,,,,,,,,,,,,,,,,,,,,,,,,,,,
61.362,0.74449,1.08224,4,,,,,,,,,,,,,,,,,,,,,,,,,,,,,,,,,,,,,
62.062,0.86621,3.36355,4,,,,,,,,,,,,,,,,,,,,,,,,,,,,,,,,,,,,,
62.762,0.98283,5.71131,4,,,,,,,,,,,,,,,,,,,,,,,,,,,,,,,,,,,,,
63.462,1.09945,8.45336,4,,,,,,,,,,,,,,,,,,,,,,,,,,,,,,,,,,,,,
64.162,1.21612,11.42243,4,,,,,,,,,,,,,,,,,,,,,,,,,,,,,,,,,,,,,
64.862,1.33286,14.74453,4,,,,,,,,,,,,,,,,,,,,,,,,,,,,,,,,,,,,,
65.562,1.44948,18.40471,4,,,,,,,,,,,,,,,,,,,,,,,,,,,,,,,,,,,,,
66.262,1.5661,22.77633,4,,,,,,,,,,,,,,,,,,,,,,,,,,,,,,,,,,,,,
66.962,1.68272,27.61596,4,,,,,,,,,,,,,,,,,,,,,,,,,,,,,,,,,,,,,
67.662,1.79939,33.03125,4,,,,,,,,,,,,,,,,,,,,,,,,,,,,,,,,,,,,,
68.362,1.91607,38.91324,4,,,,,,,,,,,,,,,,,,,,,,,,,,,,,,,,,,,,,
68.884,1.86938,35.61174,4.5,,,,,,,,,,,,,,,,,,,,,,,,,,,,,,,,,,,,,
69.584,1.75276,28.77283,4.5,,,,,,,,,,,,,,,,,,,,,,,,,,,,,,,,,,,,,
70.284,1.63614,23.03193,4.5,,,,,,,,,,,,,,,,,,,,,,,,,,,,,,,,,,,,,
70.984,1.51952,18.32667,4.5,,,,,,,,,,,,,,,,,,,,,,,,,,,,,,,,,,,,,
71.684,1.40284,14.30699,4.5,,,,,,,,,,,,,,,,,,,,,,,,,,,,,,,,,,,,,
72.384,1.28611,10.94799,4.5,,,,,,,,,,,,,,,,,,,,,,,,,,,,,,,,,,,,,
73.084,1.16949,8.11981,4.5,,,,,,,,,,,,,,,,,,,,,,,,,,,,,,,,,,,,,
73.784,1.05287,5.54686,4.5,,,,,,,,,,,,,,,,,,,,,,,,,,,,,,,,,,,,,
74.484,0.93619,3.47081,4.5,,,,,,,,,,,,,,,,,,,,,,,,,,,,,,,,,,,,,
75.184,0.81951,1.72374,4.5,,,,,,,,,,,,,,,,,,,,,,,,,,,,,,,,,,,,,
75.636,0.77356,1.0678,5,,,,,,,,,,,,,,,,,,,,,,,,,,,,,,,,,,,,,
76.336,0.89505,3.40457,5,,,,,,,,,,,,,,,,,,,,,,,,,,,,,,,,,,,,,
77.036,1.01167,5.71274,5,,,,,,,,,,,,,,,,,,,,,,,,,,,,,,,,,,,,,
77.736,1.1284,8.44825,5,,,,,,,,,,,,,,,,,,,,,,,,,,,,,,,,,,,,,
78.436,1.24508,11.47415,5,,,,,,,,,,,,,,,,,,,,,,,,,,,,,,,,,,,,,
79.136,1.36176,14.77878,5,,,,,,,,,,,,,,,,,,,,,,,,,,,,,,,,,,,,,
79.836,1.47832,18.54345,5,,,,,,,,,,,,,,,,,,,,,,,,,,,,,,,,,,,,,
80.536,1.59505,23.00987,5,,,,,,,,,,,,,,,,,,,,,,,,,,,,,,,,,,,,,
81.236,1.71184,27.89588,5,,,,,,,,,,,,,,,,,,,,,,,,,,,,,,,,,,,,,
81.936,1.82852,33.36559,5,,,,,,,,,,,,,,,,,,,,,,,,,,,,,,,,,,,,,
82.636,1.94525,39.38225,5,,,,,,,,,,,,,,,,,,,,,,,,,,,,,,,,,,,,,
83.21,1.87374,34.5503,5.5,,,,,,,,,,,,,,,,,,,,,,,,,,,,,,,,,,,,,
83.91,1.75712,27.88871,5.5,,,,,,,,,,,,,,,,,,,,,,,,,,,,,,,,,,,,,
84.61,1.64033,22.32865,5.5,,,,,,,,,,,,,,,,,,,,,,,,,,,,,,,,,,,,,
85.31,1.52371,17.7133,5.5,,,,,,,,,,,,,,,,,,,,,,,,,,,,,,,,,,,,,
86.01,1.40715,13.69929,5.5,,,,,,,,,,,,,,,,,,,,,,,,,,,,,,,,,,,,,
86.71,1.29047,10.44304,5.5,,,,,,,,,,,,,,,,,,,,,,,,,,,,,,,,,,,,,
87.41,1.17385,7.68202,5.5,,,,,,,,,,,,,,,,,,,,,,,,,,,,,,,,,,,,,
88.11,1.05717,5.22145,5.5,,,,,,,,,,,,,,,,,,,,,,,,,,,,,,,,,,,,,
88.81,0.9405,3.08274,5.5,,,,,,,,,,,,,,,,,,,,,,,,,,,,,,,,,,,,,
89.51,0.82376,1.46325,5.5,,,,,,,,,,,,,,,,,,,,,,,,,,,,,,,,,,,,,
89.916,0.82342,1.52065,6,,,,,,,,,,,,,,,,,,,,,,,,,,,,,,,,,,,,,
90.616,0.94044,3.76968,6,,,,,,,,,,,,,,,,,,,,,,,,,,,,,,,,,,,,,
91.316,1.057,6.18724,6,,,,,,,,,,,,,,,,,,,,,,,,,,,,,,,,,,,,,
92.016,1.17368,8.99667,6,,,,,,,,,,,,,,,,,,,,,,,,,,,,,,,,,,,,,
92.716,1.29041,12.0286,6,,,,,,,,,,,,,,,,,,,,,,,,,,,,,,,,,,,,,
93.416,1.40709,15.59366,6,,,,,,,,,,,,,,,,,,,,,,,,,,,,,,,,,,,,,
94.116,1.52382,19.42623,6,,,,,,,,,,,,,,,,,,,,,,,,,,,,,,,,,,,,,
94.816,1.64039,23.95647,6,,,,,,,,,,,,,,,,,,,,,,,,,,,,,,,,,,,,,
95.516,1.75701,29.09379,6,,,,,,,,,,,,,,,,,,,,,,,,,,,,,,,,,,,,,
96.216,1.87368,34.72367,6,,,,,,,,,,,,,,,,,,,,,,,,,,,,,,,,,,,,,
96.818,1.97404,40.03181,6.5,,,,,,,,,,,,,,,,,,,,,,,,,,,,,,,,,,,,,
97.518,1.85714,32.44946,6.5,,,,,,,,,,,,,,,,,,,,,,,,,,,,,,,,,,,,,
98.218,1.74052,26.0945,6.5,,,,,,,,,,,,,,,,,,,,,,,,,,,,,,,,,,,,,
98.918,1.6239,20.90549,6.5,,,,,,,,,,,,,,,,,,,,,,,,,,,,,,,,,,,,,
99.618,1.50728,16.34356,6.5,,,,,,,,,,,,,,,,,,,,,,,,,,,,,,,,,,,,,
100.318,1.39054,12.56595,6.5,,,,,,,,,,,,,,,,,,,,,,,,,,,,,,,,,,,,,
101.018,1.27381,9.57471,6.5,,,,,,,,,,,,,,,,,,,,,,,,,,,,,,,,,,,,,
101.718,1.15719,6.79675,6.5,,,,,,,,,,,,,,,,,,,,,,,,,,,,,,,,,,,,,
102.418,1.04046,4.46632,6.5,,,,,,,,,,,,,,,,,,,,,,,,,,,,,,,,,,,,,
103.118,0.92384,2.47864,6.5,,,,,,,,,,,,,,,,,,,,,,,,,,,,,,,,,,,,,
103.798,0.81045,0.99379,7,,,,,,,,,,,,,,,,,,,,,,,,,,,,,,,,,,,,,
104.302,0.89403,2.45603,7,,,,,,,,,,,,,,,,,,,,,,,,,,,,,,,,,,,,,
105.002,1.01071,4.68731,7,,,,,,,,,,,,,,,,,,,,,,,,,,,,,,,,,,,,,
105.702,1.12738,7.32438,7,,,,,,,,,,,,,,,,,,,,,,,,,,,,,,,,,,,,,
106.402,1.24406,10.25508,7,,,,,,,,,,,,,,,,,,,,,,,,,,,,,,,,,,,,,
107.102,1.36068,13.50493,7,,,,,,,,,,,,,,,,,,,,,,,,,,,,,,,,,,,,,
107.802,1.47736,17.19364,7,,,,,,,,,,,,,,,,,,,,,,,,,,,,,,,,,,,,,
108.502,1.59403,21.41191,7,,,,,,,,,,,,,,,,,,,,,,,,,,,,,,,,,,,,,
109.202,1.71082,26.24359,7,,,,,,,,,,,,,,,,,,,,,,,,,,,,,,,,,,,,,
109.902,1.82761,31.62888,7,,,,,,,,,,,,,,,,,,,,,,,,,,,,,,,,,,,,,
110.602,1.94423,37.54356,7,,,,,,,,,,,,,,,,,,,,,,,,,,,,,,,,,,,,,
111.174,1.9393,36.75691,7.5,,,,,,,,,,,,,,,,,,,,,,,,,,,,,,,,,,,,,
111.874,1.82246,29.60072,7.5,,,,,,,,,,,,,,,,,,,,,,,,,,,,,,,,,,,,,
112.574,1.70567,23.71108,7.5,,,,,,,,,,,,,,,,,,,,,,,,,,,,,,,,,,,,,
113.274,1.58905,18.91775,7.5,,,,,,,,,,,,,,,,,,,,,,,,,,,,,,,,,,,,,
113.974,1.47231,14.65092,7.5,,,,,,,,,,,,,,,,,,,,,,,,,,,,,,,,,,,,,
114.674,1.35575,11.07677,7.5,,,,,,,,,,,,,,,,,,,,,,,,,,,,,,,,,,,,,
115.374,1.23913,8.26418,7.5,,,,,,,,,,,,,,,,,,,,,,,,,,,,,,,,,,,,,
116.074,1.12251,5.68831,7.5,,,,,,,,,,,,,,,,,,,,,,,,,,,,,,,,,,,,,
116.774,1.00578,3.55309,7.5,,,,,,,,,,,,,,,,,,,,,,,,,,,,,,,,,,,,,
117.474,0.88916,1.74016,7.5,,,,,,,,,,,,,,,,,,,,,,,,,,,,,,,,,,,,,
117.936,0.8415,1.03495,8,,,,,,,,,,,,,,,,,,,,,,,,,,,,,,,,,,,,,
118.636,0.96305,3.46038,8,,,,,,,,,,,,,,,,,,,,,,,,,,,,,,,,,,,,,
119.336,1.07967,5.81741,8,,,,,,,,,,,,,,,,,,,,,,,,,,,,,,,,,,,,,
120.036,1.19635,8.59687,8,,,,,,,,,,,,,,,,,,,,,,,,,,,,,,,,,,,,,
120.736,1.31314,11.65095,8,,,,,,,,,,,,,,,,,,,,,,,,,,,,,,,,,,,,,
121.436,1.42981,15.13612,8,,,,,,,,,,,,,,,,,,,,,,,,,,,,,,,,,,,,,
122.136,1.54649,19.02231,8,,,,,,,,,,,,,,,,,,,,,,,,,,,,,,,,,,,,,
122.836,1.66322,23.56007,8,,,,,,,,,,,,,,,,,,,,,,,,,,,,,,,,,,,,,
123.536,1.77984,28.67545,8,,,,,,,,,,,,,,,,,,,,,,,,,,,,,,,,,,,,,
124.236,1.89646,34.36275,8,,,,,,,,,,,,,,,,,,,,,,,,,,,,,,,,,,,,,
124.872,2.0026,40.00702,8.5,,,,,,,,,,,,,,,,,,,,,,,,,,,,,,,,,,,,,
125.474,1.90253,33.4192,8.5,,,,,,,,,,,,,,,,,,,,,,,,,,,,,,,,,,,,,
126.174,1.78591,26.85468,8.5,,,,,,,,,,,,,,,,,,,,,,,,,,,,,,,,,,,,,
126.874,1.66923,21.54518,8.5,,,,,,,,,,,,,,,,,,,,,,,,,,,,,,,,,,,,,
127.574,1.55255,16.9131,8.5,,,,,,,,,,,,,,,,,,,,,,,,,,,,,,,,,,,,,
128.274,1.43582,13.0537,8.5,,,,,,,,,,,,,,,,,,,,,,,,,,,,,,,,,,,,,
128.974,1.31914,9.75033,8.5,,,,,,,,,,,,,,,,,,,,,,,,,,,,,,,,,,,,,
129.674,1.20252,7.07818,8.5,,,,,,,,,,,,,,,,,,,,,,,,,,,,,,,,,,,,,
130.374,1.08579,4.61486,8.5,,,,,,,,,,,,,,,,,,,,,,,,,,,,,,,,,,,,,
131.074,0.96911,2.59086,8.5,,,,,,,,,,,,,,,,,,,,,,,,,,,,,,,,,,,,,
131.768,0.85334,0.99582,9,,,,,,,,,,,,,,,,,,,,,,,,,,,,,,,,,,,,,
132.272,0.93704,2.57327,9,,,,,,,,,,,,,,,,,,,,,,,,,,,,,,,,,,,,,
132.972,1.05372,4.83406,9,,,,,,,,,,,,,,,,,,,,,,,,,,,,,,,,,,,,,
133.672,1.17039,7.54484,9,,,,,,,,,,,,,,,,,,,,,,,,,,,,,,,,,,,,,
134.372,1.28713,10.55352,9,,,,,,,,,,,,,,,,,,,,,,,,,,,,,,,,,,,,,
135.072,1.40375,13.78016,9,,,,,,,,,,,,,,,,,,,,,,,,,,,,,,,,,,,,,
135.772,1.52037,17.49081,9,,,,,,,,,,,,,,,,,,,,,,,,,,,,,,,,,,,,,
136.472,1.63704,21.89092,9,,,,,,,,,,,,,,,,,,,,,,,,,,,,,,,,,,,,,
137.172,1.75372,26.86967,9,,,,,,,,,,,,,,,,,,,,,,,,,,,,,,,,,,,,,
137.872,1.87045,32.4092,9,,,,,,,,,,,,,,,,,,,,,,,,,,,,,,,,,,,,,
138.572,1.98702,38.56419,9,,,,,,,,,,,,,,,,,,,,,,,,,,,,,,,,,,,,,
139.14,1.94826,35.67272,9.5,,,,,,,,,,,,,,,,,,,,,,,,,,,,,,,,,,,,,
139.84,1.83158,28.76132,9.5,,,,,,,,,,,,,,,,,,,,,,,,,,,,,,,,,,,,,
140.54,1.7149,22.94428,9.5,,,,,,,,,,,,,,,,,,,,,,,,,,,,,,,,,,,,,
141.24,1.59811,18.17672,9.5,,,,,,,,,,,,,,,,,,,,,,,,,,,,,,,,,,,,,
141.94,1.48127,14.07803,9.5,,,,,,,,,,,,,,,,,,,,,,,,,,,,,,,,,,,,,
142.64,1.3647,10.63025,9.5,,,,,,,,,,,,,,,,,,,,,,,,,,,,,,,,,,,,,
143.34,1.24803,7.82979,9.5,,,,,,,,,,,,,,,,,,,,,,,,,,,,,,,,,,,,,
144.04,1.13146,5.30916,9.5,,,,,,,,,,,,,,,,,,,,,,,,,,,,,,,,,,,,,
144.74,1.01467,3.10693,9.5,,,,,,,,,,,,,,,,,,,,,,,,,,,,,,,,,,,,,
145.44,0.89805,1.42305,9.5,,,,,,,,,,,,,,,,,,,,,,,,,,,,,,,,,,,,,
145.944,0.83827,0.701,10,,,,,,,,,,,,,,,,,,,,,,,,,,,,,,,,,,,,,
146.644,0.83923,0.75706,10,,,,,,,,,,,,,,,,,,,,,,,,,,,,,,,,,,,,,
147.344,0.87788,1.4963,10,,,,,,,,,,,,,,,,,,,,,,,,,,,,,,,,,,,,,
148.044,0.88808,1.64551,10,,,,,,,,,,,,,,,,,,,,,,,,,,,,,,,,,,,,,
148.744,0.87556,1.53402,10,,,,,,,,,,,,,,,,,,,,,,,,,,,,,,,,,,,,,
149.444,0.85266,1.15758,10,,,,,,,,,,,,,,,,,,,,,,,,,,,,,,,,,,,,,
150.144,0.85283,1.12999,10,,,,,,,,,,,,,,,,,,,,,,,,,,,,,,,,,,,,,
150.844,0.85323,1.1389,10,,,,,,,,,,,,,,,,,,,,,,,,,,,,,,,,,,,,,
151.544,0.85453,1.19657,10,,,,,,,,,,,,,,,,,,,,,,,,,,,,,,,,,,,,,
152.244,0.85776,1.25146,10,,,,,,,,,,,,,,,,,,,,,,,,,,,,,,,,,,,,,
152.944,0.86258,1.36511,10,,,,,,,,,,,,,,,,,,,,,,,,,,,,,,,,,,,,,
153.644,0.86315,1.44285,10,,,,,,,,,,,,,,,,,,,,,,,,,,,,,,,,,,,,,
154.344,0.86292,1.48959,10,,,,,,,,,,,,,,,,,,,,,,,,,,,,,,,,,,,,,
155.044,0.86264,1.42813,10,,,,,,,,,,,,,,,,,,,,,,,,,,,,,,,,,,,,,
155.744,0.86043,1.4511,10,,,,,,,,,,,,,,,,,,,,,,,,,,,,,,,,,,,,,
156.444,0.85544,1.33343,10,,,,,,,,,,,,,,,,,,,,,,,,,,,,,,,,,,,,,
157.144,0.85232,1.29654,10,,,,,,,,,,,,,,,,,,,,,,,,,,,,,,,,,,,,,
157.844,0.85074,1.30743,10,,,,,,,,,,,,,,,,,,,,,,,,,,,,,,,,,,,,,
158.544,0.84989,1.29931,10,,,,,,,,,,,,,,,,,,,,,,,,,,,,,,,,,,,,,
159.244,0.84943,1.26676,10,,,,,,,,,,,,,,,,,,,,,,,,,,,,,,,,,,,,,
159.944,0.84926,1.33598,10,,,,,,,,,,,,,,,,,,,,,,,,,,,,,,,,,,,,,
160.644,0.84904,1.35893,10,,,,,,,,,,,,,,,,,,,,,,,,,,,,,,,,,,,,,
161.344,0.84887,1.32675,10,,,,,,,,,,,,,,,,,,,,,,,,,,,,,,,,,,,,,
162.044,0.84858,1.31204,10,,,,,,,,,,,,,,,,,,,,,,,,,,,,,,,,,,,,,
162.744,0.84813,1.33778,10,,,,,,,,,,,,,,,,,,,,,,,,,,,,,,,,,,,,,
163.444,0.84745,1.32123,10,,,,,,,,,,,,,,,,,,,,,,,,,,,,,,,,,,,,,
164.144,0.84683,1.31689,10,,,,,,,,,,,,,,,,,,,,,,,,,,,,,,,,,,,,,
164.844,0.84598,1.2813,10,,,,,,,,,,,,,,,,,,,,,,,,,,,,,,,,,,,,,
165.544,0.84558,1.27947,10,,,,,,,,,,,,,,,,,,,,,,,,,,,,,,,,,,,,,
166.244,0.84541,1.2672,10,,,,,,,,,,,,,,,,,,,,,,,,,,,,,,,,,,,,,
166.944,0.8453,1.3115,10,,,,,,,,,,,,,,,,,,,,,,,,,,,,,,,,,,,,,
167.644,0.84541,1.22615,10,,,,,,,,,,,,,,,,,,,,,,,,,,,,,,,,,,,,,
168.344,0.84541,1.32964,10,,,,,,,,,,,,,,,,,,,,,,,,,,,,,,,,,,,,,
169.044,0.84535,1.28213,10,,,,,,,,,,,,,,,,,,,,,,,,,,,,,,,,,,,,,
169.744,0.84547,1.34485,10,,,,,,,,,,,,,,,,,,,,,,,,,,,,,,,,,,,,,
170.444,0.84547,1.34113,10,,,,,,,,,,,,,,,,,,,,,,,,,,,,,,,,,,,,,
171.144,0.84541,1.31375,10,,,,,,,,,,,,,,,,,,,,,,,,,,,,,,,,,,,,,
171.844,0.84541,1.33147,10,,,,,,,,,,,,,,,,,,,,,,,,,,,,,,,,,,,,,
172.544,0.84541,1.31119,10,,,,,,,,,,,,,,,,,,,,,,,,,,,,,,,,,,,,,
173.244,0.84541,1.25073,10,,,,,,,,,,,,,,,,,,,,,,,,,,,,,,,,,,,,,
173.944,0.84547,1.31423,10,,,,,,,,,,,,,,,,,,,,,,,,,,,,,,,,,,,,,
174.644,0.84547,1.31954,10,,,,,,,,,,,,,,,,,,,,,,,,,,,,,,,,,,,,,
175.344,0.8453,1.42656,10,,,,,,,,,,,,,,,,,,,,,,,,,,,,,,,,,,,,,
176.044,0.84524,1.36089,10,,,,,,,,,,,,,,,,,,,,,,,,,,,,,,,,,,,,,
176.744,0.84479,1.47451,10,,,,,,,,,,,,,,,,,,,,,,,,,,,,,,,,,,,,,
177.444,0.84246,1.32902,10,,,,,,,,,,,,,,,,,,,,,,,,,,,,,,,,,,,,,
178.144,0.83997,1.22899,10,,,,,,,,,,,,,,,,,,,,,,,,,,,,,,,,,,,,,
178.844,0.83935,1.30133,10,,,,,,,,,,,,,,,,,,,,,,,,,,,,,,,,,,,,,
179.544,0.83923,1.25808,10,,,,,,,,,,,,,,,,,,,,,,,,,,,,,,,,,,,,,
180.244,0.83912,1.26037,10,,,,,,,,,,,,,,,,,,,,,,,,,,,,,,,,,,,,,
180.944,0.83929,1.29704,10,,,,,,,,,,,,,,,,,,,,,,,,,,,,,,,,,,,,,
181.644,0.83935,1.29107,10,,,,,,,,,,,,,,,,,,,,,,,,,,,,,,,,,,,,,
182.344,0.83946,1.21923,10,,,,,,,,,,,,,,,,,,,,,,,,,,,,,,,,,,,,,
183.044,0.83957,1.26988,10,,,,,,,,,,,,,,,,,,,,,,,,,,,,,,,,,,,,,
183.744,0.83969,1.33747,10,,,,,,,,,,,,,,,,,,,,,,,,,,,,,,,,,,,,,
184.444,0.83991,1.22486,10,,,,,,,,,,,,,,,,,,,,,,,,,,,,,,,,,,,,,
185.144,0.84025,1.26682,10,,,,,,,,,,,,,,,,,,,,,,,,,,,,,,,,,,,,,
185.844,0.84065,1.23895,10,,,,,,,,,,,,,,,,,,,,,,,,,,,,,,,,,,,,,
186.544,0.84156,1.29746,10,,,,,,,,,,,,,,,,,,,,,,,,,,,,,,,,,,,,,
187.244,0.84252,1.30765,10,,,,,,,,,,,,,,,,,,,,,,,,,,,,,,,,,,,,,
187.944,0.8432,1.28693,10,,,,,,,,,,,,,,,,,,,,,,,,,,,,,,,,,,,,,
188.644,0.84348,1.26321,10,,,,,,,,,,,,,,,,,,,,,,,,,,,,,,,,,,,,,
189.344,0.84365,1.42763,10,,,,,,,,,,,,,,,,,,,,,,,,,,,,,,,,,,,,,
190.044,0.84354,1.29974,10,,,,,,,,,,,,,,,,,,,,,,,,,,,,,,,,,,,,,
190.744,0.84348,1.35363,10,,,,,,,,,,,,,,,,,,,,,,,,,,,,,,,,,,,,,
191.444,0.84337,1.33361,10,,,,,,,,,,,,,,,,,,,,,,,,,,,,,,,,,,,,,
192.144,0.84326,1.38298,10,,,,,,,,,,,,,,,,,,,,,,,,,,,,,,,,,,,,,
192.844,0.84309,1.37208,10,,,,,,,,,,,,,,,,,,,,,,,,,,,,,,,,,,,,,
193.544,0.84269,1.39721,10,,,,,,,,,,,,,,,,,,,,,,,,,,,,,,,,,,,,,
194.244,0.84218,1.34824,10,,,,,,,,,,,,,,,,,,,,,,,,,,,,,,,,,,,,,
194.944,0.8411,1.33915,10,,,,,,,,,,,,,,,,,,,,,,,,,,,,,,,,,,,,,
195.644,0.83986,1.37844,10,,,,,,,,,,,,,,,,,,,,,,,,,,,,,,,,,,,,,
196.344,0.83878,1.29562,10,,,,,,,,,,,,,,,,,,,,,,,,,,,,,,,,,,,,,
197.044,0.83816,1.31465,10,,,,,,,,,,,,,,,,,,,,,,,,,,,,,,,,,,,,,
197.744,0.83759,1.27546,10,,,,,,,,,,,,,,,,,,,,,,,,,,,,,,,,,,,,,
198.444,0.83719,1.30154,10,,,,,,,,,,,,,,,,,,,,,,,,,,,,,,,,,,,,,
199.144,0.83691,1.36017,10,,,,,,,,,,,,,,,,,,,,,,,,,,,,,,,,,,,,,
199.844,0.83668,1.28721,10,,,,,,,,,,,,,,,,,,,,,,,,,,,,,,,,,,,,,
200.544,0.8368,1.26667,10,,,,,,,,,,,,,,,,,,,,,,,,,,,,,,,,,,,,,
201.244,0.8368,1.27746,10,,,,,,,,,,,,,,,,,,,,,,,,,,,,,,,,,,,,,
201.944,0.8368,1.31816,10,,,,,,,,,,,,,,,,,,,,,,,,,,,,,,,,,,,,,
202.644,0.83697,1.23689,10,,,,,,,,,,,,,,,,,,,,,,,,,,,,,,,,,,,,,
203.344,0.83702,1.31625,10,,,,,,,,,,,,,,,,,,,,,,,,,,,,,,,,,,,,,
204.044,0.83714,1.26627,10,,,,,,,,,,,,,,,,,,,,,,,,,,,,,,,,,,,,,
204.744,0.83714,1.28586,10,,,,,,,,,,,,,,,,,,,,,,,,,,,,,,,,,,,,,
205.444,0.83725,1.28381,10,,,,,,,,,,,,,,,,,,,,,,,,,,,,,,,,,,,,,
206.144,0.83742,1.27957,10,,,,,,,,,,,,,,,,,,,,,,,,,,,,,,,,,,,,,
206.844,0.83765,1.25315,10,,,,,,,,,,,,,,,,,,,,,,,,,,,,,,,,,,,,,
207.544,0.83787,1.33365,10,,,,,,,,,,,,,,,,,,,,,,,,,,,,,,,,,,,,,
208.244,0.8381,1.31341,10,,,,,,,,,,,,,,,,,,,,,,,,,,,,,,,,,,,,,
208.944,0.83838,1.29784,10,,,,,,,,,,,,,,,,,,,,,,,,,,,,,,,,,,,,,
209.644,0.83872,1.27268,10,,,,,,,,,,,,,,,,,,,,,,,,,,,,,,,,,,,,,
210.344,0.83895,1.33375,10,,,,,,,,,,,,,,,,,,,,,,,,,,,,,,,,,,,,,
211.044,0.8394,1.2553,10,,,,,,,,,,,,,,,,,,,,,,,,,,,,,,,,,,,,,
211.744,0.83986,1.29237,10,,,,,,,,,,,,,,,,,,,,,,,,,,,,,,,,,,,,,
212.444,0.84025,1.28914,10,,,,,,,,,,,,,,,,,,,,,,,,,,,,,,,,,,,,,
213.144,0.84059,1.32278,10,,,,,,,,,,,,,,,,,,,,,,,,,,,,,,,,,,,,,
213.844,0.84082,1.3174,10,,,,,,,,,,,,,,,,,,,,,,,,,,,,,,,,,,,,,
214.544,0.84088,1.33299,10,,,,,,,,,,,,,,,,,,,,,,,,,,,,,,,,,,,,,
215.244,0.84082,1.32304,10,,,,,,,,,,,,,,,,,,,,,,,,,,,,,,,,,,,,,
215.944,0.84082,1.32544,10,,,,,,,,,,,,,,,,,,,,,,,,,,,,,,,,,,,,,
216.644,0.84076,1.35131,10,,,,,,,,,,,,,,,,,,,,,,,,,,,,,,,,,,,,,
217.344,0.84071,1.33179,10,,,,,,,,,,,,,,,,,,,,,,,,,,,,,,,,,,,,,
218.044,0.84065,1.25439,10,,,,,,,,,,,,,,,,,,,,,,,,,,,,,,,,,,,,,
218.744,0.84059,1.34158,10,,,,,,,,,,,,,,,,,,,,,,,,,,,,,,,,,,,,,
219.444,0.84042,1.30139,10,,,,,,,,,,,,,,,,,,,,,,,,,,,,,,,,,,,,,
220.144,0.84008,1.34321,10,,,,,,,,,,,,,,,,,,,,,,,,,,,,,,,,,,,,,
220.844,0.83963,1.36942,10,,,,,,,,,,,,,,,,,,,,,,,,,,,,,,,,,,,,,
221.544,0.83884,1.37997,10,,,,,,,,,,,,,,,,,,,,,,,,,,,,,,,,,,,,,
222.244,0.83782,1.32266,10,,,,,,,,,,,,,,,,,,,,,,,,,,,,,,,,,,,,,
222.944,0.83663,1.35866,10,,,,,,,,,,,,,,,,,,,,,,,,,,,,,,,,,,,,,
223.644,0.83566,1.29993,10,,,,,,,,,,,,,,,,,,,,,,,,,,,,,,,,,,,,,
224.344,0.83476,1.24328,10,,,,,,,,,,,,,,,,,,,,,,,,,,,,,,,,,,,,,
225.044,0.83442,1.30943,10,,,,,,,,,,,,,,,,,,,,,,,,,,,,,,,,,,,,,
225.744,0.8343,1.25441,10,,,,,,,,,,,,,,,,,,,,,,,,,,,,,,,,,,,,,
226.444,0.83442,1.27469,10,,,,,,,,,,,,,,,,,,,,,,,,,,,,,,,,,,,,,
227.144,0.83447,1.31058,10,,,,,,,,,,,,,,,,,,,,,,,,,,,,,,,,,,,,,
227.844,0.83447,1.35137,10,,,,,,,,,,,,,,,,,,,,,,,,,,,,,,,,,,,,,
228.544,0.83464,1.27086,10,,,,,,,,,,,,,,,,,,,,,,,,,,,,,,,,,,,,,
229.244,0.83476,1.25398,10,,,,,,,,,,,,,,,,,,,,,,,,,,,,,,,,,,,,,
229.944,0.83498,1.23271,10,,,,,,,,,,,,,,,,,,,,,,,,,,,,,,,,,,,,,
230.644,0.83538,1.20423,10,,,,,,,,,,,,,,,,,,,,,,,,,,,,,,,,,,,,,
231.344,0.83589,1.28304,10,,,,,,,,,,,,,,,,,,,,,,,,,,,,,,,,,,,,,
232.044,0.83708,1.27482,10,,,,,,,,,,,,,,,,,,,,,,,,,,,,,,,,,,,,,
232.744,0.8381,1.28398,10,,,,,,,,,,,,,,,,,,,,,,,,,,,,,,,,,,,,,
233.444,0.83884,1.29604,10,,,,,,,,,,,,,,,,,,,,,,,,,,,,,,,,,,,,,
234.144,0.83969,1.31758,10,,,,,,,,,,,,,,,,,,,,,,,,,,,,,,,,,,,,,
234.844,0.84031,1.42441,10,,,,,,,,,,,,,,,,,,,,,,,,,,,,,,,,,,,,,
235.544,0.84054,1.37103,10,,,,,,,,,,,,,,,,,,,,,,,,,,,,,,,,,,,,,
236.244,0.84042,1.32383,10,,,,,,,,,,,,,,,,,,,,,,,,,,,,,,,,,,,,,
236.944,0.84031,1.36774,10,,,,,,,,,,,,,,,,,,,,,,,,,,,,,,,,,,,,,
237.644,0.84025,1.32976,10,,,,,,,,,,,,,,,,,,,,,,,,,,,,,,,,,,,,,
238.344,0.8402,1.33738,10,,,,,,,,,,,,,,,,,,,,,,,,,,,,,,,,,,,,,
239.044,0.84014,1.3218,10,,,,,,,,,,,,,,,,,,,,,,,,,,,,,,,,,,,,,
239.744,0.83997,1.40525,10,,,,,,,,,,,,,,,,,,,,,,,,,,,,,,,,,,,,,
240.444,0.83963,1.28118,10,,,,,,,,,,,,,,,,,,,,,,,,,,,,,,,,,,,,,
241.144,0.83912,1.31024,10,,,,,,,,,,,,,,,,,,,,,,,,,,,,,,,,,,,,,
241.844,0.8381,1.40826,10,,,,,,,,,,,,,,,,,,,,,,,,,,,,,,,,,,,,,
242.544,0.8368,1.27989,10,,,,,,,,,,,,,,,,,,,,,,,,,,,,,,,,,,,,,
243.244,0.83634,1.31879,10,,,,,,,,,,,,,,,,,,,,,,,,,,,,,,,,,,,,,
243.944,0.836,1.30325,10,,,,,,,,,,,,,,,,,,,,,,,,,,,,,,,,,,,,,
244.644,0.83578,1.29903,10,,,,,,,,,,,,,,,,,,,,,,,,,,,,,,,,,,,,,
245.344,0.83566,1.28406,10,,,,,,,,,,,,,,,,,,,,,,,,,,,,,,,,,,,,,
246.044,0.83561,1.28587,10,,,,,,,,,,,,,,,,,,,,,,,,,,,,,,,,,,,,,
246.744,0.83572,1.24556,10,,,,,,,,,,,,,,,,,,,,,,,,,,,,,,,,,,,,,
247.444,0.83566,1.28672,10,,,,,,,,,,,,,,,,,,,,,,,,,,,,,,,,,,,,,
248.144,0.83572,1.29799,10,,,,,,,,,,,,,,,,,,,,,,,,,,,,,,,,,,,,,
248.844,0.83589,1.31944,10,,,,,,,,,,,,,,,,,,,,,,,,,,,,,,,,,,,,,
249.544,0.83595,1.2805,10,,,,,,,,,,,,,,,,,,,,,,,,,,,,,,,,,,,,,
250.244,0.83595,1.31365,10,,,,,,,,,,,,,,,,,,,,,,,,,,,,,,,,,,,,,
250.944,0.836,1.21624,10,,,,,,,,,,,,,,,,,,,,,,,,,,,,,,,,,,,,,
251.644,0.83617,1.28847,10,,,,,,,,,,,,,,,,,,,,,,,,,,,,,,,,,,,,,
252.344,0.83634,1.29991,10,,,,,,,,,,,,,,,,,,,,,,,,,,,,,,,,,,,,,
253.044,0.83657,1.23708,10,,,,,,,,,,,,,,,,,,,,,,,,,,,,,,,,,,,,,
253.744,0.8368,1.27106,10,,,,,,,,,,,,,,,,,,,,,,,,,,,,,,,,,,,,,
254.444,0.83697,1.28869,10,,,,,,,,,,,,,,,,,,,,,,,,,,,,,,,,,,,,,
255.144,0.83708,1.28243,10,,,,,,,,,,,,,,,,,,,,,,,,,,,,,,,,,,,,,
255.844,0.83714,1.28444,10,,,,,,,,,,,,,,,,,,,,,,,,,,,,,,,,,,,,,
256.544,0.83719,1.36991,10,,,,,,,,,,,,,,,,,,,,,,,,,,,,,,,,,,,,,
257.244,0.83719,1.27926,10,,,,,,,,,,,,,,,,,,,,,,,,,,,,,,,,,,,,,
257.944,0.83725,1.26374,10,,,,,,,,,,,,,,,,,,,,,,,,,,,,,,,,,,,,,
258.644,0.83731,1.35862,10,,,,,,,,,,,,,,,,,,,,,,,,,,,,,,,,,,,,,
259.344,0.83731,1.28987,10,,,,,,,,,,,,,,,,,,,,,,,,,,,,,,,,,,,,,
260.044,0.83731,1.2889,10,,,,,,,,,,,,,,,,,,,,,,,,,,,,,,,,,,,,,
260.744,0.83719,1.32736,10,,,,,,,,,,,,,,,,,,,,,,,,,,,,,,,,,,,,,
261.444,0.83719,1.25378,10,,,,,,,,,,,,,,,,,,,,,,,,,,,,,,,,,,,,,
262.144,0.83719,1.30864,10,,,,,,,,,,,,,,,,,,,,,,,,,,,,,,,,,,,,,
262.844,0.83725,1.25237,10,,,,,,,,,,,,,,,,,,,,,,,,,,,,,,,,,,,,,
263.544,0.83725,1.32253,10,,,,,,,,,,,,,,,,,,,,,,,,,,,,,,,,,,,,,
264.244,0.83725,1.32115,10,,,,,,,,,,,,,,,,,,,,,,,,,,,,,,,,,,,,,
264.944,0.83719,1.36944,10,,,,,,,,,,,,,,,,,,,,,,,,,,,,,,,,,,,,,
265.644,0.83719,1.30426,10,,,,,,,,,,,,,,,,,,,,,,,,,,,,,,,,,,,,,
266.344,0.83708,1.30345,10,,,,,,,,,,,,,,,,,,,,,,,,,,,,,,,,,,,,,
267.044,0.83702,1.30797,10,,,,,,,,,,,,,,,,,,,,,,,,,,,,,,,,,,,,,
267.744,0.83702,1.39738,10,,,,,,,,,,,,,,,,,,,,,,,,,,,,,,,,,,,,,
268.444,0.83702,1.25474,10,,,,,,,,,,,,,,,,,,,,,,,,,,,,,,,,,,,,,
269.144,0.83702,1.33318,10,,,,,,,,,,,,,,,,,,,,,,,,,,,,,,,,,,,,,
269.844,0.83714,1.26412,10,,,,,,,,,,,,,,,,,,,,,,,,,,,,,,,,,,,,,
270.544,0.83702,1.29994,10,,,,,,,,,,,,,,,,,,,,,,,,,,,,,,,,,,,,,
271.244,0.83702,1.31533,10,,,,,,,,,,,,,,,,,,,,,,,,,,,,,,,,,,,,,
271.944,0.83702,1.33438,10,,,,,,,,,,,,,,,,,,,,,,,,,,,,,,,,,,,,,
272.644,0.83702,1.29716,10,,,,,,,,,,,,,,,,,,,,,,,,,,,,,,,,,,,,,
273.344,0.83697,1.33298,10,,,,,,,,,,,,,,,,,,,,,,,,,,,,,,,,,,,,,
274.044,0.83697,1.317,10,,,,,,,,,,,,,,,,,,,,,,,,,,,,,,,,,,,,,
274.744,0.83708,1.28007,10,,,,,,,,,,,,,,,,,,,,,,,,,,,,,,,,,,,,,
275.444,0.83708,1.34712,10,,,,,,,,,,,,,,,,,,,,,,,,,,,,,,,,,,,,,
276.144,0.83708,1.32545,10,,,,,,,,,,,,,,,,,,,,,,,,,,,,,,,,,,,,,
276.844,0.83708,1.30001,10,,,,,,,,,,,,,,,,,,,,,,,,,,,,,,,,,,,,,
277.544,0.83708,1.33315,10,,,,,,,,,,,,,,,,,,,,,,,,,,,,,,,,,,,,,
278.244,0.83708,1.22106,10,,,,,,,,,,,,,,,,,,,,,,,,,,,,,,,,,,,,,
278.944,0.83702,1.34784,10,,,,,,,,,,,,,,,,,,,,,,,,,,,,,,,,,,,,,
279.644,0.83714,1.27265,10,,,,,,,,,,,,,,,,,,,,,,,,,,,,,,,,,,,,,
280.344,0.83714,1.33384,10,,,,,,,,,,,,,,,,,,,,,,,,,,,,,,,,,,,,,
281.044,0.83714,1.34021,10,,,,,,,,,,,,,,,,,,,,,,,,,,,,,,,,,,,,,
281.744,0.83714,1.35102,10,,,,,,,,,,,,,,,,,,,,,,,,,,,,,,,,,,,,,
282.444,0.83714,1.24132,10,,,,,,,,,,,,,,,,,,,,,,,,,,,,,,,,,,,,,
283.144,0.83719,1.27698,10,,,,,,,,,,,,,,,,,,,,,,,,,,,,,,,,,,,,,
283.844,0.83719,1.26463,10,,,,,,,,,,,,,,,,,,,,,,,,,,,,,,,,,,,,,
284.544,0.83725,1.2947,10,,,,,,,,,,,,,,,,,,,,,,,,,,,,,,,,,,,,,
285.244,0.83731,1.29779,10,,,,,,,,,,,,,,,,,,,,,,,,,,,,,,,,,,,,,
285.944,0.83731,1.3673,10,,,,,,,,,,,,,,,,,,,,,,,,,,,,,,,,,,,,,
286.644,0.83748,1.24734,10,,,,,,,,,,,,,,,,,,,,,,,,,,,,,,,,,,,,,
287.344,0.83793,1.27583,10,,,,,,,,,,,,,,,,,,,,,,,,,,,,,,,,,,,,,
288.044,0.83895,1.28962,10,,,,,,,,,,,,,,,,,,,,,,,,,,,,,,,,,,,,,
288.744,0.84031,1.30209,10,,,,,,,,,,,,,,,,,,,,,,,,,,,,,,,,,,,,,
289.444,0.84088,1.36317,10,,,,,,,,,,,,,,,,,,,,,,,,,,,,,,,,,,,,,
290.144,0.84127,1.29994,10,,,,,,,,,,,,,,,,,,,,,,,,,,,,,,,,,,,,,
290.844,0.8415,1.30876,10,,,,,,,,,,,,,,,,,,,,,,,,,,,,,,,,,,,,,
291.544,0.84161,1.31574,10,,,,,,,,,,,,,,,,,,,,,,,,,,,,,,,,,,,,,
292.244,0.8415,1.34095,10,,,,,,,,,,,,,,,,,,,,,,,,,,,,,,,,,,,,,
292.944,0.8415,1.33836,10,,,,,,,,,,,,,,,,,,,,,,,,,,,,,,,,,,,,,
293.644,0.8415,1.28801,10,,,,,,,,,,,,,,,,,,,,,,,,,,,,,,,,,,,,,
294.344,0.84144,1.37729,10,,,,,,,,,,,,,,,,,,,,,,,,,,,,,,,,,,,,,
295.044,0.84139,1.32133,10,,,,,,,,,,,,,,,,,,,,,,,,,,,,,,,,,,,,,
295.744,0.84139,1.28396,10,,,,,,,,,,,,,,,,,,,,,,,,,,,,,,,,,,,,,
296.444,0.84139,1.30836,10,,,,,,,,,,,,,,,,,,,,,,,,,,,,,,,,,,,,,
297.144,0.84139,1.32658,10,,,,,,,,,,,,,,,,,,,,,,,,,,,,,,,,,,,,,
297.844,0.84139,1.31113,10,,,,,,,,,,,,,,,,,,,,,,,,,,,,,,,,,,,,,
298.544,0.84133,1.37741,10,,,,,,,,,,,,,,,,,,,,,,,,,,,,,,,,,,,,,
299.244,0.84127,1.31156,10,,,,,,,,,,,,,,,,,,,,,,,,,,,,,,,,,,,,,
299.944,0.84127,1.29189,10,,,,,,,,,,,,,,,,,,,,,,,,,,,,,,,,,,,,,
300.644,0.84122,1.25696,10,,,,,,,,,,,,,,,,,,,,,,,,,,,,,,,,,,,,,
301.344,0.84122,1.3431,10,,,,,,,,,,,,,,,,,,,,,,,,,,,,,,,,,,,,,
302.044,0.84116,1.31647,10,,,,,,,,,,,,,,,,,,,,,,,,,,,,,,,,,,,,,
302.744,0.84099,1.37199,10,,,,,,,,,,,,,,,,,,,,,,,,,,,,,,,,,,,,,
303.444,0.84076,1.39981,10,,,,,,,,,,,,,,,,,,,,,,,,,,,,,,,,,,,,,
304.144,0.84048,1.33356,10,,,,,,,,,,,,,,,,,,,,,,,,,,,,,,,,,,,,,
304.844,0.83986,1.36872,10,,,,,,,,,,,,,,,,,,,,,,,,,,,,,,,,,,,,,
305.544,0.83918,1.36396,10,,,,,,,,,,,,,,,,,,,,,,,,,,,,,,,,,,,,,
306.244,0.83861,1.32957,10,,,,,,,,,,,,,,,,,,,,,,,,,,,,,,,,,,,,,
306.944,0.83821,1.33356,10,,,,,,,,,,,,,,,,,,,,,,,,,,,,,,,,,,,,,
307.644,0.83799,1.29123,10,,,,,,,,,,,,,,,,,,,,,,,,,,,,,,,,,,,,,
308.344,0.83782,1.26557,10,,,,,,,,,,,,,,,,,,,,,,,,,,,,,,,,,,,,,
309.044,0.83776,1.24542,10,,,,,,,,,,,,,,,,,,,,,,,,,,,,,,,,,,,,,
309.744,0.83787,1.28653,10,,,,,,,,,,,,,,,,,,,,,,,,,,,,,,,,,,,,,
310.444,0.83782,1.33431,10,,,,,,,,,,,,,,,,,,,,,,,,,,,,,,,,,,,,,
311.144,0.83793,1.33645,10,,,,,,,,,,,,,,,,,,,,,,,,,,,,,,,,,,,,,
311.844,0.83799,1.28427,10,,,,,,,,,,,,,,,,,,,,,,,,,,,,,,,,,,,,,
312.544,0.83804,1.2321,10,,,,,,,,,,,,,,,,,,,,,,,,,,,,,,,,,,,,,
313.244,0.83821,1.28723,10,,,,,,,,,,,,,,,,,,,,,,,,,,,,,,,,,,,,,
313.944,0.83833,1.26473,10,,,,,,,,,,,,,,,,,,,,,,,,,,,,,,,,,,,,,
314.644,0.83867,1.25459,10,,,,,,,,,,,,,,,,,,,,,,,,,,,,,,,,,,,,,
315.344,0.83901,1.31944,10,,,,,,,,,,,,,,,,,,,,,,,,,,,,,,,,,,,,,
316.044,0.83952,1.25466,10,,,,,,,,,,,,,,,,,,,,,,,,,,,,,,,,,,,,,
316.744,0.84076,1.25213,10,,,,,,,,,,,,,,,,,,,,,,,,,,,,,,,,,,,,,
317.444,0.8419,1.31963,10,,,,,,,,,,,,,,,,,,,,,,,,,,,,,,,,,,,,,
318.144,0.84258,1.2866,10,,,,,,,,,,,,,,,,,,,,,,,,,,,,,,,,,,,,,
318.844,0.84297,1.28967,10,,,,,,,,,,,,,,,,,,,,,,,,,,,,,,,,,,,,,
319.544,0.8432,1.34031,10,,,,,,,,,,,,,,,,,,,,,,,,,,,,,,,,,,,,,
320.244,0.84314,1.34202,10,,,,,,,,,,,,,,,,,,,,,,,,,,,,,,,,,,,,,
320.944,0.84314,1.31785,10,,,,,,,,,,,,,,,,,,,,,,,,,,,,,,,,,,,,,
321.644,0.84303,1.33933,10,,,,,,,,,,,,,,,,,,,,,,,,,,,,,,,,,,,,,
322.344,0.84292,1.3842,10,,,,,,,,,,,,,,,,,,,,,,,,,,,,,,,,,,,,,
323.044,0.84286,1.31237,10,,,,,,,,,,,,,,,,,,,,,,,,,,,,,,,,,,,,,
323.744,0.8428,1.34691,10,,,,,,,,,,,,,,,,,,,,,,,,,,,,,,,,,,,,,
324.444,0.84269,1.36725,10,,,,,,,,,,,,,,,,,,,,,,,,,,,,,,,,,,,,,
325.144,0.84229,1.31169,10,,,,,,,,,,,,,,,,,,,,,,,,,,,,,,,,,,,,,
325.844,0.84178,1.37038,10,,,,,,,,,,,,,,,,,,,,,,,,,,,,,,,,,,,,,
326.544,0.84099,1.35138,10,,,,,,,,,,,,,,,,,,,,,,,,,,,,,,,,,,,,,
327.244,0.84025,1.31895,10,,,,,,,,,,,,,,,,,,,,,,,,,,,,,,,,,,,,,
327.944,0.83957,1.42888,10,,,,,,,,,,,,,,,,,,,,,,,,,,,,,,,,,,,,,
328.644,0.83918,1.34675,10,,,,,,,,,,,,,,,,,,,,,,,,,,,,,,,,,,,,,
329.344,0.83884,1.29034,10,,,,,,,,,,,,,,,,,,,,,,,,,,,,,,,,,,,,,
330.044,0.83867,1.366,10,,,,,,,,,,,,,,,,,,,,,,,,,,,,,,,,,,,,,
330.744,0.83861,1.31641,10,,,,,,,,,,,,,,,,,,,,,,,,,,,,,,,,,,,,,
331.444,0.83855,1.23738,10,,,,,,,,,,,,,,,,,,,,,,,,,,,,,,,,,,,,,
332.144,0.83867,1.28994,10,,,,,,,,,,,,,,,,,,,,,,,,,,,,,,,,,,,,,
332.844,0.83872,1.29456,10,,,,,,,,,,,,,,,,,,,,,,,,,,,,,,,,,,,,,
333.544,0.83878,1.25436,10,,,,,,,,,,,,,,,,,,,,,,,,,,,,,,,,,,,,,
334.244,0.83878,1.29762,10,,,,,,,,,,,,,,,,,,,,,,,,,,,,,,,,,,,,,
334.944,0.83884,1.29952,10,,,,,,,,,,,,,,,,,,,,,,,,,,,,,,,,,,,,,
335.644,0.83901,1.31794,10,,,,,,,,,,,,,,,,,,,,,,,,,,,,,,,,,,,,,
336.344,0.83901,1.28089,10,,,,,,,,,,,,,,,,,,,,,,,,,,,,,,,,,,,,,
337.044,0.83895,1.34884,10,,,,,,,,,,,,,,,,,,,,,,,,,,,,,,,,,,,,,
337.744,0.83912,1.22093,10,,,,,,,,,,,,,,,,,,,,,,,,,,,,,,,,,,,,,
338.444,0.83929,1.34137,10,,,,,,,,,,,,,,,,,,,,,,,,,,,,,,,,,,,,,
339.144,0.83963,1.24262,10,,,,,,,,,,,,,,,,,,,,,,,,,,,,,,,,,,,,,
339.844,0.84031,1.24728,10,,,,,,,,,,,,,,,,,,,,,,,,,,,,,,,,,,,,,
340.544,0.84167,1.27422,10,,,,,,,,,,,,,,,,,,,,,,,,,,,,,,,,,,,,,
341.244,0.8428,1.30815,10,,,,,,,,,,,,,,,,,,,,,,,,,,,,,,,,,,,,,
341.944,0.8432,1.29743,10,,,,,,,,,,,,,,,,,,,,,,,,,,,,,,,,,,,,,
342.644,0.84348,1.3474,10,,,,,,,,,,,,,,,,,,,,,,,,,,,,,,,,,,,,,
343.344,0.84365,1.3421,10,,,,,,,,,,,,,,,,,,,,,,,,,,,,,,,,,,,,,
344.044,0.84371,1.31413,10,,,,,,,,,,,,,,,,,,,,,,,,,,,,,,,,,,,,,
344.744,0.8436,1.35523,10,,,,,,,,,,,,,,,,,,,,,,,,,,,,,,,,,,,,,
345.444,0.84354,1.30205,10,,,,,,,,,,,,,,,,,,,,,,,,,,,,,,,,,,,,,
346.144,0.84348,1.33211,10,,,,,,,,,,,,,,,,,,,,,,,,,,,,,,,,,,,,,
346.844,0.84348,1.42469,10,,,,,,,,,,,,,,,,,,,,,,,,,,,,,,,,,,,,,
347.544,0.84331,1.34404,10,,,,,,,,,,,,,,,,,,,,,,,,,,,,,,,,,,,,,
348.244,0.84303,1.3617,10,,,,,,,,,,,,,,,,,,,,,,,,,,,,,,,,,,,,,
348.944,0.84235,1.39022,10,,,,,,,,,,,,,,,,,,,,,,,,,,,,,,,,,,,,,
349.644,0.84144,1.36934,10,,,,,,,,,,,,,,,,,,,,,,,,,,,,,,,,,,,,,
350.344,0.84025,1.35962,10,,,,,,,,,,,,,,,,,,,,,,,,,,,,,,,,,,,,,
351.044,0.83889,1.34753,10,,,,,,,,,,,,,,,,,,,,,,,,,,,,,,,,,,,,,
351.744,0.8381,1.27149,10,,,,,,,,,,,,,,,,,,,,,,,,,,,,,,,,,,,,,
352.444,0.8377,1.25537,10,,,,,,,,,,,,,,,,,,,,,,,,,,,,,,,,,,,,,
353.144,0.83753,1.33861,10,,,,,,,,,,,,,,,,,,,,,,,,,,,,,,,,,,,,,
353.844,0.83748,1.23967,10,,,,,,,,,,,,,,,,,,,,,,,,,,,,,,,,,,,,,
354.544,0.83748,1.28283,10,,,,,,,,,,,,,,,,,,,,,,,,,,,,,,,,,,,,,
355.244,0.83759,1.28032,10,,,,,,,,,,,,,,,,,,,,,,,,,,,,,,,,,,,,,
355.944,0.83759,1.24705,10,,,,,,,,,,,,,,,,,,,,,,,,,,,,,,,,,,,,,
356.644,0.83776,1.23964,10,,,,,,,,,,,,,,,,,,,,,,,,,,,,,,,,,,,,,
357.344,0.83782,1.36876,10,,,,,,,,,,,,,,,,,,,,,,,,,,,,,,,,,,,,,
358.044,0.83787,1.2948,10,,,,,,,,,,,,,,,,,,,,,,,,,,,,,,,,,,,,,
358.744,0.83804,1.25034,10,,,,,,,,,,,,,,,,,,,,,,,,,,,,,,,,,,,,,
359.444,0.83838,1.2161,10,,,,,,,,,,,,,,,,,,,,,,,,,,,,,,,,,,,,,
360.144,0.83906,1.24989,10,,,,,,,,,,,,,,,,,,,,,,,,,,,,,,,,,,,,,
360.844,0.84065,1.27034,10,,,,,,,,,,,,,,,,,,,,,,,,,,,,,,,,,,,,,
361.544,0.8428,1.28976,10,,,,,,,,,,,,,,,,,,,,,,,,,,,,,,,,,,,,,
362.244,0.84365,1.24764,10,,,,,,,,,,,,,,,,,,,,,,,,,,,,,,,,,,,,,
362.944,0.84382,1.36742,10,,,,,,,,,,,,,,,,,,,,,,,,,,,,,,,,,,,,,
363.644,0.84365,1.42279,10,,,,,,,,,,,,,,,,,,,,,,,,,,,,,,,,,,,,,
364.344,0.84348,1.37741,10,,,,,,,,,,,,,,,,,,,,,,,,,,,,,,,,,,,,,
365.044,0.84337,1.37121,10,,,,,,,,,,,,,,,,,,,,,,,,,,,,,,,,,,,,,
365.744,0.84241,1.40293,10,,,,,,,,,,,,,,,,,,,,,,,,,,,,,,,,,,,,,
366.444,0.84076,1.37475,10,,,,,,,,,,,,,,,,,,,,,,,,,,,,,,,,,,,,,
367.144,0.83855,1.32965,10,,,,,,,,,,,,,,,,,,,,,,,,,,,,,,,,,,,,,
367.844,0.8368,1.30743,10,,,,,,,,,,,,,,,,,,,,,,,,,,,,,,,,,,,,,
368.544,0.83623,1.31556,10,,,,,,,,,,,,,,,,,,,,,,,,,,,,,,,,,,,,,
369.244,0.83595,1.23363,10,,,,,,,,,,,,,,,,,,,,,,,,,,,,,,,,,,,,,
369.944,0.83589,1.26159,10,,,,,,,,,,,,,,,,,,,,,,,,,,,,,,,,,,,,,
370.644,0.836,1.25923,10,,,,,,,,,,,,,,,,,,,,,,,,,,,,,,,,,,,,,
371.344,0.83612,1.28113,10,,,,,,,,,,,,,,,,,,,,,,,,,,,,,,,,,,,,,
372.044,0.83623,1.2388,10,,,,,,,,,,,,,,,,,,,,,,,,,,,,,,,,,,,,,
372.744,0.83629,1.24538,10,,,,,,,,,,,,,,,,,,,,,,,,,,,,,,,,,,,,,
373.444,0.83646,1.18745,10,,,,,,,,,,,,,,,,,,,,,,,,,,,,,,,,,,,,,
374.144,0.8368,1.33219,10,,,,,,,,,,,,,,,,,,,,,,,,,,,,,,,,,,,,,
374.844,0.83725,1.25871,10,,,,,,,,,,,,,,,,,,,,,,,,,,,,,,,,,,,,,
375.544,0.83799,1.22957,10,,,,,,,,,,,,,,,,,,,,,,,,,,,,,,,,,,,,,
376.244,0.83918,1.28923,10,,,,,,,,,,,,,,,,,,,,,,,,,,,,,,,,,,,,,
376.944,0.84122,1.27268,10,,,,,,,,,,,,,,,,,,,,,,,,,,,,,,,,,,,,,
377.644,0.84235,1.3073,10,,,,,,,,,,,,,,,,,,,,,,,,,,,,,,,,,,,,,
378.344,0.84263,1.37148,10,,,,,,,,,,,,,,,,,,,,,,,,,,,,,,,,,,,,,
379.044,0.84258,1.30333,10,,,,,,,,,,,,,,,,,,,,,,,,,,,,,,,,,,,,,
379.744,0.84252,1.32746,10,,,,,,,,,,,,,,,,,,,,,,,,,,,,,,,,,,,,,
380.444,0.84241,1.36385,10,,,,,,,,,,,,,,,,,,,,,,,,,,,,,,,,,,,,,
381.144,0.84235,1.37229,10,,,,,,,,,,,,,,,,,,,,,,,,,,,,,,,,,,,,,
381.844,0.84224,1.35644,10,,,,,,,,,,,,,,,,,,,,,,,,,,,,,,,,,,,,,
382.544,0.84195,1.39224,10,,,,,,,,,,,,,,,,,,,,,,,,,,,,,,,,,,,,,
383.244,0.8415,1.32777,10,,,,,,,,,,,,,,,,,,,,,,,,,,,,,,,,,,,,,
383.944,0.84071,1.33785,10,,,,,,,,,,,,,,,,,,,,,,,,,,,,,,,,,,,,,
384.644,0.83974,1.38362,10,,,,,,,,,,,,,,,,,,,,,,,,,,,,,,,,,,,,,
385.344,0.83901,1.3145,10,,,,,,,,,,,,,,,,,,,,,,,,,,,,,,,,,,,,,
386.044,0.8385,1.32181,10,,,,,,,,,,,,,,,,,,,,,,,,,,,,,,,,,,,,,
386.744,0.8381,1.35467,10,,,,,,,,,,,,,,,,,,,,,,,,,,,,,,,,,,,,,
387.444,0.8377,1.2919,10,,,,,,,,,,,,,,,,,,,,,,,,,,,,,,,,,,,,,
388.144,0.83748,1.2726,10,,,,,,,,,,,,,,,,,,,,,,,,,,,,,,,,,,,,,
388.844,0.83759,1.25169,10,,,,,,,,,,,,,,,,,,,,,,,,,,,,,,,,,,,,,
389.544,0.83765,1.29,10,,,,,,,,,,,,,,,,,,,,,,,,,,,,,,,,,,,,,
390.244,0.83759,1.26346,10,,,,,,,,,,,,,,,,,,,,,,,,,,,,,,,,,,,,,
390.944,0.8377,1.29521,10,,,,,,,,,,,,,,,,,,,,,,,,,,,,,,,,,,,,,
391.644,0.83782,1.25449,10,,,,,,,,,,,,,,,,,,,,,,,,,,,,,,,,,,,,,
392.344,0.83787,1.26865,10,,,,,,,,,,,,,,,,,,,,,,,,,,,,,,,,,,,,,
393.044,0.83804,1.24298,10,,,,,,,,,,,,,,,,,,,,,,,,,,,,,,,,,,,,,
393.744,0.83833,1.25792,10,,,,,,,,,,,,,,,,,,,,,,,,,,,,,,,,,,,,,
394.444,0.83872,1.27639,10,,,,,,,,,,,,,,,,,,,,,,,,,,,,,,,,,,,,,
395.144,0.8394,1.28437,10,,,,,,,,,,,,,,,,,,,,,,,,,,,,,,,,,,,,,
395.844,0.84082,1.28962,10,,,,,,,,,,,,,,,,,,,,,,,,,,,,,,,,,,,,,
396.544,0.84229,1.32116,10,,,,,,,,,,,,,,,,,,,,,,,,,,,,,,,,,,,,,
397.244,0.84303,1.32425,10,,,,,,,,,,,,,,,,,,,,,,,,,,,,,,,,,,,,,
397.944,0.84331,1.30675,10,,,,,,,,,,,,,,,,,,,,,,,,,,,,,,,,,,,,,
398.644,0.84337,1.33738,10,,,,,,,,,,,,,,,,,,,,,,,,,,,,,,,,,,,,,
399.344,0.8432,1.40502,10,,,,,,,,,,,,,,,,,,,,,,,,,,,,,,,,,,,,,
400.044,0.8432,1.28351,10,,,,,,,,,,,,,,,,,,,,,,,,,,,,,,,,,,,,,
400.744,0.8432,1.35877,10,,,,,,,,,,,,,,,,,,,,,,,,,,,,,,,,,,,,,
401.444,0.84309,1.31621,10,,,,,,,,,,,,,,,,,,,,,,,,,,,,,,,,,,,,,
402.144,0.84303,1.28542,10,,,,,,,,,,,,,,,,,,,,,,,,,,,,,,,,,,,,,
402.844,0.84297,1.31085,10,,,,,,,,,,,,,,,,,,,,,,,,,,,,,,,,,,,,,
403.544,0.84292,1.33404,10,,,,,,,,,,,,,,,,,,,,,,,,,,,,,,,,,,,,,
404.244,0.84286,1.35709,10,,,,,,,,,,,,,,,,,,,,,,,,,,,,,,,,,,,,,
404.944,0.84263,1.36407,10,,,,,,,,,,,,,,,,,,,,,,,,,,,,,,,,,,,,,
405.644,0.84224,1.36403,10,,,,,,,,,,,,,,,,,,,,,,,,,,,,,,,,,,,,,
406.344,0.84195,1.38754,10,,,,,,,,,,,,,,,,,,,,,,,,,,,,,,,,,,,,,
407.044,0.84156,1.31177,10,,,,,,,,,,,,,,,,,,,,,,,,,,,,,,,,,,,,,
407.744,0.8411,1.35348,10,,,,,,,,,,,,,,,,,,,,,,,,,,,,,,,,,,,,,
408.444,0.84054,1.2909,10,,,,,,,,,,,,,,,,,,,,,,,,,,,,,,,,,,,,,
409.144,0.84014,1.26178,10,,,,,,,,,,,,,,,,,,,,,,,,,,,,,,,,,,,,,
409.844,0.83986,1.33569,10,,,,,,,,,,,,,,,,,,,,,,,,,,,,,,,,,,,,,
410.544,0.8398,1.30534,10,,,,,,,,,,,,,,,,,,,,,,,,,,,,,,,,,,,,,
411.244,0.83997,1.26986,10,,,,,,,,,,,,,,,,,,,,,,,,,,,,,,,,,,,,,
411.944,0.84003,1.27124,10,,,,,,,,,,,,,,,,,,,,,,,,,,,,,,,,,,,,,
412.644,0.84008,1.22828,10,,,,,,,,,,,,,,,,,,,,,,,,,,,,,,,,,,,,,
413.344,0.84025,1.243,10,,,,,,,,,,,,,,,,,,,,,,,,,,,,,,,,,,,,,
414.044,0.84054,1.22089,10,,,,,,,,,,,,,,,,,,,,,,,,,,,,,,,,,,,,,
414.744,0.84105,1.22544,10,,,,,,,,,,,,,,,,,,,,,,,,,,,,,,,,,,,,,
415.444,0.84218,1.242,10,,,,,,,,,,,,,,,,,,,,,,,,,,,,,,,,,,,,,
416.144,0.8432,1.27546,10,,,,,,,,,,,,,,,,,,,,,,,,,,,,,,,,,,,,,
416.844,0.84388,1.28944,10,,,,,,,,,,,,,,,,,,,,,,,,,,,,,,,,,,,,,
417.544,0.84456,1.4233,10,,,,,,,,,,,,,,,,,,,,,,,,,,,,,,,,,,,,,
418.244,0.84496,1.35051,10,,,,,,,,,,,,,,,,,,,,,,,,,,,,,,,,,,,,,
418.944,0.84518,1.3519,10,,,,,,,,,,,,,,,,,,,,,,,,,,,,,,,,,,,,,
419.644,0.84524,1.30352,10,,,,,,,,,,,,,,,,,,,,,,,,,,,,,,,,,,,,,
420.344,0.84524,1.3998,10,,,,,,,,,,,,,,,,,,,,,,,,,,,,,,,,,,,,,
421.044,0.84513,1.28429,10,,,,,,,,,,,,,,,,,,,,,,,,,,,,,,,,,,,,,
421.744,0.84507,1.34074,10,,,,,,,,,,,,,,,,,,,,,,,,,,,,,,,,,,,,,
422.444,0.84501,1.32544,10,,,,,,,,,,,,,,,,,,,,,,,,,,,,,,,,,,,,,
423.144,0.84496,1.29444,10,,,,,,,,,,,,,,,,,,,,,,,,,,,,,,,,,,,,,
423.844,0.8449,1.28362,10,,,,,,,,,,,,,,,,,,,,,,,,,,,,,,,,,,,,,
424.544,0.84479,1.32466,10,,,,,,,,,,,,,,,,,,,,,,,,,,,,,,,,,,,,,
425.244,0.84467,1.37577,10,,,,,,,,,,,,,,,,,,,,,,,,,,,,,,,,,,,,,
425.944,0.84456,1.31501,10,,,,,,,,,,,,,,,,,,,,,,,,,,,,,,,,,,,,,
426.644,0.84439,1.35656,10,,,,,,,,,,,,,,,,,,,,,,,,,,,,,,,,,,,,,
427.344,0.84405,1.36459,10,,,,,,,,,,,,,,,,,,,,,,,,,,,,,,,,,,,,,
428.044,0.84371,1.34227,10,,,,,,,,,,,,,,,,,,,,,,,,,,,,,,,,,,,,,
428.744,0.84314,1.37208,10,,,,,,,,,,,,,,,,,,,,,,,,,,,,,,,,,,,,,
429.444,0.84235,1.33651,10,,,,,,,,,,,,,,,,,,,,,,,,,,,,,,,,,,,,,
430.144,0.84212,1.29708,10,,,,,,,,,,,,,,,,,,,,,,,,,,,,,,,,,,,,,
430.844,0.8419,1.32886,10,,,,,,,,,,,,,,,,,,,,,,,,,,,,,,,,,,,,,
431.544,0.84184,1.26369,10,,,,,,,,,,,,,,,,,,,,,,,,,,,,,,,,,,,,,
432.244,0.84195,1.32703,10,,,,,,,,,,,,,,,,,,,,,,,,,,,,,,,,,,,,,
432.944,0.84195,1.31179,10,,,,,,,,,,,,,,,,,,,,,,,,,,,,,,,,,,,,,
433.644,0.84195,1.28496,10,,,,,,,,,,,,,,,,,,,,,,,,,,,,,,,,,,,,,
434.344,0.84195,1.27543,10,,,,,,,,,,,,,,,,,,,,,,,,,,,,,,,,,,,,,
435.044,0.84195,1.32237,10,,,,,,,,,,,,,,,,,,,,,,,,,,,,,,,,,,,,,
435.744,0.84201,1.27438,10,,,,,,,,,,,,,,,,,,,,,,,,,,,,,,,,,,,,,
436.444,0.84207,1.2956,10,,,,,,,,,,,,,,,,,,,,,,,,,,,,,,,,,,,,,
437.144,0.84212,1.3126,10,,,,,,,,,,,,,,,,,,,,,,,,,,,,,,,,,,,,,
437.844,0.84224,1.25072,10,,,,,,,,,,,,,,,,,,,,,,,,,,,,,,,,,,,,,
438.544,0.84235,1.26387,10,,,,,,,,,,,,,,,,,,,,,,,,,,,,,,,,,,,,,
439.244,0.84263,1.33248,10,,,,,,,,,,,,,,,,,,,,,,,,,,,,,,,,,,,,,
439.944,0.84309,1.23578,10,,,,,,,,,,,,,,,,,,,,,,,,,,,,,,,,,,,,,
440.644,0.84371,1.22364,10,,,,,,,,,,,,,,,,,,,,,,,,,,,,,,,,,,,,,
441.344,0.84433,1.29971,10,,,,,,,,,,,,,,,,,,,,,,,,,,,,,,,,,,,,,
442.044,0.84501,1.30867,10,,,,,,,,,,,,,,,,,,,,,,,,,,,,,,,,,,,,,
442.744,0.84552,1.26223,10,,,,,,,,,,,,,,,,,,,,,,,,,,,,,,,,,,,,,
443.444,0.84598,1.29522,10,,,,,,,,,,,,,,,,,,,,,,,,,,,,,,,,,,,,,
444.144,0.84632,1.32074,10,,,,,,,,,,,,,,,,,,,,,,,,,,,,,,,,,,,,,
444.844,0.84649,1.28564,10,,,,,,,,,,,,,,,,,,,,,,,,,,,,,,,,,,,,,
445.544,0.8466,1.39207,10,,,,,,,,,,,,,,,,,,,,,,,,,,,,,,,,,,,,,
446.146,4.77983,272.71643,10,,,,,,,,,,,,,,,,,,,,,,,,,,,,,,,,,,,,,
446.846,10.61327,605.04248,10,,,,,,,,,,,,,,,,,,,,,,,,,,,,,,,,,,,,,
447.546,16.44671,451.86322,10,,,,,,,,,,,,,,,,,,,,,,,,,,,,,,,,,,,,,
448.246,22.27992,47.21697,10,,,,,,,,,,,,,,,,,,,,,,,,,,,,,,,,,,,,,
448.946,28.11324,30.71809,10,,,,,,,,,,,,,,,,,,,,,,,,,,,,,,,,,,,,,
449.646,33.94667,16.12697,10,,,,,,,,,,,,,,,,,,,,,,,,,,,,,,,,,,,,,
450.346,39.77988,3.66229,10,,,,,,,,,,,,,,,,,,,,,,,,,,,,,,,,,,,,,
451.046,45.6132,0.11393,10,,,,,,,,,,,,,,,,,,,,,,,,,,,,,,,,,,,,,
451.746,51.44665,-2.56913,10,,,,,,,,,,,,,,,,,,,,,,,,,,,,,,,,,,,,,
452.446,57.28003,-4.85736,10,,,,,,,,,,,,,,,,,,,,,,,,,,,,,,,,,,,,,
453.146,63.11329,-5.42429,10,,,,,,,,,,,,,,,,,,,,,,,,,,,,,,,,,,,,,
453.846,68.94662,-5.39111,10,,,,,,,,,,,,,,,,,,,,,,,,,,,,,,,,,,,,,
454.546,74.77988,-5.34971,10,,,,,,,,,,,,,,,,,,,,,,,,,,,,,,,,,,,,,
455.246,80.6132,-6.40828,10,,,,,,,,,,,,,,,,,,,,,,,,,,,,,,,,,,,,,
455.262,80.74653,-6.45296,10,,,,,,,,,,,,,,,,,,,,,,,,,,,,,,,,,,,,,