File: combined_ligament_solver/data/processed/Data Sheet 3_S152718_MCL.csv
Specimen properties : Length,50,mm,Unnamed: 3,Unnamed: 4,Unnamed: 5,Unnamed: 6,Unnamed: 7,Unnamed: 8,Unnamed: 9,Unnamed: 10,Unnamed: 11,Stress-Strain,Unnamed: 13,Unnamed: 14,Unnamed: 15,Unnamed: 16,Unnamed: 17,Unnamed: 18,Unnamed: 19,Unnamed: 20,Unnamed: 21,Unnamed: 22,Unnamed: 23,Unnamed: 24,Unnamed: 25,Unnamed: 26,Unnamed: 27,Linear,Unnamed: 29,Unnamed: 30,Unnamed: 31,Unnamed: 32,Unnamed: 33,Modulus,Unnamed: 35,Failure,Unnamed: 37,Unnamed: 38,Unnamed: 39,Unnamed: 40
Cross Section Average,58.684,mm2,,,,,,,,,,Polynomial Coefficients,,,,,,,,,,,,,,,,Force,,Stress,Extension,Strain,,Secant,Tangent,Load,Stress,Extension,Strain,Stiffness
Time,Extension,Load,Total cycle count,,,Extension,Load,Strain,Stress,E-tan,,X6,,,,,,,,,,Strain,Stress,E-tan,,,,(N),,(MPa),(mm),(%),,(MPa),(MPa),(N),(MPa),(mm),(%),(N/mm)
(s),(mm),(N),,,,(mm),(N),(mm/mm),(MPa),(MPa),,X5,-3863863.452804925,,,,,,,,,(mm/mm),(MPa),(MPa),,,,96.5296967047584,,1.6449065623467793,2.6,5.2,,31.63281850666883,55.08415335925382,139.01949,2.3689504805398403,3.81678,7.63356,37.12680642490707
0.6,0.19686,2.17614,0,,,5.30995,134.88345,,,,,,,,,,,,,,,0.006,0.039694718733632346,10.101451100836627,,,,,,,,,,,,,,,,
1.3,0.31342,3.68737,0,,,11.14333,220.67331,,,,,,,,,,,,,,,0.013,0.14204075341894315,17.75046429207559,,,,,,,,,,,,,,,,
2,0.4301,5.37718,0,,,16.97659,182.29698,,,,,,,,,,,,,,,0.02,0.2936430292618545,24.597421147855044,,,,,,,,,,,,,,,,
2.7,0.54672,7.15595,0,,,22.80986,119.87046,,,,,,,,,,,,,,,0.027,0.494847166591614,31.973288717823426,,,,,,,,,,,,,,,,
3.4,0.66345,9.04901,0,,,,,,,,,,,,,,,,,,,0.034,0.7508625297329218,40.095777713607795,,,,,,,,,,,,,,,,
4.1,0.78019,11.2316,0,,,,,,,,,,,,,,,,,,,0.041,1.063969432639774,48.0693425088123,,,,,,,,,,,,,,,,
4.8,0.89675,13.49119,0,,,,,,,,,,,,,,,,,,,0.048,1.4257263445293094,53.885181139018805,,,,,,,,,,,,,,,,
5.5,1.01348,15.90006,0,,,,,,,,,,,,,,,,,,,0.055,1.8091770955156523,54.42123530178716,,,,,,,,,,,,,,,,
6.2,1.13016,18.25755,0,,,,,,,,,,,,,,,,,,,0.062,2.1610580822437613,45.44219035665526,,,,,,,,,,,,,,,,
6.9,1.24689,20.75593,0,,,,,,,,,,,,,,,,,,,0.069,2.3940054735232694,21.599475325142038,,,,,,,,,,,,,,,,
7.6,1.36368,23.51635,0,,,,,,,,,,,,,,,,,,,0.076,,,,,,,,,,,,,,,,,,
8.3,1.4803,26.5041,0,,,,,,,,,,,,,,,,,,,0.083,,,,,,,,,,,,,,,,,,
9,1.59687,29.74762,0,,,,,,,,,,,,,,,,,,,0.09,,,,,,,,,,,,,,,,,,
9.7,1.71349,33.07479,0,,,,,,,,,,,,,,,,,,,0.097,,,,,,,,,,,,,,,,,,
10.4,1.83016,36.84191,0,,,,,,,,,,,,,,,,,,,0.104,,,,,,,,,,,,,,,,,,
10.986,1.92791,40.01495,0.5,,,,,,,,,,,,,,,,,,,0.111,,,,,,,,,,,,,,,,,,
11.686,1.81095,33.77427,0.5,,,,,,,,,,,,,,,,,,,0.118,,,,,,,,,,,,,,,,,,
12.386,1.69416,28.37333,0.5,,,,,,,,,,,,,,,,,,,0.125,,,,,,,,,,,,,,,,,,
13.086,1.57743,23.90893,0.5,,,,,,,,,,,,,,,,,,,0.132,,,,,,,,,,,,,,,,,,
13.786,1.46075,19.89091,0.5,,,,,,,,,,,,,,,,,,,0.139,,,,,,,,,,,,,,,,,,
14.486,1.34402,16.37738,0.5,,,,,,,,,,,,,,,,,,,0.146,,,,,,,,,,,,,,,,,,
15.186,1.22746,13.46466,0.5,,,,,,,,,,,,,,,,,,,0.153,,,,,,,,,,,,,,,,,,
15.886,1.11078,10.91115,0.5,,,,,,,,,,,,,,,,,,,0.16,,,,,,,,,,,,,,,,,,
16.586,0.99416,8.45039,0.5,,,,,,,,,,,,,,,,,,,0.167,,,,,,,,,,,,,,,,,,
17.286,0.87748,6.37819,0.5,,,,,,,,,,,,,,,,,,,0.174,,,,,,,,,,,,,,,,,,
17.986,0.76086,4.57028,0.5,,,,,,,,,,,,,,,,,,,0.181,,,,,,,,,,,,,,,,,,
18.686,0.64424,3.00457,0.5,,,,,,,,,,,,,,,,,,,0.188,,,,,,,,,,,,,,,,,,
19.386,0.52757,1.69972,0.5,,,,,,,,,,,,,,,,,,,0.195,,,,,,,,,,,,,,,,,,
19.81,0.4569,0.97594,1,,,,,,,,,,,,,,,,,,,,,,,,,,,,,,,,,,,,,
20.51,0.5746,2.38871,1,,,,,,,,,,,,,,,,,,,,,,,,,,,,,,,,,,,,,
21.21,0.69122,3.99051,1,,,,,,,,,,,,,,,,,,,,,,,,,,,,,,,,,,,,,
21.91,0.80778,5.90053,1,,,,,,,,,,,,,,,,,,,,,,,,,,,,,,,,,,,,,
22.61,0.92446,8.08288,1,,,,,,,,,,,,,,,,,,,,,,,,,,,,,,,,,,,,,
23.31,1.04119,10.45322,1,,,,,,,,,,,,,,,,,,,,,,,,,,,,,,,,,,,,,
24.01,1.15787,13.11865,1,,,,,,,,,,,,,,,,,,,,,,,,,,,,,,,,,,,,,
24.71,1.27449,16.06948,1,,,,,,,,,,,,,,,,,,,,,,,,,,,,,,,,,,,,,
25.41,1.39111,19.07355,1,,,,,,,,,,,,,,,,,,,,,,,,,,,,,,,,,,,,,
26.11,1.50773,22.42601,1,,,,,,,,,,,,,,,,,,,,,,,,,,,,,,,,,,,,,
26.81,1.62441,26.18536,1,,,,,,,,,,,,,,,,,,,,,,,,,,,,,,,,,,,,,
27.51,1.74108,30.23593,1,,,,,,,,,,,,,,,,,,,,,,,,,,,,,,,,,,,,,
28.21,1.85776,34.54032,1,,,,,,,,,,,,,,,,,,,,,,,,,,,,,,,,,,,,,
28.91,1.97449,39.05116,1,,,,,,,,,,,,,,,,,,,,,,,,,,,,,,,,,,,,,
29.464,1.93324,36.58412,1.5,,,,,,,,,,,,,,,,,,,,,,,,,,,,,,,,,,,,,
30.164,1.81662,30.88488,1.5,,,,,,,,,,,,,,,,,,,,,,,,,,,,,,,,,,,,,
30.864,1.69994,25.99907,1.5,,,,,,,,,,,,,,,,,,,,,,,,,,,,,,,,,,,,,
31.564,1.58327,21.82262,1.5,,,,,,,,,,,,,,,,,,,,,,,,,,,,,,,,,,,,,
32.264,1.46648,18.03013,1.5,,,,,,,,,,,,,,,,,,,,,,,,,,,,,,,,,,,,,
32.964,1.34974,14.81004,1.5,,,,,,,,,,,,,,,,,,,,,,,,,,,,,,,,,,,,,
33.664,1.23307,12.09828,1.5,,,,,,,,,,,,,,,,,,,,,,,,,,,,,,,,,,,,,
34.364,1.11639,9.51162,1.5,,,,,,,,,,,,,,,,,,,,,,,,,,,,,,,,,,,,,
35.064,0.99977,7.27774,1.5,,,,,,,,,,,,,,,,,,,,,,,,,,,,,,,,,,,,,
35.764,0.88315,5.36707,1.5,,,,,,,,,,,,,,,,,,,,,,,,,,,,,,,,,,,,,
36.464,0.76647,3.62626,1.5,,,,,,,,,,,,,,,,,,,,,,,,,,,,,,,,,,,,,
37.164,0.64985,2.26273,1.5,,,,,,,,,,,,,,,,,,,,,,,,,,,,,,,,,,,,,
37.864,0.53323,1.06045,1.5,,,,,,,,,,,,,,,,,,,,,,,,,,,,,,,,,,,,,
38.294,0.59579,1.85169,2,,,,,,,,,,,,,,,,,,,,,,,,,,,,,,,,,,,,,
38.994,0.71241,3.33775,2,,,,,,,,,,,,,,,,,,,,,,,,,,,,,,,,,,,,,
39.694,0.82903,5.11304,2,,,,,,,,,,,,,,,,,,,,,,,,,,,,,,,,,,,,,
40.394,0.94571,7.17358,2,,,,,,,,,,,,,,,,,,,,,,,,,,,,,,,,,,,,,
41.094,1.06239,9.5226,2,,,,,,,,,,,,,,,,,,,,,,,,,,,,,,,,,,,,,
41.794,1.17918,12.07341,2,,,,,,,,,,,,,,,,,,,,,,,,,,,,,,,,,,,,,
42.494,1.29585,14.9986,2,,,,,,,,,,,,,,,,,,,,,,,,,,,,,,,,,,,,,
43.194,1.41253,18.16667,2,,,,,,,,,,,,,,,,,,,,,,,,,,,,,,,,,,,,,
43.894,1.52926,21.35102,2,,,,,,,,,,,,,,,,,,,,,,,,,,,,,,,,,,,,,
44.594,1.64594,25.07997,2,,,,,,,,,,,,,,,,,,,,,,,,,,,,,,,,,,,,,
45.294,1.76262,29.17093,2,,,,,,,,,,,,,,,,,,,,,,,,,,,,,,,,,,,,,
45.994,1.87924,33.54163,2,,,,,,,,,,,,,,,,,,,,,,,,,,,,,,,,,,,,,
46.694,1.9958,38.26498,2,,,,,,,,,,,,,,,,,,,,,,,,,,,,,,,,,,,,,
47.256,1.98934,37.51882,2.5,,,,,,,,,,,,,,,,,,,,,,,,,,,,,,,,,,,,,
47.956,1.87261,31.58506,2.5,,,,,,,,,,,,,,,,,,,,,,,,,,,,,,,,,,,,,
48.656,1.75599,26.62683,2.5,,,,,,,,,,,,,,,,,,,,,,,,,,,,,,,,,,,,,
49.356,1.6392,22.33977,2.5,,,,,,,,,,,,,,,,,,,,,,,,,,,,,,,,,,,,,
50.056,1.52246,18.49279,2.5,,,,,,,,,,,,,,,,,,,,,,,,,,,,,,,,,,,,,
50.756,1.40573,15.23009,2.5,,,,,,,,,,,,,,,,,,,,,,,,,,,,,,,,,,,,,
51.456,1.28905,12.44609,2.5,,,,,,,,,,,,,,,,,,,,,,,,,,,,,,,,,,,,,
52.156,1.17243,9.83554,2.5,,,,,,,,,,,,,,,,,,,,,,,,,,,,,,,,,,,,,
52.856,1.05576,7.61954,2.5,,,,,,,,,,,,,,,,,,,,,,,,,,,,,,,,,,,,,
53.556,0.93914,5.55647,2.5,,,,,,,,,,,,,,,,,,,,,,,,,,,,,,,,,,,,,
54.256,0.82252,3.84322,2.5,,,,,,,,,,,,,,,,,,,,,,,,,,,,,,,,,,,,,
54.956,0.70584,2.41009,2.5,,,,,,,,,,,,,,,,,,,,,,,,,,,,,,,,,,,,,
55.656,0.58928,1.18691,2.5,,,,,,,,,,,,,,,,,,,,,,,,,,,,,,,,,,,,,
56.096,0.61676,1.51193,3,,,,,,,,,,,,,,,,,,,,,,,,,,,,,,,,,,,,,
56.796,0.73349,2.97944,3,,,,,,,,,,,,,,,,,,,,,,,,,,,,,,,,,,,,,
57.496,0.85023,4.70603,3,,,,,,,,,,,,,,,,,,,,,,,,,,,,,,,,,,,,,
58.196,0.9669,6.78396,3,,,,,,,,,,,,,,,,,,,,,,,,,,,,,,,,,,,,,
58.896,1.08364,9.11244,3,,,,,,,,,,,,,,,,,,,,,,,,,,,,,,,,,,,,,
59.596,1.2002,11.62173,3,,,,,,,,,,,,,,,,,,,,,,,,,,,,,,,,,,,,,
60.296,1.31682,14.46717,3,,,,,,,,,,,,,,,,,,,,,,,,,,,,,,,,,,,,,
60.996,1.43344,17.67154,3,,,,,,,,,,,,,,,,,,,,,,,,,,,,,,,,,,,,,
61.696,1.55012,20.86116,3,,,,,,,,,,,,,,,,,,,,,,,,,,,,,,,,,,,,,
62.396,1.66685,24.54757,3,,,,,,,,,,,,,,,,,,,,,,,,,,,,,,,,,,,,,
63.096,1.78347,28.59971,3,,,,,,,,,,,,,,,,,,,,,,,,,,,,,,,,,,,,,
63.796,1.90015,33.055,3,,,,,,,,,,,,,,,,,,,,,,,,,,,,,,,,,,,,,
64.496,2.01677,37.88527,3,,,,,,,,,,,,,,,,,,,,,,,,,,,,,,,,,,,,,
65,2.03433,38.4993,3.5,,,,,,,,,,,,,,,,,,,,,,,,,,,,,,,,,,,,,
65.7,1.9172,32.386,3.5,,,,,,,,,,,,,,,,,,,,,,,,,,,,,,,,,,,,,
66.4,1.80041,27.32026,3.5,,,,,,,,,,,,,,,,,,,,,,,,,,,,,,,,,,,,,
67.1,1.68374,22.90255,3.5,,,,,,,,,,,,,,,,,,,,,,,,,,,,,,,,,,,,,
67.8,1.56706,19.01781,3.5,,,,,,,,,,,,,,,,,,,,,,,,,,,,,,,,,,,,,
68.5,1.45044,15.67776,3.5,,,,,,,,,,,,,,,,,,,,,,,,,,,,,,,,,,,,,
69.2,1.33382,12.83749,3.5,,,,,,,,,,,,,,,,,,,,,,,,,,,,,,,,,,,,,
69.9,1.2172,10.21507,3.5,,,,,,,,,,,,,,,,,,,,,,,,,,,,,,,,,,,,,
70.6,1.10047,7.78419,3.5,,,,,,,,,,,,,,,,,,,,,,,,,,,,,,,,,,,,,
71.3,0.9839,5.7652,3.5,,,,,,,,,,,,,,,,,,,,,,,,,,,,,,,,,,,,,
72,0.86717,4.03728,3.5,,,,,,,,,,,,,,,,,,,,,,,,,,,,,,,,,,,,,
72.7,0.75049,2.54731,3.5,,,,,,,,,,,,,,,,,,,,,,,,,,,,,,,,,,,,,
73.4,0.63393,1.32689,3.5,,,,,,,,,,,,,,,,,,,,,,,,,,,,,,,,,,,,,
73.814,0.63212,1.23541,4,,,,,,,,,,,,,,,,,,,,,,,,,,,,,,,,,,,,,
74.514,0.74919,2.77262,4,,,,,,,,,,,,,,,,,,,,,,,,,,,,,,,,,,,,,
75.214,0.86587,4.48889,4,,,,,,,,,,,,,,,,,,,,,,,,,,,,,,,,,,,,,
75.914,0.98243,6.59666,4,,,,,,,,,,,,,,,,,,,,,,,,,,,,,,,,,,,,,
76.614,1.09911,8.80593,4,,,,,,,,,,,,,,,,,,,,,,,,,,,,,,,,,,,,,
77.314,1.21578,11.30539,4,,,,,,,,,,,,,,,,,,,,,,,,,,,,,,,,,,,,,
78.014,1.33252,14.15072,4,,,,,,,,,,,,,,,,,,,,,,,,,,,,,,,,,,,,,
78.714,1.44919,17.2799,4,,,,,,,,,,,,,,,,,,,,,,,,,,,,,,,,,,,,,
79.414,1.56576,20.44253,4,,,,,,,,,,,,,,,,,,,,,,,,,,,,,,,,,,,,,
80.114,1.68238,24.20504,4,,,,,,,,,,,,,,,,,,,,,,,,,,,,,,,,,,,,,
80.814,1.79911,28.23857,4,,,,,,,,,,,,,,,,,,,,,,,,,,,,,,,,,,,,,
81.514,1.91584,32.75611,4,,,,,,,,,,,,,,,,,,,,,,,,,,,,,,,,,,,,,
82.214,2.03252,37.58195,4,,,,,,,,,,,,,,,,,,,,,,,,,,,,,,,,,,,,,
82.754,2.05609,38.5467,4.5,,,,,,,,,,,,,,,,,,,,,,,,,,,,,,,,,,,,,
83.454,1.93896,32.4347,4.5,,,,,,,,,,,,,,,,,,,,,,,,,,,,,,,,,,,,,
84.154,1.82229,27.33581,4.5,,,,,,,,,,,,,,,,,,,,,,,,,,,,,,,,,,,,,
84.854,1.70555,22.92319,4.5,,,,,,,,,,,,,,,,,,,,,,,,,,,,,,,,,,,,,
85.554,1.58888,19.02248,4.5,,,,,,,,,,,,,,,,,,,,,,,,,,,,,,,,,,,,,
86.254,1.4722,15.61463,4.5,,,,,,,,,,,,,,,,,,,,,,,,,,,,,,,,,,,,,
86.954,1.35564,12.78148,4.5,,,,,,,,,,,,,,,,,,,,,,,,,,,,,,,,,,,,,
87.654,1.23885,10.00641,4.5,,,,,,,,,,,,,,,,,,,,,,,,,,,,,,,,,,,,,
88.354,1.12206,7.75443,4.5,,,,,,,,,,,,,,,,,,,,,,,,,,,,,,,,,,,,,
89.054,1.00538,5.71967,4.5,,,,,,,,,,,,,,,,,,,,,,,,,,,,,,,,,,,,,
89.754,0.8887,4.00409,4.5,,,,,,,,,,,,,,,,,,,,,,,,,,,,,,,,,,,,,
90.454,0.77214,2.46201,4.5,,,,,,,,,,,,,,,,,,,,,,,,,,,,,,,,,,,,,
91.154,0.65552,1.28585,4.5,,,,,,,,,,,,,,,,,,,,,,,,,,,,,,,,,,,,,
91.626,0.67779,1.51318,5,,,,,,,,,,,,,,,,,,,,,,,,,,,,,,,,,,,,,
92.326,0.79458,2.99311,5,,,,,,,,,,,,,,,,,,,,,,,,,,,,,,,,,,,,,
93.026,0.91131,4.81561,5,,,,,,,,,,,,,,,,,,,,,,,,,,,,,,,,,,,,,
93.726,1.02793,6.87009,5,,,,,,,,,,,,,,,,,,,,,,,,,,,,,,,,,,,,,
94.426,1.14455,9.21493,5,,,,,,,,,,,,,,,,,,,,,,,,,,,,,,,,,,,,,
95.126,1.26112,11.76639,5,,,,,,,,,,,,,,,,,,,,,,,,,,,,,,,,,,,,,
95.826,1.37779,14.73487,5,,,,,,,,,,,,,,,,,,,,,,,,,,,,,,,,,,,,,
96.526,1.49441,17.91975,5,,,,,,,,,,,,,,,,,,,,,,,,,,,,,,,,,,,,,
97.226,1.61115,21.11018,5,,,,,,,,,,,,,,,,,,,,,,,,,,,,,,,,,,,,,
97.926,1.72782,24.95866,5,,,,,,,,,,,,,,,,,,,,,,,,,,,,,,,,,,,,,
98.626,1.84444,29.22067,5,,,,,,,,,,,,,,,,,,,,,,,,,,,,,,,,,,,,,
99.326,1.96106,33.8089,5,,,,,,,,,,,,,,,,,,,,,,,,,,,,,,,,,,,,,
100.026,2.0778,38.75841,5,,,,,,,,,,,,,,,,,,,,,,,,,,,,,,,,,,,,,
100.606,2.04096,36.63718,5.5,,,,,,,,,,,,,,,,,,,,,,,,,,,,,,,,,,,,,
101.306,1.92429,30.91767,5.5,,,,,,,,,,,,,,,,,,,,,,,,,,,,,,,,,,,,,
102.006,1.8075,26.08552,5.5,,,,,,,,,,,,,,,,,,,,,,,,,,,,,,,,,,,,,
102.706,1.69082,21.75362,5.5,,,,,,,,,,,,,,,,,,,,,,,,,,,,,,,,,,,,,
103.406,1.57409,17.97051,5.5,,,,,,,,,,,,,,,,,,,,,,,,,,,,,,,,,,,,,
104.106,1.45735,14.74689,5.5,,,,,,,,,,,,,,,,,,,,,,,,,,,,,,,,,,,,,
104.806,1.34068,11.98162,5.5,,,,,,,,,,,,,,,,,,,,,,,,,,,,,,,,,,,,,
105.506,1.22411,9.38805,5.5,,,,,,,,,,,,,,,,,,,,,,,,,,,,,,,,,,,,,
106.206,1.10749,7.14017,5.5,,,,,,,,,,,,,,,,,,,,,,,,,,,,,,,,,,,,,
106.906,0.99082,5.16322,5.5,,,,,,,,,,,,,,,,,,,,,,,,,,,,,,,,,,,,,
107.606,0.87414,3.51458,5.5,,,,,,,,,,,,,,,,,,,,,,,,,,,,,,,,,,,,,
108.306,0.75752,2.11325,5.5,,,,,,,,,,,,,,,,,,,,,,,,,,,,,,,,,,,,,
108.944,0.65116,0.99676,6,,,,,,,,,,,,,,,,,,,,,,,,,,,,,,,,,,,,,
109.448,0.73491,1.99596,6,,,,,,,,,,,,,,,,,,,,,,,,,,,,,,,,,,,,,
110.148,0.85153,3.53835,6,,,,,,,,,,,,,,,,,,,,,,,,,,,,,,,,,,,,,
110.848,0.96826,5.43876,6,,,,,,,,,,,,,,,,,,,,,,,,,,,,,,,,,,,,,
111.548,1.08488,7.56692,6,,,,,,,,,,,,,,,,,,,,,,,,,,,,,,,,,,,,,
112.248,1.20156,9.96862,6,,,,,,,,,,,,,,,,,,,,,,,,,,,,,,,,,,,,,
112.948,1.31824,12.67894,6,,,,,,,,,,,,,,,,,,,,,,,,,,,,,,,,,,,,,
113.648,1.4348,15.70245,6,,,,,,,,,,,,,,,,,,,,,,,,,,,,,,,,,,,,,
114.348,1.55142,18.92197,6,,,,,,,,,,,,,,,,,,,,,,,,,,,,,,,,,,,,,
115.048,1.66815,22.39489,6,,,,,,,,,,,,,,,,,,,,,,,,,,,,,,,,,,,,,
115.748,1.78483,26.39935,6,,,,,,,,,,,,,,,,,,,,,,,,,,,,,,,,,,,,,
116.448,1.90151,30.79305,6,,,,,,,,,,,,,,,,,,,,,,,,,,,,,,,,,,,,,
117.148,2.01807,35.5217,6,,,,,,,,,,,,,,,,,,,,,,,,,,,,,,,,,,,,,
117.776,2.12279,40.01621,6.5,,,,,,,,,,,,,,,,,,,,,,,,,,,,,,,,,,,,,
118.378,2.02277,34.97561,6.5,,,,,,,,,,,,,,,,,,,,,,,,,,,,,,,,,,,,,
119.078,1.9061,29.46535,6.5,,,,,,,,,,,,,,,,,,,,,,,,,,,,,,,,,,,,,
119.778,1.78953,24.77647,6.5,,,,,,,,,,,,,,,,,,,,,,,,,,,,,,,,,,,,,
120.478,1.67286,20.64937,6.5,,,,,,,,,,,,,,,,,,,,,,,,,,,,,,,,,,,,,
121.178,1.55618,16.96728,6.5,,,,,,,,,,,,,,,,,,,,,,,,,,,,,,,,,,,,,
121.878,1.43956,13.94389,6.5,,,,,,,,,,,,,,,,,,,,,,,,,,,,,,,,,,,,,
122.578,1.32294,11.17887,6.5,,,,,,,,,,,,,,,,,,,,,,,,,,,,,,,,,,,,,
123.278,1.20626,8.70271,6.5,,,,,,,,,,,,,,,,,,,,,,,,,,,,,,,,,,,,,
123.978,1.08953,6.55674,6.5,,,,,,,,,,,,,,,,,,,,,,,,,,,,,,,,,,,,,
124.678,0.97291,4.71475,6.5,,,,,,,,,,,,,,,,,,,,,,,,,,,,,,,,,,,,,
125.378,0.85623,3.12899,6.5,,,,,,,,,,,,,,,,,,,,,,,,,,,,,,,,,,,,,
126.078,0.73961,1.71403,6.5,,,,,,,,,,,,,,,,,,,,,,,,,,,,,,,,,,,,,
126.534,0.6634,0.99038,7,,,,,,,,,,,,,,,,,,,,,,,,,,,,,,,,,,,,,
127.234,0.78115,2.32801,7,,,,,,,,,,,,,,,,,,,,,,,,,,,,,,,,,,,,,
127.934,0.89783,4.01064,7,,,,,,,,,,,,,,,,,,,,,,,,,,,,,,,,,,,,,
128.634,1.0145,5.94898,7,,,,,,,,,,,,,,,,,,,,,,,,,,,,,,,,,,,,,
129.334,1.13118,8.20205,7,,,,,,,,,,,,,,,,,,,,,,,,,,,,,,,,,,,,,
130.034,1.24791,10.78143,7,,,,,,,,,,,,,,,,,,,,,,,,,,,,,,,,,,,,,
130.734,1.36465,13.45218,7,,,,,,,,,,,,,,,,,,,,,,,,,,,,,,,,,,,,,
131.434,1.48127,16.53521,7,,,,,,,,,,,,,,,,,,,,,,,,,,,,,,,,,,,,,
132.134,1.59794,19.72409,7,,,,,,,,,,,,,,,,,,,,,,,,,,,,,,,,,,,,,
132.834,1.71445,23.47842,7,,,,,,,,,,,,,,,,,,,,,,,,,,,,,,,,,,,,,
133.534,1.83113,27.57612,7,,,,,,,,,,,,,,,,,,,,,,,,,,,,,,,,,,,,,
134.234,1.9478,32.05959,7,,,,,,,,,,,,,,,,,,,,,,,,,,,,,,,,,,,,,
134.934,2.06448,36.91882,7,,,,,,,,,,,,,,,,,,,,,,,,,,,,,,,,,,,,,
135.458,2.12279,39.8992,7.5,,,,,,,,,,,,,,,,,,,,,,,,,,,,,,,,,,,,,
136.158,2.00158,33.26612,7.5,,,,,,,,,,,,,,,,,,,,,,,,,,,,,,,,,,,,,
136.858,1.88496,27.97229,7.5,,,,,,,,,,,,,,,,,,,,,,,,,,,,,,,,,,,,,
137.558,1.76823,23.49005,7.5,,,,,,,,,,,,,,,,,,,,,,,,,,,,,,,,,,,,,
138.258,1.65149,19.44797,7.5,,,,,,,,,,,,,,,,,,,,,,,,,,,,,,,,,,,,,
138.958,1.53487,16.02196,7.5,,,,,,,,,,,,,,,,,,,,,,,,,,,,,,,,,,,,,
139.658,1.41825,13.06416,7.5,,,,,,,,,,,,,,,,,,,,,,,,,,,,,,,,,,,,,
140.358,1.30158,10.36714,7.5,,,,,,,,,,,,,,,,,,,,,,,,,,,,,,,,,,,,,
141.058,1.1849,8.0261,7.5,,,,,,,,,,,,,,,,,,,,,,,,,,,,,,,,,,,,,
141.758,1.06817,5.93996,7.5,,,,,,,,,,,,,,,,,,,,,,,,,,,,,,,,,,,,,
142.458,0.95143,4.145,7.5,,,,,,,,,,,,,,,,,,,,,,,,,,,,,,,,,,,,,
143.158,0.8347,2.62164,7.5,,,,,,,,,,,,,,,,,,,,,,,,,,,,,,,,,,,,,
143.858,0.71808,1.37514,7.5,,,,,,,,,,,,,,,,,,,,,,,,,,,,,,,,,,,,,
144.356,0.73621,1.56723,8,,,,,,,,,,,,,,,,,,,,,,,,,,,,,,,,,,,,,
145.056,0.85289,3.18707,8,,,,,,,,,,,,,,,,,,,,,,,,,,,,,,,,,,,,,
145.756,0.96957,4.99536,8,,,,,,,,,,,,,,,,,,,,,,,,,,,,,,,,,,,,,
146.456,1.08619,7.03965,8,,,,,,,,,,,,,,,,,,,,,,,,,,,,,,,,,,,,,
147.156,1.20286,9.41442,8,,,,,,,,,,,,,,,,,,,,,,,,,,,,,,,,,,,,,
147.856,1.31948,11.98716,8,,,,,,,,,,,,,,,,,,,,,,,,,,,,,,,,,,,,,
148.556,1.4361,14.9664,8,,,,,,,,,,,,,,,,,,,,,,,,,,,,,,,,,,,,,
149.256,1.55278,18.18262,8,,,,,,,,,,,,,,,,,,,,,,,,,,,,,,,,,,,,,
149.956,1.66946,21.51039,8,,,,,,,,,,,,,,,,,,,,,,,,,,,,,,,,,,,,,
150.656,1.78619,25.42694,8,,,,,,,,,,,,,,,,,,,,,,,,,,,,,,,,,,,,,
151.356,1.90287,29.79344,8,,,,,,,,,,,,,,,,,,,,,,,,,,,,,,,,,,,,,
152.056,2.01943,34.52572,8,,,,,,,,,,,,,,,,,,,,,,,,,,,,,,,,,,,,,
152.756,2.13605,39.60331,8,,,,,,,,,,,,,,,,,,,,,,,,,,,,,,,,,,,,,
153.314,2.06289,35.77689,8.5,,,,,,,,,,,,,,,,,,,,,,,,,,,,,,,,,,,,,
154.014,1.94627,30.19285,8.5,,,,,,,,,,,,,,,,,,,,,,,,,,,,,,,,,,,,,
154.714,1.8296,25.39682,8.5,,,,,,,,,,,,,,,,,,,,,,,,,,,,,,,,,,,,,
155.414,1.71292,21.16897,8.5,,,,,,,,,,,,,,,,,,,,,,,,,,,,,,,,,,,,,
156.114,1.59619,17.47516,8.5,,,,,,,,,,,,,,,,,,,,,,,,,,,,,,,,,,,,,
156.814,1.47957,14.27156,8.5,,,,,,,,,,,,,,,,,,,,,,,,,,,,,,,,,,,,,
157.514,1.36289,11.48306,8.5,,,,,,,,,,,,,,,,,,,,,,,,,,,,,,,,,,,,,
158.214,1.24621,8.93243,8.5,,,,,,,,,,,,,,,,,,,,,,,,,,,,,,,,,,,,,
158.914,1.12959,6.76235,8.5,,,,,,,,,,,,,,,,,,,,,,,,,,,,,,,,,,,,,
159.614,1.01286,4.9249,8.5,,,,,,,,,,,,,,,,,,,,,,,,,,,,,,,,,,,,,
160.314,0.89601,3.30129,8.5,,,,,,,,,,,,,,,,,,,,,,,,,,,,,,,,,,,,,
161.014,0.77939,1.89614,8.5,,,,,,,,,,,,,,,,,,,,,,,,,,,,,,,,,,,,,
161.538,0.69218,0.99279,9,,,,,,,,,,,,,,,,,,,,,,,,,,,,,,,,,,,,,
162.14,0.79288,2.14585,9,,,,,,,,,,,,,,,,,,,,,,,,,,,,,,,,,,,,,
162.84,0.90961,3.76671,9,,,,,,,,,,,,,,,,,,,,,,,,,,,,,,,,,,,,,
163.54,1.02623,5.66162,9,,,,,,,,,,,,,,,,,,,,,,,,,,,,,,,,,,,,,
164.24,1.14285,7.8808,9,,,,,,,,,,,,,,,,,,,,,,,,,,,,,,,,,,,,,
164.94,1.25953,10.37971,9,,,,,,,,,,,,,,,,,,,,,,,,,,,,,,,,,,,,,
165.64,1.37615,13.11551,9,,,,,,,,,,,,,,,,,,,,,,,,,,,,,,,,,,,,,
166.34,1.49283,16.14161,9,,,,,,,,,,,,,,,,,,,,,,,,,,,,,,,,,,,,,
167.04,1.6095,19.40934,9,,,,,,,,,,,,,,,,,,,,,,,,,,,,,,,,,,,,,
167.74,1.72607,23.05692,9,,,,,,,,,,,,,,,,,,,,,,,,,,,,,,,,,,,,,
168.44,1.84274,27.13937,9,,,,,,,,,,,,,,,,,,,,,,,,,,,,,,,,,,,,,
169.14,1.95948,31.63855,9,,,,,,,,,,,,,,,,,,,,,,,,,,,,,,,,,,,,,
169.84,2.07615,36.51797,9,,,,,,,,,,,,,,,,,,,,,,,,,,,,,,,,,,,,,
170.422,2.14398,39.97775,9.5,,,,,,,,,,,,,,,,,,,,,,,,,,,,,,,,,,,,,
171.122,2.02277,33.32963,9.5,,,,,,,,,,,,,,,,,,,,,,,,,,,,,,,,,,,,,
171.822,1.90615,28.03789,9.5,,,,,,,,,,,,,,,,,,,,,,,,,,,,,,,,,,,,,
172.522,1.78953,23.54508,9.5,,,,,,,,,,,,,,,,,,,,,,,,,,,,,,,,,,,,,
173.222,1.67286,19.47079,9.5,,,,,,,,,,,,,,,,,,,,,,,,,,,,,,,,,,,,,
173.922,1.55612,16.03558,9.5,,,,,,,,,,,,,,,,,,,,,,,,,,,,,,,,,,,,,
174.622,1.43956,13.05495,9.5,,,,,,,,,,,,,,,,,,,,,,,,,,,,,,,,,,,,,
175.322,1.32294,10.28628,9.5,,,,,,,,,,,,,,,,,,,,,,,,,,,,,,,,,,,,,
176.022,1.20626,7.94157,9.5,,,,,,,,,,,,,,,,,,,,,,,,,,,,,,,,,,,,,
176.722,1.08953,5.94408,9.5,,,,,,,,,,,,,,,,,,,,,,,,,,,,,,,,,,,,,
177.422,0.97285,4.18254,9.5,,,,,,,,,,,,,,,,,,,,,,,,,,,,,,,,,,,,,
178.122,0.85623,2.71538,9.5,,,,,,,,,,,,,,,,,,,,,,,,,,,,,,,,,,,,,
178.822,0.73961,1.33091,9.5,,,,,,,,,,,,,,,,,,,,,,,,,,,,,,,,,,,,,
179.346,0.67003,0.58038,10,,,,,,,,,,,,,,,,,,,,,,,,,,,,,,,,,,,,,
180.046,0.66731,0.70419,10,,,,,,,,,,,,,,,,,,,,,,,,,,,,,,,,,,,,,
180.746,0.6834,0.8528,10,,,,,,,,,,,,,,,,,,,,,,,,,,,,,,,,,,,,,
181.446,0.73298,1.5209,10,,,,,,,,,,,,,,,,,,,,,,,,,,,,,,,,,,,,,
182.146,0.73259,1.51456,10,,,,,,,,,,,,,,,,,,,,,,,,,,,,,,,,,,,,,
182.846,0.71904,1.31683,10,,,,,,,,,,,,,,,,,,,,,,,,,,,,,,,,,,,,,
183.546,0.69184,1.01261,10,,,,,,,,,,,,,,,,,,,,,,,,,,,,,,,,,,,,,
184.246,0.69162,1.04281,10,,,,,,,,,,,,,,,,,,,,,,,,,,,,,,,,,,,,,
184.946,0.6919,1.05454,10,,,,,,,,,,,,,,,,,,,,,,,,,,,,,,,,,,,,,
185.646,0.69218,1.07321,10,,,,,,,,,,,,,,,,,,,,,,,,,,,,,,,,,,,,,
186.346,0.69258,1.11297,10,,,,,,,,,,,,,,,,,,,,,,,,,,,,,,,,,,,,,
187.046,0.69326,1.11854,10,,,,,,,,,,,,,,,,,,,,,,,,,,,,,,,,,,,,,
187.746,0.69428,1.11627,10,,,,,,,,,,,,,,,,,,,,,,,,,,,,,,,,,,,,,
188.446,0.6949,1.14597,10,,,,,,,,,,,,,,,,,,,,,,,,,,,,,,,,,,,,,
189.146,0.69547,1.13148,10,,,,,,,,,,,,,,,,,,,,,,,,,,,,,,,,,,,,,
189.846,0.69581,1.18012,10,,,,,,,,,,,,,,,,,,,,,,,,,,,,,,,,,,,,,
190.546,0.69587,1.24156,10,,,,,,,,,,,,,,,,,,,,,,,,,,,,,,,,,,,,,
191.246,0.69581,1.18522,10,,,,,,,,,,,,,,,,,,,,,,,,,,,,,,,,,,,,,
191.946,0.69592,1.16113,10,,,,,,,,,,,,,,,,,,,,,,,,,,,,,,,,,,,,,
192.646,0.69581,1.15664,10,,,,,,,,,,,,,,,,,,,,,,,,,,,,,,,,,,,,,
193.346,0.6957,1.15145,10,,,,,,,,,,,,,,,,,,,,,,,,,,,,,,,,,,,,,
194.046,0.6957,1.21077,10,,,,,,,,,,,,,,,,,,,,,,,,,,,,,,,,,,,,,
194.746,0.69547,1.17768,10,,,,,,,,,,,,,,,,,,,,,,,,,,,,,,,,,,,,,
195.446,0.6953,1.22221,10,,,,,,,,,,,,,,,,,,,,,,,,,,,,,,,,,,,,,
196.146,0.69496,1.32185,10,,,,,,,,,,,,,,,,,,,,,,,,,,,,,,,,,,,,,
196.846,0.69439,1.19762,10,,,,,,,,,,,,,,,,,,,,,,,,,,,,,,,,,,,,,
197.546,0.6932,1.18889,10,,,,,,,,,,,,,,,,,,,,,,,,,,,,,,,,,,,,,
198.246,0.69128,1.21127,10,,,,,,,,,,,,,,,,,,,,,,,,,,,,,,,,,,,,,
198.946,0.68703,1.11692,10,,,,,,,,,,,,,,,,,,,,,,,,,,,,,,,,,,,,,
199.646,0.68487,1.13259,10,,,,,,,,,,,,,,,,,,,,,,,,,,,,,,,,,,,,,
200.346,0.68442,1.08744,10,,,,,,,,,,,,,,,,,,,,,,,,,,,,,,,,,,,,,
201.046,0.68419,1.09602,10,,,,,,,,,,,,,,,,,,,,,,,,,,,,,,,,,,,,,
201.746,0.68408,1.08067,10,,,,,,,,,,,,,,,,,,,,,,,,,,,,,,,,,,,,,
202.446,0.68414,1.10496,10,,,,,,,,,,,,,,,,,,,,,,,,,,,,,,,,,,,,,
203.146,0.68419,1.13452,10,,,,,,,,,,,,,,,,,,,,,,,,,,,,,,,,,,,,,
203.846,0.68431,1.15649,10,,,,,,,,,,,,,,,,,,,,,,,,,,,,,,,,,,,,,
204.546,0.68436,1.12411,10,,,,,,,,,,,,,,,,,,,,,,,,,,,,,,,,,,,,,
205.246,0.68436,1.15545,10,,,,,,,,,,,,,,,,,,,,,,,,,,,,,,,,,,,,,
205.946,0.68436,1.16308,10,,,,,,,,,,,,,,,,,,,,,,,,,,,,,,,,,,,,,
206.646,0.68436,1.15514,10,,,,,,,,,,,,,,,,,,,,,,,,,,,,,,,,,,,,,
207.346,0.68436,1.1616,10,,,,,,,,,,,,,,,,,,,,,,,,,,,,,,,,,,,,,
208.046,0.68436,1.12702,10,,,,,,,,,,,,,,,,,,,,,,,,,,,,,,,,,,,,,
208.746,0.68425,1.10661,10,,,,,,,,,,,,,,,,,,,,,,,,,,,,,,,,,,,,,
209.446,0.68425,1.15935,10,,,,,,,,,,,,,,,,,,,,,,,,,,,,,,,,,,,,,
210.146,0.68419,1.08985,10,,,,,,,,,,,,,,,,,,,,,,,,,,,,,,,,,,,,,
210.846,0.68414,1.13187,10,,,,,,,,,,,,,,,,,,,,,,,,,,,,,,,,,,,,,
211.546,0.68414,1.14017,10,,,,,,,,,,,,,,,,,,,,,,,,,,,,,,,,,,,,,
212.246,0.68419,1.13719,10,,,,,,,,,,,,,,,,,,,,,,,,,,,,,,,,,,,,,
212.946,0.68408,1.1353,10,,,,,,,,,,,,,,,,,,,,,,,,,,,,,,,,,,,,,
213.646,0.68408,1.18344,10,,,,,,,,,,,,,,,,,,,,,,,,,,,,,,,,,,,,,
214.346,0.68397,1.16295,10,,,,,,,,,,,,,,,,,,,,,,,,,,,,,,,,,,,,,
215.046,0.68306,1.23219,10,,,,,,,,,,,,,,,,,,,,,,,,,,,,,,,,,,,,,
215.746,0.68074,1.13982,10,,,,,,,,,,,,,,,,,,,,,,,,,,,,,,,,,,,,,
216.446,0.67892,1.14776,10,,,,,,,,,,,,,,,,,,,,,,,,,,,,,,,,,,,,,
217.146,0.6783,1.13394,10,,,,,,,,,,,,,,,,,,,,,,,,,,,,,,,,,,,,,
217.846,0.67796,1.06292,10,,,,,,,,,,,,,,,,,,,,,,,,,,,,,,,,,,,,,
218.546,0.67796,1.09431,10,,,,,,,,,,,,,,,,,,,,,,,,,,,,,,,,,,,,,
219.246,0.67813,1.0737,10,,,,,,,,,,,,,,,,,,,,,,,,,,,,,,,,,,,,,
219.946,0.67819,1.1498,10,,,,,,,,,,,,,,,,,,,,,,,,,,,,,,,,,,,,,
220.646,0.67824,1.07151,10,,,,,,,,,,,,,,,,,,,,,,,,,,,,,,,,,,,,,
221.346,0.67836,1.11638,10,,,,,,,,,,,,,,,,,,,,,,,,,,,,,,,,,,,,,
222.046,0.67841,1.04803,10,,,,,,,,,,,,,,,,,,,,,,,,,,,,,,,,,,,,,
222.746,0.67847,1.1247,10,,,,,,,,,,,,,,,,,,,,,,,,,,,,,,,,,,,,,
223.446,0.67853,1.1259,10,,,,,,,,,,,,,,,,,,,,,,,,,,,,,,,,,,,,,
224.146,0.67853,1.13078,10,,,,,,,,,,,,,,,,,,,,,,,,,,,,,,,,,,,,,
224.846,0.67853,1.15577,10,,,,,,,,,,,,,,,,,,,,,,,,,,,,,,,,,,,,,
225.546,0.67853,1.11644,10,,,,,,,,,,,,,,,,,,,,,,,,,,,,,,,,,,,,,
226.246,0.67853,1.16832,10,,,,,,,,,,,,,,,,,,,,,,,,,,,,,,,,,,,,,
226.946,0.67853,1.17482,10,,,,,,,,,,,,,,,,,,,,,,,,,,,,,,,,,,,,,
227.646,0.67853,1.15465,10,,,,,,,,,,,,,,,,,,,,,,,,,,,,,,,,,,,,,
228.346,0.67853,1.1653,10,,,,,,,,,,,,,,,,,,,,,,,,,,,,,,,,,,,,,
229.046,0.67853,1.17507,10,,,,,,,,,,,,,,,,,,,,,,,,,,,,,,,,,,,,,
229.746,0.67853,1.12776,10,,,,,,,,,,,,,,,,,,,,,,,,,,,,,,,,,,,,,
230.446,0.67853,1.12714,10,,,,,,,,,,,,,,,,,,,,,,,,,,,,,,,,,,,,,
231.146,0.67853,1.17886,10,,,,,,,,,,,,,,,,,,,,,,,,,,,,,,,,,,,,,
231.846,0.67853,1.13661,10,,,,,,,,,,,,,,,,,,,,,,,,,,,,,,,,,,,,,
232.546,0.67853,1.16333,10,,,,,,,,,,,,,,,,,,,,,,,,,,,,,,,,,,,,,
233.246,0.67853,1.19834,10,,,,,,,,,,,,,,,,,,,,,,,,,,,,,,,,,,,,,
233.946,0.67853,1.16605,10,,,,,,,,,,,,,,,,,,,,,,,,,,,,,,,,,,,,,
234.646,0.67853,1.09028,10,,,,,,,,,,,,,,,,,,,,,,,,,,,,,,,,,,,,,
235.346,0.67853,1.16278,10,,,,,,,,,,,,,,,,,,,,,,,,,,,,,,,,,,,,,
236.046,0.67853,1.10057,10,,,,,,,,,,,,,,,,,,,,,,,,,,,,,,,,,,,,,
236.746,0.67853,1.17404,10,,,,,,,,,,,,,,,,,,,,,,,,,,,,,,,,,,,,,
237.446,0.67841,1.13736,10,,,,,,,,,,,,,,,,,,,,,,,,,,,,,,,,,,,,,
238.146,0.67853,1.15886,10,,,,,,,,,,,,,,,,,,,,,,,,,,,,,,,,,,,,,
238.846,0.67841,1.13752,10,,,,,,,,,,,,,,,,,,,,,,,,,,,,,,,,,,,,,
239.546,0.67841,1.12998,10,,,,,,,,,,,,,,,,,,,,,,,,,,,,,,,,,,,,,
240.246,0.67841,1.19332,10,,,,,,,,,,,,,,,,,,,,,,,,,,,,,,,,,,,,,
240.946,0.67841,1.18735,10,,,,,,,,,,,,,,,,,,,,,,,,,,,,,,,,,,,,,
241.646,0.67847,1.14944,10,,,,,,,,,,,,,,,,,,,,,,,,,,,,,,,,,,,,,
242.346,0.67847,1.12591,10,,,,,,,,,,,,,,,,,,,,,,,,,,,,,,,,,,,,,
243.046,0.67847,1.12769,10,,,,,,,,,,,,,,,,,,,,,,,,,,,,,,,,,,,,,
243.746,0.67836,1.20051,10,,,,,,,,,,,,,,,,,,,,,,,,,,,,,,,,,,,,,
244.446,0.6783,1.2028,10,,,,,,,,,,,,,,,,,,,,,,,,,,,,,,,,,,,,,
245.146,0.67824,1.19607,10,,,,,,,,,,,,,,,,,,,,,,,,,,,,,,,,,,,,,
245.846,0.67824,1.14728,10,,,,,,,,,,,,,,,,,,,,,,,,,,,,,,,,,,,,,
246.546,0.67819,1.1538,10,,,,,,,,,,,,,,,,,,,,,,,,,,,,,,,,,,,,,
247.246,0.67813,1.2449,10,,,,,,,,,,,,,,,,,,,,,,,,,,,,,,,,,,,,,
247.946,0.67802,1.15862,10,,,,,,,,,,,,,,,,,,,,,,,,,,,,,,,,,,,,,
248.646,0.67773,1.15425,10,,,,,,,,,,,,,,,,,,,,,,,,,,,,,,,,,,,,,
249.346,0.67734,1.18877,10,,,,,,,,,,,,,,,,,,,,,,,,,,,,,,,,,,,,,
250.046,0.67547,1.1612,10,,,,,,,,,,,,,,,,,,,,,,,,,,,,,,,,,,,,,
250.746,0.67184,1.13247,10,,,,,,,,,,,,,,,,,,,,,,,,,,,,,,,,,,,,,
251.446,0.6711,1.07628,10,,,,,,,,,,,,,,,,,,,,,,,,,,,,,,,,,,,,,
252.146,0.67099,1.06706,10,,,,,,,,,,,,,,,,,,,,,,,,,,,,,,,,,,,,,
252.846,0.67116,1.07164,10,,,,,,,,,,,,,,,,,,,,,,,,,,,,,,,,,,,,,
253.546,0.67122,1.16333,10,,,,,,,,,,,,,,,,,,,,,,,,,,,,,,,,,,,,,
254.246,0.67139,1.1676,10,,,,,,,,,,,,,,,,,,,,,,,,,,,,,,,,,,,,,
254.946,0.67144,1.13277,10,,,,,,,,,,,,,,,,,,,,,,,,,,,,,,,,,,,,,
255.646,0.67161,1.09539,10,,,,,,,,,,,,,,,,,,,,,,,,,,,,,,,,,,,,,
256.346,0.67173,1.13815,10,,,,,,,,,,,,,,,,,,,,,,,,,,,,,,,,,,,,,
257.046,0.67178,1.15169,10,,,,,,,,,,,,,,,,,,,,,,,,,,,,,,,,,,,,,
257.746,0.6719,1.09586,10,,,,,,,,,,,,,,,,,,,,,,,,,,,,,,,,,,,,,
258.446,0.67207,1.08874,10,,,,,,,,,,,,,,,,,,,,,,,,,,,,,,,,,,,,,
259.146,0.67224,1.14022,10,,,,,,,,,,,,,,,,,,,,,,,,,,,,,,,,,,,,,
259.846,0.67235,1.10958,10,,,,,,,,,,,,,,,,,,,,,,,,,,,,,,,,,,,,,
260.546,0.67246,1.10695,10,,,,,,,,,,,,,,,,,,,,,,,,,,,,,,,,,,,,,
261.246,0.67258,1.1657,10,,,,,,,,,,,,,,,,,,,,,,,,,,,,,,,,,,,,,
261.946,0.67263,1.12233,10,,,,,,,,,,,,,,,,,,,,,,,,,,,,,,,,,,,,,
262.646,0.67258,1.13514,10,,,,,,,,,,,,,,,,,,,,,,,,,,,,,,,,,,,,,
263.346,0.67269,1.10807,10,,,,,,,,,,,,,,,,,,,,,,,,,,,,,,,,,,,,,
264.046,0.67269,1.15214,10,,,,,,,,,,,,,,,,,,,,,,,,,,,,,,,,,,,,,
264.746,0.67269,1.10838,10,,,,,,,,,,,,,,,,,,,,,,,,,,,,,,,,,,,,,
265.446,0.67269,1.05986,10,,,,,,,,,,,,,,,,,,,,,,,,,,,,,,,,,,,,,
266.146,0.67269,1.17,10,,,,,,,,,,,,,,,,,,,,,,,,,,,,,,,,,,,,,
266.846,0.67269,1.14852,10,,,,,,,,,,,,,,,,,,,,,,,,,,,,,,,,,,,,,
267.546,0.67269,1.14493,10,,,,,,,,,,,,,,,,,,,,,,,,,,,,,,,,,,,,,
268.246,0.67269,1.15182,10,,,,,,,,,,,,,,,,,,,,,,,,,,,,,,,,,,,,,
268.946,0.67269,1.10566,10,,,,,,,,,,,,,,,,,,,,,,,,,,,,,,,,,,,,,
269.646,0.67269,1.12733,10,,,,,,,,,,,,,,,,,,,,,,,,,,,,,,,,,,,,,
270.346,0.67269,1.12128,10,,,,,,,,,,,,,,,,,,,,,,,,,,,,,,,,,,,,,
271.046,0.67269,1.18182,10,,,,,,,,,,,,,,,,,,,,,,,,,,,,,,,,,,,,,
271.746,0.67269,1.14131,10,,,,,,,,,,,,,,,,,,,,,,,,,,,,,,,,,,,,,
272.446,0.67269,1.18526,10,,,,,,,,,,,,,,,,,,,,,,,,,,,,,,,,,,,,,
273.146,0.67269,1.11855,10,,,,,,,,,,,,,,,,,,,,,,,,,,,,,,,,,,,,,
273.846,0.67269,1.16246,10,,,,,,,,,,,,,,,,,,,,,,,,,,,,,,,,,,,,,
274.546,0.67258,1.16082,10,,,,,,,,,,,,,,,,,,,,,,,,,,,,,,,,,,,,,
275.246,0.67258,1.16885,10,,,,,,,,,,,,,,,,,,,,,,,,,,,,,,,,,,,,,
275.946,0.67263,1.214,10,,,,,,,,,,,,,,,,,,,,,,,,,,,,,,,,,,,,,
276.646,0.67258,1.10982,10,,,,,,,,,,,,,,,,,,,,,,,,,,,,,,,,,,,,,
277.346,0.67246,1.1702,10,,,,,,,,,,,,,,,,,,,,,,,,,,,,,,,,,,,,,
278.046,0.67241,1.14796,10,,,,,,,,,,,,,,,,,,,,,,,,,,,,,,,,,,,,,
278.746,0.67241,1.16255,10,,,,,,,,,,,,,,,,,,,,,,,,,,,,,,,,,,,,,
279.446,0.67235,1.17658,10,,,,,,,,,,,,,,,,,,,,,,,,,,,,,,,,,,,,,
280.146,0.67218,1.13143,10,,,,,,,,,,,,,,,,,,,,,,,,,,,,,,,,,,,,,
280.846,0.67212,1.10692,10,,,,,,,,,,,,,,,,,,,,,,,,,,,,,,,,,,,,,
281.546,0.67207,1.12742,10,,,,,,,,,,,,,,,,,,,,,,,,,,,,,,,,,,,,,
282.246,0.67207,1.12941,10,,,,,,,,,,,,,,,,,,,,,,,,,,,,,,,,,,,,,
282.946,0.67207,1.14156,10,,,,,,,,,,,,,,,,,,,,,,,,,,,,,,,,,,,,,
283.646,0.67207,1.14918,10,,,,,,,,,,,,,,,,,,,,,,,,,,,,,,,,,,,,,
284.346,0.67207,1.15377,10,,,,,,,,,,,,,,,,,,,,,,,,,,,,,,,,,,,,,
285.046,0.67207,1.20018,10,,,,,,,,,,,,,,,,,,,,,,,,,,,,,,,,,,,,,
285.746,0.67195,1.08893,10,,,,,,,,,,,,,,,,,,,,,,,,,,,,,,,,,,,,,
286.446,0.67195,1.18351,10,,,,,,,,,,,,,,,,,,,,,,,,,,,,,,,,,,,,,
287.146,0.67201,1.14023,10,,,,,,,,,,,,,,,,,,,,,,,,,,,,,,,,,,,,,
287.846,0.67195,1.13492,10,,,,,,,,,,,,,,,,,,,,,,,,,,,,,,,,,,,,,
288.546,0.67195,1.18642,10,,,,,,,,,,,,,,,,,,,,,,,,,,,,,,,,,,,,,
289.246,0.6719,1.08304,10,,,,,,,,,,,,,,,,,,,,,,,,,,,,,,,,,,,,,
289.946,0.6719,1.13122,10,,,,,,,,,,,,,,,,,,,,,,,,,,,,,,,,,,,,,
290.646,0.6719,1.10838,10,,,,,,,,,,,,,,,,,,,,,,,,,,,,,,,,,,,,,
291.346,0.67184,1.31535,10,,,,,,,,,,,,,,,,,,,,,,,,,,,,,,,,,,,,,
292.046,0.67184,1.13298,10,,,,,,,,,,,,,,,,,,,,,,,,,,,,,,,,,,,,,
292.746,0.67184,1.15206,10,,,,,,,,,,,,,,,,,,,,,,,,,,,,,,,,,,,,,
293.446,0.67178,1.13959,10,,,,,,,,,,,,,,,,,,,,,,,,,,,,,,,,,,,,,
294.146,0.67173,1.07321,10,,,,,,,,,,,,,,,,,,,,,,,,,,,,,,,,,,,,,
294.846,0.67156,1.18944,10,,,,,,,,,,,,,,,,,,,,,,,,,,,,,,,,,,,,,
295.546,0.67133,1.17719,10,,,,,,,,,,,,,,,,,,,,,,,,,,,,,,,,,,,,,
296.246,0.67093,1.1653,10,,,,,,,,,,,,,,,,,,,,,,,,,,,,,,,,,,,,,
296.946,0.6702,1.18556,10,,,,,,,,,,,,,,,,,,,,,,,,,,,,,,,,,,,,,
297.646,0.66906,1.13576,10,,,,,,,,,,,,,,,,,,,,,,,,,,,,,,,,,,,,,
298.346,0.6681,1.20502,10,,,,,,,,,,,,,,,,,,,,,,,,,,,,,,,,,,,,,
299.046,0.66753,1.18705,10,,,,,,,,,,,,,,,,,,,,,,,,,,,,,,,,,,,,,
299.746,0.66702,1.14134,10,,,,,,,,,,,,,,,,,,,,,,,,,,,,,,,,,,,,,
300.446,0.66668,1.08177,10,,,,,,,,,,,,,,,,,,,,,,,,,,,,,,,,,,,,,
301.146,0.66651,1.11426,10,,,,,,,,,,,,,,,,,,,,,,,,,,,,,,,,,,,,,
301.846,0.66657,1.09157,10,,,,,,,,,,,,,,,,,,,,,,,,,,,,,,,,,,,,,
302.546,0.66668,1.08045,10,,,,,,,,,,,,,,,,,,,,,,,,,,,,,,,,,,,,,
303.246,0.66674,1.10055,10,,,,,,,,,,,,,,,,,,,,,,,,,,,,,,,,,,,,,
303.946,0.66674,1.10672,10,,,,,,,,,,,,,,,,,,,,,,,,,,,,,,,,,,,,,
304.646,0.66691,1.09233,10,,,,,,,,,,,,,,,,,,,,,,,,,,,,,,,,,,,,,
305.346,0.66697,1.16623,10,,,,,,,,,,,,,,,,,,,,,,,,,,,,,,,,,,,,,
306.046,0.66702,1.14985,10,,,,,,,,,,,,,,,,,,,,,,,,,,,,,,,,,,,,,
306.746,0.66708,1.13903,10,,,,,,,,,,,,,,,,,,,,,,,,,,,,,,,,,,,,,
307.446,0.66714,1.11063,10,,,,,,,,,,,,,,,,,,,,,,,,,,,,,,,,,,,,,
308.146,0.66719,1.14593,10,,,,,,,,,,,,,,,,,,,,,,,,,,,,,,,,,,,,,
308.846,0.66725,1.12525,10,,,,,,,,,,,,,,,,,,,,,,,,,,,,,,,,,,,,,
309.546,0.66725,1.15535,10,,,,,,,,,,,,,,,,,,,,,,,,,,,,,,,,,,,,,
310.246,0.66731,1.15014,10,,,,,,,,,,,,,,,,,,,,,,,,,,,,,,,,,,,,,
310.946,0.66731,1.08735,10,,,,,,,,,,,,,,,,,,,,,,,,,,,,,,,,,,,,,
311.646,0.66731,1.06367,10,,,,,,,,,,,,,,,,,,,,,,,,,,,,,,,,,,,,,
312.346,0.66731,1.19696,10,,,,,,,,,,,,,,,,,,,,,,,,,,,,,,,,,,,,,
313.046,0.66731,1.18738,10,,,,,,,,,,,,,,,,,,,,,,,,,,,,,,,,,,,,,
313.746,0.66719,1.13916,10,,,,,,,,,,,,,,,,,,,,,,,,,,,,,,,,,,,,,
314.446,0.66731,1.06716,10,,,,,,,,,,,,,,,,,,,,,,,,,,,,,,,,,,,,,
315.146,0.66731,1.11169,10,,,,,,,,,,,,,,,,,,,,,,,,,,,,,,,,,,,,,
315.846,0.66731,1.17733,10,,,,,,,,,,,,,,,,,,,,,,,,,,,,,,,,,,,,,
316.546,0.66719,1.19129,10,,,,,,,,,,,,,,,,,,,,,,,,,,,,,,,,,,,,,
317.246,0.66731,1.11665,10,,,,,,,,,,,,,,,,,,,,,,,,,,,,,,,,,,,,,
317.946,0.66731,1.15189,10,,,,,,,,,,,,,,,,,,,,,,,,,,,,,,,,,,,,,
318.646,0.66731,1.10644,10,,,,,,,,,,,,,,,,,,,,,,,,,,,,,,,,,,,,,
319.346,0.66719,1.14856,10,,,,,,,,,,,,,,,,,,,,,,,,,,,,,,,,,,,,,
320.046,0.66719,1.1967,10,,,,,,,,,,,,,,,,,,,,,,,,,,,,,,,,,,,,,
320.746,0.66719,1.22924,10,,,,,,,,,,,,,,,,,,,,,,,,,,,,,,,,,,,,,
321.446,0.66725,1.14397,10,,,,,,,,,,,,,,,,,,,,,,,,,,,,,,,,,,,,,
322.146,0.66725,1.16976,10,,,,,,,,,,,,,,,,,,,,,,,,,,,,,,,,,,,,,
322.846,0.66725,1.14384,10,,,,,,,,,,,,,,,,,,,,,,,,,,,,,,,,,,,,,
323.546,0.66725,1.12524,10,,,,,,,,,,,,,,,,,,,,,,,,,,,,,,,,,,,,,
324.246,0.66725,1.11095,10,,,,,,,,,,,,,,,,,,,,,,,,,,,,,,,,,,,,,
324.946,0.66725,1.12808,10,,,,,,,,,,,,,,,,,,,,,,,,,,,,,,,,,,,,,
325.646,0.66719,1.11801,10,,,,,,,,,,,,,,,,,,,,,,,,,,,,,,,,,,,,,
326.346,0.66719,1.12657,10,,,,,,,,,,,,,,,,,,,,,,,,,,,,,,,,,,,,,
327.046,0.66719,1.22037,10,,,,,,,,,,,,,,,,,,,,,,,,,,,,,,,,,,,,,
327.746,0.66719,1.17206,10,,,,,,,,,,,,,,,,,,,,,,,,,,,,,,,,,,,,,
328.446,0.66719,1.13859,10,,,,,,,,,,,,,,,,,,,,,,,,,,,,,,,,,,,,,
329.146,0.66725,1.15608,10,,,,,,,,,,,,,,,,,,,,,,,,,,,,,,,,,,,,,
329.846,0.66725,1.12965,10,,,,,,,,,,,,,,,,,,,,,,,,,,,,,,,,,,,,,
330.546,0.66725,1.13109,10,,,,,,,,,,,,,,,,,,,,,,,,,,,,,,,,,,,,,
331.246,0.66725,1.14267,10,,,,,,,,,,,,,,,,,,,,,,,,,,,,,,,,,,,,,
331.946,0.66725,1.14774,10,,,,,,,,,,,,,,,,,,,,,,,,,,,,,,,,,,,,,
332.646,0.66725,1.16455,10,,,,,,,,,,,,,,,,,,,,,,,,,,,,,,,,,,,,,
333.346,0.66725,1.1748,10,,,,,,,,,,,,,,,,,,,,,,,,,,,,,,,,,,,,,
334.046,0.66725,1.166,10,,,,,,,,,,,,,,,,,,,,,,,,,,,,,,,,,,,,,
334.746,0.66725,1.14671,10,,,,,,,,,,,,,,,,,,,,,,,,,,,,,,,,,,,,,
335.446,0.66725,1.14664,10,,,,,,,,,,,,,,,,,,,,,,,,,,,,,,,,,,,,,
336.146,0.66725,1.14649,10,,,,,,,,,,,,,,,,,,,,,,,,,,,,,,,,,,,,,
336.846,0.66725,1.13527,10,,,,,,,,,,,,,,,,,,,,,,,,,,,,,,,,,,,,,
337.546,0.66725,1.08847,10,,,,,,,,,,,,,,,,,,,,,,,,,,,,,,,,,,,,,
338.246,0.66725,1.15484,10,,,,,,,,,,,,,,,,,,,,,,,,,,,,,,,,,,,,,
338.946,0.66725,1.12385,10,,,,,,,,,,,,,,,,,,,,,,,,,,,,,,,,,,,,,
339.646,0.66725,1.08645,10,,,,,,,,,,,,,,,,,,,,,,,,,,,,,,,,,,,,,
340.346,0.66725,1.17631,10,,,,,,,,,,,,,,,,,,,,,,,,,,,,,,,,,,,,,
341.046,0.66725,1.13509,10,,,,,,,,,,,,,,,,,,,,,,,,,,,,,,,,,,,,,
341.746,0.66725,1.12227,10,,,,,,,,,,,,,,,,,,,,,,,,,,,,,,,,,,,,,
342.446,0.66725,1.21672,10,,,,,,,,,,,,,,,,,,,,,,,,,,,,,,,,,,,,,
343.146,0.66725,1.13632,10,,,,,,,,,,,,,,,,,,,,,,,,,,,,,,,,,,,,,
343.846,0.66725,1.14584,10,,,,,,,,,,,,,,,,,,,,,,,,,,,,,,,,,,,,,
344.546,0.66714,1.21319,10,,,,,,,,,,,,,,,,,,,,,,,,,,,,,,,,,,,,,
345.246,0.66725,1.12424,10,,,,,,,,,,,,,,,,,,,,,,,,,,,,,,,,,,,,,
345.946,0.66714,1.11387,10,,,,,,,,,,,,,,,,,,,,,,,,,,,,,,,,,,,,,
346.646,0.66725,1.12009,10,,,,,,,,,,,,,,,,,,,,,,,,,,,,,,,,,,,,,
347.346,0.66725,1.08588,10,,,,,,,,,,,,,,,,,,,,,,,,,,,,,,,,,,,,,
348.046,0.66725,1.1432,10,,,,,,,,,,,,,,,,,,,,,,,,,,,,,,,,,,,,,
348.746,0.66725,1.18301,10,,,,,,,,,,,,,,,,,,,,,,,,,,,,,,,,,,,,,
349.446,0.66725,1.22199,10,,,,,,,,,,,,,,,,,,,,,,,,,,,,,,,,,,,,,
350.146,0.66725,1.17211,10,,,,,,,,,,,,,,,,,,,,,,,,,,,,,,,,,,,,,
350.846,0.66725,1.15831,10,,,,,,,,,,,,,,,,,,,,,,,,,,,,,,,,,,,,,
351.546,0.66725,1.13235,10,,,,,,,,,,,,,,,,,,,,,,,,,,,,,,,,,,,,,
352.246,0.66725,1.12925,10,,,,,,,,,,,,,,,,,,,,,,,,,,,,,,,,,,,,,
352.946,0.66725,1.15784,10,,,,,,,,,,,,,,,,,,,,,,,,,,,,,,,,,,,,,
353.646,0.66725,1.08176,10,,,,,,,,,,,,,,,,,,,,,,,,,,,,,,,,,,,,,
354.346,0.66725,1.14283,10,,,,,,,,,,,,,,,,,,,,,,,,,,,,,,,,,,,,,
355.046,0.66725,1.10911,10,,,,,,,,,,,,,,,,,,,,,,,,,,,,,,,,,,,,,
355.746,0.66725,1.19039,10,,,,,,,,,,,,,,,,,,,,,,,,,,,,,,,,,,,,,
356.446,0.66725,1.18216,10,,,,,,,,,,,,,,,,,,,,,,,,,,,,,,,,,,,,,
357.146,0.66714,1.09838,10,,,,,,,,,,,,,,,,,,,,,,,,,,,,,,,,,,,,,
357.846,0.66719,1.1621,10,,,,,,,,,,,,,,,,,,,,,,,,,,,,,,,,,,,,,
358.546,0.66719,1.13326,10,,,,,,,,,,,,,,,,,,,,,,,,,,,,,,,,,,,,,
359.246,0.66719,1.17255,10,,,,,,,,,,,,,,,,,,,,,,,,,,,,,,,,,,,,,
359.946,0.66714,1.10906,10,,,,,,,,,,,,,,,,,,,,,,,,,,,,,,,,,,,,,
360.646,0.66714,1.12399,10,,,,,,,,,,,,,,,,,,,,,,,,,,,,,,,,,,,,,
361.346,0.66714,1.15436,10,,,,,,,,,,,,,,,,,,,,,,,,,,,,,,,,,,,,,
362.046,0.66714,1.12045,10,,,,,,,,,,,,,,,,,,,,,,,,,,,,,,,,,,,,,
362.746,0.66719,1.15699,10,,,,,,,,,,,,,,,,,,,,,,,,,,,,,,,,,,,,,
363.446,0.66714,1.10852,10,,,,,,,,,,,,,,,,,,,,,,,,,,,,,,,,,,,,,
364.146,0.66714,1.17821,10,,,,,,,,,,,,,,,,,,,,,,,,,,,,,,,,,,,,,
364.846,0.66719,1.10848,10,,,,,,,,,,,,,,,,,,,,,,,,,,,,,,,,,,,,,
365.546,0.66719,1.11396,10,,,,,,,,,,,,,,,,,,,,,,,,,,,,,,,,,,,,,
366.246,0.66719,1.13134,10,,,,,,,,,,,,,,,,,,,,,,,,,,,,,,,,,,,,,
366.946,0.66708,1.12666,10,,,,,,,,,,,,,,,,,,,,,,,,,,,,,,,,,,,,,
367.646,0.66719,1.15253,10,,,,,,,,,,,,,,,,,,,,,,,,,,,,,,,,,,,,,
368.346,0.66719,1.10703,10,,,,,,,,,,,,,,,,,,,,,,,,,,,,,,,,,,,,,
369.046,0.66719,1.12624,10,,,,,,,,,,,,,,,,,,,,,,,,,,,,,,,,,,,,,
369.746,0.66719,1.16359,10,,,,,,,,,,,,,,,,,,,,,,,,,,,,,,,,,,,,,
370.446,0.66719,1.1366,10,,,,,,,,,,,,,,,,,,,,,,,,,,,,,,,,,,,,,
371.146,0.66714,1.14713,10,,,,,,,,,,,,,,,,,,,,,,,,,,,,,,,,,,,,,
371.846,0.66702,1.13585,10,,,,,,,,,,,,,,,,,,,,,,,,,,,,,,,,,,,,,
372.546,0.66702,1.12615,10,,,,,,,,,,,,,,,,,,,,,,,,,,,,,,,,,,,,,
373.246,0.66697,1.11884,10,,,,,,,,,,,,,,,,,,,,,,,,,,,,,,,,,,,,,
373.946,0.66697,1.19555,10,,,,,,,,,,,,,,,,,,,,,,,,,,,,,,,,,,,,,
374.646,0.66691,1.13512,10,,,,,,,,,,,,,,,,,,,,,,,,,,,,,,,,,,,,,
375.346,0.66685,1.12212,10,,,,,,,,,,,,,,,,,,,,,,,,,,,,,,,,,,,,,
376.046,0.6668,1.15907,10,,,,,,,,,,,,,,,,,,,,,,,,,,,,,,,,,,,,,
376.746,0.66674,1.17878,10,,,,,,,,,,,,,,,,,,,,,,,,,,,,,,,,,,,,,
377.446,0.66668,1.10212,10,,,,,,,,,,,,,,,,,,,,,,,,,,,,,,,,,,,,,
378.146,0.66668,1.2057,10,,,,,,,,,,,,,,,,,,,,,,,,,,,,,,,,,,,,,
378.846,0.66651,1.16895,10,,,,,,,,,,,,,,,,,,,,,,,,,,,,,,,,,,,,,
379.546,0.66617,1.19188,10,,,,,,,,,,,,,,,,,,,,,,,,,,,,,,,,,,,,,
380.246,0.66549,1.20858,10,,,,,,,,,,,,,,,,,,,,,,,,,,,,,,,,,,,,,
380.946,0.66345,1.17292,10,,,,,,,,,,,,,,,,,,,,,,,,,,,,,,,,,,,,,
381.646,0.66068,1.09842,10,,,,,,,,,,,,,,,,,,,,,,,,,,,,,,,,,,,,,
382.346,0.66011,1.05833,10,,,,,,,,,,,,,,,,,,,,,,,,,,,,,,,,,,,,,
383.046,0.66011,1.08755,10,,,,,,,,,,,,,,,,,,,,,,,,,,,,,,,,,,,,,
383.746,0.66011,1.05514,10,,,,,,,,,,,,,,,,,,,,,,,,,,,,,,,,,,,,,
384.446,0.66028,1.11052,10,,,,,,,,,,,,,,,,,,,,,,,,,,,,,,,,,,,,,
385.146,0.66051,1.05509,10,,,,,,,,,,,,,,,,,,,,,,,,,,,,,,,,,,,,,
385.846,0.66062,1.07919,10,,,,,,,,,,,,,,,,,,,,,,,,,,,,,,,,,,,,,
386.546,0.66085,1.16705,10,,,,,,,,,,,,,,,,,,,,,,,,,,,,,,,,,,,,,
387.246,0.66107,1.11493,10,,,,,,,,,,,,,,,,,,,,,,,,,,,,,,,,,,,,,
387.946,0.66119,1.10935,10,,,,,,,,,,,,,,,,,,,,,,,,,,,,,,,,,,,,,
388.646,0.66147,1.11042,10,,,,,,,,,,,,,,,,,,,,,,,,,,,,,,,,,,,,,
389.346,0.6617,1.10588,10,,,,,,,,,,,,,,,,,,,,,,,,,,,,,,,,,,,,,
390.046,0.66192,1.14272,10,,,,,,,,,,,,,,,,,,,,,,,,,,,,,,,,,,,,,
390.746,0.66215,1.1395,10,,,,,,,,,,,,,,,,,,,,,,,,,,,,,,,,,,,,,
391.446,0.66238,1.14932,10,,,,,,,,,,,,,,,,,,,,,,,,,,,,,,,,,,,,,
392.146,0.66266,1.18231,10,,,,,,,,,,,,,,,,,,,,,,,,,,,,,,,,,,,,,
392.846,0.66283,1.15701,10,,,,,,,,,,,,,,,,,,,,,,,,,,,,,,,,,,,,,
393.546,0.66289,1.24642,10,,,,,,,,,,,,,,,,,,,,,,,,,,,,,,,,,,,,,
394.246,0.663,1.12777,10,,,,,,,,,,,,,,,,,,,,,,,,,,,,,,,,,,,,,
394.946,0.66317,1.11544,10,,,,,,,,,,,,,,,,,,,,,,,,,,,,,,,,,,,,,
395.646,0.66323,1.20374,10,,,,,,,,,,,,,,,,,,,,,,,,,,,,,,,,,,,,,
396.346,0.66334,1.14215,10,,,,,,,,,,,,,,,,,,,,,,,,,,,,,,,,,,,,,
397.046,0.66345,1.14944,10,,,,,,,,,,,,,,,,,,,,,,,,,,,,,,,,,,,,,
397.746,0.66351,1.13718,10,,,,,,,,,,,,,,,,,,,,,,,,,,,,,,,,,,,,,
398.446,0.66351,1.14401,10,,,,,,,,,,,,,,,,,,,,,,,,,,,,,,,,,,,,,
399.146,0.66351,1.11732,10,,,,,,,,,,,,,,,,,,,,,,,,,,,,,,,,,,,,,
399.846,0.66345,1.09136,10,,,,,,,,,,,,,,,,,,,,,,,,,,,,,,,,,,,,,
400.546,0.66345,1.26236,10,,,,,,,,,,,,,,,,,,,,,,,,,,,,,,,,,,,,,
401.246,0.66357,1.10645,10,,,,,,,,,,,,,,,,,,,,,,,,,,,,,,,,,,,,,
401.946,0.66362,1.19677,10,,,,,,,,,,,,,,,,,,,,,,,,,,,,,,,,,,,,,
402.646,0.66362,1.15143,10,,,,,,,,,,,,,,,,,,,,,,,,,,,,,,,,,,,,,
403.346,0.66368,1.14422,10,,,,,,,,,,,,,,,,,,,,,,,,,,,,,,,,,,,,,
404.046,0.66368,1.14767,10,,,,,,,,,,,,,,,,,,,,,,,,,,,,,,,,,,,,,
404.746,0.66362,1.13718,10,,,,,,,,,,,,,,,,,,,,,,,,,,,,,,,,,,,,,
405.446,0.66374,1.12809,10,,,,,,,,,,,,,,,,,,,,,,,,,,,,,,,,,,,,,
406.146,0.66368,1.12856,10,,,,,,,,,,,,,,,,,,,,,,,,,,,,,,,,,,,,,
406.846,0.66379,1.15114,10,,,,,,,,,,,,,,,,,,,,,,,,,,,,,,,,,,,,,
407.546,0.66379,1.18767,10,,,,,,,,,,,,,,,,,,,,,,,,,,,,,,,,,,,,,
408.246,0.66379,1.12847,10,,,,,,,,,,,,,,,,,,,,,,,,,,,,,,,,,,,,,
408.946,0.66374,1.11438,10,,,,,,,,,,,,,,,,,,,,,,,,,,,,,,,,,,,,,
409.646,0.66385,1.14892,10,,,,,,,,,,,,,,,,,,,,,,,,,,,,,,,,,,,,,
410.346,0.66391,1.16152,10,,,,,,,,,,,,,,,,,,,,,,,,,,,,,,,,,,,,,
411.046,0.66391,1.15573,10,,,,,,,,,,,,,,,,,,,,,,,,,,,,,,,,,,,,,
411.746,0.66391,1.12339,10,,,,,,,,,,,,,,,,,,,,,,,,,,,,,,,,,,,,,
412.446,0.66396,1.09858,10,,,,,,,,,,,,,,,,,,,,,,,,,,,,,,,,,,,,,
413.146,0.66402,1.12202,10,,,,,,,,,,,,,,,,,,,,,,,,,,,,,,,,,,,,,
413.846,0.66413,1.16536,10,,,,,,,,,,,,,,,,,,,,,,,,,,,,,,,,,,,,,
414.546,0.66425,1.15865,10,,,,,,,,,,,,,,,,,,,,,,,,,,,,,,,,,,,,,
415.246,0.66436,1.102,10,,,,,,,,,,,,,,,,,,,,,,,,,,,,,,,,,,,,,
415.946,0.66453,1.12735,10,,,,,,,,,,,,,,,,,,,,,,,,,,,,,,,,,,,,,
416.646,0.66464,1.14446,10,,,,,,,,,,,,,,,,,,,,,,,,,,,,,,,,,,,,,
417.346,0.6647,1.17772,10,,,,,,,,,,,,,,,,,,,,,,,,,,,,,,,,,,,,,
418.046,0.66476,1.1517,10,,,,,,,,,,,,,,,,,,,,,,,,,,,,,,,,,,,,,
418.746,0.66481,1.13641,10,,,,,,,,,,,,,,,,,,,,,,,,,,,,,,,,,,,,,
419.446,0.66476,1.12882,10,,,,,,,,,,,,,,,,,,,,,,,,,,,,,,,,,,,,,
420.146,0.66487,1.11142,10,,,,,,,,,,,,,,,,,,,,,,,,,,,,,,,,,,,,,
420.846,0.66493,1.16106,10,,,,,,,,,,,,,,,,,,,,,,,,,,,,,,,,,,,,,
421.546,0.66493,1.16142,10,,,,,,,,,,,,,,,,,,,,,,,,,,,,,,,,,,,,,
422.246,0.66493,1.14295,10,,,,,,,,,,,,,,,,,,,,,,,,,,,,,,,,,,,,,
422.946,0.66493,1.1922,10,,,,,,,,,,,,,,,,,,,,,,,,,,,,,,,,,,,,,
423.646,0.66493,1.12817,10,,,,,,,,,,,,,,,,,,,,,,,,,,,,,,,,,,,,,
424.346,0.66493,1.11442,10,,,,,,,,,,,,,,,,,,,,,,,,,,,,,,,,,,,,,
425.046,0.66493,1.19235,10,,,,,,,,,,,,,,,,,,,,,,,,,,,,,,,,,,,,,
425.746,0.66493,1.16602,10,,,,,,,,,,,,,,,,,,,,,,,,,,,,,,,,,,,,,
426.446,0.66493,1.13099,10,,,,,,,,,,,,,,,,,,,,,,,,,,,,,,,,,,,,,
427.146,0.66493,1.14034,10,,,,,,,,,,,,,,,,,,,,,,,,,,,,,,,,,,,,,
427.846,0.66481,1.20035,10,,,,,,,,,,,,,,,,,,,,,,,,,,,,,,,,,,,,,
428.546,0.66476,1.14848,10,,,,,,,,,,,,,,,,,,,,,,,,,,,,,,,,,,,,,
429.246,0.66476,1.1227,10,,,,,,,,,,,,,,,,,,,,,,,,,,,,,,,,,,,,,
429.946,0.66487,1.13285,10,,,,,,,,,,,,,,,,,,,,,,,,,,,,,,,,,,,,,
430.646,0.66487,1.20505,10,,,,,,,,,,,,,,,,,,,,,,,,,,,,,,,,,,,,,
431.346,0.66487,1.14229,10,,,,,,,,,,,,,,,,,,,,,,,,,,,,,,,,,,,,,
432.046,0.66487,1.1424,10,,,,,,,,,,,,,,,,,,,,,,,,,,,,,,,,,,,,,
432.746,0.66487,1.11004,10,,,,,,,,,,,,,,,,,,,,,,,,,,,,,,,,,,,,,
433.446,0.66481,1.17077,10,,,,,,,,,,,,,,,,,,,,,,,,,,,,,,,,,,,,,
434.146,0.66487,1.15315,10,,,,,,,,,,,,,,,,,,,,,,,,,,,,,,,,,,,,,
434.846,0.66487,1.1712,10,,,,,,,,,,,,,,,,,,,,,,,,,,,,,,,,,,,,,
435.546,0.66487,1.15414,10,,,,,,,,,,,,,,,,,,,,,,,,,,,,,,,,,,,,,
436.246,0.66487,1.1447,10,,,,,,,,,,,,,,,,,,,,,,,,,,,,,,,,,,,,,
436.946,0.66487,1.10684,10,,,,,,,,,,,,,,,,,,,,,,,,,,,,,,,,,,,,,
437.646,0.66487,1.17757,10,,,,,,,,,,,,,,,,,,,,,,,,,,,,,,,,,,,,,
438.346,0.66487,1.14902,10,,,,,,,,,,,,,,,,,,,,,,,,,,,,,,,,,,,,,
439.046,0.66487,1.17601,10,,,,,,,,,,,,,,,,,,,,,,,,,,,,,,,,,,,,,
439.746,0.66487,1.14824,10,,,,,,,,,,,,,,,,,,,,,,,,,,,,,,,,,,,,,
440.446,0.66487,1.13967,10,,,,,,,,,,,,,,,,,,,,,,,,,,,,,,,,,,,,,
441.146,0.66487,1.11724,10,,,,,,,,,,,,,,,,,,,,,,,,,,,,,,,,,,,,,
441.846,0.66487,1.16815,10,,,,,,,,,,,,,,,,,,,,,,,,,,,,,,,,,,,,,
442.546,0.66487,1.14893,10,,,,,,,,,,,,,,,,,,,,,,,,,,,,,,,,,,,,,
443.246,0.66487,1.15379,10,,,,,,,,,,,,,,,,,,,,,,,,,,,,,,,,,,,,,
443.946,0.66476,1.17148,10,,,,,,,,,,,,,,,,,,,,,,,,,,,,,,,,,,,,,
444.646,0.66481,1.2134,10,,,,,,,,,,,,,,,,,,,,,,,,,,,,,,,,,,,,,
445.346,0.6647,1.14246,10,,,,,,,,,,,,,,,,,,,,,,,,,,,,,,,,,,,,,
446.046,0.6647,1.15267,10,,,,,,,,,,,,,,,,,,,,,,,,,,,,,,,,,,,,,
446.746,0.66476,1.18864,10,,,,,,,,,,,,,,,,,,,,,,,,,,,,,,,,,,,,,
447.446,0.66476,1.13969,10,,,,,,,,,,,,,,,,,,,,,,,,,,,,,,,,,,,,,
448.146,0.6647,1.1415,10,,,,,,,,,,,,,,,,,,,,,,,,,,,,,,,,,,,,,
448.846,0.6647,1.13073,10,,,,,,,,,,,,,,,,,,,,,,,,,,,,,,,,,,,,,
449.546,0.6647,1.16137,10,,,,,,,,,,,,,,,,,,,,,,,,,,,,,,,,,,,,,
450.246,0.6647,1.10191,10,,,,,,,,,,,,,,,,,,,,,,,,,,,,,,,,,,,,,
450.946,0.6647,1.14858,10,,,,,,,,,,,,,,,,,,,,,,,,,,,,,,,,,,,,,
451.646,0.66464,1.29602,10,,,,,,,,,,,,,,,,,,,,,,,,,,,,,,,,,,,,,
452.346,0.66476,1.16075,10,,,,,,,,,,,,,,,,,,,,,,,,,,,,,,,,,,,,,
453.046,0.66476,1.13512,10,,,,,,,,,,,,,,,,,,,,,,,,,,,,,,,,,,,,,
453.746,0.66476,1.13183,10,,,,,,,,,,,,,,,,,,,,,,,,,,,,,,,,,,,,,
454.446,0.66476,1.11561,10,,,,,,,,,,,,,,,,,,,,,,,,,,,,,,,,,,,,,
455.146,0.66476,1.15957,10,,,,,,,,,,,,,,,,,,,,,,,,,,,,,,,,,,,,,
455.846,0.66476,1.15754,10,,,,,,,,,,,,,,,,,,,,,,,,,,,,,,,,,,,,,
456.546,0.6647,1.12233,10,,,,,,,,,,,,,,,,,,,,,,,,,,,,,,,,,,,,,
457.246,0.66476,1.14837,10,,,,,,,,,,,,,,,,,,,,,,,,,,,,,,,,,,,,,
457.946,0.66476,1.13637,10,,,,,,,,,,,,,,,,,,,,,,,,,,,,,,,,,,,,,
458.646,0.66476,1.18863,10,,,,,,,,,,,,,,,,,,,,,,,,,,,,,,,,,,,,,
459.346,0.66476,1.18054,10,,,,,,,,,,,,,,,,,,,,,,,,,,,,,,,,,,,,,
460.046,0.6647,1.15854,10,,,,,,,,,,,,,,,,,,,,,,,,,,,,,,,,,,,,,
460.746,0.66464,1.17931,10,,,,,,,,,,,,,,,,,,,,,,,,,,,,,,,,,,,,,
461.446,0.66464,1.10851,10,,,,,,,,,,,,,,,,,,,,,,,,,,,,,,,,,,,,,
462.146,0.66464,1.16508,10,,,,,,,,,,,,,,,,,,,,,,,,,,,,,,,,,,,,,
462.846,0.66459,1.17397,10,,,,,,,,,,,,,,,,,,,,,,,,,,,,,,,,,,,,,
463.546,0.66453,1.2355,10,,,,,,,,,,,,,,,,,,,,,,,,,,,,,,,,,,,,,
464.246,0.66447,1.17575,10,,,,,,,,,,,,,,,,,,,,,,,,,,,,,,,,,,,,,
464.946,0.66442,1.13683,10,,,,,,,,,,,,,,,,,,,,,,,,,,,,,,,,,,,,,
465.646,0.66447,1.10892,10,,,,,,,,,,,,,,,,,,,,,,,,,,,,,,,,,,,,,
466.346,0.66436,1.10212,10,,,,,,,,,,,,,,,,,,,,,,,,,,,,,,,,,,,,,
467.046,0.66436,1.10618,10,,,,,,,,,,,,,,,,,,,,,,,,,,,,,,,,,,,,,
467.746,0.66447,1.13753,10,,,,,,,,,,,,,,,,,,,,,,,,,,,,,,,,,,,,,
468.446,0.66447,1.14299,10,,,,,,,,,,,,,,,,,,,,,,,,,,,,,,,,,,,,,
469.146,0.66436,1.12168,10,,,,,,,,,,,,,,,,,,,,,,,,,,,,,,,,,,,,,
469.846,0.66436,1.15289,10,,,,,,,,,,,,,,,,,,,,,,,,,,,,,,,,,,,,,
470.546,0.66436,1.11892,10,,,,,,,,,,,,,,,,,,,,,,,,,,,,,,,,,,,,,
471.246,0.66436,1.16337,10,,,,,,,,,,,,,,,,,,,,,,,,,,,,,,,,,,,,,
471.946,0.6643,1.24546,10,,,,,,,,,,,,,,,,,,,,,,,,,,,,,,,,,,,,,
472.646,0.66425,1.20916,10,,,,,,,,,,,,,,,,,,,,,,,,,,,,,,,,,,,,,
473.346,0.66408,1.13318,10,,,,,,,,,,,,,,,,,,,,,,,,,,,,,,,,,,,,,
474.046,0.66385,1.17757,10,,,,,,,,,,,,,,,,,,,,,,,,,,,,,,,,,,,,,
474.746,0.66351,1.18744,10,,,,,,,,,,,,,,,,,,,,,,,,,,,,,,,,,,,,,
475.446,0.663,1.22799,10,,,,,,,,,,,,,,,,,,,,,,,,,,,,,,,,,,,,,
476.146,0.66198,1.17695,10,,,,,,,,,,,,,,,,,,,,,,,,,,,,,,,,,,,,,
476.846,0.66102,1.17395,10,,,,,,,,,,,,,,,,,,,,,,,,,,,,,,,,,,,,,
477.546,0.66039,1.14254,10,,,,,,,,,,,,,,,,,,,,,,,,,,,,,,,,,,,,,
478.246,0.66005,1.11825,10,,,,,,,,,,,,,,,,,,,,,,,,,,,,,,,,,,,,,
478.946,0.65994,1.15262,10,,,,,,,,,,,,,,,,,,,,,,,,,,,,,,,,,,,,,
479.548,4.47672,139.01949,10,,,,,,,,,,,,,,,,,,,,,,,,,,,,,,,,,,,,,
480.248,10.30993,218.15529,10,,,,,,,,,,,,,,,,,,,,,,,,,,,,,,,,,,,,,
480.948,16.14326,201.83623,10,,,,,,,,,,,,,,,,,,,,,,,,,,,,,,,,,,,,,
481.648,21.97663,124.7535,10,,,,,,,,,,,,,,,,,,,,,,,,,,,,,,,,,,,,,
482.348,27.8099,85.28683,10,,,,,,,,,,,,,,,,,,,,,,,,,,,,,,,,,,,,,
483.048,33.64328,66.03072,10,,,,,,,,,,,,,,,,,,,,,,,,,,,,,,,,,,,,,
483.748,39.47666,35.90179,10,,,,,,,,,,,,,,,,,,,,,,,,,,,,,,,,,,,,,
484.448,45.30998,32.58196,10,,,,,,,,,,,,,,,,,,,,,,,,,,,,,,,,,,,,,
485.148,51.14325,-2.30205,10,,,,,,,,,,,,,,,,,,,,,,,,,,,,,,,,,,,,,
485.848,56.97657,-2.55445,10,,,,,,,,,,,,,,,,,,,,,,,,,,,,,,,,,,,,,
486.548,62.80984,-3.05606,10,,,,,,,,,,,,,,,,,,,,,,,,,,,,,,,,,,,,,
487.248,68.64327,-3.32102,10,,,,,,,,,,,,,,,,,,,,,,,,,,,,,,,,,,,,,
487.948,74.47665,-3.48049,10,,,,,,,,,,,,,,,,,,,,,,,,,,,,,,,,,,,,,
488.648,80.30997,-3.51748,10,,,,,,,,,,,,,,,,,,,,,,,,,,,,,,,,,,,,,
489.348,86.14325,-3.57208,10,,,,,,,,,,,,,,,,,,,,,,,,,,,,,,,,,,,,,
490.048,91.97663,-3.58746,10,,,,,,,,,,,,,,,,,,,,,,,,,,,,,,,,,,,,,
490.356,94.54329,-3.58894,10,,,,,,,,,,,,,,,,,,,,,,,,,,,,,,,,,,,,,