File: combined_ligament_solver/data/processed/Data Sheet 3_S151624_MCL.csv
Specimen properties : Length,103,mm,Unnamed: 3,Unnamed: 4,Unnamed: 5,Unnamed: 6,Unnamed: 7,Unnamed: 8,Unnamed: 9,Unnamed: 10,Unnamed: 11,Stress-Strain,Unnamed: 13,Unnamed: 14,Unnamed: 15,Unnamed: 16,Unnamed: 17,Unnamed: 18,Unnamed: 19,Unnamed: 20,Unnamed: 21,Unnamed: 22,Unnamed: 23,Unnamed: 24,Unnamed: 25,Unnamed: 26,Unnamed: 27,Linear,Unnamed: 29,Unnamed: 30,Unnamed: 31,Unnamed: 32,Unnamed: 33,Modulus,Unnamed: 35,Failure,Unnamed: 37,Unnamed: 38,Unnamed: 39,Unnamed: 40
Cross Section Average,24.509500000000003,mm2,,,,,,,,,,Polynomial Coefficients,,,,,,,,,,,,,,,,Force,,Stress,Extension,Strain,,Secant,Tangent,Load,Stress,Extension,Strain,Stiffness
Time,Extension,Load,Total cycle count,,,Extension,Load,Strain,Stress,E-tan,,X6,205594694.68819097,,,,,,,,,Strain,Stress,E-tan,,,,(N),,(MPa),(mm),(%),,(MPa),(MPa),(N),(MPa),(mm),(%),(N/mm)
(s),(mm),(N),,,,(mm),(N),(mm/mm),(MPa),(MPa),,X5,-47353576.56585666,,,,,,,,,(mm/mm),(MPa),(MPa),,,,267.2045996920283,,10.902082853262135,5.562,5.4,,201.89042320855805,353.9930622428923,438.48361,17.89035312837879,8.000029999999999,7.767019417475727,48.04110026825393
0.7,0.32668,1.93395,0,,,5.90308,260.71924,0.053397572815533985,10.637476896713519,350.57285392942555,,,,,,,,,,,,0.007,0.25330685591368957,57.71752902610121,,,,,,,,,,,,,,,,
1.5,0.46013,3.164,0,,,12.56986,86.54245,,,,,,,,,,,,,,,0.015,0.9522361549050793,110.56191659144461,,,,,,,,,,,,,,,,
2.3,0.59347,4.68758,0,,,,,,,,,,,,,,,,,,,0.023,2.093622171839637,168.80799938881546,,,,,,,,,,,,,,,,
3.1,0.72669,6.38487,0,,,,,,,,,,,,,,,,,,,0.031,3.7315952224349322,233.12322842888798,,,,,,,,,,,,,,,,
3.9,0.86026,8.19757,0,,,,,,,,,,,,,,,,,,,0.039,5.879093744598389,294.5421018536593,,,,,,,,,,,,,,,,
4.7,0.99342,9.81216,0,,,,,,,,,,,,,,,,,,,0.047,8.452628318813838,339.316752344439,,,,,,,,,,,,,,,,
5.5,1.12665,11.68212,0,,,,,,,,,,,,,,,,,,,0.055,11.255850387792,353.76753452986486,,,,,,,,,,,,,,,,
6.3,1.26021,13.83948,0,,,,,,,,,,,,,,,,,,,0.063,14.001925675384852,329.13361239381237,,,,,,,,,,,,,,,,
7.1,1.39338,16.4938,0,,,,,,,,,,,,,,,,,,,0.071,16.37471230476402,266.4235466835371,,,,,,,,,,,,,,,,
7.9,1.52671,19.68471,0,,,,,,,,,,,,,,,,,,,0.079,18.128743615862962,181.26588231746493,,,,,,,,,,,,,,,,
8.7,1.66028,22.58538,0,,,,,,,,,,,,,,,,,,,0.087,,,,,,,,,,,,,,,,,,
9.5,1.79339,25.97271,0,,,,,,,,,,,,,,,,,,,0.095,,,,,,,,,,,,,,,,,,
10.3,1.92672,29.73159,0,,,,,,,,,,,,,,,,,,,0.103,,,,,,,,,,,,,,,,,,
11.1,2.06023,33.62161,0,,,,,,,,,,,,,,,,,,,0.111,,,,,,,,,,,,,,,,,,
11.9,2.19334,37.83246,0,,,,,,,,,,,,,,,,,,,0.119,,,,,,,,,,,,,,,,,,
12.568,2.2045,38.06657,0.5,,,,,,,,,,,,,,,,,,,0.127,,,,,,,,,,,,,,,,,,
13.368,2.07122,32.71133,0.5,,,,,,,,,,,,,,,,,,,0.135,,,,,,,,,,,,,,,,,,
14.168,1.93783,28.15666,0.5,,,,,,,,,,,,,,,,,,,0.143,,,,,,,,,,,,,,,,,,
14.968,1.80444,23.98698,0.5,,,,,,,,,,,,,,,,,,,0.151,,,,,,,,,,,,,,,,,,
15.768,1.67116,20.27293,0.5,,,,,,,,,,,,,,,,,,,0.159,,,,,,,,,,,,,,,,,,
16.568,1.53782,16.96296,0.5,,,,,,,,,,,,,,,,,,,0.167,,,,,,,,,,,,,,,,,,
17.368,1.40443,14.17147,0.5,,,,,,,,,,,,,,,,,,,0.175,,,,,,,,,,,,,,,,,,
18.168,1.27115,11.65916,0.5,,,,,,,,,,,,,,,,,,,0.183,,,,,,,,,,,,,,,,,,
18.968,1.13781,9.31848,0.5,,,,,,,,,,,,,,,,,,,0.191,,,,,,,,,,,,,,,,,,
19.768,1.00447,7.40889,0.5,,,,,,,,,,,,,,,,,,,0.199,,,,,,,,,,,,,,,,,,
20.568,0.87108,5.74113,0.5,,,,,,,,,,,,,,,,,,,,,,,,,,,,,,,,,,,,,
21.368,0.73774,4.09942,0.5,,,,,,,,,,,,,,,,,,,,,,,,,,,,,,,,,,,,,
22.168,0.60446,2.8804,0.5,,,,,,,,,,,,,,,,,,,,,,,,,,,,,,,,,,,,,
22.968,0.47113,1.76411,0.5,,,,,,,,,,,,,,,,,,,,,,,,,,,,,,,,,,,,,
23.606,0.36482,1.00071,1,,,,,,,,,,,,,,,,,,,,,,,,,,,,,,,,,,,,,
24.308,0.48212,2.04532,1,,,,,,,,,,,,,,,,,,,,,,,,,,,,,,,,,,,,,
25.108,0.6154,3.38442,1,,,,,,,,,,,,,,,,,,,,,,,,,,,,,,,,,,,,,
25.908,0.74879,4.99089,1,,,,,,,,,,,,,,,,,,,,,,,,,,,,,,,,,,,,,
26.708,0.88213,6.87006,1,,,,,,,,,,,,,,,,,,,,,,,,,,,,,,,,,,,,,
27.508,1.01535,8.73954,1,,,,,,,,,,,,,,,,,,,,,,,,,,,,,,,,,,,,,
28.308,1.1488,10.61721,1,,,,,,,,,,,,,,,,,,,,,,,,,,,,,,,,,,,,,
29.108,1.28208,12.78076,1,,,,,,,,,,,,,,,,,,,,,,,,,,,,,,,,,,,,,
29.908,1.41542,15.63991,1,,,,,,,,,,,,,,,,,,,,,,,,,,,,,,,,,,,,,
30.708,1.54887,18.72805,1,,,,,,,,,,,,,,,,,,,,,,,,,,,,,,,,,,,,,
31.508,1.68215,21.67714,1,,,,,,,,,,,,,,,,,,,,,,,,,,,,,,,,,,,,,
32.308,1.81543,25.11618,1,,,,,,,,,,,,,,,,,,,,,,,,,,,,,,,,,,,,,
33.108,1.94877,28.88341,1,,,,,,,,,,,,,,,,,,,,,,,,,,,,,,,,,,,,,
33.908,2.0821,33.00245,1,,,,,,,,,,,,,,,,,,,,,,,,,,,,,,,,,,,,,
34.708,2.2155,37.46227,1,,,,,,,,,,,,,,,,,,,,,,,,,,,,,,,,,,,,,
35.358,2.25726,38.97663,1.5,,,,,,,,,,,,,,,,,,,,,,,,,,,,,,,,,,,,,
36.158,2.12358,33.55808,1.5,,,,,,,,,,,,,,,,,,,,,,,,,,,,,,,,,,,,,
36.958,1.99025,28.88373,1.5,,,,,,,,,,,,,,,,,,,,,,,,,,,,,,,,,,,,,
37.758,1.85674,24.70149,1.5,,,,,,,,,,,,,,,,,,,,,,,,,,,,,,,,,,,,,
38.558,1.72346,21.01264,1.5,,,,,,,,,,,,,,,,,,,,,,,,,,,,,,,,,,,,,
39.358,1.59018,17.65738,1.5,,,,,,,,,,,,,,,,,,,,,,,,,,,,,,,,,,,,,
40.158,1.45679,14.68441,1.5,,,,,,,,,,,,,,,,,,,,,,,,,,,,,,,,,,,,,
40.958,1.32345,12.19988,1.5,,,,,,,,,,,,,,,,,,,,,,,,,,,,,,,,,,,,,
41.758,1.19011,9.81476,1.5,,,,,,,,,,,,,,,,,,,,,,,,,,,,,,,,,,,,,
42.558,1.05678,7.72127,1.5,,,,,,,,,,,,,,,,,,,,,,,,,,,,,,,,,,,,,
43.358,0.9235,6.08232,1.5,,,,,,,,,,,,,,,,,,,,,,,,,,,,,,,,,,,,,
44.158,0.79005,4.4012,1.5,,,,,,,,,,,,,,,,,,,,,,,,,,,,,,,,,,,,,
44.958,0.65677,2.95295,1.5,,,,,,,,,,,,,,,,,,,,,,,,,,,,,,,,,,,,,
45.758,0.52349,1.91665,1.5,,,,,,,,,,,,,,,,,,,,,,,,,,,,,,,,,,,,,
46.532,0.39434,0.99781,2,,,,,,,,,,,,,,,,,,,,,,,,,,,,,,,,,,,,,
47.136,0.49476,1.83291,2,,,,,,,,,,,,,,,,,,,,,,,,,,,,,,,,,,,,,
47.936,0.62809,3.13086,2,,,,,,,,,,,,,,,,,,,,,,,,,,,,,,,,,,,,,
48.736,0.76143,4.766,2,,,,,,,,,,,,,,,,,,,,,,,,,,,,,,,,,,,,,
49.536,0.89477,6.5983,2,,,,,,,,,,,,,,,,,,,,,,,,,,,,,,,,,,,,,
50.336,1.0281,8.46668,2,,,,,,,,,,,,,,,,,,,,,,,,,,,,,,,,,,,,,
51.136,1.16138,10.30927,2,,,,,,,,,,,,,,,,,,,,,,,,,,,,,,,,,,,,,
51.936,1.29472,12.64489,2,,,,,,,,,,,,,,,,,,,,,,,,,,,,,,,,,,,,,
52.736,1.42817,15.42889,2,,,,,,,,,,,,,,,,,,,,,,,,,,,,,,,,,,,,,
53.536,1.56145,18.42007,2,,,,,,,,,,,,,,,,,,,,,,,,,,,,,,,,,,,,,
54.336,1.69467,21.48807,2,,,,,,,,,,,,,,,,,,,,,,,,,,,,,,,,,,,,,
55.136,1.82812,24.93696,2,,,,,,,,,,,,,,,,,,,,,,,,,,,,,,,,,,,,,
55.936,1.9614,28.66386,2,,,,,,,,,,,,,,,,,,,,,,,,,,,,,,,,,,,,,
56.736,2.09474,32.81182,2,,,,,,,,,,,,,,,,,,,,,,,,,,,,,,,,,,,,,
57.536,2.22819,37.32831,2,,,,,,,,,,,,,,,,,,,,,,,,,,,,,,,,,,,,,
58.19,2.27063,38.81757,2.5,,,,,,,,,,,,,,,,,,,,,,,,,,,,,,,,,,,,,
58.99,2.13684,33.39358,2.5,,,,,,,,,,,,,,,,,,,,,,,,,,,,,,,,,,,,,
59.79,2.00345,28.74014,2.5,,,,,,,,,,,,,,,,,,,,,,,,,,,,,,,,,,,,,
60.59,1.87011,24.68189,2.5,,,,,,,,,,,,,,,,,,,,,,,,,,,,,,,,,,,,,
61.39,1.73678,21.03311,2.5,,,,,,,,,,,,,,,,,,,,,,,,,,,,,,,,,,,,,
62.19,1.6035,17.59507,2.5,,,,,,,,,,,,,,,,,,,,,,,,,,,,,,,,,,,,,
62.99,1.47005,14.6471,2.5,,,,,,,,,,,,,,,,,,,,,,,,,,,,,,,,,,,,,
63.79,1.33682,12.17233,2.5,,,,,,,,,,,,,,,,,,,,,,,,,,,,,,,,,,,,,
64.59,1.20349,9.84768,2.5,,,,,,,,,,,,,,,,,,,,,,,,,,,,,,,,,,,,,
65.39,1.07004,7.75596,2.5,,,,,,,,,,,,,,,,,,,,,,,,,,,,,,,,,,,,,
66.19,0.93681,5.97326,2.5,,,,,,,,,,,,,,,,,,,,,,,,,,,,,,,,,,,,,
66.99,0.80348,4.34395,2.5,,,,,,,,,,,,,,,,,,,,,,,,,,,,,,,,,,,,,
67.79,0.67008,2.93201,2.5,,,,,,,,,,,,,,,,,,,,,,,,,,,,,,,,,,,,,
68.59,0.5368,1.80502,2.5,,,,,,,,,,,,,,,,,,,,,,,,,,,,,,,,,,,,,
69.308,0.41707,0.99967,3,,,,,,,,,,,,,,,,,,,,,,,,,,,,,,,,,,,,,
69.912,0.51754,1.86883,3,,,,,,,,,,,,,,,,,,,,,,,,,,,,,,,,,,,,,
70.712,0.65065,3.2301,3,,,,,,,,,,,,,,,,,,,,,,,,,,,,,,,,,,,,,
71.512,0.78404,4.83592,3,,,,,,,,,,,,,,,,,,,,,,,,,,,,,,,,,,,,,
72.312,0.91755,6.71461,3,,,,,,,,,,,,,,,,,,,,,,,,,,,,,,,,,,,,,
73.112,1.05066,8.57004,3,,,,,,,,,,,,,,,,,,,,,,,,,,,,,,,,,,,,,
73.912,1.18411,10.44203,3,,,,,,,,,,,,,,,,,,,,,,,,,,,,,,,,,,,,,
74.712,1.3175,12.82992,3,,,,,,,,,,,,,,,,,,,,,,,,,,,,,,,,,,,,,
75.512,1.45067,15.72891,3,,,,,,,,,,,,,,,,,,,,,,,,,,,,,,,,,,,,,
76.312,1.58406,18.62429,3,,,,,,,,,,,,,,,,,,,,,,,,,,,,,,,,,,,,,
77.112,1.71751,21.68791,3,,,,,,,,,,,,,,,,,,,,,,,,,,,,,,,,,,,,,
77.912,1.85073,25.11423,3,,,,,,,,,,,,,,,,,,,,,,,,,,,,,,,,,,,,,
78.712,1.98413,28.94386,3,,,,,,,,,,,,,,,,,,,,,,,,,,,,,,,,,,,,,
79.512,2.11741,33.0553,3,,,,,,,,,,,,,,,,,,,,,,,,,,,,,,,,,,,,,
80.312,2.25074,37.63242,3,,,,,,,,,,,,,,,,,,,,,,,,,,,,,,,,,,,,,
80.99,2.26338,38.05043,3.5,,,,,,,,,,,,,,,,,,,,,,,,,,,,,,,,,,,,,
81.79,2.13021,32.72471,3.5,,,,,,,,,,,,,,,,,,,,,,,,,,,,,,,,,,,,,
82.59,1.99682,28.18249,3.5,,,,,,,,,,,,,,,,,,,,,,,,,,,,,,,,,,,,,
83.39,1.86337,24.15157,3.5,,,,,,,,,,,,,,,,,,,,,,,,,,,,,,,,,,,,,
84.19,1.73015,20.51462,3.5,,,,,,,,,,,,,,,,,,,,,,,,,,,,,,,,,,,,,
84.99,1.59681,17.26747,3.5,,,,,,,,,,,,,,,,,,,,,,,,,,,,,,,,,,,,,
85.79,1.4633,14.31599,3.5,,,,,,,,,,,,,,,,,,,,,,,,,,,,,,,,,,,,,
86.59,1.33025,11.9175,3.5,,,,,,,,,,,,,,,,,,,,,,,,,,,,,,,,,,,,,
87.39,1.1968,9.55,3.5,,,,,,,,,,,,,,,,,,,,,,,,,,,,,,,,,,,,,
88.19,1.06335,7.50161,3.5,,,,,,,,,,,,,,,,,,,,,,,,,,,,,,,,,,,,,
88.99,0.93018,5.73093,3.5,,,,,,,,,,,,,,,,,,,,,,,,,,,,,,,,,,,,,
89.79,0.79679,4.16243,3.5,,,,,,,,,,,,,,,,,,,,,,,,,,,,,,,,,,,,,
90.59,0.6634,2.72153,3.5,,,,,,,,,,,,,,,,,,,,,,,,,,,,,,,,,,,,,
91.39,0.53017,1.68689,3.5,,,,,,,,,,,,,,,,,,,,,,,,,,,,,,,,,,,,,
91.99,0.43016,0.98994,4,,,,,,,,,,,,,,,,,,,,,,,,,,,,,,,,,,,,,
92.79,0.56429,2.17804,4,,,,,,,,,,,,,,,,,,,,,,,,,,,,,,,,,,,,,
93.59,0.69791,3.5976,4,,,,,,,,,,,,,,,,,,,,,,,,,,,,,,,,,,,,,
94.39,0.83102,5.27841,4,,,,,,,,,,,,,,,,,,,,,,,,,,,,,,,,,,,,,
95.19,0.96435,7.14489,4,,,,,,,,,,,,,,,,,,,,,,,,,,,,,,,,,,,,,
95.99,1.0978,9.03703,4,,,,,,,,,,,,,,,,,,,,,,,,,,,,,,,,,,,,,
96.79,1.23108,10.95114,4,,,,,,,,,,,,,,,,,,,,,,,,,,,,,,,,,,,,,
97.59,1.36448,13.57437,4,,,,,,,,,,,,,,,,,,,,,,,,,,,,,,,,,,,,,
98.39,1.49781,16.46774,4,,,,,,,,,,,,,,,,,,,,,,,,,,,,,,,,,,,,,
99.19,1.63104,19.20414,4,,,,,,,,,,,,,,,,,,,,,,,,,,,,,,,,,,,,,
99.99,1.76449,22.55621,4,,,,,,,,,,,,,,,,,,,,,,,,,,,,,,,,,,,,,
100.79,1.89782,26.09421,4,,,,,,,,,,,,,,,,,,,,,,,,,,,,,,,,,,,,,
101.59,2.03099,30.05281,4,,,,,,,,,,,,,,,,,,,,,,,,,,,,,,,,,,,,,
102.39,2.16455,34.31496,4,,,,,,,,,,,,,,,,,,,,,,,,,,,,,,,,,,,,,
103.19,2.29778,38.98691,4,,,,,,,,,,,,,,,,,,,,,,,,,,,,,,,,,,,,,
103.858,2.24219,36.783,4.5,,,,,,,,,,,,,,,,,,,,,,,,,,,,,,,,,,,,,
104.658,2.10885,31.61589,4.5,,,,,,,,,,,,,,,,,,,,,,,,,,,,,,,,,,,,,
105.458,1.97534,27.26665,4.5,,,,,,,,,,,,,,,,,,,,,,,,,,,,,,,,,,,,,
106.258,1.84212,23.25519,4.5,,,,,,,,,,,,,,,,,,,,,,,,,,,,,,,,,,,,,
107.058,1.70884,19.66835,4.5,,,,,,,,,,,,,,,,,,,,,,,,,,,,,,,,,,,,,
107.858,1.57539,16.568,4.5,,,,,,,,,,,,,,,,,,,,,,,,,,,,,,,,,,,,,
108.658,1.44217,13.76542,4.5,,,,,,,,,,,,,,,,,,,,,,,,,,,,,,,,,,,,,
109.458,1.30889,11.35169,4.5,,,,,,,,,,,,,,,,,,,,,,,,,,,,,,,,,,,,,
110.258,1.17538,9.02945,4.5,,,,,,,,,,,,,,,,,,,,,,,,,,,,,,,,,,,,,
111.058,1.0421,7.05299,4.5,,,,,,,,,,,,,,,,,,,,,,,,,,,,,,,,,,,,,
111.858,0.90882,5.33231,4.5,,,,,,,,,,,,,,,,,,,,,,,,,,,,,,,,,,,,,
112.658,0.77548,3.83013,4.5,,,,,,,,,,,,,,,,,,,,,,,,,,,,,,,,,,,,,
113.458,0.64215,2.45152,4.5,,,,,,,,,,,,,,,,,,,,,,,,,,,,,,,,,,,,,
114.258,0.50875,1.49007,4.5,,,,,,,,,,,,,,,,,,,,,,,,,,,,,,,,,,,,,
114.782,0.4509,1.02223,5,,,,,,,,,,,,,,,,,,,,,,,,,,,,,,,,,,,,,
115.582,0.58911,2.30389,5,,,,,,,,,,,,,,,,,,,,,,,,,,,,,,,,,,,,,
116.382,0.72244,3.79693,5,,,,,,,,,,,,,,,,,,,,,,,,,,,,,,,,,,,,,
117.182,0.85584,5.48891,5,,,,,,,,,,,,,,,,,,,,,,,,,,,,,,,,,,,,,
117.982,0.98917,7.36085,5,,,,,,,,,,,,,,,,,,,,,,,,,,,,,,,,,,,,,
118.782,1.12234,9.27075,5,,,,,,,,,,,,,,,,,,,,,,,,,,,,,,,,,,,,,
119.582,1.25585,11.20283,5,,,,,,,,,,,,,,,,,,,,,,,,,,,,,,,,,,,,,
120.382,1.38907,13.91468,5,,,,,,,,,,,,,,,,,,,,,,,,,,,,,,,,,,,,,
121.182,1.52235,16.94926,5,,,,,,,,,,,,,,,,,,,,,,,,,,,,,,,,,,,,,
121.982,1.65586,19.63493,5,,,,,,,,,,,,,,,,,,,,,,,,,,,,,,,,,,,,,
122.782,1.78914,23.03053,5,,,,,,,,,,,,,,,,,,,,,,,,,,,,,,,,,,,,,
123.582,1.92236,26.53698,5,,,,,,,,,,,,,,,,,,,,,,,,,,,,,,,,,,,,,
124.382,2.05581,30.54315,5,,,,,,,,,,,,,,,,,,,,,,,,,,,,,,,,,,,,,
125.182,2.18909,34.85032,5,,,,,,,,,,,,,,,,,,,,,,,,,,,,,,,,,,,,,
125.982,2.32237,39.64632,5,,,,,,,,,,,,,,,,,,,,,,,,,,,,,,,,,,,,,
126.652,2.2338,36.12109,5.5,,,,,,,,,,,,,,,,,,,,,,,,,,,,,,,,,,,,,
127.452,2.10046,31.01716,5.5,,,,,,,,,,,,,,,,,,,,,,,,,,,,,,,,,,,,,
128.252,1.96713,26.68575,5.5,,,,,,,,,,,,,,,,,,,,,,,,,,,,,,,,,,,,,
129.052,1.83385,22.80354,5.5,,,,,,,,,,,,,,,,,,,,,,,,,,,,,,,,,,,,,
129.852,1.70045,19.32726,5.5,,,,,,,,,,,,,,,,,,,,,,,,,,,,,,,,,,,,,
130.652,1.56717,16.21376,5.5,,,,,,,,,,,,,,,,,,,,,,,,,,,,,,,,,,,,,
131.452,1.43384,13.47334,5.5,,,,,,,,,,,,,,,,,,,,,,,,,,,,,,,,,,,,,
132.252,1.30033,11.05812,5.5,,,,,,,,,,,,,,,,,,,,,,,,,,,,,,,,,,,,,
133.052,1.16716,8.8327,5.5,,,,,,,,,,,,,,,,,,,,,,,,,,,,,,,,,,,,,
133.852,1.03383,6.82055,5.5,,,,,,,,,,,,,,,,,,,,,,,,,,,,,,,,,,,,,
134.652,0.90032,5.16075,5.5,,,,,,,,,,,,,,,,,,,,,,,,,,,,,,,,,,,,,
135.452,0.76715,3.62952,5.5,,,,,,,,,,,,,,,,,,,,,,,,,,,,,,,,,,,,,
136.252,0.63382,2.34166,5.5,,,,,,,,,,,,,,,,,,,,,,,,,,,,,,,,,,,,,
137.052,0.50037,1.3538,5.5,,,,,,,,,,,,,,,,,,,,,,,,,,,,,,,,,,,,,
137.612,0.50802,1.44287,6,,,,,,,,,,,,,,,,,,,,,,,,,,,,,,,,,,,,,
138.412,0.64147,2.76346,6,,,,,,,,,,,,,,,,,,,,,,,,,,,,,,,,,,,,,
139.212,0.77475,4.30374,6,,,,,,,,,,,,,,,,,,,,,,,,,,,,,,,,,,,,,
140.012,0.90808,6.00054,6,,,,,,,,,,,,,,,,,,,,,,,,,,,,,,,,,,,,,
140.812,1.04142,7.90884,6,,,,,,,,,,,,,,,,,,,,,,,,,,,,,,,,,,,,,
141.612,1.17476,9.79781,6,,,,,,,,,,,,,,,,,,,,,,,,,,,,,,,,,,,,,
142.412,1.30809,12.12268,6,,,,,,,,,,,,,,,,,,,,,,,,,,,,,,,,,,,,,
143.212,1.44143,14.9345,6,,,,,,,,,,,,,,,,,,,,,,,,,,,,,,,,,,,,,
144.012,1.57471,17.91729,6,,,,,,,,,,,,,,,,,,,,,,,,,,,,,,,,,,,,,
144.812,1.70816,20.76651,6,,,,,,,,,,,,,,,,,,,,,,,,,,,,,,,,,,,,,
145.612,1.84144,24.15383,6,,,,,,,,,,,,,,,,,,,,,,,,,,,,,,,,,,,,,
146.412,1.97478,27.87221,6,,,,,,,,,,,,,,,,,,,,,,,,,,,,,,,,,,,,,
147.212,2.10817,31.97156,6,,,,,,,,,,,,,,,,,,,,,,,,,,,,,,,,,,,,,
148.012,2.24145,36.45681,6,,,,,,,,,,,,,,,,,,,,,,,,,,,,,,,,,,,,,
148.672,2.32226,39.76783,6.5,,,,,,,,,,,,,,,,,,,,,,,,,,,,,,,,,,,,,
149.472,2.18456,33.97436,6.5,,,,,,,,,,,,,,,,,,,,,,,,,,,,,,,,,,,,,
150.272,2.05122,29.23463,6.5,,,,,,,,,,,,,,,,,,,,,,,,,,,,,,,,,,,,,
151.072,1.91766,25.02245,6.5,,,,,,,,,,,,,,,,,,,,,,,,,,,,,,,,,,,,,
151.872,1.78449,21.26366,6.5,,,,,,,,,,,,,,,,,,,,,,,,,,,,,,,,,,,,,
152.672,1.65121,18.06252,6.5,,,,,,,,,,,,,,,,,,,,,,,,,,,,,,,,,,,,,
153.472,1.51765,15.1013,6.5,,,,,,,,,,,,,,,,,,,,,,,,,,,,,,,,,,,,,
154.272,1.38454,12.48663,6.5,,,,,,,,,,,,,,,,,,,,,,,,,,,,,,,,,,,,,
155.072,1.25114,10.15115,6.5,,,,,,,,,,,,,,,,,,,,,,,,,,,,,,,,,,,,,
155.872,1.11775,7.99515,6.5,,,,,,,,,,,,,,,,,,,,,,,,,,,,,,,,,,,,,
156.672,0.98453,6.12389,6.5,,,,,,,,,,,,,,,,,,,,,,,,,,,,,,,,,,,,,
157.472,0.85113,4.47472,6.5,,,,,,,,,,,,,,,,,,,,,,,,,,,,,,,,,,,,,
158.272,0.71774,3.0563,6.5,,,,,,,,,,,,,,,,,,,,,,,,,,,,,,,,,,,,,
159.072,0.58452,1.90364,6.5,,,,,,,,,,,,,,,,,,,,,,,,,,,,,,,,,,,,,
159.872,0.45107,1.0245,6.5,,,,,,,,,,,,,,,,,,,,,,,,,,,,,,,,,,,,,
160.392,0.53204,1.59881,7,,,,,,,,,,,,,,,,,,,,,,,,,,,,,,,,,,,,,
161.192,0.66544,2.92523,7,,,,,,,,,,,,,,,,,,,,,,,,,,,,,,,,,,,,,
161.992,0.79883,4.47677,7,,,,,,,,,,,,,,,,,,,,,,,,,,,,,,,,,,,,,
162.792,0.932,6.28702,7,,,,,,,,,,,,,,,,,,,,,,,,,,,,,,,,,,,,,
163.592,1.06545,8.30592,7,,,,,,,,,,,,,,,,,,,,,,,,,,,,,,,,,,,,,
164.392,1.1989,10.1356,7,,,,,,,,,,,,,,,,,,,,,,,,,,,,,,,,,,,,,
165.192,1.33201,12.45938,7,,,,,,,,,,,,,,,,,,,,,,,,,,,,,,,,,,,,,
165.992,1.4654,15.31713,7,,,,,,,,,,,,,,,,,,,,,,,,,,,,,,,,,,,,,
166.792,1.59885,18.24058,7,,,,,,,,,,,,,,,,,,,,,,,,,,,,,,,,,,,,,
167.592,1.73213,21.20285,7,,,,,,,,,,,,,,,,,,,,,,,,,,,,,,,,,,,,,
168.392,1.86547,24.5834,7,,,,,,,,,,,,,,,,,,,,,,,,,,,,,,,,,,,,,
169.192,1.99886,28.44179,7,,,,,,,,,,,,,,,,,,,,,,,,,,,,,,,,,,,,,
169.992,2.13208,32.56272,7,,,,,,,,,,,,,,,,,,,,,,,,,,,,,,,,,,,,,
170.792,2.26536,37.20866,7,,,,,,,,,,,,,,,,,,,,,,,,,,,,,,,,,,,,,
171.456,2.30962,38.82318,7.5,,,,,,,,,,,,,,,,,,,,,,,,,,,,,,,,,,,,,
172.256,2.17589,33.50694,7.5,,,,,,,,,,,,,,,,,,,,,,,,,,,,,,,,,,,,,
173.056,2.04249,28.77981,7.5,,,,,,,,,,,,,,,,,,,,,,,,,,,,,,,,,,,,,
173.856,1.90916,24.61093,7.5,,,,,,,,,,,,,,,,,,,,,,,,,,,,,,,,,,,,,
174.656,1.77576,20.98028,7.5,,,,,,,,,,,,,,,,,,,,,,,,,,,,,,,,,,,,,
175.456,1.64243,17.7263,7.5,,,,,,,,,,,,,,,,,,,,,,,,,,,,,,,,,,,,,
176.256,1.50909,14.88354,7.5,,,,,,,,,,,,,,,,,,,,,,,,,,,,,,,,,,,,,
177.056,1.37587,12.24312,7.5,,,,,,,,,,,,,,,,,,,,,,,,,,,,,,,,,,,,,
177.856,1.24236,10.05824,7.5,,,,,,,,,,,,,,,,,,,,,,,,,,,,,,,,,,,,,
178.656,1.10908,7.81813,7.5,,,,,,,,,,,,,,,,,,,,,,,,,,,,,,,,,,,,,
179.456,0.9758,5.93911,7.5,,,,,,,,,,,,,,,,,,,,,,,,,,,,,,,,,,,,,
180.256,0.84241,4.3453,7.5,,,,,,,,,,,,,,,,,,,,,,,,,,,,,,,,,,,,,
181.056,0.70918,2.85076,7.5,,,,,,,,,,,,,,,,,,,,,,,,,,,,,,,,,,,,,
181.856,0.57585,1.81796,7.5,,,,,,,,,,,,,,,,,,,,,,,,,,,,,,,,,,,,,
182.536,0.46251,0.99383,8,,,,,,,,,,,,,,,,,,,,,,,,,,,,,,,,,,,,,
183.238,0.57987,1.98831,8,,,,,,,,,,,,,,,,,,,,,,,,,,,,,,,,,,,,,
184.038,0.71304,3.34162,8,,,,,,,,,,,,,,,,,,,,,,,,,,,,,,,,,,,,,
184.838,0.84632,5.01324,8,,,,,,,,,,,,,,,,,,,,,,,,,,,,,,,,,,,,,
185.638,0.97994,6.94026,8,,,,,,,,,,,,,,,,,,,,,,,,,,,,,,,,,,,,,
186.438,1.11305,8.72869,8,,,,,,,,,,,,,,,,,,,,,,,,,,,,,,,,,,,,,
187.238,1.24638,10.8098,8,,,,,,,,,,,,,,,,,,,,,,,,,,,,,,,,,,,,,
188.038,1.37989,13.38181,8,,,,,,,,,,,,,,,,,,,,,,,,,,,,,,,,,,,,,
188.838,1.513,16.20757,8,,,,,,,,,,,,,,,,,,,,,,,,,,,,,,,,,,,,,
189.638,1.64645,19.00075,8,,,,,,,,,,,,,,,,,,,,,,,,,,,,,,,,,,,,,
190.438,1.77979,22.27759,8,,,,,,,,,,,,,,,,,,,,,,,,,,,,,,,,,,,,,
191.238,1.91307,25.742,8,,,,,,,,,,,,,,,,,,,,,,,,,,,,,,,,,,,,,
192.038,2.04657,29.69954,8,,,,,,,,,,,,,,,,,,,,,,,,,,,,,,,,,,,,,
192.838,2.1798,33.96766,8,,,,,,,,,,,,,,,,,,,,,,,,,,,,,,,,,,,,,
193.638,2.31302,38.70365,8,,,,,,,,,,,,,,,,,,,,,,,,,,,,,,,,,,,,,
194.25,2.28157,37.43384,8.5,,,,,,,,,,,,,,,,,,,,,,,,,,,,,,,,,,,,,
195.05,2.14812,32.25053,8.5,,,,,,,,,,,,,,,,,,,,,,,,,,,,,,,,,,,,,
195.85,2.01478,27.67449,8.5,,,,,,,,,,,,,,,,,,,,,,,,,,,,,,,,,,,,,
196.65,1.8815,23.69433,8.5,,,,,,,,,,,,,,,,,,,,,,,,,,,,,,,,,,,,,
197.45,1.74805,20.02249,8.5,,,,,,,,,,,,,,,,,,,,,,,,,,,,,,,,,,,,,
198.25,1.61477,17.05708,8.5,,,,,,,,,,,,,,,,,,,,,,,,,,,,,,,,,,,,,
199.05,1.48149,14.12259,8.5,,,,,,,,,,,,,,,,,,,,,,,,,,,,,,,,,,,,,
199.85,1.34804,11.66293,8.5,,,,,,,,,,,,,,,,,,,,,,,,,,,,,,,,,,,,,
200.65,1.21471,9.35851,8.5,,,,,,,,,,,,,,,,,,,,,,,,,,,,,,,,,,,,,
201.45,1.08154,7.26388,8.5,,,,,,,,,,,,,,,,,,,,,,,,,,,,,,,,,,,,,
202.25,0.94803,5.48096,8.5,,,,,,,,,,,,,,,,,,,,,,,,,,,,,,,,,,,,,
203.05,0.81475,3.89324,8.5,,,,,,,,,,,,,,,,,,,,,,,,,,,,,,,,,,,,,
203.85,0.68147,2.59816,8.5,,,,,,,,,,,,,,,,,,,,,,,,,,,,,,,,,,,,,
204.65,0.54814,1.53282,8.5,,,,,,,,,,,,,,,,,,,,,,,,,,,,,,,,,,,,,
205.242,0.47866,0.96485,9,,,,,,,,,,,,,,,,,,,,,,,,,,,,,,,,,,,,,
206.042,0.61699,2.29879,9,,,,,,,,,,,,,,,,,,,,,,,,,,,,,,,,,,,,,
206.842,0.75049,3.73918,9,,,,,,,,,,,,,,,,,,,,,,,,,,,,,,,,,,,,,
207.642,0.88377,5.47065,9,,,,,,,,,,,,,,,,,,,,,,,,,,,,,,,,,,,,,
208.442,1.017,7.32344,9,,,,,,,,,,,,,,,,,,,,,,,,,,,,,,,,,,,,,
209.242,1.1505,9.20915,9,,,,,,,,,,,,,,,,,,,,,,,,,,,,,,,,,,,,,
210.042,1.28373,11.34857,9,,,,,,,,,,,,,,,,,,,,,,,,,,,,,,,,,,,,,
210.842,1.41706,13.97403,9,,,,,,,,,,,,,,,,,,,,,,,,,,,,,,,,,,,,,
211.642,1.55051,16.91414,9,,,,,,,,,,,,,,,,,,,,,,,,,,,,,,,,,,,,,
212.442,1.68374,19.74959,9,,,,,,,,,,,,,,,,,,,,,,,,,,,,,,,,,,,,,
213.242,1.81707,23.01993,9,,,,,,,,,,,,,,,,,,,,,,,,,,,,,,,,,,,,,
214.042,1.95047,26.56881,9,,,,,,,,,,,,,,,,,,,,,,,,,,,,,,,,,,,,,
214.842,2.08369,30.71236,9,,,,,,,,,,,,,,,,,,,,,,,,,,,,,,,,,,,,,
215.642,2.2172,35.14792,9,,,,,,,,,,,,,,,,,,,,,,,,,,,,,,,,,,,,,
216.442,2.35053,39.99279,9,,,,,,,,,,,,,,,,,,,,,,,,,,,,,,,,,,,,,
217.046,2.25074,35.98487,9.5,,,,,,,,,,,,,,,,,,,,,,,,,,,,,,,,,,,,,
217.846,2.11758,30.98109,9.5,,,,,,,,,,,,,,,,,,,,,,,,,,,,,,,,,,,,,
218.646,1.98401,26.6962,9.5,,,,,,,,,,,,,,,,,,,,,,,,,,,,,,,,,,,,,
219.446,1.85079,22.73334,9.5,,,,,,,,,,,,,,,,,,,,,,,,,,,,,,,,,,,,,
220.246,1.71757,19.25694,9.5,,,,,,,,,,,,,,,,,,,,,,,,,,,,,,,,,,,,,
221.046,1.584,16.22289,9.5,,,,,,,,,,,,,,,,,,,,,,,,,,,,,,,,,,,,,
221.846,1.45078,13.42153,9.5,,,,,,,,,,,,,,,,,,,,,,,,,,,,,,,,,,,,,
222.646,1.31756,11.06013,9.5,,,,,,,,,,,,,,,,,,,,,,,,,,,,,,,,,,,,,
223.446,1.18394,8.75677,9.5,,,,,,,,,,,,,,,,,,,,,,,,,,,,,,,,,,,,,
224.246,1.05083,6.75844,9.5,,,,,,,,,,,,,,,,,,,,,,,,,,,,,,,,,,,,,
225.046,0.91749,5.10754,9.5,,,,,,,,,,,,,,,,,,,,,,,,,,,,,,,,,,,,,
225.846,0.78387,3.57173,9.5,,,,,,,,,,,,,,,,,,,,,,,,,,,,,,,,,,,,,
226.646,0.65087,2.26995,9.5,,,,,,,,,,,,,,,,,,,,,,,,,,,,,,,,,,,,,
227.446,0.51754,1.36122,9.5,,,,,,,,,,,,,,,,,,,,,,,,,,,,,,,,,,,,,
228.148,0.40528,0.71444,10,,,,,,,,,,,,,,,,,,,,,,,,,,,,,,,,,,,,,
228.948,0.36624,0.5499,10,,,,,,,,,,,,,,,,,,,,,,,,,,,,,,,,,,,,,
229.748,0.36771,0.60725,10,,,,,,,,,,,,,,,,,,,,,,,,,,,,,,,,,,,,,
230.548,0.40307,0.76633,10,,,,,,,,,,,,,,,,,,,,,,,,,,,,,,,,,,,,,
231.348,0.46064,1.15251,10,,,,,,,,,,,,,,,,,,,,,,,,,,,,,,,,,,,,,
232.148,0.46104,1.16662,10,,,,,,,,,,,,,,,,,,,,,,,,,,,,,,,,,,,,,
232.948,0.45135,1.14452,10,,,,,,,,,,,,,,,,,,,,,,,,,,,,,,,,,,,,,
233.748,0.40653,0.85694,10,,,,,,,,,,,,,,,,,,,,,,,,,,,,,,,,,,,,,
234.548,0.4008,0.82479,10,,,,,,,,,,,,,,,,,,,,,,,,,,,,,,,,,,,,,
235.348,0.40097,0.79372,10,,,,,,,,,,,,,,,,,,,,,,,,,,,,,,,,,,,,,
236.148,0.40143,0.81823,10,,,,,,,,,,,,,,,,,,,,,,,,,,,,,,,,,,,,,
236.948,0.40409,0.74253,10,,,,,,,,,,,,,,,,,,,,,,,,,,,,,,,,,,,,,
237.748,0.41559,0.91607,10,,,,,,,,,,,,,,,,,,,,,,,,,,,,,,,,,,,,,
238.548,0.43033,0.98407,10,,,,,,,,,,,,,,,,,,,,,,,,,,,,,,,,,,,,,
239.348,0.43055,1.00439,10,,,,,,,,,,,,,,,,,,,,,,,,,,,,,,,,,,,,,
240.148,0.43038,0.97804,10,,,,,,,,,,,,,,,,,,,,,,,,,,,,,,,,,,,,,
240.948,0.4301,1.04025,10,,,,,,,,,,,,,,,,,,,,,,,,,,,,,,,,,,,,,
241.748,0.42738,1.14922,10,,,,,,,,,,,,,,,,,,,,,,,,,,,,,,,,,,,,,
242.548,0.41423,0.90867,10,,,,,,,,,,,,,,,,,,,,,,,,,,,,,,,,,,,,,
243.348,0.4042,0.87263,10,,,,,,,,,,,,,,,,,,,,,,,,,,,,,,,,,,,,,
244.148,0.40409,0.83256,10,,,,,,,,,,,,,,,,,,,,,,,,,,,,,,,,,,,,,
244.948,0.4042,0.81055,10,,,,,,,,,,,,,,,,,,,,,,,,,,,,,,,,,,,,,
245.748,0.40426,0.92938,10,,,,,,,,,,,,,,,,,,,,,,,,,,,,,,,,,,,,,
246.548,0.40454,0.78732,10,,,,,,,,,,,,,,,,,,,,,,,,,,,,,,,,,,,,,
247.348,0.40528,0.7791,10,,,,,,,,,,,,,,,,,,,,,,,,,,,,,,,,,,,,,
248.148,0.40766,0.83831,10,,,,,,,,,,,,,,,,,,,,,,,,,,,,,,,,,,,,,
248.948,0.41151,0.85689,10,,,,,,,,,,,,,,,,,,,,,,,,,,,,,,,,,,,,,
249.748,0.41967,0.95353,10,,,,,,,,,,,,,,,,,,,,,,,,,,,,,,,,,,,,,
250.548,0.42137,0.92799,10,,,,,,,,,,,,,,,,,,,,,,,,,,,,,,,,,,,,,
251.348,0.42143,0.91796,10,,,,,,,,,,,,,,,,,,,,,,,,,,,,,,,,,,,,,
252.148,0.42126,1.01202,10,,,,,,,,,,,,,,,,,,,,,,,,,,,,,,,,,,,,,
252.948,0.42103,1.00988,10,,,,,,,,,,,,,,,,,,,,,,,,,,,,,,,,,,,,,
253.748,0.41984,1.02972,10,,,,,,,,,,,,,,,,,,,,,,,,,,,,,,,,,,,,,
254.548,0.41542,0.95279,10,,,,,,,,,,,,,,,,,,,,,,,,,,,,,,,,,,,,,
255.348,0.40692,0.9405,10,,,,,,,,,,,,,,,,,,,,,,,,,,,,,,,,,,,,,
256.148,0.40528,0.91389,10,,,,,,,,,,,,,,,,,,,,,,,,,,,,,,,,,,,,,
256.948,0.40466,0.88516,10,,,,,,,,,,,,,,,,,,,,,,,,,,,,,,,,,,,,,
257.748,0.40454,0.94606,10,,,,,,,,,,,,,,,,,,,,,,,,,,,,,,,,,,,,,
258.548,0.4046,0.84894,10,,,,,,,,,,,,,,,,,,,,,,,,,,,,,,,,,,,,,
259.348,0.4046,0.85235,10,,,,,,,,,,,,,,,,,,,,,,,,,,,,,,,,,,,,,
260.148,0.40471,0.88414,10,,,,,,,,,,,,,,,,,,,,,,,,,,,,,,,,,,,,,
260.948,0.40471,0.88179,10,,,,,,,,,,,,,,,,,,,,,,,,,,,,,,,,,,,,,
261.748,0.40477,0.92278,10,,,,,,,,,,,,,,,,,,,,,,,,,,,,,,,,,,,,,
262.548,0.40488,0.877,10,,,,,,,,,,,,,,,,,,,,,,,,,,,,,,,,,,,,,
263.348,0.405,0.82917,10,,,,,,,,,,,,,,,,,,,,,,,,,,,,,,,,,,,,,
264.148,0.40511,0.83399,10,,,,,,,,,,,,,,,,,,,,,,,,,,,,,,,,,,,,,
264.948,0.40539,0.85895,10,,,,,,,,,,,,,,,,,,,,,,,,,,,,,,,,,,,,,
265.748,0.40562,0.85109,10,,,,,,,,,,,,,,,,,,,,,,,,,,,,,,,,,,,,,
266.548,0.40624,0.84511,10,,,,,,,,,,,,,,,,,,,,,,,,,,,,,,,,,,,,,
267.348,0.40721,0.92047,10,,,,,,,,,,,,,,,,,,,,,,,,,,,,,,,,,,,,,
268.148,0.40806,0.84162,10,,,,,,,,,,,,,,,,,,,,,,,,,,,,,,,,,,,,,
268.948,0.40862,0.85242,10,,,,,,,,,,,,,,,,,,,,,,,,,,,,,,,,,,,,,
269.748,0.40913,0.9002,10,,,,,,,,,,,,,,,,,,,,,,,,,,,,,,,,,,,,,
270.548,0.40959,0.95965,10,,,,,,,,,,,,,,,,,,,,,,,,,,,,,,,,,,,,,
271.348,0.40981,0.93486,10,,,,,,,,,,,,,,,,,,,,,,,,,,,,,,,,,,,,,
272.148,0.40993,0.98689,10,,,,,,,,,,,,,,,,,,,,,,,,,,,,,,,,,,,,,
272.948,0.40976,0.90619,10,,,,,,,,,,,,,,,,,,,,,,,,,,,,,,,,,,,,,
273.748,0.4097,0.95498,10,,,,,,,,,,,,,,,,,,,,,,,,,,,,,,,,,,,,,
274.548,0.4097,0.89512,10,,,,,,,,,,,,,,,,,,,,,,,,,,,,,,,,,,,,,
275.348,0.40964,0.85036,10,,,,,,,,,,,,,,,,,,,,,,,,,,,,,,,,,,,,,
276.148,0.40953,0.928,10,,,,,,,,,,,,,,,,,,,,,,,,,,,,,,,,,,,,,
276.948,0.40936,0.9239,10,,,,,,,,,,,,,,,,,,,,,,,,,,,,,,,,,,,,,
277.748,0.40919,0.94154,10,,,,,,,,,,,,,,,,,,,,,,,,,,,,,,,,,,,,,
278.548,0.40874,0.94654,10,,,,,,,,,,,,,,,,,,,,,,,,,,,,,,,,,,,,,
279.348,0.40783,0.89351,10,,,,,,,,,,,,,,,,,,,,,,,,,,,,,,,,,,,,,
280.148,0.40687,0.89568,10,,,,,,,,,,,,,,,,,,,,,,,,,,,,,,,,,,,,,
280.948,0.40539,0.93018,10,,,,,,,,,,,,,,,,,,,,,,,,,,,,,,,,,,,,,
281.748,0.40409,0.89875,10,,,,,,,,,,,,,,,,,,,,,,,,,,,,,,,,,,,,,
282.548,0.40182,0.89153,10,,,,,,,,,,,,,,,,,,,,,,,,,,,,,,,,,,,,,
283.348,0.39961,0.84634,10,,,,,,,,,,,,,,,,,,,,,,,,,,,,,,,,,,,,,
284.148,0.39763,0.88885,10,,,,,,,,,,,,,,,,,,,,,,,,,,,,,,,,,,,,,
284.948,0.39689,0.85547,10,,,,,,,,,,,,,,,,,,,,,,,,,,,,,,,,,,,,,
285.748,0.39672,0.86914,10,,,,,,,,,,,,,,,,,,,,,,,,,,,,,,,,,,,,,
286.548,0.39678,0.82382,10,,,,,,,,,,,,,,,,,,,,,,,,,,,,,,,,,,,,,
287.348,0.39695,0.83705,10,,,,,,,,,,,,,,,,,,,,,,,,,,,,,,,,,,,,,
288.148,0.39712,0.83521,10,,,,,,,,,,,,,,,,,,,,,,,,,,,,,,,,,,,,,
288.948,0.39735,0.80631,10,,,,,,,,,,,,,,,,,,,,,,,,,,,,,,,,,,,,,
289.748,0.39791,0.82136,10,,,,,,,,,,,,,,,,,,,,,,,,,,,,,,,,,,,,,
290.548,0.39916,0.85344,10,,,,,,,,,,,,,,,,,,,,,,,,,,,,,,,,,,,,,
291.348,0.40239,0.8585,10,,,,,,,,,,,,,,,,,,,,,,,,,,,,,,,,,,,,,
292.148,0.40766,0.87997,10,,,,,,,,,,,,,,,,,,,,,,,,,,,,,,,,,,,,,
292.948,0.40902,0.85513,10,,,,,,,,,,,,,,,,,,,,,,,,,,,,,,,,,,,,,
293.748,0.40942,0.91035,10,,,,,,,,,,,,,,,,,,,,,,,,,,,,,,,,,,,,,
294.548,0.40936,0.91825,10,,,,,,,,,,,,,,,,,,,,,,,,,,,,,,,,,,,,,
295.348,0.4093,0.89081,10,,,,,,,,,,,,,,,,,,,,,,,,,,,,,,,,,,,,,
296.148,0.40919,0.99101,10,,,,,,,,,,,,,,,,,,,,,,,,,,,,,,,,,,,,,
296.948,0.40913,0.89363,10,,,,,,,,,,,,,,,,,,,,,,,,,,,,,,,,,,,,,
297.748,0.40908,0.88157,10,,,,,,,,,,,,,,,,,,,,,,,,,,,,,,,,,,,,,
298.548,0.40885,0.94485,10,,,,,,,,,,,,,,,,,,,,,,,,,,,,,,,,,,,,,
299.348,0.408,0.93179,10,,,,,,,,,,,,,,,,,,,,,,,,,,,,,,,,,,,,,
300.148,0.4067,0.95897,10,,,,,,,,,,,,,,,,,,,,,,,,,,,,,,,,,,,,,
300.948,0.40477,0.89139,10,,,,,,,,,,,,,,,,,,,,,,,,,,,,,,,,,,,,,
301.748,0.4025,0.93357,10,,,,,,,,,,,,,,,,,,,,,,,,,,,,,,,,,,,,,
302.548,0.40024,0.8847,10,,,,,,,,,,,,,,,,,,,,,,,,,,,,,,,,,,,,,
303.348,0.39763,0.89698,10,,,,,,,,,,,,,,,,,,,,,,,,,,,,,,,,,,,,,
304.148,0.39655,0.91075,10,,,,,,,,,,,,,,,,,,,,,,,,,,,,,,,,,,,,,
304.948,0.39627,0.83367,10,,,,,,,,,,,,,,,,,,,,,,,,,,,,,,,,,,,,,
305.748,0.39638,0.8506,10,,,,,,,,,,,,,,,,,,,,,,,,,,,,,,,,,,,,,
306.548,0.3965,0.83771,10,,,,,,,,,,,,,,,,,,,,,,,,,,,,,,,,,,,,,
307.348,0.39655,0.86095,10,,,,,,,,,,,,,,,,,,,,,,,,,,,,,,,,,,,,,
308.148,0.39678,0.89127,10,,,,,,,,,,,,,,,,,,,,,,,,,,,,,,,,,,,,,
308.948,0.39706,0.82225,10,,,,,,,,,,,,,,,,,,,,,,,,,,,,,,,,,,,,,
309.748,0.39769,0.84165,10,,,,,,,,,,,,,,,,,,,,,,,,,,,,,,,,,,,,,
310.548,0.39939,0.81588,10,,,,,,,,,,,,,,,,,,,,,,,,,,,,,,,,,,,,,
311.348,0.40318,0.84432,10,,,,,,,,,,,,,,,,,,,,,,,,,,,,,,,,,,,,,
312.148,0.40777,0.94597,10,,,,,,,,,,,,,,,,,,,,,,,,,,,,,,,,,,,,,
312.948,0.40845,0.95753,10,,,,,,,,,,,,,,,,,,,,,,,,,,,,,,,,,,,,,
313.748,0.40862,0.9212,10,,,,,,,,,,,,,,,,,,,,,,,,,,,,,,,,,,,,,
314.548,0.40845,0.95056,10,,,,,,,,,,,,,,,,,,,,,,,,,,,,,,,,,,,,,
315.348,0.40845,0.95643,10,,,,,,,,,,,,,,,,,,,,,,,,,,,,,,,,,,,,,
316.148,0.40834,0.94061,10,,,,,,,,,,,,,,,,,,,,,,,,,,,,,,,,,,,,,
316.948,0.40811,0.9208,10,,,,,,,,,,,,,,,,,,,,,,,,,,,,,,,,,,,,,
317.748,0.40794,1.04198,10,,,,,,,,,,,,,,,,,,,,,,,,,,,,,,,,,,,,,
318.548,0.40687,0.96803,10,,,,,,,,,,,,,,,,,,,,,,,,,,,,,,,,,,,,,
319.348,0.40483,0.95753,10,,,,,,,,,,,,,,,,,,,,,,,,,,,,,,,,,,,,,
320.148,0.40279,0.9527,10,,,,,,,,,,,,,,,,,,,,,,,,,,,,,,,,,,,,,
320.948,0.40075,0.93202,10,,,,,,,,,,,,,,,,,,,,,,,,,,,,,,,,,,,,,
321.748,0.39876,0.87259,10,,,,,,,,,,,,,,,,,,,,,,,,,,,,,,,,,,,,,
322.548,0.39729,0.91366,10,,,,,,,,,,,,,,,,,,,,,,,,,,,,,,,,,,,,,
323.348,0.39667,0.93175,10,,,,,,,,,,,,,,,,,,,,,,,,,,,,,,,,,,,,,
324.148,0.39644,0.87209,10,,,,,,,,,,,,,,,,,,,,,,,,,,,,,,,,,,,,,
324.948,0.39638,0.93665,10,,,,,,,,,,,,,,,,,,,,,,,,,,,,,,,,,,,,,
325.748,0.3965,0.87993,10,,,,,,,,,,,,,,,,,,,,,,,,,,,,,,,,,,,,,
326.548,0.39661,0.84001,10,,,,,,,,,,,,,,,,,,,,,,,,,,,,,,,,,,,,,
327.348,0.39667,0.86535,10,,,,,,,,,,,,,,,,,,,,,,,,,,,,,,,,,,,,,
328.148,0.39684,0.8181,10,,,,,,,,,,,,,,,,,,,,,,,,,,,,,,,,,,,,,
328.948,0.39706,0.87658,10,,,,,,,,,,,,,,,,,,,,,,,,,,,,,,,,,,,,,
329.748,0.39757,0.87088,10,,,,,,,,,,,,,,,,,,,,,,,,,,,,,,,,,,,,,
330.548,0.39888,0.80075,10,,,,,,,,,,,,,,,,,,,,,,,,,,,,,,,,,,,,,
331.348,0.40194,0.83531,10,,,,,,,,,,,,,,,,,,,,,,,,,,,,,,,,,,,,,
332.148,0.40704,0.87391,10,,,,,,,,,,,,,,,,,,,,,,,,,,,,,,,,,,,,,
332.948,0.40828,0.99527,10,,,,,,,,,,,,,,,,,,,,,,,,,,,,,,,,,,,,,
333.748,0.4084,0.98999,10,,,,,,,,,,,,,,,,,,,,,,,,,,,,,,,,,,,,,
334.548,0.40817,0.96285,10,,,,,,,,,,,,,,,,,,,,,,,,,,,,,,,,,,,,,
335.348,0.40806,0.88367,10,,,,,,,,,,,,,,,,,,,,,,,,,,,,,,,,,,,,,
336.148,0.40783,0.94287,10,,,,,,,,,,,,,,,,,,,,,,,,,,,,,,,,,,,,,
336.948,0.40726,1.0537,10,,,,,,,,,,,,,,,,,,,,,,,,,,,,,,,,,,,,,
337.748,0.40551,0.96805,10,,,,,,,,,,,,,,,,,,,,,,,,,,,,,,,,,,,,,
338.548,0.40307,0.90749,10,,,,,,,,,,,,,,,,,,,,,,,,,,,,,,,,,,,,,
339.348,0.39956,0.93404,10,,,,,,,,,,,,,,,,,,,,,,,,,,,,,,,,,,,,,
340.148,0.39695,0.89001,10,,,,,,,,,,,,,,,,,,,,,,,,,,,,,,,,,,,,,
340.948,0.39599,0.93168,10,,,,,,,,,,,,,,,,,,,,,,,,,,,,,,,,,,,,,
341.748,0.39582,0.96477,10,,,,,,,,,,,,,,,,,,,,,,,,,,,,,,,,,,,,,
342.548,0.39587,0.86757,10,,,,,,,,,,,,,,,,,,,,,,,,,,,,,,,,,,,,,
343.348,0.39593,0.84345,10,,,,,,,,,,,,,,,,,,,,,,,,,,,,,,,,,,,,,
344.148,0.39599,0.90285,10,,,,,,,,,,,,,,,,,,,,,,,,,,,,,,,,,,,,,
344.948,0.39593,0.9255,10,,,,,,,,,,,,,,,,,,,,,,,,,,,,,,,,,,,,,
345.748,0.39604,0.88311,10,,,,,,,,,,,,,,,,,,,,,,,,,,,,,,,,,,,,,
346.548,0.39616,0.90447,10,,,,,,,,,,,,,,,,,,,,,,,,,,,,,,,,,,,,,
347.348,0.39621,0.89608,10,,,,,,,,,,,,,,,,,,,,,,,,,,,,,,,,,,,,,
348.148,0.39627,0.87175,10,,,,,,,,,,,,,,,,,,,,,,,,,,,,,,,,,,,,,
348.948,0.39627,0.84187,10,,,,,,,,,,,,,,,,,,,,,,,,,,,,,,,,,,,,,
349.748,0.39633,0.89223,10,,,,,,,,,,,,,,,,,,,,,,,,,,,,,,,,,,,,,
350.548,0.39638,0.90089,10,,,,,,,,,,,,,,,,,,,,,,,,,,,,,,,,,,,,,
351.348,0.39655,0.87707,10,,,,,,,,,,,,,,,,,,,,,,,,,,,,,,,,,,,,,
352.148,0.39672,0.78723,10,,,,,,,,,,,,,,,,,,,,,,,,,,,,,,,,,,,,,
352.948,0.39723,0.78243,10,,,,,,,,,,,,,,,,,,,,,,,,,,,,,,,,,,,,,
353.748,0.39837,0.87938,10,,,,,,,,,,,,,,,,,,,,,,,,,,,,,,,,,,,,,
354.548,0.40063,0.90105,10,,,,,,,,,,,,,,,,,,,,,,,,,,,,,,,,,,,,,
355.348,0.40347,0.86879,10,,,,,,,,,,,,,,,,,,,,,,,,,,,,,,,,,,,,,
356.148,0.4059,0.89328,10,,,,,,,,,,,,,,,,,,,,,,,,,,,,,,,,,,,,,
356.948,0.4063,0.88494,10,,,,,,,,,,,,,,,,,,,,,,,,,,,,,,,,,,,,,
357.748,0.40641,0.96489,10,,,,,,,,,,,,,,,,,,,,,,,,,,,,,,,,,,,,,
358.548,0.40636,0.96789,10,,,,,,,,,,,,,,,,,,,,,,,,,,,,,,,,,,,,,
359.348,0.40613,1.03309,10,,,,,,,,,,,,,,,,,,,,,,,,,,,,,,,,,,,,,
360.148,0.40596,0.93254,10,,,,,,,,,,,,,,,,,,,,,,,,,,,,,,,,,,,,,
360.948,0.40562,1.00777,10,,,,,,,,,,,,,,,,,,,,,,,,,,,,,,,,,,,,,
361.748,0.40449,0.95966,10,,,,,,,,,,,,,,,,,,,,,,,,,,,,,,,,,,,,,
362.548,0.40239,0.95775,10,,,,,,,,,,,,,,,,,,,,,,,,,,,,,,,,,,,,,
363.348,0.39927,0.93803,10,,,,,,,,,,,,,,,,,,,,,,,,,,,,,,,,,,,,,
364.148,0.39718,0.91686,10,,,,,,,,,,,,,,,,,,,,,,,,,,,,,,,,,,,,,
364.948,0.39644,0.87524,10,,,,,,,,,,,,,,,,,,,,,,,,,,,,,,,,,,,,,
365.748,0.39599,0.93459,10,,,,,,,,,,,,,,,,,,,,,,,,,,,,,,,,,,,,,
366.548,0.39565,0.94184,10,,,,,,,,,,,,,,,,,,,,,,,,,,,,,,,,,,,,,
367.348,0.39553,0.90552,10,,,,,,,,,,,,,,,,,,,,,,,,,,,,,,,,,,,,,
368.148,0.39542,0.87419,10,,,,,,,,,,,,,,,,,,,,,,,,,,,,,,,,,,,,,
368.948,0.39542,0.82743,10,,,,,,,,,,,,,,,,,,,,,,,,,,,,,,,,,,,,,
369.748,0.39553,0.90574,10,,,,,,,,,,,,,,,,,,,,,,,,,,,,,,,,,,,,,
370.548,0.39559,0.90559,10,,,,,,,,,,,,,,,,,,,,,,,,,,,,,,,,,,,,,
371.348,0.39565,0.86075,10,,,,,,,,,,,,,,,,,,,,,,,,,,,,,,,,,,,,,
372.148,0.3957,0.83714,10,,,,,,,,,,,,,,,,,,,,,,,,,,,,,,,,,,,,,
372.948,0.39576,0.8303,10,,,,,,,,,,,,,,,,,,,,,,,,,,,,,,,,,,,,,
373.748,0.39587,0.86724,10,,,,,,,,,,,,,,,,,,,,,,,,,,,,,,,,,,,,,
374.548,0.39599,0.84458,10,,,,,,,,,,,,,,,,,,,,,,,,,,,,,,,,,,,,,
375.348,0.39621,0.84828,10,,,,,,,,,,,,,,,,,,,,,,,,,,,,,,,,,,,,,
376.148,0.39655,0.80889,10,,,,,,,,,,,,,,,,,,,,,,,,,,,,,,,,,,,,,
376.948,0.39723,0.86066,10,,,,,,,,,,,,,,,,,,,,,,,,,,,,,,,,,,,,,
377.748,0.39825,0.92039,10,,,,,,,,,,,,,,,,,,,,,,,,,,,,,,,,,,,,,
378.548,0.40029,0.89026,10,,,,,,,,,,,,,,,,,,,,,,,,,,,,,,,,,,,,,
379.348,0.40194,0.86689,10,,,,,,,,,,,,,,,,,,,,,,,,,,,,,,,,,,,,,
380.148,0.4033,0.90453,10,,,,,,,,,,,,,,,,,,,,,,,,,,,,,,,,,,,,,
380.948,0.40381,0.9061,10,,,,,,,,,,,,,,,,,,,,,,,,,,,,,,,,,,,,,
381.748,0.40386,1.00273,10,,,,,,,,,,,,,,,,,,,,,,,,,,,,,,,,,,,,,
382.548,0.40375,0.93792,10,,,,,,,,,,,,,,,,,,,,,,,,,,,,,,,,,,,,,
383.348,0.40369,0.91325,10,,,,,,,,,,,,,,,,,,,,,,,,,,,,,,,,,,,,,
384.148,0.40358,0.94468,10,,,,,,,,,,,,,,,,,,,,,,,,,,,,,,,,,,,,,
384.948,0.40341,0.90235,10,,,,,,,,,,,,,,,,,,,,,,,,,,,,,,,,,,,,,
385.748,0.40324,0.92183,10,,,,,,,,,,,,,,,,,,,,,,,,,,,,,,,,,,,,,
386.548,0.40279,0.9697,10,,,,,,,,,,,,,,,,,,,,,,,,,,,,,,,,,,,,,
387.348,0.40205,0.92914,10,,,,,,,,,,,,,,,,,,,,,,,,,,,,,,,,,,,,,
388.148,0.4008,0.93161,10,,,,,,,,,,,,,,,,,,,,,,,,,,,,,,,,,,,,,
388.948,0.39893,0.88855,10,,,,,,,,,,,,,,,,,,,,,,,,,,,,,,,,,,,,,
389.748,0.39718,0.91058,10,,,,,,,,,,,,,,,,,,,,,,,,,,,,,,,,,,,,,
390.548,0.39616,0.90591,10,,,,,,,,,,,,,,,,,,,,,,,,,,,,,,,,,,,,,
391.348,0.39548,0.89761,10,,,,,,,,,,,,,,,,,,,,,,,,,,,,,,,,,,,,,
392.148,0.39497,0.92336,10,,,,,,,,,,,,,,,,,,,,,,,,,,,,,,,,,,,,,
392.948,0.39468,0.8822,10,,,,,,,,,,,,,,,,,,,,,,,,,,,,,,,,,,,,,
393.748,0.39463,0.86552,10,,,,,,,,,,,,,,,,,,,,,,,,,,,,,,,,,,,,,
394.548,0.39468,0.91283,10,,,,,,,,,,,,,,,,,,,,,,,,,,,,,,,,,,,,,
395.348,0.39474,0.84029,10,,,,,,,,,,,,,,,,,,,,,,,,,,,,,,,,,,,,,
396.148,0.3948,0.85917,10,,,,,,,,,,,,,,,,,,,,,,,,,,,,,,,,,,,,,
396.948,0.39485,0.88434,10,,,,,,,,,,,,,,,,,,,,,,,,,,,,,,,,,,,,,
397.748,0.39497,0.86341,10,,,,,,,,,,,,,,,,,,,,,,,,,,,,,,,,,,,,,
398.548,0.39508,0.85167,10,,,,,,,,,,,,,,,,,,,,,,,,,,,,,,,,,,,,,
399.348,0.39531,0.83948,10,,,,,,,,,,,,,,,,,,,,,,,,,,,,,,,,,,,,,
400.148,0.39565,0.90792,10,,,,,,,,,,,,,,,,,,,,,,,,,,,,,,,,,,,,,
400.948,0.39582,0.80346,10,,,,,,,,,,,,,,,,,,,,,,,,,,,,,,,,,,,,,
401.748,0.39638,0.83697,10,,,,,,,,,,,,,,,,,,,,,,,,,,,,,,,,,,,,,
402.548,0.3978,0.82745,10,,,,,,,,,,,,,,,,,,,,,,,,,,,,,,,,,,,,,
403.348,0.3999,0.86037,10,,,,,,,,,,,,,,,,,,,,,,,,,,,,,,,,,,,,,
404.148,0.40148,0.89553,10,,,,,,,,,,,,,,,,,,,,,,,,,,,,,,,,,,,,,
404.948,0.4025,0.8721,10,,,,,,,,,,,,,,,,,,,,,,,,,,,,,,,,,,,,,
405.748,0.40301,0.93,10,,,,,,,,,,,,,,,,,,,,,,,,,,,,,,,,,,,,,
406.548,0.4033,0.98072,10,,,,,,,,,,,,,,,,,,,,,,,,,,,,,,,,,,,,,
407.348,0.4033,0.90926,10,,,,,,,,,,,,,,,,,,,,,,,,,,,,,,,,,,,,,
408.148,0.40318,0.89824,10,,,,,,,,,,,,,,,,,,,,,,,,,,,,,,,,,,,,,
408.948,0.40313,0.89865,10,,,,,,,,,,,,,,,,,,,,,,,,,,,,,,,,,,,,,
409.748,0.40307,0.9355,10,,,,,,,,,,,,,,,,,,,,,,,,,,,,,,,,,,,,,
410.548,0.40296,0.89153,10,,,,,,,,,,,,,,,,,,,,,,,,,,,,,,,,,,,,,
411.348,0.40284,0.90058,10,,,,,,,,,,,,,,,,,,,,,,,,,,,,,,,,,,,,,
412.148,0.40267,0.92933,10,,,,,,,,,,,,,,,,,,,,,,,,,,,,,,,,,,,,,
412.948,0.40205,0.92689,10,,,,,,,,,,,,,,,,,,,,,,,,,,,,,,,,,,,,,
413.748,0.40052,1.01657,10,,,,,,,,,,,,,,,,,,,,,,,,,,,,,,,,,,,,,
414.548,0.39859,0.9086,10,,,,,,,,,,,,,,,,,,,,,,,,,,,,,,,,,,,,,
415.348,0.39661,0.94732,10,,,,,,,,,,,,,,,,,,,,,,,,,,,,,,,,,,,,,
416.148,0.39497,0.92847,10,,,,,,,,,,,,,,,,,,,,,,,,,,,,,,,,,,,,,
416.948,0.39304,0.90992,10,,,,,,,,,,,,,,,,,,,,,,,,,,,,,,,,,,,,,
417.748,0.39162,0.88659,10,,,,,,,,,,,,,,,,,,,,,,,,,,,,,,,,,,,,,
418.548,0.39134,0.89538,10,,,,,,,,,,,,,,,,,,,,,,,,,,,,,,,,,,,,,
419.348,0.3914,0.8553,10,,,,,,,,,,,,,,,,,,,,,,,,,,,,,,,,,,,,,
420.148,0.3914,0.81459,10,,,,,,,,,,,,,,,,,,,,,,,,,,,,,,,,,,,,,
420.948,0.39157,0.79881,10,,,,,,,,,,,,,,,,,,,,,,,,,,,,,,,,,,,,,
421.748,0.39168,0.85447,10,,,,,,,,,,,,,,,,,,,,,,,,,,,,,,,,,,,,,
422.548,0.39191,0.826,10,,,,,,,,,,,,,,,,,,,,,,,,,,,,,,,,,,,,,
423.348,0.39259,0.81813,10,,,,,,,,,,,,,,,,,,,,,,,,,,,,,,,,,,,,,
424.148,0.39491,0.85692,10,,,,,,,,,,,,,,,,,,,,,,,,,,,,,,,,,,,,,
424.948,0.39865,0.86014,10,,,,,,,,,,,,,,,,,,,,,,,,,,,,,,,,,,,,,
425.748,0.40262,0.91928,10,,,,,,,,,,,,,,,,,,,,,,,,,,,,,,,,,,,,,
426.548,0.40386,0.87187,10,,,,,,,,,,,,,,,,,,,,,,,,,,,,,,,,,,,,,
427.348,0.40415,0.89236,10,,,,,,,,,,,,,,,,,,,,,,,,,,,,,,,,,,,,,
428.148,0.40409,0.9586,10,,,,,,,,,,,,,,,,,,,,,,,,,,,,,,,,,,,,,
428.948,0.40403,0.93002,10,,,,,,,,,,,,,,,,,,,,,,,,,,,,,,,,,,,,,
429.748,0.40392,0.91416,10,,,,,,,,,,,,,,,,,,,,,,,,,,,,,,,,,,,,,
430.548,0.40381,0.95726,10,,,,,,,,,,,,,,,,,,,,,,,,,,,,,,,,,,,,,
431.348,0.40364,0.95734,10,,,,,,,,,,,,,,,,,,,,,,,,,,,,,,,,,,,,,
432.148,0.40256,1.0328,10,,,,,,,,,,,,,,,,,,,,,,,,,,,,,,,,,,,,,
432.948,0.40109,0.95909,10,,,,,,,,,,,,,,,,,,,,,,,,,,,,,,,,,,,,,
433.748,0.39825,0.92213,10,,,,,,,,,,,,,,,,,,,,,,,,,,,,,,,,,,,,,
434.548,0.39599,0.90122,10,,,,,,,,,,,,,,,,,,,,,,,,,,,,,,,,,,,,,
435.348,0.39497,0.8796,10,,,,,,,,,,,,,,,,,,,,,,,,,,,,,,,,,,,,,
436.148,0.39429,0.88261,10,,,,,,,,,,,,,,,,,,,,,,,,,,,,,,,,,,,,,
436.948,0.39395,0.86266,10,,,,,,,,,,,,,,,,,,,,,,,,,,,,,,,,,,,,,
437.748,0.39366,0.92189,10,,,,,,,,,,,,,,,,,,,,,,,,,,,,,,,,,,,,,
438.548,0.39361,0.84303,10,,,,,,,,,,,,,,,,,,,,,,,,,,,,,,,,,,,,,
439.348,0.39355,0.8901,10,,,,,,,,,,,,,,,,,,,,,,,,,,,,,,,,,,,,,
440.148,0.39366,0.96169,10,,,,,,,,,,,,,,,,,,,,,,,,,,,,,,,,,,,,,
440.948,0.39372,0.86176,10,,,,,,,,,,,,,,,,,,,,,,,,,,,,,,,,,,,,,
441.748,0.39378,0.85571,10,,,,,,,,,,,,,,,,,,,,,,,,,,,,,,,,,,,,,
442.548,0.39383,0.87329,10,,,,,,,,,,,,,,,,,,,,,,,,,,,,,,,,,,,,,
443.348,0.39389,0.85977,10,,,,,,,,,,,,,,,,,,,,,,,,,,,,,,,,,,,,,
444.148,0.39406,0.85543,10,,,,,,,,,,,,,,,,,,,,,,,,,,,,,,,,,,,,,
444.948,0.39417,0.9027,10,,,,,,,,,,,,,,,,,,,,,,,,,,,,,,,,,,,,,
445.748,0.39457,0.85898,10,,,,,,,,,,,,,,,,,,,,,,,,,,,,,,,,,,,,,
446.548,0.39508,0.81239,10,,,,,,,,,,,,,,,,,,,,,,,,,,,,,,,,,,,,,
447.348,0.39633,0.85388,10,,,,,,,,,,,,,,,,,,,,,,,,,,,,,,,,,,,,,
448.148,0.39854,0.88445,10,,,,,,,,,,,,,,,,,,,,,,,,,,,,,,,,,,,,,
448.948,0.40137,0.87191,10,,,,,,,,,,,,,,,,,,,,,,,,,,,,,,,,,,,,,
449.748,0.40199,0.92443,10,,,,,,,,,,,,,,,,,,,,,,,,,,,,,,,,,,,,,
450.548,0.40216,0.95328,10,,,,,,,,,,,,,,,,,,,,,,,,,,,,,,,,,,,,,
451.348,0.40199,0.9266,10,,,,,,,,,,,,,,,,,,,,,,,,,,,,,,,,,,,,,
452.148,0.40199,1.00539,10,,,,,,,,,,,,,,,,,,,,,,,,,,,,,,,,,,,,,
452.948,0.40194,0.87296,10,,,,,,,,,,,,,,,,,,,,,,,,,,,,,,,,,,,,,
453.748,0.40182,0.93453,10,,,,,,,,,,,,,,,,,,,,,,,,,,,,,,,,,,,,,
454.548,0.40177,0.9405,10,,,,,,,,,,,,,,,,,,,,,,,,,,,,,,,,,,,,,
455.348,0.40171,0.93256,10,,,,,,,,,,,,,,,,,,,,,,,,,,,,,,,,,,,,,
456.148,0.4016,0.90755,10,,,,,,,,,,,,,,,,,,,,,,,,,,,,,,,,,,,,,
456.948,0.40143,1.00131,10,,,,,,,,,,,,,,,,,,,,,,,,,,,,,,,,,,,,,
457.748,0.4008,0.99051,10,,,,,,,,,,,,,,,,,,,,,,,,,,,,,,,,,,,,,
458.548,0.39973,0.94768,10,,,,,,,,,,,,,,,,,,,,,,,,,,,,,,,,,,,,,
459.348,0.39837,0.88968,10,,,,,,,,,,,,,,,,,,,,,,,,,,,,,,,,,,,,,
460.148,0.3974,0.92808,10,,,,,,,,,,,,,,,,,,,,,,,,,,,,,,,,,,,,,
460.948,0.39644,0.92004,10,,,,,,,,,,,,,,,,,,,,,,,,,,,,,,,,,,,,,
461.748,0.39582,0.92041,10,,,,,,,,,,,,,,,,,,,,,,,,,,,,,,,,,,,,,
462.548,0.39514,0.88821,10,,,,,,,,,,,,,,,,,,,,,,,,,,,,,,,,,,,,,
463.348,0.39474,0.86272,10,,,,,,,,,,,,,,,,,,,,,,,,,,,,,,,,,,,,,
464.148,0.39446,0.92206,10,,,,,,,,,,,,,,,,,,,,,,,,,,,,,,,,,,,,,
464.948,0.39429,0.84417,10,,,,,,,,,,,,,,,,,,,,,,,,,,,,,,,,,,,,,
465.748,0.39429,0.93437,10,,,,,,,,,,,,,,,,,,,,,,,,,,,,,,,,,,,,,
466.548,0.3944,0.93634,10,,,,,,,,,,,,,,,,,,,,,,,,,,,,,,,,,,,,,
467.348,0.39446,0.90003,10,,,,,,,,,,,,,,,,,,,,,,,,,,,,,,,,,,,,,
468.148,0.39451,0.83734,10,,,,,,,,,,,,,,,,,,,,,,,,,,,,,,,,,,,,,
468.948,0.39463,0.89868,10,,,,,,,,,,,,,,,,,,,,,,,,,,,,,,,,,,,,,
469.748,0.39468,0.84074,10,,,,,,,,,,,,,,,,,,,,,,,,,,,,,,,,,,,,,
470.548,0.3948,0.85726,10,,,,,,,,,,,,,,,,,,,,,,,,,,,,,,,,,,,,,
471.348,0.39497,0.84781,10,,,,,,,,,,,,,,,,,,,,,,,,,,,,,,,,,,,,,
472.148,0.39542,0.8339,10,,,,,,,,,,,,,,,,,,,,,,,,,,,,,,,,,,,,,
472.948,0.39621,0.82501,10,,,,,,,,,,,,,,,,,,,,,,,,,,,,,,,,,,,,,
473.748,0.39763,0.88109,10,,,,,,,,,,,,,,,,,,,,,,,,,,,,,,,,,,,,,
474.548,0.40012,0.86702,10,,,,,,,,,,,,,,,,,,,,,,,,,,,,,,,,,,,,,
475.348,0.40182,0.93249,10,,,,,,,,,,,,,,,,,,,,,,,,,,,,,,,,,,,,,
476.148,0.40284,0.90259,10,,,,,,,,,,,,,,,,,,,,,,,,,,,,,,,,,,,,,
476.948,0.40335,0.92128,10,,,,,,,,,,,,,,,,,,,,,,,,,,,,,,,,,,,,,
477.748,0.40352,0.93666,10,,,,,,,,,,,,,,,,,,,,,,,,,,,,,,,,,,,,,
478.548,0.40341,0.94628,10,,,,,,,,,,,,,,,,,,,,,,,,,,,,,,,,,,,,,
479.348,0.40335,0.93457,10,,,,,,,,,,,,,,,,,,,,,,,,,,,,,,,,,,,,,
480.148,0.40324,0.92659,10,,,,,,,,,,,,,,,,,,,,,,,,,,,,,,,,,,,,,
480.948,0.40301,0.92298,10,,,,,,,,,,,,,,,,,,,,,,,,,,,,,,,,,,,,,
481.748,0.40267,0.96987,10,,,,,,,,,,,,,,,,,,,,,,,,,,,,,,,,,,,,,
482.548,0.40165,0.94666,10,,,,,,,,,,,,,,,,,,,,,,,,,,,,,,,,,,,,,
483.348,0.40041,0.91527,10,,,,,,,,,,,,,,,,,,,,,,,,,,,,,,,,,,,,,
484.148,0.39859,0.89214,10,,,,,,,,,,,,,,,,,,,,,,,,,,,,,,,,,,,,,
484.948,0.39729,0.88888,10,,,,,,,,,,,,,,,,,,,,,,,,,,,,,,,,,,,,,
485.748,0.39633,0.90937,10,,,,,,,,,,,,,,,,,,,,,,,,,,,,,,,,,,,,,
486.548,0.39565,0.92843,10,,,,,,,,,,,,,,,,,,,,,,,,,,,,,,,,,,,,,
487.348,0.39497,0.8702,10,,,,,,,,,,,,,,,,,,,,,,,,,,,,,,,,,,,,,
488.148,0.39468,0.92855,10,,,,,,,,,,,,,,,,,,,,,,,,,,,,,,,,,,,,,
488.948,0.39457,0.81833,10,,,,,,,,,,,,,,,,,,,,,,,,,,,,,,,,,,,,,
489.748,0.39468,0.86086,10,,,,,,,,,,,,,,,,,,,,,,,,,,,,,,,,,,,,,
490.548,0.39474,0.89201,10,,,,,,,,,,,,,,,,,,,,,,,,,,,,,,,,,,,,,
491.348,0.3948,0.85257,10,,,,,,,,,,,,,,,,,,,,,,,,,,,,,,,,,,,,,
492.148,0.39474,0.84151,10,,,,,,,,,,,,,,,,,,,,,,,,,,,,,,,,,,,,,
492.948,0.39491,0.87936,10,,,,,,,,,,,,,,,,,,,,,,,,,,,,,,,,,,,,,
493.748,0.39508,0.8299,10,,,,,,,,,,,,,,,,,,,,,,,,,,,,,,,,,,,,,
494.548,0.39531,0.81515,10,,,,,,,,,,,,,,,,,,,,,,,,,,,,,,,,,,,,,
495.348,0.39576,0.85391,10,,,,,,,,,,,,,,,,,,,,,,,,,,,,,,,,,,,,,
496.148,0.39655,0.83701,10,,,,,,,,,,,,,,,,,,,,,,,,,,,,,,,,,,,,,
496.948,0.39808,0.83674,10,,,,,,,,,,,,,,,,,,,,,,,,,,,,,,,,,,,,,
497.748,0.40092,0.91062,10,,,,,,,,,,,,,,,,,,,,,,,,,,,,,,,,,,,,,
498.548,0.40296,0.92107,10,,,,,,,,,,,,,,,,,,,,,,,,,,,,,,,,,,,,,
499.348,0.40347,0.91348,10,,,,,,,,,,,,,,,,,,,,,,,,,,,,,,,,,,,,,
500.148,0.40364,0.98325,10,,,,,,,,,,,,,,,,,,,,,,,,,,,,,,,,,,,,,
500.948,0.40358,0.95643,10,,,,,,,,,,,,,,,,,,,,,,,,,,,,,,,,,,,,,
501.748,0.40347,0.95216,10,,,,,,,,,,,,,,,,,,,,,,,,,,,,,,,,,,,,,
502.548,0.40335,0.97934,10,,,,,,,,,,,,,,,,,,,,,,,,,,,,,,,,,,,,,
503.348,0.4033,0.91137,10,,,,,,,,,,,,,,,,,,,,,,,,,,,,,,,,,,,,,
504.148,0.40324,0.95168,10,,,,,,,,,,,,,,,,,,,,,,,,,,,,,,,,,,,,,
504.948,0.40324,0.94811,10,,,,,,,,,,,,,,,,,,,,,,,,,,,,,,,,,,,,,
505.748,0.40307,0.94189,10,,,,,,,,,,,,,,,,,,,,,,,,,,,,,,,,,,,,,
506.548,0.40267,0.89231,10,,,,,,,,,,,,,,,,,,,,,,,,,,,,,,,,,,,,,
507.348,0.40171,0.96833,10,,,,,,,,,,,,,,,,,,,,,,,,,,,,,,,,,,,,,
508.148,0.40018,0.93833,10,,,,,,,,,,,,,,,,,,,,,,,,,,,,,,,,,,,,,
508.948,0.39859,0.90688,10,,,,,,,,,,,,,,,,,,,,,,,,,,,,,,,,,,,,,
509.748,0.39695,0.96784,10,,,,,,,,,,,,,,,,,,,,,,,,,,,,,,,,,,,,,
510.548,0.39599,0.85529,10,,,,,,,,,,,,,,,,,,,,,,,,,,,,,,,,,,,,,
511.348,0.39542,0.86883,10,,,,,,,,,,,,,,,,,,,,,,,,,,,,,,,,,,,,,
512.148,0.39514,0.94388,10,,,,,,,,,,,,,,,,,,,,,,,,,,,,,,,,,,,,,
512.948,0.39491,0.86334,10,,,,,,,,,,,,,,,,,,,,,,,,,,,,,,,,,,,,,
513.748,0.39485,0.88689,10,,,,,,,,,,,,,,,,,,,,,,,,,,,,,,,,,,,,,
514.548,0.39502,0.86569,10,,,,,,,,,,,,,,,,,,,,,,,,,,,,,,,,,,,,,
515.348,0.39508,0.81992,10,,,,,,,,,,,,,,,,,,,,,,,,,,,,,,,,,,,,,
516.148,0.39514,0.85163,10,,,,,,,,,,,,,,,,,,,,,,,,,,,,,,,,,,,,,
516.948,0.39508,0.88764,10,,,,,,,,,,,,,,,,,,,,,,,,,,,,,,,,,,,,,
517.748,0.39531,0.89872,10,,,,,,,,,,,,,,,,,,,,,,,,,,,,,,,,,,,,,
518.548,0.39548,0.85181,10,,,,,,,,,,,,,,,,,,,,,,,,,,,,,,,,,,,,,
519.348,0.39576,0.83923,10,,,,,,,,,,,,,,,,,,,,,,,,,,,,,,,,,,,,,
520.148,0.39621,0.82524,10,,,,,,,,,,,,,,,,,,,,,,,,,,,,,,,,,,,,,
520.948,0.39723,0.84713,10,,,,,,,,,,,,,,,,,,,,,,,,,,,,,,,,,,,,,
521.748,0.39905,0.90177,10,,,,,,,,,,,,,,,,,,,,,,,,,,,,,,,,,,,,,
522.548,0.40182,0.91205,10,,,,,,,,,,,,,,,,,,,,,,,,,,,,,,,,,,,,,
523.348,0.40324,0.92526,10,,,,,,,,,,,,,,,,,,,,,,,,,,,,,,,,,,,,,
524.148,0.40352,0.97534,10,,,,,,,,,,,,,,,,,,,,,,,,,,,,,,,,,,,,,
524.948,0.40341,0.90972,10,,,,,,,,,,,,,,,,,,,,,,,,,,,,,,,,,,,,,
525.748,0.40341,0.96423,10,,,,,,,,,,,,,,,,,,,,,,,,,,,,,,,,,,,,,
526.548,0.40324,0.94928,10,,,,,,,,,,,,,,,,,,,,,,,,,,,,,,,,,,,,,
527.348,0.40318,0.96805,10,,,,,,,,,,,,,,,,,,,,,,,,,,,,,,,,,,,,,
528.05,2.56881,43.14571,10,,,,,,,,,,,,,,,,,,,,,,,,,,,,,,,,,,,,,
528.85,9.23667,183.4035,10,,,,,,,,,,,,,,,,,,,,,,,,,,,,,,,,,,,,,
529.65,15.9031,43.19605,10,,,,,,,,,,,,,,,,,,,,,,,,,,,,,,,,,,,,,
530.45,22.56977,15.20988,10,,,,,,,,,,,,,,,,,,,,,,,,,,,,,,,,,,,,,
531.25,29.23654,7.51555,10,,,,,,,,,,,,,,,,,,,,,,,,,,,,,,,,,,,,,
532.05,35.90303,5.34821,10,,,,,,,,,,,,,,,,,,,,,,,,,,,,,,,,,,,,,
532.85,42.5697,2.39891,10,,,,,,,,,,,,,,,,,,,,,,,,,,,,,,,,,,,,,
533.65,49.23647,0.99038,10,,,,,,,,,,,,,,,,,,,,,,,,,,,,,,,,,,,,,
534.45,55.90314,-0.47788,10,,,,,,,,,,,,,,,,,,,,,,,,,,,,,,,,,,,,,
535.25,62.56974,-0.52864,10,,,,,,,,,,,,,,,,,,,,,,,,,,,,,,,,,,,,,
536.05,69.2364,-0.81876,10,,,,,,,,,,,,,,,,,,,,,,,,,,,,,,,,,,,,,
536.85,75.90312,-0.91624,10,,,,,,,,,,,,,,,,,,,,,,,,,,,,,,,,,,,,,
537.65,82.56973,-1.03645,10,,,,,,,,,,,,,,,,,,,,,,,,,,,,,,,,,,,,,
538.45,89.23645,-1.66838,10,,,,,,,,,,,,,,,,,,,,,,,,,,,,,,,,,,,,,
539.25,95.90317,-1.69175,10,,,,,,,,,,,,,,,,,,,,,,,,,,,,,,,,,,,,,
540.05,102.56973,-1.72033,10,,,,,,,,,,,,,,,,,,,,,,,,,,,,,,,,,,,,,
540.644,107.51973,-1.74204,10,,,,,,,,,,,,,,,,,,,,,,,,,,,,,,,,,,,,,