File: combined_ligament_solver/data/processed/Data Sheet 3_S151568_MCL.csv
Specimen properties : Length,101,mm,Unnamed: 3,Unnamed: 4,Unnamed: 5,Unnamed: 6,Unnamed: 7,Unnamed: 8,Unnamed: 9,Unnamed: 10,Unnamed: 11,Stress-Strain,Unnamed: 13,Unnamed: 14,Unnamed: 15,Unnamed: 16,Unnamed: 17,Unnamed: 18,Unnamed: 19,Unnamed: 20,Unnamed: 21,Unnamed: 22,Unnamed: 23,Unnamed: 24,Unnamed: 25,Unnamed: 26,Unnamed: 27,Linear,Unnamed: 29,Unnamed: 30,Unnamed: 31,Unnamed: 32,Unnamed: 33,Modulus,Unnamed: 35,Failure,Unnamed: 37,Unnamed: 38,Unnamed: 39,Unnamed: 40
Cross Section Average,22.371000000000002,mm2,,,,,,,,,,Polynomial Coefficients,,,,,,,,,,,,,,,,Force,,Stress,Extension,Strain,,Secant,Tangent,Load,Stress,Extension,Strain,Stiffness
Time,Extension,Load,Total cycle count,,,Extension,Load,Strain,Stress,E-tan,,X6,,,,,,,,,,Strain,Stress,E-tan,,,,(N),,(MPa),(mm),(%),,(MPa),(MPa),(N),(MPa),(mm),(%),(N/mm)
(s),(mm),(N),,,,(mm),(N),(mm/mm),(MPa),(MPa),,X5,,,,,,,,,,(mm/mm),(MPa),(MPa),,,,,,,,,,,,,,0,,
0,0.26237,1.17046,0,,,0,0,0,0,,,X4,,,,,,,,,,0,,,,,,,,,,,,,,,,,,
0.1,0.27053,1.08014,0,,,0,0,0,0,,,X3,,,,,,,,,,0.001,,,,,,,,,,,,,,,,,,
0.2,0.28719,1.206,0,,,,,,,,,X2,,,,,,,,,,0.002,,,,,,,,,,,,,,,,,,
0.3,0.3039,1.22727,0,,,,,,,,,X1,,,,,,,,,,0.003,,,,,,,,,,,,,,,,,,
0.4,0.32045,1.27692,0,,,,,,,,,,,,,,,,,,,0.004,,,,,,,,,,,,,,,,,,
0.5,0.33739,1.34989,0,,,,,,,,,,,,,,,,,,,0.005,,,,,,,,,,,,,,,,,,
0.6,0.35388,1.43468,0,,,,,,,,,,,,,,,,,,,0.006,,,,,,,,,,,,,,,,,,
0.7,0.37054,1.47586,0,,,,,,,,,,,,,,,,,,,0.007,,,,,,,,,,,,,,,,,,
0.8,0.38726,1.53142,0,,,,,,,,,,,,,,,,,,,0.008,,,,,,,,,,,,,,,,,,
0.9,0.40392,1.63714,0,,,,,,,,,,,,,,,,,,,0.009,,,,,,,,,,,,,,,,,,
1,0.42052,1.73022,0,,,,,,,,,,,,,,,,,,,0.01,,,,,,,,,,,,,,,,,,
1.1,0.43724,1.80614,0,,,,,,,,,,,,,,,,,,,0.011,,,,,,,,,,,,,,,,,,
1.2,0.45407,1.86292,0,,,,,,,,,,,,,,,,,,,0.012,,,,,,,,,,,,,,,,,,
1.3,0.4705,1.94155,0,,,,,,,,,,,,,,,,,,,0.013,,,,,,,,,,,,,,,,,,
1.4,0.48711,2.03894,0,,,,,,,,,,,,,,,,,,,0.014,,,,,,,,,,,,,,,,,,
1.5,0.50399,2.05189,0,,,,,,,,,,,,,,,,,,,0.015,,,,,,,,,,,,,,,,,,
1.6,0.5206,2.15287,0,,,,,,,,,,,,,,,,,,,0.016,,,,,,,,,,,,,,,,,,
1.7,0.53714,2.18457,0,,,,,,,,,,,,,,,,,,,0.017,,,,,,,,,,,,,,,,,,
1.8,0.55392,2.29806,0,,,,,,,,,,,,,,,,,,,0.018,,,,,,,,,,,,,,,,,,
1.9,0.57063,2.43839,0,,,,,,,,,,,,,,,,,,,0.019,,,,,,,,,,,,,,,,,,
2,0.58729,2.49462,0,,,,,,,,,,,,,,,,,,,0.02,,,,,,,,,,,,,,,,,,
2.1,0.60384,2.52041,0,,,,,,,,,,,,,,,,,,,0.021,,,,,,,,,,,,,,,,,,
2.2,0.62067,2.5763,0,,,,,,,,,,,,,,,,,,,0.022,,,,,,,,,,,,,,,,,,
2.3,0.63722,2.6367,0,,,,,,,,,,,,,,,,,,,0.023,,,,,,,,,,,,,,,,,,
2.4,0.65382,2.70452,0,,,,,,,,,,,,,,,,,,,0.024,,,,,,,,,,,,,,,,,,
2.5,0.67059,2.76181,0,,,,,,,,,,,,,,,,,,,0.025,,,,,,,,,,,,,,,,,,
2.6,0.68725,2.83576,0,,,,,,,,,,,,,,,,,,,0.026,,,,,,,,,,,,,,,,,,
2.7,0.70397,2.86575,0,,,,,,,,,,,,,,,,,,,0.027,,,,,,,,,,,,,,,,,,
2.8,0.72046,2.99627,0,,,,,,,,,,,,,,,,,,,0.028,,,,,,,,,,,,,,,,,,
2.9,0.73735,2.99711,0,,,,,,,,,,,,,,,,,,,0.029,,,,,,,,,,,,,,,,,,
3,0.75384,3.08368,0,,,,,,,,,,,,,,,,,,,0.03,,,,,,,,,,,,,,,,,,
3.1,0.77061,3.18938,0,,,,,,,,,,,,,,,,,,,0.031,,,,,,,,,,,,,,,,,,
3.2,0.78733,3.22008,0,,,,,,,,,,,,,,,,,,,0.032,,,,,,,,,,,,,,,,,,
3.3,0.80387,3.26216,0,,,,,,,,,,,,,,,,,,,0.033,,,,,,,,,,,,,,,,,,
3.4,0.82059,3.32491,0,,,,,,,,,,,,,,,,,,,0.034,,,,,,,,,,,,,,,,,,
3.5,0.83725,3.38027,0,,,,,,,,,,,,,,,,,,,0.035,,,,,,,,,,,,,,,,,,
3.6,0.85391,3.44097,0,,,,,,,,,,,,,,,,,,,0.036,,,,,,,,,,,,,,,,,,
3.7,0.87051,3.46395,0,,,,,,,,,,,,,,,,,,,0.037,,,,,,,,,,,,,,,,,,
3.8,0.88723,3.53359,0,,,,,,,,,,,,,,,,,,,0.038,,,,,,,,,,,,,,,,,,
3.9,0.90395,3.58737,0,,,,,,,,,,,,,,,,,,,0.039,,,,,,,,,,,,,,,,,,
4,0.92061,3.70611,0,,,,,,,,,,,,,,,,,,,0.04,,,,,,,,,,,,,,,,,,
4.1,0.93715,3.68107,0,,,,,,,,,,,,,,,,,,,0.041,,,,,,,,,,,,,,,,,,
4.2,0.95398,3.76611,0,,,,,,,,,,,,,,,,,,,0.042,,,,,,,,,,,,,,,,,,
4.3,0.97059,3.76824,0,,,,,,,,,,,,,,,,,,,0.043,,,,,,,,,,,,,,,,,,
4.4,0.98725,3.83422,0,,,,,,,,,,,,,,,,,,,0.044,,,,,,,,,,,,,,,,,,
4.5,1.00391,3.84235,0,,,,,,,,,,,,,,,,,,,0.045,,,,,,,,,,,,,,,,,,
4.6,1.02068,3.87439,0,,,,,,,,,,,,,,,,,,,0.046,,,,,,,,,,,,,,,,,,
4.7,1.03728,3.94836,0,,,,,,,,,,,,,,,,,,,0.047,,,,,,,,,,,,,,,,,,
4.8,1.05377,3.93139,0,,,,,,,,,,,,,,,,,,,0.048,,,,,,,,,,,,,,,,,,
4.9,1.07072,4.00944,0,,,,,,,,,,,,,,,,,,,0.049,,,,,,,,,,,,,,,,,,
5,1.08721,4.01468,0,,,,,,,,,,,,,,,,,,,0.05,,,,,,,,,,,,,,,,,,
5.1,1.10392,4.08643,0,,,,,,,,,,,,,,,,,,,0.051,,,,,,,,,,,,,,,,,,
5.2,1.12053,4.13026,0,,,,,,,,,,,,,,,,,,,0.052,,,,,,,,,,,,,,,,,,
5.3,1.13741,4.21778,0,,,,,,,,,,,,,,,,,,,0.053,,,,,,,,,,,,,,,,,,
5.4,1.15385,4.1918,0,,,,,,,,,,,,,,,,,,,0.054,,,,,,,,,,,,,,,,,,
5.5,1.17051,4.21021,0,,,,,,,,,,,,,,,,,,,0.055,,,,,,,,,,,,,,,,,,
5.6,1.18739,4.2367,0,,,,,,,,,,,,,,,,,,,0.056,,,,,,,,,,,,,,,,,,
5.7,1.20394,4.21973,0,,,,,,,,,,,,,,,,,,,0.057,,,,,,,,,,,,,,,,,,
5.8,1.22049,4.30951,0,,,,,,,,,,,,,,,,,,,0.058,,,,,,,,,,,,,,,,,,
5.9,1.23726,4.25883,0,,,,,,,,,,,,,,,,,,,0.059,,,,,,,,,,,,,,,,,,
6,1.25403,4.26328,0,,,,,,,,,,,,,,,,,,,0.06,,,,,,,,,,,,,,,,,,
6.1,1.27052,4.30305,0,,,,,,,,,,,,,,,,,,,0.061,,,,,,,,,,,,,,,,,,
6.2,1.28724,4.31207,0,,,,,,,,,,,,,,,,,,,0.062,,,,,,,,,,,,,,,,,,
6.3,1.30396,4.30074,0,,,,,,,,,,,,,,,,,,,0.063,,,,,,,,,,,,,,,,,,
6.4,1.32062,4.30531,0,,,,,,,,,,,,,,,,,,,0.064,,,,,,,,,,,,,,,,,,
6.5,1.33716,4.37198,0,,,,,,,,,,,,,,,,,,,0.065,,,,,,,,,,,,,,,,,,
6.6,1.35399,4.33116,0,,,,,,,,,,,,,,,,,,,0.066,,,,,,,,,,,,,,,,,,
6.7,1.37054,4.38575,0,,,,,,,,,,,,,,,,,,,0.067,,,,,,,,,,,,,,,,,,
6.8,1.3872,4.42088,0,,,,,,,,,,,,,,,,,,,0.068,,,,,,,,,,,,,,,,,,
6.9,1.40392,4.41085,0,,,,,,,,,,,,,,,,,,,0.069,,,,,,,,,,,,,,,,,,
7,1.42058,4.42198,0,,,,,,,,,,,,,,,,,,,0.07,,,,,,,,,,,,,,,,,,
7.1,1.43724,4.41143,0,,,,,,,,,,,,,,,,,,,0.071,,,,,,,,,,,,,,,,,,
7.2,1.45384,4.4303,0,,,,,,,,,,,,,,,,,,,0.072,,,,,,,,,,,,,,,,,,
7.3,1.47073,4.4013,0,,,,,,,,,,,,,,,,,,,0.073,,,,,,,,,,,,,,,,,,
7.4,1.48716,4.38888,0,,,,,,,,,,,,,,,,,,,0.074,,,,,,,,,,,,,,,,,,
7.5,1.50393,4.40781,0,,,,,,,,,,,,,,,,,,,0.075,,,,,,,,,,,,,,,,,,
7.6,1.52065,4.39725,0,,,,,,,,,,,,,,,,,,,0.076,,,,,,,,,,,,,,,,,,
7.7,1.53725,4.38117,0,,,,,,,,,,,,,,,,,,,0.077,,,,,,,,,,,,,,,,,,
7.8,1.55386,4.45734,0,,,,,,,,,,,,,,,,,,,0.078,,,,,,,,,,,,,,,,,,
7.9,1.57057,4.4174,0,,,,,,,,,,,,,,,,,,,0.079,,,,,,,,,,,,,,,,,,
8,1.58735,4.42221,0,,,,,,,,,,,,,,,,,,,0.08,,,,,,,,,,,,,,,,,,
8.1,1.60378,4.4208,0,,,,,,,,,,,,,,,,,,,0.081,,,,,,,,,,,,,,,,,,
8.2,1.6205,4.4244,0,,,,,,,,,,,,,,,,,,,0.082,,,,,,,,,,,,,,,,,,
8.3,1.63733,4.42476,0,,,,,,,,,,,,,,,,,,,0.083,,,,,,,,,,,,,,,,,,
8.4,1.65399,4.42577,0,,,,,,,,,,,,,,,,,,,0.084,,,,,,,,,,,,,,,,,,
8.5,1.67048,4.43011,0,,,,,,,,,,,,,,,,,,,0.085,,,,,,,,,,,,,,,,,,
8.6,1.68725,4.45122,0,,,,,,,,,,,,,,,,,,,0.086,,,,,,,,,,,,,,,,,,
8.7,1.70397,4.41212,0,,,,,,,,,,,,,,,,,,,0.087,,,,,,,,,,,,,,,,,,
8.8,1.72057,4.41262,0,,,,,,,,,,,,,,,,,,,0.088,,,,,,,,,,,,,,,,,,
8.9,1.73717,4.43626,0,,,,,,,,,,,,,,,,,,,0.089,,,,,,,,,,,,,,,,,,
9,1.754,4.41798,0,,,,,,,,,,,,,,,,,,,0.09,,,,,,,,,,,,,,,,,,
9.1,1.77061,4.44868,0,,,,,,,,,,,,,,,,,,,0.091,,,,,,,,,,,,,,,,,,
9.2,1.78715,4.4006,0,,,,,,,,,,,,,,,,,,,0.092,,,,,,,,,,,,,,,,,,
9.3,1.80393,4.45652,0,,,,,,,,,,,,,,,,,,,0.093,,,,,,,,,,,,,,,,,,
9.4,1.82059,4.51811,0,,,,,,,,,,,,,,,,,,,0.094,,,,,,,,,,,,,,,,,,
9.5,1.8373,4.47711,0,,,,,,,,,,,,,,,,,,,0.095,,,,,,,,,,,,,,,,,,
9.6,1.85379,4.42557,0,,,,,,,,,,,,,,,,,,,0.096,,,,,,,,,,,,,,,,,,
9.7,1.87074,4.51631,0,,,,,,,,,,,,,,,,,,,0.097,,,,,,,,,,,,,,,,,,
9.8,1.88723,4.43121,0,,,,,,,,,,,,,,,,,,,0.098,,,,,,,,,,,,,,,,,,
9.9,1.90389,4.4387,0,,,,,,,,,,,,,,,,,,,0.099,,,,,,,,,,,,,,,,,,
10,1.92072,4.40258,0,,,,,,,,,,,,,,,,,,,0.1,,,,,,,,,,,,,,,,,,
10.1,1.93726,4.43613,0,,,,,,,,,,,,,,,,,,,0.101,,,,,,,,,,,,,,,,,,
10.2,1.95387,4.39929,0,,,,,,,,,,,,,,,,,,,0.102,,,,,,,,,,,,,,,,,,
10.3,1.97053,4.4341,0,,,,,,,,,,,,,,,,,,,0.103,,,,,,,,,,,,,,,,,,
10.4,1.9873,4.45826,0,,,,,,,,,,,,,,,,,,,0.104,,,,,,,,,,,,,,,,,,
10.5,2.0039,4.42327,0,,,,,,,,,,,,,,,,,,,0.105,,,,,,,,,,,,,,,,,,
10.6,2.02056,4.45788,0,,,,,,,,,,,,,,,,,,,0.106,,,,,,,,,,,,,,,,,,
10.7,2.03728,4.43329,0,,,,,,,,,,,,,,,,,,,0.107,,,,,,,,,,,,,,,,,,
10.8,2.05394,4.45086,0,,,,,,,,,,,,,,,,,,,0.108,,,,,,,,,,,,,,,,,,
10.9,2.07049,4.47205,0,,,,,,,,,,,,,,,,,,,0.109,,,,,,,,,,,,,,,,,,
11,2.08726,4.44023,0,,,,,,,,,,,,,,,,,,,0.11,,,,,,,,,,,,,,,,,,
11.1,2.10386,4.45162,0,,,,,,,,,,,,,,,,,,,0.111,,,,,,,,,,,,,,,,,,
11.2,2.12058,4.46566,0,,,,,,,,,,,,,,,,,,,0.112,,,,,,,,,,,,,,,,,,
11.3,2.1373,4.52934,0,,,,,,,,,,,,,,,,,,,0.113,,,,,,,,,,,,,,,,,,
11.4,2.15396,4.46268,0,,,,,,,,,,,,,,,,,,,0.114,,,,,,,,,,,,,,,,,,
11.5,2.17062,4.42265,0,,,,,,,,,,,,,,,,,,,0.115,,,,,,,,,,,,,,,,,,
11.6,2.18716,4.4098,0,,,,,,,,,,,,,,,,,,,0.116,,,,,,,,,,,,,,,,,,
11.7,2.20405,4.39827,0,,,,,,,,,,,,,,,,,,,0.117,,,,,,,,,,,,,,,,,,
11.8,2.22054,4.44001,0,,,,,,,,,,,,,,,,,,,0.118,,,,,,,,,,,,,,,,,,
11.9,2.23726,4.38723,0,,,,,,,,,,,,,,,,,,,0.119,,,,,,,,,,,,,,,,,,
12,2.25386,4.34841,0,,,,,,,,,,,,,,,,,,,0.12,,,,,,,,,,,,,,,,,,
12.1,2.27069,4.33101,0,,,,,,,,,,,,,,,,,,,0.121,,,,,,,,,,,,,,,,,,
12.2,2.28724,4.34532,0,,,,,,,,,,,,,,,,,,,0.122,,,,,,,,,,,,,,,,,,
12.3,2.30384,4.30635,0,,,,,,,,,,,,,,,,,,,0.123,,,,,,,,,,,,,,,,,,
12.4,2.32067,4.30022,0,,,,,,,,,,,,,,,,,,,0.124,,,,,,,,,,,,,,,,,,
12.5,2.33727,4.30237,0,,,,,,,,,,,,,,,,,,,0.125,,,,,,,,,,,,,,,,,,
12.6,2.35388,4.25372,0,,,,,,,,,,,,,,,,,,,0.126,,,,,,,,,,,,,,,,,,
12.7,2.37059,4.20974,0,,,,,,,,,,,,,,,,,,,0.127,,,,,,,,,,,,,,,,,,
12.8,2.38731,4.20396,0,,,,,,,,,,,,,,,,,,,0.128,,,,,,,,,,,,,,,,,,
12.9,2.40386,4.14376,0,,,,,,,,,,,,,,,,,,,0.129,,,,,,,,,,,,,,,,,,
13,2.42057,4.12766,0,,,,,,,,,,,,,,,,,,,0.13,,,,,,,,,,,,,,,,,,
13.1,2.43729,4.08716,0,,,,,,,,,,,,,,,,,,,0.131,,,,,,,,,,,,,,,,,,
13.2,2.45395,4.0724,0,,,,,,,,,,,,,,,,,,,0.132,,,,,,,,,,,,,,,,,,
13.3,2.4705,4.02415,0,,,,,,,,,,,,,,,,,,,0.133,,,,,,,,,,,,,,,,,,
13.4,2.48733,4.06164,0,,,,,,,,,,,,,,,,,,,0.134,,,,,,,,,,,,,,,,,,
13.5,2.50387,3.94891,0,,,,,,,,,,,,,,,,,,,0.135,,,,,,,,,,,,,,,,,,
13.6,2.52053,3.96053,0,,,,,,,,,,,,,,,,,,,0.136,,,,,,,,,,,,,,,,,,
13.7,2.53725,3.97936,0,,,,,,,,,,,,,,,,,,,0.137,,,,,,,,,,,,,,,,,,
13.8,2.55391,3.87053,0,,,,,,,,,,,,,,,,,,,0.138,,,,,,,,,,,,,,,,,,
13.9,2.57057,3.85221,0,,,,,,,,,,,,,,,,,,,0.139,,,,,,,,,,,,,,,,,,
14,2.58712,3.83897,0,,,,,,,,,,,,,,,,,,,0.14,,,,,,,,,,,,,,,,,,
14.1,2.60412,3.8032,0,,,,,,,,,,,,,,,,,,,0.141,,,,,,,,,,,,,,,,,,
14.2,2.62049,3.80365,0,,,,,,,,,,,,,,,,,,,0.142,,,,,,,,,,,,,,,,,,
14.3,2.63721,3.8085,0,,,,,,,,,,,,,,,,,,,0.143,,,,,,,,,,,,,,,,,,
14.4,2.65398,3.73212,0,,,,,,,,,,,,,,,,,,,0.144,,,,,,,,,,,,,,,,,,
14.5,2.67064,3.77268,0,,,,,,,,,,,,,,,,,,,0.145,,,,,,,,,,,,,,,,,,
14.6,2.68719,3.72537,0,,,,,,,,,,,,,,,,,,,0.146,,,,,,,,,,,,,,,,,,
14.7,2.70391,3.79165,0,,,,,,,,,,,,,,,,,,,0.147,,,,,,,,,,,,,,,,,,
14.8,2.72068,3.70871,0,,,,,,,,,,,,,,,,,,,0.148,,,,,,,,,,,,,,,,,,
14.9,2.73717,3.67226,0,,,,,,,,,,,,,,,,,,,0.149,,,,,,,,,,,,,,,,,,
15,2.75383,3.66146,0,,,,,,,,,,,,,,,,,,,0.15,,,,,,,,,,,,,,,,,,
15.1,2.77066,3.62467,0,,,,,,,,,,,,,,,,,,,0.151,,,,,,,,,,,,,,,,,,
15.2,2.78732,3.59868,0,,,,,,,,,,,,,,,,,,,0.152,,,,,,,,,,,,,,,,,,
15.3,2.80381,3.54909,0,,,,,,,,,,,,,,,,,,,0.153,,,,,,,,,,,,,,,,,,
15.4,2.82058,3.57434,0,,,,,,,,,,,,,,,,,,,0.154,,,,,,,,,,,,,,,,,,
15.5,2.8373,3.51328,0,,,,,,,,,,,,,,,,,,,0.155,,,,,,,,,,,,,,,,,,
15.6,2.85396,3.43671,0,,,,,,,,,,,,,,,,,,,0.156,,,,,,,,,,,,,,,,,,
15.7,2.87051,3.46389,0,,,,,,,,,,,,,,,,,,,0.157,,,,,,,,,,,,,,,,,,
15.8,2.88734,3.43246,0,,,,,,,,,,,,,,,,,,,0.158,,,,,,,,,,,,,,,,,,
15.9,2.90394,3.40514,0,,,,,,,,,,,,,,,,,,,0.159,,,,,,,,,,,,,,,,,,
16,2.92054,3.40147,0,,,,,,,,,,,,,,,,,,,0.16,,,,,,,,,,,,,,,,,,
16.1,2.93732,3.35987,0,,,,,,,,,,,,,,,,,,,0.161,,,,,,,,,,,,,,,,,,
16.2,2.95386,3.34398,0,,,,,,,,,,,,,,,,,,,0.162,,,,,,,,,,,,,,,,,,
16.3,2.97058,3.32325,0,,,,,,,,,,,,,,,,,,,0.163,,,,,,,,,,,,,,,,,,
16.4,2.98713,3.34352,0,,,,,,,,,,,,,,,,,,,0.164,,,,,,,,,,,,,,,,,,
16.5,3.00407,3.33003,0,,,,,,,,,,,,,,,,,,,0.165,,,,,,,,,,,,,,,,,,
16.6,3.0205,3.29761,0,,,,,,,,,,,,,,,,,,,0.166,,,,,,,,,,,,,,,,,,
16.7,3.03722,3.28251,0,,,,,,,,,,,,,,,,,,,0.167,,,,,,,,,,,,,,,,,,
16.8,3.05399,3.25037,0,,,,,,,,,,,,,,,,,,,0.168,,,,,,,,,,,,,,,,,,
16.9,3.07054,3.21909,0,,,,,,,,,,,,,,,,,,,0.169,,,,,,,,,,,,,,,,,,
17,3.08726,3.19434,0,,,,,,,,,,,,,,,,,,,0.17,,,,,,,,,,,,,,,,,,
17.1,3.10392,3.17339,0,,,,,,,,,,,,,,,,,,,0.171,,,,,,,,,,,,,,,,,,
17.2,3.12063,3.11451,0,,,,,,,,,,,,,,,,,,,0.172,,,,,,,,,,,,,,,,,,
17.3,3.13724,3.1412,0,,,,,,,,,,,,,,,,,,,0.173,,,,,,,,,,,,,,,,,,
17.4,3.1539,3.09213,0,,,,,,,,,,,,,,,,,,,0.174,,,,,,,,,,,,,,,,,,
17.5,3.17061,3.11467,0,,,,,,,,,,,,,,,,,,,0.175,,,,,,,,,,,,,,,,,,
17.6,3.18722,3.08354,0,,,,,,,,,,,,,,,,,,,0.176,,,,,,,,,,,,,,,,,,
17.7,3.20382,3.07116,0,,,,,,,,,,,,,,,,,,,0.177,,,,,,,,,,,,,,,,,,
17.8,3.22071,3.06922,0,,,,,,,,,,,,,,,,,,,0.178,,,,,,,,,,,,,,,,,,
17.9,3.2372,3.03562,0,,,,,,,,,,,,,,,,,,,0.179,,,,,,,,,,,,,,,,,,
18,3.25386,2.94261,0,,,,,,,,,,,,,,,,,,,0.18,,,,,,,,,,,,,,,,,,
18.1,3.27057,2.92743,0,,,,,,,,,,,,,,,,,,,0.181,,,,,,,,,,,,,,,,,,
18.2,3.28735,2.93937,0,,,,,,,,,,,,,,,,,,,0.182,,,,,,,,,,,,,,,,,,
18.3,3.30389,2.87324,0,,,,,,,,,,,,,,,,,,,0.183,,,,,,,,,,,,,,,,,,
18.4,3.3205,2.83246,0,,,,,,,,,,,,,,,,,,,0.184,,,,,,,,,,,,,,,,,,
18.5,3.33738,2.83874,0,,,,,,,,,,,,,,,,,,,0.185,,,,,,,,,,,,,,,,,,
18.6,3.35387,2.78653,0,,,,,,,,,,,,,,,,,,,0.186,,,,,,,,,,,,,,,,,,
18.7,3.37053,2.77049,0,,,,,,,,,,,,,,,,,,,0.187,,,,,,,,,,,,,,,,,,
18.8,3.38719,2.79206,0,,,,,,,,,,,,,,,,,,,0.188,,,,,,,,,,,,,,,,,,
18.9,3.40402,2.70645,0,,,,,,,,,,,,,,,,,,,0.189,,,,,,,,,,,,,,,,,,
19,3.42057,2.70376,0,,,,,,,,,,,,,,,,,,,0.19,,,,,,,,,,,,,,,,,,
19.1,3.43717,2.71143,0,,,,,,,,,,,,,,,,,,,0.191,,,,,,,,,,,,,,,,,,
19.2,3.454,2.66587,0,,,,,,,,,,,,,,,,,,,0.192,,,,,,,,,,,,,,,,,,
19.3,3.47055,2.66609,0,,,,,,,,,,,,,,,,,,,0.193,,,,,,,,,,,,,,,,,,
19.4,3.48721,2.74109,0,,,,,,,,,,,,,,,,,,,0.194,,,,,,,,,,,,,,,,,,
19.5,3.50393,2.62101,0,,,,,,,,,,,,,,,,,,,0.195,,,,,,,,,,,,,,,,,,
19.6,3.5207,2.68859,0,,,,,,,,,,,,,,,,,,,0.196,,,,,,,,,,,,,,,,,,
19.7,3.53719,2.60751,0,,,,,,,,,,,,,,,,,,,0.197,,,,,,,,,,,,,,,,,,
19.8,3.55391,2.62718,0,,,,,,,,,,,,,,,,,,,0.198,,,,,,,,,,,,,,,,,,
19.9,3.57062,2.61403,0,,,,,,,,,,,,,,,,,,,0.199,,,,,,,,,,,,,,,,,,
20,3.58728,2.65045,0,,,,,,,,,,,,,,,,,,,0.2,,,,,,,,,,,,,,,,,,
20.1,3.60383,2.60631,0,,,,,,,,,,,,,,,,,,,,,,,,,,,,,,,,,,,,,
20.2,3.6206,2.60823,0,,,,,,,,,,,,,,,,,,,,,,,,,,,,,,,,,,,,,
20.3,3.63726,2.5746,0,,,,,,,,,,,,,,,,,,,,,,,,,,,,,,,,,,,,,
20.4,3.65387,2.61876,0,,,,,,,,,,,,,,,,,,,,,,,,,,,,,,,,,,,,,
20.5,3.67058,2.56879,0,,,,,,,,,,,,,,,,,,,,,,,,,,,,,,,,,,,,,
20.6,3.6873,2.54664,0,,,,,,,,,,,,,,,,,,,,,,,,,,,,,,,,,,,,,
20.7,3.7039,2.60345,0,,,,,,,,,,,,,,,,,,,,,,,,,,,,,,,,,,,,,
20.8,3.72051,2.54616,0,,,,,,,,,,,,,,,,,,,,,,,,,,,,,,,,,,,,,
20.9,3.73739,2.53051,0,,,,,,,,,,,,,,,,,,,,,,,,,,,,,,,,,,,,,
21,3.75388,2.48814,0,,,,,,,,,,,,,,,,,,,,,,,,,,,,,,,,,,,,,
21.1,3.7706,2.4994,0,,,,,,,,,,,,,,,,,,,,,,,,,,,,,,,,,,,,,
21.2,3.78726,2.50006,0,,,,,,,,,,,,,,,,,,,,,,,,,,,,,,,,,,,,,
21.3,3.80392,2.49196,0,,,,,,,,,,,,,,,,,,,,,,,,,,,,,,,,,,,,,
21.4,3.82058,2.48484,0,,,,,,,,,,,,,,,,,,,,,,,,,,,,,,,,,,,,,
21.5,3.83724,2.49708,0,,,,,,,,,,,,,,,,,,,,,,,,,,,,,,,,,,,,,
21.6,3.85401,2.44748,0,,,,,,,,,,,,,,,,,,,,,,,,,,,,,,,,,,,,,
21.7,3.8705,2.48079,0,,,,,,,,,,,,,,,,,,,,,,,,,,,,,,,,,,,,,
21.8,3.88722,2.48052,0,,,,,,,,,,,,,,,,,,,,,,,,,,,,,,,,,,,,,
21.9,3.90394,2.44018,0,,,,,,,,,,,,,,,,,,,,,,,,,,,,,,,,,,,,,
22,3.9206,2.43101,0,,,,,,,,,,,,,,,,,,,,,,,,,,,,,,,,,,,,,
22.1,3.93714,2.39399,0,,,,,,,,,,,,,,,,,,,,,,,,,,,,,,,,,,,,,
22.2,3.95392,2.38529,0,,,,,,,,,,,,,,,,,,,,,,,,,,,,,,,,,,,,,
22.3,3.97058,2.42606,0,,,,,,,,,,,,,,,,,,,,,,,,,,,,,,,,,,,,,
22.4,3.98724,2.39853,0,,,,,,,,,,,,,,,,,,,,,,,,,,,,,,,,,,,,,
22.5,4.00384,2.3997,0,,,,,,,,,,,,,,,,,,,,,,,,,,,,,,,,,,,,,
22.6,4.02067,2.43394,0,,,,,,,,,,,,,,,,,,,,,,,,,,,,,,,,,,,,,
22.7,4.03727,2.41762,0,,,,,,,,,,,,,,,,,,,,,,,,,,,,,,,,,,,,,
22.8,4.05382,2.40698,0,,,,,,,,,,,,,,,,,,,,,,,,,,,,,,,,,,,,,
22.9,4.07065,2.40938,0,,,,,,,,,,,,,,,,,,,,,,,,,,,,,,,,,,,,,
23,4.08725,2.41816,0,,,,,,,,,,,,,,,,,,,,,,,,,,,,,,,,,,,,,
23.1,4.10391,2.38929,0,,,,,,,,,,,,,,,,,,,,,,,,,,,,,,,,,,,,,
23.2,4.12052,2.38364,0,,,,,,,,,,,,,,,,,,,,,,,,,,,,,,,,,,,,,
23.3,4.1374,2.3589,0,,,,,,,,,,,,,,,,,,,,,,,,,,,,,,,,,,,,,
23.4,4.15384,2.35061,0,,,,,,,,,,,,,,,,,,,,,,,,,,,,,,,,,,,,,
23.5,4.17055,2.34689,0,,,,,,,,,,,,,,,,,,,,,,,,,,,,,,,,,,,,,
23.6,4.18733,2.3583,0,,,,,,,,,,,,,,,,,,,,,,,,,,,,,,,,,,,,,
23.7,4.20393,2.35355,0,,,,,,,,,,,,,,,,,,,,,,,,,,,,,,,,,,,,,
23.8,4.22059,2.27977,0,,,,,,,,,,,,,,,,,,,,,,,,,,,,,,,,,,,,,
23.9,4.23725,2.26467,0,,,,,,,,,,,,,,,,,,,,,,,,,,,,,,,,,,,,,
24,4.25402,2.27223,0,,,,,,,,,,,,,,,,,,,,,,,,,,,,,,,,,,,,,
24.1,4.27051,2.30003,0,,,,,,,,,,,,,,,,,,,,,,,,,,,,,,,,,,,,,
24.2,4.28717,2.24273,0,,,,,,,,,,,,,,,,,,,,,,,,,,,,,,,,,,,,,
24.3,4.30395,2.22863,0,,,,,,,,,,,,,,,,,,,,,,,,,,,,,,,,,,,,,
24.4,4.32061,2.20737,0,,,,,,,,,,,,,,,,,,,,,,,,,,,,,,,,,,,,,
24.5,4.33715,2.24683,0,,,,,,,,,,,,,,,,,,,,,,,,,,,,,,,,,,,,,
24.6,4.35398,2.16651,0,,,,,,,,,,,,,,,,,,,,,,,,,,,,,,,,,,,,,
24.7,4.37059,2.21218,0,,,,,,,,,,,,,,,,,,,,,,,,,,,,,,,,,,,,,
24.8,4.38725,2.14029,0,,,,,,,,,,,,,,,,,,,,,,,,,,,,,,,,,,,,,
24.9,4.40391,2.15854,0,,,,,,,,,,,,,,,,,,,,,,,,,,,,,,,,,,,,,
25,4.42062,2.12043,0,,,,,,,,,,,,,,,,,,,,,,,,,,,,,,,,,,,,,
25.1,4.43723,2.10622,0,,,,,,,,,,,,,,,,,,,,,,,,,,,,,,,,,,,,,
25.2,4.45383,2.05814,0,,,,,,,,,,,,,,,,,,,,,,,,,,,,,,,,,,,,,
25.3,4.47072,2.0944,0,,,,,,,,,,,,,,,,,,,,,,,,,,,,,,,,,,,,,
25.4,4.48715,2.03396,0,,,,,,,,,,,,,,,,,,,,,,,,,,,,,,,,,,,,,
25.5,4.50392,2.07736,0,,,,,,,,,,,,,,,,,,,,,,,,,,,,,,,,,,,,,
25.6,4.52058,2.05305,0,,,,,,,,,,,,,,,,,,,,,,,,,,,,,,,,,,,,,
25.7,4.53736,2.1278,0,,,,,,,,,,,,,,,,,,,,,,,,,,,,,,,,,,,,,
25.8,4.55385,2.01091,0,,,,,,,,,,,,,,,,,,,,,,,,,,,,,,,,,,,,,
25.9,4.57051,2.03474,0,,,,,,,,,,,,,,,,,,,,,,,,,,,,,,,,,,,,,
26,4.58734,2.03736,0,,,,,,,,,,,,,,,,,,,,,,,,,,,,,,,,,,,,,
26.1,4.60388,1.95634,0,,,,,,,,,,,,,,,,,,,,,,,,,,,,,,,,,,,,,
26.2,4.62054,2.04336,0,,,,,,,,,,,,,,,,,,,,,,,,,,,,,,,,,,,,,
26.3,4.63732,2.01054,0,,,,,,,,,,,,,,,,,,,,,,,,,,,,,,,,,,,,,
26.4,4.65398,1.9988,0,,,,,,,,,,,,,,,,,,,,,,,,,,,,,,,,,,,,,
26.5,4.67052,1.94501,0,,,,,,,,,,,,,,,,,,,,,,,,,,,,,,,,,,,,,
26.6,4.68724,1.974,0,,,,,,,,,,,,,,,,,,,,,,,,,,,,,,,,,,,,,
26.7,4.70401,2.03809,0,,,,,,,,,,,,,,,,,,,,,,,,,,,,,,,,,,,,,
26.8,4.72056,1.98387,0,,,,,,,,,,,,,,,,,,,,,,,,,,,,,,,,,,,,,
26.9,4.73711,1.97067,0,,,,,,,,,,,,,,,,,,,,,,,,,,,,,,,,,,,,,
27,4.75399,1.94937,0,,,,,,,,,,,,,,,,,,,,,,,,,,,,,,,,,,,,,
27.1,4.7706,1.93501,0,,,,,,,,,,,,,,,,,,,,,,,,,,,,,,,,,,,,,
27.2,4.7872,1.96764,0,,,,,,,,,,,,,,,,,,,,,,,,,,,,,,,,,,,,,
27.3,4.80392,1.91621,0,,,,,,,,,,,,,,,,,,,,,,,,,,,,,,,,,,,,,
27.4,4.82063,1.99447,0,,,,,,,,,,,,,,,,,,,,,,,,,,,,,,,,,,,,,
27.5,4.83724,1.95126,0,,,,,,,,,,,,,,,,,,,,,,,,,,,,,,,,,,,,,
27.6,4.85378,1.91913,0,,,,,,,,,,,,,,,,,,,,,,,,,,,,,,,,,,,,,
27.7,4.87073,1.9796,0,,,,,,,,,,,,,,,,,,,,,,,,,,,,,,,,,,,,,
27.8,4.88722,1.8899,0,,,,,,,,,,,,,,,,,,,,,,,,,,,,,,,,,,,,,
27.9,4.90393,1.88394,0,,,,,,,,,,,,,,,,,,,,,,,,,,,,,,,,,,,,,
28,4.92059,1.84451,0,,,,,,,,,,,,,,,,,,,,,,,,,,,,,,,,,,,,,
28.1,4.93731,1.83065,0,,,,,,,,,,,,,,,,,,,,,,,,,,,,,,,,,,,,,
28.2,4.95391,1.84788,0,,,,,,,,,,,,,,,,,,,,,,,,,,,,,,,,,,,,,
28.3,4.97057,1.8448,0,,,,,,,,,,,,,,,,,,,,,,,,,,,,,,,,,,,,,
28.4,4.98735,1.83003,0,,,,,,,,,,,,,,,,,,,,,,,,,,,,,,,,,,,,,
28.5,5.00384,1.80858,0,,,,,,,,,,,,,,,,,,,,,,,,,,,,,,,,,,,,,
28.6,5.02055,1.79591,0,,,,,,,,,,,,,,,,,,,,,,,,,,,,,,,,,,,,,
28.7,5.03727,1.82483,0,,,,,,,,,,,,,,,,,,,,,,,,,,,,,,,,,,,,,
28.8,5.05393,1.77128,0,,,,,,,,,,,,,,,,,,,,,,,,,,,,,,,,,,,,,
28.9,5.07048,1.80227,0,,,,,,,,,,,,,,,,,,,,,,,,,,,,,,,,,,,,,
29,5.08725,1.76691,0,,,,,,,,,,,,,,,,,,,,,,,,,,,,,,,,,,,,,
29.1,5.10397,1.7314,0,,,,,,,,,,,,,,,,,,,,,,,,,,,,,,,,,,,,,
29.2,5.12057,1.77272,0,,,,,,,,,,,,,,,,,,,,,,,,,,,,,,,,,,,,,
29.3,5.13717,1.76045,0,,,,,,,,,,,,,,,,,,,,,,,,,,,,,,,,,,,,,
29.4,5.154,1.73246,0,,,,,,,,,,,,,,,,,,,,,,,,,,,,,,,,,,,,,
29.5,5.17055,1.70214,0,,,,,,,,,,,,,,,,,,,,,,,,,,,,,,,,,,,,,
29.6,5.18715,1.74084,0,,,,,,,,,,,,,,,,,,,,,,,,,,,,,,,,,,,,,
29.7,5.20398,1.78262,0,,,,,,,,,,,,,,,,,,,,,,,,,,,,,,,,,,,,,
29.8,5.22059,1.7553,0,,,,,,,,,,,,,,,,,,,,,,,,,,,,,,,,,,,,,
29.9,5.23725,1.70251,0,,,,,,,,,,,,,,,,,,,,,,,,,,,,,,,,,,,,,
30,5.25385,1.68934,0,,,,,,,,,,,,,,,,,,,,,,,,,,,,,,,,,,,,,
30.1,5.27074,1.72095,0,,,,,,,,,,,,,,,,,,,,,,,,,,,,,,,,,,,,,
30.2,5.28717,1.71653,0,,,,,,,,,,,,,,,,,,,,,,,,,,,,,,,,,,,,,
30.3,5.30389,1.73945,0,,,,,,,,,,,,,,,,,,,,,,,,,,,,,,,,,,,,,
30.4,5.32072,1.69999,0,,,,,,,,,,,,,,,,,,,,,,,,,,,,,,,,,,,,,
30.5,5.33726,1.7077,0,,,,,,,,,,,,,,,,,,,,,,,,,,,,,,,,,,,,,
30.6,5.35392,1.62619,0,,,,,,,,,,,,,,,,,,,,,,,,,,,,,,,,,,,,,
30.7,5.37058,1.69099,0,,,,,,,,,,,,,,,,,,,,,,,,,,,,,,,,,,,,,
30.8,5.3873,1.73142,0,,,,,,,,,,,,,,,,,,,,,,,,,,,,,,,,,,,,,
30.9,5.40385,1.64685,0,,,,,,,,,,,,,,,,,,,,,,,,,,,,,,,,,,,,,
31,5.42056,1.6587,0,,,,,,,,,,,,,,,,,,,,,,,,,,,,,,,,,,,,,
31.1,5.43728,1.63132,0,,,,,,,,,,,,,,,,,,,,,,,,,,,,,,,,,,,,,
31.2,5.45394,1.62309,0,,,,,,,,,,,,,,,,,,,,,,,,,,,,,,,,,,,,,
31.3,5.47043,1.62794,0,,,,,,,,,,,,,,,,,,,,,,,,,,,,,,,,,,,,,
31.4,5.48732,1.62348,0,,,,,,,,,,,,,,,,,,,,,,,,,,,,,,,,,,,,,
31.5,5.50398,1.57441,0,,,,,,,,,,,,,,,,,,,,,,,,,,,,,,,,,,,,,
31.6,5.52058,1.60246,0,,,,,,,,,,,,,,,,,,,,,,,,,,,,,,,,,,,,,
31.7,5.53718,1.65064,0,,,,,,,,,,,,,,,,,,,,,,,,,,,,,,,,,,,,,
31.8,5.55401,1.56034,0,,,,,,,,,,,,,,,,,,,,,,,,,,,,,,,,,,,,,
31.9,5.57062,1.485,0,,,,,,,,,,,,,,,,,,,,,,,,,,,,,,,,,,,,,
32,5.58711,1.56714,0,,,,,,,,,,,,,,,,,,,,,,,,,,,,,,,,,,,,,
32.1,5.60399,1.53237,0,,,,,,,,,,,,,,,,,,,,,,,,,,,,,,,,,,,,,
32.2,5.62054,1.56923,0,,,,,,,,,,,,,,,,,,,,,,,,,,,,,,,,,,,,,
32.3,5.63731,1.49023,0,,,,,,,,,,,,,,,,,,,,,,,,,,,,,,,,,,,,,
32.4,5.65386,1.54124,0,,,,,,,,,,,,,,,,,,,,,,,,,,,,,,,,,,,,,
32.5,5.67063,1.54568,0,,,,,,,,,,,,,,,,,,,,,,,,,,,,,,,,,,,,,
32.6,5.68718,1.55004,0,,,,,,,,,,,,,,,,,,,,,,,,,,,,,,,,,,,,,
32.7,5.70384,1.58247,0,,,,,,,,,,,,,,,,,,,,,,,,,,,,,,,,,,,,,
32.8,5.72067,1.53102,0,,,,,,,,,,,,,,,,,,,,,,,,,,,,,,,,,,,,,
32.9,5.73722,1.48829,0,,,,,,,,,,,,,,,,,,,,,,,,,,,,,,,,,,,,,
33,5.75388,1.48972,0,,,,,,,,,,,,,,,,,,,,,,,,,,,,,,,,,,,,,
33.1,5.77065,1.51819,0,,,,,,,,,,,,,,,,,,,,,,,,,,,,,,,,,,,,,
33.2,5.78731,1.52663,0,,,,,,,,,,,,,,,,,,,,,,,,,,,,,,,,,,,,,
33.3,5.8038,1.42558,0,,,,,,,,,,,,,,,,,,,,,,,,,,,,,,,,,,,,,
33.4,5.82063,1.49429,0,,,,,,,,,,,,,,,,,,,,,,,,,,,,,,,,,,,,,
33.5,5.83729,1.45668,0,,,,,,,,,,,,,,,,,,,,,,,,,,,,,,,,,,,,,
33.6,5.85389,1.38741,0,,,,,,,,,,,,,,,,,,,,,,,,,,,,,,,,,,,,,
33.7,5.8705,1.49332,0,,,,,,,,,,,,,,,,,,,,,,,,,,,,,,,,,,,,,
33.8,5.88738,1.39733,0,,,,,,,,,,,,,,,,,,,,,,,,,,,,,,,,,,,,,
33.9,5.90387,1.42543,0,,,,,,,,,,,,,,,,,,,,,,,,,,,,,,,,,,,,,
34,5.92048,1.37695,0,,,,,,,,,,,,,,,,,,,,,,,,,,,,,,,,,,,,,
34.1,5.93725,1.39585,0,,,,,,,,,,,,,,,,,,,,,,,,,,,,,,,,,,,,,
34.2,5.95397,1.3817,0,,,,,,,,,,,,,,,,,,,,,,,,,,,,,,,,,,,,,
34.3,5.97057,1.34295,0,,,,,,,,,,,,,,,,,,,,,,,,,,,,,,,,,,,,,
34.4,5.98712,1.3298,0,,,,,,,,,,,,,,,,,,,,,,,,,,,,,,,,,,,,,
34.5,6.00406,1.26511,0,,,,,,,,,,,,,,,,,,,,,,,,,,,,,,,,,,,,,
34.6,6.02055,1.27304,0,,,,,,,,,,,,,,,,,,,,,,,,,,,,,,,,,,,,,
34.7,6.03721,1.30815,0,,,,,,,,,,,,,,,,,,,,,,,,,,,,,,,,,,,,,
34.8,6.05398,1.2232,0,,,,,,,,,,,,,,,,,,,,,,,,,,,,,,,,,,,,,
34.9,6.07064,1.25698,0,,,,,,,,,,,,,,,,,,,,,,,,,,,,,,,,,,,,,
35,6.08719,1.15698,0,,,,,,,,,,,,,,,,,,,,,,,,,,,,,,,,,,,,,
35.1,6.10391,1.14551,0,,,,,,,,,,,,,,,,,,,,,,,,,,,,,,,,,,,,,
35.2,6.12068,1.12683,0,,,,,,,,,,,,,,,,,,,,,,,,,,,,,,,,,,,,,
35.3,6.13717,1.06085,0,,,,,,,,,,,,,,,,,,,,,,,,,,,,,,,,,,,,,
35.4,6.15383,0.93314,0,,,,,,,,,,,,,,,,,,,,,,,,,,,,,,,,,,,,,
35.5,6.1706,0.80361,0,,,,,,,,,,,,,,,,,,,,,,,,,,,,,,,,,,,,,
35.6,6.18726,0.78696,0,,,,,,,,,,,,,,,,,,,,,,,,,,,,,,,,,,,,,
35.7,6.20387,0.79627,0,,,,,,,,,,,,,,,,,,,,,,,,,,,,,,,,,,,,,
35.8,6.22058,0.70667,0,,,,,,,,,,,,,,,,,,,,,,,,,,,,,,,,,,,,,
35.9,6.2373,0.71577,0,,,,,,,,,,,,,,,,,,,,,,,,,,,,,,,,,,,,,
36,6.2539,0.66236,0,,,,,,,,,,,,,,,,,,,,,,,,,,,,,,,,,,,,,
36.1,6.27051,0.61692,0,,,,,,,,,,,,,,,,,,,,,,,,,,,,,,,,,,,,,
36.2,6.28734,0.64263,0,,,,,,,,,,,,,,,,,,,,,,,,,,,,,,,,,,,,,
36.3,6.30394,0.53093,0,,,,,,,,,,,,,,,,,,,,,,,,,,,,,,,,,,,,,
36.4,6.32049,0.58723,0,,,,,,,,,,,,,,,,,,,,,,,,,,,,,,,,,,,,,
36.5,6.33732,0.53809,0,,,,,,,,,,,,,,,,,,,,,,,,,,,,,,,,,,,,,
36.6,6.35386,0.51025,0,,,,,,,,,,,,,,,,,,,,,,,,,,,,,,,,,,,,,
36.7,6.37058,0.54864,0,,,,,,,,,,,,,,,,,,,,,,,,,,,,,,,,,,,,,
36.8,6.38718,0.50334,0,,,,,,,,,,,,,,,,,,,,,,,,,,,,,,,,,,,,,
36.9,6.40401,0.48107,0,,,,,,,,,,,,,,,,,,,,,,,,,,,,,,,,,,,,,
37,6.42056,0.46221,0,,,,,,,,,,,,,,,,,,,,,,,,,,,,,,,,,,,,,
37.1,6.43722,0.50039,0,,,,,,,,,,,,,,,,,,,,,,,,,,,,,,,,,,,,,
37.2,6.45405,0.44311,0,,,,,,,,,,,,,,,,,,,,,,,,,,,,,,,,,,,,,
37.3,6.47054,0.43009,0,,,,,,,,,,,,,,,,,,,,,,,,,,,,,,,,,,,,,
37.4,6.48714,0.48315,0,,,,,,,,,,,,,,,,,,,,,,,,,,,,,,,,,,,,,
37.5,6.50392,0.40543,0,,,,,,,,,,,,,,,,,,,,,,,,,,,,,,,,,,,,,
37.6,6.52069,0.42483,0,,,,,,,,,,,,,,,,,,,,,,,,,,,,,,,,,,,,,
37.7,6.53718,0.39995,0,,,,,,,,,,,,,,,,,,,,,,,,,,,,,,,,,,,,,
37.8,6.55384,0.36787,0,,,,,,,,,,,,,,,,,,,,,,,,,,,,,,,,,,,,,
37.9,6.57067,0.42518,0,,,,,,,,,,,,,,,,,,,,,,,,,,,,,,,,,,,,,
38,6.58727,0.37932,0,,,,,,,,,,,,,,,,,,,,,,,,,,,,,,,,,,,,,
38.1,6.60382,0.34185,0,,,,,,,,,,,,,,,,,,,,,,,,,,,,,,,,,,,,,
38.2,6.62065,0.33429,0,,,,,,,,,,,,,,,,,,,,,,,,,,,,,,,,,,,,,
38.3,6.63725,0.31691,0,,,,,,,,,,,,,,,,,,,,,,,,,,,,,,,,,,,,,
38.4,6.65391,0.29219,0,,,,,,,,,,,,,,,,,,,,,,,,,,,,,,,,,,,,,
38.5,6.67057,0.26554,0,,,,,,,,,,,,,,,,,,,,,,,,,,,,,,,,,,,,,
38.6,6.68729,0.26364,0,,,,,,,,,,,,,,,,,,,,,,,,,,,,,,,,,,,,,
38.7,6.70389,0.27405,0,,,,,,,,,,,,,,,,,,,,,,,,,,,,,,,,,,,,,
38.8,6.72044,0.22628,0,,,,,,,,,,,,,,,,,,,,,,,,,,,,,,,,,,,,,
38.9,6.73733,0.21667,0,,,,,,,,,,,,,,,,,,,,,,,,,,,,,,,,,,,,,
39,6.75387,0.22793,0,,,,,,,,,,,,,,,,,,,,,,,,,,,,,,,,,,,,,
39.1,6.77053,0.18404,0,,,,,,,,,,,,,,,,,,,,,,,,,,,,,,,,,,,,,
39.2,6.78719,0.17463,0,,,,,,,,,,,,,,,,,,,,,,,,,,,,,,,,,,,,,
39.3,6.80402,0.19639,0,,,,,,,,,,,,,,,,,,,,,,,,,,,,,,,,,,,,,
39.4,6.82051,0.16699,0,,,,,,,,,,,,,,,,,,,,,,,,,,,,,,,,,,,,,
39.5,6.83717,0.17073,0,,,,,,,,,,,,,,,,,,,,,,,,,,,,,,,,,,,,,
39.6,6.854,0.14205,0,,,,,,,,,,,,,,,,,,,,,,,,,,,,,,,,,,,,,
39.7,6.87055,0.17812,0,,,,,,,,,,,,,,,,,,,,,,,,,,,,,,,,,,,,,
39.8,6.88721,0.12827,0,,,,,,,,,,,,,,,,,,,,,,,,,,,,,,,,,,,,,
39.9,6.90398,0.13334,0,,,,,,,,,,,,,,,,,,,,,,,,,,,,,,,,,,,,,
40,6.92064,0.10946,0,,,,,,,,,,,,,,,,,,,,,,,,,,,,,,,,,,,,,
40.1,6.93719,0.04967,0,,,,,,,,,,,,,,,,,,,,,,,,,,,,,,,,,,,,,
40.2,6.95396,0.09707,0,,,,,,,,,,,,,,,,,,,,,,,,,,,,,,,,,,,,,
40.3,6.97062,0.07427,0,,,,,,,,,,,,,,,,,,,,,,,,,,,,,,,,,,,,,
40.4,6.98723,0.04041,0,,,,,,,,,,,,,,,,,,,,,,,,,,,,,,,,,,,,,
40.5,7.00383,0.04028,0,,,,,,,,,,,,,,,,,,,,,,,,,,,,,,,,,,,,,
40.6,7.02072,0.07895,0,,,,,,,,,,,,,,,,,,,,,,,,,,,,,,,,,,,,,
40.7,7.03721,0.05341,0,,,,,,,,,,,,,,,,,,,,,,,,,,,,,,,,,,,,,
40.8,7.05387,0.06813,0,,,,,,,,,,,,,,,,,,,,,,,,,,,,,,,,,,,,,
40.9,7.07058,0.05242,0,,,,,,,,,,,,,,,,,,,,,,,,,,,,,,,,,,,,,
41,7.0873,0.1375,0,,,,,,,,,,,,,,,,,,,,,,,,,,,,,,,,,,,,,
41.1,7.10396,0.05763,0,,,,,,,,,,,,,,,,,,,,,,,,,,,,,,,,,,,,,
41.2,7.12045,0.03489,0,,,,,,,,,,,,,,,,,,,,,,,,,,,,,,,,,,,,,
41.3,7.13739,0.04836,0,,,,,,,,,,,,,,,,,,,,,,,,,,,,,,,,,,,,,
41.4,7.15383,0.01957,0,,,,,,,,,,,,,,,,,,,,,,,,,,,,,,,,,,,,,
41.5,7.17054,0.06349,0,,,,,,,,,,,,,,,,,,,,,,,,,,,,,,,,,,,,,
41.6,7.18726,0.03898,0,,,,,,,,,,,,,,,,,,,,,,,,,,,,,,,,,,,,,
41.7,7.20398,0.01338,0,,,,,,,,,,,,,,,,,,,,,,,,,,,,,,,,,,,,,
41.8,7.22052,0.00562,0,,,,,,,,,,,,,,,,,,,,,,,,,,,,,,,,,,,,,
41.9,7.23718,-0.00336,0,,,,,,,,,,,,,,,,,,,,,,,,,,,,,,,,,,,,,
42,7.25401,0.05694,0,,,,,,,,,,,,,,,,,,,,,,,,,,,,,,,,,,,,,
42.1,7.2705,-0.00439,0,,,,,,,,,,,,,,,,,,,,,,,,,,,,,,,,,,,,,
42.2,7.28716,0.01317,0,,,,,,,,,,,,,,,,,,,,,,,,,,,,,,,,,,,,,
42.3,7.30399,0.04267,0,,,,,,,,,,,,,,,,,,,,,,,,,,,,,,,,,,,,,
42.4,7.3206,0.0064,0,,,,,,,,,,,,,,,,,,,,,,,,,,,,,,,,,,,,,
42.5,7.33714,-0.02686,0,,,,,,,,,,,,,,,,,,,,,,,,,,,,,,,,,,,,,
42.6,7.35397,-0.03092,0,,,,,,,,,,,,,,,,,,,,,,,,,,,,,,,,,,,,,
42.7,7.37063,0.00088,0,,,,,,,,,,,,,,,,,,,,,,,,,,,,,,,,,,,,,
42.8,7.38729,-0.02222,0,,,,,,,,,,,,,,,,,,,,,,,,,,,,,,,,,,,,,
42.9,7.40378,-0.02635,0,,,,,,,,,,,,,,,,,,,,,,,,,,,,,,,,,,,,,
43,7.42067,0.03681,0,,,,,,,,,,,,,,,,,,,,,,,,,,,,,,,,,,,,,
43.1,7.43722,-0.0225,0,,,,,,,,,,,,,,,,,,,,,,,,,,,,,,,,,,,,,
43.2,7.45388,-0.02382,0,,,,,,,,,,,,,,,,,,,,,,,,,,,,,,,,,,,,,
43.3,7.47065,-0.04717,0,,,,,,,,,,,,,,,,,,,,,,,,,,,,,,,,,,,,,
43.4,7.48725,-0.02164,0,,,,,,,,,,,,,,,,,,,,,,,,,,,,,,,,,,,,,
43.5,7.50391,-0.05328,0,,,,,,,,,,,,,,,,,,,,,,,,,,,,,,,,,,,,,
43.6,7.52046,0.02443,0,,,,,,,,,,,,,,,,,,,,,,,,,,,,,,,,,,,,,
43.7,7.53735,-0.05605,0,,,,,,,,,,,,,,,,,,,,,,,,,,,,,,,,,,,,,
43.8,7.55384,-0.07258,0,,,,,,,,,,,,,,,,,,,,,,,,,,,,,,,,,,,,,
43.9,7.57055,-0.05102,0,,,,,,,,,,,,,,,,,,,,,,,,,,,,,,,,,,,,,
44,7.58738,-0.045,0,,,,,,,,,,,,,,,,,,,,,,,,,,,,,,,,,,,,,
44.1,7.60393,-0.02819,0,,,,,,,,,,,,,,,,,,,,,,,,,,,,,,,,,,,,,
44.2,7.62053,-0.08208,0,,,,,,,,,,,,,,,,,,,,,,,,,,,,,,,,,,,,,
44.3,7.63725,-0.08164,0,,,,,,,,,,,,,,,,,,,,,,,,,,,,,,,,,,,,,
44.4,7.65402,-0.11826,0,,,,,,,,,,,,,,,,,,,,,,,,,,,,,,,,,,,,,
44.5,7.67051,-0.07275,0,,,,,,,,,,,,,,,,,,,,,,,,,,,,,,,,,,,,,
44.6,7.68717,-0.10469,0,,,,,,,,,,,,,,,,,,,,,,,,,,,,,,,,,,,,,
44.7,7.704,-0.06464,0,,,,,,,,,,,,,,,,,,,,,,,,,,,,,,,,,,,,,
44.8,7.72061,-0.02863,0,,,,,,,,,,,,,,,,,,,,,,,,,,,,,,,,,,,,,
44.9,7.7371,-0.09816,0,,,,,,,,,,,,,,,,,,,,,,,,,,,,,,,,,,,,,
45,7.75404,-0.0927,0,,,,,,,,,,,,,,,,,,,,,,,,,,,,,,,,,,,,,
45.1,7.77059,-0.11582,0,,,,,,,,,,,,,,,,,,,,,,,,,,,,,,,,,,,,,
45.2,7.78719,-0.08783,0,,,,,,,,,,,,,,,,,,,,,,,,,,,,,,,,,,,,,
45.3,7.80385,-0.12322,0,,,,,,,,,,,,,,,,,,,,,,,,,,,,,,,,,,,,,
45.4,7.82068,-0.11665,0,,,,,,,,,,,,,,,,,,,,,,,,,,,,,,,,,,,,,
45.5,7.83728,-0.12782,0,,,,,,,,,,,,,,,,,,,,,,,,,,,,,,,,,,,,,
45.6,7.85383,-0.16842,0,,,,,,,,,,,,,,,,,,,,,,,,,,,,,,,,,,,,,
45.7,7.87066,-0.15428,0,,,,,,,,,,,,,,,,,,,,,,,,,,,,,,,,,,,,,
45.8,7.88721,-0.14821,0,,,,,,,,,,,,,,,,,,,,,,,,,,,,,,,,,,,,,
45.9,7.90392,-0.20997,0,,,,,,,,,,,,,,,,,,,,,,,,,,,,,,,,,,,,,
46,7.92053,-0.20515,0,,,,,,,,,,,,,,,,,,,,,,,,,,,,,,,,,,,,,
46.1,7.93736,-0.14979,0,,,,,,,,,,,,,,,,,,,,,,,,,,,,,,,,,,,,,
46.2,7.95385,-0.27098,0,,,,,,,,,,,,,,,,,,,,,,,,,,,,,,,,,,,,,
46.3,7.97051,-0.22056,0,,,,,,,,,,,,,,,,,,,,,,,,,,,,,,,,,,,,,
46.4,7.98734,-0.27182,0,,,,,,,,,,,,,,,,,,,,,,,,,,,,,,,,,,,,,
46.5,8.00388,-0.27413,0,,,,,,,,,,,,,,,,,,,,,,,,,,,,,,,,,,,,,
46.6,8.02054,-0.23969,0,,,,,,,,,,,,,,,,,,,,,,,,,,,,,,,,,,,,,
46.7,8.03732,-0.26975,0,,,,,,,,,,,,,,,,,,,,,,,,,,,,,,,,,,,,,
46.8,8.05398,-0.27276,0,,,,,,,,,,,,,,,,,,,,,,,,,,,,,,,,,,,,,
46.9,8.07052,-0.28271,0,,,,,,,,,,,,,,,,,,,,,,,,,,,,,,,,,,,,,
47,8.0873,-0.29901,0,,,,,,,,,,,,,,,,,,,,,,,,,,,,,,,,,,,,,
47.1,8.10401,-0.27061,0,,,,,,,,,,,,,,,,,,,,,,,,,,,,,,,,,,,,,
47.2,8.12056,-0.30063,0,,,,,,,,,,,,,,,,,,,,,,,,,,,,,,,,,,,,,
47.3,8.13716,-0.25278,0,,,,,,,,,,,,,,,,,,,,,,,,,,,,,,,,,,,,,
47.4,8.15399,-0.3455,0,,,,,,,,,,,,,,,,,,,,,,,,,,,,,,,,,,,,,
47.5,8.1706,-0.28312,0,,,,,,,,,,,,,,,,,,,,,,,,,,,,,,,,,,,,,
47.6,8.1872,-0.31305,0,,,,,,,,,,,,,,,,,,,,,,,,,,,,,,,,,,,,,
47.7,8.20392,-0.26873,0,,,,,,,,,,,,,,,,,,,,,,,,,,,,,,,,,,,,,
47.8,8.22058,-0.32027,0,,,,,,,,,,,,,,,,,,,,,,,,,,,,,,,,,,,,,
47.9,8.23724,-0.32867,0,,,,,,,,,,,,,,,,,,,,,,,,,,,,,,,,,,,,,
48,8.25384,-0.32584,0,,,,,,,,,,,,,,,,,,,,,,,,,,,,,,,,,,,,,
48.1,8.27078,-0.31437,0,,,,,,,,,,,,,,,,,,,,,,,,,,,,,,,,,,,,,
48.2,8.28716,-0.35428,0,,,,,,,,,,,,,,,,,,,,,,,,,,,,,,,,,,,,,
48.3,8.30388,-0.34464,0,,,,,,,,,,,,,,,,,,,,,,,,,,,,,,,,,,,,,
48.4,8.32065,-0.32023,0,,,,,,,,,,,,,,,,,,,,,,,,,,,,,,,,,,,,,
48.5,8.33731,-0.35419,0,,,,,,,,,,,,,,,,,,,,,,,,,,,,,,,,,,,,,
48.6,8.3538,-0.40153,0,,,,,,,,,,,,,,,,,,,,,,,,,,,,,,,,,,,,,
48.7,8.37052,-0.37734,0,,,,,,,,,,,,,,,,,,,,,,,,,,,,,,,,,,,,,
48.8,8.38735,-0.3649,0,,,,,,,,,,,,,,,,,,,,,,,,,,,,,,,,,,,,,
48.9,8.40384,-0.4086,0,,,,,,,,,,,,,,,,,,,,,,,,,,,,,,,,,,,,,
49,8.4205,-0.46054,0,,,,,,,,,,,,,,,,,,,,,,,,,,,,,,,,,,,,,
49.1,8.43733,-0.47404,0,,,,,,,,,,,,,,,,,,,,,,,,,,,,,,,,,,,,,
49.2,8.45399,-0.5023,0,,,,,,,,,,,,,,,,,,,,,,,,,,,,,,,,,,,,,
49.3,8.47053,-0.49597,0,,,,,,,,,,,,,,,,,,,,,,,,,,,,,,,,,,,,,
49.4,8.48725,-0.49706,0,,,,,,,,,,,,,,,,,,,,,,,,,,,,,,,,,,,,,
49.5,8.50397,-0.49555,0,,,,,,,,,,,,,,,,,,,,,,,,,,,,,,,,,,,,,
49.6,8.52063,-0.51406,0,,,,,,,,,,,,,,,,,,,,,,,,,,,,,,,,,,,,,
49.7,8.53723,-0.50748,0,,,,,,,,,,,,,,,,,,,,,,,,,,,,,,,,,,,,,
49.8,8.55395,-0.53615,0,,,,,,,,,,,,,,,,,,,,,,,,,,,,,,,,,,,,,
49.9,8.57061,-0.54608,0,,,,,,,,,,,,,,,,,,,,,,,,,,,,,,,,,,,,,
50,8.58715,-0.53351,0,,,,,,,,,,,,,,,,,,,,,,,,,,,,,,,,,,,,,
50.1,8.60398,-0.59188,0,,,,,,,,,,,,,,,,,,,,,,,,,,,,,,,,,,,,,
50.2,8.62059,-0.53259,0,,,,,,,,,,,,,,,,,,,,,,,,,,,,,,,,,,,,,
50.3,8.63725,-0.52498,0,,,,,,,,,,,,,,,,,,,,,,,,,,,,,,,,,,,,,
50.4,8.65385,-0.57403,0,,,,,,,,,,,,,,,,,,,,,,,,,,,,,,,,,,,,,
50.5,8.67074,-0.5601,0,,,,,,,,,,,,,,,,,,,,,,,,,,,,,,,,,,,,,
50.6,8.68711,-0.56613,0,,,,,,,,,,,,,,,,,,,,,,,,,,,,,,,,,,,,,
50.7,8.70389,-0.57412,0,,,,,,,,,,,,,,,,,,,,,,,,,,,,,,,,,,,,,
50.8,8.72072,-0.57334,0,,,,,,,,,,,,,,,,,,,,,,,,,,,,,,,,,,,,,
50.9,8.73726,-0.5966,0,,,,,,,,,,,,,,,,,,,,,,,,,,,,,,,,,,,,,
51,8.75387,-0.59629,0,,,,,,,,,,,,,,,,,,,,,,,,,,,,,,,,,,,,,
51.1,8.77058,-0.6147,0,,,,,,,,,,,,,,,,,,,,,,,,,,,,,,,,,,,,,
51.2,8.7873,-0.56158,0,,,,,,,,,,,,,,,,,,,,,,,,,,,,,,,,,,,,,
51.3,8.80379,-0.58726,0,,,,,,,,,,,,,,,,,,,,,,,,,,,,,,,,,,,,,
51.4,8.82051,-0.59325,0,,,,,,,,,,,,,,,,,,,,,,,,,,,,,,,,,,,,,
51.5,8.83734,-0.59305,0,,,,,,,,,,,,,,,,,,,,,,,,,,,,,,,,,,,,,
51.6,8.85394,-0.58135,0,,,,,,,,,,,,,,,,,,,,,,,,,,,,,,,,,,,,,
51.7,8.87043,-0.62891,0,,,,,,,,,,,,,,,,,,,,,,,,,,,,,,,,,,,,,
51.8,8.88732,-0.60381,0,,,,,,,,,,,,,,,,,,,,,,,,,,,,,,,,,,,,,
51.9,8.90392,-0.62462,0,,,,,,,,,,,,,,,,,,,,,,,,,,,,,,,,,,,,,
52,8.92052,-0.61099,0,,,,,,,,,,,,,,,,,,,,,,,,,,,,,,,,,,,,,
52.1,8.93718,-0.62245,0,,,,,,,,,,,,,,,,,,,,,,,,,,,,,,,,,,,,,
52.2,8.95401,-0.63582,0,,,,,,,,,,,,,,,,,,,,,,,,,,,,,,,,,,,,,
52.3,8.97062,-0.61402,0,,,,,,,,,,,,,,,,,,,,,,,,,,,,,,,,,,,,,
52.4,8.98711,-0.65514,0,,,,,,,,,,,,,,,,,,,,,,,,,,,,,,,,,,,,,
52.5,9.00405,-0.6706,0,,,,,,,,,,,,,,,,,,,,,,,,,,,,,,,,,,,,,
52.6,9.02054,-0.62848,0,,,,,,,,,,,,,,,,,,,,,,,,,,,,,,,,,,,,,
52.7,9.03726,-0.68751,0,,,,,,,,,,,,,,,,,,,,,,,,,,,,,,,,,,,,,
52.8,9.05386,-0.64337,0,,,,,,,,,,,,,,,,,,,,,,,,,,,,,,,,,,,,,
52.9,9.07069,-0.62867,0,,,,,,,,,,,,,,,,,,,,,,,,,,,,,,,,,,,,,
53,9.08724,-0.65025,0,,,,,,,,,,,,,,,,,,,,,,,,,,,,,,,,,,,,,
53.1,9.10378,-0.63067,0,,,,,,,,,,,,,,,,,,,,,,,,,,,,,,,,,,,,,
53.2,9.12067,-0.66618,0,,,,,,,,,,,,,,,,,,,,,,,,,,,,,,,,,,,,,
53.3,9.13727,-0.73171,0,,,,,,,,,,,,,,,,,,,,,,,,,,,,,,,,,,,,,
53.4,9.15388,-0.70036,0,,,,,,,,,,,,,,,,,,,,,,,,,,,,,,,,,,,,,
53.5,9.17054,-0.69098,0,,,,,,,,,,,,,,,,,,,,,,,,,,,,,,,,,,,,,
53.6,9.18731,-0.74305,0,,,,,,,,,,,,,,,,,,,,,,,,,,,,,,,,,,,,,
53.7,9.20391,-0.70619,0,,,,,,,,,,,,,,,,,,,,,,,,,,,,,,,,,,,,,
53.8,9.22063,-0.71432,0,,,,,,,,,,,,,,,,,,,,,,,,,,,,,,,,,,,,,
53.9,9.23729,-0.75532,0,,,,,,,,,,,,,,,,,,,,,,,,,,,,,,,,,,,,,
54,9.25395,-0.73337,0,,,,,,,,,,,,,,,,,,,,,,,,,,,,,,,,,,,,,
54.1,9.2705,-0.72947,0,,,,,,,,,,,,,,,,,,,,,,,,,,,,,,,,,,,,,
54.2,9.28733,-0.71662,0,,,,,,,,,,,,,,,,,,,,,,,,,,,,,,,,,,,,,
54.3,9.30393,-0.74596,0,,,,,,,,,,,,,,,,,,,,,,,,,,,,,,,,,,,,,
54.4,9.32053,-0.74512,0,,,,,,,,,,,,,,,,,,,,,,,,,,,,,,,,,,,,,
54.5,9.33725,-0.72548,0,,,,,,,,,,,,,,,,,,,,,,,,,,,,,,,,,,,,,
54.6,9.35391,-0.75444,0,,,,,,,,,,,,,,,,,,,,,,,,,,,,,,,,,,,,,
54.7,9.37057,-0.75863,0,,,,,,,,,,,,,,,,,,,,,,,,,,,,,,,,,,,,,
54.8,9.38717,-0.75444,0,,,,,,,,,,,,,,,,,,,,,,,,,,,,,,,,,,,,,
54.9,9.40406,-0.78223,0,,,,,,,,,,,,,,,,,,,,,,,,,,,,,,,,,,,,,
55,9.42049,-0.77846,0,,,,,,,,,,,,,,,,,,,,,,,,,,,,,,,,,,,,,
55.1,9.43721,-0.78589,0,,,,,,,,,,,,,,,,,,,,,,,,,,,,,,,,,,,,,
55.2,9.45398,-0.76597,0,,,,,,,,,,,,,,,,,,,,,,,,,,,,,,,,,,,,,
55.3,9.47059,-0.74729,0,,,,,,,,,,,,,,,,,,,,,,,,,,,,,,,,,,,,,
55.4,9.48719,-0.78748,0,,,,,,,,,,,,,,,,,,,,,,,,,,,,,,,,,,,,,
55.5,9.50391,-0.79173,0,,,,,,,,,,,,,,,,,,,,,,,,,,,,,,,,,,,,,
55.6,9.52074,-0.78228,0,,,,,,,,,,,,,,,,,,,,,,,,,,,,,,,,,,,,,
55.7,9.53717,-0.796,0,,,,,,,,,,,,,,,,,,,,,,,,,,,,,,,,,,,,,
55.8,9.55383,-0.78261,0,,,,,,,,,,,,,,,,,,,,,,,,,,,,,,,,,,,,,
55.9,9.5706,-0.80827,0,,,,,,,,,,,,,,,,,,,,,,,,,,,,,,,,,,,,,
56,9.58726,-0.80835,0,,,,,,,,,,,,,,,,,,,,,,,,,,,,,,,,,,,,,
56.1,9.60381,-0.8079,0,,,,,,,,,,,,,,,,,,,,,,,,,,,,,,,,,,,,,
56.2,9.62058,-0.81999,0,,,,,,,,,,,,,,,,,,,,,,,,,,,,,,,,,,,,,
56.3,9.6373,-0.81028,0,,,,,,,,,,,,,,,,,,,,,,,,,,,,,,,,,,,,,
56.4,9.65396,-0.86108,0,,,,,,,,,,,,,,,,,,,,,,,,,,,,,,,,,,,,,
56.5,9.67051,-0.85274,0,,,,,,,,,,,,,,,,,,,,,,,,,,,,,,,,,,,,,
56.6,9.68728,-0.85752,0,,,,,,,,,,,,,,,,,,,,,,,,,,,,,,,,,,,,,
56.7,9.70394,-0.83535,0,,,,,,,,,,,,,,,,,,,,,,,,,,,,,,,,,,,,,
56.8,9.72049,-0.85124,0,,,,,,,,,,,,,,,,,,,,,,,,,,,,,,,,,,,,,
56.9,9.73726,-0.89103,0,,,,,,,,,,,,,,,,,,,,,,,,,,,,,,,,,,,,,
57,9.75392,-0.8444,0,,,,,,,,,,,,,,,,,,,,,,,,,,,,,,,,,,,,,
57.1,9.77058,-0.87359,0,,,,,,,,,,,,,,,,,,,,,,,,,,,,,,,,,,,,,
57.2,9.78718,-0.91098,0,,,,,,,,,,,,,,,,,,,,,,,,,,,,,,,,,,,,,
57.3,9.80401,-0.93744,0,,,,,,,,,,,,,,,,,,,,,,,,,,,,,,,,,,,,,
57.4,9.8205,-0.86671,0,,,,,,,,,,,,,,,,,,,,,,,,,,,,,,,,,,,,,
57.5,9.83722,-0.89998,0,,,,,,,,,,,,,,,,,,,,,,,,,,,,,,,,,,,,,
57.6,9.85399,-0.93307,0,,,,,,,,,,,,,,,,,,,,,,,,,,,,,,,,,,,,,
57.7,9.87059,-0.90525,0,,,,,,,,,,,,,,,,,,,,,,,,,,,,,,,,,,,,,
57.8,9.8872,-0.88682,0,,,,,,,,,,,,,,,,,,,,,,,,,,,,,,,,,,,,,
57.9,9.90392,-0.93453,0,,,,,,,,,,,,,,,,,,,,,,,,,,,,,,,,,,,,,
58,9.92063,-0.87853,0,,,,,,,,,,,,,,,,,,,,,,,,,,,,,,,,,,,,,
58.1,9.93712,-0.93709,0,,,,,,,,,,,,,,,,,,,,,,,,,,,,,,,,,,,,,
58.2,9.95395,-0.94463,0,,,,,,,,,,,,,,,,,,,,,,,,,,,,,,,,,,,,,
58.3,9.97067,-0.87537,0,,,,,,,,,,,,,,,,,,,,,,,,,,,,,,,,,,,,,
58.4,9.98722,-0.91789,0,,,,,,,,,,,,,,,,,,,,,,,,,,,,,,,,,,,,,
58.5,10.00376,-0.93178,0,,,,,,,,,,,,,,,,,,,,,,,,,,,,,,,,,,,,,
58.6,10.02065,-0.92187,0,,,,,,,,,,,,,,,,,,,,,,,,,,,,,,,,,,,,,
58.7,10.03725,-0.90838,0,,,,,,,,,,,,,,,,,,,,,,,,,,,,,,,,,,,,,
58.8,10.05386,-0.90816,0,,,,,,,,,,,,,,,,,,,,,,,,,,,,,,,,,,,,,
58.9,10.07057,-0.9113,0,,,,,,,,,,,,,,,,,,,,,,,,,,,,,,,,,,,,,
59,10.08735,-0.95944,0,,,,,,,,,,,,,,,,,,,,,,,,,,,,,,,,,,,,,
59.1,10.10395,-0.9806,0,,,,,,,,,,,,,,,,,,,,,,,,,,,,,,,,,,,,,
59.2,10.12044,-0.92104,0,,,,,,,,,,,,,,,,,,,,,,,,,,,,,,,,,,,,,
59.3,10.13738,-0.92267,0,,,,,,,,,,,,,,,,,,,,,,,,,,,,,,,,,,,,,
59.4,10.15387,-0.94992,0,,,,,,,,,,,,,,,,,,,,,,,,,,,,,,,,,,,,,
59.5,10.17059,-0.96078,0,,,,,,,,,,,,,,,,,,,,,,,,,,,,,,,,,,,,,
59.6,10.18719,-0.97848,0,,,,,,,,,,,,,,,,,,,,,,,,,,,,,,,,,,,,,
59.7,10.20402,-0.97209,0,,,,,,,,,,,,,,,,,,,,,,,,,,,,,,,,,,,,,
59.8,10.22057,-0.93603,0,,,,,,,,,,,,,,,,,,,,,,,,,,,,,,,,,,,,,
59.9,10.23717,-1.01459,0,,,,,,,,,,,,,,,,,,,,,,,,,,,,,,,,,,,,,
60,10.254,-1.03106,0,,,,,,,,,,,,,,,,,,,,,,,,,,,,,,,,,,,,,
60.1,10.27055,-1.03566,0,,,,,,,,,,,,,,,,,,,,,,,,,,,,,,,,,,,,,
60.2,10.28721,-0.99166,0,,,,,,,,,,,,,,,,,,,,,,,,,,,,,,,,,,,,,
60.3,10.30393,-1.02161,0,,,,,,,,,,,,,,,,,,,,,,,,,,,,,,,,,,,,,
60.4,10.32064,-0.98957,0,,,,,,,,,,,,,,,,,,,,,,,,,,,,,,,,,,,,,
60.5,10.33719,-1.05766,0,,,,,,,,,,,,,,,,,,,,,,,,,,,,,,,,,,,,,
60.6,10.3539,-1.05577,0,,,,,,,,,,,,,,,,,,,,,,,,,,,,,,,,,,,,,
60.7,10.37062,-1.07292,0,,,,,,,,,,,,,,,,,,,,,,,,,,,,,,,,,,,,,
60.8,10.38728,-1.0938,0,,,,,,,,,,,,,,,,,,,,,,,,,,,,,,,,,,,,,
60.9,10.40383,-1.1949,0,,,,,,,,,,,,,,,,,,,,,,,,,,,,,,,,,,,,,
61,10.42066,-1.14909,0,,,,,,,,,,,,,,,,,,,,,,,,,,,,,,,,,,,,,
61.1,10.43721,-1.19016,0,,,,,,,,,,,,,,,,,,,,,,,,,,,,,,,,,,,,,
61.2,10.45387,-1.21802,0,,,,,,,,,,,,,,,,,,,,,,,,,,,,,,,,,,,,,
61.3,10.47058,-1.21009,0,,,,,,,,,,,,,,,,,,,,,,,,,,,,,,,,,,,,,
61.4,10.4873,-1.20815,0,,,,,,,,,,,,,,,,,,,,,,,,,,,,,,,,,,,,,
61.5,10.50396,-1.23685,0,,,,,,,,,,,,,,,,,,,,,,,,,,,,,,,,,,,,,
61.6,10.5205,-1.25677,0,,,,,,,,,,,,,,,,,,,,,,,,,,,,,,,,,,,,,
61.7,10.53739,-1.30617,0,,,,,,,,,,,,,,,,,,,,,,,,,,,,,,,,,,,,,
61.8,10.55388,-1.33622,0,,,,,,,,,,,,,,,,,,,,,,,,,,,,,,,,,,,,,
61.9,10.57054,-1.36011,0,,,,,,,,,,,,,,,,,,,,,,,,,,,,,,,,,,,,,
62,10.58726,-1.37323,0,,,,,,,,,,,,,,,,,,,,,,,,,,,,,,,,,,,,,
62.1,10.60392,-1.38556,0,,,,,,,,,,,,,,,,,,,,,,,,,,,,,,,,,,,,,
62.2,10.62047,-1.38038,0,,,,,,,,,,,,,,,,,,,,,,,,,,,,,,,,,,,,,
62.3,10.63724,-1.34386,0,,,,,,,,,,,,,,,,,,,,,,,,,,,,,,,,,,,,,
62.4,10.65401,-1.41681,0,,,,,,,,,,,,,,,,,,,,,,,,,,,,,,,,,,,,,
62.5,10.67045,-1.4193,0,,,,,,,,,,,,,,,,,,,,,,,,,,,,,,,,,,,,,
62.6,10.68716,-1.41876,0,,,,,,,,,,,,,,,,,,,,,,,,,,,,,,,,,,,,,
62.7,10.70399,-1.43323,0,,,,,,,,,,,,,,,,,,,,,,,,,,,,,,,,,,,,,
62.8,10.72065,-1.46877,0,,,,,,,,,,,,,,,,,,,,,,,,,,,,,,,,,,,,,
62.9,10.73709,-1.43802,0,,,,,,,,,,,,,,,,,,,,,,,,,,,,,,,,,,,,,
63,10.75397,-1.52931,0,,,,,,,,,,,,,,,,,,,,,,,,,,,,,,,,,,,,,
63.1,10.77069,-1.41938,0,,,,,,,,,,,,,,,,,,,,,,,,,,,,,,,,,,,,,
63.2,10.78724,-1.47073,0,,,,,,,,,,,,,,,,,,,,,,,,,,,,,,,,,,,,,
63.3,10.80384,-1.41882,0,,,,,,,,,,,,,,,,,,,,,,,,,,,,,,,,,,,,,
63.4,10.82073,-1.43848,0,,,,,,,,,,,,,,,,,,,,,,,,,,,,,,,,,,,,,
63.5,10.83722,-1.48487,0,,,,,,,,,,,,,,,,,,,,,,,,,,,,,,,,,,,,,
63.6,10.85382,-1.47711,0,,,,,,,,,,,,,,,,,,,,,,,,,,,,,,,,,,,,,
63.7,10.87065,-1.45354,0,,,,,,,,,,,,,,,,,,,,,,,,,,,,,,,,,,,,,
63.8,10.88725,-1.4447,0,,,,,,,,,,,,,,,,,,,,,,,,,,,,,,,,,,,,,
63.9,10.90397,-1.48278,0,,,,,,,,,,,,,,,,,,,,,,,,,,,,,,,,,,,,,
64,10.92046,-1.48869,0,,,,,,,,,,,,,,,,,,,,,,,,,,,,,,,,,,,,,
64.1,10.9374,-1.4846,0,,,,,,,,,,,,,,,,,,,,,,,,,,,,,,,,,,,,,
64.2,10.95384,-1.47792,0,,,,,,,,,,,,,,,,,,,,,,,,,,,,,,,,,,,,,
64.3,10.97055,-1.45361,0,,,,,,,,,,,,,,,,,,,,,,,,,,,,,,,,,,,,,
64.4,10.98738,-1.47053,0,,,,,,,,,,,,,,,,,,,,,,,,,,,,,,,,,,,,,
64.5,11.00387,-1.46713,0,,,,,,,,,,,,,,,,,,,,,,,,,,,,,,,,,,,,,
64.6,11.02053,-1.42937,0,,,,,,,,,,,,,,,,,,,,,,,,,,,,,,,,,,,,,
64.7,11.03719,-1.47312,0,,,,,,,,,,,,,,,,,,,,,,,,,,,,,,,,,,,,,
64.8,11.05402,-1.50243,0,,,,,,,,,,,,,,,,,,,,,,,,,,,,,,,,,,,,,
64.9,11.07051,-1.46901,0,,,,,,,,,,,,,,,,,,,,,,,,,,,,,,,,,,,,,
65,11.08723,-1.4754,0,,,,,,,,,,,,,,,,,,,,,,,,,,,,,,,,,,,,,
65.1,11.104,-1.46431,0,,,,,,,,,,,,,,,,,,,,,,,,,,,,,,,,,,,,,
65.2,11.12061,-1.47236,0,,,,,,,,,,,,,,,,,,,,,,,,,,,,,,,,,,,,,
65.3,11.13715,-1.49007,0,,,,,,,,,,,,,,,,,,,,,,,,,,,,,,,,,,,,,
65.4,11.15398,-1.47934,0,,,,,,,,,,,,,,,,,,,,,,,,,,,,,,,,,,,,,
65.5,11.17053,-1.50288,0,,,,,,,,,,,,,,,,,,,,,,,,,,,,,,,,,,,,,
65.6,11.18725,-1.51368,0,,,,,,,,,,,,,,,,,,,,,,,,,,,,,,,,,,,,,
65.7,11.20391,-1.51108,0,,,,,,,,,,,,,,,,,,,,,,,,,,,,,,,,,,,,,
65.8,11.22062,-1.44774,0,,,,,,,,,,,,,,,,,,,,,,,,,,,,,,,,,,,,,
65.9,11.23728,-1.53631,0,,,,,,,,,,,,,,,,,,,,,,,,,,,,,,,,,,,,,
66,11.25377,-1.52334,0,,,,,,,,,,,,,,,,,,,,,,,,,,,,,,,,,,,,,
66.1,11.27072,-1.47506,0,,,,,,,,,,,,,,,,,,,,,,,,,,,,,,,,,,,,,
66.2,11.28721,-1.51528,0,,,,,,,,,,,,,,,,,,,,,,,,,,,,,,,,,,,,,
66.3,11.30387,-1.49903,0,,,,,,,,,,,,,,,,,,,,,,,,,,,,,,,,,,,,,
66.4,11.32053,-1.47956,0,,,,,,,,,,,,,,,,,,,,,,,,,,,,,,,,,,,,,
66.5,11.3373,-1.41282,0,,,,,,,,,,,,,,,,,,,,,,,,,,,,,,,,,,,,,
66.6,11.35385,-1.49947,0,,,,,,,,,,,,,,,,,,,,,,,,,,,,,,,,,,,,,
66.7,11.37051,-1.54522,0,,,,,,,,,,,,,,,,,,,,,,,,,,,,,,,,,,,,,
66.8,11.38739,-1.49812,0,,,,,,,,,,,,,,,,,,,,,,,,,,,,,,,,,,,,,
66.9,11.40383,-1.53471,0,,,,,,,,,,,,,,,,,,,,,,,,,,,,,,,,,,,,,
67,11.42054,-1.51807,0,,,,,,,,,,,,,,,,,,,,,,,,,,,,,,,,,,,,,
67.1,11.43732,-1.55279,0,,,,,,,,,,,,,,,,,,,,,,,,,,,,,,,,,,,,,
67.2,11.45397,-1.56027,0,,,,,,,,,,,,,,,,,,,,,,,,,,,,,,,,,,,,,
67.3,11.47052,-1.53516,0,,,,,,,,,,,,,,,,,,,,,,,,,,,,,,,,,,,,,
67.4,11.4873,-1.5157,0,,,,,,,,,,,,,,,,,,,,,,,,,,,,,,,,,,,,,
67.5,11.50396,-1.56059,0,,,,,,,,,,,,,,,,,,,,,,,,,,,,,,,,,,,,,
67.6,11.52061,-1.55139,0,,,,,,,,,,,,,,,,,,,,,,,,,,,,,,,,,,,,,
67.7,11.53716,-1.54655,0,,,,,,,,,,,,,,,,,,,,,,,,,,,,,,,,,,,,,
67.8,11.55399,-1.51945,0,,,,,,,,,,,,,,,,,,,,,,,,,,,,,,,,,,,,,
67.9,11.57054,-1.54049,0,,,,,,,,,,,,,,,,,,,,,,,,,,,,,,,,,,,,,
68,11.58714,-1.52859,0,,,,,,,,,,,,,,,,,,,,,,,,,,,,,,,,,,,,,
68.1,11.60397,-1.53714,0,,,,,,,,,,,,,,,,,,,,,,,,,,,,,,,,,,,,,
68.2,11.62063,-1.53263,0,,,,,,,,,,,,,,,,,,,,,,,,,,,,,,,,,,,,,
68.3,11.63723,-1.59267,0,,,,,,,,,,,,,,,,,,,,,,,,,,,,,,,,,,,,,
68.4,11.65378,-1.63003,0,,,,,,,,,,,,,,,,,,,,,,,,,,,,,,,,,,,,,
68.5,11.67078,-1.58787,0,,,,,,,,,,,,,,,,,,,,,,,,,,,,,,,,,,,,,
68.6,11.68722,-1.59346,0,,,,,,,,,,,,,,,,,,,,,,,,,,,,,,,,,,,,,
68.7,11.70388,-1.54936,0,,,,,,,,,,,,,,,,,,,,,,,,,,,,,,,,,,,,,
68.8,11.72054,-1.51784,0,,,,,,,,,,,,,,,,,,,,,,,,,,,,,,,,,,,,,
68.9,11.73731,-1.59906,0,,,,,,,,,,,,,,,,,,,,,,,,,,,,,,,,,,,,,
69,11.75386,-1.57038,0,,,,,,,,,,,,,,,,,,,,,,,,,,,,,,,,,,,,,
69.1,11.77057,-1.61674,0,,,,,,,,,,,,,,,,,,,,,,,,,,,,,,,,,,,,,
69.2,11.78735,-1.61626,0,,,,,,,,,,,,,,,,,,,,,,,,,,,,,,,,,,,,,
69.3,11.80384,-1.59676,0,,,,,,,,,,,,,,,,,,,,,,,,,,,,,,,,,,,,,
69.4,11.82055,-1.62275,0,,,,,,,,,,,,,,,,,,,,,,,,,,,,,,,,,,,,,
69.5,11.83733,-1.63488,0,,,,,,,,,,,,,,,,,,,,,,,,,,,,,,,,,,,,,
69.6,11.85393,-1.63313,0,,,,,,,,,,,,,,,,,,,,,,,,,,,,,,,,,,,,,
69.7,11.87048,-1.60796,0,,,,,,,,,,,,,,,,,,,,,,,,,,,,,,,,,,,,,
69.8,11.88731,-1.57199,0,,,,,,,,,,,,,,,,,,,,,,,,,,,,,,,,,,,,,
69.9,11.90396,-1.61295,0,,,,,,,,,,,,,,,,,,,,,,,,,,,,,,,,,,,,,
69.944,11.91122,-1.60714,0,,,,,,,,,,,,,,,,,,,,,,,,,,,,,,,,,,,,,